Workbook

Sheet 様式１　プログラムを構成する授業科目（申請用）
T1: 様式１ | V1: 「学部・学科によって、修了要件は相違する」場合は、本シートを複製の上＜様式１－〇＞と枝番号を付してください
B2: 大学等名 | C2: 北海道教育大学
B3: プログラム名 | C3: 数理・データサイエンス・AI教育プログラム（リテラシーレベル）
A5: リテラシーレベルのプログラムを構成する授業科目について
A7: ① 教育プログラムの修了要件 | L7: 学部・学科によって、修了要件は相違しない
A9: ② 対象となる学部・学科名称
A14: ③ 修了要件
B15: 本プログラムを構成する授業科目「情報教育実践論」（２単位）の単位修得を修了要件としている。 上記授業は、「５つの審査項目」と「モデルカリキュラム」の各項目を網羅している。 | X15: 【プルダウンリスト】
X16: 令和６年度以前より、履修することが必須のプログラムとして実施
X17: 令和９年度までに履修必須とする計画
X18: 令和１０年度以降に履修必須とする計画、又は未定
B22: 必要最低科目数・単位数 | E22: 1 | F22: 科目 | H22: 2 | I22: 単位 | M22: 履修必須の有無 | N22: 令和６年度以前より、履修することが必須のプログラムとして実施
A24: ④ 現在進行中の社会変化（第４次産業革命、Society 5.0、データ駆動型社会等）に深く寄与しているものであり、それが自らの生活と密接に結びついている」の内容を含む授業科目
B26: 授業科目 | G26: 単位数 | H26: 必須 | I26: 1-1 | J26: 1-6 | K26: 授業科目 | R26: 単位数 | S26: 必須 | T26: 1-1 | U26: 1-6
B27: 情報教育実践論 | G27: 2 | H27: ○ | I27: ○ | J27: ○
A35: ⑤ 「社会で活用されているデータ」や「データの活用領域」は非常に広範囲であって、日常生活や社会の課題を解決する有用なツールになり得るもの」の内容を含む授業科目
B37: 授業科目 | G37: 単位数 | H37: 必須 | I37: 1-2 | J37: 1-3 | K37: 授業科目 | R37: 単位数 | S37: 必須 | T37: 1-2 | U37: 1-3
B38: 情報教育実践論 | G38: 2 | H38: ○ | I38: ○ | J38: ○
A46: ⑥ 「様々なデータ利活用の現場におけるデータ利活用事例が示され、様々な適用領域（流通、製造、金融、サービス、インフラ、公共、ヘルスケア等）の知見と組み合わせることで価値を創出するもの」の内容を含む授業科目
B48: 授業科目 | G48: 単位数 | H48: 必須 | I48: 1-4 | J48: 1-5 | K48: 授業科目 | R48: 単位数 | S48: 必須 | T48: 1-4 | U48: 1-5
B49: 情報教育実践論 | G49: 2 | H49: ○ | I49: ○ | J49: ○
A57: ⑦ 「活用に当たっての様々な留意事項（ELSI、個人情報、データ倫理、ＡＩ社会原則等）を考慮し、情報セキュリティや情報漏洩等、データを守る上での留意事項への理解をする」の内容を含む授業科目
B59: 授業科目 | G59: 単位数 | H59: 必須 | I59: 3-1 | J59: 3-2 | K59: 授業科目 | R59: 単位数 | S59: 必須 | T59: 3-1 | U59: 3-2
B60: 情報教育実践論 | G60: 2 | H60: ○ | I60: ○ | J60: ○
A68: ⑧ 「実データ・実課題（学術データ等を含む）を用いた演習など、社会での実例を題材として、「データを読む、説明する、扱う」といった数理・データサイエンス・ＡＩの基本的な活用法に関するもの」の内容を含む授業科目
B70: 授業科目 | F70: 単位数 | G70: 必須 | H70: 2-1 | I70: 2-2 | J70: 2-3 | K70: 授業科目 | Q70: 単位数 | R70: 必須 | S70: 2-1 | T70: 2-2 | U70: 2-3
B71: 情報教育実践論 | F71: 2 | G71: ○ | H71: ○ | I71: ○ | J71: ○
A79: ⑨ 選択「４．オプション」の内容を含む授業科目
B80: 授業科目 | G80: 選択項目 | K80: 授業科目 | R80: 選択項目 | AA80: 4-1統計および数理基礎
AA81: 4‐2アルゴリズム基礎
AA82: 4‐3データ構造とプログラミング基礎
AA83: 4‐4時系列データ解析
AA84: 4‐5自然言語処理
AA85: 4‐6画像認識
AA86: 4‐7データハンドリング
AA87: 4‐8データ活用実践（教師あり学習）
AA88: 4‐9データ活用実践（教師なし学習）
A89: ⑩ プログラムを構成する授業の内容 | AA89: その他
B90: 授業に含まれている内容・要素 | D90: 講義内容
B91: （１）現在進行中の社会変化（第４次産業革命、Society 5.0、データ駆動型社会等）に深く寄与しているものであり、それが自らの生活と密接に結びついている | C91: 1-1 | D91: 情報教育実践論（第１回） ビッグデータ、ＩｏＴ、ＡＩ、生成ＡＩ、ロボット データ量の増加、計算機の処理性能の向上、ＡＩの非連続的進化 第4次産業革命、Society5.0、データ駆動型社会
...

Sheet 様式２ 履修者等数の実績（申請用）
S1: 様式２
Q2: ='様式１ プログラムを構成する授業科目（申請用）'!C2 -> 北海道教育大学
A3: リテラシーレベルのプログラムの履修者数等の実績について
A5: ①プログラム開設年度 | C5: 令和６ | E5: 年度（和暦）
A7: ②大学等全体の男女別学生数 | E7: 男性 | F7: 2278 | G7: 人 | H7: 女性 | I7: 2777 | J7: 人 | K7: （ | L7: 合計 | M7: =F7+I7 -> 5055 | N7: 人 | O7: ）
B8: （令和６年５月１日時点）
A9: ③履修者・修了者の実績
B11: 学部・学科名称 | C11: 学生数 | D11: 入学 定員 | E11: 収容 定員 | F11: 令和6年度 | H11: 令和5年度 | J11: 令和4年度 | L11: 令和3年度 | N11: 令和2年度 | P11: 令和元年度 | R11: 履修者数 合計 | S11: 履修率
F12: 履修者数 | G12: 修了者数 | H12: 履修者数 | I12: 修了者数 | J12: 履修者数 | K12: 修了者数 | L12: 履修者数 | M12: 修了者数 | N12: 履修者数 | O12: 修了者数 | P12: 履修者数 | Q12: 修了者数
B13: 教育学部教員養成課程 | C13: 3063 | D13: 720 | E13: 2880 | F13: 14 | G13: 14 | R13: =F13+H13+J13+L13+N13+P13 -> 14 | S13: =R13/E13 -> 0.0048611111
B14: 国際地域学科 | C14: 1232 | D14: 285 | E14: 1140 | F14: 7 | G14: 6 | R14: =F14+H14+J14+L14+N14+P14 -> 7 | S14: =R14/E14 -> 0.0061403509
B15: 芸術・スポーツ文化学科 | C15: 760 | D15: 180 | E15: 720 | F15: 0 | G15: 0 | R15: =F15+H15+J15+L15+N15+P15 -> 0 | S15: =R15/E15 -> 0
R16: =F16+H16+J16+L16+N16+P16 -> 0 | S16: =R16/E16 -> #DIV/0!
R17: =F17+H17+J17+L17+N17+P17 -> 0 | S17: =R17/E17 -> #DIV/0!
R18: =F18+H18+J18+L18+N18+P18 -> 0 | S18: =R18/E18 -> #DIV/0!
R19: =F19+H19+J19+L19+N19+P19 -> 0 | S19: =R19/E19 -> #DIV/0!
R20: =F20+H20+J20+L20+N20+P20 -> 0 | S20: =R20/E20 -> #DIV/0!
R21: =F21+H21+J21+L21+N21+P21 -> 0 | S21: =R21/E21 -> #DIV/0!
R22: =F22+H22+J22+L22+N22+P22 -> 0 | S22: =R22/E22 -> #DIV/0!
R23: =F23+H23+J23+L23+N23+P23 -> 0 | S23: =R23/E23 -> #DIV/0!
R24: =F24+H24+J24+L24+N24+P24 -> 0 | S24: =R24/E24 -> #DIV/0!
R25: =F25+H25+J25+L25+N25+P25 -> 0 | S25: =R25/E25 -> #DIV/0!
R26: =F26+H26+J26+L26+N26+P26 -> 0 | S26: =R26/E26 -> #DIV/0!
R27: =F27+H27+J27+L27+N27+P27 -> 0 | S27: =R27/E27 -> #DIV/0!
... R32: =F32+H32+J32+L32+N32+P32 -> 0 | S32: =R32/E32 -> #DIV/0!
B33: 合 計 | C33: =SUM(C13:C32) -> 5055 | D33: =SUM(D13:D32) -> 1185 | E33: =SUM(E13:E32) -> 4740 | F33: =SUM(F13:F32) -> 21 | G33: =SUM(G13:G32) -> 20 | H33: =SUM(H13:H32) -> 0 | I33: =SUM(I13:I32) -> 0 | J33: =SUM(J13:J32) -> 0 | ... R33: =SUM(R13:R32) -> 21 | S33: =R33/E33 -> 0.0044303797

Sheet 様式３ 教育の質・履修者数を向上させるための体制・計画 （申請
I1: 様式３
G2: 大学等名 | H2: ='様式１ プログラムを構成する授業科目（申請用）'!C2 -> 北海道教育大学
A4: 教育の質・履修者数を向上させるための体制・計画について
A6: ① | B6: 全学の教員数 | C6: (常勤） | E6: 346 | F6: 人 | G6: （非常勤） | H6: 718 | I6: 人
A8: ② | B8: プログラムの授業を教えている教員数 | H8: 1 | I8: 人
A10: ③ | B10: プログラムの運営責任者
B11: （責任者名） | C11: 海老名 尚 | G11: （役職名） | H11: 理事（教育・評価担当）・副学長
A13: ④ | B13: プログラムを改善・進化させるための体制（委員会・組織等）
B14: 北海道教育大学教育委員会数理・データ・サイエンス・AI教育プログラム部会
B16: （責任者名） | C16: 山中謙司 | G16: （役職名） | H16: 准教授・ 教育担当特別補佐
A18: ⑤ | B18: プログラムを改善・進化させるための体制を定める規則名称
B19: 北海道教育委員会規則 北海道教育大学教育委員会に設置する部会に関する要項
A21: ⑥ | B21: 体制の目的
B22: 本学が実施する数理・データサイエンス・AI 教育プログラム(以下，「MDASH」という。)の実施計画の策定、MDASHの基本方針及び運営方針、MDASHを構成する授業科目の内容、MDASHの実施についての各校間における連絡調整、MDASHに関する自己点検評価等に関する業務を目的としている。
A34: ⑦ | B34: 具体的な構成員
B35: 部会長 １名 山中 謙司・旭川校准教授 部会員 ６名 石川 智浩・札幌校准教授 植田 優基・旭川校准教授 廣重 真人・釧路校准教授 大久保 好章・函館校准教授 鈴木 哲平・岩見沢校准教授 佐藤 正範・未来の学び協創研究センター特任講師
A48: ⑧ | B48: 履修者数・履修率の向上に向けた計画 ※様式１の「履修必須の有無」で「計画がある」としている場合は詳細について記載すること
B49: 令和６年度実績 | C49: ='様式２ 履修者等数の実績（申請用）'!S13 -> 0.0048611111 | E49: 令和７年度予定 | F49: 0.2 | H49: 令和８年度予定 | I49: 0.4
B50: 令和９年度予定 | C50: 0.6 | E50: 令和１０年度予定 | F50: 0.8 | H50: 収容定員（名） | I50: ='様式２ 履修者等数の実績（申請用）'!E33 -> 4740
B51: 具体的な計画
B52: 令和６年度は開講初年度であったことから受講者が少なかった。令和７年度は、さらなる周知を図り、履修者数の増を目指す。 なお、令和７ 年度から「情報機器の操作」の内容を見直した授業科目「現代社会の情報活用」を開設（教員養成課程・国際地域学科地域教育専攻においては必修科目、国際地域学科地域協働専攻及び芸術・スポーツ文化学科においては選択科目）し、同プログラムに追加することとしている。 「情報教育実践論」「現代社会の情報活用」のそれぞれの科目が単独で「５つの審査項目」と「モデルカリキュラム」の各項目を網羅しており、どちらか一方の科目を履修・単位修得することでプログラムを修了することができる。科目の選択肢を増やすことで、令和７年度以降、同プログラムの履修者数増を見込んでいる。
A65: ⑨ | B65: 学部・学科に関係なく希望する学生全員が受講可能となるような必要な体制・取組等
B66: 令和６年度から本学の全てのキャンパス（札幌校、旭川校、釧路校、函館校、岩見沢校）の学生が受講できるよう令和５年度に科目編成を整えた（履修基準の改正）。 なお、令和７年度から「情報機器の操作」の内容を見直した授業科目「現代社会の情報活用」を開設（教員養成課程・国際地域学科地域教育専攻においては必修科目、国際地域学科地域協働専攻及び芸術・スポーツ文化学科においては選択科目）し、同プログラムに追加することとしている。 「情報教育実践論」「現代社会の情報活用」のそれぞれの科目が単独で「５つの審査項目」と「モデルカリキュラム」の各項目を網羅しており、どちらか一方の科目を履修・単位修得することでプログラムを修了することができるようにすることで、学生全員が受講可能となるような科目の選択肢を増やす体制としている。
A79: ⑩ | B79: できる限り多くの学生が履修できるような具体的な周知方法・取組
B80: 本学HPへの掲載、教務システムをはじめとした掲示等により、数理・データサイエンス・AI教育プログラムについての周知を行っている。 また、学内の会議においても周知を図り、教員から学生への働かきかけを行うよう依頼している。 なお、令和７年度から「情報機器の操作」の内容を見直した授業科目「現代社会の情報活用」を開設（教員養成課程・国際地域学科地域教育専攻においては必修科目、国際地域学科地域協働専攻及び芸術・スポーツ文化学科においては選択科目）し、同プログラムに追加することとしている。 「情報教育実践論」「現代社会の情報活用」のそれぞれの科目が単独で「５つの審査項目」と「モデルカリキュラム」の各項目を網羅しており、どちらか一方の科目を履修・単位修得することでプログラムを修了することができるようにすることで、できる限り多くの学生が履修できるよう選択肢を増やす取組を行っている。
A93: ⑪ | B93: できる限り多くの学生が履修・修得できるようなサポート体制
B94: 本学は、教育職員免許を取得する学生が大半であり、必修科目等の履修すべき科目数が多いことから、学期内での開講では、履修の機会を得ることができない学生もいることが予想されるため、通常授業に加えて集中講義でも開講することとした。令和６年度から数理・データサイエンスAI教育プログラム部会を設置し、各校に専門教員を配置することで学生の履修・修得がスムーズに行われる体制をつくった。
A107: ⑫ | B107: 授業時間内外で学習指導、質問を受け付ける具体的な仕組み
B108: 授業担当教員が設けるオフィスアワーにより不明な点があれば随時質問できるようにしている。また、内容に関しての質問対応を本講義を受講する学生専用のClassroomを作成し、各回ごとに質問フォーム上で受け付けることができるようにした。フィードバックは受講生全体が閲覧可能な仕組みとしている。

Sheet 様式４　自己点検・評価（申請用）
I1: 様式４
H2: 大学等名 | I2: ='様式１ プログラムを構成する授業科目（申請用）'!C2 -> 北海道教育大学
A3: 自己点検・評価について
A5: ① | B5: プログラムの自己点検・評価を行う体制（委員会・組織等）
B6: 数理・データサイエンス・AI教育プログラム部会
D8: （責任者名） | E8: 山中謙司 | G8: （役職名） | H8: 准教授・教育担当特別補佐
A10: ② | B10: 自己点検・評価体制における意見等
B11: 自己点検・評価の視点 | E11: 自己点検・評価体制における意見・結果・改善に向けた取組等
B12: 学内からの視点
C13: プログラムの履修・修得状況 | E13: 全学的に運用されている教育支援総合システムのデータをもとに、受講者の履修・取得状況を確認して いる。令和６年度のプログラムを構成する授業科目「情報教育実践論」の履修者数は２１人であった。本学の収容定員は４，７４０人であることから、履修率は０．４４％（２１人／４，７４０人）と非常に少ない状況であった。令和７年度は、履修者増に向けて、更なる働きかけが必要である。 なお、当該科目は１科目で５つの審査項目及びモデルカリキュラムを網羅しており、履修者２１人のうち１人が欠席したことから修了率は９５．２％である。 なお、令和７ 年度から「情報機器の操作」の内容を見直した授業科目「現代社会の情報活用」を開設（教員養成課程・国際地域学科地域教育専攻においては必修科目、国際地域学科地域協働専攻及び芸術・スポーツ文化学科においては選択科目）し、同プログラムに追加することとしている。 「情報教育実践論」「現代社会の情報活用」のそれぞれの科目が単独で５つの審査項目及びモデルカリキュラムを網羅しており、どちらか一方の科目を履修・単位修得することでプログラムを修了することができる。科目の選択肢を増やすことで、令和７年度以降、同プログラムの履修者数増を見込んでいる。
C14: 学修成果 | E14: 学生アンケートにおいて以下の項目について質問（４段階）を行った。 「3 講義で使用された教材(ICTツールやアプリ)は役に立つと思いましたか？」 「4 この講義の受講によって、数理・データサイエンス・AIへの興味や関心が広がりましたか？」 「5 この講義の受講内容が、これからの学生生活や未来において、友達等との話題になることがあると感じますか？」 「6 この講義の受講内容が、これからの学生生活や未来において、他の学生や新しい人脈など、人的ネットワークの広がりにつながると感じますか？」 上記質問項目の回答平均値（４が最高）について、それぞれ、 [3]：3.85 [4]：3.80 [5]：3.50 [6]：3.10 と肯定的な結果となっており、学修成果があったと言える。
C15: 学生アンケート等を通じた学生の内容の理解度 | E15: 学生アンケートの質問項目「講義の内容について、全体の理解度はどのように感じていますか？」（４段階）に対し、回答平均値が3.65であったことから、理解度が高いと言える。
C16: 学生アンケート等を通じた後輩等他の学生への推奨度 | E16: 学生アンケートの質問項目「この講義を他の学生に推薦しようと思いますか？」に対し、全ての学生が「思う」「とても思う」と回答した。 推奨しようとする理由については、複数回答で ①教材(ICTツール・アプリ)が役立つと思うから 16件 ②講義の内容が興味深かったから 14件 ③講義の実施方法・講師の教え方が良かったから 13件 ④内容に対する理解が深まったから 10件 ⑤他の講義内容や活動や実生活等で応用できそうだから 10件 が挙げられている。
C17: 全学的な履修者数、履修率向上に向けた計画の達成・進捗状況 | E17: 履修者数増に向け、全学会議での周知、全学HPや教育支援総合システム等による学生への周知などの取組を行ったが、令和６年度は開講初年度ということもあり認知度が低く履修者数は２１人にとどまった。令和７年度においては、更なる周知を図っていく。 なお、令和７年度から「情報機器の操作」の内容を見直した授業科目「現代社会の情報活用」を開設（教員養成課程・国際地域学科地域教育専攻においては必修科目、国際地域学科地域協働専攻及び芸術・スポーツ文化学科においては選択科目）し、同プログラムに追加することとしている。 「情報教育実践論」「現代社会の情報活用」のそれぞれの科目が単独で５つの審査項目及びモデルカリキュラムを網羅しており、どちらか一方の科目を履修・単位修得することでプログラムを修了することができる。科目の選択肢を増やすことで、令和７年度以降、同プログラムの履修者数増を見込んでいる。
B18: 学外からの視点
C19: 教育プログラム修了者の進路、活躍状況、企業等の評価 | E19: 本プログラムを修了した卒業生は令和６年度末時点で出ていない。卒業生を輩出後、就職先への意見聴取等により、活躍状況等確認を行う予定である。
C20: 産業界からの視点を含めた教育プログラム内容・手法等への意見 | E20: 本学の主な就職先や共同研究先である学校現場や企業等に対して、本学の数理・データサイエンス・AI教育プログラムの内容を説明し、意見等を聴取していくこととする。
B21: 数理・データサイエンス・ＡＩを「学ぶ楽しさ」「学ぶことの意義」を理解させること | E21: 学生アンケートから 「自分が児童・生徒の頃とは全く異なった教育が展開されようとしている事を実感した。情報化に伴って社会が教育に求めていることは次々と更新されていく。教員のアップデートの重要性を痛感すると共に、今の自分に足りないものやこれからの自分が身につけなければならないことを発見できた。」 「ツールやアプリの使い方がわかるとともに、教育の場でICTをどのように使っていくべきかを考えさせられる内容だったことがよかった。他の授業では理論的な内容でとどまってしまうところを、実際に触ってそのメリットもデメリットも様々な面を体感できてよかった。」 「AIの使用や動画編集などやってみようと思っていてもなかなか手が出せなかったことも講義で取り上げられていたので学びの一歩を踏み出すことができた。」 「プログラミングや生成AIを簡単な操作から学ぶことができ，考え方や情報活用の仕方について理解を深められた。」 など、「学ぶ楽しさ」や「学ぶことの意義」についての意見が多く寄せられた。
B22: 内容・水準を維持・向上しつつ、より「分かりやすい」授業とすること ※社会の変化や生成AI等の技術の発展を踏まえて教育内容を継続的に見直すなど、より教育効果の高まる授業内容・方法とするための取組や仕組みについても該当があれば記載 | E22: 講義について、難しかった点、改善点などについて、学生アンケートで質問しており、寄せられた意見等を踏まえて、授業内容を改善していく。具体的には、課題解決に際しての活動時間が短かった。という意見や、機械学習のプログラムがうまく動かなかったという意見があったが、既に活動内容を見直したり、機械学習で使用するプログラミング環境を変更している。
