Workbook

Sheet 様式１-1　プログラムを構成する授業科目 (SMIS)
T1: 様式１-１ | V1: 「学部・学科によって、修了要件は相違する」場合は、本シートを複製の上＜様式１－〇＞と枝番号を付してください
B2: 大学等名 | C2: 多摩大学
B3: プログラム名 | C3: 多摩大学 数理・データサイエンス・AI教育基礎プログラム
A5: リテラシーレベルのプログラムを構成する授業科目について
A7: ① 教育プログラムの修了要件 | L7: 学部・学科によって、修了要件は相違する
A9: ② 対象となる学部・学科名称
B11: 経営情報学部
A14: ③ 修了要件
B15: プログラムを構成する科目すべて、下記２科目合計４単位を修得すること。 １．AIの活用基礎、２．ICTコミュニケーション入門 | X15: 【プルダウンリスト】
X16: 令和６年度以前より、履修することが必須のプログラムとして実施
X17: 令和９年度までに履修必須とする計画
X18: 令和１０年度以降に履修必須とする計画、又は未定
B22: 必要最低科目数・単位数 | E22: 2 | F22: 科目 | H22: 4 | I22: 単位 | M22: 履修必須の有無 | N22: 令和１０年度以降に履修必須とする計画、又は未定
A24: ④ 現在進行中の社会変化（第４次産業革命、Society 5.0、データ駆動型社会等）に深く寄与しているものであり、それが自らの生活と密接に結びついている」の内容を含む授業科目
B26: 授業科目 | G26: 単位数 | H26: 必須 | I26: 1-1 | J26: 1-6 | K26: 授業科目 | R26: 単位数 | S26: 必須 | T26: 1-1 | U26: 1-6
B27: AIの活用基礎 | G27: 2 | H27: ○ | I27: ○ | J27: ○
A35: ⑤ 「社会で活用されているデータ」や「データの活用領域」は非常に広範囲であって、日常生活や社会の課題を解決する有用なツールになり得るもの」の内容を含む授業科目
B37: 授業科目 | G37: 単位数 | H37: 必須 | I37: 1-2 | J37: 1-3 | K37: 授業科目 | R37: 単位数 | S37: 必須 | T37: 1-2 | U37: 1-3
B38: AIの活用基礎 | G38: 2 | H38: ○ | I38: ○ | J38: ○
A46: ⑥ 「様々なデータ利活用の現場におけるデータ利活用事例が示され、様々な適用領域（流通、製造、金融、サービス、インフラ、公共、ヘルスケア等）の知見と組み合わせることで価値を創出するもの」の内容を含む授業科目
B48: 授業科目 | G48: 単位数 | H48: 必須 | I48: 1-4 | J48: 1-5 | K48: 授業科目 | R48: 単位数 | S48: 必須 | T48: 1-4 | U48: 1-5
B49: AIの活用基礎 | G49: 2 | H49: ○ | I49: ○ | J49: ○
A57: ⑦ 「活用に当たっての様々な留意事項（ELSI、個人情報、データ倫理、ＡＩ社会原則等）を考慮し、情報セキュリティや情報漏洩等、データを守る上での留意事項への理解をする」の内容を含む授業科目
B59: 授業科目 | G59: 単位数 | H59: 必須 | I59: 3-1 | J59: 3-2 | K59: 授業科目 | R59: 単位数 | S59: 必須 | T59: 3-1 | U59: 3-2
B60: AIの活用基礎 | G60: 2 | H60: ○ | I60: ○ | J60: ○
A68: ⑧ 「実データ・実課題（学術データ等を含む）を用いた演習など、社会での実例を題材として、「データを読む、説明する、扱う」といった数理・データサイエンス・ＡＩの基本的な活用法に関するもの」の内容を含む授業科目
B70: 授業科目 | F70: 単位数 | G70: 必須 | H70: 2-1 | I70: 2-2 | J70: 2-3 | K70: 授業科目 | Q70: 単位数 | R70: 必須 | S70: 2-1 | T70: 2-2 | U70: 2-3
B71: ICTコミュニケーション入門 | F71: 2 | G71: ○ | H71: ○ | I71: ○ | J71: ○
A79: ⑨ 選択「４．オプション」の内容を含む授業科目
B80: 授業科目 | G80: 選択項目 | K80: 授業科目 | R80: 選択項目 | AA80: 4-1統計および数理基礎
AA81: 4‐2アルゴリズム基礎
AA82: 4‐3データ構造とプログラミング基礎
AA83: 4‐4時系列データ解析
AA84: 4‐5自然言語処理
AA85: 4‐6画像認識
AA86: 4‐7データハンドリング
AA87: 4‐8データ活用実践（教師あり学習）
AA88: 4‐9データ活用実践（教師なし学習）
A89: ⑩ プログラムを構成する授業の内容 | AA89: その他
B90: 授業に含まれている内容・要素 | D90: 講義内容
...

Sheet 様式１-2　プログラムを構成する授業科目(SGS)
T1: 様式１-２ | V1: 「学部・学科によって、修了要件は相違する」場合は、本シートを複製の上＜様式１－〇＞と枝番号を付してください
B2: 大学等名 | C2: 多摩大学
B3: プログラム名 | C3: 多摩大学 数理・データサイエンス・AI教育基礎プログラム
A5: リテラシーレベルのプログラムを構成する授業科目について
A7: ① 教育プログラムの修了要件 | L7: 学部・学科によって、修了要件は相違する
A9: ② 対象となる学部・学科名称
B11: グローバルスタディーズ学部
A14: ③ 修了要件
B15: プログラムを構成する科目すべて、下記２科目合計８単位を修得すること。 １．AI・ゲーム・デジタル産業、２．調査法入門：量的 | X15: 【プルダウンリスト】
X16: 令和６年度以前より、履修することが必須のプログラムとして実施
X17: 令和９年度までに履修必須とする計画
X18: 令和１０年度以降に履修必須とする計画、又は未定
B22: 必要最低科目数・単位数 | E22: 2 | F22: 科目 | H22: 8 | I22: 単位 | M22: 履修必須の有無 | N22: 令和１０年度以降に履修必須とする計画、又は未定
A24: ④ 現在進行中の社会変化（第４次産業革命、Society 5.0、データ駆動型社会等）に深く寄与しているものであり、それが自らの生活と密接に結びついている」の内容を含む授業科目
B26: 授業科目 | G26: 単位数 | H26: 必須 | I26: 1-1 | J26: 1-6 | K26: 授業科目 | R26: 単位数 | S26: 必須 | T26: 1-1 | U26: 1-6
B27: AI・ゲーム・デジタル産業 | G27: 4 | H27: ○ | I27: ○ | J27: ○
B28: 調査法入門：量的 | G28: 4 | H28: ○ | I28: ○
A35: ⑤ 「社会で活用されているデータ」や「データの活用領域」は非常に広範囲であって、日常生活や社会の課題を解決する有用なツールになり得るもの」の内容を含む授業科目
B37: 授業科目 | G37: 単位数 | H37: 必須 | I37: 1-2 | J37: 1-3 | K37: 授業科目 | R37: 単位数 | S37: 必須 | T37: 1-2 | U37: 1-3
B38: AI・ゲーム・デジタル産業 | G38: 4 | H38: ○ | I38: ○ | J38: ○
B39: 調査法入門：量的 | G39: 4 | H39: ○ | I39: ○ | J39: ○
A46: ⑥ 「様々なデータ利活用の現場におけるデータ利活用事例が示され、様々な適用領域（流通、製造、金融、サービス、インフラ、公共、ヘルスケア等）の知見と組み合わせることで価値を創出するもの」の内容を含む授業科目
B48: 授業科目 | G48: 単位数 | H48: 必須 | I48: 1-4 | J48: 1-5 | K48: 授業科目 | R48: 単位数 | S48: 必須 | T48: 1-4 | U48: 1-5
B49: AI・ゲーム・デジタル産業 | G49: 4 | H49: ○ | I49: ○ | J49: ○
A57: ⑦ 「活用に当たっての様々な留意事項（ELSI、個人情報、データ倫理、ＡＩ社会原則等）を考慮し、情報セキュリティや情報漏洩等、データを守る上での留意事項への理解をする」の内容を含む授業科目
B59: 授業科目 | G59: 単位数 | H59: 必須 | I59: 3-1 | J59: 3-2 | K59: 授業科目 | R59: 単位数 | S59: 必須 | T59: 3-1 | U59: 3-2
B60: AI・ゲーム・デジタル産業 | G60: 4 | H60: ○ | I60: ○ | J60: ○
A68: ⑧ 「実データ・実課題（学術データ等を含む）を用いた演習など、社会での実例を題材として、「データを読む、説明する、扱う」といった数理・データサイエンス・ＡＩの基本的な活用法に関するもの」の内容を含む授業科目
B70: 授業科目 | F70: 単位数 | G70: 必須 | H70: 2-1 | I70: 2-2 | J70: 2-3 | K70: 授業科目 | Q70: 単位数 | R70: 必須 | S70: 2-1 | T70: 2-2 | U70: 2-3
B71: 調査法入門：量的 | F71: 4 | G71: ○ | H71: ○ | I71: ○ | J71: ○
A79: ⑨ 選択「４．オプション」の内容を含む授業科目
B80: 授業科目 | G80: 選択項目 | K80: 授業科目 | R80: 選択項目 | AA80: 4-1統計および数理基礎
AA81: 4‐2アルゴリズム基礎
AA82: 4‐3データ構造とプログラミング基礎
AA83: 4‐4時系列データ解析
AA84: 4‐5自然言語処理
AA85: 4‐6画像認識
AA86: 4‐7データハンドリング
AA87: 4‐8データ活用実践（教師あり学習）
AA88: 4‐9データ活用実践（教師なし学習）
...

Sheet 様式２ 履修者等数の実績
S1: 様式２
Q2: ='様式１-2 プログラムを構成する授業科目(SGS)'!C2 -> 多摩大学
A3: リテラシーレベルのプログラムの履修者数等の実績について
A5: ①プログラム開設年度 | C5: 令和6 | E5: 年度（和暦）
A7: ②大学等全体の男女別学生数 | E7: 男性 | F7: 1445 | G7: 人 | H7: 女性 | I7: 474 | J7: 人 | K7: （ | L7: 合計 | M7: =F7+I7 -> 1919 | N7: 人 | O7: ）
B8: （令和６年５月１日時点）
A9: ③履修者・修了者の実績
B11: 学部・学科名称 | C11: 学生数 | D11: 入学 定員 | E11: 収容 定員 | F11: 令和6年度 | H11: 令和5年度 | J11: 令和4年度 | L11: 令和3年度 | N11: 令和2年度 | P11: 令和元年度 | R11: 履修者数 合計 | S11: 履修率
F12: 履修者数 | G12: 修了者数 | H12: 履修者数 | I12: 修了者数 | J12: 履修者数 | K12: 修了者数 | L12: 履修者数 | M12: 修了者数 | N12: 履修者数 | O12: 修了者数 | P12: 履修者数 | Q12: 修了者数
B13: 経営情報学部 | C13: 1324 | D13: 317 | E13: 1280 | F13: 188 | G13: 137 | R13: =F13+H13+J13+L13+N13+P13 -> 188 | S13: =R13/E13 -> 0.146875
B14: グローバルスタディーズ学部 | C14: 595 | D14: 147 | E14: 600 | F14: 1 | G14: 1 | R14: =F14+H14+J14+L14+N14+P14 -> 1 | S14: =R14/E14 -> 0.0016666667
R15: =F15+H15+J15+L15+N15+P15 -> 0 | S15: =R15/E15 -> #DIV/0!
R16: =F16+H16+J16+L16+N16+P16 -> 0 | S16: =R16/E16 -> #DIV/0!
R17: =F17+H17+J17+L17+N17+P17 -> 0 | S17: =R17/E17 -> #DIV/0!
R18: =F18+H18+J18+L18+N18+P18 -> 0 | S18: =R18/E18 -> #DIV/0!
R19: =F19+H19+J19+L19+N19+P19 -> 0 | S19: =R19/E19 -> #DIV/0!
R20: =F20+H20+J20+L20+N20+P20 -> 0 | S20: =R20/E20 -> #DIV/0!
R21: =F21+H21+J21+L21+N21+P21 -> 0 | S21: =R21/E21 -> #DIV/0!
R22: =F22+H22+J22+L22+N22+P22 -> 0 | S22: =R22/E22 -> #DIV/0!
R23: =F23+H23+J23+L23+N23+P23 -> 0 | S23: =R23/E23 -> #DIV/0!
R24: =F24+H24+J24+L24+N24+P24 -> 0 | S24: =R24/E24 -> #DIV/0!
R25: =F25+H25+J25+L25+N25+P25 -> 0 | S25: =R25/E25 -> #DIV/0!
R26: =F26+H26+J26+L26+N26+P26 -> 0 | S26: =R26/E26 -> #DIV/0!
... R31: =F31+H31+J31+L31+N31+P31 -> 0 | S31: =R31/E31 -> #DIV/0!
B33: 合 計 | C33: =SUM(C13:C32) -> 1919 | D33: =SUM(D13:D32) -> 464 | E33: =SUM(E13:E32) -> 1880 | F33: =SUM(F13:F32) -> 189 | G33: =SUM(G13:G32) -> 138 | H33: =SUM(H13:H32) -> 0 | I33: =SUM(I13:I32) -> 0 | J33: =SUM(J13:J32) -> 0 | ... R33: =SUM(R13:R32) -> 189 | S33: =R33/E33 -> 0.10053191

Sheet 様式３教育の質・履修者数を向上のための体制(SMIS・SGS)
I1: 様式３
G2: 大学等名 | H2: ='様式１-2 プログラムを構成する授業科目(SGS)'!C2 -> 多摩大学
A4: 教育の質・履修者数を向上させるための体制・計画について
A6: ① | B6: 全学の教員数 | C6: (常勤） | E6: 57 | F6: 人 | G6: （非常勤） | H6: 90 | I6: 人 | K6: 21 | M6: 45
A8: ② | B8: プログラムの授業を教えている教員数 | H8: 11 | I8: 人
A10: ③ | B10: プログラムの運営責任者
B11: （責任者名） | C11: 杉田 文章 | G11: （役職名） | H11: 教授(副学長)
A13: ④ | B13: プログラムを改善・進化させるための体制（委員会・組織等）
B14: 多摩大学教学マネジメント会議
B16: （責任者名） | C16: 杉田 文章 | G16: （役職名） | H16: 教授(副学長)
A18: ⑤ | B18: プログラムを改善・進化させるための体制を定める規則名称
B19: 多摩大学教学マネジメント会議規程
A21: ⑥ | B21: 体制の目的
B22: 当学では教学マネジメントに関わる方針の策定・検証・評価を行うことを目的とし、平成30年4月から組織され、現在に至るまで運営している。具体的には、教育プログラムの構築・改善・進化に関する事項等を審議する役割を担っている。なお、本プログラムについての改善・進化に伴う施策の策定は教務委員会が行い、自己点検・評価は教育・研究推進センター運営委員会にて実施する。各委員会の施策及び点検・評価の結果は、当該教学マネジメント会議に上程され、最終的な審議・決定を行うこととなっている。
A29: ⑦ | B29: 具体的な構成員
B30: 議長 副学長 教授 杉田 文章 委員 副学長 兼 グローバルスタディーズ学部長 教授 新美 潤 委員 経営情報学部長 教授 小林 英夫 委員 経営情報学研究科長 教授 河野 龍太 委員 教育・研究推進センター長 教授 小西 英行 委員 IR推進室係長 満岡 直之 委員 経営情報学科長 教授 出原 至道 委員 事業構想学科長 教授 下井 直毅 委員 グローバルスタディーズ学科長 教授 太田 哲 委員 経営情報学部教務委員長 教授 落合 孝彦 委員 グローバルスタディーズ学部教務委員長 准教授 田中 孝枝 委員 経営情報学研究科教務委員長 教授 川田 英樹 委員 多摩キャンパス教務課長 中澤 和臣 委員 湘南キャンパス教務課長 杉本 次郎太 委員 大学院事務課長 瀧川 浩人
Y33: 384 | AA33: 0.20425532
Y34: 576 | Z34: 30 | AA34: 0.32234043
Y35: 768 | Z35: 60 | AA35: 0.44042553
Y36: 1024 | Z36: 120 | AA36: 0.60851064
A43: ⑧ | B43: 履修者数・履修率の向上に向けた計画 ※様式１の「履修必須の有無」で「計画がある」としている場合は詳細について記載すること
B44: 令和６年度実績 | C44: ='様式２ 履修者等数の実績'!S33 -> 0.10053191 | E44: 令和７年度予定 | F44: 0.20426 | H44: 令和８年度予定 | I44: 0.32234
B45: 令和９年度予定 | C45: 0.44043 | E45: 令和１０年度予定 | F45: 0.60851 | H45: 収容定員（名） | I45: ='様式２ 履修者等数の実績'!E33 -> 1880
B46: 具体的な計画
B47: 【経営情報学部】 計画した履修者を実現させるため、以下の取り組みを実施する。 ・修了証の活用例等をホームページに掲載し、就職活動での利用価値をアピールすることで学生への認知度を高めることを検討する。 ・1～2年生を対象としたオリエンテーションの場を活用し、数理・AI・データサイエンスの重要性と当該プログラムのカリキュラムを案内することを通して、学生の履修意欲を促進させる。 ・本プログラムを構成する｢AIの活用基礎｣について、2025年度から開講を1クラス編成から2クラス編成に変更し、より多くの学生が履修できる機会を設ける。 ・本プログラム用の担当科目報告書を作成し、反省点や改善すべき点を洗い出した上で、履修率向上に向けた施策に反映させる。 【グローバルスタディーズ学部】 プログラムを構成する2つの授業において履修者は「AI・ゲームデジタル産業」が30名、「調査法入門：量的」が4名であった。オリエンテーション等を通して本授業の重要性を説明し履修者率向上を目指す。
A60: ⑨ | B60: 学部・学科に関係なく希望する学生全員が受講可能となるような必要な体制・取組等
B61: 【経営情報学部】 ・プログラムは学部ごとに科目を設置しており、経営情報学部では｢AIの活用基礎｣と｢ICTコミュニケーション入門｣が対象となる。また、グローバルスタディーズ学部では｢AI・ゲーム・デジタル産業｣と｢調査方法入門：量的｣を対象の科目としている。よって、学生が希望するれば受講できる体制が構築されている。また、学則の中で他学部科目の履修を認めることを定めている。 【グローバルスタディーズ学部】 グローバルスタディーズ学部では｢AI・ゲーム・デジタル産業｣と｢調査方法入門：量的｣を対象の科目としている。
A70: ⑩ | B70: できる限り多くの学生が履修できるような具体的な周知方法・取組
B71: 【経営情報学部】 ・多くの入学生に対し履修することを推奨するため、初年次教育の科目として位置づけている。 ・大学の公式サイトで情報公開し、修了要件等を公開している。 ・学内における複数の箇所にチラシを掲示することで、周知を図っている。 ・大学のキャンパスシステムであるT-NEXTを用いて、初回授業前に入学生宛に案内の連絡を行っている。 【グローバルスタディーズ学部】 ・大学の公式サイトで情報公開し、修了要件等を公開している。 ・学内における複数の箇所にチラシを掲示することで、周知を行っている。
A82: ⑪ | B82: できる限り多くの学生が履修・修得できるようなサポート体制
B83: 【経営情報学部】 ･本プログラムの受講にあたっては、エクセル等のOfficeソフトを利用することが必須となる。 当学では在籍中に学生からの申請を以って、Microsoft 365ライセンスを提供する体制が構築されている。 ・本プログラムを構成する｢ICTコミュニケーション入門｣では、授業内でExcel表計算処理技能認定試験を行うにあたり、受験申込のサポートを教務課窓口で行っている。 ・学生自身が保有するパソコンに異常が発生した場合等を想定し、メディアサービスの窓口にてノートパソコンや周辺機器の貸出を行っている。 ・GoogleClassroomの機能を用いて、講義資料のアーカイブや学修に役立つ参考資料の閲覧が可能となっている。 【グローバルスタディーズ学部】 ･学部・学科に関係なく学生全員が受講可能となる制度としている。単位修得に向けたサポートについては、教員・チューター・SAにより、授業内外における学修支援体制を整備している。
A97: ⑫ | B97: 授業時間内外で学習指導、質問を受け付ける具体的な仕組み
B98: 【経営情報学部】 ・オフィスアワー制度の採用により、授業科目の担当教員への直接質問等を受付ける時間を1週間の間で90分以上設定している。なお、本プログラムを構成する｢AI活用基礎｣と｢ICTコミュニケーション入門｣も当該オフィスアワー制度の適用対象となる。 ･総合的な学修支援として、学修サポート室を図書館内に設置している。 【グローバルスタディーズ学部】 本教育プログラムについての履修をT-NEXT（授業支援システム）にて管理し、学生とのコミュニケーションはメール等を通じて行っているため、学生は授業時間以外に不明点等確認できる体制となっている。

Sheet 様式４　自己点検・評価
I1: 様式４
H2: 大学等名 | I2: ='様式１-2 プログラムを構成する授業科目(SGS)'!C2 -> 多摩大学
A3: 自己点検・評価について
A5: ① | B5: プログラムの自己点検・評価を行う体制（委員会・組織等）
B6: 多摩大学教育・研究推進センター運営委員会
D8: （責任者名） | E8: 小西 英行 | G8: （役職名） | H8: 教育・研究推進センター長
A10: ② | B10: 自己点検・評価体制における意見等
B11: 自己点検・評価の視点 | E11: 自己点検・評価体制における意見・結果・改善に向けた取組等
B12: 学内からの視点
C13: プログラムの履修・修得状況 | E13: 【経営情報学部】 本プログラムは2024年度以降入学生を対象としていることから、1年生のみを対象とした場合、365名中188名が履修し、修了者数は137名という結果になった。これは1年生の半分以上が本プログラムを履修し、且つ、70％を超える履修者がリテラシーレベルを修了したこととなるため、良好な結果であると評価できる。 【グローバルスタディーズ学部】 グローバルスタディーズ学部の本プログラムを構成する2つの授業において履修者は「AI・ゲームデジタル産業」が30名、「調査法入門：量的」が4名であった。両科目を修了した者は1名なので、ガイダンス等で履修者数を上げる改善が必要である。
C14: 学修成果 | E14: 【経営情報学部】 ・本プログラムを構成する｢AIの活用基礎｣では、毎回の授業で課題提出を課しており、各回の講義における学生ごとの習熟度を確認する上で活用されている。 ・2024年度より本プログラムを構成する｢ICTコミュニケーション入門｣では、Excel表計算処理技能認定試験3級のCBT方式による試験を学内で実施することを通して、学修成果の測定を実施した。今後、デジタル教材の有効活用により、試験の合格率の向上にも努めていく予定である。 【グローバルスタディーズ学部】 ・「AI・ゲーム・デジタル産業」では、課題及び発表、復習テスト、期末テストを実施し、データサイエンス・AIへの理解と基礎的な能力を身につけることができている。 ・「調査法入門：量的」では、中間レポート及び期末レポートを実施し、量的データの集計方法の理解を深めている。
C15: 学生アンケート等を通じた学生の内容の理解度 | E15: 【経営情報学部】 学生による授業評価(VOICE)結果のうち、｢授業は有益(効果的)でしたか｣の項目について、プログラム構成科目の状況は以下のとおり4.00以上の高い評価数値となったことから、ある程度の理解度が身についたものと考えている。 ＜評価結果＞ ｢AIの活用基礎｣ ：4.00(5段階評価) ｢ICTコミュニケーション入門｣ ：4.38(5段階評価、※クラス平均値) 【グローバルスタディーズ学部】 ｢AI・ゲーム・デジタル産業｣ ：4.24(5段階評価) ｢調査法入門：量的｣ ：5(5段階評価)
C16: 学生アンケート等を通じた後輩等他の学生への推奨度 | E16: 【経営情報学部】 学生による授業評価(VOICE)結果のうち、｢授業は有益(効果的)でしたか｣の項目について、プログラム構成科目の状況は以下のとおり4.00以上の高い評価数値となったことから、履修済の学生が他の学生に推奨できる授業内容であったと評価できる。 ＜評価結果＞ ｢AIの活用基礎｣ ：4.00(5段階評価) ｢ICTコミュニケーション入門｣ ：4.38(5段階評価、※クラス平均値) 【グローバルスタディーズ学部】 ｢AI・ゲーム・デジタル産業｣ ：4.24(5段階評価) ｢調査法入門：量的｣ ：5(5段階評価)
C17: 全学的な履修者数、履修率向上に向けた計画の達成・進捗状況 | E17: 【経営情報学部】 項番1で示したとおり、2024年度の履修者数については良好な結果がえられている。 また、当該プログラムを構成する科目である｢AIの活用基礎｣を、2025年度より1クラスから2クラス編成に見直すことで、履修者の増加を図っていく。 【グローバルスタディーズ学部】 「AI・ゲームデジタル産業」が30名、「調査法入門：量的」が4名であることから、特に「調査法入門：量的」の履修者増に向けた取り組みを行う。
B18: 学外からの視点
C19: 教育プログラム修了者の進路、活躍状況、企業等の評価 | E19: 【経営情報学部】 本プログラムを修了した学生が企業等に就職するのは、令和10年以降となる。 なお、当学では、卒業生の就職先に対し、卒業後アンケートを毎年実施している。当該アンケートを用いて、今後、リテラシーレベルの修了者の状況の把握と分析を行っていく予定である。 【グローバルスタディーズ学部】 当該プログラムが開設されたのが、令和6(2024)年度であり、まだ卒業生はなく、今後の取り組みとなる。今後、卒業時には可能な範囲で進路等の評価を実践する予定である。卒業後の企業等に調査をし効果の検証を実施していく。
C20: 産業界からの視点を含めた教育プログラム内容・手法等への意見 | E20: 【経営情報学部】 2024年度は小田急不動産株式会社と多摩市にご協力頂き、アンケート及び情報交換会を実施した。今回は、DXの重要性に関する意見があり、具体的にはAIを活用できる人材の育成が求められていることについて情報共有した。今後、本プログラムに関しても、産業界からの具体的な意見を確認していきたい。
B21: 数理・データサイエンス・ＡＩを「学ぶ楽しさ」「学ぶことの意義」を理解させること | E21: 【経営情報学部】 学生による授業評価(VOICE)結果のうち、｢授業内容が興味深く触発されることが多い｣の項目について、プログラム構成科目の状況は概ね4.00に近い評価数値となったことから、概ね達成できたと考えている。 ＜評価結果＞ ｢AIの活用基礎｣ ：4.00(5段階評価) ｢ICTコミュニケーション入門｣ ：3.96(5段階評価、※クラス平均値) 【グローバルスタディーズ学部】 ｢AI・ゲーム・デジタル産業｣ ：4.10(5段階評価) ｢調査法入門：量的｣ ：5(5段階評価)
B22: 内容・水準を維持・向上しつつ、より「分かりやすい」授業とすること ※社会の変化や生成AI等の技術の発展を踏まえて教育内容を継続的に見直すなど、より教育効果の高まる授業内容・方法とするための取組や仕組みについても該当があれば記載 | E22: 学生による授業評価(VOICE)結果のうち、｢学生（院生）の理解水準を踏まえた説明をする｣の項目について、プログラム構成科目の状況は概ね4.00に近い評価数値となったことから、概ね達成できたと考えている。 ＜評価結果＞ ｢AIの活用基礎｣ ：3.91(5段階評価) ｢ICTコミュニケーション入門｣ ：4.07(5段階評価、※クラス平均値) また、担当科目報告書から、2025年度は以下の改善の取組みを検討中であることを確認した。 ＜改善取組検討内容＞ ｢AIの活用基礎｣ ：復習に効果的な動画教材を提供できるように準備する。 ｢ICTコミュニケーション入門｣ ：Windowsパソコンを前提とした授業であるため、Macパソコンの利用は不可 とする対応を徹底したい。 【グローバルスタディーズ学部】 ｢AI・ゲーム・デジタル産業｣ ：3.76(5段階評価) ｢調査法入門：量的｣ ：5(5段階評価) ＜改善取組検討内容＞ ｢AI・ゲーム・デジタル産業｣ ：アクティブ・ラーニング手法を用い、授業内容について学生が自ら調べ、考えたうえで、授業内で発表することにより、AI・データの利活用に対する理解をさらに深め、より高い教育効果を目指している。 「調査法入門：量的」 ：計量経済学の手法を学習する上で前提となる推測統計学に関する教材を準備し、講義における学習の入り口とする。
