Workbook

Sheet 様式１－１　プログラムを構成する授業科目
T1: 様式１－１ | V1: 「学部・学科によって、修了要件は相違する」場合は、本シートを複製の上＜様式１－〇＞と枝番号を付してください
B2: 大学等名 | C2: 摂南大学
B3: プログラム名 | C3: 摂南大学 数理・データサイエンス・AI教育プログラム（リテラシーレベル）
A5: リテラシーレベルのプログラムを構成する授業科目について
A7: ① 教育プログラムの修了要件 | L7: 学部・学科によって、修了要件は相違する
A9: ② 対象となる学部・学科名称
B11: 理工学部
A14: ③ 修了要件
B15: 生命科学科：「生命科学・統計情報処理」の２単位を取得すること。 建築学科：「情報メディアデザイン」の２単位を取得すること。 住環境デザイン学科、都市環境工学科、機械工学科、電気電子工学科：「統計情報処理」の１単位を取得すること。 | X15: 【プルダウンリスト】
X16: 令和６年度以前より、履修することが必須のプログラムとして実施
X17: 令和９年度までに履修必須とする計画
X18: 令和１０年度以降に履修必須とする計画、又は未定
B22: 必要最低科目数・単位数 | E22: 1 | F22: 科目 | H22: 1 | I22: 単位 | M22: 履修必須の有無 | N22: 令和１０年度以降に履修必須とする計画、又は未定
A24: ④ 現在進行中の社会変化（第４次産業革命、Society 5.0、データ駆動型社会等）に深く寄与しているものであり、それが自らの生活と密接に結びついている」の内容を含む授業科目
B26: 授業科目 | G26: 単位数 | H26: 必須 | I26: 1-1 | J26: 1-6 | K26: 授業科目 | R26: 単位数 | S26: 必須 | T26: 1-1 | U26: 1-6
B27: 生命科学・統計情報処理 | G27: 2 | H27: ○ | I27: ○ | J27: ○
B28: 情報メディアデザイン | G28: 2 | H28: ○ | I28: ○ | J28: ○
B29: 統計情報処理 | G29: 1 | H29: ○ | I29: ○ | J29: ○
A35: ⑤ 「社会で活用されているデータ」や「データの活用領域」は非常に広範囲であって、日常生活や社会の課題を解決する有用なツールになり得るもの」の内容を含む授業科目
B37: 授業科目 | G37: 単位数 | H37: 必須 | I37: 1-2 | J37: 1-3 | K37: 授業科目 | R37: 単位数 | S37: 必須 | T37: 1-2 | U37: 1-3
B38: 生命科学・統計情報処理 | G38: 2 | H38: ○ | I38: ○ | J38: ○
B39: 情報メディアデザイン | G39: 2 | H39: ○ | I39: ○ | J39: ○
B40: 統計情報処理 | G40: 1 | H40: ○ | I40: ○ | J40: ○
A46: ⑥ 「様々なデータ利活用の現場におけるデータ利活用事例が示され、様々な適用領域（流通、製造、金融、サービス、インフラ、公共、ヘルスケア等）の知見と組み合わせることで価値を創出するもの」の内容を含む授業科目
B48: 授業科目 | G48: 単位数 | H48: 必須 | I48: 1-4 | J48: 1-5 | K48: 授業科目 | R48: 単位数 | S48: 必須 | T48: 1-4 | U48: 1-5
B49: 生命科学・統計情報処理 | G49: 2 | H49: ○ | I49: ○ | J49: ○
B50: 情報メディアデザイン | G50: 2 | H50: ○ | I50: ○ | J50: ○
B51: 統計情報処理 | G51: 1 | H51: ○ | I51: ○ | J51: ○
A57: ⑦ 「活用に当たっての様々な留意事項（ELSI、個人情報、データ倫理、ＡＩ社会原則等）を考慮し、情報セキュリティや情報漏洩等、データを守る上での留意事項への理解をする」の内容を含む授業科目
B59: 授業科目 | G59: 単位数 | H59: 必須 | I59: 3-1 | J59: 3-2 | K59: 授業科目 | R59: 単位数 | S59: 必須 | T59: 3-1 | U59: 3-2
B60: 生命科学・統計情報処理 | G60: 2 | H60: ○ | I60: ○ | J60: ○
B61: 情報メディアデザイン | G61: 2 | H61: ○ | I61: ○ | J61: ○
B62: 統計情報処理 | G62: 1 | H62: ○ | I62: ○ | J62: ○
A68: ⑧ 「実データ・実課題（学術データ等を含む）を用いた演習など、社会での実例を題材として、「データを読む、説明する、扱う」といった数理・データサイエンス・ＡＩの基本的な活用法に関するもの」の内容を含む授業科目
B70: 授業科目 | F70: 単位数 | G70: 必須 | H70: 2-1 | I70: 2-2 | J70: 2-3 | K70: 授業科目 | Q70: 単位数 | R70: 必須 | S70: 2-1 | T70: 2-2 | U70: 2-3
B71: 生命科学・統計情報処理 | F71: 2 | G71: ○ | H71: ○ | I71: ○ | J71: ○
B72: 情報メディアデザイン | F72: 2 | G72: ○ | H72: ○ | I72: ○ | J72: ○
B73: 統計情報処理 | F73: 1 | G73: ○ | H73: ○ | I73: ○ | J73: ○
A79: ⑨ 選択「４．オプション」の内容を含む授業科目
B80: 授業科目 | G80: 選択項目 | K80: 授業科目 | R80: 選択項目 | AA80: 4-1統計および数理基礎
...

Sheet 様式１－２　プログラムを構成する授業科目
T1: 様式１－２ | V1: 「学部・学科によって、修了要件は相違する」場合は、本シートを複製の上＜様式１－〇＞と枝番号を付してください
B2: 大学等名 | C2: 摂南大学
B3: プログラム名 | C3: 摂南大学 数理・データサイエンス・AI教育プログラム（リテラシーレベル）
A5: リテラシーレベルのプログラムを構成する授業科目について
A7: ① 教育プログラムの修了要件 | L7: 学部・学科によって、修了要件は相違する
A9: ② 対象となる学部・学科名称
B11: 国際学部、農学部、経済学部
A14: ③ 修了要件
B15: 「情報リテラシーⅡ」の１単位を取得すること。 | X15: 【プルダウンリスト】
X16: 令和６年度以前より、履修することが必須のプログラムとして実施
X17: 令和９年度までに履修必須とする計画
X18: 令和１０年度以降に履修必須とする計画、又は未定
B22: 必要最低科目数・単位数 | E22: 1 | F22: 科目 | H22: 1 | I22: 単位 | M22: 履修必須の有無 | N22: 令和１０年度以降に履修必須とする計画、又は未定
A24: ④ 現在進行中の社会変化（第４次産業革命、Society 5.0、データ駆動型社会等）に深く寄与しているものであり、それが自らの生活と密接に結びついている」の内容を含む授業科目
B26: 授業科目 | G26: 単位数 | H26: 必須 | I26: 1-1 | J26: 1-6 | K26: 授業科目 | R26: 単位数 | S26: 必須 | T26: 1-1 | U26: 1-6
B27: 情報リテラシーⅡ | G27: 1 | H27: ○ | I27: ○ | J27: ○
A35: ⑤ 「社会で活用されているデータ」や「データの活用領域」は非常に広範囲であって、日常生活や社会の課題を解決する有用なツールになり得るもの」の内容を含む授業科目
B37: 授業科目 | G37: 単位数 | H37: 必須 | I37: 1-2 | J37: 1-3 | K37: 授業科目 | R37: 単位数 | S37: 必須 | T37: 1-2 | U37: 1-3
B38: 情報リテラシーⅡ | G38: 1 | H38: ○ | I38: ○ | J38: ○
A46: ⑥ 「様々なデータ利活用の現場におけるデータ利活用事例が示され、様々な適用領域（流通、製造、金融、サービス、インフラ、公共、ヘルスケア等）の知見と組み合わせることで価値を創出するもの」の内容を含む授業科目
B48: 授業科目 | G48: 単位数 | H48: 必須 | I48: 1-4 | J48: 1-5 | K48: 授業科目 | R48: 単位数 | S48: 必須 | T48: 1-4 | U48: 1-5
B49: 情報リテラシーⅡ | G49: 1 | H49: ○ | I49: ○ | J49: ○
A57: ⑦ 「活用に当たっての様々な留意事項（ELSI、個人情報、データ倫理、ＡＩ社会原則等）を考慮し、情報セキュリティや情報漏洩等、データを守る上での留意事項への理解をする」の内容を含む授業科目
B59: 授業科目 | G59: 単位数 | H59: 必須 | I59: 3-1 | J59: 3-2 | K59: 授業科目 | R59: 単位数 | S59: 必須 | T59: 3-1 | U59: 3-2
B60: 情報リテラシーⅡ | G60: 1 | H60: ○ | I60: ○ | J60: ○
A68: ⑧ 「実データ・実課題（学術データ等を含む）を用いた演習など、社会での実例を題材として、「データを読む、説明する、扱う」といった数理・データサイエンス・ＡＩの基本的な活用法に関するもの」の内容を含む授業科目
B70: 授業科目 | F70: 単位数 | G70: 必須 | H70: 2-1 | I70: 2-2 | J70: 2-3 | K70: 授業科目 | Q70: 単位数 | R70: 必須 | S70: 2-1 | T70: 2-2 | U70: 2-3
B71: 情報リテラシーⅡ | F71: 1 | G71: ○ | H71: ○ | I71: ○ | J71: ○
A79: ⑨ 選択「４．オプション」の内容を含む授業科目
B80: 授業科目 | G80: 選択項目 | K80: 授業科目 | R80: 選択項目 | AA80: 4-1統計および数理基礎
AA81: 4‐2アルゴリズム基礎
AA82: 4‐3データ構造とプログラミング基礎
AA83: 4‐4時系列データ解析
AA84: 4‐5自然言語処理
AA85: 4‐6画像認識
AA86: 4‐7データハンドリング
AA87: 4‐8データ活用実践（教師あり学習）
AA88: 4‐9データ活用実践（教師なし学習）
A89: ⑩ プログラムを構成する授業の内容 | AA89: その他
B90: 授業に含まれている内容・要素 | D90: 講義内容
...

Sheet 様式１－３　プログラムを構成する授業科目
T1: 様式１－３ | V1: 「学部・学科によって、修了要件は相違する」場合は、本シートを複製の上＜様式１－〇＞と枝番号を付してください
B2: 大学等名 | C2: 摂南大学
B3: プログラム名 | C3: 摂南大学 数理・データサイエンス・AI教育プログラム（リテラシーレベル）
A5: リテラシーレベルのプログラムを構成する授業科目について
A7: ① 教育プログラムの修了要件 | L7: 学部・学科によって、修了要件は相違する
A9: ② 対象となる学部・学科名称
B11: 経営学部
A14: ③ 修了要件
B15: 「ICTビジネス入門」「ビジネス情報処理Ⅰ」「ビジネス情報処理Ⅱ」「情報倫理」の４科目計８単位を取得すること。 | X15: 【プルダウンリスト】
X16: 令和６年度以前より、履修することが必須のプログラムとして実施
X17: 令和９年度までに履修必須とする計画
X18: 令和１０年度以降に履修必須とする計画、又は未定
B22: 必要最低科目数・単位数 | E22: 4 | F22: 科目 | H22: 8 | I22: 単位 | M22: 履修必須の有無 | N22: 令和１０年度以降に履修必須とする計画、又は未定
A24: ④ 現在進行中の社会変化（第４次産業革命、Society 5.0、データ駆動型社会等）に深く寄与しているものであり、それが自らの生活と密接に結びついている」の内容を含む授業科目
B26: 授業科目 | G26: 単位数 | H26: 必須 | I26: 1-1 | J26: 1-6 | K26: 授業科目 | R26: 単位数 | S26: 必須 | T26: 1-1 | U26: 1-6
B27: ICTビジネス入門 | G27: 2 | H27: ○ | I27: ○ | J27: ○
A35: ⑤ 「社会で活用されているデータ」や「データの活用領域」は非常に広範囲であって、日常生活や社会の課題を解決する有用なツールになり得るもの」の内容を含む授業科目
B37: 授業科目 | G37: 単位数 | H37: 必須 | I37: 1-2 | J37: 1-3 | K37: 授業科目 | R37: 単位数 | S37: 必須 | T37: 1-2 | U37: 1-3
B38: ICTビジネス入門 | G38: 2 | H38: ○ | I38: ○ | J38: ○
B39: ビジネス情報処理Ⅱ | G39: 2 | H39: ○ | I39: ○
A46: ⑥ 「様々なデータ利活用の現場におけるデータ利活用事例が示され、様々な適用領域（流通、製造、金融、サービス、インフラ、公共、ヘルスケア等）の知見と組み合わせることで価値を創出するもの」の内容を含む授業科目
B48: 授業科目 | G48: 単位数 | H48: 必須 | I48: 1-4 | J48: 1-5 | K48: 授業科目 | R48: 単位数 | S48: 必須 | T48: 1-4 | U48: 1-5
B49: ICTビジネス入門 | G49: 2 | H49: ○ | I49: ○ | J49: ○
A57: ⑦ 「活用に当たっての様々な留意事項（ELSI、個人情報、データ倫理、ＡＩ社会原則等）を考慮し、情報セキュリティや情報漏洩等、データを守る上での留意事項への理解をする」の内容を含む授業科目
B59: 授業科目 | G59: 単位数 | H59: 必須 | I59: 3-1 | J59: 3-2 | K59: 授業科目 | R59: 単位数 | S59: 必須 | T59: 3-1 | U59: 3-2
B60: 情報倫理 | G60: 2 | H60: ○ | I60: ○ | J60: ○
B61: ビジネス情報処理Ⅰ | G61: 2 | H61: ○ | J61: ○
A68: ⑧ 「実データ・実課題（学術データ等を含む）を用いた演習など、社会での実例を題材として、「データを読む、説明する、扱う」といった数理・データサイエンス・ＡＩの基本的な活用法に関するもの」の内容を含む授業科目
B70: 授業科目 | F70: 単位数 | G70: 必須 | H70: 2-1 | I70: 2-2 | J70: 2-3 | K70: 授業科目 | Q70: 単位数 | R70: 必須 | S70: 2-1 | T70: 2-2 | U70: 2-3
B71: ICTビジネス入門 | F71: 2 | G71: ○ | H71: ○
B72: ビジネス情報処理Ⅰ | F72: 2 | G72: ○ | I72: ○ | J72: ○
B73: ビジネス情報処理Ⅱ | F73: 2 | G73: ○ | H73: ○ | J73: ○
A79: ⑨ 選択「４．オプション」の内容を含む授業科目
B80: 授業科目 | G80: 選択項目 | K80: 授業科目 | R80: 選択項目 | AA80: 4-1統計および数理基礎
AA81: 4‐2アルゴリズム基礎
AA82: 4‐3データ構造とプログラミング基礎
AA83: 4‐4時系列データ解析
AA84: 4‐5自然言語処理
AA85: 4‐6画像認識
AA86: 4‐7データハンドリング
...

Sheet 様式１－４　プログラムを構成する授業科目
T1: 様式１－４ | V1: 「学部・学科によって、修了要件は相違する」場合は、本シートを複製の上＜様式１－〇＞と枝番号を付してください
B2: 大学等名 | C2: 摂南大学
B3: プログラム名 | C3: 摂南大学 数理・データサイエンス・AI教育プログラム（リテラシーレベル）
A5: リテラシーレベルのプログラムを構成する授業科目について
A7: ① 教育プログラムの修了要件 | L7: 学部・学科によって、修了要件は相違する
A9: ② 対象となる学部・学科名称
B11: 看護学部
A14: ③ 修了要件
B15: 「情報リテラシーⅠ」の１単位を取得すること。 | X15: 【プルダウンリスト】
X16: 令和６年度以前より、履修することが必須のプログラムとして実施
X17: 令和９年度までに履修必須とする計画
X18: 令和１０年度以降に履修必須とする計画、又は未定
B22: 必要最低科目数・単位数 | E22: 1 | F22: 科目 | H22: 1 | I22: 単位 | M22: 履修必須の有無 | N22: 令和６年度以前より、履修することが必須のプログラムとして実施
A24: ④ 現在進行中の社会変化（第４次産業革命、Society 5.0、データ駆動型社会等）に深く寄与しているものであり、それが自らの生活と密接に結びついている」の内容を含む授業科目
B26: 授業科目 | G26: 単位数 | H26: 必須 | I26: 1-1 | J26: 1-6 | K26: 授業科目 | R26: 単位数 | S26: 必須 | T26: 1-1 | U26: 1-6
B27: 情報リテラシーⅠ | G27: 1 | H27: ○ | I27: ○ | J27: ○
A35: ⑤ 「社会で活用されているデータ」や「データの活用領域」は非常に広範囲であって、日常生活や社会の課題を解決する有用なツールになり得るもの」の内容を含む授業科目
B37: 授業科目 | G37: 単位数 | H37: 必須 | I37: 1-2 | J37: 1-3 | K37: 授業科目 | R37: 単位数 | S37: 必須 | T37: 1-2 | U37: 1-3
B38: 情報リテラシーⅠ | G38: 1 | H38: ○ | I38: ○ | J38: ○
A46: ⑥ 「様々なデータ利活用の現場におけるデータ利活用事例が示され、様々な適用領域（流通、製造、金融、サービス、インフラ、公共、ヘルスケア等）の知見と組み合わせることで価値を創出するもの」の内容を含む授業科目
B48: 授業科目 | G48: 単位数 | H48: 必須 | I48: 1-4 | J48: 1-5 | K48: 授業科目 | R48: 単位数 | S48: 必須 | T48: 1-4 | U48: 1-5
B49: 情報リテラシーⅠ | G49: 1 | H49: ○ | I49: ○ | J49: ○
A57: ⑦ 「活用に当たっての様々な留意事項（ELSI、個人情報、データ倫理、ＡＩ社会原則等）を考慮し、情報セキュリティや情報漏洩等、データを守る上での留意事項への理解をする」の内容を含む授業科目
B59: 授業科目 | G59: 単位数 | H59: 必須 | I59: 3-1 | J59: 3-2 | K59: 授業科目 | R59: 単位数 | S59: 必須 | T59: 3-1 | U59: 3-2
B60: 情報リテラシーⅠ | G60: 1 | H60: ○ | I60: ○ | J60: ○
A68: ⑧ 「実データ・実課題（学術データ等を含む）を用いた演習など、社会での実例を題材として、「データを読む、説明する、扱う」といった数理・データサイエンス・ＡＩの基本的な活用法に関するもの」の内容を含む授業科目
B70: 授業科目 | F70: 単位数 | G70: 必須 | H70: 2-1 | I70: 2-2 | J70: 2-3 | K70: 授業科目 | Q70: 単位数 | R70: 必須 | S70: 2-1 | T70: 2-2 | U70: 2-3
B71: 情報リテラシーⅠ | F71: 1 | G71: ○ | H71: ○ | I71: ○ | J71: ○
A79: ⑨ 選択「４．オプション」の内容を含む授業科目
B80: 授業科目 | G80: 選択項目 | K80: 授業科目 | R80: 選択項目 | AA80: 4-1統計および数理基礎
AA81: 4‐2アルゴリズム基礎
AA82: 4‐3データ構造とプログラミング基礎
AA83: 4‐4時系列データ解析
AA84: 4‐5自然言語処理
AA85: 4‐6画像認識
AA86: 4‐7データハンドリング
AA87: 4‐8データ活用実践（教師あり学習）
AA88: 4‐9データ活用実践（教師なし学習）
A89: ⑩ プログラムを構成する授業の内容 | AA89: その他
B90: 授業に含まれている内容・要素 | D90: 講義内容
...

Sheet 様式１－５　プログラムを構成する授業科目
T1: 様式１－５ | V1: 「学部・学科によって、修了要件は相違する」場合は、本シートを複製の上＜様式１－〇＞と枝番号を付してください
B2: 大学等名 | C2: 摂南大学
B3: プログラム名 | C3: 摂南大学 数理・データサイエンス・AI教育プログラム（リテラシーレベル）
A5: リテラシーレベルのプログラムを構成する授業科目について
A7: ① 教育プログラムの修了要件 | L7: 学部・学科によって、修了要件は相違する
A9: ② 対象となる学部・学科名称
B11: 現代社会学部、法学部、薬学部
A14: ③ 修了要件
B15: 「データサイエンス基礎」の１単位を取得すること． | X15: 【プルダウンリスト】
X16: 令和６年度以前より、履修することが必須のプログラムとして実施
X17: 令和９年度までに履修必須とする計画
X18: 令和１０年度以降に履修必須とする計画、又は未定
B22: 必要最低科目数・単位数 | E22: 1 | F22: 科目 | H22: 1 | I22: 単位 | M22: 履修必須の有無 | N22: 令和１０年度以降に履修必須とする計画、又は未定
A24: ④ 現在進行中の社会変化（第４次産業革命、Society 5.0、データ駆動型社会等）に深く寄与しているものであり、それが自らの生活と密接に結びついている」の内容を含む授業科目
B26: 授業科目 | G26: 単位数 | H26: 必須 | I26: 1-1 | J26: 1-6 | K26: 授業科目 | R26: 単位数 | S26: 必須 | T26: 1-1 | U26: 1-6
B27: データサイエンス基礎 | G27: 1 | H27: ○ | I27: ○ | J27: ○
A35: ⑤ 「社会で活用されているデータ」や「データの活用領域」は非常に広範囲であって、日常生活や社会の課題を解決する有用なツールになり得るもの」の内容を含む授業科目
B37: 授業科目 | G37: 単位数 | H37: 必須 | I37: 1-2 | J37: 1-3 | K37: 授業科目 | R37: 単位数 | S37: 必須 | T37: 1-2 | U37: 1-3
B38: データサイエンス基礎 | G38: 1 | H38: ○ | I38: ○ | J38: ○
A46: ⑥ 「様々なデータ利活用の現場におけるデータ利活用事例が示され、様々な適用領域（流通、製造、金融、サービス、インフラ、公共、ヘルスケア等）の知見と組み合わせることで価値を創出するもの」の内容を含む授業科目
B48: 授業科目 | G48: 単位数 | H48: 必須 | I48: 1-4 | J48: 1-5 | K48: 授業科目 | R48: 単位数 | S48: 必須 | T48: 1-4 | U48: 1-5
B49: データサイエンス基礎 | G49: 1 | H49: ○ | I49: ○ | J49: ○
A57: ⑦ 「活用に当たっての様々な留意事項（ELSI、個人情報、データ倫理、ＡＩ社会原則等）を考慮し、情報セキュリティや情報漏洩等、データを守る上での留意事項への理解をする」の内容を含む授業科目
B59: 授業科目 | G59: 単位数 | H59: 必須 | I59: 3-1 | J59: 3-2 | K59: 授業科目 | R59: 単位数 | S59: 必須 | T59: 3-1 | U59: 3-2
B60: データサイエンス基礎 | G60: 1 | H60: ○ | I60: ○ | J60: ○
A68: ⑧ 「実データ・実課題（学術データ等を含む）を用いた演習など、社会での実例を題材として、「データを読む、説明する、扱う」といった数理・データサイエンス・ＡＩの基本的な活用法に関するもの」の内容を含む授業科目
B70: 授業科目 | F70: 単位数 | G70: 必須 | H70: 2-1 | I70: 2-2 | J70: 2-3 | K70: 授業科目 | Q70: 単位数 | R70: 必須 | S70: 2-1 | T70: 2-2 | U70: 2-3
B71: データサイエンス基礎 | F71: 1 | G71: ○ | H71: ○ | I71: ○ | J71: ○
A79: ⑨ 選択「４．オプション」の内容を含む授業科目
B80: 授業科目 | G80: 選択項目 | K80: 授業科目 | R80: 選択項目 | AA80: 4-1統計および数理基礎
AA81: 4‐2アルゴリズム基礎
AA82: 4‐3データ構造とプログラミング基礎
AA83: 4‐4時系列データ解析
AA84: 4‐5自然言語処理
AA85: 4‐6画像認識
AA86: 4‐7データハンドリング
AA87: 4‐8データ活用実践（教師あり学習）
AA88: 4‐9データ活用実践（教師なし学習）
A89: ⑩ プログラムを構成する授業の内容 | AA89: その他
B90: 授業に含まれている内容・要素 | D90: 講義内容
...

Sheet 様式２ 履修者等数の実績
S1: 様式２
Q2: ='様式１－１ プログラムを構成する授業科目'!C2 -> 摂南大学
A3: リテラシーレベルのプログラムの履修者数等の実績について
A5: ①プログラム開設年度 | C5: 令和６ | E5: 年度（和暦）
A7: ②大学等全体の男女別学生数 | E7: 男性 | F7: 6802 | G7: 人 | H7: 女性 | I7: 3424 | J7: 人 | K7: （ | L7: 合計 | M7: =F7+I7 -> 10226 | N7: 人 | O7: ）
B8: （令和６年５月１日時点）
A9: ③履修者・修了者の実績
B11: 学部・学科名称 | C11: 学生数 | D11: 入学 定員 | E11: 収容 定員 | F11: 令和6年度 | H11: 令和5年度 | J11: 令和4年度 | L11: 令和3年度 | N11: 令和2年度 | P11: 令和元年度 | R11: 履修者数 合計 | S11: 履修率
F12: 履修者数 | G12: 修了者数 | H12: 履修者数 | I12: 修了者数 | J12: 履修者数 | K12: 修了者数 | L12: 履修者数 | M12: 修了者数 | N12: 履修者数 | O12: 修了者数 | P12: 履修者数 | Q12: 修了者数
B13: 理工学部 | C13: 2266 | D13: 585 | E13: 2400 | F13: 362 | G13: 320 | R13: =F13+H13+J13+L13+N13+P13 -> 362 | S13: =R13/E13 -> 0.15083333
B14: 外国語学部（募集停止） | C14: 204 | D14: - | E14: 225 | F14: 0 | G14: 0 | R14: =F14+H14+J14+L14+N14+P14 -> 0 | S14: =R14/E14 -> 0
B15: 国際学部 | C15: 730 | D15: 250 | E15: 755 | F15: 243 | G15: 222 | R15: =F15+H15+J15+L15+N15+P15 -> 243 | S15: =R15/E15 -> 0.3218543
B16: 経営学部 | C16: 1189 | D16: 280 | E16: 1124 | F16: 269 | G16: 0 | R16: =F16+H16+J16+L16+N16+P16 -> 269 | S16: =R16/E16 -> 0.23932384
B17: 薬学部 | C17: 1305 | D17: 220 | E17: 1320 | F17: 212 | G17: 201 | R17: =F17+H17+J17+L17+N17+P17 -> 212 | S17: =R17/E17 -> 0.16060606
B18: 法学部 | C18: 1152 | D18: 280 | E18: 1130 | F18: 167 | G18: 118 | R18: =F18+H18+J18+L18+N18+P18 -> 167 | S18: =R18/E18 -> 0.14778761
B19: 経済学部 | C19: 1159 | D19: 280 | E19: 1128 | F19: 272 | G19: 237 | R19: =F19+H19+J19+L19+N19+P19 -> 272 | S19: =R19/E19 -> 0.24113475
B20: 看護学部 | C20: 408 | D20: 100 | E20: 400 | F20: 92 | G20: 92 | R20: =F20+H20+J20+L20+N20+P20 -> 92 | S20: =R20/E20 -> 0.23
B21: 農学部 | C21: 1301 | D21: 340 | E21: 1360 | F21: 184 | G21: 177 | R21: =F21+H21+J21+L21+N21+P21 -> 184 | S21: =R21/E21 -> 0.13529412
B22: 現代社会学部 | C22: 512 | D22: 250 | E22: 500 | F22: 224 | G22: 198 | R22: =F22+H22+J22+L22+N22+P22 -> 224 | S22: =R22/E22 -> 0.448
B33: 合 計 | C33: =SUM(C13:C32) -> 10226 | D33: =SUM(D13:D32) -> 2585 | E33: =SUM(E13:E32) -> 10342 | F33: =SUM(F13:F32) -> 2025 | G33: =SUM(G13:G32) -> 1565 | H33: =SUM(H13:H32) -> 0 | I33: =SUM(I13:I32) -> 0 | J33: =SUM(J13:J32) -> 0 | ... R33: =SUM(R13:R32) -> 2025 | S33: =R33/E33 -> 0.19580352

Sheet 様式３ 教育の質・履修者数を向上させるための体制・計画
I1: 様式３
G2: 大学等名 | H2: ='様式１－１ プログラムを構成する授業科目'!C2 -> 摂南大学
A4: 教育の質・履修者数を向上させるための体制・計画について
A6: ① | B6: 全学の教員数 | C6: (常勤） | E6: 396 | F6: 人 | G6: （非常勤） | H6: 531 | I6: 人
A8: ② | B8: プログラムの授業を教えている教員数 | H8: 16 | I8: 人
A10: ③ | B10: プログラムの運営責任者
B11: （責任者名） | C11: 諏訪晴彦 | G11: （役職名） | H11: 全学教育機構長
A13: ④ | B13: プログラムを改善・進化させるための体制（委員会・組織等）
B14: 摂南大学 教育推進会議
B16: （責任者名） | C16: 諏訪晴彦 | G16: （役職名） | H16: 全学教育機構長
A18: ⑤ | B18: プログラムを改善・進化させるための体制を定める規則名称
B19: 摂南大学教育推進会議規定
A21: ⑥ | B21: 体制の目的
B22: 教育推進会議は、教育推進戦略に関する基本方針や、全学共通教養教育に関する事等の審議を行う組織である。教育推進会議では、文理問わず、全学部の学生が数理・データサイエンス・AIへの関心を高め、かつ、数理・データサイエンス・AIを適切に理解し、各専門分野でそれらを使いこなすことができる基礎的な力の育成を目的とした本プログラムの内容や全学的な普及状況を確認し、必要に応じてプログラムの改善・進化を検討する。そして、教育推進会議規定に基づく委員会として、教育推進会議の下に本プログラムの日常的な運営および改善に資する取り組み行う数理・データサイエンス・AI教育プログラム委員会を設置している。
A34: ⑦ | B34: 具体的な構成員
B35: 【教育推進会議構成員】 全学教育機構長 諏訪 晴彦 グローバル教育センター長 西川 眞由美 全学教育機構課長 山田 敬 全学教育機構課長 中村 智大 理工学部長 池内 淳子 国際学部長 鳥居 祐介 経営学部長 岩坪 加紋 薬学部長 佐久間 信至 法学部長 河原 匡見 経済学部長 柳川 隆 看護学部長 鎌田 佳奈美 農学部長 椎名 隆 現代社会学部長 浅野 慎一 【数理・データサイエンス・AI教育プログラム委員会】 経済学部教授 小塚 匡文（委員長） 理工学部講師 久保田 誠也 全学教育機構講師 新居 英志
A48: ⑧ | B48: 履修者数・履修率の向上に向けた計画 ※様式１の「履修必須の有無」で「計画がある」としている場合は詳細について記載すること
B49: 令和６年度実績 | C49: ='様式２ 履修者等数の実績'!S33 -> 0.19580352 | E49: 令和７年度予定 | F49: 0.4 | H49: 令和８年度予定 | I49: 0.6
B50: 令和９年度予定 | C50: 0.8 | E50: 令和１０年度予定 | F50: 0.85 | H50: 収容定員（名） | I50: ='様式２ 履修者等数の実績'!E33 -> 10342
B51: 具体的な計画
B52: 学部によって必修科目としており、年次進行に伴い該当学部の履修者数は増加していく予定である。このほか、大学全体の動きとして現在、全学教養教育科目の見直しを予定している。新しい全学教養教育では、初年次教育科目に数理・データサイエンス・AI教育プログラムのリテラシーレベルを学ぶ「データサイエンス基礎」を必修科目として開講することとしている。この全学教養教育科目は、2027年度より随時、学部のカリキュラム改正のタイミングなどに応じた導入を予定しており、最終的には全学必修科目としての「データサイエンス基礎」の開講を目指している。
A65: ⑨ | B65: 学部・学科に関係なく希望する学生全員が受講可能となるような必要な体制・取組等
B66: 各学部において、 既存の授業科目として開講しており、必修科目として開講している学部では全員が受講できるほか、それ以外の学部においても希望する学生が受講可能である。
A79: ⑩ | B79: できる限り多くの学生が履修できるような具体的な周知方法・取組
B80: 本教育プログラムの科目の大半は１年次配当科目としている。また、学部によっては必修科目としている。必修科目としていない学部の中でも、履修が望ましい科目と位置付け、必履修科目として事前に履修登録を行い、多くの学生が履修できるような取り組みを行っている。
A93: ⑪ | B93: できる限り多くの学生が履修・修得できるようなサポート体制
B94: PCを常設した自習室を設置しており、開室時間内であれば自由にＰＣを使用し学修できる環境を整備している。一部の学部で開講している「データサイエンス基礎」は完全オンデマンド授業として開講している。オンデマンド授業の利点を生かし、学生個人の学修ペースに合わせて任意に振り返り学修を行うことができるように教材提供を行っている。
A107: ⑫ | B107: 授業時間内外で学習指導、質問を受け付ける具体的な仕組み
B108: 授業内での質疑応答を受け付けるとともに、授業担当者は原則週1回のオフィスアワーを設定し、曜日・時間・場所等をシラバスに明記している。学生は授業の内外問わず、相談に行くことができる環境を整備している。

Sheet 様式４　自己点検・評価
I1: 様式４
H2: 大学等名 | I2: ='様式１－１ プログラムを構成する授業科目'!C2 -> 摂南大学
A3: 自己点検・評価について
A5: ① | B5: プログラムの自己点検・評価を行う体制（委員会・組織等）
B6: 摂南大学 教育推進会議、数理・データサイエンス・AI教育プログラム委員会
D8: （責任者名） | E8: 諏訪晴彦 | G8: （役職名） | H8: 全学教育機構長
A10: ② | B10: 自己点検・評価体制における意見等
B11: 自己点検・評価の視点 | E11: 自己点検・評価体制における意見・結果・改善に向けた取組等
B12: 学内からの視点
C13: プログラムの履修・修得状況 | E13: 数理・データサイエンス・AI教育プログラム委員会において、MDASHの教育プログラムの修得状況についての分析を実施した。これらは履修者に関する各種情報に基づくものである。 2024年度における、本プログラムの修了要件は、学部・学科ごとに定められている。現代社会学部、理工学部住環境デザイン学科、同生命科学科、経済学部、国際学部、看護学部では、本プログラム修了要件の科目を必修科目に、その他の学部・学科では選択科目・選択必修科目としている。 本プログラムは2024年度開講であり、主に１年次生が履修するため、2024年度は収容定員に対する履修率は低い。しかし、選択科目・選択必修科目としている学部・学科があるにもかかわらず、入学者数に対する履修率は高い。そのため、将来的には本プログラム対象科目の収容定員に対する履修率・履修済み学生の割合は向上するものと期待される。 また、2024年度における本プログラム対象科目の修了率は、70％～100%となっている。ほとんどの学部で修了率が80%を超えており、多くの学生が内容を修得できているものと考えられる。
C14: 学修成果 | E14: シラバスでは授業計画で何を学ぶかを具体的に示し、適切な到達目標を設定している。多くの学部・学科で、本プログラム対象科目共通のアンケートを実施し、データサイエンスの活用事例、分析方法についての知識、留意点についての理解度を聞いている。このアンケートは初回と最終回に履修者に対して実施し、該当する講義を履修する前と後での変化を調査している。これによって学修成果を把握し、評価・改善に活用している。 また、全学で実施する通常の授業アンケートでは、修得できたと考える能力、理解度、関心度の高さなどについて尋ねている。このアンケートを期末に実施することで、該当する講義を履修することで得られた効果や講義運営上の課題を明らかにしている。これによって学修成果を把握し、評価・改善に活用している。
C15: 学生アンケート等を通じた学生の内容の理解度 | E15: 本プログラム対象科目共通のアンケートの結果では、データサイエンスの活用事例、分析方法に関する知識、そして留意点についての理解度を尋ねている。このアンケートを初回講義と最終回に履修者に実施することで、講義を一通り受講した後の学修成果を把握している。このアンケートを集計した結果、個人差はあるものの、全体的に講義を通して理解度が向上していることが示されていることが確認できた。ただし、最終回における本プログラム対象科目共通のアンケートの回収率は全体的に低調であった。これは出席率とも関係している可能性があるため、今後は履修ガイダンスでもMDASHの意義を周知するとともに、あわせて授業改善のためのアンケートへの協力を呼びかける。 また、全学で実施する通常の授業アンケートの結果によれば、講義で取得できた能力として、多くの履修者が「一般的な教養」と「専門的な知識」を挙げていた。データサイエンスの基本的な知識を習得する、というプログラムの目的に沿った成果が得られた、と多くの履修者が認識していることがうかがえる。また個人差はあるものの、全体的に講義を通して理解度が向上していることも確認できた。
C16: 学生アンケート等を通じた後輩等他の学生への推奨度 | E16: 一部の学部・学科を除いて実施した本プログラム対象科目共通のアンケートでは、最終回実施分において、他の学生への推奨度を尋ねている。アンケートの結果、選択肢「１．（推奨が）十分にできる」「２．少しできる」と回答したものが60%～76％を占めていることが判明した。これは、当該科目の履修者が今後の入学生に対して、履修を推奨することが期待できる結果である。
C17: 全学的な履修者数、履修率向上に向けた計画の達成・進捗状況 | E17: 2024年度において、本プログラムを構成する講義は、５学部６学科で必修科目として開講した。2024年度において必修科目としていない学部・学科も含めて、全学教養教育科目「データサイエンス基礎」を開講し、2027年度以降に全学部で必修科目とする方針である。それまでは、履修者数増加のため、データサイエンス教育の重要性を学生に説明する。また履修者に対しては、課題の提出率を向上させ、講義内容修得の効果が得られることを目指す。具体的には、成績評価に占める課題の割合を見直すこと、さらにこれら課題のうち、講義中に取り組むものを設定するなどの方策が有効と考えられる。
B18: 学外からの視点
C19: 教育プログラム修了者の進路、活躍状況、企業等の評価 | E19: プログラムは2024年度開始であり、本プログラムの対象科目は、２年次配当科目である経営学部の「情報倫理」を除き、１年次配当科目となっている。そのため、2024年度末の時点で、本プログラムを修了した卒業者は０名である。このうような事情から、具体的な企業の評価や進路は不明であるが、今後は就職課の協力を得て、入社先の企業を対象としたアンケートを実施することで、意見を募ることを検討したい。
C20: 産業界からの視点を含めた教育プログラム内容・手法等への意見 | E20: 全学で実施するアンケートや本プログラム対象科目共通のアンケートおよび数理・データサイエンス・AI教育プログラム委員会による自己点検・評価を通じて、改善に向けた課題が明らかになっており、これらについて、順を追って改善を進めていく。得られた意見等については、教育推進会議を通じて全学的に共有を行う。 なお、このプログラムは2024年度に開始したものであり、まだ履修経験のある卒業生はいないため、産業界（企業）からの意見は得られていない。
B21: 数理・データサイエンス・ＡＩを「学ぶ楽しさ」「学ぶことの意義」を理解させること | E21: データサイエンス・AIを学ぶ楽しさや意義を理解させるため、過去の具体的な成功事例を交えてデータ分析が有意義であることを示す講義内容としている。さらに、学生自身が使っているAIツールの使い方やツールを構成する技術内容にも触れることで、AIをより身近に感じ興味を持てるような仕組みを取り入れている。
B22: 内容・水準を維持・向上しつつ、より「分かりやすい」授業とすること ※社会の変化や生成AI等の技術の発展を踏まえて教育内容を継続的に見直すなど、より教育効果の高まる授業内容・方法とするための取組や仕組みについても該当があれば記載 | E22: 授業資料に加えて随時ニュース記事などを用いることで、普遍的な知識・技術に加えて社会情勢を踏まえたAI技術などの最新動向を知ることができる構成としている。また、大学独自の授業アンケートを受講者全員を対象に実施し、その結果や自由記述欄のコメントをもとに改善点の洗い出しを行うことで、授業の質向上に努めている。
