Workbook

Sheet 様式１プログラムを構成する授業科目
T1: 様式１－１ | V1: 「学部・学科によって、修了要件は相違する」場合は、本シートを複製の上＜様式１－〇＞と枝番号を付してください
B2: 大学等名 | C2: 旭川医科大学
B3: プログラム名 | C3: 数理・データサイエンス・AI教育プログラム
A5: リテラシーレベルのプログラムを構成する授業科目について
A7: ① 教育プログラムの修了要件 | L7: 学部・学科によって、修了要件は相違する
A9: ② 対象となる学部・学科名称
B11: 医学部
A14: ③ 修了要件
B15: 医学部医学科においては、プログラムを構成する「データサイエンス（第１学年、後期必修１単位）」、「情報リテラシー（第１学年、前期必修１単位）」すべての単位取得を要件とする。 医学部看護学科においては、プログラムを構成する「統計学（第２学年、前期必修１単位）」、「情報リテラシー（第１学年、前期必修１単位）」、「保健統計（第２学年、通年必修２単位）」すべての単位取得を要件とする。 | X15: 【プルダウンリスト】
X16: 令和６年度以前より、履修することが必須のプログラムとして実施
X17: 令和９年度までに履修必須とする計画
X18: 令和１０年度以降に履修必須とする計画、又は未定
B22: 必要最低科目数・単位数 | E22: 2 | F22: 科目 | H22: 2 | I22: 単位 | M22: 履修必須の有無 | N22: 令和６年度以前より、履修することが必須のプログラムとして実施
A24: ④ 現在進行中の社会変化（第４次産業革命、Society 5.0、データ駆動型社会等）に深く寄与しているものであり、それが自らの生活と密接に結びついている」の内容を含む授業科目
B26: 授業科目 | G26: 単位数 | H26: 必須 | I26: 1-1 | J26: 1-6 | K26: 授業科目 | R26: 単位数 | S26: 必須 | T26: 1-1 | U26: 1-6
B27: データサイエンス | G27: 1 | H27: ○ | I27: ○ | J27: ○
B28: 情報リテラシー | G28: 1 | H28: ○
B30: 統計学 | G30: 1 | H30: ○ | I30: ○
B31: 情報リテラシー | G31: 1 | H31: ○ | J31: ○
B32: 保健統計 | G32: 2 | H32: ○ | I32: ○
A35: ⑤ 「社会で活用されているデータ」や「データの活用領域」は非常に広範囲であって、日常生活や社会の課題を解決する有用なツールになり得るもの」の内容を含む授業科目
B37: 授業科目 | G37: 単位数 | H37: 必須 | I37: 1-2 | J37: 1-3 | K37: 授業科目 | R37: 単位数 | S37: 必須 | T37: 1-2 | U37: 1-3
B38: データサイエンス | G38: 1 | H38: ○ | I38: ○ | J38: ○
B39: 情報リテラシー | G39: 1 | H39: ○
B41: 統計学 | G41: 1 | H41: ○ | I41: ○ | J41: ○
B42: 情報リテラシー | G42: 1 | H42: ○
B43: 保健統計 | G43: 2 | H43: ○ | I43: ○
A46: ⑥ 「様々なデータ利活用の現場におけるデータ利活用事例が示され、様々な適用領域（流通、製造、金融、サービス、インフラ、公共、ヘルスケア等）の知見と組み合わせることで価値を創出するもの」の内容を含む授業科目
B48: 授業科目 | G48: 単位数 | H48: 必須 | I48: 1-4 | J48: 1-5 | K48: 授業科目 | R48: 単位数 | S48: 必須 | T48: 1-4 | U48: 1-5
B49: データサイエンス | G49: 1 | H49: ○ | I49: ○ | J49: ○
B50: 情報リテラシー | G50: 1 | H50: ○
B52: 統計学 | G52: 1 | H52: ○ | I52: ○
B53: 情報リテラシー | G53: 1 | H53: ○ | I53: ○ | J53: ○
B54: 保健統計 | G54: 2 | H54: ○
A57: ⑦ 「活用に当たっての様々な留意事項（ELSI、個人情報、データ倫理、ＡＩ社会原則等）を考慮し、情報セキュリティや情報漏洩等、データを守る上での留意事項への理解をする」の内容を含む授業科目
B59: 授業科目 | G59: 単位数 | H59: 必須 | I59: 3-1 | J59: 3-2 | K59: 授業科目 | R59: 単位数 | S59: 必須 | T59: 3-1 | U59: 3-2
B60: データサイエンス | G60: 1 | H60: ○ | I60: ○ | J60: ○
B61: 情報リテラシー | G61: 1 | H61: ○ | I61: ○ | J61: ○
B63: 統計学 | G63: 1 | H63: ○
B64: 情報リテラシー | G64: 1 | H64: ○ | I64: ○ | J64: ○
...

Sheet 様式２ 履修者等数の実績
S1: 様式２
Q2: =様式１プログラムを構成する授業科目!C2 -> 旭川医科大学
A3: リテラシーレベルのプログラムの履修者数等の実績について
A5: ①プログラム開設年度 | C5: 令和5 | E5: 年度（和暦）
A7: ②大学等全体の男女別学生数 | E7: 男性 | F7: 382 | G7: 人 | H7: 女性 | I7: 477 | J7: 人 | K7: （ | L7: 合計 | M7: =F7+I7 -> 859 | N7: 人 | O7: ）
B8: （令和６年５月１日時点）
A9: ③履修者・修了者の実績
B11: 学部・学科名称 | C11: 学生数 | D11: 入学 定員 | E11: 収容 定員 | F11: 令和6年度 | H11: 令和5年度 | J11: 令和4年度 | L11: 令和3年度 | N11: 令和2年度 | P11: 令和元年度 | R11: 履修者数 合計 | S11: 履修率
F12: 履修者数 | G12: 修了者数 | H12: 履修者数 | I12: 修了者数 | J12: 履修者数 | K12: 修了者数 | L12: 履修者数 | M12: 修了者数 | N12: 履修者数 | O12: 修了者数 | P12: 履修者数 | Q12: 修了者数
B13: 医学部 医学科 | C13: 620 | D13: 95 | E13: 620 | F13: 95 | G13: 92 | H13: 94 | I13: 94 | J13: 95 | K13: 95 | R13: =F13+H13+J13+L13+N13+P13 -> 284 | S13: =R13/E13 -> 0.45806452
B14: 医学部 看護学科 | C14: 239 | D14: 60 | E14: 240 | F14: 59 | G14: 58 | H14: 60 | I14: 60 | J14: 60 | K14: 60 | L14: 60 | M14: 60 | R14: =F14+H14+J14+L14+N14+P14 -> 239 | S14: =R14/E14 -> 0.99583333
R15: =F15+H15+J15+L15+N15+P15 -> 0 | S15: =R15/E15 -> #DIV/0!
R16: =F16+H16+J16+L16+N16+P16 -> 0 | S16: =R16/E16 -> #DIV/0!
R17: =F17+H17+J17+L17+N17+P17 -> 0 | S17: =R17/E17 -> #DIV/0!
R18: =F18+H18+J18+L18+N18+P18 -> 0 | S18: =R18/E18 -> #DIV/0!
R19: =F19+H19+J19+L19+N19+P19 -> 0 | S19: =R19/E19 -> #DIV/0!
R20: =F20+H20+J20+L20+N20+P20 -> 0 | S20: =R20/E20 -> #DIV/0!
R21: =F21+H21+J21+L21+N21+P21 -> 0 | S21: =R21/E21 -> #DIV/0!
R22: =F22+H22+J22+L22+N22+P22 -> 0 | S22: =R22/E22 -> #DIV/0!
R23: =F23+H23+J23+L23+N23+P23 -> 0 | S23: =R23/E23 -> #DIV/0!
R24: =F24+H24+J24+L24+N24+P24 -> 0 | S24: =R24/E24 -> #DIV/0!
R25: =F25+H25+J25+L25+N25+P25 -> 0 | S25: =R25/E25 -> #DIV/0!
R26: =F26+H26+J26+L26+N26+P26 -> 0 | S26: =R26/E26 -> #DIV/0!
... R32: =F32+H32+J32+L32+N32+P32 -> 0 | S32: =R32/E32 -> #DIV/0!
B33: 合 計 | C33: =SUM(C13:C32) -> 859 | D33: =SUM(D13:D32) -> 155 | E33: =SUM(E13:E32) -> 860 | F33: =SUM(F13:F32) -> 154 | G33: =SUM(G13:G32) -> 150 | H33: =SUM(H13:H32) -> 154 | I33: =SUM(I13:I32) -> 154 | J33: =SUM(J13:J32) -> 155 | ... R33: =SUM(R13:R32) -> 523 | S33: =R33/E33 -> 0.60813953

Sheet 様式３ 教育の質・履修者数を向上させるための体制・計画
I1: 様式３
G2: 大学等名 | H2: =様式１プログラムを構成する授業科目!C2 -> 旭川医科大学
A4: 教育の質・履修者数を向上させるための体制・計画について
A6: ① | B6: 全学の教員数 | C6: (常勤） | E6: 343 | F6: 人 | G6: （非常勤） | H6: 128 | I6: 人
A8: ② | B8: プログラムの授業を教えている教員数 | H8: 9 | I8: 人
A10: ③ | B10: プログラムの運営責任者
B11: （責任者名） | C11: (1)奥村 利勝、(2)古川 博之 | G11: （役職名） | H11: (1)教育担当副学長、(2)評価担当副学長
A13: ④ | B13: プログラムを改善・進化させるための体制（委員会・組織等）
B14: 旭川医科大学カリキュラム委員会
B16: （責任者名） | C16: 奥村 利勝、古川 博之 | G16: （役職名） | H16: 教育担当副学長、評価担当副学長
A18: ⑤ | B18: プログラムを改善・進化させるための体制を定める規則名称
B19: (1)旭川医科大学カリキュラム委員会規程、(2)旭川医科大学医学部医学科教育プログラム評価規程、（3）旭川医科大学医学部看護学科教育プログラム評価規程
A21: ⑥ | B21: 体制の目的
B22: ビッグテータを利用した新たな価値の創出、AIを利用したデータ解析や画像解析および最適な治療計画の策定などを見据えた講義・実習を展開すること。さらに、社会の変化、特に医療現場の進化・多様化にあわせて講義・実習内容をアップデートさせる助言を与えることである。 なお、本学の体制としては、 「カリキュラム委員会」において、医学科及び看護学科のカリキュラムの立案・編成に関することを審議し、「教育プログラム評価委員会」において、点検及び評価を行っている。
A34: ⑦ | B34: 具体的な構成員
B35: ＜カリキュラム委員会＞ 奥村利勝委員長（理事・医学科長）、升田由美子副委員長（看護学科長）、佐藤伸之委員（教育センター教員）、野津 司委員（教育センター教員）、眞山博幸委員（一般教育教員）、工藤直志委員（一般教育教員）、西條泰明委員（基礎医学教員）、中山 恒委員（基礎医学教員）、中川直樹委員（臨床医学教員）、長岡泰司委員（臨床医学教員）、長谷川博亮委員（看護学科教員）、平 義樹委員（看護学科教員）、学生１０名（各学科・学年から1名）、学外有識者1名、牧野雄一委員（地域共生医育センター）、その他（委員会が必要と認めたもの） ＜医学科教育プログラム評価委員会＞ 古川博之委員長（理事・副学長）、東信良委員（病院長）、井戸川みどり委員（特任看護部長）、髙澤啓（基礎医学教員）、高原幹（臨床医学教員）、池上将永（一般教育教員）、吉原秀昭（事務局長）、学外有識者５名、学生１名、その他（委員が必要と認めたもの） ＜看護学科教育プログラム評価委員会＞ 古川博之委員長（理事・副学長）、東信良委員（病院長）、井戸川みどり（特任看護部長）、山根由起子（看護学科教員）、菅原峰子（看護学科教員）、高橋龍尚（一般教育教員）、吉原秀昭（事務局長）、学外委員５名、学生３名（看護・保健・助産から各１名）、その他（委員会が必要と認めたもの）
A48: ⑧ | B48: 履修者数・履修率の向上に向けた計画 ※様式１の「履修必須の有無」で「計画がある」としている場合は詳細について記載すること
B49: 令和６年度実績 | C49: ='様式２ 履修者等数の実績'!S33 -> 0.60813953 | E49: 令和７年度予定 | F49: 0.74 | H49: 令和８年度予定 | I49: 0.87
B50: 令和９年度予定 | C50: 1 | E50: 令和１０年度予定 | F50: 1 | H50: 収容定員（名） | I50: ='様式２ 履修者等数の実績'!E33 -> 860
B51: 具体的な計画
B52: 入学直後に実施する「新入生オリエンテーション」において、当プログラムの概要について説明するとともに、医療における数理・データサイエンス・AIに関する知識および技術習得の必要性について周知する。本学では、プログラム構成科目はすべて必修であることから履修率１００％が原則となる。そこで、当該科目を学ぶことの重要性を強調し、単なる必修科目と考えるのではなく、真に学ぶべき目的の理解を求める。
A65: ⑨ | B65: 学部・学科に関係なく希望する学生全員が受講可能となるような必要な体制・取組等
B66: 必修科目であるため、対象となる学生は全員受講することになっている。また、他学年の学生が受講を希望する際には受講を可能とする。
A79: ⑩ | B79: できる限り多くの学生が履修できるような具体的な周知方法・取組
B80: 入学直後に実施する「新入生オリエンテーション」において、必修科目および選択科目の履修方法の説明を行っている。特に、当該プログラムの単位認定の仕組みについては、国策ともいえる新しい試みであることも含め丁寧な説明を行う。また、学習支援システムmanaba上でも詳細を掲示する。
A93: ⑪ | B93: できる限り多くの学生が履修・修得できるようなサポート体制
B94: 学習支援システムmanabaを利用して、いつでも講義資料や課題をダウンロードできる環境を整えている。
A107: ⑫ | B107: 授業時間内外で学習指導、質問を受け付ける具体的な仕組み
B108: 講義に関する質問は、学習支援システムmanaba やメールで常時受け付けていることをシラバスや学生生活のしおり に明記している。また、講義時間外であっても直接教員の居室に来て質問することもできることを周知している（オフィスアワー制度）。

Sheet 様式４　自己点検・評価
I1: 様式４
H2: 大学等名 | I2: =様式１プログラムを構成する授業科目!C2 -> 旭川医科大学
A3: 自己点検・評価について
A5: ① | B5: プログラムの自己点検・評価を行う体制（委員会・組織等）
B6: 医学部医学科教育プログラム評価委員会、医学部看護学科教育プログラム評価委員会
D8: （責任者名） | E8: 古川 博之 | G8: （役職名） | H8: 副学長（評価担当）
A10: ② | B10: 自己点検・評価体制における意見等
B11: 自己点検・評価の視点 | E11: 自己点検・評価体制における意見・結果・改善に向けた取組等
B12: 学内からの視点
C13: プログラムの履修・修得状況 | E13: プログラムを構成する科目の履修・修得状況は、学生支援課が集計、管理している。 科目を担当する各教員は、授業アンケートの結果をもとに、改善点を見出し次年度以降の講義に活かしている。
C14: 学修成果 | E14: プログラムを構成する科目は、主に１年生または２年生が履修する。そのため、例えば履修前では pc 操作スキルに個人差がある。各教員は、前年度に実施したアンケート調査を活用することで、このような問題点を解消する。
C15: 学生アンケート等を通じた学生の内容の理解度 | E15: 学生の講義内容に対する理解度を確認するために、学生アンケートを実施している。教員は学生の理解度を把握し、適切な難易度になるように講義内容を修正している。
C16: 学生アンケート等を通じた後輩等他の学生への推奨度 | E16: 学生アンケート調査を実施した後、その結果を受けて教員がコメントする。コメントは公開されており、学生へのメッセージとするだけではなく、次年度以降の講義に改善点を反映させる。
C17: 全学的な履修者数、履修率向上に向けた計画の達成・進捗状況 | E17: プログラムを構成する科目は必修科目として展開されている。そのため、すべての学生が単位を取得できるように各教員は講義内容を工夫している。これまでにおいては、対象となる学生の履修率はすでに目標の100%を達成しており、今後も目標を維持できるようアンケート調査を実施するなどの取組を継続していきたい。
B18: 学外からの視点
C19: 教育プログラム修了者の進路、活躍状況、企業等の評価 | E19: 医療現場で必要とされる卒業生の能力評価の情報は、副委員長を通じて様式３の⑦に直接伝えられる。（教育プログラム評価委員会）
C20: 産業界からの視点を含めた教育プログラム内容・手法等への意見 | E20: 医療現場で必要とされる卒業生の能力の改善・向上のための要望は、病院長を通じて様式③の⑦（カリキュラム委員会）に直接伝えられる。
B21: 数理・データサイエンス・ＡＩを「学ぶ楽しさ」「学ぶことの意義」を理解させること | E21: 近年、生成AIの発展は著しく、旬な話題としてメディア等で見聞きする機会が増えている。講義中にこうしたAIのトレンドを紹介することで数理・データサイエンス・AI を学ぶ楽しさを周知する。 データサイエンスでのプログラミング基礎（Python）や看護統計学での SPSS の基本的な使い方を学ぶことは、将来的に医療分野への応用を考える上で重要であることを理解させ、データサイエンスを学ぶ動機づけを促す。
B22: 内容・水準を維持・向上しつつ、より「分かりやすい」授業とすること ※社会の変化や生成AI等の技術の発展を踏まえて教育内容を継続的に見直すなど、より教育効果の高まる授業内容・方法とするための取組や仕組みについても該当があれば記載 | E22: 講義アンケートの結果を踏まえて、講義内容を適宜修正し、次年度以降の講義に役立てる。 数理・データサイエンス・AI 教育プログラムを構成する各科目について、特に医療への応用を念頭に学ぶ目的を明確にし、より分かりやすい講義内容にすることを目指す。
