Workbook

Sheet 様式１−１　プログラムを構成する授業科目
T1: 様式１ー１ | V1: 「学部・学科によって、修了要件は相違する」場合は、本シートを複製の上＜様式１－〇＞と枝番号を付してください
B2: 大学等名 | C2: 湘北短期大学
B3: プログラム名 | C3: 湘北数理・データサイエンス・AI教育プログラム
A5: リテラシーレベルのプログラムを構成する授業科目について
A7: ① 教育プログラムの修了要件 | L7: 学部・学科によって、修了要件は相違する
A9: ② 対象となる学部・学科名称
B11: 総合ビジネス・情報学科、生活プロデュース学科
A14: ③ 修了要件
B15: 1年次前期必修科目「情報リテラシー（データサイエンス入門）」の2単位を取得すること。 | X15: 【プルダウンリスト】
X16: 令和６年度以前より、履修することが必須のプログラムとして実施
X17: 令和９年度までに履修必須とする計画
X18: 令和１０年度以降に履修必須とする計画、又は未定
B22: 必要最低科目数・単位数 | E22: 1 | F22: 科目 | H22: 2 | I22: 単位 | M22: 履修必須の有無 | N22: 令和６年度以前より、履修することが必須のプログラムとして実施
A24: ④ 現在進行中の社会変化（第４次産業革命、Society 5.0、データ駆動型社会等）に深く寄与しているものであり、それが自らの生活と密接に結びついている」の内容を含む授業科目
B26: 授業科目 | G26: 単位数 | H26: 必須 | I26: 1-1 | J26: 1-6 | K26: 授業科目 | R26: 単位数 | S26: 必須 | T26: 1-1 | U26: 1-6
B27: 情報リテラシー（データサイエンス入門） | G27: 2 | H27: ○ | I27: ○ | J27: ○
A35: ⑤ 「社会で活用されているデータ」や「データの活用領域」は非常に広範囲であって、日常生活や社会の課題を解決する有用なツールになり得るもの」の内容を含む授業科目
B37: 授業科目 | G37: 単位数 | H37: 必須 | I37: 1-2 | J37: 1-3 | K37: 授業科目 | R37: 単位数 | S37: 必須 | T37: 1-2 | U37: 1-3
B38: 情報リテラシー（データサイエンス入門） | G38: 2 | H38: ○ | I38: ○ | J38: ○
A46: ⑥ 「様々なデータ利活用の現場におけるデータ利活用事例が示され、様々な適用領域（流通、製造、金融、サービス、インフラ、公共、ヘルスケア等）の知見と組み合わせることで価値を創出するもの」の内容を含む授業科目
B48: 授業科目 | G48: 単位数 | H48: 必須 | I48: 1-4 | J48: 1-5 | K48: 授業科目 | R48: 単位数 | S48: 必須 | T48: 1-4 | U48: 1-5
B49: 情報リテラシー（データサイエンス入門） | G49: 2 | H49: ○ | I49: ○ | J49: ○
A57: ⑦ 「活用に当たっての様々な留意事項（ELSI、個人情報、データ倫理、ＡＩ社会原則等）を考慮し、情報セキュリティや情報漏洩等、データを守る上での留意事項への理解をする」の内容を含む授業科目
B59: 授業科目 | G59: 単位数 | H59: 必須 | I59: 3-1 | J59: 3-2 | K59: 授業科目 | R59: 単位数 | S59: 必須 | T59: 3-1 | U59: 3-2
B60: 情報リテラシー（データサイエンス入門） | G60: 2 | H60: ○ | I60: ○ | J60: ○
A68: ⑧ 「実データ・実課題（学術データ等を含む）を用いた演習など、社会での実例を題材として、「データを読む、説明する、扱う」といった数理・データサイエンス・ＡＩの基本的な活用法に関するもの」の内容を含む授業科目
B70: 授業科目 | F70: 単位数 | G70: 必須 | H70: 2-1 | I70: 2-2 | J70: 2-3 | K70: 授業科目 | Q70: 単位数 | R70: 必須 | S70: 2-1 | T70: 2-2 | U70: 2-3
B71: 情報リテラシー（データサイエンス入門） | F71: 2 | G71: ○ | H71: ○ | I71: ○ | J71: ○
A79: ⑨ 選択「４．オプション」の内容を含む授業科目
B80: 授業科目 | G80: 選択項目 | K80: 授業科目 | R80: 選択項目 | AA80: 4-1統計および数理基礎
AA81: 4‐2アルゴリズム基礎
AA82: 4‐3データ構造とプログラミング基礎
AA83: 4‐4時系列データ解析
AA84: 4‐5自然言語処理
AA85: 4‐6画像認識
AA86: 4‐7データハンドリング
AA87: 4‐8データ活用実践（教師あり学習）
AA88: 4‐9データ活用実践（教師なし学習）
A89: ⑩ プログラムを構成する授業の内容 | AA89: その他
B90: 授業に含まれている内容・要素 | D90: 講義内容
...

Sheet 様式１−２　プログラムを構成する授業科目
T1: 様式１ー２ | V1: 「学部・学科によって、修了要件は相違する」場合は、本シートを複製の上＜様式１－〇＞と枝番号を付してください
B2: 大学等名 | C2: 湘北短期大学
B3: プログラム名 | C3: 湘北数理・データサイエンス・AI教育プログラム
A5: リテラシーレベルのプログラムを構成する授業科目について
A7: ① 教育プログラムの修了要件 | L7: 学部・学科によって、修了要件は相違する
A9: ② 対象となる学部・学科名称
B11: 保育学科
A14: ③ 修了要件
B15: 2年次通年必修科目「保育のためのICT・DX入門Ⅱ」の1単位を取得すること。 | X15: 【プルダウンリスト】
X16: 令和６年度以前より、履修することが必須のプログラムとして実施
X17: 令和９年度までに履修必須とする計画
X18: 令和１０年度以降に履修必須とする計画、又は未定
B22: 必要最低科目数・単位数 | E22: 1 | F22: 科目 | H22: 1 | I22: 単位 | M22: 履修必須の有無 | N22: 令和６年度以前より、履修することが必須のプログラムとして実施
A24: ④ 現在進行中の社会変化（第４次産業革命、Society 5.0、データ駆動型社会等）に深く寄与しているものであり、それが自らの生活と密接に結びついている」の内容を含む授業科目
B26: 授業科目 | G26: 単位数 | H26: 必須 | I26: 1-1 | J26: 1-6 | K26: 授業科目 | R26: 単位数 | S26: 必須 | T26: 1-1 | U26: 1-6
B27: 保育のためのICT・DX入門Ⅱ | G27: 1 | H27: ○ | I27: ○ | J27: ○
A35: ⑤ 「社会で活用されているデータ」や「データの活用領域」は非常に広範囲であって、日常生活や社会の課題を解決する有用なツールになり得るもの」の内容を含む授業科目
B37: 授業科目 | G37: 単位数 | H37: 必須 | I37: 1-2 | J37: 1-3 | K37: 授業科目 | R37: 単位数 | S37: 必須 | T37: 1-2 | U37: 1-3
B38: 保育のためのICT・DX入門Ⅱ | G38: 1 | H38: ○ | I38: ○ | J38: ○
A46: ⑥ 「様々なデータ利活用の現場におけるデータ利活用事例が示され、様々な適用領域（流通、製造、金融、サービス、インフラ、公共、ヘルスケア等）の知見と組み合わせることで価値を創出するもの」の内容を含む授業科目
B48: 授業科目 | G48: 単位数 | H48: 必須 | I48: 1-4 | J48: 1-5 | K48: 授業科目 | R48: 単位数 | S48: 必須 | T48: 1-4 | U48: 1-5
B49: 保育のためのICT・DX入門Ⅱ | G49: 1 | H49: ○ | I49: ○ | J49: ○
A57: ⑦ 「活用に当たっての様々な留意事項（ELSI、個人情報、データ倫理、ＡＩ社会原則等）を考慮し、情報セキュリティや情報漏洩等、データを守る上での留意事項への理解をする」の内容を含む授業科目
B59: 授業科目 | G59: 単位数 | H59: 必須 | I59: 3-1 | J59: 3-2 | K59: 授業科目 | R59: 単位数 | S59: 必須 | T59: 3-1 | U59: 3-2
B60: 保育のためのICT・DX入門Ⅱ | G60: 1 | H60: ○ | I60: ○ | J60: ○
A68: ⑧ 「実データ・実課題（学術データ等を含む）を用いた演習など、社会での実例を題材として、「データを読む、説明する、扱う」といった数理・データサイエンス・ＡＩの基本的な活用法に関するもの」の内容を含む授業科目
B70: 授業科目 | F70: 単位数 | G70: 必須 | H70: 2-1 | I70: 2-2 | J70: 2-3 | K70: 授業科目 | Q70: 単位数 | R70: 必須 | S70: 2-1 | T70: 2-2 | U70: 2-3
B71: 保育のためのICT・DX入門Ⅱ | F71: 1 | G71: ○ | H71: ○ | I71: ○ | J71: ○
A79: ⑨ 選択「４．オプション」の内容を含む授業科目
B80: 授業科目 | G80: 選択項目 | K80: 授業科目 | R80: 選択項目 | AA80: 4-1統計および数理基礎
AA81: 4‐2アルゴリズム基礎
AA82: 4‐3データ構造とプログラミング基礎
AA83: 4‐4時系列データ解析
AA84: 4‐5自然言語処理
AA85: 4‐6画像認識
AA86: 4‐7データハンドリング
AA87: 4‐8データ活用実践（教師あり学習）
AA88: 4‐9データ活用実践（教師なし学習）
A89: ⑩ プログラムを構成する授業の内容 | AA89: その他
B90: 授業に含まれている内容・要素 | D90: 講義内容
...

Sheet 様式２ 履修者等数の実績
S1: 様式２
Q2: ='様式１−１ プログラムを構成する授業科目'!C2 -> 湘北短期大学
A3: リテラシーレベルのプログラムの履修者数等の実績について
A5: ①プログラム開設年度 | C5: 令和6 | E5: 年度（和暦）
A7: ②大学等全体の男女別学生数 | E7: 男性 | F7: 119 | G7: 人 | H7: 女性 | I7: 523 | J7: 人 | K7: （ | L7: 合計 | M7: =F7+I7 -> 642 | N7: 人 | O7: ）
B8: （令和６年５月１日時点）
A9: ③履修者・修了者の実績
B11: 学部・学科名称 | C11: 学生数 | D11: 入学 定員 | E11: 収容 定員 | F11: 令和6年度 | H11: 令和5年度 | J11: 令和4年度 | L11: 令和3年度 | N11: 令和2年度 | P11: 令和元年度 | R11: 履修者数 合計 | S11: 履修率
F12: 履修者数 | G12: 修了者数 | H12: 履修者数 | I12: 修了者数 | J12: 履修者数 | K12: 修了者数 | L12: 履修者数 | M12: 修了者数 | N12: 履修者数 | O12: 修了者数 | P12: 履修者数 | Q12: 修了者数
B13: 総合ビジネス・情報学科 | C13: 321 | D13: 220 | E13: 440 | F13: 154 | G13: 142 | R13: =F13+H13+J13+L13+N13+P13 -> 154 | S13: =R13/E13 -> 0.35
B14: 生活プロデュース学科 | C14: 136 | D14: 125 | E14: 250 | F14: 77 | G14: 74 | R14: =F14+H14+J14+L14+N14+P14 -> 77 | S14: =R14/E14 -> 0.308
B15: 保育学科 | C15: 185 | D15: 135 | E15: 270 | F15: 0 | G15: 0 | R15: =F15+H15+J15+L15+N15+P15 -> 0 | S15: =R15/E15 -> 0
R16: =F16+H16+J16+L16+N16+P16 -> 0 | S16: =R16/E16 -> #DIV/0!
R17: =F17+H17+J17+L17+N17+P17 -> 0 | S17: =R17/E17 -> #DIV/0!
R18: =F18+H18+J18+L18+N18+P18 -> 0 | S18: =R18/E18 -> #DIV/0!
R19: =F19+H19+J19+L19+N19+P19 -> 0 | S19: =R19/E19 -> #DIV/0!
R20: =F20+H20+J20+L20+N20+P20 -> 0 | S20: =R20/E20 -> #DIV/0!
R21: =F21+H21+J21+L21+N21+P21 -> 0 | S21: =R21/E21 -> #DIV/0!
R22: =F22+H22+J22+L22+N22+P22 -> 0 | S22: =R22/E22 -> #DIV/0!
R23: =F23+H23+J23+L23+N23+P23 -> 0 | S23: =R23/E23 -> #DIV/0!
R24: =F24+H24+J24+L24+N24+P24 -> 0 | S24: =R24/E24 -> #DIV/0!
R25: =F25+H25+J25+L25+N25+P25 -> 0 | S25: =R25/E25 -> #DIV/0!
R26: =F26+H26+J26+L26+N26+P26 -> 0 | S26: =R26/E26 -> #DIV/0!
R27: =F27+H27+J27+L27+N27+P27 -> 0 | S27: =R27/E27 -> #DIV/0!
... R32: =F32+H32+J32+L32+N32+P32 -> 0 | S32: =R32/E32 -> #DIV/0!
B33: 合 計 | C33: =SUM(C13:C32) -> 642 | D33: =SUM(D13:D32) -> 480 | E33: =SUM(E13:E32) -> 960 | F33: =SUM(F13:F32) -> 231 | G33: =SUM(G13:G32) -> 216 | H33: =SUM(H13:H32) -> 0 | I33: =SUM(I13:I32) -> 0 | J33: =SUM(J13:J32) -> 0 | ... R33: =SUM(R13:R32) -> 231 | S33: =R33/E33 -> 0.240625

Sheet 様式３ 教育の質・履修者数を向上させるための体制・計画
I1: 様式３
G2: 大学等名 | H2: ='様式１−１ プログラムを構成する授業科目'!C2 -> 湘北短期大学
A4: 教育の質・履修者数を向上させるための体制・計画について
A6: ① | B6: 全学の教員数 | C6: (常勤） | E6: 34 | F6: 人 | G6: （非常勤） | H6: 82 | I6: 人
A8: ② | B8: プログラムの授業を教えている教員数 | H8: 2 | I8: 人
A10: ③ | B10: プログラムの運営責任者
B11: （責任者名） | C11: 髙橋洋 | G11: （役職名） | H11: 学長
A13: ④ | B13: プログラムを改善・進化させるための体制（委員会・組織等）
B14: 数理・データサイエンス・AI教育推進ワーキンググループ
B16: （責任者名） | C16: 髙嶋章雄 | G16: （役職名） | H16: リベラルアーツセンター長
A18: ⑤ | B18: プログラムを改善・進化させるための体制を定める規則名称
B19: 数理・データサイエンス・AI教育推進ワーキンググループ設置要綱
A21: ⑥ | B21: 体制の目的
B22: 湘北短期大学数理・データサイエンス・AI教育推進ワーキンググループは、以下の業務を所管する （1）当教育プログラムの具体的な内容に関する協議・検討 （2）当教育プログラムの計画（当教育プログラムにおいて身に付けることのできる能力、修了要件、開設される授業科目、授業の方法、及び内容等）の策定並びに実施体制の構築、及びそれらの公表 （3）学生に対し当教育プログラムの履修を促す取組の協議・検討、及び実施 （4）当教育プログラムについての点検及び評価、その結果の公表
A34: ⑦ | B34: 具体的な構成員
B35: 髙嶋章雄 リベラルアーツセンター長（責任者） 矢沢隆 教務・学生部部長（副責任者） 小林良向 IR室長 泉屋咲月 生活プロデュース学科 小笠原大輔 保育学科 北野俊之 教務・学生部 高橋博子 教務・学生部
A48: ⑧ | B48: 履修者数・履修率の向上に向けた計画 ※様式１の「履修必須の有無」で「計画がある」としている場合は詳細について記載すること
B49: 令和６年度実績 | C49: ='様式２ 履修者等数の実績'!S33 -> 0.240625 | E49: 令和７年度予定 | F49: 0.67 | H49: 令和８年度予定 | I49: 0.8
B50: 令和９年度予定 | C50: 0.9 | E50: 令和１０年度予定 | F50: 1 | H50: 収容定員（名） | I50: ='様式２ 履修者等数の実績'!E33 -> 960
B51: 具体的な計画
B52: 湘北短期大学は総合ビジネス・情報学科、生活プロデュース学科、保育学科からなる総合短期大学である。各専門分野での実務において重要な役割を果たすと考え、全学科で数理・データサイエンス・AIに関する科目を、必修科目として位置づけている。 総合ビジネス・情報学科および生活プロデュース学科においては、1年次前期の必修科目として「情報リテラシー（データサイエンス入門）」を開講する。PCを操作する内容も含むため、全15回のオンデマンド科目とし、自由な時間に何度でも動画を見直しながら学習を進められるようにしている。 保育学科においては、基本的なPCスキルを学ぶ1年次通年隔週で開講する「保育のためのICT・DX入門Ⅰ」の発展として、2年次通年隔週で開講する「保育のためのICT・DX入門Ⅱ」を開講している。本教育プログラムが対象とする科目は「保育のためのICT・DX入門Ⅱ」とする。 令和6年度以降の全入学生が本プログラムの履修対象学生となる。総合ビジネス・情報学科と生活プロデュース学科の学生は、令和6年度に対象科目の履修を終え、保育学科の学生は、令和7年度に対象科目の履修を終えることとなる。 収容定員ではなく在籍者数を母数とした場合の履修率は、令和7年度以降100%となる。
A65: ⑨ | B65: 学部・学科に関係なく希望する学生全員が受講可能となるような必要な体制・取組等
B66: 本教育プログラムを構成する「情報リテラシー（データサイエンス入門）」および「保育のためのICT・DX入門Ⅱ」は、各学科の卒業要件に含まれる必修科目として開講している。
A79: ⑩ | B79: できる限り多くの学生が履修できるような具体的な周知方法・取組
B80: 入学後のガイダンスや学生向けの情報ポータルにおいて、本教育プログラムの内容を周知している。
A93: ⑪ | B93: できる限り多くの学生が履修・修得できるようなサポート体制
B94: 本教育プログラムを構成する全科目は、講義資料をLMSで管理・提供している。「情報リテラシー（データサイエンス入門）」は、学外のインストラクショナルデザインの専門家に協力を仰ぎ、50件の動画を中心としたオンデマンド科目として、学生が繰り返し学習可能な環境を提供している。
A107: ⑫ | B107: 授業時間内外で学習指導、質問を受け付ける具体的な仕組み
B108: 対面で実施する科目は授業中や授業後に質問を受け付けている。オンデマンド科目はLMSを通じて質問を受け付けるとともに、担当する常勤教員がオフィスアワーを中心に対面での質問を受け付けている。また、本学にはPCやIT機器を利用する上でわからないことを学生が気軽に相談できる「ITコンシェルジュ」が常駐しており、学修を妨げない範囲でITに関するトラブル解決を行っている。

Sheet 様式４　自己点検・評価
I1: 様式４
H2: 大学等名 | I2: ='様式１−１ プログラムを構成する授業科目'!C2 -> 湘北短期大学
A3: 自己点検・評価について
A5: ① | B5: プログラムの自己点検・評価を行う体制（委員会・組織等）
B6: 数理・データサイエンス・AI教育推進ワーキンググループ
D8: （責任者名） | E8: 髙嶋章雄 | G8: （役職名） | H8: リベラルアーツセンター長
A10: ② | B10: 自己点検・評価体制における意見等
B11: 自己点検・評価の視点 | E11: 自己点検・評価体制における意見・結果・改善に向けた取組等
B12: 学内からの視点
C13: プログラムの履修・修得状況 | E13: 数理・データサイエンス・AI教育推進ワーキンググループおよび教務・学生課において本プログラムの履修・単位修得状況を分析している。令和6年度終了時点で、総合ビジネス・情報学科および生活プロデュース学科の学生が受講できる「情報リテラシー（データサイエンス入門）」が終了している。単位修得率は87.9%（203/231名）であった。このうち、開講期中または期後に休学もしくは退学した学生を除くと単位修得率は98.5%（203/206名）となる。
C14: 学修成果 | E14: 担当教員はLMSを通じて学生の進捗を常に把握しており、担当教員および数理・データサイエンス・AI教育推進ワーキンググループにおいて本プログラムの履修・単位修得状況を分析している。 「情報リテラシー（データサイエンス入門）」は、全15回（動画・課題提出・小テストを含む全94レクチャー）のオンデマンド科目であり、LMSへのログイン状況、動画閲覧状況、課題提出状況を教員が常にモニタリングし、進捗の芳しくない学生にはメール等でリマインドした。学修成果を確認する小テストを25件設け、テストをクリアしない限り先のレクチャーに進めない仕様としているため、全レクチャーに取り組んだ学生は一定の学修成果を有していると考えられる。
C15: 学生アンケート等を通じた学生の内容の理解度 | E15: 教務・学生課において本教育プログラム受講者全員に対して授業改善アンケートを実施している。また、リベラルアーツセンターにおいて、オンデマンド科目の受講スタイルに関するアンケートを実施している。数理・データサイエンス・AI教育推進ワーキンググループにおいて各アンケート結果を分析している。 令和6年度の「情報リテラシー（データサイエンス入門）」においては、授業改善アンケートの設問「この授業の目的とする知識や技能、考え方が身についたか」「この授業を通じて自分が以前より成長できたか」において、4段階評価で肯定的な意見が、それぞれ92%を超える結果となった。学生の自己評価として、各自が内容を理解できたと考えられる。
C16: 学生アンケート等を通じた後輩等他の学生への推奨度 | E16: 令和6年度の「情報リテラシー（データサイエンス入門）」の授業改善アンケートの設問「授業の内容は興味深いものであったか」において、88.4%の肯定的な意見が得られた。後輩等への推奨度を直接調査したものではないが、多くの学生にとって履修する価値のある内容として受け入れられたと考えられる。
C17: 全学的な履修者数、履修率向上に向けた計画の達成・進捗状況 | E17: 本教育プログラムを構成する「情報リテラシー（データサイエンス入門）」および「保育のためのICT・DX入門Ⅱ」は、各学科の卒業要件に含まれる必修科目として開講している。
B18: 学外からの視点
C19: 教育プログラム修了者の進路、活躍状況、企業等の評価 | E19: 本教育プログラムを修了した学生が卒業するのは令和7年度末が初めてとなり、進路についても今後判明する状況である。
C20: 産業界からの視点を含めた教育プログラム内容・手法等への意見 | E20: 本学卒業生がターゲットとする就職先の内、事務職やSEはもとより、人と人とのコミュニケーションが重要視される接客業や保育の現場においても、本プログラムの学修内容が重要視されている。過去の来店データに基づく顧客との対面コミュニケーションの円滑化や、午睡センサーを利用した園児の安全確保など、質の高いサービス提供の事例が増えつつある。生成AI関連技術の急速な発展も注視しつつ、学生にとって有益な情報を提供できるようプログラムの内容を、数理・データサイエンス・AI教育推進ワーキンググループにおいて継続点検する。
B21: 数理・データサイエンス・ＡＩを「学ぶ楽しさ」「学ぶことの意義」を理解させること | E21: 本教育プログラムは、各学科必修科目のみで構成されており、もともと興味を持っていない学生も一定数含まれる。そのため、産業界からの視点だけでなく、学生目線の身近な事例なども散りばめて、数理・データサイエンス・AIに関する知識やスキルを自然と理解できるような授業を展開している。結果として上述した複数の設問において肯定的な意見が得られたと考えられる。
B22: 内容・水準を維持・向上しつつ、より「分かりやすい」授業とすること ※社会の変化や生成AI等の技術の発展を踏まえて教育内容を継続的に見直すなど、より教育効果の高まる授業内容・方法とするための取組や仕組みについても該当があれば記載 | E22: オンデマンド科目においては、授業設計段階から学外のインストラクショナルデザイナーに協力を仰ぎ動画制作や課題設定を構成した。受講スタイルに関するアンケートから、オンデマンド形式に関して79.5%の肯定的な意見が得られた。授業改善アンケート等で得られる情報や、本教育プログラム以外の授業内容・スタイルも参考にし、分かりやすさの観点から授業およびプログラムを、数理・データサイエンス・AI教育推進ワーキンググループにおいて継続点検する。
