Workbook

Sheet 様式１　プログラムを構成する授業科目 
T1: 様式１ | V1: 「学部・学科によって、修了要件は相違する」場合は、本シートを複製の上＜様式１－〇＞と枝番号を付してください
B2: 大学等名 | C2: 神戸市外国語大学
B3: プログラム名 | C3: 神戸市外国語大学数理・データサイエンス・AI 教育プログラム(KCUFS-DASH)
A5: リテラシーレベルのプログラムを構成する授業科目について
A7: ① 教育プログラムの修了要件 | L7: 学部・学科によって、修了要件は相違しない
A9: ② 対象となる学部・学科名称
A14: ③ 修了要件
B15: 全学共通科目（自然・人間科学領域）から「キャンパスライフ入門」（2単位）と「データサイエンス入門」（2単位）いずれの単位も修得すること。 | X15: 【プルダウンリスト】
X16: 令和６年度以前より、履修することが必須のプログラムとして実施
X17: 令和９年度までに履修必須とする計画
X18: 令和１０年度以降に履修必須とする計画、又は未定
B22: 必要最低科目数・単位数 | E22: 2 | F22: 科目 | H22: 4 | I22: 単位 | M22: 履修必須の有無 | N22: 令和６年度以前より、履修することが必須のプログラムとして実施
A24: ④ 現在進行中の社会変化（第４次産業革命、Society 5.0、データ駆動型社会等）に深く寄与しているものであり、それが自らの生活と密接に結びついている」の内容を含む授業科目
B26: 授業科目 | G26: 単位数 | H26: 必須 | I26: 1-1 | J26: 1-6 | K26: 授業科目 | R26: 単位数 | S26: 必須 | T26: 1-1 | U26: 1-6
B27: キャンパスライフ入門 | G27: 2 | H27: ○ | I27: ○ | J27: ○
B28: データサイエンス入門 | G28: 2 | H28: ○ | I28: ○ | J28: ○
A35: ⑤ 「社会で活用されているデータ」や「データの活用領域」は非常に広範囲であって、日常生活や社会の課題を解決する有用なツールになり得るもの」の内容を含む授業科目
B37: 授業科目 | G37: 単位数 | H37: 必須 | I37: 1-2 | J37: 1-3 | K37: 授業科目 | R37: 単位数 | S37: 必須 | T37: 1-2 | U37: 1-3
B38: キャンパスライフ入門 | G38: 2 | H38: ○ | I38: ○ | J38: ○
B39: データサイエンス入門 | G39: 2 | H39: ○ | I39: ○ | J39: ○
A46: ⑥ 「様々なデータ利活用の現場におけるデータ利活用事例が示され、様々な適用領域（流通、製造、金融、サービス、インフラ、公共、ヘルスケア等）の知見と組み合わせることで価値を創出するもの」の内容を含む授業科目
B48: 授業科目 | G48: 単位数 | H48: 必須 | I48: 1-4 | J48: 1-5 | K48: 授業科目 | R48: 単位数 | S48: 必須 | T48: 1-4 | U48: 1-5
B49: キャンパスライフ入門 | G49: 2 | H49: ○ | I49: ○ | J49: ○
B50: データサイエンス入門 | G50: 2 | H50: ○ | I50: ○
A57: ⑦ 「活用に当たっての様々な留意事項（ELSI、個人情報、データ倫理、ＡＩ社会原則等）を考慮し、情報セキュリティや情報漏洩等、データを守る上での留意事項への理解をする」の内容を含む授業科目
B59: 授業科目 | G59: 単位数 | H59: 必須 | I59: 3-1 | J59: 3-2 | K59: 授業科目 | R59: 単位数 | S59: 必須 | T59: 3-1 | U59: 3-2
B60: キャンパスライフ入門 | G60: 2 | H60: ○ | I60: ○ | J60: ○
A68: ⑧ 「実データ・実課題（学術データ等を含む）を用いた演習など、社会での実例を題材として、「データを読む、説明する、扱う」といった数理・データサイエンス・ＡＩの基本的な活用法に関するもの」の内容を含む授業科目
B70: 授業科目 | F70: 単位数 | G70: 必須 | H70: 2-1 | I70: 2-2 | J70: 2-3 | K70: 授業科目 | Q70: 単位数 | R70: 必須 | S70: 2-1 | T70: 2-2 | U70: 2-3
B71: キャンパスライフ入門 | F71: 2 | G71: ○ | H71: ○ | I71: ○ | J71: ○
B72: データサイエンス入門 | F72: 2 | G72: ○ | H72: ○ | I72: ○ | J72: ○
A79: ⑨ 選択「４．オプション」の内容を含む授業科目
B80: 授業科目 | G80: 選択項目 | K80: 授業科目 | R80: 選択項目 | AA80: 4-1統計および数理基礎
B81: キャンパスライフ入門 | G81: 4-1統計および数理基礎 | K81: データサイエンス入門 | R81: 4‐7データハンドリング | AA81: 4‐2アルゴリズム基礎
B82: キャンパスライフ入門 | G82: 4‐8データ活用実践（教師あり学習） | AA82: 4‐3データ構造とプログラミング基礎
B83: データサイエンス入門 | G83: 4-1統計および数理基礎 | AA83: 4‐4時系列データ解析
B84: データサイエンス入門 | G84: 4‐3データ構造とプログラミング基礎 | AA84: 4‐5自然言語処理
B85: データサイエンス入門 | G85: 4‐4時系列データ解析 | AA85: 4‐6画像認識
B86: データサイエンス入門 | G86: 4‐5自然言語処理 | AA86: 4‐7データハンドリング
B87: データサイエンス入門 | G87: 4‐6画像認識 | AA87: 4‐8データ活用実践（教師あり学習）
...

Sheet 様式２ 履修者等数の実績
S1: 様式２
Q2: ='様式１ プログラムを構成する授業科目 '!C2 -> 神戸市外国語大学
A3: リテラシーレベルのプログラムの履修者数等の実績について
A5: ①プログラム開設年度 | C5: 令和６ | E5: 年度（和暦）
A7: ②大学等全体の男女別学生数 | E7: 男性 | F7: 670 | G7: 人 | H7: 女性 | I7: 1416 | J7: 人 | K7: （ | L7: 合計 | M7: =F7+I7 -> 2086 | N7: 人 | O7: ）
B8: （令和６年５月１日時点）
A9: ③履修者・修了者の実績
B11: 学部・学科名称 | C11: 学生数 | D11: 入学 定員 | E11: 収容 定員 | F11: 令和6年度 | H11: 令和5年度 | J11: 令和4年度 | L11: 令和3年度 | N11: 令和2年度 | P11: 令和元年度 | R11: 履修者数 合計 | S11: 履修率
F12: 履修者数 | G12: 修了者数 | H12: 履修者数 | I12: 修了者数 | J12: 履修者数 | K12: 修了者数 | L12: 履修者数 | M12: 修了者数 | N12: 履修者数 | O12: 修了者数 | P12: 履修者数 | Q12: 修了者数
B13: 外国語学部英米学科 | C13: 691 | D13: 140 | E13: 560 | F13: 143 | G13: 127 | R13: =F13+H13+J13+L13+N13+P13 -> 143 | S13: =R13/E13 -> 0.25535714
B14: 外国語学部ロシア学科 | C14: 183 | D14: 40 | E14: 160 | F14: 45 | G14: 34 | R14: =F14+H14+J14+L14+N14+P14 -> 45 | S14: =R14/E14 -> 0.28125
B15: 外国語学部中国学科 | C15: 239 | D15: 50 | E15: 200 | F15: 49 | G15: 39 | R15: =F15+H15+J15+L15+N15+P15 -> 49 | S15: =R15/E15 -> 0.245
B16: 外国語学部イスパニア学科 | C16: 196 | D16: 40 | E16: 160 | F16: 43 | G16: 34 | R16: =F16+H16+J16+L16+N16+P16 -> 43 | S16: =R16/E16 -> 0.26875
B17: 外国語学部国際関係学科 | C17: 392 | D17: 80 | E17: 320 | F17: 85 | G17: 75 | R17: =F17+H17+J17+L17+N17+P17 -> 85 | S17: =R17/E17 -> 0.265625
B18: 外国語学部第２部英米学科 | C18: 385 | D18: 80 | E18: 320 | F18: 86 | G18: 72 | R18: =F18+H18+J18+L18+N18+P18 -> 86 | S18: =R18/E18 -> 0.26875
R19: =F19+H19+J19+L19+N19+P19 -> 0 | S19: =R19/E19 -> #DIV/0!
R20: =F20+H20+J20+L20+N20+P20 -> 0 | S20: =R20/E20 -> #DIV/0!
R21: =F21+H21+J21+L21+N21+P21 -> 0 | S21: =R21/E21 -> #DIV/0!
R22: =F22+H22+J22+L22+N22+P22 -> 0 | S22: =R22/E22 -> #DIV/0!
R23: =F23+H23+J23+L23+N23+P23 -> 0 | S23: =R23/E23 -> #DIV/0!
R24: =F24+H24+J24+L24+N24+P24 -> 0 | S24: =R24/E24 -> #DIV/0!
R25: =F25+H25+J25+L25+N25+P25 -> 0 | S25: =R25/E25 -> #DIV/0!
R26: =F26+H26+J26+L26+N26+P26 -> 0 | S26: =R26/E26 -> #DIV/0!
R27: =F27+H27+J27+L27+N27+P27 -> 0 | S27: =R27/E27 -> #DIV/0!
R28: =F28+H28+J28+L28+N28+P28 -> 0 | S28: =R28/E28 -> #DIV/0!
R29: =F29+H29+J29+L29+N29+P29 -> 0 | S29: =R29/E29 -> #DIV/0!
R30: =F30+H30+J30+L30+N30+P30 -> 0 | S30: =R30/E30 -> #DIV/0!
... R32: =F32+H32+J32+L32+N32+P32 -> 0 | S32: =R32/E32 -> #DIV/0!
B33: 合 計 | C33: =SUM(C13:C32) -> 2086 | D33: =SUM(D13:D32) -> 430 | E33: =SUM(E13:E32) -> 1720 | F33: =SUM(F13:F32) -> 451 | G33: =SUM(G13:G32) -> 381 | H33: =SUM(H13:H32) -> 0 | I33: =SUM(I13:I32) -> 0 | J33: =SUM(J13:J32) -> 0 | ... R33: =SUM(R13:R32) -> 451 | S33: =R33/E33 -> 0.2622093

Sheet 様式３ 教育の質・履修者数を向上させるための体制・計画
I1: 様式３
G2: 大学等名 | H2: ='様式１ プログラムを構成する授業科目 '!C2 -> 神戸市外国語大学
A4: 教育の質・履修者数を向上させるための体制・計画について
A6: ① | B6: 全学の教員数 | C6: (常勤） | E6: 76 | F6: 人 | G6: （非常勤） | H6: 231 | I6: 人
A8: ② | B8: プログラムの授業を教えている教員数 | H8: 8 | I8: 人
A10: ③ | B10: プログラムの運営責任者
B11: （責任者名） | C11: 林 範彦 | G11: （役職名） | H11: 副学長
A13: ④ | B13: プログラムを改善・進化させるための体制（委員会・組織等）
B14: 神戸市外国語大学数理・データサイエンス・ＡＩ教育推進部会
B16: （責任者名） | C16: 林 範彦 | G16: （役職名） | H16: 副学長・部会長
A18: ⑤ | B18: プログラムを改善・進化させるための体制を定める規則名称
B19: 神戸市外国語大学数理・データサイエンス・ＡＩ教育推進部会規程
A21: ⑥ | B21: 体制の目的
B22: 神戸市公立大学法人教育研究評議会規則（2023年４月規則第60号）第７条第１項の規定に基づき神戸市外国語大学教育研究評議会に数理・データサイエンス・ＡＩ教育推進部会を設置する。 数理・データサイエンス・ＡＩ教育推進部会は、次の事項を審議する。 (1) 数理・データサイエンス・ＡＩ教育プログラムの企画、運営及び推進に関すること。 (2) 数理・データサイエンス・ＡＩ教育プログラムの点検、評価及び改善に関すること。 (3) その他数理・データサイエンス・ＡＩ教育プログラムに関すること。
A34: ⑦ | B34: 具体的な構成員
B35: 数理・データサイエンス・AI教育推進部会 部会長 林 範彦 （外国語学部総合文化教授） 数理・データサイエンス・AI教育推進部会 副部会長 前村 奈央佳 （外国語学部国際関係学科准教授） 数理・データサイエンス・AI教育推進部会 部会委員 中村 嘉孝 （外国語学部国際関係学科教授） 数理・データサイエンス・AI教育推進部会 部会委員 藤井 隆雄 （外国語学部国際関係学科教授） 数理・データサイエンス・AI教育推進部会 部会委員 関 陽介（外国語学部総合文化准教授） 数理・データサイエンス・AI教育推進部会 オブザーバー 芝 勝徳（本学名誉教授）
A48: ⑧ | B48: 履修者数・履修率の向上に向けた計画 ※様式１の「履修必須の有無」で「計画がある」としている場合は詳細について記載すること
B49: 令和６年度実績 | C49: ='様式２ 履修者等数の実績'!S33 -> 0.2622093 | E49: 令和７年度予定 | F49: 0.5 | H49: 令和８年度予定 | I49: 0.75
B50: 令和９年度予定 | C50: 0.95 | E50: 令和１０年度予定 | F50: 0.96 | H50: 収容定員（名） | I50: ='様式２ 履修者等数の実績'!E33 -> 1720
B51: 具体的な計画
B52: 本プログラムを設置した令和６年度に、１年生前期の必履修科目「初年次研修」を大幅に見直し、大学生に必要なデジタル時代の「読み・書き・そろばん」である数理・データサイエンス・AIに関する内容を盛り込んだ科目「キャンパスライフ入門」を新設。令和６年度以降の入学生については、１年生の必履修科目として、新入生全員が履修している。 同様に、令和６年度後期に「データサイエンス入門」を新設。令和６年度以降に入学した学生は全員が一度は履修する科目としてプログラムを設計した。 制度設計上は令和９年度には100%の学生が一度は履修することになるが、一定の割合で令和５年度以前入学生も在籍することが見込まれるため、100%となるのは制度上、令和５年度以前入学生が在学年限を迎えた後の令和12年度以降である。 なお、令和５年度以前入学生をはじめ、未履修・単位未修得の学生も履修可能であり、履修登録の時期に学内ポータルサイト、ホームページ、You Tube動画を通じて、全学生に対して積極的に本プログラムのPRを行っている。
A65: ⑨ | B65: 学部・学科に関係なく希望する学生全員が受講可能となるような必要な体制・取組等
B66: 本プログラムは、大学生に必要なデジタル時代の「読み・書き・そろばん」としての位置づけで１年生の必履修科目として設定している。本学は昼間部となる「学部」と夜間部となる「第２部」を設置しているが、所属に関わりなく受講が可能なように前期「キャンパスライフ入門」はオンデマンドで実施している。 他方、後期に実施している「データサイエンス入門」は実践的な側面を重視した授業である。ここでは高い学習効果が期待される対面クラスを展開するため、新入生クラスについては昼間部に４クラス、夜間部に１クラス設置している。さらに２年生以上が履修できるクラスを昼間部、夜間部にそれぞれ１クラスずつ開講している。
A79: ⑩ | B79: できる限り多くの学生が履修できるような具体的な周知方法・取組
B80: 新入生への履修ガイダンスにおいて、本学の数理・データサイエンス・AI教育プログラムについて説明、学生への周知を行っている。前期に行う「キャンパスライフ入門」のイントロダクションにおいても、同授業を含む本プログラムの全体像について説明している。また、令和５年度以前に入学した学生に対しては、本学HPやポータルサイトで案内を行いＰＲしているが、今後は広報班やキャリアサポートセンター等とも連携を行い、本プログラムの意義についてもＰＲしていきたいと考えている。
A93: ⑪ | B93: できる限り多くの学生が履修・修得できるようなサポート体制
B94: 前期「キャンパスライフ入門」は学部・学科特有の時間割に左右されないオンデマンド授業である。そのため、動画・課題は授業回毎に定められた期間内であれば何度も視聴が可能であり、個々の学生が自身の理解度にあわせて学習できる体制を整えている。後期「データサイエンス入門」では、より実践的な能力の開発を促す内容から、対面授業を展開しているが、きめ細やかな学習対応が必要となる。このため、本学ではデータサイエンス・アシスタント制度を導入している。同一法人内の神戸市立工業高等専門学校の本科4年生以上の学生の協力を得て、Excel（操作方法や関数の使用方法）やプログラミング（if、 for 等の簡単な処理）、PC 操作（主にWindows）の授業内でのサポートを行っている。
A107: ⑫ | B107: 授業時間内外で学習指導、質問を受け付ける具体的な仕組み
B108: 後期の対面で行っている「データサイエンス入門」の授業時間内では、⑪に記載したデータサイエンス・アシスタントを採用している。前期の「キャンパスライフ入門」ではオンデマンド授業のため、個別的な学習指導や質問受け付けは原則的に授業時間外となるが、本学のLMS「GAIDAI PASS」により随時質問の受付が可能である。またオフィスアワーを利用することで、対面・オンラインのいずれからも学生の質問に対応できる仕組みを用意している。

Sheet 様式４　自己点検・評価
I1: 様式４
H2: 大学等名 | I2: ='様式１ プログラムを構成する授業科目 '!C2 -> 神戸市外国語大学
A3: 自己点検・評価について
A5: ① | B5: プログラムの自己点検・評価を行う体制（委員会・組織等）
B6: 神戸市外国語大学数理・データサイエンス・ＡＩ教育推進部会
D8: （責任者名） | E8: 林 範彦 | G8: （役職名） | H8: 副学長・部会長
A10: ② | B10: 自己点検・評価体制における意見等
B11: 自己点検・評価の視点 | E11: 自己点検・評価体制における意見・結果・改善に向けた取組等
B12: 学内からの視点
C13: プログラムの履修・修得状況 | E13: 令和６年度は「キャンパスライフ入門」の履修者数533名、単位修得者数472名で88.6%の学生が単位修得した。「データサイエンス入門」の履修者数は464名、単位修得者数415名で89.4%の学生が単位修得した。いずれも高い単位修得率であり、プログラムの履修者451名の内、修了者は381名であった。プログラムとしても84.5%と高い修得率であり、本学学生の修学意欲の高さを改めて認識したところである。 履修・単位修得状況については、教務入試班から数理・データサイエンス・AI教育推進部会に報告、当該部会は授業評価アンケートの結果とあわせて自己点検・評価を行い、評価企画会議に報告している。
C14: 学修成果 | E14: 「キャンパスライフ入門」は単位認定科目であり、各回の課題提出状況・授業評価アンケートから読み取ったのは、数学が苦手な学生が多いということである。苦手ながらも懸命に取り組む姿勢が見られ、次年度のキャンパスライフ入門では、授業内で適宜フォロー解説を入れていただくことを担当教員に依頼した。 「データサイエンス入門」はGPの分布が0～4.5と広がっており、得意・不得意の差が現れた。しかしながら授業評価アンケートの学生の評価は高く、学生の満足度も高かったことから、授業の丁寧な取組が高い学修成果（単位修得率89.4%）につながったと認識している。
C15: 学生アンケート等を通じた学生の内容の理解度 | E15: 本学FD部会が実施する半期に一度の授業評価アンケートに数理・データサイエンス・AI教育プログラム独自の項目を追加し、細かな学習理解度や多面的な学修成果の把握を行っている。 「キャンパスライフ入門」「データサイエンス入門」いずれにおいても、数学の基礎的な内容で学生の理解度が低下する傾向があった。次年度は授業内で適宜フォロー解説を入れるよう担当教員に依頼している。 「キャンパスライフ入門」はオンデマンド授業であり、わからない箇所を何度も復習して見返せる点で好評であり、「データサイエンス入門」は、データサイエンス・アシスタントの導入により授業内でわからないことを聞ける点で好評であった。
C16: 学生アンケート等を通じた後輩等他の学生への推奨度 | E16: 授業評価アンケートに数理・データサイエンス・AI教育プログラム独自の項目を追加し、「よかった点」を記載させている。 「キャンパスライフ入門」においては、オンデマンド形式による柔軟な学習環境の提供と、幅広い分野の知識を得られる点で高い評価を得た。特に、リレー講義による多様な視点の提供や、学生自身のペースで学習できる点が好評であった。 「データサイエンス入門」においては、全体として丁寧な指導、質問しやすい環境、実践的な学びに高評価が集まった。 本学のプログラム設計上、新入生の必履修科目としているため、アンケート等による他の学生への推奨度が及ぼす影響は少ないと考えている。
C17: 全学的な履修者数、履修率向上に向けた計画の達成・進捗状況 | E17: 「キャンパスライフ入門」および「データサイエンス入門」は必履修としているため、休学者を除き、新入生の履修率は100％となる。全学的な履修率は毎年自動的にあがるプログラム設計となっており、令和５年度以前入学の学生についても、履修できるようにクラス編成を行っている。 令和６年度のプログラム履修者数451名の内1年生が436名、2～4年生が15名であったことから、次年度3・4年生の履修を増やすため、履修登録前にポータルサイト・HP等でプログラムの意義を説明するPRを行っている。 | J17: =LEN(E17) -> 239
B18: 学外からの視点
C19: 教育プログラム修了者の進路、活躍状況、企業等の評価 | E19: 本教育プログラムを修了した学生の情報をキャリアサポート部会に共有し、進路先を把握する予定である。その内の数社、ご協力いただける企業にアンケートを実施し、活躍状況、評価について伺うことを検討している。現在本学のプログラム履修者は１年生が主となっていることから、主な進路先把握は2027（令和９)年度以降の予定である。
C20: 産業界からの視点を含めた教育プログラム内容・手法等への意見 | E20: プログラム開始初年度は、経営協議会の外部委員に対してプログラム内容・手法に関するご意見を伺った。 今後は、本学学生向けの学内企業説明会に参加している企業に対してアンケートを実施し、教育プログラムの講義内容及び実データを活用した演習等の手法について意見を収集するとともに、数理・データサイエンス・AI教育推進部会においてプログラムの改善に活用する計画である。
B21: 数理・データサイエンス・ＡＩを「学ぶ楽しさ」「学ぶことの意義」を理解させること | E21: データサイエンス入門では、実習形式を採用しており、最初に統計やプログラミング、AI等の説明をした後に、ExcelまたはGoogle Colab（Python）を用いたデータ分析等の実施、課題提出を行っている。また、より実践的な作業を経験させるため、オープンデータとして公開されている気象庁の観測データや世界の人口推移、パリオリンピックのメダル数等も用いて分析している。Pythonは未経験の学生が多いため、大学側でコードを用意することで、より複雑な処理がプログラミングで可能なことを体験的に伝えている。
B22: 内容・水準を維持・向上しつつ、より「分かりやすい」授業とすること ※社会の変化や生成AI等の技術の発展を踏まえて教育内容を継続的に見直すなど、より教育効果の高まる授業内容・方法とするための取組や仕組みについても該当があれば記載 | E22: キャンパスライフ入門ではオンデマンド講義を採用しており、学生は任意の時間に受講可能な環境を構築している。データサイエンス入門では、文系の学生を考慮して数式を用いた説明は最小限として、可能な限りグラフやイラストを用いた視覚的な資料を作成・配布している。また、実習で用いる関数等は資料に記載しており、聞き洩らした・欠席した学生が課題に取り込める工夫をしている。両講義において、AIの発展は迅速であるため、毎年最新の技術を収集して学生に伝えている。
