Workbook

Sheet 様式１-１　プログラムを構成する授業科目
T1: 様式１－１ | V1: 「学部・学科によって、修了要件は相違する」場合は、本シートを複製の上＜様式１－〇＞と枝番号を付してください
B2: 大学等名 | C2: 藤田医科大学
B3: プログラム名 | C3: FHUデータサイエンス教育プログラム
A5: リテラシーレベルのプログラムを構成する授業科目について
A7: ① 教育プログラムの修了要件 | L7: 学部・学科によって、修了要件は相違する
A9: ② 対象となる学部・学科名称
B11: 医学部
A14: ③ 修了要件
B15: 医学部医学科においては、プログラムを構成する「基礎データサイエンス（医学科必修 2単位）」、「医学統計学（医学科必修 1単位）」を取得すること。 | X15: 【プルダウンリスト】
X16: 令和６年度以前より、履修することが必須のプログラムとして実施
X17: 令和９年度までに履修必須とする計画
X18: 令和１０年度以降に履修必須とする計画、又は未定
B22: 必要最低科目数・単位数 | E22: 2 | F22: 科目 | H22: 3 | I22: 単位 | M22: 履修必須の有無 | N22: 令和６年度以前より、履修することが必須のプログラムとして実施
A24: ④ 現在進行中の社会変化（第４次産業革命、Society 5.0、データ駆動型社会等）に深く寄与しているものであり、それが自らの生活と密接に結びついている」の内容を含む授業科目
B26: 授業科目 | G26: 単位数 | H26: 必須 | I26: 1-1 | J26: 1-6 | K26: 授業科目 | R26: 単位数 | S26: 必須 | T26: 1-1 | U26: 1-6
B27: 基礎データサイエンス | G27: 2 | H27: ○ | I27: ○ | J27: ○
A35: ⑤ 「社会で活用されているデータ」や「データの活用領域」は非常に広範囲であって、日常生活や社会の課題を解決する有用なツールになり得るもの」の内容を含む授業科目
B37: 授業科目 | G37: 単位数 | H37: 必須 | I37: 1-2 | J37: 1-3 | K37: 授業科目 | R37: 単位数 | S37: 必須 | T37: 1-2 | U37: 1-3
B38: 基礎データサイエンス | G38: 2 | H38: ○ | I38: ○ | J38: ○
A46: ⑥ 「様々なデータ利活用の現場におけるデータ利活用事例が示され、様々な適用領域（流通、製造、金融、サービス、インフラ、公共、ヘルスケア等）の知見と組み合わせることで価値を創出するもの」の内容を含む授業科目
B48: 授業科目 | G48: 単位数 | H48: 必須 | I48: 1-4 | J48: 1-5 | K48: 授業科目 | R48: 単位数 | S48: 必須 | T48: 1-4 | U48: 1-5
B49: 基礎データサイエンス | G49: 2 | H49: ○ | I49: ○ | J49: ○
A57: ⑦ 「活用に当たっての様々な留意事項（ELSI、個人情報、データ倫理、ＡＩ社会原則等）を考慮し、情報セキュリティや情報漏洩等、データを守る上での留意事項への理解をする」の内容を含む授業科目
B59: 授業科目 | G59: 単位数 | H59: 必須 | I59: 3-1 | J59: 3-2 | K59: 授業科目 | R59: 単位数 | S59: 必須 | T59: 3-1 | U59: 3-2
B60: 基礎データサイエンス | G60: 2 | H60: ○ | I60: ○ | J60: ○
A68: ⑧ 「実データ・実課題（学術データ等を含む）を用いた演習など、社会での実例を題材として、「データを読む、説明する、扱う」といった数理・データサイエンス・ＡＩの基本的な活用法に関するもの」の内容を含む授業科目
B70: 授業科目 | F70: 単位数 | G70: 必須 | H70: 2-1 | I70: 2-2 | J70: 2-3 | K70: 授業科目 | Q70: 単位数 | R70: 必須 | S70: 2-1 | T70: 2-2 | U70: 2-3
B71: 基礎データサイエンス | F71: 2 | G71: ○ | H71: ○ | I71: ○ | J71: ○
B72: 医学統計学 | F72: 1 | G72: ○ | H72: ○ | I72: ○ | J72: ○
A79: ⑨ 選択「４．オプション」の内容を含む授業科目
B80: 授業科目 | G80: 選択項目 | K80: 授業科目 | R80: 選択項目 | AA80: 4-1統計および数理基礎
B81: 医学統計学 | G81: 4-1統計および数理基礎 | AA81: 4‐2アルゴリズム基礎
B82: 医学統計学 | G82: 4‐7データハンドリング | AA82: 4‐3データ構造とプログラミング基礎
B83: 基礎データサイエンス | G83: 4-1統計および数理基礎 | AA83: 4‐4時系列データ解析
B84: 基礎データサイエンス | G84: 4‐3データ構造とプログラミング基礎 | AA84: 4‐5自然言語処理
B85: 基礎データサイエンス | G85: 4‐6画像認識 | AA85: 4‐6画像認識
B86: 基礎データサイエンス | G86: 4‐8データ活用実践（教師あり学習） | AA86: 4‐7データハンドリング
B87: 基礎データサイエンス | G87: 4‐9データ活用実践（教師なし学習） | AA87: 4‐8データ活用実践（教師あり学習）
AA88: 4‐9データ活用実践（教師なし学習）
A89: ⑩ プログラムを構成する授業の内容 | AA89: その他
...

Sheet 様式１－2　プログラムを構成する授業科目
T1: 様式１－２ | V1: 「学部・学科によって、修了要件は相違する」場合は、本シートを複製の上＜様式１－〇＞と枝番号を付してください
B2: 大学等名 | C2: 藤田医科大学
B3: プログラム名 | C3: FHUデータサイエンス教育プログラム
A5: リテラシーレベルのプログラムを構成する授業科目について
A7: ① 教育プログラムの修了要件 | L7: 学部・学科によって、修了要件は相違する
A9: ② 対象となる学部・学科名称
B11: 医療科学部
A14: ③ 修了要件
B15: 医療科学部においては、「データサイエンス」1単位及び「医療統計学」1単位の合計2単位を修得すること。 | X15: 【プルダウンリスト】
X16: 令和６年度以前より、履修することが必須のプログラムとして実施
X17: 令和９年度までに履修必須とする計画
X18: 令和１０年度以降に履修必須とする計画、又は未定
B22: 必要最低科目数・単位数 | E22: 2 | F22: 科目 | H22: 2 | I22: 単位 | M22: 履修必須の有無 | N22: 令和６年度以前より、履修することが必須のプログラムとして実施
A24: ④ 現在進行中の社会変化（第４次産業革命、Society 5.0、データ駆動型社会等）に深く寄与しているものであり、それが自らの生活と密接に結びついている」の内容を含む授業科目
B26: 授業科目 | G26: 単位数 | H26: 必須 | I26: 1-1 | J26: 1-6 | K26: 授業科目 | R26: 単位数 | S26: 必須 | T26: 1-1 | U26: 1-6
B27: データサイエンス | G27: 1 | H27: ○ | I27: ○ | J27: ○
A35: ⑤ 「社会で活用されているデータ」や「データの活用領域」は非常に広範囲であって、日常生活や社会の課題を解決する有用なツールになり得るもの」の内容を含む授業科目
B37: 授業科目 | G37: 単位数 | H37: 必須 | I37: 1-2 | J37: 1-3 | K37: 授業科目 | R37: 単位数 | S37: 必須 | T37: 1-2 | U37: 1-3
B38: データサイエンス | G38: 1 | H38: ○ | I38: ○ | J38: ○
A46: ⑥ 「様々なデータ利活用の現場におけるデータ利活用事例が示され、様々な適用領域（流通、製造、金融、サービス、インフラ、公共、ヘルスケア等）の知見と組み合わせることで価値を創出するもの」の内容を含む授業科目
B48: 授業科目 | G48: 単位数 | H48: 必須 | I48: 1-4 | J48: 1-5 | K48: 授業科目 | R48: 単位数 | S48: 必須 | T48: 1-4 | U48: 1-5
B49: 医療統計学 | G49: 1 | H49: ○ | I49: ○ | J49: ○
A57: ⑦ 「活用に当たっての様々な留意事項（ELSI、個人情報、データ倫理、ＡＩ社会原則等）を考慮し、情報セキュリティや情報漏洩等、データを守る上での留意事項への理解をする」の内容を含む授業科目
B59: 授業科目 | G59: 単位数 | H59: 必須 | I59: 3-1 | J59: 3-2 | K59: 授業科目 | R59: 単位数 | S59: 必須 | T59: 3-1 | U59: 3-2
B60: データサイエンス | G60: 1 | H60: ○ | I60: ○ | J60: ○
A68: ⑧ 「実データ・実課題（学術データ等を含む）を用いた演習など、社会での実例を題材として、「データを読む、説明する、扱う」といった数理・データサイエンス・ＡＩの基本的な活用法に関するもの」の内容を含む授業科目
B70: 授業科目 | F70: 単位数 | G70: 必須 | H70: 2-1 | I70: 2-2 | J70: 2-3 | K70: 授業科目 | Q70: 単位数 | R70: 必須 | S70: 2-1 | T70: 2-2 | U70: 2-3
B71: データサイエンス | F71: 1 | G71: ○ | H71: ○ | I71: ○ | J71: ○
B72: 医療統計学 | F72: 1 | G72: ○ | H72: ○ | I72: ○ | J72: ○
A79: ⑨ 選択「４．オプション」の内容を含む授業科目
B80: 授業科目 | G80: 選択項目 | K80: 授業科目 | R80: 選択項目
B81: 医療統計学 | G81: 4-1統計および数理基礎
A89: ⑩ プログラムを構成する授業の内容
B90: 授業に含まれている内容・要素 | D90: 講義内容
B91: （１）現在進行中の社会変化（第４次産業革命、Society 5.0、データ駆動型社会等）に深く寄与しているものであり、それが自らの生活と密接に結びついている | C91: 1-1 | D91: ・ビッグデータ、IoT、AI、データ量の増加、計算機の処理性能の向上、Society 5.0 「データサイエンス」（1回目）
C92: 1-6 | D92: ・AI最新技術の活用例（深層生成モデル、強化学習、転移学習、生成AIなど）「データサイエンス」（1回目,9回目）
B93: （２）「社会で活用されているデータ」や「データの活用領域」は非常に広範囲であって、日常生活や社会の課題を解決する有用なツールになり得るもの | C93: 1-2 | D93: ・調査データ、実験データ、人の行動ログデータ、機械の稼働ログデータなど「データサイエンス」（4回目） ・1次データ、2次データ、データのメタ化、構造化データ、非構造化データ（文章、画像/動画、音声/音楽など）「データサイエンス」（2回目)
C94: 1-3 | D94: ・データ・AI活用領域の広がり(生産、消費、文化活動など)「データサイエンス」（4回目）
B95: （３）様々なデータ利活用の現場におけるデータ利活用事例が示され、様々な適用領域（流通、製造、金融、サービス、インフラ、公共、ヘルスケア等）の知見と組み合わせることで価値を創出するもの | C95: 1-4 | D95: ・データ可視化：複合グラフ、2軸グラフ、多次元の可視化、関係性の可視化、挙動・軌跡の可視化「データ・サイエンス」（2,4回目） ・データ可視化：複合グラフ、関係性の可視化「医療統計学」（2,4,6,8,10回目） ・データ解析：予測「データ・サイエンス」（7,8回目）「医療統計学」（9～12回目）
C96: 1-5 | D96: ・データサイエンスのサイクル（データの取得・管理・加工）「データサイエンス」（4回目） ・ヘルスケア等におけるデータ・AI利活用事例紹介「データサイエンス」（1回目）
...

Sheet 様式１－3　プログラムを構成する授業科目
T1: 様式１－３ | V1: 「学部・学科によって、修了要件は相違する」場合は、本シートを複製の上＜様式１－〇＞と枝番号を付してください
B2: 大学等名 | C2: 藤田医科大学
B3: プログラム名 | C3: FHUデータサイエンス教育プログラム
A5: リテラシーレベルのプログラムを構成する授業科目について
A7: ① 教育プログラムの修了要件 | L7: 学部・学科によって、修了要件は相違する
A9: ② 対象となる学部・学科名称
B11: 保健衛生学部
A14: ③ 修了要件
B15: 学科ごとに認定された「認定科目」の単位を修得する。単位の修得によって本プログラムの修了が認定される。 保健衛生学部看護学科においては、「情報リテラシー」１単位、「データサイエンス」1単位、「看護研究方法論」1単位を修得すること。 また、「情報機器の操作」２単位、「保健統計学演習」１単位、も選択科目として履修可能。 保健衛生学部リハビリテーション学科においては、「基礎情報処理学」1単位、「統計学」1単位、「リハビリテーション情報工学」1単位、「運動学演習」１単位、「研究概論」1単位を修得すること。また、「数学」1単位、「医用情報処理学」1単位も選択科目として履修可能。 | X15: 【プルダウンリスト】
X16: 令和６年度以前より、履修することが必須のプログラムとして実施
X17: 令和９年度までに履修必須とする計画
X18: 令和１０年度以降に履修必須とする計画、又は未定
B22: 必要最低科目数・単位数 | E22: 3 | F22: 科目 | H22: 3 | I22: 単位 | M22: 履修必須の有無 | N22: 令和６年度以前より、履修することが必須のプログラムとして実施
A24: ④ 現在進行中の社会変化（第４次産業革命、Society 5.0、データ駆動型社会等）に深く寄与しているものであり、それが自らの生活と密接に結びついている」の内容を含む授業科目
B26: 授業科目 | G26: 単位数 | H26: 必須 | I26: 1-1 | J26: 1-6 | K26: 授業科目 | R26: 単位数 | S26: 必須 | T26: 1-1 | U26: 1-6
B27: 情報リテラシー | G27: 1 | H27: ○ | I27: ○ | K27: 基礎情報処理学 | R27: 1 | S27: ○ | T27: ○
B28: データサイエンス | G28: 1 | H28: ○ | I28: ○ | J28: ○ | K28: 医用情報処理学 | R28: 1 | T28: ○ | U28: ○
B29: 保健統計学演習 | G29: 1 | I29: ○ | J29: ○ | K29: リハビリテーション情報工学 | R29: 1 | S29: ○ | T29: ○ | U29: ○
A35: ⑤ 「社会で活用されているデータ」や「データの活用領域」は非常に広範囲であって、日常生活や社会の課題を解決する有用なツールになり得るもの」の内容を含む授業科目
B37: 授業科目 | G37: 単位数 | H37: 必須 | I37: 1-2 | J37: 1-3 | K37: 授業科目 | R37: 単位数 | S37: 必須 | T37: 1-2 | U37: 1-3
B38: 情報リテラシー | G38: 1 | H38: ○ | I38: ○ | J38: ○ | K38: 医用情報処理学 | R38: 1 | T38: ○ | U38: ○
B39: データサイエンス | G39: 1 | H39: ○ | I39: ○ | J39: ○ | K39: リハビリテーション情報工学 | R39: 1 | S39: ○ | U39: ○
B40: 保健統計学演習 | G40: 1 | I40: ○ | J40: ○ | K40: 運動学演習 | R40: 1 | S40: ○ | T40: ○
A46: ⑥ 「様々なデータ利活用の現場におけるデータ利活用事例が示され、様々な適用領域（流通、製造、金融、サービス、インフラ、公共、ヘルスケア等）の知見と組み合わせることで価値を創出するもの」の内容を含む授業科目
B48: 授業科目 | G48: 単位数 | H48: 必須 | I48: 1-4 | J48: 1-5 | K48: 授業科目 | R48: 単位数 | S48: 必須 | T48: 1-4 | U48: 1-5
B49: 情報リテラシー | G49: 1 | H49: ○ | J49: ○ | K49: 医用情報処理学 | R49: 1 | T49: ○ | U49: ○
B50: データサイエンス | G50: 1 | H50: ○ | I50: ○ | J50: ○ | K50: リハビリテーション情報工学 | R50: 1 | S50: ○ | T50: ○ | U50: ○
B51: 情報機器の操作 | G51: 2 | I51: ○ | K51: 運動学演習 | R51: 1 | S51: ○ | T51: ○
B52: 保健統計学演習 | G52: 1 | I52: ○ | J52: ○ | K52: 基礎情報処理学 | R52: 1 | S52: ○ | T52: ○
A57: ⑦ 「活用に当たっての様々な留意事項（ELSI、個人情報、データ倫理、ＡＩ社会原則等）を考慮し、情報セキュリティや情報漏洩等、データを守る上での留意事項への理解をする」の内容を含む授業科目
B59: 授業科目 | G59: 単位数 | H59: 必須 | I59: 3-1 | J59: 3-2 | K59: 授業科目 | R59: 単位数 | S59: 必須 | T59: 3-1 | U59: 3-2
B60: 情報リテラシー | G60: 1 | H60: ○ | I60: ○ | J60: ○ | K60: 基礎情報処理学 | R60: 1 | S60: ○ | U60: ○
B61: データサイエンス | G61: 1 | H61: ○ | I61: ○ | J61: ○ | K61: 研究概論 | R61: 1 | S61: ○ | T61: ○
B62: 看護研究方法論 | G62: 1 | H62: ○ | I62: ○ | J62: ○ | K62: 医用情報処理学 | R62: 1 | T62: ○
B63: 保健統計学演習 | G63: 1 | I63: ○ | J63: ○ | K63: リハビリテーション情報工学 | R63: 1 | S63: ○ | T63: ○
A68: ⑧ 「実データ・実課題（学術データ等を含む）を用いた演習など、社会での実例を題材として、「データを読む、説明する、扱う」といった数理・データサイエンス・ＡＩの基本的な活用法に関するもの」の内容を含む授業科目
B70: 授業科目 | F70: 単位数 | G70: 必須 | H70: 2-1 | I70: 2-2 | J70: 2-3 | K70: 授業科目 | Q70: 単位数 | R70: 必須 | S70: 2-1 | T70: 2-2 | U70: 2-3
B71: 情報リテラシー | F71: 1 | G71: ○ | H71: ○ | I71: ○ | J71: ○ | K71: 基礎情報処理学 | Q71: 1 | R71: ○ | S71: ○ | T71: ○
B72: データサイエンス | F72: 1 | G72: ○ | H72: ○ | I72: ○ | J72: ○ | K72: 統計学 | Q72: 1 | R72: ○ | S72: ○ | T72: ○
B73: 情報機器の操作 | F73: 2 | H73: ○ | I73: ○ | J73: ○ | K73: 数学 | Q73: 1 | S73: ○ | T73: ○
...

Sheet 様式２ 履修者等数の実績
S1: 様式２
Q2: ='様式１-１ プログラムを構成する授業科目'!C2 -> 藤田医科大学
A3: リテラシーレベルのプログラムの履修者数等の実績について
A5: ①プログラム開設年度 | C5: 令和6 | E5: 年度（和暦）
A7: ②大学等全体の男女別学生数 | E7: 男性 | F7: 963 | G7: 人 | H7: 女性 | I7: 1792 | J7: 人 | K7: （ | L7: 合計 | M7: =F7+I7 -> 2755 | N7: 人 | O7: ）
B8: （令和６年５月１日時点）
A9: ③履修者・修了者の実績
B11: 学部・学科名称 | C11: 学生数 | D11: 入学 定員 | E11: 収容 定員 | F11: 令和6年度 | H11: 令和5年度 | J11: 令和4年度 | L11: 令和3年度 | N11: 令和2年度 | P11: 令和元年度 | R11: 履修者数 合計 | S11: 履修率 | W11: =C13+C14+C15 -> 2755
F12: 履修者数 | G12: 修了者数 | H12: 履修者数 | I12: 修了者数 | J12: 履修者数 | K12: 修了者数 | L12: 履修者数 | M12: 修了者数 | N12: 履修者数 | O12: 修了者数 | P12: 履修者数 | Q12: 修了者数
B13: 医学部 | C13: 737 | D13: 120 | E13: 720 | F13: 130 | G13: 121 | R13: =F13+H13+J13+L13+N13+P13 -> 130 | S13: =R13/E13 -> 0.18055556 | V13: 医学部 | W13: 737
B14: 医療科学部 | C14: 957 | D14: 230 | E14: 920 | F14: 240 | G14: 238 | R14: =F14+H14+J14+L14+N14+P14 -> 240 | S14: =R14/E14 -> 0.26086957 | V14: 医療科学部 | W14: 588
B15: 保健衛生学部 | C15: 1061 | D15: 250 | E15: 1000 | F15: 279 | G15: 265 | R15: =F15+H15+J15+L15+N15+P15 -> 279 | S15: =R15/E15 -> 0.279 | V15: 医療科学部・放射線学科 | W15: 369
R16: =F16+H16+J16+L16+N16+P16 -> 0 | S16: =R16/E16 -> #DIV/0! | V16: 保健衛生学部・看護学科 | W16: 562
R17: =F17+H17+J17+L17+N17+P17 -> 0 | S17: =R17/E17 -> #DIV/0! | V17: 保健衛生学部・リハビリテーション学科 | W17: 499
R18: =F18+H18+J18+L18+N18+P18 -> 0 | S18: =R18/E18 -> #DIV/0!
R19: =F19+H19+J19+L19+N19+P19 -> 0 | S19: =R19/E19 -> #DIV/0!
R20: =F20+H20+J20+L20+N20+P20 -> 0 | S20: =R20/E20 -> #DIV/0!
R21: =F21+H21+J21+L21+N21+P21 -> 0 | S21: =R21/E21 -> #DIV/0!
R22: =F22+H22+J22+L22+N22+P22 -> 0 | S22: =R22/E22 -> #DIV/0!
R23: =F23+H23+J23+L23+N23+P23 -> 0 | S23: =R23/E23 -> #DIV/0!
R24: =F24+H24+J24+L24+N24+P24 -> 0 | S24: =R24/E24 -> #DIV/0!
R25: =F25+H25+J25+L25+N25+P25 -> 0 | S25: =R25/E25 -> #DIV/0!
R26: =F26+H26+J26+L26+N26+P26 -> 0 | S26: =R26/E26 -> #DIV/0!
R27: =F27+H27+J27+L27+N27+P27 -> 0 | S27: =R27/E27 -> #DIV/0!
R28: =F28+H28+J28+L28+N28+P28 -> 0 | S28: =R28/E28 -> #DIV/0!
R29: =F29+H29+J29+L29+N29+P29 -> 0 | S29: =R29/E29 -> #DIV/0!
... R32: =F32+H32+J32+L32+N32+P32 -> 0 | S32: =R32/E32 -> #DIV/0!
B33: 合 計 | C33: =SUM(C13:C32) -> 2755 | D33: =SUM(D13:D32) -> 600 | E33: =SUM(E13:E32) -> 2640 | F33: =SUM(F13:F32) -> 649 | G33: =SUM(G13:G32) -> 624 | H33: =SUM(H13:H32) -> 0 | I33: =SUM(I13:I32) -> 0 | J33: =SUM(J13:J32) -> 0 | ... R33: =SUM(R13:R32) -> 649 | S33: =R33/E33 -> 0.24583333

Sheet 様式３ 教育の質・履修者数を向上させるための体制・計画
I1: 様式３
G2: 大学等名 | H2: ='様式１-１ プログラムを構成する授業科目'!C2 -> 藤田医科大学
A4: 教育の質・履修者数を向上させるための体制・計画について
A6: ① | B6: 全学の教員数 | C6: (常勤） | E6: 1303 | F6: 人 | G6: （非常勤） | H6: 281 | I6: 人
A8: ② | B8: プログラムの授業を教えている教員数 | H8: 78 | I8: 人
A10: ③ | B10: プログラムの運営責任者
B11: （責任者名） | C11: 長崎 弘 | G11: （役職名） | H11: 教育推進本部副本部長
A13: ④ | B13: プログラムを改善・進化させるための体制（委員会・組織等）
B14: 藤田医科大学 数理・データサイエンス・AI教育プログラム委員会
B16: （責任者名） | C16: 吉本 潤一郎 | G16: （役職名） | H16: 医学部教授/委員長
A18: ⑤ | B18: プログラムを改善・進化させるための体制を定める規則名称
B19: 藤田医科大学数理・データサイエンス・AI教育プログラム委員会規程
A21: ⑥ | B21: 体制の目的
B22: 本委員会は、藤田医科大学における数理・データサイエンス・AIに関する教育を全学的に統括し、学生の興味関心を高めつつ、基礎的能力から応用的活用力までを体系的に育成することを目的として、教育推進本部会議の下部組織として設置される。本委員会では、各学部の特性を生かした教育連携により、分野横断的な学びを促進し、将来の医療・生命科学分野におけるデータ駆動研究を実践できる人材の育成を図る。また、教育プログラムの企画・実施・評価を通じて継続的な質の向上を目指すとともに、外部機関との連携を通じて先進的かつ実践的な教育内容の充実を図る。
A34: ⑦ | B34: 具体的な構成員
B35: ＜委員長＞ 医学部 教授 吉本 潤一郎 ＜副委員長＞ 医学部 教授 長崎 弘 ＜委 員＞ 医療科学部 教授 鈴木 康司 医療科学部 准教授 武藤 晃一 保健衛生学部 教授 山田 晃司 保健衛生学部 准教授 皆川 敦子 保健衛生学部 准教授 小山 総市朗 大学事務局 学務部長 保科 豊次 （医学部） 学務課員 金子 祥子、櫻井 麗子 （医療科学部） 学務課員 羽根友弥、村川のぞみ、三浦真紀子 (保健衛生学部) 学務課員 坂井田 直孝、原 美佳、松原 睦
A48: ⑧ | B48: 履修者数・履修率の向上に向けた計画 ※様式１の「履修必須の有無」で「計画がある」としている場合は詳細について記載すること
B49: 令和６年度実績 | C49: ='様式２ 履修者等数の実績'!S33 -> 0.24583333 | E49: 令和７年度予定 | F49: 0.5 | H49: 令和８年度予定 | I49: 0.75
B50: 令和９年度予定 | C50: 1 | E50: 令和１０年度予定 | F50: 1 | H50: 収容定員（名） | I50: ='様式２ 履修者等数の実績'!E33 -> 2640
B51: 具体的な計画
B52: 本学では、すべての学部において、本プログラムを構成する1科目以上が必修科目であるため、履修率向上について具体的な計画・目標は定めない。一方で、社会的ニーズが高い生成AIに関する教育プログラムを充実させることで、数理・データサイエンス・AIに対する学生の関心と興味を引き付ける施策を実施する。具体的には、令和6年度に少人数で試行した生成AIに関する全学セミナーを、規模を拡大して令和7年度中に実施する。この講義資料や動画アーカイブは本プログラムに関わる教員に共有し、各学部で提供する授業科目でも再利用できるようにする。令和8年以降についても、受講生からのフィードバックをもとに検証・改善を進めながら本セミナーを継続する。また、本セミナーの受講生には、就職活動時の自己アピールに活用できるように、修了証のデジタル証明（オープンバッジ）を発行する。
A65: ⑨ | B65: 学部・学科に関係なく希望する学生全員が受講可能となるような必要な体制・取組等
B66: 本プログラム委員長である吉本潤一郎は、医学部において「基礎データサイエンス」と「医学統計学」の授業科目を分担している。医学部では、授業の様子をビデオアーカイブ化し、学生が授業後に閲覧できるVODのシステムをすでに導入している。このビデオアーカイブを他学部の学生も閲覧できるようにする。また、本委員会からは、数理・データサイエンス・AI教育強化拠点コンソーシアムで提供している講義資料・動画集の情報を定期的に学生に発信する。以上によって、希望する学生が自主的に学習できる環境を整える。
A79: ⑩ | B79: できる限り多くの学生が履修できるような具体的な周知方法・取組
B80: 本学のホームページで、本プログラムの概要や目的、意義を周知している。加えて、上記の通り、年に1回以上の頻度で数理・データサイエンス・AIに関する全学セミナーを開催し、多くの学生が興味を持ちそうなテーマに関する講演会やハンズオンを実施することで、本プログラムの有用性を再確認する機会を設けている。
A93: ⑪ | B93: できる限り多くの学生が履修・修得できるようなサポート体制
B94: 本教育プログラムの多くの授業については、学習管理システムMoodle上に講義資料や小テスト問題を蓄積しており、受講生がいつでも講義内容を閲覧したり、理解度を確認したりすることが可能な環境を構築している。
A107: ⑫ | B107: 授業時間内外で学習指導、質問を受け付ける具体的な仕組み
B108: すべての授業にはオフィスアワーを設けており、学生が個別に質問や相談に教員を訪問することが可能な仕組みを取り入れている。

Sheet 様式４　自己点検・評価
I1: 様式４
H2: 大学等名 | I2: ='様式１-１ プログラムを構成する授業科目'!C2 -> 藤田医科大学
A3: 自己点検・評価について
A5: ① | B5: プログラムの自己点検・評価を行う体制（委員会・組織等）
B6: 藤田医科大学 数理・データサイエンス・AI教育プログラム委員会
D8: （責任者名） | E8: 吉本 潤一郎 | G8: （役職名） | H8: 医学部教授/委員長
A10: ② | B10: 自己点検・評価体制における意見等
B11: 自己点検・評価の視点 | E11: 自己点検・評価体制における意見・結果・改善に向けた取組等
B12: 学内からの視点
C13: プログラムの履修・修得状況 | E13: プログラムの履修・習得状況については、各学部の学務課担当事務員が随時チェックしており、欠席超過者や成績不良者などが発見された場合には、その内容が各学部の教務委員会で共有され、必要に応じて学生との面談を実施している。年度末には、藤田医科大学数理・データサイエンス・AI教育プログラム委員会（以下、「本委員会」と呼ぶ）において、各科目コーディネーターに作成を依頼した自己点検票をもとに本プログラムの問題点の洗い出しやその解決策について議論し、必要に応じて科目コーディネーターへフィードバックしている。
C14: 学修成果 | E14: 全学教学運営委員会からの依頼のもと、IR推進センターおよび各学部IR分室で授業評価アンケートや学修実態調査などを学修成果に関連する調査の分析と評価を実施している。その結果を、全学教学運営委員会や教育推進本部会議が点検し、問題点の改善に向けた提言を行う。そのうち、FHUデータサイエンス教育プログラム（以下、「本プログラム」と呼ぶ）に関わるものについては、本委員会で具体的な施策を考案し、科目担当教員にその実践を依頼している。
C15: 学生アンケート等を通じた学生の内容の理解度 | E15: （本プログラムに限らず）すべての科目において、受講生は講義実施日ごとに授業評価アンケートに回答を求められ、各科目の講師は随時、その評価結果や学生からのコメントを確認できる。また、アンケート結果は教育推進本部会議においても点検・評価され、その結果をもとに改善や向上に向けた提言がなされる。その提言をもとに、本委員会で具体的な施策を考案し、科目担当教員にその実践を依頼する仕組みを構築している。
C16: 学生アンケート等を通じた後輩等他の学生への推奨度 | E16: 本プログラムを構成する科目は事実上の必修科目となっているため、後輩等他の学生へ推奨度の調査は実施しておらず、また、その必要はないものと考えている。一方で、本委員会が主催となって「数理・データサイエンス・AI教育のための全学セミナー」を年1回以上開催し、そのセミナー中に実施しているグループ演習やハンズオンでの議論を通して、学生本人やその学友の本プログラムへの関心を確認している。
C17: 全学的な履修者数、履修率向上に向けた計画の達成・進捗状況 | E17: 本プログラムを構成する科目は事実上の必修科目となっているため、基本的には履修率は100％達成となる。ただし、今まで各学部において個別に実施していた科目をプログラムとして運用を始めたのは令和6年度からであるため、収容定員と科目単位を取得する学年(時期)の関係で初年度はパーセンテージが低いが、令和9年度までには在学生全員が100％履修済となる見込みである（※医学部は6年制のため令和9年度の5・6年生については100％履修済見込みの算出対象外とする。）一方で、年度末には、本委員会が実施するプログラム自己点検において、各科目コーディネーターから学生の関心や学生のレベルに応じた講義が提供できているかについて自己点検票による聞き取り調査を行っている。
B18: 学外からの視点
C19: 教育プログラム修了者の進路、活躍状況、企業等の評価 | E19: 各学部学務課が卒業生の進路先は把握している。また、調査の必要があれば、IR推進センターや各学部のIR分室に本プログラムの修学が就職先でどの程度役立ったか等の調査は可能な体制にある。さらに、本学付属病院にも多くの卒業生が在籍しており、彼らの活躍状況や病院での評価を容易に調査できる体制にある。
C20: 産業界からの視点を含めた教育プログラム内容・手法等への意見 | E20: 医療系大学であるため、卒業生の多くは医療業務に携わっており、本学付属病院にも多くの卒業生が在籍している。配属先医局から本プログラムに関連する現場の課題が、全学教学運営委員会や教育推進本部会議に上がってくる仕組みが整っており、本プログラムの改善に活用できる体制にある。
B21: 数理・データサイエンス・ＡＩを「学ぶ楽しさ」「学ぶことの意義」を理解させること | E21: 上記の通り、本委員会が主催となって「数理・データサイエンス・AI教育のための全学セミナー」を年1回以上開催している。ここでは、学生・教職員が一緒にグループ演習に取り組むプログラムも組み入れており、参加者の自由な発想で課題設定をし、生成AIや統計処理技術など本プログラムが講義科目で提供する知識や技術を用いて問題解決に取り組むことを目標としている。このように、能動的な学びの場を提供することで、数理・データサイエンス・ＡＩを「学ぶ楽しさ」「学ぶことの意義」を理解させる取り組みを行っている。
B22: 内容・水準を維持・向上しつつ、より「分かりやすい」授業とすること ※社会の変化や生成AI等の技術の発展を踏まえて教育内容を継続的に見直すなど、より教育効果の高まる授業内容・方法とするための取組や仕組みについても該当があれば記載 | E22: 年度末に本プログラムを構成している科目のコーディネーターに、各科目で提供している講義の内容・実施方法・特徴、課題をまとめた自己点検票の作成を依頼している。本委員会では、自己点検票を回覧し、学生の理解や関心を向上させる授業方法や現場での課題を議論し、必要に応じて科目コーディネーターにフィードバックしている。加えて、上記の「数理・データサイエンス・AI教育のための全学セミナー」は新たなテーマや授業方法を試行するための模擬授業にもなっており、良いものは講義にも組み込むことを推奨する取り組みを行っている。
