Workbook

Sheet 様式１－１　プログラムを構成する授業科目
T1: 様式１－１ | V1: 「学部・学科によって、修了要件は相違する」場合は、本シートを複製の上＜様式１－〇＞と枝番号を付してください
B2: 大学等名 | C2: 酪農学園大学
B3: プログラム名 | C3: 酪農学園大学 数理・データサイエンス・AI教育プログラム
A5: リテラシーレベルのプログラムを構成する授業科目について
A7: ① 教育プログラムの修了要件 | L7: 学部・学科によって、修了要件は相違する
A9: ② 対象となる学部・学科名称
B11: 農食環境学群
A14: ③ 修了要件
B15: 以下の対象科目の単位を修得すること。 ・情報科学の基礎 ２単位 ・情報処理基礎演習 １単位 ・統計学Ⅰ ２単位 | X15: 【プルダウンリスト】
X16: 令和６年度以前より、履修することが必須のプログラムとして実施
X17: 令和９年度までに履修必須とする計画
X18: 令和１０年度以降に履修必須とする計画、又は未定
B22: 必要最低科目数・単位数 | E22: 3 | F22: 科目 | H22: 5 | I22: 単位 | M22: 履修必須の有無 | N22: 令和１０年度以降に履修必須とする計画、又は未定
A24: ④ 現在進行中の社会変化（第４次産業革命、Society 5.0、データ駆動型社会等）に深く寄与しているものであり、それが自らの生活と密接に結びついている」の内容を含む授業科目
B26: 授業科目 | G26: 単位数 | H26: 必須 | I26: 1-1 | J26: 1-6 | K26: 授業科目 | R26: 単位数 | S26: 必須 | T26: 1-1 | U26: 1-6
B27: 情報科学の基礎 | G27: 2 | H27: ○ | I27: ○ | J27: ○
A35: ⑤ 「社会で活用されているデータ」や「データの活用領域」は非常に広範囲であって、日常生活や社会の課題を解決する有用なツールになり得るもの」の内容を含む授業科目
B37: 授業科目 | G37: 単位数 | H37: 必須 | I37: 1-2 | J37: 1-3 | K37: 授業科目 | R37: 単位数 | S37: 必須 | T37: 1-2 | U37: 1-3
B38: 情報科学の基礎 | G38: 2 | H38: ○ | I38: ○ | J38: ○
A46: ⑥ 「様々なデータ利活用の現場におけるデータ利活用事例が示され、様々な適用領域（流通、製造、金融、サービス、インフラ、公共、ヘルスケア等）の知見と組み合わせることで価値を創出するもの」の内容を含む授業科目
B48: 授業科目 | G48: 単位数 | H48: 必須 | I48: 1-4 | J48: 1-5 | K48: 授業科目 | R48: 単位数 | S48: 必須 | T48: 1-4 | U48: 1-5
B49: 情報科学の基礎 | G49: 2 | H49: ○ | I49: ○ | J49: ○
A57: ⑦ 「活用に当たっての様々な留意事項（ELSI、個人情報、データ倫理、ＡＩ社会原則等）を考慮し、情報セキュリティや情報漏洩等、データを守る上での留意事項への理解をする」の内容を含む授業科目
B59: 授業科目 | G59: 単位数 | H59: 必須 | I59: 3-1 | J59: 3-2 | K59: 授業科目 | R59: 単位数 | S59: 必須 | T59: 3-1 | U59: 3-2
B60: 情報科学の基礎 | G60: 2 | H60: ○ | I60: ○ | J60: ○
A68: ⑧ 「実データ・実課題（学術データ等を含む）を用いた演習など、社会での実例を題材として、「データを読む、説明する、扱う」といった数理・データサイエンス・ＡＩの基本的な活用法に関するもの」の内容を含む授業科目
B70: 授業科目 | F70: 単位数 | G70: 必須 | H70: 2-1 | I70: 2-2 | J70: 2-3 | K70: 授業科目 | Q70: 単位数 | R70: 必須 | S70: 2-1 | T70: 2-2 | U70: 2-3
B71: 情報処理基礎演習 | F71: 1 | G71: ○ | I71: ○ | J71: ○
B72: 統計学Ⅰ | F72: 2 | G72: ○ | H72: ○
A79: ⑨ 選択「４．オプション」の内容を含む授業科目
B80: 授業科目 | G80: 選択項目 | K80: 授業科目 | R80: 選択項目 | AA80: 4-1統計および数理基礎
AA81: 4‐2アルゴリズム基礎
AA82: 4‐3データ構造とプログラミング基礎
AA83: 4‐4時系列データ解析
AA84: 4‐5自然言語処理
AA85: 4‐6画像認識
AA86: 4‐7データハンドリング
AA87: 4‐8データ活用実践（教師あり学習）
AA88: 4‐9データ活用実践（教師なし学習）
A89: ⑩ プログラムを構成する授業の内容 | AA89: その他
...

Sheet 様式１－２　プログラムを構成する授業科目
T1: 様式１－２ | V1: 「学部・学科によって、修了要件は相違する」場合は、本シートを複製の上＜様式１－〇＞と枝番号を付してください
B2: 大学等名 | C2: 酪農学園大学
B3: プログラム名 | C3: 酪農学園大学 数理・データサイエンス・AI教育プログラム
A5: リテラシーレベルのプログラムを構成する授業科目について
A7: ① 教育プログラムの修了要件 | L7: 学部・学科によって、修了要件は相違する
A9: ② 対象となる学部・学科名称
B11: 獣医学群
A14: ③ 修了要件
B15: 以下の対象科目の単位を修得すること。 ・情報科学の基礎 ２単位 ・情報処理基礎演習 １単位 ・統計学Ⅱ ２単位 | X15: 【プルダウンリスト】
X16: 令和６年度以前より、履修することが必須のプログラムとして実施
X17: 令和９年度までに履修必須とする計画
X18: 令和１０年度以降に履修必須とする計画、又は未定
B22: 必要最低科目数・単位数 | E22: 3 | F22: 科目 | H22: 5 | I22: 単位 | M22: 履修必須の有無 | N22: 令和１０年度以降に履修必須とする計画、又は未定
A24: ④ 現在進行中の社会変化（第４次産業革命、Society 5.0、データ駆動型社会等）に深く寄与しているものであり、それが自らの生活と密接に結びついている」の内容を含む授業科目
B26: 授業科目 | G26: 単位数 | H26: 必須 | I26: 1-1 | J26: 1-6 | K26: 授業科目 | R26: 単位数 | S26: 必須 | T26: 1-1 | U26: 1-6
B27: 情報科学の基礎 | G27: 2 | H27: ○ | I27: ○ | J27: ○
A35: ⑤ 「社会で活用されているデータ」や「データの活用領域」は非常に広範囲であって、日常生活や社会の課題を解決する有用なツールになり得るもの」の内容を含む授業科目
B37: 授業科目 | G37: 単位数 | H37: 必須 | I37: 1-2 | J37: 1-3 | K37: 授業科目 | R37: 単位数 | S37: 必須 | T37: 1-2 | U37: 1-3
B38: 情報科学の基礎 | G38: 2 | H38: ○ | I38: ○ | J38: ○
A46: ⑥ 「様々なデータ利活用の現場におけるデータ利活用事例が示され、様々な適用領域（流通、製造、金融、サービス、インフラ、公共、ヘルスケア等）の知見と組み合わせることで価値を創出するもの」の内容を含む授業科目
B48: 授業科目 | G48: 単位数 | H48: 必須 | I48: 1-4 | J48: 1-5 | K48: 授業科目 | R48: 単位数 | S48: 必須 | T48: 1-4 | U48: 1-5
B49: 情報科学の基礎 | G49: 2 | H49: ○ | I49: ○ | J49: ○
A57: ⑦ 「活用に当たっての様々な留意事項（ELSI、個人情報、データ倫理、ＡＩ社会原則等）を考慮し、情報セキュリティや情報漏洩等、データを守る上での留意事項への理解をする」の内容を含む授業科目
B59: 授業科目 | G59: 単位数 | H59: 必須 | I59: 3-1 | J59: 3-2 | K59: 授業科目 | R59: 単位数 | S59: 必須 | T59: 3-1 | U59: 3-2
B60: 情報科学の基礎 | G60: 2 | H60: ○ | I60: ○ | J60: ○
A68: ⑧ 「実データ・実課題（学術データ等を含む）を用いた演習など、社会での実例を題材として、「データを読む、説明する、扱う」といった数理・データサイエンス・ＡＩの基本的な活用法に関するもの」の内容を含む授業科目
B70: 授業科目 | F70: 単位数 | G70: 必須 | H70: 2-1 | I70: 2-2 | J70: 2-3 | K70: 授業科目 | Q70: 単位数 | R70: 必須 | S70: 2-1 | T70: 2-2 | U70: 2-3
B71: 情報処理基礎演習 | F71: 1 | G71: ○ | I71: ○ | J71: ○
B72: 統計学Ⅱ | F72: 2 | G72: ○ | H72: ○
A79: ⑨ 選択「４．オプション」の内容を含む授業科目
B80: 授業科目 | G80: 選択項目 | K80: 授業科目 | R80: 選択項目 | AA80: 4-1統計および数理基礎
AA81: 4‐2アルゴリズム基礎
AA82: 4‐3データ構造とプログラミング基礎
AA83: 4‐4時系列データ解析
AA84: 4‐5自然言語処理
AA85: 4‐6画像認識
AA86: 4‐7データハンドリング
AA87: 4‐8データ活用実践（教師あり学習）
AA88: 4‐9データ活用実践（教師なし学習）
A89: ⑩ プログラムを構成する授業の内容 | AA89: その他
...

Sheet 様式２ 履修者等数の実績
S1: 様式２
Q2: ='様式１－２ プログラムを構成する授業科目'!C2 -> 酪農学園大学
A3: リテラシーレベルのプログラムの履修者数等の実績について
A5: ①プログラム開設年度 | C5: 令和６ | E5: 年度（和暦）
A7: ②大学等全体の男女別学生数 | E7: 男性 | F7: 1389 | G7: 人 | H7: 女性 | I7: 1439 | J7: 人 | K7: （ | L7: 合計 | M7: =F7+I7 -> 2828 | N7: 人 | O7: ）
B8: （令和６年５月１日時点）
A9: ③履修者・修了者の実績
B11: 学部・学科名称 | C11: 学生数 | D11: 入学 定員 | E11: 収容 定員 | F11: 令和6年度 | H11: 令和5年度 | J11: 令和4年度 | L11: 令和3年度 | N11: 令和2年度 | P11: 令和元年度 | R11: 履修者数 合計 | S11: 履修率
F12: 履修者数 | G12: 修了者数 | H12: 履修者数 | I12: 修了者数 | J12: 履修者数 | K12: 修了者数 | L12: 履修者数 | M12: 修了者数 | N12: 履修者数 | O12: 修了者数 | P12: 履修者数 | Q12: 修了者数
B13: 農食環境学群 | C13: 1699 | D13: 520 | E13: 2080 | F13: 200 | G13: 0 | R13: =F13+H13+J13+L13+N13+P13 -> 200 | S13: =R13/E13 -> 0.096153846
B14: 獣医学群獣医学類 | C14: 853 | D14: 120 | E14: 720 | F14: 9 | G14: 0 | R14: =F14+H14+J14+L14+N14+P14 -> 9 | S14: =R14/E14 -> 0.0125
B15: 獣医学群獣医保健看護学類 | C15: 276 | D15: 60 | E15: 240 | F15: 2 | G15: 0 | R15: =F15+H15+J15+L15+N15+P15 -> 2 | S15: =R15/E15 -> 0.0083333333
R16: =F16+H16+J16+L16+N16+P16 -> 0 | S16: =R16/E16 -> #DIV/0!
R17: =F17+H17+J17+L17+N17+P17 -> 0 | S17: =R17/E17 -> #DIV/0!
R18: =F18+H18+J18+L18+N18+P18 -> 0 | S18: =R18/E18 -> #DIV/0!
R19: =F19+H19+J19+L19+N19+P19 -> 0 | S19: =R19/E19 -> #DIV/0!
R20: =F20+H20+J20+L20+N20+P20 -> 0 | S20: =R20/E20 -> #DIV/0!
R21: =F21+H21+J21+L21+N21+P21 -> 0 | S21: =R21/E21 -> #DIV/0!
R22: =F22+H22+J22+L22+N22+P22 -> 0 | S22: =R22/E22 -> #DIV/0!
R23: =F23+H23+J23+L23+N23+P23 -> 0 | S23: =R23/E23 -> #DIV/0!
R24: =F24+H24+J24+L24+N24+P24 -> 0 | S24: =R24/E24 -> #DIV/0!
R25: =F25+H25+J25+L25+N25+P25 -> 0 | S25: =R25/E25 -> #DIV/0!
R26: =F26+H26+J26+L26+N26+P26 -> 0 | S26: =R26/E26 -> #DIV/0!
R27: =F27+H27+J27+L27+N27+P27 -> 0 | S27: =R27/E27 -> #DIV/0!
... R32: =F32+H32+J32+L32+N32+P32 -> 0 | S32: =R32/E32 -> #DIV/0!
B33: 合 計 | C33: =SUM(C13:C32) -> 2828 | D33: =SUM(D13:D32) -> 700 | E33: =SUM(E13:E32) -> 3040 | F33: =SUM(F13:F32) -> 211 | G33: =SUM(G13:G32) -> 0 | H33: =SUM(H13:H32) -> 0 | I33: =SUM(I13:I32) -> 0 | J33: =SUM(J13:J32) -> 0 | ... R33: =SUM(R13:R32) -> 211 | S33: =R33/E33 -> 0.069407895

Sheet 様式３ 教育の質・履修者数を向上させるための体制・計画
I1: 様式３
G2: 大学等名 | H2: ='様式１－２ プログラムを構成する授業科目'!C2 -> 酪農学園大学
A4: 教育の質・履修者数を向上させるための体制・計画について
A6: ① | B6: 全学の教員数 | C6: (常勤） | E6: 194 | F6: 人 | G6: （非常勤） | H6: 79 | I6: 人
A8: ② | B8: プログラムの授業を教えている教員数 | H8: 13 | I8: 人
A10: ③ | B10: プログラムの運営責任者
B11: （責任者名） | C11: 上野 岳史 | G11: （役職名） | H11: 教育センター長
A13: ④ | B13: プログラムを改善・進化させるための体制（委員会・組織等）
B14: 酪農学園大学数理・データサイエンス・AI教育プログラム推進委員会
B16: （責任者名） | C16: 上野 岳史 | G16: （役職名） | H16: 教育センター長
A18: ⑤ | B18: プログラムを改善・進化させるための体制を定める規則名称
B19: 酪農学園大学教務委員会規程及び酪農学園大学数理・データサイエンス・AI教育プログラム推進委員会運営要領
A21: ⑥ | B21: 体制の目的
B22: 教務に関する重要な事項の協議並びに教育課程について、各学群・学類間の連絡・調整を円滑にすることを目的に設置されている「酪農学園大学教務委員会」の下に、「酪農学園大学数理・データサイエンス・AI教育プログラム（以下「プログラム」という。）」に関する事項を調査検討するための小委員会として、「酪農学園大学数理・データサイエンス・AI教育プログラム推進委員会」を設置した。 本小委員会は、プログラムの計画・策定を行い、適正に運用することを目的としており、次の事項を協議する。 （1）プログラムの開発、管理及び運営に関すること。 （2）学修支援及び情報公開に関すること。 （3）自己点検・自己評価及び改訂に関すること。 （4）その他プログラムに関すること。 | J22: =LEN(B22) -> 324 | K22: 400
A34: ⑦ | B34: 具体的な構成員
B35: 教育センター長 農食環境学群食と健康学類 教授 上野 岳史 学長が指名する教員３名 農食環境学群循環農学類 講師 毛利 泰大 農食環境学群環境共生学類 教授 星野 仏方 獣医学群獣医学類 准教授 安井 由美子 教務課長 中村 隆文
A48: ⑧ | B48: 履修者数・履修率の向上に向けた計画 ※様式１の「履修必須の有無」で「計画がある」としている場合は詳細について記載すること
B49: 令和６年度実績 | C49: ='様式２ 履修者等数の実績'!S33 -> 0.069407895 | E49: 令和７年度予定 | F49: 0.14 | H49: 令和８年度予定 | I49: 0.25
B50: 令和９年度予定 | C50: 0.4 | E50: 令和１０年度予定 | F50: 0.5 | H50: 収容定員（名） | I50: ='様式２ 履修者等数の実績'!E33 -> 3040
B51: 具体的な計画
B52: 本プログラムは、１年次開講科目である「情報科学の基礎」及び「情報処理基礎演習」、２年次開講科目である「統計学Ⅰ」または「統計学Ⅱ」の単位修得が修了要件となる２ヵ年にわたるプログラムとなっている。「情報科学の基礎」は選択科目となるが、他の科目は必修科目となるため、１学年に対して、どれだけ本プログラムの必要性を説明できるかが重要となる。また、本学においては、管理栄養士、獣医師、愛玩動物看護師を目指す食と健康学類管理栄養士コース（入学定員40名）、獣医学類（入学定員120名）、獣医保健看護学類（入学定員60名）があるため、この国家資格取得を目指す学生に対して、どのように当該プログラムへの理解を広めるかが、履修率向上のポイントとして捉えている。当面の計画としては、履修ガイダンスにおいて、プログラムの内容はもちろんであるが、身に付ける力と社会との関連性を重点的に説明し、当該科目の履修を促すこととし、当該プログラムを修了した学生のキャリア形成との関連性を検証することとしたい。 （注）食と健康学類管理栄養士コースの「情報科学の基礎」及び「情報処理基礎演習」は２年次開講科目となる。 | J52: =LEN(B52) -> 490 | K52: 500
A65: ⑨ | B65: 学部・学科に関係なく希望する学生全員が受講可能となるような必要な体制・取組等
B66: 本プログラムの対象科目は、農食環境学群及び獣医学群ともに「基盤教育」科目に配置されており、全学生が履修できる科目として、次のとおり開講している。 農食環境学群 ： １・２年次基盤教育科目 「情報科学の基礎」＝１年次開講科目（選択） 「情報処理基礎演習」＝１年次開講科目（必修） 「統計学Ⅰ」＝２年次開講科目（必修） （注）食と健康学類管理栄養士コースは、全ての科目が２年次開講科目となる。 獣医学群 ： １・２年次基盤教育科目 「情報科学の基礎」＝１年次開講科目（選択） 「情報処理基礎演習」＝１年次開講科目（必修） 「統計学Ⅱ」＝２年次開講科目（必修） | J66: =LEN(B66) -> 279 | K66: 400
A79: ⑩ | B79: できる限り多くの学生が履修できるような具体的な周知方法・取組
B80: 2025年度からは、ＨＰでの周知に加え、在学生が必ず使用するｅラーニングでの周知、また、2026年４月入学者に対しては、本学入学予定者が必ず確認する「新入生サイト」において当該プログラムの概要を掲載することで、入学前から必要科目履修の意識を高める取り組みを進める。 | J80: =LEN(B80) -> 132 | K80: 400
A93: ⑪ | B93: できる限り多くの学生が履修・修得できるようなサポート体制
B94: 本学では、入学時より学生ごとに「学生担当教員」を配置し、学生の諸活動をサポートしており、その中で、教務課職員と連携した履修登録に向けた相談にも対応している。また、構内における（ほぼ）全ての建物には、無線ＬＡＮが整備され、授業中はもちろん、授業外の時間においてもインターネットの利用が可能になっており、環境面でのサポートも行っている。 | J94: =LEN(B94) -> 166 | K94: 400
A107: ⑫ | B107: 授業時間内外で学習指導、質問を受け付ける具体的な仕組み
B108: 授業時間内での学習指導や質問等への対応は、各授業担当教員が行うことはもちろんであるが、授業時間外については、オフィスアワーの活用のほか、学生・教員・保護者が利用するポータルサイトである「ＵＮＩＰＡ」を活用することにより、オンラインでの対応も行っている。 | J108: =LEN(B108) -> 126 | K108: 400

Sheet 様式４　自己点検・評価
I1: 様式４
H2: 大学等名 | I2: ='様式１－２ プログラムを構成する授業科目'!C2 -> 酪農学園大学
A3: 自己点検・評価について
A5: ① | B5: プログラムの自己点検・評価を行う体制（委員会・組織等）
B6: 酪農学園大学数理・データサイエンス・AI教育プログラム推進委員会
D8: （責任者名） | E8: 上野 岳史 | G8: （役職名） | H8: 教育センター長
A10: ② | B10: 自己点検・評価体制における意見等
B11: 自己点検・評価の視点 | E11: 自己点検・評価体制における意見・結果・改善に向けた取組等
B12: 学内からの視点
C13: プログラムの履修・修得状況 | E13: 2024年度から本プログラムが開始され、１年次開講科目である「情報科学の基礎」及び「情報処理基礎演習」の履修者及び単位修得者は次のとおりである。 〇農食環境学群（食と健康学類（管理栄養士コースを除く）） 情報科学の基礎：履修者 200名、単位修得者 124名 情報処理基礎演習：履修者 359名、単位修得者 342名 〇獣医学群 情報科学の基礎：履修者 11名、単位修得者 11名 情報処理基礎演習：履修者 215名、単位修得者 208名 なお、2025年３月時点における「情報科学の基礎」及び「情報処理基礎演習」両方を修得した学生は135名である。 | K13: =LEN(E13) -> 280 | L13: 300
C14: 学修成果 | E14: 2024年度に履修した学生について、当該科目の到達目標を授業内課題及び期末試験により評価した結果は次のとおりであった。 【情報科学の基礎】 S：22名、A：30名、B：37名、C：46名、D（不合格）：56名、×（受験不可）20名 【情報処理基礎演習】 S：228名、A：177名、B：93名、C：52名、D（不合格）：7名、×（受験不可）17名 （注）受験不可：出席日数不足 「情報科学の基礎」について、D評価が多い点を懸念している。年度によるバラつきはあるものの、授業評価アンケートの結果や2025年度の状況も踏まえて、対応を検討していきたい。 | K14: =LEN(E14) -> 275 | L14: 300
C15: 学生アンケート等を通じた学生の内容の理解度 | E15: 授業評価アンケートからは、「情報科学の基礎」及び「情報処理基礎演習」ともに、授業内容に興味を持って多くの知識を得ることができ、有意義な授業であったことが伺える。また、アンケートの自由記述に関しても批判的なコメントはなく、「社会に出た際に必要なスキルの基礎を身に付けることができる」という記述があった一方で、授業の進行速度が速いというコメントもあった。学生一人ひとりの理解度に違いがある中、どのように進行することが良いかを検討していく。 | K15: =LEN(E15) -> 217 | L15: 300
C16: 学生アンケート等を通じた後輩等他の学生への推奨度 | E16: 授業評価アンケートの項目には、「後輩等他の学生への推奨度」という項目はないものの、自由記述には「将来に役立つ」や「ゼミなどで活用できそう」というコメントがあることから、後輩等他の学生への推奨度は高いものと推察できる。 | K16: =LEN(E16) -> 108 | L16: 300
C17: 全学的な履修者数、履修率向上に向けた計画の達成・進捗状況 | E17: 2024年度に開始したプログラムのため、学生への周知が十分に行えなった点があり、2025年度に入学した学生の履修状況は前年度と同水準となっているが、身に付ける力と社会との関連性を上手く説明することにより、学生の興味関心は高まるものと考えている。また、本学においては、国家資格取得を目指す食と健康学類（管理栄養士コース）、獣医学類、獣医保健看護学類の学生に対して、どのようにアプローチしていくかが課題と感じているため、その点を引き続き検討していきたい。 | K17: =LEN(E17) -> 225 | L17: 300
B18: 学外からの視点
C19: 教育プログラム修了者の進路、活躍状況、企業等の評価 | E19: 本プログラムは2024年度から開始し、２ヵ年にわたるプログラムとなるため、現在はまだ修了者はいない。 2024年４月以降に入学した学生を対象としており、現２学年で対象科目の単位を修得した学生が初めての修了者となる。その後、卒業・就職までに２年あるが、当該学生が就職後は、キャリアセンターとも連携し、企業へのアンケート調査等により状況把握を行っていきたい。 | K19: =LEN(E19) -> 177 | L19: 300
C20: 産業界からの視点を含めた教育プログラム内容・手法等への意見 | E20: 現時点では意見収集を行っていないが、本学においては、2026年４月に開設予定の「農環境情報学類」の届出申請準備の中で、企業への聞き取り調査を行っていることから、「情報の力」をもった人材のニーズ等を把握しながら対応を進めていきたい。 | K20: =LEN(E20) -> 115 | L20: 300
B21: 数理・データサイエンス・ＡＩを「学ぶ楽しさ」「学ぶことの意義」を理解させること | E21: データの分析を通して、意外な事実や興味深い相関関係を発見する演習を実施することで、学生がデータ分析の面白さを理解できる工夫をしている。さらに、分析結果をグラフや図などの視覚的な表現を用いた発表をすることで、学生が自身の学習成果を共有し、互いに刺激し合いながら学びを深めることができるように工夫している。 | K21: =LEN(E21) -> 151 | L21: 300
B22: 内容・水準を維持・向上しつつ、より「分かりやすい」授業とすること ※社会の変化や生成AI等の技術の発展を踏まえて教育内容を継続的に見直すなど、より教育効果の高まる授業内容・方法とするための取組や仕組みについても該当があれば記載 | E22: プログラムの受講生は、この分野の基礎知識をほとんど持たず、初めて学習する学生であることを前提として講義・演習を準備している。そして、eラーニングで授業動画を活用するなど、学生が十分に自学自習できる環境を整備するとともに、科目担当教員間でeラーニングの相互登録や演習問題の共有などを行うことによって、授業内容の改善に努めている。 | K22: =LEN(E22) -> 163 | L22: 300
