Workbook

Sheet 様式１－１　プログラムを構成する授業科目
T1: 様式１ー１ | V1: 「学部・学科によって、修了要件は相違する」場合は、本シートを複製の上＜様式１－〇＞と枝番号を付してください
B2: 大学等名 | C2: 青森中央学院大学
B3: プログラム名 | C3: データサイエンス・AI基礎プログラム
A5: リテラシーレベルのプログラムを構成する授業科目について
A7: ① 教育プログラムの修了要件 | L7: 学部・学科によって、修了要件は相違する
A9: ② 対象となる学部・学科名称
B11: 経営法学部
A14: ③ 修了要件
B15: データサイエンス・AI基礎の2単位を取得すること | X15: 【プルダウンリスト】
X16: 令和６年度以前より、履修することが必須のプログラムとして実施
X17: 令和９年度までに履修必須とする計画
X18: 令和１０年度以降に履修必須とする計画、又は未定
B22: 必要最低科目数・単位数 | E22: 1 | F22: 科目 | H22: 2 | I22: 単位 | M22: 履修必須の有無 | N22: 令和６年度以前より、履修することが必須のプログラムとして実施
A24: ④ 現在進行中の社会変化（第４次産業革命、Society 5.0、データ駆動型社会等）に深く寄与しているものであり、それが自らの生活と密接に結びついている」の内容を含む授業科目
B26: 授業科目 | G26: 単位数 | H26: 必須 | I26: 1-1 | J26: 1-6 | K26: 授業科目 | R26: 単位数 | S26: 必須 | T26: 1-1 | U26: 1-6
B27: データサイエンス・AI基礎 | G27: 2 | H27: ○ | I27: ○ | J27: ○
A35: ⑤ 「社会で活用されているデータ」や「データの活用領域」は非常に広範囲であって、日常生活や社会の課題を解決する有用なツールになり得るもの」の内容を含む授業科目
B37: 授業科目 | G37: 単位数 | H37: 必須 | I37: 1-2 | J37: 1-3 | K37: 授業科目 | R37: 単位数 | S37: 必須 | T37: 1-2 | U37: 1-3
B38: データサイエンス・AI基礎 | G38: 2 | H38: ○ | I38: ○ | J38: ○
A46: ⑥ 「様々なデータ利活用の現場におけるデータ利活用事例が示され、様々な適用領域（流通、製造、金融、サービス、インフラ、公共、ヘルスケア等）の知見と組み合わせることで価値を創出するもの」の内容を含む授業科目
B48: 授業科目 | G48: 単位数 | H48: 必須 | I48: 1-4 | J48: 1-5 | K48: 授業科目 | R48: 単位数 | S48: 必須 | T48: 1-4 | U48: 1-5
B49: データサイエンス・AI基礎 | G49: 2 | H49: ○ | I49: ○ | J49: ○
A57: ⑦ 「活用に当たっての様々な留意事項（ELSI、個人情報、データ倫理、ＡＩ社会原則等）を考慮し、情報セキュリティや情報漏洩等、データを守る上での留意事項への理解をする」の内容を含む授業科目
B59: 授業科目 | G59: 単位数 | H59: 必須 | I59: 3-1 | J59: 3-2 | K59: 授業科目 | R59: 単位数 | S59: 必須 | T59: 3-1 | U59: 3-2
B60: データサイエンス・AI基礎 | G60: 2 | H60: ○ | I60: ○ | J60: ○
A68: ⑧ 「実データ・実課題（学術データ等を含む）を用いた演習など、社会での実例を題材として、「データを読む、説明する、扱う」といった数理・データサイエンス・ＡＩの基本的な活用法に関するもの」の内容を含む授業科目
B70: 授業科目 | F70: 単位数 | G70: 必須 | H70: 2-1 | I70: 2-2 | J70: 2-3 | K70: 授業科目 | Q70: 単位数 | R70: 必須 | S70: 2-1 | T70: 2-2 | U70: 2-3
B71: データサイエンス・AI基礎 | F71: 2 | G71: ○ | H71: ○ | I71: ○ | J71: ○
A79: ⑨ 選択「４．オプション」の内容を含む授業科目
B80: 授業科目 | G80: 選択項目 | K80: 授業科目 | R80: 選択項目 | AA80: 4-1統計および数理基礎
AA81: 4‐2アルゴリズム基礎
AA82: 4‐3データ構造とプログラミング基礎
AA83: 4‐4時系列データ解析
AA84: 4‐5自然言語処理
AA85: 4‐6画像認識
AA86: 4‐7データハンドリング
AA87: 4‐8データ活用実践（教師あり学習）
AA88: 4‐9データ活用実践（教師なし学習）
A89: ⑩ プログラムを構成する授業の内容 | AA89: その他
B90: 授業に含まれている内容・要素 | D90: 講義内容
...

Sheet 様式１ー２　プログラムを構成する授業科目
T1: 様式１－２ | V1: 「学部・学科によって、修了要件は相違する」場合は、本シートを複製の上＜様式１－〇＞と枝番号を付してください
B2: 大学等名 | C2: 青森中央学院大学
B3: プログラム名 | C3: データサイエンス・AI基礎プログラム
A5: リテラシーレベルのプログラムを構成する授業科目について
A7: ① 教育プログラムの修了要件 | L7: 学部・学科によって、修了要件は相違する
A9: ② 対象となる学部・学科名称
B11: 看護学部
A14: ③ 修了要件
B15: 情報処理Ⅰの2単位を取得すること 情報処理Ⅱの1単位を取得すること | X15: 【プルダウンリスト】
X16: 令和６年度以前より、履修することが必須のプログラムとして実施
X17: 令和９年度までに履修必須とする計画
X18: 令和１０年度以降に履修必須とする計画、又は未定
B22: 必要最低科目数・単位数 | E22: 2 | F22: 科目 | H22: 3 | I22: 単位 | M22: 履修必須の有無 | N22: 令和６年度以前より、履修することが必須のプログラムとして実施
A24: ④ 現在進行中の社会変化（第４次産業革命、Society 5.0、データ駆動型社会等）に深く寄与しているものであり、それが自らの生活と密接に結びついている」の内容を含む授業科目
B26: 授業科目 | G26: 単位数 | H26: 必須 | I26: 1-1 | J26: 1-6 | K26: 授業科目 | R26: 単位数 | S26: 必須 | T26: 1-1 | U26: 1-6
B27: 情報処理Ⅰ | G27: 2 | H27: ○ | I27: ○ | J27: ○
A35: ⑤ 「社会で活用されているデータ」や「データの活用領域」は非常に広範囲であって、日常生活や社会の課題を解決する有用なツールになり得るもの」の内容を含む授業科目
B37: 授業科目 | G37: 単位数 | H37: 必須 | I37: 1-2 | J37: 1-3 | K37: 授業科目 | R37: 単位数 | S37: 必須 | T37: 1-2 | U37: 1-3
B38: 情報処理Ⅰ | G38: 2 | H38: ○ | J38: ○
B39: 情報処理Ⅱ | G39: 1 | H39: ○ | I39: ○
A46: ⑥ 「様々なデータ利活用の現場におけるデータ利活用事例が示され、様々な適用領域（流通、製造、金融、サービス、インフラ、公共、ヘルスケア等）の知見と組み合わせることで価値を創出するもの」の内容を含む授業科目
B48: 授業科目 | G48: 単位数 | H48: 必須 | I48: 1-4 | J48: 1-5 | K48: 授業科目 | R48: 単位数 | S48: 必須 | T48: 1-4 | U48: 1-5
B49: 情報処理Ⅱ | G49: 1 | H49: ○ | I49: ○ | J49: ○
A57: ⑦ 「活用に当たっての様々な留意事項（ELSI、個人情報、データ倫理、ＡＩ社会原則等）を考慮し、情報セキュリティや情報漏洩等、データを守る上での留意事項への理解をする」の内容を含む授業科目
B59: 授業科目 | G59: 単位数 | H59: 必須 | I59: 3-1 | J59: 3-2 | K59: 授業科目 | R59: 単位数 | S59: 必須 | T59: 3-1 | U59: 3-2
B60: 情報処理Ⅰ | G60: 2 | H60: ○ | I60: ○ | J60: ○
A68: ⑧ 「実データ・実課題（学術データ等を含む）を用いた演習など、社会での実例を題材として、「データを読む、説明する、扱う」といった数理・データサイエンス・ＡＩの基本的な活用法に関するもの」の内容を含む授業科目
B70: 授業科目 | F70: 単位数 | G70: 必須 | H70: 2-1 | I70: 2-2 | J70: 2-3 | K70: 授業科目 | Q70: 単位数 | R70: 必須 | S70: 2-1 | T70: 2-2 | U70: 2-3
B71: 情報処理Ⅱ | F71: 1 | G71: ○ | H71: ○ | I71: ○ | J71: ○
A79: ⑨ 選択「４．オプション」の内容を含む授業科目
B80: 授業科目 | G80: 選択項目 | K80: 授業科目 | R80: 選択項目 | AA80: 4-1統計および数理基礎
AA81: 4‐2アルゴリズム基礎
AA82: 4‐3データ構造とプログラミング基礎
AA83: 4‐4時系列データ解析
AA84: 4‐5自然言語処理
AA85: 4‐6画像認識
AA86: 4‐7データハンドリング
AA87: 4‐8データ活用実践（教師あり学習）
AA88: 4‐9データ活用実践（教師なし学習）
A89: ⑩ プログラムを構成する授業の内容 | AA89: その他
...

Sheet 様式２ 履修者等数の実績
S1: 様式２
Q2: ='様式１－１ プログラムを構成する授業科目'!C2 -> 青森中央学院大学
A3: リテラシーレベルのプログラムの履修者数等の実績について
A5: ①プログラム開設年度 | C5: 令和6 | E5: 年度（和暦）
A7: ②大学等全体の男女別学生数 | E7: 男性 | F7: 491 | G7: 人 | H7: 女性 | I7: 480 | J7: 人 | K7: （ | L7: 合計 | M7: =F7+I7 -> 971 | N7: 人 | O7: ）
B8: （令和６年５月１日時点）
A9: ③履修者・修了者の実績
B11: 学部・学科名称 | C11: 学生数 | D11: 入学 定員 | E11: 収容 定員 | F11: 令和6年度 | H11: 令和5年度 | J11: 令和4年度 | L11: 令和3年度 | N11: 令和2年度 | P11: 令和元年度 | R11: 履修者数 合計 | S11: 履修率
F12: 履修者数 | G12: 修了者数 | H12: 履修者数 | I12: 修了者数 | J12: 履修者数 | K12: 修了者数 | L12: 履修者数 | M12: 修了者数 | N12: 履修者数 | O12: 修了者数 | P12: 履修者数 | Q12: 修了者数
B13: 経営法学部 | C13: =454+205 -> 659 | D13: 165 | E13: 700 | F13: 132 | G13: 129 | R13: =F13+H13+J13+L13+N13+P13 -> 132 | S13: =R13/E13 -> 0.18857143
B14: 看護学部 | C14: =37+275 -> 312 | D14: 80 | E14: 320 | F14: 71 | G14: 69 | H14: 76 | I14: 76 | R14: =F14+H14+J14+L14+N14+P14 -> 147 | S14: =R14/E14 -> 0.459375
R15: =F15+H15+J15+L15+N15+P15 -> 0 | S15: =R15/E15 -> #DIV/0!
R16: =F16+H16+J16+L16+N16+P16 -> 0 | S16: =R16/E16 -> #DIV/0!
R17: =F17+H17+J17+L17+N17+P17 -> 0 | S17: =R17/E17 -> #DIV/0!
R18: =F18+H18+J18+L18+N18+P18 -> 0 | S18: =R18/E18 -> #DIV/0!
R19: =F19+H19+J19+L19+N19+P19 -> 0 | S19: =R19/E19 -> #DIV/0!
R20: =F20+H20+J20+L20+N20+P20 -> 0 | S20: =R20/E20 -> #DIV/0!
R21: =F21+H21+J21+L21+N21+P21 -> 0 | S21: =R21/E21 -> #DIV/0!
R22: =F22+H22+J22+L22+N22+P22 -> 0 | S22: =R22/E22 -> #DIV/0!
R23: =F23+H23+J23+L23+N23+P23 -> 0 | S23: =R23/E23 -> #DIV/0!
R24: =F24+H24+J24+L24+N24+P24 -> 0 | S24: =R24/E24 -> #DIV/0!
R25: =F25+H25+J25+L25+N25+P25 -> 0 | S25: =R25/E25 -> #DIV/0!
R26: =F26+H26+J26+L26+N26+P26 -> 0 | S26: =R26/E26 -> #DIV/0!
... R32: =F32+H32+J32+L32+N32+P32 -> 0 | S32: =R32/E32 -> #DIV/0!
B33: 合 計 | C33: =SUM(C13:C32) -> 971 | D33: =SUM(D13:D32) -> 245 | E33: =SUM(E13:E32) -> 1020 | F33: =SUM(F13:F32) -> 203 | G33: =SUM(G13:G32) -> 198 | H33: =SUM(H13:H32) -> 76 | I33: =SUM(I13:I32) -> 76 | J33: =SUM(J13:J32) -> 0 | ... R33: =SUM(R13:R32) -> 279 | S33: =R33/E33 -> 0.27352941

Sheet 様式３ 教育の質・履修者数を向上させるための体制・計画
I1: 様式３
G2: 大学等名 | H2: ='様式１－１ プログラムを構成する授業科目'!C2 -> 青森中央学院大学
A4: 教育の質・履修者数を向上させるための体制・計画について
A6: ① | B6: 全学の教員数 | C6: (常勤） | E6: 67 | F6: 人 | G6: （非常勤） | H6: 87 | I6: 人
A8: ② | B8: プログラムの授業を教えている教員数 | H8: 2 | I8: 人
A10: ③ | B10: プログラムの運営責任者
B11: （責任者名） | C11: 大泉 常長 | G11: （役職名） | H11: 基幹教育センター長
A13: ④ | B13: プログラムを改善・進化させるための体制（委員会・組織等）
B14: 基幹教育センター
B16: （責任者名） | C16: 大泉 常長 | G16: （役職名） | H16: 基幹教育センター長
A18: ⑤ | B18: プログラムを改善・進化させるための体制を定める規則名称
B19: 学校法人青森田中学園 基幹教育センター規程
A21: ⑥ | B21: 体制の目的
B22: 学校法人青森田中学園各設置校における、今後必要となる教育内容、および、答申等に示された求められる教育内容について、本学への導入に向けた情報収集と課題の整理をおこなうための共同利用機関として基幹教育センターを置く。センターは、これらの目的を達成するために、次の事業を行う。（１）学園設置校における数理、データサイエンス、ＡＩ教育の導入に関すること。（２）設置校・学部を横断する教育の導入に関すること。（３）ICTを活用した教育の導入に関すること。
A34: ⑦ | B34: 具体的な構成員
B35: 基幹教育センター長（経営法学部 教授） 大泉 常長 経営法学部 准教授 木村 隆雄 経営法学部 准教授 山本 俊 経営法学部 准教授 楠山 大暁 経営法学部 准教授 中村 智行 経営法学部 講師 新免 圭介 経営法学部 講師 畠山 光史 看護学部 教授 玉熊 和子 看護学部 准教授 藤澤 珠織 食物栄養学科 教授 棟方 秀和 幼児保育学科 教授 鈴木 寛康 事務局 局長 石田 壮平 事務局 次長（学事担当） 石田 智久 事務局 学務課リーダー 坂本 貴行 事務局 企画課長 石田 光 事務局 企画課情報システム部門リーダー 石山 直敬 事務局 企画課情報システム部門 柿﨑 雄希
A48: ⑧ | B48: 履修者数・履修率の向上に向けた計画 ※様式１の「履修必須の有無」で「計画がある」としている場合は詳細について記載すること
B49: 令和６年度実績 | C49: ='様式２ 履修者等数の実績'!S33 -> 0.27352941 | E49: 令和７年度予定 | F49: 1 | H49: 令和８年度予定 | I49: 1
B50: 令和９年度予定 | C50: 1 | E50: 令和１０年度予定 | F50: 1 | H50: 収容定員（名） | I50: ='様式２ 履修者等数の実績'!E33 -> 1020
B51: 具体的な計画
B52: 令和６年度より、履修することが必須のプログラムとして実施している。
A65: ⑨ | B65: 学部・学科に関係なく希望する学生全員が受講可能となるような必要な体制・取組等
B66: センターの設置により、全学的な教育コンテンツ作成を支援し、プログラムの基礎部分である「データサイエンス・AI基礎」（経営法学部）および「情報処理I」（看護学部）においては全学生が受講できるように必修科目としている。
A79: ⑩ | B79: できる限り多くの学生が履修できるような具体的な周知方法・取組
B80: 入学後のオリエンテーション、在学生の始業ガイダンス、大学ホームページなどで、学生にプログラムを受講することの意義を周知している。学生便覧に本プログラムに属する科目のカリキュラムマップおよびカリキュラムツリーなどを掲載して、学生が情報を受け取りやすい環境を整備している。
A93: ⑪ | B93: できる限り多くの学生が履修・修得できるようなサポート体制
B94: 本教育プログラムの授業について、「データサイエンス・AI基礎」の授業用Teams上で授業資料をPDFファイルで学生に共有し、また演習課題についても問題文・課題データなどをTeamsを通じて情報共有し、多くの学生がいつでも講義資料などの閲覧が可能な環境を構築している。
A107: ⑫ | B107: 授業時間内外で学習指導、質問を受け付ける具体的な仕組み
B108: 本教育プログラムの授業についての履修を本学ポータルサイトにて管理し、学生は授業時間以外に不明点などをTeamsのチャット機能を通じて確認することができ、質問は主として授業担当教員を通じて返答する体制を整備している。

Sheet 様式４　自己点検・評価
I1: 様式４
H2: 大学等名 | I2: ='様式１－１ プログラムを構成する授業科目'!C2 -> 青森中央学院大学
A3: 自己点検・評価について
A5: ① | B5: プログラムの自己点検・評価を行う体制（委員会・組織等）
B6: 基幹教育センター
D8: （責任者名） | E8: 大泉 常長 | G8: （役職名） | H8: 基幹教育センター長
A10: ② | B10: 自己点検・評価体制における意見等
B11: 自己点検・評価の視点 | E11: 自己点検・評価体制における意見・結果・改善に向けた取組等
B12: 学内からの視点
C13: プログラムの履修・修得状況 | E13: 全学必修科目として実施し、単位修得率は97.5％となった。 また、演習課題の回答状況については、一部学生において遅れがあったものの、最終的には単位修得学生においてはすべての演習課題を回答した。
C14: 学修成果 | E14: 学修成果等アンケートの結果を見ると、 経営法学部においては、DPに基づく全24項目の学習目標のうち、本プログラムに関連する「多様性の尊重」は全体で1番目、「広い視野からの理解」は14番目、「変化と備えるべき能力の理解」は11番目、「数量的スキル」は16番目という結果になった。 看護学部においては、DPに基づく全20項目の学習目標のうち、本プログラムに関連する「人間と社会、自然への理解」は全体で3番目、「科学的判断の理解」は全体で18番目、「課題解決力」は全体で13番目という結果になった。 数理・データサイエンス・AIに関する知識の必要性についてはある程度理解が進んだものの、自身のスキルや科学的思考に関しては自信がない状況であることが読み取れ、この結果を踏まえ改善を行っていく必要があることを確認した。
C15: 学生アンケート等を通じた学生の内容の理解度 | E15: 授業改善アンケートの「この授業の内容を理解しましたか。」について、 青森中央学院大学経営法学部における「データサイエンス・AI基礎」では、そう思う・まあそう思う（全選択肢：そう思う・まあそう思う・あまりそう思わない・そう思わない）の割合が75.4% 青森中央学院大学看護学部における「情報処理Ⅰ」では、そう思う・まあそう思う（全選択肢：そう思う・まあそう思う・あまりそう思わない・そう思わない）の割合が85.0% であった。 いずれも同セメスターの全科目の平均値と比較して低い状況であり、数理・データサイエンス・AI教育の授業における難易度設定について改善が必要であることを確認した。 またアンケートの自由記述をみると、「結構面白いと思えた」「今の時代に合ったAIの解説やネット社会で使える技術と知識を知ることができた」など、一部の学生においては、本プログラムの受講により、数理・データサイエンス・AIに興味をもったという意見もあった。全学必修科目として実施していることにより、初めは興味がなくとも本プログラムが興味を持つきっかけになった学生がいたという点で、有意義な取り組みだと評価できる。
C16: 学生アンケート等を通じた後輩等他の学生への推奨度 | E16: 本学では、全学必修科目として実施しているため、推奨の度合いによって履修者に変化はないが、授業改善アンケートの結果を基幹教育センターで分析し、後輩学生の授業時に修得に対するモチベーション向上の観点からも授業改善を検討している。
C17: 全学的な履修者数、履修率向上に向けた計画の達成・進捗状況 | E17: 本教育プログラムを構成する科目「データサイエンス・AI基礎」については令和6年度から経営法学部において必修としており、履修者数、履修率の向上を推進している。また、「情報処理I」については、平成26年度から看護学部において必修としており、履修者数、履修率の向上を推進している。なお、「データサイエンス・AI基礎」については令和7年度から看護学部においても必修とすることが決定している。
B18: 学外からの視点
C19: 教育プログラム修了者の進路、活躍状況、企業等の評価 | E19: R6年度から実施しているプログラムであるため、本教育プログラムの修了者が今後本学を卒業した後に、卒業生アンケートなどを通じて進路、活躍状況、企業などの評価を把握する予定である。
C20: 産業界からの視点を含めた教育プログラム内容・手法等への意見 | E20: 令和6年12月7日（土）に、青森中央学院大学・青森中央短期大学主催令和6年度「数理・データサイエンス・AI教育に関する取り組み事例研究会」を実施し、教育プログラムの講義内容および実データを活用した演習などの手法について意見を収集した。 ・学生は、授業・課題等でデータ分析等を手順通りに作業として実施することはできるが、今この作業が何のための分析なのか、何を明らかにできるのかなどを理解できていない場合がある。仮説を考えてもらったり、その結論に導くためにどんな分析が必要かを考えてもらうことで、作業にならない工夫が必要である。 ・アプリケーションの機能を用いればボタン一つで分析結果がわかるが、結果を導く計算式までを理解するのは難しい。どこまでを教えるのが適切なのかは悩むところである。初めは手計算で行わせるなどアプリケーションに頼らないやり方もありえるが、その分時間がかかってしまう。一方で社会で役立つ能力と割り切ると、リテラシーレベルということも鑑みると、アプリケーションはあるのだから、数式などの説明は割愛するという考え方もありえる。 基幹教育センターにおいて上記の意見等を踏まえ、プログラムの改善に活用している。
B21: 数理・データサイエンス・ＡＩを「学ぶ楽しさ」「学ぶことの意義」を理解させること | E21: モデルカリキュラムリテラシーレベルの導入・基礎・心得に準じた内容を展開し、時事やトレンドなど社会での実例をもとにAIなどがどのような活用をされているのかを中心に、受講生の専門分野である経営学、法学、看護学等とも関連付けながら、好奇心を促す講義内容としている。取りあげる実例については、授業改善アンケートなどの結果を活用し、その内容について評価を実施し改善に活かしている。
B22: 内容・水準を維持・向上しつつ、より「分かりやすい」授業とすること ※社会の変化や生成AI等の技術の発展を踏まえて教育内容を継続的に見直すなど、より教育効果の高まる授業内容・方法とするための取組や仕組みについても該当があれば記載 | E22: 基幹教育センターにて、授業改善アンケートの意見を参考に、学生の「分かりやすさ」の観点から講義の内容・実施方法の見直しを行っている。例えば、令和7年度からはクラスサイズを調整し「データサイエンス・AI基礎」については2クラス開講とすることで学修効果の向上を図っている。
