Workbook

Sheet 様式１－１　プログラムを構成する授業科目
T1: 様式１－１ | V1: 「学部・学科によって、修了要件は相違する」場合は、本シートを複製の上＜様式１－〇＞と枝番号を付してください
B2: 大学等名 | C2: 北海学園大学
B3: プログラム名 | C3: HGU数理・データサイエンス教育プログラム
A5: プログラムを構成する授業科目について
A7: ① 教育プログラムの修了要件 | L7: 学部・学科によって、修了要件は相違する
A9: ② 対象となる学部・学科名称
B11: 経済学部1部、経済学部2部
A14: ③ 修了要件
B15: プログラムを構成する必修科目を含めて4単位以上を修得すること。 必修科目：「教養科目特別講義（情報リテラシー）」 2単位 選択科目：「情報と社会」2単位、「情報技術論」2単位、「統計学Ⅰ」2単位、「数学概論Ⅰ」2単位、「数学概論Ⅱ」2単位、「情報処理論」4単位 | X15: 【プルダウンリスト】
X16: 令和５年度以前より、履修することが必須のプログラムとして実施
X17: 令和８年度までに履修必須とする計画
X18: 令和９年度以降に履修必須とする計画、又は未定
B22: 必要最低科目数・単位数 | E22: 2 | F22: 科目 | H22: 4 | I22: 単位 | M22: 履修必須の有無 | N22: 令和９年度以降に履修必須とする計画、又は未定
A24: ④ 現在進行中の社会変化（第４次産業革命、Society 5.0、データ駆動型社会等）に深く寄与しているものであり、それが自らの生活と密接に結びついている」の内容を含む授業科目
B26: 授業科目 | G26: 単位数 | H26: 必須 | I26: 1-1 | J26: 1-6 | K26: 授業科目 | R26: 単位数 | S26: 必須 | T26: 1-1 | U26: 1-6
B27: 教養科目特別講義（情報リテラシー） | G27: 2 | H27: ○ | I27: ○ | J27: ○
A35: ⑤ 「社会で活用されているデータ」や「データの活用領域」は非常に広範囲であって、日常生活や社会の課題を解決する有用なツールになり得るもの」の内容を含む授業科目
B37: 授業科目 | G37: 単位数 | H37: 必須 | I37: 1-2 | J37: 1-3 | K37: 授業科目 | R37: 単位数 | S37: 必須 | T37: 1-2 | U37: 1-3
B38: 教養科目特別講義（情報リテラシー） | G38: 2 | H38: ○ | I38: ○ | J38: ○
B39: 情報技術論 | G39: 2 | I39: ○
A46: ⑥ 「様々なデータ利活用の現場におけるデータ利活用事例が示され、様々な適用領域（流通、製造、金融、サービス、インフラ、公共、ヘルスケア等）の知見と組み合わせることで価値を創出するもの」の内容を含む授業科目
B48: 授業科目 | G48: 単位数 | H48: 必須 | I48: 1-4 | J48: 1-5 | K48: 授業科目 | R48: 単位数 | S48: 必須 | T48: 1-4 | U48: 1-5
B49: 教養科目特別講義（情報リテラシー） | G49: 2 | H49: ○ | I49: ○ | J49: ○
A57: ⑦ 「活用に当たっての様々な留意事項（ELSI、個人情報、データ倫理、ＡＩ社会原則等）を考慮し、情報セキュリティや情報漏洩等、データを守る上での留意事項への理解をする」の内容を含む授業科目
B59: 授業科目 | G59: 単位数 | H59: 必須 | I59: 3-1 | J59: 3-2 | K59: 授業科目 | R59: 単位数 | S59: 必須 | T59: 3-1 | U59: 3-2
B60: 教養科目特別講義（情報リテラシー） | G60: 2 | H60: ○ | I60: ○ | J60: ○
B61: 情報技術論 | G61: 2 | J61: ○
B62: 情報と社会 | G62: 2 | I62: ○ | J62: ○
A68: ⑧ 「実データ・実課題（学術データ等を含む）を用いた演習など、社会での実例を題材として、「データを読む、説明する、扱う」といった数理・データサイエンス・ＡＩの基本的な活用法に関するもの」の内容を含む授業科目
B70: 授業科目 | F70: 単位数 | G70: 必須 | H70: 2-1 | I70: 2-2 | J70: 2-3 | K70: 授業科目 | Q70: 単位数 | R70: 必須 | S70: 2-1 | T70: 2-2 | U70: 2-3
B71: 教養科目特別講義（情報リテラシー） | F71: 2 | G71: ○ | H71: ○ | I71: ○ | J71: ○
B72: 情報処理論 | F72: 4 | J72: ○
A79: ⑨ 選択「４．オプション」の内容を含む授業科目
B80: 授業科目 | G80: 選択項目 | K80: 授業科目 | R80: 選択項目
B81: 統計学Ⅰ | G81: 4-1統計および数理基礎
B82: 数学概論Ⅰ | G82: 4-1統計および数理基礎
B83: 数学概論Ⅱ | G83: 4-1統計および数理基礎
A89: ⑩ プログラムを構成する授業の内容
B90: 授業に含まれている内容・要素 | D90: 講義内容
B91: （１）現在進行中の社会変化（第４次産業革命、Society 5.0、データ駆動型社会等）に深く寄与しているものであり、それが自らの生活と密接に結びついている | C91: 1-1 | D91: ・ビッグデータ、IoT、AI、ロボット「教養科目特別講義（情報リテラシー）」（第1回） ・データ量の増加、計算機の処理性能の向上「教養科目特別講義（情報リテラシー）」（第1回） ・第4次産業革命、Society 5.0、データ駆動型社会「教養科目特別講義（情報リテラシー）」（第2回） ・複数技術を組み合わせたAIサービス「教養科目特別講義（情報リテラシー）」（第1回） ・人間の知的活動とAIの関係性「教養科目特別講義（情報リテラシー）」（第1回、第4回） ・データを起点としたものの見方、人間の知的活動を起点としたものの見方「教養科目特別講義（情報リテラシー）」（第2回）
...

Sheet 様式１－2　プログラムを構成する授業科目 
T1: 様式１－２ | V1: 「学部・学科によって、修了要件は相違する」場合は、本シートを複製の上＜様式１－〇＞と枝番号を付してください
B2: 大学等名 | C2: 北海学園大学
B3: プログラム名 | C3: HGU数理・データサイエンス教育プログラム
A5: プログラムを構成する授業科目について
A7: ① 教育プログラムの修了要件 | L7: 学部・学科によって、修了要件は相違する
A9: ② 対象となる学部・学科名称
B11: 経営学部1部、経営学部2部
A14: ③ 修了要件
B15: プログラムを構成する必修科目8単位を修得すること。 必修科目：「情報リテラシー」4単位、「経営統計学概論Ⅰ」2単位、「経営統計学概論Ⅱ」2単位 選択科目：「教養科目特別講義（情報リテラシー）」 2単位、「情報と社会」2単位、「情報技術論」2単位、「統計学Ⅰ」2単位、「数学概論Ⅰ」2単位、「数学概論Ⅱ」2単位 | X15: 【プルダウンリスト】
X16: 令和５年度以前より、履修することが必須のプログラムとして実施
X17: 令和８年度までに履修必須とする計画
X18: 令和９年度以降に履修必須とする計画、又は未定
B22: 必要最低科目数・単位数 | E22: 3 | F22: 科目 | H22: 8 | I22: 単位 | M22: 履修必須の有無 | N22: 令和５年度以前より、履修することが必須のプログラムとして実施
A24: ④ 現在進行中の社会変化（第４次産業革命、Society 5.0、データ駆動型社会等）に深く寄与しているものであり、それが自らの生活と密接に結びついている」の内容を含む授業科目
B26: 授業科目 | G26: 単位数 | H26: 必須 | I26: 1-1 | J26: 1-6 | K26: 授業科目 | R26: 単位数 | S26: 必須 | T26: 1-1 | U26: 1-6
B27: 情報リテラシー | G27: 4 | H27: ○ | J27: ○
B28: 経営統計学概論Ⅰ | G28: 2 | H28: ○ | I28: ○ | J28: ○
B29: 教養科目特別講義（情報リテラシー） | G29: 2 | I29: ○ | J29: ○
A35: ⑤ 「社会で活用されているデータ」や「データの活用領域」は非常に広範囲であって、日常生活や社会の課題を解決する有用なツールになり得るもの」の内容を含む授業科目
B37: 授業科目 | G37: 単位数 | H37: 必須 | I37: 1-2 | J37: 1-3 | K37: 授業科目 | R37: 単位数 | S37: 必須 | T37: 1-2 | U37: 1-3
B38: 経営統計学概論Ⅰ | G38: 2 | H38: ○ | J38: ○
B39: 経営統計学概論Ⅱ | G39: 2 | H39: ○ | I39: ○
B40: 教養科目特別講義（情報リテラシー） | G40: 2 | I40: ○ | J40: ○
B41: 情報技術論 | G41: 2 | I41: ○
A46: ⑥ 「様々なデータ利活用の現場におけるデータ利活用事例が示され、様々な適用領域（流通、製造、金融、サービス、インフラ、公共、ヘルスケア等）の知見と組み合わせることで価値を創出するもの」の内容を含む授業科目
B48: 授業科目 | G48: 単位数 | H48: 必須 | I48: 1-4 | J48: 1-5 | K48: 授業科目 | R48: 単位数 | S48: 必須 | T48: 1-4 | U48: 1-5
B49: 経営統計学概論Ⅰ | G49: 2 | H49: ○ | I49: ○
B50: 経営統計学概論Ⅱ | G50: 2 | H50: ○ | J50: ○
B51: 教養科目特別講義（情報リテラシー） | G51: 2 | I51: ○ | J51: ○
A57: ⑦ 「活用に当たっての様々な留意事項（ELSI、個人情報、データ倫理、ＡＩ社会原則等）を考慮し、情報セキュリティや情報漏洩等、データを守る上での留意事項への理解をする」の内容を含む授業科目
B59: 授業科目 | G59: 単位数 | H59: 必須 | I59: 3-1 | J59: 3-2 | K59: 授業科目 | R59: 単位数 | S59: 必須 | T59: 3-1 | U59: 3-2
B60: 情報リテラシー | G60: 4 | H60: ○ | J60: ○
B61: 経営統計学概論Ⅱ | G61: 2 | H61: ○ | I61: ○
B62: 教養科目特別講義（情報リテラシー） | G62: 2 | I62: ○ | J62: ○
B63: 情報技術論 | G63: 2 | J63: ○
B64: 情報と社会 | G64: 2 | I64: ○ | J64: ○
A68: ⑧ 「実データ・実課題（学術データ等を含む）を用いた演習など、社会での実例を題材として、「データを読む、説明する、扱う」といった数理・データサイエンス・ＡＩの基本的な活用法に関するもの」の内容を含む授業科目
B70: 授業科目 | F70: 単位数 | G70: 必須 | H70: 2-1 | I70: 2-2 | J70: 2-3 | K70: 授業科目 | Q70: 単位数 | R70: 必須 | S70: 2-1 | T70: 2-2 | U70: 2-3
B71: 情報リテラシー | F71: 4 | G71: ○ | I71: ○ | J71: ○
B72: 経営統計学概論Ⅰ | F72: 2 | G72: ○ | H72: ○ | I72: ○ | J72: ○
...

Sheet 様式１－3　プログラムを構成する授業科目
T1: 様式１－３ | V1: 「学部・学科によって、修了要件は相違する」場合は、本シートを複製の上＜様式１－〇＞と枝番号を付してください
B2: 大学等名 | C2: 北海学園大学
B3: プログラム名 | C3: HGU数理・データサイエンス教育プログラム
A5: プログラムを構成する授業科目について
A7: ① 教育プログラムの修了要件 | L7: 学部・学科によって、修了要件は相違する
A9: ② 対象となる学部・学科名称
B11: 法学部1部、法学部2部、人文学部1部、人文学部2部
A14: ③ 修了要件
B15: プログラムを構成する必修科目を含めて4単位以上を修得すること。 必修科目：「教養科目特別講義（情報リテラシー）」 2単位 選択科目：「情報と社会」2単位、「情報技術論」2単位、「コンピュータ科学」2単位、「統計学Ⅰ」2単位、「数学概論Ⅰ」2単位、「数学概論Ⅱ」2単位 | X15: 【プルダウンリスト】
X16: 令和５年度以前より、履修することが必須のプログラムとして実施
X17: 令和８年度までに履修必須とする計画
X18: 令和９年度以降に履修必須とする計画、又は未定
B22: 必要最低科目数・単位数 | E22: 2 | F22: 科目 | H22: 4 | I22: 単位 | M22: 履修必須の有無 | N22: 令和９年度以降に履修必須とする計画、又は未定
A24: ④ 現在進行中の社会変化（第４次産業革命、Society 5.0、データ駆動型社会等）に深く寄与しているものであり、それが自らの生活と密接に結びついている」の内容を含む授業科目
B26: 授業科目 | G26: 単位数 | H26: 必須 | I26: 1-1 | J26: 1-6 | K26: 授業科目 | R26: 単位数 | S26: 必須 | T26: 1-1 | U26: 1-6
B27: 教養科目特別講義（情報リテラシー） | G27: 2 | H27: ○ | I27: ○ | J27: ○
A35: ⑤ 「社会で活用されているデータ」や「データの活用領域」は非常に広範囲であって、日常生活や社会の課題を解決する有用なツールになり得るもの」の内容を含む授業科目
B37: 授業科目 | G37: 単位数 | H37: 必須 | I37: 1-2 | J37: 1-3 | K37: 授業科目 | R37: 単位数 | S37: 必須 | T37: 1-2 | U37: 1-3
B38: 教養科目特別講義（情報リテラシー） | G38: 2 | H38: ○ | I38: ○ | J38: ○
B39: 情報技術論 | G39: 2 | I39: ○
A46: ⑥ 「様々なデータ利活用の現場におけるデータ利活用事例が示され、様々な適用領域（流通、製造、金融、サービス、インフラ、公共、ヘルスケア等）の知見と組み合わせることで価値を創出するもの」の内容を含む授業科目
B48: 授業科目 | G48: 単位数 | H48: 必須 | I48: 1-4 | J48: 1-5 | K48: 授業科目 | R48: 単位数 | S48: 必須 | T48: 1-4 | U48: 1-5
B49: 教養科目特別講義（情報リテラシー） | G49: 2 | H49: ○ | I49: ○ | J49: ○
A57: ⑦ 「活用に当たっての様々な留意事項（ELSI、個人情報、データ倫理、ＡＩ社会原則等）を考慮し、情報セキュリティや情報漏洩等、データを守る上での留意事項への理解をする」の内容を含む授業科目
B59: 授業科目 | G59: 単位数 | H59: 必須 | I59: 3-1 | J59: 3-2 | K59: 授業科目 | R59: 単位数 | S59: 必須 | T59: 3-1 | U59: 3-2
B60: 教養科目特別講義（情報リテラシー） | G60: 2 | H60: ○ | I60: ○ | J60: ○
B61: 情報技術論 | G61: 2 | J61: ○
B62: 情報と社会 | G62: 2 | I62: ○ | J62: ○
A68: ⑧ 「実データ・実課題（学術データ等を含む）を用いた演習など、社会での実例を題材として、「データを読む、説明する、扱う」といった数理・データサイエンス・ＡＩの基本的な活用法に関するもの」の内容を含む授業科目
B70: 授業科目 | F70: 単位数 | G70: 必須 | H70: 2-1 | I70: 2-2 | J70: 2-3 | K70: 授業科目 | Q70: 単位数 | R70: 必須 | S70: 2-1 | T70: 2-2 | U70: 2-3
B71: 教養科目特別講義（情報リテラシー） | F71: 2 | G71: ○ | H71: ○ | I71: ○ | J71: ○
B72: コンピュータ科学 | F72: 2 | I72: ○
A79: ⑨ 選択「４．オプション」の内容を含む授業科目
B80: 授業科目 | G80: 選択項目 | K80: 授業科目 | R80: 選択項目
B81: 統計学Ⅰ | G81: 4-1統計および数理基礎
B82: 数学概論Ⅰ | G82: 4-1統計および数理基礎
B83: 数学概論Ⅱ | G83: 4-1統計および数理基礎
A89: ⑩ プログラムを構成する授業の内容
B90: 授業に含まれている内容・要素 | D90: 講義内容
B91: （１）現在進行中の社会変化（第４次産業革命、Society 5.0、データ駆動型社会等）に深く寄与しているものであり、それが自らの生活と密接に結びついている | C91: 1-1 | D91: ・ビッグデータ、IoT、AI、ロボット「教養科目特別講義（情報リテラシー）」（第1回） ・データ量の増加、計算機の処理性能の向上「教養科目特別講義（情報リテラシー）」（第1回） ・第4次産業革命、Society 5.0、データ駆動型社会「教養科目特別講義（情報リテラシー）」（第2回） ・複数技術を組み合わせたAIサービス「教養科目特別講義（情報リテラシー）」（第1回） ・人間の知的活動とAIの関係性「教養科目特別講義（情報リテラシー）」（第1回、第4回） ・データを起点としたものの見方、人間の知的活動を起点としたものの見方「教養科目特別講義（情報リテラシー）」（第2回）
...

Sheet 様式１－4　プログラムを構成する授業科目
T1: 様式１－４ | V1: 「学部・学科によって、修了要件は相違する」場合は、本シートを複製の上＜様式１－〇＞と枝番号を付してください
B2: 大学等名 | C2: 北海学園大学
B3: プログラム名 | C3: HGU数理・データサイエンス教育プログラム
A5: プログラムを構成する授業科目について
A7: ① 教育プログラムの修了要件 | L7: 学部・学科によって、修了要件は相違する
A9: ② 対象となる学部・学科名称
B11: 工学部
A14: ③ 修了要件
B15: プログラムを構成する必修科目を含めて4単位以上を修得すること。 必修科目：「教養科目特別講義（情報リテラシー）」 2単位 選択科目：「情報と社会」2単位、「情報技術論」2単位、「コンピュータ科学」2単位、「数学概論Ⅰ」2単位、「数学概論Ⅱ」2単位、「確率統計」2単位 | X15: 【プルダウンリスト】
X16: 令和５年度以前より、履修することが必須のプログラムとして実施
X17: 令和８年度までに履修必須とする計画
X18: 令和９年度以降に履修必須とする計画、又は未定
B22: 必要最低科目数・単位数 | E22: 2 | F22: 科目 | H22: 4 | I22: 単位 | M22: 履修必須の有無 | N22: 令和９年度以降に履修必須とする計画、又は未定
A24: ④ 現在進行中の社会変化（第４次産業革命、Society 5.0、データ駆動型社会等）に深く寄与しているものであり、それが自らの生活と密接に結びついている」の内容を含む授業科目
B26: 授業科目 | G26: 単位数 | H26: 必須 | I26: 1-1 | J26: 1-6 | K26: 授業科目 | R26: 単位数 | S26: 必須 | T26: 1-1 | U26: 1-6
B27: 教養科目特別講義（情報リテラシー） | G27: 2 | H27: ○ | I27: ○ | J27: ○
A35: ⑤ 「社会で活用されているデータ」や「データの活用領域」は非常に広範囲であって、日常生活や社会の課題を解決する有用なツールになり得るもの」の内容を含む授業科目
B37: 授業科目 | G37: 単位数 | H37: 必須 | I37: 1-2 | J37: 1-3 | K37: 授業科目 | R37: 単位数 | S37: 必須 | T37: 1-2 | U37: 1-3
B38: 教養科目特別講義（情報リテラシー） | G38: 2 | H38: ○ | I38: ○ | J38: ○
B39: 情報技術論 | G39: 2 | I39: ○
A46: ⑥ 「様々なデータ利活用の現場におけるデータ利活用事例が示され、様々な適用領域（流通、製造、金融、サービス、インフラ、公共、ヘルスケア等）の知見と組み合わせることで価値を創出するもの」の内容を含む授業科目
B48: 授業科目 | G48: 単位数 | H48: 必須 | I48: 1-4 | J48: 1-5 | K48: 授業科目 | R48: 単位数 | S48: 必須 | T48: 1-4 | U48: 1-5
B49: 教養科目特別講義（情報リテラシー） | G49: 2 | H49: ○ | I49: ○ | J49: ○
A57: ⑦ 「活用に当たっての様々な留意事項（ELSI、個人情報、データ倫理、ＡＩ社会原則等）を考慮し、情報セキュリティや情報漏洩等、データを守る上での留意事項への理解をする」の内容を含む授業科目
B59: 授業科目 | G59: 単位数 | H59: 必須 | I59: 3-1 | J59: 3-2 | K59: 授業科目 | R59: 単位数 | S59: 必須 | T59: 3-1 | U59: 3-2
B60: 教養科目特別講義（情報リテラシー） | G60: 2 | H60: ○ | I60: ○ | J60: ○
B61: 情報技術論 | G61: 2 | J61: ○
B62: 情報と社会 | G62: 2 | I62: ○ | J62: ○
A68: ⑧ 「実データ・実課題（学術データ等を含む）を用いた演習など、社会での実例を題材として、「データを読む、説明する、扱う」といった数理・データサイエンス・ＡＩの基本的な活用法に関するもの」の内容を含む授業科目
B70: 授業科目 | F70: 単位数 | G70: 必須 | H70: 2-1 | I70: 2-2 | J70: 2-3 | K70: 授業科目 | Q70: 単位数 | R70: 必須 | S70: 2-1 | T70: 2-2 | U70: 2-3
B71: 教養科目特別講義（情報リテラシー） | F71: 2 | G71: ○ | H71: ○ | I71: ○ | J71: ○
B72: コンピュータ科学 | F72: 2 | I72: ○
A79: ⑨ 選択「４．オプション」の内容を含む授業科目
B80: 授業科目 | G80: 選択項目 | K80: 授業科目 | R80: 選択項目
B81: 数学概論Ⅰ | G81: 4-1統計および数理基礎
B82: 数学概論Ⅱ | G82: 4-1統計および数理基礎
B83: 確率統計 | G83: 4-1統計および数理基礎
A89: ⑩ プログラムを構成する授業の内容
B90: 授業に含まれている内容・要素 | D90: 講義内容
B91: （１）現在進行中の社会変化（第４次産業革命、Society 5.0、データ駆動型社会等）に深く寄与しているものであり、それが自らの生活と密接に結びついている | C91: 1-1 | D91: ・ビッグデータ、IoT、AI、ロボット「教養科目特別講義（情報リテラシー）」（第1回） ・データ量の増加、計算機の処理性能の向上「教養科目特別講義（情報リテラシー）」（第1回） ・第4次産業革命、Society 5.0、データ駆動型社会「教養科目特別講義（情報リテラシー）」（第2回） ・複数技術を組み合わせたAIサービス「教養科目特別講義（情報リテラシー）」（第1回） ・人間の知的活動とAIの関係性「教養科目特別講義（情報リテラシー）」（第1回、第4回） ・データを起点としたものの見方、人間の知的活動を起点としたものの見方「教養科目特別講義（情報リテラシー）」（第2回）
...

Sheet 様式２ 履修者等数の実績
S1: 様式２
Q2: ='様式１－１ プログラムを構成する授業科目'!C2 -> 北海学園大学
A3: プログラムの履修者数等の実績について
A5: ①プログラム開設年度 | C5: 令和5 | E5: 年度
A7: ②大学等全体の男女別学生数 | E7: 男性 | F7: 5412 | G7: 人 | H7: 女性 | I7: 2483 | J7: 人 | K7: （ | L7: 合計 | M7: =F7+I7 -> 7895 | N7: 人 | O7: ）
A9: ③履修者・修了者の実績
B11: 学部・学科名称 | C11: 学生数 | D11: 入学 定員 | E11: 収容 定員 | F11: 令和5年度 | H11: 令和4年度 | J11: 令和3年度 | L11: 令和2年度 | N11: 令和元年度 | P11: 平成30年度 | R11: 履修者数 合計 | S11: 履修率
F12: 履修者数 | G12: 修了者数 | H12: 履修者数 | I12: 修了者数 | J12: 履修者数 | K12: 修了者数 | L12: 履修者数 | M12: 修了者数 | N12: 履修者数 | O12: 修了者数 | P12: 履修者数 | Q12: 修了者数
B13: 経済学部1部 | C13: 1257 | D13: 300 | E13: 1200 | F13: 3 | R13: =F13+H13+J13+L13+N13+P13 -> 3 | S13: =R13/E13 -> 0.0025
B14: 経営学部1部 | C14: 1323 | D14: 300 | E14: 1200 | F14: 21 | G14: 7 | R14: =F14+H14+J14+L14+N14+P14 -> 21 | S14: =R14/E14 -> 0.0175
B15: 法学部1部 | C15: 1134 | D15: 255 | E15: 1020 | F15: 6 | R15: =F15+H15+J15+L15+N15+P15 -> 6 | S15: =R15/E15 -> 0.0058823529
B16: 人文学部1部 | C16: 853 | D16: 195 | E16: 780 | F16: 4 | R16: =F16+H16+J16+L16+N16+P16 -> 4 | S16: =R16/E16 -> 0.0051282051
B17: 工学部 | C17: 1144 | D17: 260 | E17: 1040 | F17: 118 | R17: =F17+H17+J17+L17+N17+P17 -> 118 | S17: =R17/E17 -> 0.11346154
B18: 経済学部2部 | C18: 569 | D18: 120 | E18: 480 | F18: 1 | R18: =F18+H18+J18+L18+N18+P18 -> 1 | S18: =R18/E18 -> 0.0020833333
B19: 経営学部2部 | C19: 475 | D19: 100 | E19: 400 | F19: 6 | G19: 1 | R19: =F19+H19+J19+L19+N19+P19 -> 6 | S19: =R19/E19 -> 0.015
B20: 法学部2部 | C20: 802 | D20: 180 | E20: 720 | F20: 3 | R20: =F20+H20+J20+L20+N20+P20 -> 3 | S20: =R20/E20 -> 0.0041666667
B21: 人文学部2部 | C21: 338 | D21: 70 | E21: 280 | F21: 0 | R21: =F21+H21+J21+L21+N21+P21 -> 0 | S21: =R21/E21 -> 0
R22: =F22+H22+J22+L22+N22+P22 -> 0 | S22: =R22/E22 -> #DIV/0!
R23: =F23+H23+J23+L23+N23+P23 -> 0 | S23: =R23/E23 -> #DIV/0!
R24: =F24+H24+J24+L24+N24+P24 -> 0 | S24: =R24/E24 -> #DIV/0!
R25: =F25+H25+J25+L25+N25+P25 -> 0 | S25: =R25/E25 -> #DIV/0!
R26: =F26+H26+J26+L26+N26+P26 -> 0 | S26: =R26/E26 -> #DIV/0!
R27: =F27+H27+J27+L27+N27+P27 -> 0 | S27: =R27/E27 -> #DIV/0!
R28: =F28+H28+J28+L28+N28+P28 -> 0 | S28: =R28/E28 -> #DIV/0!
R29: =F29+H29+J29+L29+N29+P29 -> 0 | S29: =R29/E29 -> #DIV/0!
R30: =F30+H30+J30+L30+N30+P30 -> 0 | S30: =R30/E30 -> #DIV/0!
R31: =F31+H31+J31+L31+N31+P31 -> 0 | S31: =R31/E31 -> #DIV/0!
R32: =F32+H32+J32+L32+N32+P32 -> 0 | S32: =R32/E32 -> #DIV/0!
B33: 合 計 | C33: =SUM(C13:C32) -> 7895 | D33: =SUM(D13:D32) -> 1780 | E33: =SUM(E13:E32) -> 7120 | F33: =SUM(F13:F32) -> 162 | G33: =SUM(G13:G32) -> 8 | H33: =SUM(H13:H32) -> 0 | I33: =SUM(I13:I32) -> 0 | J33: =SUM(J13:J32) -> 0 | ... R33: =SUM(R13:R32) -> 162 | S33: =R33/E33 -> 0.022752809

Sheet 様式３ 教育の質・履修者数を向上させるための体制・計画
I1: 様式３
G2: 大学等名 | H2: ='様式１－１ プログラムを構成する授業科目'!C2 -> 北海学園大学
A4: 教育の質・履修者数を向上させるための体制・計画について
A6: ① | B6: 全学の教員数 | C6: (常勤） | E6: 214 | F6: 人 | G6: （非常勤） | H6: 284 | I6: 人
A8: ② | B8: プログラムの授業を教えている教員数 | H8: 25 | I8: 人
A10: ③ | B10: プログラムの運営責任者
B11: （責任者名） | C11: 森下 宏美 | G11: （役職名） | H11: 学長
A13: ④ | B13: プログラムを改善・進化させるための体制（委員会・組織等）
B14: HGU数理・データサイエンス教育プログラム運営委員会
B16: （責任者名） | C16: 元木 邦俊 | G16: （役職名） | H16: 教授／工学部長
A18: ⑤ | B18: プログラムを改善・進化させるための体制を定める規則名称
B19: HGU数理・データサイエンス教育プログラム運営委員会規程
A21: ⑥ | B21: 体制の目的
B22: HGU数理・データサイエンス教育プログラム運営委員会は、本学の「HGU数理・データサイエンス教育プログラム」の全学的な実施、並びにプログラムの改善・向上及び自己点検・評価を行うことを目的としている。
A34: ⑦ | B34: 具体的な構成員
B35: 工学部 教授／工学部長 元木 邦俊 経済学部 教授 上園 昌武 経営学部 教授 関 哲人 法学部 准教授 髙橋 美野梨 人文学部 教授 柴田 崇 工学部 准教授 長谷川 大 法学部 教授／教務センター長 鈴木 美佐子 工学部 准教授 船川 大樹 教務センター事務長 中山 知幸
A48: ⑧ | B48: 履修者数・履修率の向上に向けた計画 ※様式１の「履修必須の有無」で「計画がある」としている場合は詳細について記載すること
B49: 令和５年度実績 | C49: ='様式２ 履修者等数の実績'!S33 -> 0.022752809 | E49: 令和６年度予定 | F49: 0.06 | H49: 令和７年度予定 | I49: 0.12
B50: 令和８年度予定 | C50: 0.2 | E50: 令和９年度予定 | F50: 0.3 | H50: 収容定員（名） | I50: ='様式２ 履修者等数の実績'!E33 -> 7120
B51: 具体的な計画
B52: 本プログラムは在学生の全員が履修可能となっているが、特に新入生（入学定員1780人）のプログラムの履修率を令和9年度までに50%以上となるように、各学部で行われる新入生ガイダンスでプログラムの履修を指導する。また、在学生ガイダンスにおいても、1年次配当科目の履修が可能であることを説明して、プログラムの履修を強く推奨する。学生への周知が徹底できるように１学期・２学期の履修登録の時期に合わせて、プログラムの履修を全ての学生に大学のポータルサイトなどで案内する。
A65: ⑨ | B65: 学部・学科に関係なく希望する学生全員が受講可能となるような必要な体制・取組等
B66: 経済学部・法学部・人文学部・工学部のプログラム構成科目の必修科目「教養科目特別講義（情報リテラシー）」は、一般教育科目に位置づけており、すべての学生が履修することが可能である。なお、経済学部と工学部の選択科目の一部に専門科目を配置しているが、それ以外の選択科目は、一般教育科目に位置づけているため、履修することが可能である。 経営学部のプログラム構成科目の必修科目は、専門科目である「情報リテラシー」、「経営統計学概論Ⅰ」、「経営統計学概論Ⅱ」であるが、一般教育科目も受講可能としているため、学生の選択肢を閉ざすことのないように展開している。
A79: ⑩ | B79: できる限り多くの学生が履修できるような具体的な周知方法・取組
B80: プログラムのお知らせを学内ポータルサイトG-PLUS!で新年度ガイダンスの告知と併せてしており、全学生に周知している。また、履修登録開始時にも再度告知をし、プログラムの希望者を募っている。
A92: ⑪ | B92: できる限り多くの学生が履修・修得できるようなサポート体制
B93: 教育プログラムに関する質問を常時受け付けており、質問内容に応じて教務センターまたはHGU数理・データサイエンス教育プログラム運営委員会から回答している。LMSでは、教材の提示だけではなく、小テストの実施やレポート課題の提出をオンラインで行うことができ、LMSを通じて個別指導を行うことができる。
A106: ⑫ | B106: 授業時間内外で学習指導、質問を受け付ける具体的な仕組み
B107: 本学で開講されている全ての科目で、LMSの【重要事項】の掲載項目として担当教員への連絡先を示しており、学生はメール等により質問をすることができる。本プログラムの設定科目の多くは一般教育科目であることから、教務センター窓口で質問内容を伝えることができる。また、科目担当の専任教員についてはオフィスアワーを設けており、学生からの質問に対面形式で回答することができる。

Sheet 様式４　自己点検・評価
I1: 様式４
H2: 大学等名 | I2: ='様式１－１ プログラムを構成する授業科目'!C2 -> 北海学園大学
A3: 自己点検・評価について
A5: ① | B5: プログラムの自己点検・評価を行う体制（委員会・組織等）
B6: HGU数理・データサイエンス教育プログラム運営委員会
D8: （責任者名） | E8: 元木 邦俊 | G8: （役職名） | H8: 教授／工学部長
A10: ② | B10: 自己点検・評価体制における意見等
B11: 自己点検・評価の視点 | E11: 自己点検・評価体制における意見・結果・改善に向けた取組等
B12: 学内からの視点
C13: プログラムの履修・修得状況 | E13: 経済学部、法学部、人文学部、工学部は、一般教育科目の「教養科目特別講義（情報リテラシー）」（２単位）を必修科目とし、数学、情報、統計関係の科目を選択科目として、合計４単位以上をプログラムの修了要件としている。また、経営学部は、専門教育科目の「情報リテラシー」（４単位）、「経営統計学概論Ⅰ、Ⅱ」（各２単位）を必修科目とし、必修８単位をプログラムの修了要件としている。2023年度のプログラムの履修登録者は、合計１６２名となった。過年度の学生のプログラムへの参加を認めており、４年生の８名は修了要件を満たしており、2023年度のプログラム修了者となった。
C14: 学修成果 | E14: 経済学部、法学部、人文学部、工学部の必修科目である「教養科目特別講義（情報リテラシー）」は、オンデマンドの遠隔授業として実施した。履修者数は322名（プログラムに参加していない学生を含む全履修者数）、合格率は84%となった。経営学部必修科目「情報リテラシー」の履修者数は469名（同上）、合格率は96％、「経営統計学概論Ⅰ、Ⅱ」はそれぞれ、339名、269名（同上）、合格率は69%、72%となった。これらの科目の学修目標、合否の状況、成績分布はHGU数理・データサイエンス教育プログラム運営委員会に報告され、科目実施体制の見直しなど、教育プログラムの改善・自己点検に活用されている。
C15: 学生アンケート等を通じた学生の内容の理解度 | E15: 全学生を対象に行っている授業改善アンケートで、本プログラムに設定されている科目に関するアンケート結果を学習支援システム課IR担当で集計し、HGU数理・データサイエンス教育プログラム運営委員会に報告されている。質問項目の１つである「授業内容の理解度」は、本プログラムの必修科目で3.53～4.54（1点～5点（5点満点）での評価）、選択科目で3.30～4.42となった。また、各科目の「総合評価」は、必修科目で4.05～4.25、選択科目で3.80～4.59であったことから、本プログラムで設定されている科目の授業内容は概ね理解されていると評価できる。
C16: 学生アンケート等を通じた後輩等他の学生への推奨度 | E16: 授業改善アンケートの「積極的な授業参加」の回答は3.73～4.61、「将来役に立つ」かどうかの回答は3.81～4.93と他の質問より高い結果となっていることから、自身の履修した科目について、後輩等への推奨度は高いのではないかと推察している。
C17: 全学的な履修者数、履修率向上に向けた計画の達成・進捗状況 | E17: 本学のポータルサイトG-PLUS!で、全ての学生に対して本プログラムへの参加を呼びかけているものの、初年度(2023年度)の参加者数は１６２名に留まっている。2024年度からは、１学期および２学期の履修登録の時期に合わせて本プログラムへの参加を促す予定である。経済学部、法学部、人文学部、工学部の必修科目である「教養科目特別講義（情報リテラシー）」の担当教員を2024年度からは３名に増員し、800名程度の履修者にも対応できる教員配置としている。また、経営学部の必修科目については、2023年度以降入学者からは卒業要件の必履修科目としている。
B18: 学外からの視点
C19: 教育プログラム修了者の進路、活躍状況、企業等の評価 | E19: 2023年度の開始であるため修了者は８名に留まっており、企業等からの修了者への直接的な評価はまだ受けていないが、全学的な自己点検・評価のために行った企業等との意見交換で、本プログラムの必要性と重要性について確認することができた。
C20: 産業界からの視点を含めた教育プログラム内容・手法等への意見 | E20: 「北海学園大学の教育活動・学生支援に関するアンケート調査」を実施しており、2023年度は民間企業・団体・自治体・官公庁など386社に依頼した（回答率26.4％）。アンケートでは本プログラムに関連して、“データサイエンスやAI に関する知識”、“情報化社会で必要となるAI を含めた基礎的な情報リテラシーの能力”の必要性についてお尋ねした。また、民間企業3社（情報通信業、建設業、金融業）の人事担当者、自治体1団体の総務・人事／DX担当者と対面で意見交換を行った。本プログラムの内容を示したうえで、このようなカリキュラムの必要性や重要性について伺った。多くの肯定的、積極的なご意見を頂戴した。
B21: 数理・データサイエンス・ＡＩを「学ぶ楽しさ」「学ぶことの意義」を理解させること | E21: データサイエンスを学ぶと、客観的な根拠となるデータを分析し可視化することで、「わからないことがわかる」楽しさに出会うことがある。そして、データサイエンスは実用性や応用性が高いため、際限のない知の探究が求められる。文系や理系にかかわらず、現代社会で必須の素養を身につけることができるように、必修科目以外に基礎的な数学、統計学、コンピュータ操作を含む情報に関する科目を選択科目として設定して、学生が自らの興味・関心に応じてこれらの能力を伸ばすことができるようにしている。
B22: 内容・水準を維持・向上しつつ、より「分かりやすい」授業とすること ※社会の変化や生成AI等の技術の発展を踏まえて教育内容を継続的に見直すなど、より教育効果の高まる授業内容・方法とするための取組や仕組みについても該当があれば記載 | E22: 2023年度２学期から全ての科目で成績提出時に当該科目のレビューを記述することになっており、教育改善についての記述についてはその方法を共有していく予定である。また、数理・データサイエンス・AI教育に関する講演会、シンポジウム、コンソーシアムなどへの参加を通じて、この分野の最新の教育水準を常に確認するとともに、他大学の例なども参考にして、分かりやすい授業の実施について改善を進めていく。

Sheet Sheet1
