Workbook

Sheet 様式１　プログラムを構成する授業科目
T1: 様式１ | V1: 「学部・学科によって、修了要件は相違する」場合は、本シートを複製の上＜様式１－〇＞と枝番号を付してください
B2: 大学等名 | C2: 名古屋学院大学
B3: プログラム名 | C3: 数理・データサイエンス・AI 教育プログラム
A5: プログラムを構成する授業科目について
A7: ① 教育プログラムの修了要件 | L7: 学部・学科によって、修了要件は相違しない
A9: ② 対象となる学部・学科名称
A14: ③ 修了要件
B15: 「情報処理リテラシー（2単位）」と「データサイエンスリテラシー（2単位）」計4単位を修得すること。 「情報処理リテラシー」は、全学で卒業要件として必修科目である。 「データサイエンスリテラシー」は、全学で卒業要件として選択科目である。 | X15: 【プルダウンリスト】
X16: 令和５年度以前より、履修することが必須のプログラムとして実施
X17: 令和８年度までに履修必須とする計画
X18: 令和９年度以降に履修必須とする計画、又は未定
B22: 必要最低科目数・単位数 | E22: 2 | F22: 科目 | H22: 4 | I22: 単位 | M22: 履修必須の有無 | N22: 令和９年度以降に履修必須とする計画、又は未定
A24: ④ 現在進行中の社会変化（第４次産業革命、Society 5.0、データ駆動型社会等）に深く寄与しているものであり、それが自らの生活と密接に結びついている」の内容を含む授業科目
B26: 授業科目 | G26: 単位数 | H26: 必須 | I26: 1-1 | J26: 1-6 | K26: 授業科目 | R26: 単位数 | S26: 必須 | T26: 1-1 | U26: 1-6
B27: 情報処理リテラシー | G27: 2 | H27: ○ | I27: ○
B28: データサイエンスリテラシー | G28: 2 | H28: ○ | I28: ○ | J28: ○
A35: ⑤ 「社会で活用されているデータ」や「データの活用領域」は非常に広範囲であって、日常生活や社会の課題を解決する有用なツールになり得るもの」の内容を含む授業科目
B37: 授業科目 | G37: 単位数 | H37: 必須 | I37: 1-2 | J37: 1-3 | K37: 授業科目 | R37: 単位数 | S37: 必須 | T37: 1-2 | U37: 1-3
B38: 情報処理リテラシー | G38: 2 | H38: ○ | I38: ○
B39: データサイエンスリテラシー | G39: 2 | H39: ○ | J39: ○
A46: ⑥ 「様々なデータ利活用の現場におけるデータ利活用事例が示され、様々な適用領域（流通、製造、金融、サービス、インフラ、公共、ヘルスケア等）の知見と組み合わせることで価値を創出するもの」の内容を含む授業科目
B48: 授業科目 | G48: 単位数 | H48: 必須 | I48: 1-4 | J48: 1-5 | K48: 授業科目 | R48: 単位数 | S48: 必須 | T48: 1-4 | U48: 1-5
B49: 情報処理リテラシー | G49: 2 | H49: ○ | I49: ○ | J49: ○
B50: データサイエンスリテラシー | G50: 2 | H50: ○ | I50: ○ | J50: ○
A57: ⑦ 「活用に当たっての様々な留意事項（ELSI、個人情報、データ倫理、ＡＩ社会原則等）を考慮し、情報セキュリティや情報漏洩等、データを守る上での留意事項への理解をする」の内容を含む授業科目
B59: 授業科目 | G59: 単位数 | H59: 必須 | I59: 3-1 | J59: 3-2 | K59: 授業科目 | R59: 単位数 | S59: 必須 | T59: 3-1 | U59: 3-2
B60: 情報処理リテラシー | G60: 2 | H60: ○ | I60: ○ | J60: ○
B61: データサイエンスリテラシー | G61: 2 | H61: ○ | I61: ○
A68: ⑧ 「実データ・実課題（学術データ等を含む）を用いた演習など、社会での実例を題材として、「データを読む、説明する、扱う」といった数理・データサイエンス・ＡＩの基本的な活用法に関するもの」の内容を含む授業科目
B70: 授業科目 | F70: 単位数 | G70: 必須 | H70: 2-1 | I70: 2-2 | J70: 2-3 | K70: 授業科目 | Q70: 単位数 | R70: 必須 | S70: 2-1 | T70: 2-2 | U70: 2-3
B71: 情報処理リテラシー | F71: 2 | G71: ○ | H71: ○ | I71: ○ | J71: ○
B72: データサイエンスリテラシー | F72: 2 | G72: ○ | H72: ○
A79: ⑨ 選択「４．オプション」の内容を含む授業科目
B80: 授業科目 | G80: 選択項目 | K80: 授業科目 | R80: 選択項目
B81: 情報処理リテラシー | G81: 4‐2アルゴリズム基礎
B82: 情報処理リテラシー | G82: 4‐3データ構造とプログラミング基礎
B83: データサイエンスリテラシー | G83: 4‐7データハンドリング
B84: データサイエンスリテラシー | G84: 4‐8データ活用実践（教師あり学習）
B85: データサイエンスリテラシー | G85: 4‐9データ活用実践（教師なし学習）
A89: ⑩ プログラムを構成する授業の内容
...

Sheet 様式２ 履修者等数の実績
S1: 様式２
Q2: ='様式１ プログラムを構成する授業科目'!C2 -> 名古屋学院大学
A3: プログラムの履修者数等の実績について
A5: ①プログラム開設年度 | C5: 令和5 | E5: 年度
A7: ②大学等全体の男女別学生数 | E7: 男性 | F7: 4388 | G7: 人 | H7: 女性 | I7: 1787 | J7: 人 | K7: （ | L7: 合計 | M7: =F7+I7 -> 6175 | N7: 人 | O7: ）
A9: ③履修者・修了者の実績
B11: 学部・学科名称 | C11: 学生数 | D11: 入学 定員 | E11: 収容 定員 | F11: 令和5年度 | H11: 令和4年度 | J11: 令和3年度 | L11: 令和2年度 | N11: 令和元年度 | P11: 平成30年度 | R11: 履修者数 合計 | S11: 履修率
F12: 履修者数 | G12: 修了者数 | H12: 履修者数 | I12: 修了者数 | J12: 履修者数 | K12: 修了者数 | L12: 履修者数 | M12: 修了者数 | N12: 履修者数 | O12: 修了者数 | P12: 履修者数 | Q12: 修了者数
B13: 経済学部 | C13: 1169 | D13: 250 | E13: 1000 | F13: 279 | G13: 47 | R13: =F13+H13+J13+L13+N13+P13 -> 279 | S13: =R13/E13 -> 0.279
B14: 現代社会学部 | C14: 704 | D14: 150 | E14: 600 | F14: 184 | G14: 6 | R14: =F14+H14+J14+L14+N14+P14 -> 184 | S14: =R14/E14 -> 0.30666667
B15: 商学部 | C15: 1339 | D15: 295 | E15: 1180 | F15: 356 | G15: 82 | R15: =F15+H15+J15+L15+N15+P15 -> 356 | S15: =R15/E15 -> 0.30169492
B16: 法学部 | C16: 782 | D16: 165 | E16: 660 | F16: 206 | G16: 56 | R16: =F16+H16+J16+L16+N16+P16 -> 206 | S16: =R16/E16 -> 0.31212121
B17: 外国語学部 | C17: 570 | D17: 140 | E17: 560 | F17: 163 | G17: 19 | R17: =F17+H17+J17+L17+N17+P17 -> 163 | S17: =R17/E17 -> 0.29107143
B18: 国際文化学部 | C18: 615 | D18: 150 | E18: 600 | F18: 202 | G18: 46 | R18: =F18+H18+J18+L18+N18+P18 -> 202 | S18: =R18/E18 -> 0.33666667
B19: スポーツ健康学部 | C19: 675 | D19: 170 | E19: 680 | F19: 172 | G19: 0 | R19: =F19+H19+J19+L19+N19+P19 -> 172 | S19: =R19/E19 -> 0.25294118
B20: リハビリテーション学部 | C20: 321 | D20: 80 | E20: 320 | F20: 90 | G20: 0 | R20: =F20+H20+J20+L20+N20+P20 -> 90 | S20: =R20/E20 -> 0.28125
B33: 合 計 | C33: =SUM(C13:C32) -> 6175 | D33: =SUM(D13:D32) -> 1400 | E33: =SUM(E13:E32) -> 5600 | F33: =SUM(F13:F32) -> 1652 | G33: =SUM(G13:G32) -> 256 | H33: =SUM(H13:H32) -> 0 | I33: =SUM(I13:I32) -> 0 | J33: =SUM(J13:J32) -> 0 | ... R33: =SUM(R13:R32) -> 1652 | S33: =R33/E33 -> 0.295

Sheet 様式３ 教育の質・履修者数を向上させるための体制・計画
I1: 様式３
G2: 大学等名 | H2: ='様式１ プログラムを構成する授業科目'!C2 -> 名古屋学院大学
C3: 数理・データサイエンス・AI 教育プログラム
A4: 教育の質・履修者数を向上させるための体制・計画について
A6: ① | B6: 全学の教員数 | C6: (常勤） | E6: 170 | F6: 人 | G6: （非常勤） | H6: 188 | I6: 人
A8: ② | B8: プログラムの授業を教えている教員数 | H8: 12 | I8: 人
A10: ③ | B10: プログラムの運営責任者
B11: （責任者名） | C11: 赤楚 治之 | G11: （役職名） | H11: 学長
A13: ④ | B13: プログラムを改善・進化させるための体制（委員会・組織等）
B14: 数理・データサイエンス・ＡＩ教育プログラム委員会
B16: （責任者名） | C16: 赤楚 治之 | G16: （役職名） | H16: 学長
A18: ⑤ | B18: プログラムを改善・進化させるための体制を定める規則名称
B19: 数理・データサイエンス・ＡＩ教育プログラム委員会規程
A21: ⑥ | B21: 体制の目的
B22: 委員会は、文部科学省が定める「数理・データサイエンス・AI教育プログラム認定制度」に基づく認定プログラムを運営、改善することを目的とする。 委員会では、具体的に以下を行う。 （１） 教育プログラムの立案、実施に関する事項 （２） 教育プログラムに設置する授業科目に関する事項 （３） 教育プログラムについての、自己点検・評価に関する事項 （４） 教育プログラムについての、情報公開に関する事項 （５） その他教育プログラム実施に際し、必要な事項
A34: ⑦ | B34: 具体的な構成員
B35: （１） 学長(数理・データサイエンス・ＡＩ教育プログラム委員長)：赤楚 治之 （２） 学術情報センター長：肥田 朋子 （３） 教務部長 兼 教養教育運営委員長：濵 満久 （４） 教養教育運営委員会情報部会所属教員から若干名：齋藤 邦彦 （５） 事務局次長（教学担当）：加藤 高明 （６） 学術情報センター、教務部から事務職員各１名：牧野 雅(学術情報センター)、 岡本 康(教務課)
A48: ⑧ | B48: 履修者数・履修率の向上に向けた計画 ※様式１の「履修必須の有無」で「計画がある」としている場合は詳細について記載すること
B49: 令和５年度実績 | C49: ='様式２ 履修者等数の実績'!S33 -> 0.295 | E49: 令和６年度予定 | F49: 0.5 | H49: 令和７年度予定 | I49: 0.75
B50: 令和８年度予定 | C50: 1 | E50: 令和９年度予定 | F50: 1 | H50: 収容定員（名） | I50: ='様式２ 履修者等数の実績'!E33 -> 5600
B51: 具体的な計画
B52: 本学公式ホームページの「数理・データサイエンス・AI教育プログラム」のサイトで履修することで身に付くことができる力を掲載するとともに本学ポータルサイト上に本プログラムに関するバナーを掲載し、修了することによるメリットを定期的に発信していく。また、本教育プログラムの授業科目である「情報処理リテラシー」は、１年次の春学期全学部必修科目となっているため、授業内で数理・データサイエンス・AI教育プログラムについて紹介し、修了要件で必要となる「データサイエンスリテラシー」の履修を全学部に対して促す。
A65: ⑨ | B65: 学部・学科に関係なく希望する学生全員が受講可能となるような必要な体制・取組等
B66: 本教育プログラムを構成する2科目とも全学共通科目であり、全ての学生が受講することができる科目である。「情報処理リテラシー」は、１年次の春学期全学部必修科目として位置づけられており名古屋キャンパス、瀬戸キャンパスで学科毎に開講クラスを設定し、2023年度は合計73コマ、教員数11名を確保している。「データサイエンスリテラシー」は、Microsoft Streamでの動画配信機能や本学独自開発のポータルサイト[CCS]の資料配布機能、レポート提出機能を利用したオンデマンド授業としており、他の科目の授業時間や課外活動、所属キャンパス等による制限を受けず、希望する学生は、全員受講可能な体制を整えている。
A79: ⑩ | B79: できる限り多くの学生が履修できるような具体的な周知方法・取組
B80: 卒業要件上の必修科目である「情報処理リテラシー」の授業内で数理・データサイエンス・AI教育プログラムの紹介を行い、本教育プログラムを修了することで、社会の中で求められる役割・責任を自覚し、数理・データサイエンス・AIの広範な適用領域を意識しながらデータを適切に読み解き、活用する方法を身につけることができる等のメリットを伝えている。また、大学公式ホームページに数理・データサイエンス・AI教育プログラム専用ページ(https://www.ngu.jp/faculty/department/datascience/)を作成し、学生が情報を受け取りやすい環境を整備し周知するとともに、大学案内などの広報媒体を使用し、本教育プログラムの情報を発信し、入学予定者へのさらなる訴求も行っていく。
A93: ⑪ | B93: できる限り多くの学生が履修・修得できるようなサポート体制
B94: より多くの学生が履修・修得できるようにサポートする手段として、本学独自開発の学内ポータルサイト[CCS]で授業の資料提示やレポート提出、質問受付等を行っている。また、本学では、全ての学生に一台ずつノートPCを配付しているため、場所を選ばず予習や復習ができる環境となっている。「データサイエンスリテラシー」に関しては、授業で使用する教材を動画とPDFの両方で作成しており、動画での復習が可能となることに加え、動画が視聴できない環境下でもPDFを閲覧し、学習できるよう配慮している。また、学生からのパソコンの相談を受け付けるパソコン相談コーナーで授業で使用する統計解析ソフトR、プログラミング言語Python等のアプリケーションのインストールをサポートしている。
A107: ⑫ | B107: 授業時間内外で学習指導、質問を受け付ける具体的な仕組み
B108: 本学独自開発の学内ポータルサイト[CCS]で、学生は授業時間内外で担当教員に質問ができる。担当教員には質問が来ると通知がされ、返答できる仕組みとなっている。「情報処理リテラシー」では、授業内でのパソコン操作実習の進捗具合を都度確認し、進捗が遅れている学生がいた場合は、個別に対応し授業を進めていることに加え、Microsoft Teamsでのチャットやメールによる質問も受け付けており、学生からの質問受付の方法を複数用意している。また、学生からのパソコンの相談を受け付けるパソコン相談コーナーでは、パソコンの操作実習で使用するMicrosoft Office等の使用方法について相談を受け付けており、授業時間外でも対面でサポートできる体制を整えている。

Sheet 様式４　自己点検・評価
I1: 様式４
H2: 大学等名 | I2: ='様式１ プログラムを構成する授業科目'!C2 -> 名古屋学院大学
A3: 自己点検・評価について
A5: ① | B5: プログラムの自己点検・評価を行う体制（委員会・組織等）
B6: 数理・データサイエンス・ＡＩ教育プログラム委員会
D8: （責任者名） | E8: 学長 | G8: （役職名） | H8: 赤楚 治之
A10: ② | B10: 自己点検・評価体制における意見等
B11: 自己点検・評価の視点 | E11: 自己点検・評価体制における意見・結果・改善に向けた取組等
B12: 学内からの視点
C13: プログラムの履修・修得状況 | E13: 学内ポータルサイト[CCS]において、プログラムを構成する授業科目の履修・修得状況を管理するとともに、これらのデータは、数理・データサイエンス・ＡＩ教育プログラム委員会で共有し、本教育プログラムの評価・改善に活用している。令和5年度から開始した本教育プログラムの履修状況としては、全学で300人が履修、256人が修了した。教育プログラムの対象科目を履修できる1年次の本教育プログラムの全体に対する修了率は、15.5%であった。 (参考) ＜情報処理リテラシー＞ 履修者数：1,652名、修得者数：1,581名 ＜データサイエンスリテラシー＞ 履修者数：300名、修得者数：256名
C14: 学修成果 | E14: 本教育プログラム受講者全員に対して授業アンケートを実施しており、学内ポータルサイト[CCS]で学生が授業に関する内容に、さらに興味・感心を持つようになったかや授業を通じて、新しい知識や技能を得たり、理解が深まったかを把握できる仕組みとなっている。令和5年度の結果では、興味関心に関する質問に対し、「情報処理リテラシー」は87.7%、「データサイエンスリテラシー」は72.4%の学生が興味を持ったと回答し、「理解・修得」に関する質問に対しては、「情報処理リテラシー」は95.9%、「データサイエンスリテラシー」は86.1%の学生が理解が高まったと回答している。
C15: 学生アンケート等を通じた学生の内容の理解度 | E15: 本教育プログラム受講者全員に対して授業アンケートを実施しており、学内ポータルサイト[CCS]で学生の理解度を担当教員が把握できる仕組みとなっている。アンケート結果は数理・データサイエンス・ＡＩ教育プログラム委員会で共有し、本教育プログラムの評価・改善に活用している。前項(学修成果)に記載のとおり「理解・修得」に関するアンケート結果から、多くの学生が理解が深まったと回答している。記述式のアンケートでも社会で役立つIT関連の知識、スキルを身につけれられたなどの回答があり、授業内容を理解し、スキルを身につけられていることが分かる。
C16: 学生アンケート等を通じた後輩等他の学生への推奨度 | E16: 授業アンケートでは、授業に対する満足度を定量的に把握できる。また、記述式設問の「良かった点、評価できる点」等の回答でより具体的な意見を把握することができる。また、これら授業アンケートの結果は、常に全学生が閲覧可能な状態である。令和5年度のアンケート結果では、「総合的にみて、この授業の内容に満足しているか」の質問に対して、「情報処理リテラシー」は95.1%、「データサイエンスリテラシー」は78.6%の学生が満足していると回答していることから、後輩等他の学生への推奨度が高いことが分かる。
C17: 全学的な履修者数、履修率向上に向けた計画の達成・進捗状況 | E17: プログラムを構成する授業科目の履修・修得状況を数理・データサイエンス・ＡＩ教育プログラム委員会で共有し、履修・修得状況に問題がないか点検し、必要があれば改善していく。本学は、3月下旬(在学生)と4月上旬(新入生)に春学期と秋学期の1年分をまとめて履修登録の受け付けをしている。本教育プログラムの構成科目である「データサイエンスリテラシー」は秋学期に開講している科目だが、開講する約半年前の早期段階で履修登録人数を把握することができるため、履修状況を確認し履修者が少ない等問題があれば、9月下旬の秋学期履修登録変更期間までに履修者が増えるよう情報発信するなど対策を講じていく。
B18: 学外からの視点
C19: 教育プログラム修了者の進路、活躍状況、企業等の評価 | E19: 本教育プログラムは令和5年度から開講しているため、プログラムを修了し、卒業した学生はいない状況であり、第1期生の卒業は令和8年度からとなる。今後に向けては、本教育プログラムを修了した卒業生の進路先や活躍状況を把握するため、就職先企業に対して調査を実施、本教育プログラムを修了した卒業生の企業における活用状況や評価を把握する仕組みを数理・データサイエンス・ＡＩ教育プログラム委員会で検討していく。
C20: 産業界からの視点を含めた教育プログラム内容・手法等への意見 | E20: 学内就職説明会で来学した企業やインターンシップの依頼がある企業に対してアンケートを実施し、本教育プログラムの内容・手法等への意見をキャリアセンターを通じて収集していく。また、自治体や企業に教育プログラムの講義内容及び実データを活用した演習等の協力を仰ぎ、社会でデータがどのようなデータがどんな分析をされ、実際に活用されているか具体的なイメージがつくように内容・手法の見直しを行っていく。
B21: 数理・データサイエンス・ＡＩを「学ぶ楽しさ」「学ぶことの意義」を理解させること | E21: 本教育プログラムでは、時事やトレンドなど社会での実例をもとにAI技術等がどのように活用されているかの紹介や実際に統計解析ソフトR、プログラミング言語Pythonを使ったデータ分析を実施する等、好奇心を高める授業内容としている。令和5年度のアンケート結果では、「教員は学生が授業内容に興味を持つように工夫していた。」の質問に対して、「情報処理リテラシー」は92.2%、「データサイエンスリテラシー」は71.7%の学生が興味を持つよう工夫されていたと回答している。
B22: 内容・水準を維持・向上しつつ、より「分かりやすい」授業とすること ※社会の変化や生成AI等の技術の発展を踏まえて教育内容を継続的に見直すなど、より教育効果の高まる授業内容・方法とするための取組や仕組みについても該当があれば記載 | E22: 毎年の学生アンケートの意見を参考に、学生の「分かりやすさ」の観点から授業の内容・実施方法の見直しを行っていく。令和5年度のアンケート結果では、「授業における適切な教材・資料の提示が理解を促した。」の質問に対して、「情報処理リテラシー」は88.7%、「データサイエンスリテラシー」は83.8%の学生が授業における適切な教材・資料の提示が理解を促したと回答している。また、記述式のアンケートでは、「先生の丁寧な指導や個別サポートのおかげで分かりやすかった(情報処理リテラシー)」、「PDFと動画が両方配布されており、じっくりと理解できた(データサイエンスリテラシー)」等の感想があった。
