Workbook

Sheet 様式１-１　プログラムを構成する授業科目
T1: 様式１-１ | V1: 「学部・学科によって、修了要件は相違する」場合は、本シートを複製の上＜様式１－〇＞と枝番号を付してください
B2: 大学等名 | C2: 名古屋国際工科専門職大学
B3: プログラム名 | C3: 数理・データサイエンス・AI教育リテラシープログラム
A5: プログラムを構成する授業科目について
A7: ① 教育プログラムの修了要件 | L7: 学部・学科によって、修了要件は相違する
A9: ② 対象となる学部・学科名称
B11: 工科学部・情報工学科
A14: ③ 修了要件
B15: 情報工学科では、１年次開講の「情報工学概論」と２年次開講の「確率統計論」の各2単位と、1年次開講の「コンピュータアーキテクチャ」の4単位の科目をすべて履修し、合計8単位を取得することにより、本プログラムの修了認定となります。 | X15: 【プルダウンリスト】
X16: 令和５年度以前より、履修することが必須のプログラムとして実施
X17: 令和８年度までに履修必須とする計画
X18: 令和９年度以降に履修必須とする計画、又は未定
B22: 必要最低科目数・単位数 | E22: 3 | F22: 科目 | H22: 8 | I22: 単位 | M22: 履修必須の有無 | N22: 令和５年度以前より、履修することが必須のプログラムとして実施
A24: ④ 現在進行中の社会変化（第４次産業革命、Society 5.0、データ駆動型社会等）に深く寄与しているものであり、それが自らの生活と密接に結びついている」の内容を含む授業科目
B26: 授業科目 | G26: 単位数 | H26: 必須 | I26: 1-1 | J26: 1-6 | K26: 授業科目 | R26: 単位数 | S26: 必須 | T26: 1-1 | U26: 1-6
B27: 情報工学概論 | G27: 2 | H27: ○ | I27: ○ | J27: ○
B28: コンピュータアーキテクチャ | G28: 4 | H28: ○ | I28: ○ | J28: ○
B29: 確率統計論 | G29: 2 | H29: ○
A35: ⑤ 「社会で活用されているデータ」や「データの活用領域」は非常に広範囲であって、日常生活や社会の課題を解決する有用なツールになり得るもの」の内容を含む授業科目
B37: 授業科目 | G37: 単位数 | H37: 必須 | I37: 1-2 | J37: 1-3 | K37: 授業科目 | R37: 単位数 | S37: 必須 | T37: 1-2 | U37: 1-3
B38: 情報工学概論 | G38: 2 | H38: ○ | I38: ○ | J38: ○
B39: コンピュータアーキテクチャ | G39: 4 | H39: ○ | I39: ○ | J39: ○
B40: 確率統計論 | G40: 2 | H40: ○
A46: ⑥ 「様々なデータ利活用の現場におけるデータ利活用事例が示され、様々な適用領域（流通、製造、金融、サービス、インフラ、公共、ヘルスケア等）の知見と組み合わせることで価値を創出するもの」の内容を含む授業科目
B48: 授業科目 | G48: 単位数 | H48: 必須 | I48: 1-4 | J48: 1-5 | K48: 授業科目 | R48: 単位数 | S48: 必須 | T48: 1-4 | U48: 1-5
B49: 情報工学概論 | G49: 2 | H49: ○ | I49: ○ | J49: ○
B50: コンピュータアーキテクチャ | G50: 4 | H50: ○ | I50: ○ | J50: ○
B51: 確率統計論 | G51: 2 | H51: ○
A57: ⑦ 「活用に当たっての様々な留意事項（ELSI、個人情報、データ倫理、ＡＩ社会原則等）を考慮し、情報セキュリティや情報漏洩等、データを守る上での留意事項への理解をする」の内容を含む授業科目
B59: 授業科目 | G59: 単位数 | H59: 必須 | I59: 3-1 | J59: 3-2 | K59: 授業科目 | R59: 単位数 | S59: 必須 | T59: 3-1 | U59: 3-2
B60: 情報工学概論 | G60: 2 | H60: ○ | I60: ○ | J60: ○
B61: コンピュータアーキテクチャ | G61: 4 | H61: ○ | I61: ○ | J61: ○
B62: 確率統計論 | G62: 2 | H62: ○
A68: ⑧ 「実データ・実課題（学術データ等を含む）を用いた演習など、社会での実例を題材として、「データを読む、説明する、扱う」といった数理・データサイエンス・ＡＩの基本的な活用法に関するもの」の内容を含む授業科目
B70: 授業科目 | F70: 単位数 | G70: 必須 | H70: 2-1 | I70: 2-2 | J70: 2-3 | K70: 授業科目 | Q70: 単位数 | R70: 必須 | S70: 2-1 | T70: 2-2 | U70: 2-3
B71: 情報工学概論 | F71: 2 | G71: ○
B72: コンピュータアーキテクチャ | F72: 4 | G72: ○
B73: 確率統計論 | F73: 2 | G73: ○ | H73: ○ | I73: ○ | J73: ○
A79: ⑨ 選択「４．オプション」の内容を含む授業科目
B80: 授業科目 | G80: 選択項目 | K80: 授業科目 | R80: 選択項目
...

Sheet 様式１-２　プログラムを構成する授業科目
T1: 様式１-２ | V1: 「学部・学科によって、修了要件は相違する」場合は、本シートを複製の上＜様式１－〇＞と枝番号を付してください
B2: 大学等名 | C2: 名古屋国際工科専門職大学
B3: プログラム名 | C3: 数理・データサイエンス・AI教育リテラシープログラム
A5: プログラムを構成する授業科目について
A7: ① 教育プログラムの修了要件 | L7: 学部・学科によって、修了要件は相違する
A9: ② 対象となる学部・学科名称
B11: 工科学部・デジタルエンタテインメント学科
A14: ③ 修了要件
B15: デジタルエンタテインメント学科では、１年次開講の「コンテンツデザイン概論」、「電子情報工学概論」と２年次開講の「統計論」の各2単位の科目をすべて履修し、合計6単位を取得することにより、本プログラムの修了認定となります。 | X15: 【プルダウンリスト】
X16: 令和５年度以前より、履修することが必須のプログラムとして実施
X17: 令和８年度までに履修必須とする計画
X18: 令和９年度以降に履修必須とする計画、又は未定
B22: 必要最低科目数・単位数 | E22: 3 | F22: 科目 | H22: 6 | I22: 単位 | M22: 履修必須の有無 | N22: 令和５年度以前より、履修することが必須のプログラムとして実施
A24: ④ 現在進行中の社会変化（第４次産業革命、Society 5.0、データ駆動型社会等）に深く寄与しているものであり、それが自らの生活と密接に結びついている」の内容を含む授業科目
B26: 授業科目 | G26: 単位数 | H26: 必須 | I26: 1-1 | J26: 1-6 | K26: 授業科目 | R26: 単位数 | S26: 必須 | T26: 1-1 | U26: 1-6
B27: コンテンツデザイン概論 | G27: 2 | H27: ○ | I27: ○ | J27: ○
B28: 電子情報工学概論 | G28: 2 | H28: ○ | I28: ○ | J28: ○
B29: 統計論 | G29: 2 | H29: ○
A35: ⑤ 「社会で活用されているデータ」や「データの活用領域」は非常に広範囲であって、日常生活や社会の課題を解決する有用なツールになり得るもの」の内容を含む授業科目
B37: 授業科目 | G37: 単位数 | H37: 必須 | I37: 1-2 | J37: 1-3 | K37: 授業科目 | R37: 単位数 | S37: 必須 | T37: 1-2 | U37: 1-3
B38: コンテンツデザイン概論 | G38: 2 | H38: ○ | I38: ○ | J38: ○
B39: 電子情報工学概論 | G39: 2 | H39: ○ | I39: ○ | J39: ○
B40: 統計論 | G40: 2 | H40: ○ | I40: ○ | J40: ○
A46: ⑥ 「様々なデータ利活用の現場におけるデータ利活用事例が示され、様々な適用領域（流通、製造、金融、サービス、インフラ、公共、ヘルスケア等）の知見と組み合わせることで価値を創出するもの」の内容を含む授業科目
B48: 授業科目 | G48: 単位数 | H48: 必須 | I48: 1-4 | J48: 1-5 | K48: 授業科目 | R48: 単位数 | S48: 必須 | T48: 1-4 | U48: 1-5
B49: コンテンツデザイン概論 | G49: 2 | H49: ○ | I49: ○ | J49: ○
B50: 電子情報工学概論 | G50: 2 | H50: ○ | I50: ○ | J50: ○
B51: 統計論 | G51: 2 | H51: ○ | I51: ○ | J51: ○
A57: ⑦ 「活用に当たっての様々な留意事項（ELSI、個人情報、データ倫理、ＡＩ社会原則等）を考慮し、情報セキュリティや情報漏洩等、データを守る上での留意事項への理解をする」の内容を含む授業科目
B59: 授業科目 | G59: 単位数 | H59: 必須 | I59: 3-1 | J59: 3-2 | K59: 授業科目 | R59: 単位数 | S59: 必須 | T59: 3-1 | U59: 3-2
B60: コンテンツデザイン概論 | G60: 2 | H60: ○ | I60: ○ | J60: ○
B61: 電子情報工学概論 | G61: 2 | H61: ○ | I61: ○ | J61: ○
B62: 統計論 | G62: 2 | H62: ○
A68: ⑧ 「実データ・実課題（学術データ等を含む）を用いた演習など、社会での実例を題材として、「データを読む、説明する、扱う」といった数理・データサイエンス・ＡＩの基本的な活用法に関するもの」の内容を含む授業科目
B70: 授業科目 | F70: 単位数 | G70: 必須 | H70: 2-1 | I70: 2-2 | J70: 2-3 | K70: 授業科目 | Q70: 単位数 | R70: 必須 | S70: 2-1 | T70: 2-2 | U70: 2-3
B71: コンテンツデザイン概論 | F71: 2 | G71: ○
B72: 電子情報工学概論 | F72: 2 | G72: ○
B73: 統計論 | F73: 2 | G73: ○ | H73: ○ | I73: ○ | J73: ○
A79: ⑨ 選択「４．オプション」の内容を含む授業科目
B80: 授業科目 | G80: 選択項目 | K80: 授業科目 | R80: 選択項目
...

Sheet 様式２ 履修者等数の実績
S1: 様式２
Q2: ='様式１-１ プログラムを構成する授業科目'!C2 -> 名古屋国際工科専門職大学
A3: プログラムの履修者数等の実績について
A5: ①プログラム開設年度 | C5: 令和3 | E5: 年度
A7: ②大学等全体の男女別学生数 | E7: 男性 | F7: 342 | G7: 人 | H7: 女性 | I7: 40 | J7: 人 | K7: （ | L7: 合計 | M7: =F7+I7 -> 382 | N7: 人 | O7: ）
A9: ③履修者・修了者の実績
B11: 学部・学科名称 | C11: 学生数 | D11: 入学 定員 | E11: 収容 定員 | F11: 令和5年度 | H11: 令和4年度 | J11: 令和3年度 | L11: 令和2年度 | N11: 令和元年度 | P11: 平成30年度 | R11: 履修者数 合計 | S11: 履修率
F12: 履修者数 | G12: 修了者数 | H12: 履修者数 | I12: 修了者数 | J12: 履修者数 | K12: 修了者数 | L12: 履修者数 | M12: 修了者数 | N12: 履修者数 | O12: 修了者数 | P12: 履修者数 | Q12: 修了者数
B13: 情報工学科 | C13: 249 | D13: 80 | E13: 320 | F13: 99 | G13: 91 | H13: 82 | I13: 81 | J13: 89 | K13: 89 | R13: =F13+H13+J13+L13+N13+P13 -> 270 | S13: =R13/E13 -> 0.84375
B14: デジタルエンタテインメント学科 | C14: 133 | D14: 40 | E14: 160 | F14: 46 | G14: 46 | H14: 45 | I14: 44 | J14: 42 | K14: 42 | R14: =F14+H14+J14+L14+N14+P14 -> 133 | S14: =R14/E14 -> 0.83125
R15: =F15+H15+J15+L15+N15+P15 -> 0 | S15: =R15/E15 -> #DIV/0!
R16: =F16+H16+J16+L16+N16+P16 -> 0 | S16: =R16/E16 -> #DIV/0!
R17: =F17+H17+J17+L17+N17+P17 -> 0 | S17: =R17/E17 -> #DIV/0!
R18: =F18+H18+J18+L18+N18+P18 -> 0 | S18: =R18/E18 -> #DIV/0!
R19: =F19+H19+J19+L19+N19+P19 -> 0 | S19: =R19/E19 -> #DIV/0!
R20: =F20+H20+J20+L20+N20+P20 -> 0 | S20: =R20/E20 -> #DIV/0!
R21: =F21+H21+J21+L21+N21+P21 -> 0 | S21: =R21/E21 -> #DIV/0!
R22: =F22+H22+J22+L22+N22+P22 -> 0 | S22: =R22/E22 -> #DIV/0!
R23: =F23+H23+J23+L23+N23+P23 -> 0 | S23: =R23/E23 -> #DIV/0!
R24: =F24+H24+J24+L24+N24+P24 -> 0 | S24: =R24/E24 -> #DIV/0!
R25: =F25+H25+J25+L25+N25+P25 -> 0 | S25: =R25/E25 -> #DIV/0!
R26: =F26+H26+J26+L26+N26+P26 -> 0 | S26: =R26/E26 -> #DIV/0!
... R32: =F32+H32+J32+L32+N32+P32 -> 0 | S32: =R32/E32 -> #DIV/0!
B33: 合 計 | C33: =SUM(C13:C32) -> 382 | D33: =SUM(D13:D32) -> 120 | E33: =SUM(E13:E32) -> 480 | F33: =SUM(F13:F32) -> 145 | G33: =SUM(G13:G32) -> 137 | H33: =SUM(H13:H32) -> 127 | I33: =SUM(I13:I32) -> 125 | J33: =SUM(J13:J32) -> 131 | ... R33: =SUM(R13:R32) -> 403 | S33: =R33/E33 -> 0.83958333

Sheet 様式３ 教育の質・履修者数を向上させるための体制・計画
I1: 様式３
G2: 大学等名 | H2: ='様式１-１ プログラムを構成する授業科目'!C2 -> 名古屋国際工科専門職大学
A4: 教育の質・履修者数を向上させるための体制・計画について
A6: ① | B6: 全学の教員数 | C6: (常勤） | E6: 28 | F6: 人 | G6: （非常勤） | H6: 3 | I6: 人
A8: ② | B8: プログラムの授業を教えている教員数 | H8: 3 | I8: 人
A10: ③ | B10: プログラムの運営責任者
B11: （責任者名） | C11: 松井 信行 | G11: （役職名） | H11: 学長
A13: ④ | B13: プログラムを改善・進化させるための体制（委員会・組織等）
B14: FD委員会
B16: （責任者名） | C16: 西井 育生 | G16: （役職名） | H16: 教授
A18: ⑤ | B18: プログラムを改善・進化させるための体制を定める規則名称
B19: 名古屋国際工科専門職大学 FD(ファカルティ・ディベロップメント)委員会規程
A21: ⑥ | B21: 体制の目的
B22: 本学カリキュラムの中で、「数理・データサイエンス・AI」に関する科目の履修と、教育内容の高度化を図り、当該領域の基盤を固めるとともに、接続科目との整合性を調整してし、教育効果の改善を推進していく。
A34: ⑦ | B34: 具体的な構成員
B35: 西井 育生（デジタルエンタテイメント学科、教授） 佐藤 省三（情報工学科、教授） 小南 哲也（情報工学科、教授） 伊部 公紀（デジタルエンタテインメント学科、講師） 田中 厚美（デジタルエンタテインメント学科、講師）
A48: ⑧ | B48: 履修者数・履修率の向上に向けた計画 ※様式１の「履修必須の有無」で「計画がある」としている場合は詳細について記載すること
B49: 令和５年度実績 | C49: ='様式２ 履修者等数の実績'!S33 -> 0.83958333 | E49: 令和６年度予定 | F49: 0.92 | H49: 令和７年度予定 | I49: 1
B50: 令和８年度予定 | C50: 1 | E50: 令和９年度予定 | F50: 1 | H50: 収容定員（名） | I50: ='様式２ 履修者等数の実績'!E33 -> 480
B51: 具体的な計画
B52: 本学ではプログラムを構成する授業科目が必修科目となっているため、現体制を維持することにより、履修者数・履修率が向上していく。
A65: ⑨ | B65: 学部・学科に関係なく希望する学生全員が受講可能となるような必要な体制・取組等
B66: 情報工学科の「情報工学概論」「コンピュータアーキテクチャ」「確率統計論」は、それぞれともに本学の数理・データサイエンス・AIに関する基礎科目であり、各学科で卒業必修科目に位置付けられているため、すべての学生が履修する。
A79: ⑩ | B79: できる限り多くの学生が履修できるような具体的な周知方法・取組
B80: 全学共通の施策として以下の２点が実施されている。 (1)LMSによる課題の提出を行い、評価のフィードバックを行えるような環境を提供している。 (2)Slackにより授業の補足の情報の配信を行い、また学生から各科目の教員に質問を行う ことができる環境を提供している。
A93: ⑪ | B93: できる限り多くの学生が履修・修得できるようなサポート体制
B94: 全学共通の施策として以下の２点が実施されている。 (1)LMSによる課題の提出を行い、評価のフィードバックを行えるような環境を提供している。 (2)Slackにより授業の補足の情報の配信を行い、また学生から各科目の教員に質問を行う ことができる環境を提供している。
A107: ⑫ | B107: 授業時間内外で学習指導、質問を受け付ける具体的な仕組み
B108: 全学共通の施策として以下の２点が実施されている。 (1)LMSによる課題の提出を行い、評価のフィードバック２を行えるような環境を提供している。 (2)Slackにより授業の補足の情報の配信を行い、また学生から各科目の教員に質問を行う ことができる環境を提供している。

Sheet 様式４　自己点検・評価
I1: 様式４
H2: 大学等名 | I2: ='様式１-１ プログラムを構成する授業科目'!C2 -> 名古屋国際工科専門職大学
A3: 自己点検・評価について
A5: ① | B5: プログラムの自己点検・評価を行う体制（委員会・組織等）
B6: 自己点検・評価委員会
D8: （責任者名） | E8: 松井 信行 | G8: （役職名） | H8: 学長
A10: ② | B10: 自己点検・評価体制における意見等
B11: 自己点検・評価の視点 | E11: 自己点検・評価体制における意見・結果・改善に向けた取組等
B12: 学内からの視点
C13: プログラムの履修・修得状況 | E13: 出欠をLMSで把握、単位取得情報は成績管理システムで担任が把握出来るような仕組みが整っている。LMSの出欠情報は、毎週全教員にフィードバックされるため、担当科目の履修・修得状況の向上に努めている。
C14: 学修成果 | E14: 本講義受講者全員に対してLMSなどを用いた授業アンケートを実施しており、アンケート結果をもとに、学生の理解度を分析し、学修成果の確認を行っている。
C15: 学生アンケート等を通じた学生の内容の理解度 | E15: 授業アンケートの分析結果等により、数理の理解度が高くないことから、教員を増員するなど指導体制の強化を図っていく。
C16: 学生アンケート等を通じた後輩等他の学生への推奨度 | E16: 本科目は必修科目のため、履修する上での先輩から後輩、他学生への推奨、という場面は特段発生しないが、学内コミュニケーションツールとして整備したSlackによる学年を超えた交流や研究室活動、課外活動など上級生と下級生が交流する状況において、本教育プログラムで身につけた知識やスキル、数理・データサイエンス・AIなどの話題が学びの基盤となることを相互に共有し、また刺激しあう状況があると考えられる。
C17: 全学的な履修者数、履修率向上に向けた計画の達成・進捗状況 | E17: 本科目は全学的な卒業必修科目に位置付けられている。卒業までにすべての履修者は本プログラムを修了することになる。
B18: 学外からの視点
C19: 教育プログラム修了者の進路、活躍状況、企業等の評価 | E19: 令和３年度から始まった講義であり、まだ修了者の進路、活躍状況、企業の評価は調査されていない。今後、卒業生調査を行うことを予定している。
C20: 産業界からの視点を含めた教育プログラム内容・手法等への意見 | E20: 本学では、産業界からの視点を教育に反映させるため、産業界と「教育課程連携協議会」を運営し、意見をいただいている。また、地域共創デザイン実習や臨地実務実習において、数理・データサイエンス・AIに関する基礎学力の強化を求める意見や期待が出されている。
B21: 数理・データサイエンス・ＡＩを「学ぶ楽しさ」「学ぶことの意義」を理解させること | E21: キャリア教育プログラムの一環として両学科合同による拡大授業に外部講師を招き、講演を行っている。AI・深層学習に関する最先端・第一線の研究者を招いた講演により、学びの楽しさを感じることができるような機会を与えるよう工夫している。
B22: 内容・水準を維持・向上しつつ、より「分かりやすい」授業とすること ※社会の変化や生成AI等の技術の発展を踏まえて教育内容を継続的に見直すなど、より教育効果の高まる授業内容・方法とするための取組や仕組みについても該当があれば記載 | E22: LMSなどを用いた授業アンケートにより、学生の意見を抽出する仕組みがあり、FD活動等を通じてより「分かりやすい」授業となるよう努めている。
