Workbook

Sheet 様式１-1　プログラムを構成する授業科目
T1: 様式１-１ | V1: 「学部・学科によって、修了要件は相違する」場合は、本シートを複製の上＜様式１－〇＞と枝番号を付してください
B2: 大学等名 | C2: 国際医療福祉大学
B3: プログラム名 | C3: 国際医療福祉大学数理・データサイエンス・AI教育プログラム
A5: プログラムを構成する授業科目について
A7: ① 教育プログラムの修了要件 | L7: 学部・学科によって、修了要件は相違する
A9: ② 対象となる学部・学科名称
B11: 保健医療学部、医療福祉学部、薬学部、医学部、成田看護学部、成田保健医療学部、小田原保健医療学部、福岡保健医療学部
A14: ③ 修了要件
B15: 以下２科目、合計２単位を修得すること。 ・データリテラシー【１単位】 ・医療必修-医療の倫理とプロ意識・医療情報-【１単位】 | X15: 【プルダウンリスト】
X16: 令和５年度以前より、履修することが必須のプログラムとして実施
X17: 令和８年度までに履修必須とする計画
X18: 令和９年度以降に履修必須とする計画、又は未定
B22: 必要最低科目数・単位数 | E22: 2 | F22: 科目 | H22: 2 | I22: 単位 | M22: 履修必須の有無 | N22: 令和５年度以前より、履修することが必須のプログラムとして実施
A24: ④ 現在進行中の社会変化（第４次産業革命、Society 5.0、データ駆動型社会等）に深く寄与しているものであり、それが自らの生活と密接に結びついている」の内容を含む授業科目
B26: 授業科目 | G26: 単位数 | H26: 必須 | I26: 1-1 | J26: 1-6 | K26: 授業科目 | R26: 単位数 | S26: 必須 | T26: 1-1 | U26: 1-6
B27: データリテラシー | G27: 1 | H27: ○ | I27: ○
B28: 医療必修-医療の倫理とプロ意識・医療情報- | G28: 1 | H28: ○ | J28: ○
A35: ⑤ 「社会で活用されているデータ」や「データの活用領域」は非常に広範囲であって、日常生活や社会の課題を解決する有用なツールになり得るもの」の内容を含む授業科目
B37: 授業科目 | G37: 単位数 | H37: 必須 | I37: 1-2 | J37: 1-3 | K37: 授業科目 | R37: 単位数 | S37: 必須 | T37: 1-2 | U37: 1-3
B38: データリテラシー | G38: 1 | H38: ○ | I38: ○
B39: 医療必修-医療の倫理とプロ意識・医療情報- | G39: 1 | H39: ○ | I39: ○ | J39: ○
A46: ⑥ 「様々なデータ利活用の現場におけるデータ利活用事例が示され、様々な適用領域（流通、製造、金融、サービス、インフラ、公共、ヘルスケア等）の知見と組み合わせることで価値を創出するもの」の内容を含む授業科目
B48: 授業科目 | G48: 単位数 | H48: 必須 | I48: 1-4 | J48: 1-5 | K48: 授業科目 | R48: 単位数 | S48: 必須 | T48: 1-4 | U48: 1-5
B49: 医療必修-医療の倫理とプロ意識・医療情報- | G49: 1 | H49: ○ | I49: ○ | J49: ○
A57: ⑦ 「活用に当たっての様々な留意事項（ELSI、個人情報、データ倫理、ＡＩ社会原則等）を考慮し、情報セキュリティや情報漏洩等、データを守る上での留意事項への理解をする」の内容を含む授業科目
B59: 授業科目 | G59: 単位数 | H59: 必須 | I59: 3-1 | J59: 3-2 | K59: 授業科目 | R59: 単位数 | S59: 必須 | T59: 3-1 | U59: 3-2
B60: 医療必修-医療の倫理とプロ意識・医療情報- | G60: 1 | H60: ○ | I60: ○ | J60: ○
A68: ⑧ 「実データ・実課題（学術データ等を含む）を用いた演習など、社会での実例を題材として、「データを読む、説明する、扱う」といった数理・データサイエンス・ＡＩの基本的な活用法に関するもの」の内容を含む授業科目
B70: 授業科目 | F70: 単位数 | G70: 必須 | H70: 2-1 | I70: 2-2 | J70: 2-3 | K70: 授業科目 | Q70: 単位数 | R70: 必須 | S70: 2-1 | T70: 2-2 | U70: 2-3
B71: データリテラシー | F71: 1 | G71: ○ | H71: ○ | I71: ○ | J71: ○
A79: ⑨ 選択「４．オプション」の内容を含む授業科目
B80: 授業科目 | G80: 選択項目 | K80: 授業科目 | R80: 選択項目
A89: ⑩ プログラムを構成する授業の内容
B90: 授業に含まれている内容・要素 | D90: 講義内容
B91: （１）現在進行中の社会変化（第４次産業革命、Society 5.0、データ駆動型社会等）に深く寄与しているものであり、それが自らの生活と密接に結びついている | C91: 1-1 | D91: データリテラシー 第1回 データリテラシー入門 （ビックデータ、IoT、AI、第4次産業革命、Society 5.0、データ駆動型社会、データ量の増加、人間の知的活動とAIの関係性）
C92: 1-6 | D92: 医療必修 第14回 ICT・AIの医学・医療への応用とセキュリティ （AI最新技術の活用例、Society 5.0）
B93: （２）「社会で活用されているデータ」や「データの活用領域」は非常に広範囲であって、日常生活や社会の課題を解決する有用なツールになり得るもの | C93: 1-2 | D93: データリテラシー 第1回 データリテラシー入門 （調査データ、実験データ、ログデータ、1次データ、2次データ、データのメタ化、構造化データ、非構造化データ、オープンデータ） 医療必修 第9回 社会におけるデータ・AI利活用 （データ・AI活用領域の広がり、仮説検証、調査データ、実験データ、ログデータ、1次データ、2次データ、データのメタ化、構造化データ、非構造化データ、オープンデータ、生成AI）
C94: 1-3 | D94: 医療必修 第9回 社会におけるデータ・AI利活用 （データ・AI活用領域の広がり、仮説検証、調査データ、実験データ、ログデータ、1次データ、2次データ、データのメタ化、構造化データ、非構造化データ、オープンデータ、生成AI）
B95: （３）様々なデータ利活用の現場におけるデータ利活用事例が示され、様々な適用領域（流通、製造、金融、サービス、インフラ、公共、ヘルスケア等）の知見と組み合わせることで価値を創出するもの | C95: 1-4 | D95: 医療必修 第9回 社会におけるデータ・AI利活用 医療必修 第13回 医療データ管理と病院管理・データ利活用の現場 医療必修 第14回 ICT・AIの医学・医療への応用とセキュリティ
C96: 1-5 | D96: 医療必修 第13回 医療データ管理と病院管理・データ利活用の現場 医療必修 第14回 ICT・AIの医学・医療への応用とセキュリティ
...

Sheet 様式１-２　プログラムを構成する授業科目 (成田RT)
T1: 様式１-２ | V1: 「学部・学科によって、修了要件は相違する」場合は、本シートを複製の上＜様式１－〇＞と枝番号を付してください
B2: 大学等名 | C2: 国際医療福祉大学
B3: プログラム名 | C3: 国際医療福祉大学数理・データサイエンス・AI教育プログラム
A5: プログラムを構成する授業科目について
A7: ① 教育プログラムの修了要件 | L7: 学部・学科によって、修了要件は相違する
A9: ② 対象となる学部・学科名称
B11: 成田保健医療学部放射線・情報科学科
A14: ③ 修了要件
B15: 以下２科目、合計２単位を修得すること。 ・情報処理Ⅱ（基礎）【１単位】 ・医療必修-医療の倫理とプロ意識・医療情報-【１単位】 | X15: 【プルダウンリスト】
X16: 令和５年度以前より、履修することが必須のプログラムとして実施
X17: 令和８年度までに履修必須とする計画
X18: 令和９年度以降に履修必須とする計画、又は未定
B22: 必要最低科目数・単位数 | E22: 2 | F22: 科目 | H22: 2 | I22: 単位 | M22: 履修必須の有無 | N22: 令和５年度以前より、履修することが必須のプログラムとして実施
A24: ④ 現在進行中の社会変化（第４次産業革命、Society 5.0、データ駆動型社会等）に深く寄与しているものであり、それが自らの生活と密接に結びついている」の内容を含む授業科目
B26: 授業科目 | G26: 単位数 | H26: 必須 | I26: 1-1 | J26: 1-6 | K26: 授業科目 | R26: 単位数 | S26: 必須 | T26: 1-1 | U26: 1-6
B27: 情報処理Ⅱ（基礎） | G27: 1 | H27: ○ | I27: ○
B28: 医療必修-医療の倫理とプロ意識・医療情報- | G28: 1 | H28: ○ | J28: ○
A35: ⑤ 「社会で活用されているデータ」や「データの活用領域」は非常に広範囲であって、日常生活や社会の課題を解決する有用なツールになり得るもの」の内容を含む授業科目
B37: 授業科目 | G37: 単位数 | H37: 必須 | I37: 1-2 | J37: 1-3 | K37: 授業科目 | R37: 単位数 | S37: 必須 | T37: 1-2 | U37: 1-3
B38: 情報処理Ⅱ（基礎） | G38: 1 | H38: ○ | I38: ○
B39: 医療必修-医療の倫理とプロ意識・医療情報- | G39: 1 | H39: ○ | I39: ○ | J39: ○
A46: ⑥ 「様々なデータ利活用の現場におけるデータ利活用事例が示され、様々な適用領域（流通、製造、金融、サービス、インフラ、公共、ヘルスケア等）の知見と組み合わせることで価値を創出するもの」の内容を含む授業科目
B48: 授業科目 | G48: 単位数 | H48: 必須 | I48: 1-4 | J48: 1-5 | K48: 授業科目 | R48: 単位数 | S48: 必須 | T48: 1-4 | U48: 1-5
B49: 医療必修-医療の倫理とプロ意識・医療情報- | G49: 1 | H49: ○ | I49: ○ | J49: ○
A57: ⑦ 「活用に当たっての様々な留意事項（ELSI、個人情報、データ倫理、ＡＩ社会原則等）を考慮し、情報セキュリティや情報漏洩等、データを守る上での留意事項への理解をする」の内容を含む授業科目
B59: 授業科目 | G59: 単位数 | H59: 必須 | I59: 3-1 | J59: 3-2 | K59: 授業科目 | R59: 単位数 | S59: 必須 | T59: 3-1 | U59: 3-2
B60: 医療必修-医療の倫理とプロ意識・医療情報- | G60: 1 | H60: ○ | I60: ○ | J60: ○
A68: ⑧ 「実データ・実課題（学術データ等を含む）を用いた演習など、社会での実例を題材として、「データを読む、説明する、扱う」といった数理・データサイエンス・ＡＩの基本的な活用法に関するもの」の内容を含む授業科目
B70: 授業科目 | F70: 単位数 | G70: 必須 | H70: 2-1 | I70: 2-2 | J70: 2-3 | K70: 授業科目 | Q70: 単位数 | R70: 必須 | S70: 2-1 | T70: 2-2 | U70: 2-3
B71: 情報処理Ⅱ（基礎） | F71: 1 | G71: ○ | H71: ○ | I71: ○ | J71: ○
A79: ⑨ 選択「４．オプション」の内容を含む授業科目
B80: 授業科目 | G80: 選択項目 | K80: 授業科目 | R80: 選択項目
A89: ⑩ プログラムを構成する授業の内容
B90: 授業に含まれている内容・要素 | D90: 講義内容
B91: （１）現在進行中の社会変化（第４次産業革命、Society 5.0、データ駆動型社会等）に深く寄与しているものであり、それが自らの生活と密接に結びついている | C91: 1-1 | D91: 情報処理Ⅱ（基礎） 第1回 データリテラシー入門 （ビックデータ、IoT、AI、第4次産業革命、Society 5.0、データ駆動型社会、データ量の増加、人間の知的活動とAIの関係性）
C92: 1-6 | D92: 医療必修 第14回 ICT・AIの医学・医療への応用とセキュリティ （AI最新技術の活用例、Society 5.0）
B93: （２）「社会で活用されているデータ」や「データの活用領域」は非常に広範囲であって、日常生活や社会の課題を解決する有用なツールになり得るもの | C93: 1-2 | D93: 情報処理Ⅱ（基礎） 第1回 データリテラシー入門 （調査データ、実験データ、ログデータ、1次データ、2次データ、データのメタ化、構造化データ、非構造化データ、オープンデータ） 医療必修 第9回 社会におけるデータ・AI利活用 （データ・AI活用領域の広がり、仮説検証、調査データ、実験データ、ログデータ、1次データ、2次データ、データのメタ化、構造化データ、非構造化データ、オープンデータ、生成AI）
C94: 1-3 | D94: 医療必修 第9回 社会におけるデータ・AI利活用 （データ・AI活用領域の広がり、仮説検証、調査データ、実験データ、ログデータ、1次データ、2次データ、データのメタ化、構造化データ、非構造化データ、オープンデータ、生成AI）
B95: （３）様々なデータ利活用の現場におけるデータ利活用事例が示され、様々な適用領域（流通、製造、金融、サービス、インフラ、公共、ヘルスケア等）の知見と組み合わせることで価値を創出するもの | C95: 1-4 | D95: 医療必修 第9回 社会におけるデータ・AI利活用 医療必修 第13回 医療データ管理と病院管理・データ利活用の現場 医療必修 第14回 ICT・AIの医学・医療への応用とセキュリティ
C96: 1-5 | D96: 医療必修 第13回 医療データ管理と病院管理・データ利活用の現場 医療必修 第14回 ICT・AIの医学・医療への応用とセキュリティ
...

Sheet 様式１-３　プログラムを構成する授業科目 (赤坂心理)
T1: 様式１-３ | V1: 「学部・学科によって、修了要件は相違する」場合は、本シートを複製の上＜様式１－〇＞と枝番号を付してください
B2: 大学等名 | C2: 国際医療福祉大学
B3: プログラム名 | C3: 国際医療福祉大学数理・データサイエンス・AI教育プログラム
A5: プログラムを構成する授業科目について
A7: ① 教育プログラムの修了要件 | L7: 学部・学科によって、修了要件は相違する
A9: ② 対象となる学部・学科名称
B11: 赤坂心理・医療福祉マネジメント学部心理学科
A14: ③ 修了要件
B15: 以下２科目、合計３単位を修得すること。 ・心理学統計法Ⅰ（単変量解析講義・データリテラシー）【２単位】 ・医療必修-医療の倫理とプロ意識・医療情報-【１単位】 | X15: 【プルダウンリスト】
X16: 令和５年度以前より、履修することが必須のプログラムとして実施
X17: 令和８年度までに履修必須とする計画
X18: 令和９年度以降に履修必須とする計画、又は未定
B22: 必要最低科目数・単位数 | E22: 2 | F22: 科目 | H22: 3 | I22: 単位 | M22: 履修必須の有無 | N22: 令和５年度以前より、履修することが必須のプログラムとして実施
A24: ④ 現在進行中の社会変化（第４次産業革命、Society 5.0、データ駆動型社会等）に深く寄与しているものであり、それが自らの生活と密接に結びついている」の内容を含む授業科目
B26: 授業科目 | G26: 単位数 | H26: 必須 | I26: 1-1 | J26: 1-6 | K26: 授業科目 | R26: 単位数 | S26: 必須 | T26: 1-1 | U26: 1-6
B27: 心理学統計法Ⅰ（単変量解析講義・データリテラシー） | G27: 2 | H27: ○ | I27: ○
B28: 医療必修-医療の倫理とプロ意識・医療情報- | G28: 1 | H28: ○ | J28: ○
A35: ⑤ 「社会で活用されているデータ」や「データの活用領域」は非常に広範囲であって、日常生活や社会の課題を解決する有用なツールになり得るもの」の内容を含む授業科目
B37: 授業科目 | G37: 単位数 | H37: 必須 | I37: 1-2 | J37: 1-3 | K37: 授業科目 | R37: 単位数 | S37: 必須 | T37: 1-2 | U37: 1-3
B38: 心理学統計法Ⅰ（単変量解析講義・データリテラシー） | G38: 2 | H38: ○ | I38: ○
B39: 医療必修-医療の倫理とプロ意識・医療情報- | G39: 1 | H39: ○ | I39: ○ | J39: ○
A46: ⑥ 「様々なデータ利活用の現場におけるデータ利活用事例が示され、様々な適用領域（流通、製造、金融、サービス、インフラ、公共、ヘルスケア等）の知見と組み合わせることで価値を創出するもの」の内容を含む授業科目
B48: 授業科目 | G48: 単位数 | H48: 必須 | I48: 1-4 | J48: 1-5 | K48: 授業科目 | R48: 単位数 | S48: 必須 | T48: 1-4 | U48: 1-5
B49: 医療必修-医療の倫理とプロ意識・医療情報- | G49: 1 | H49: ○ | I49: ○ | J49: ○
A57: ⑦ 「活用に当たっての様々な留意事項（ELSI、個人情報、データ倫理、ＡＩ社会原則等）を考慮し、情報セキュリティや情報漏洩等、データを守る上での留意事項への理解をする」の内容を含む授業科目
B59: 授業科目 | G59: 単位数 | H59: 必須 | I59: 3-1 | J59: 3-2 | K59: 授業科目 | R59: 単位数 | S59: 必須 | T59: 3-1 | U59: 3-2
B60: 医療必修-医療の倫理とプロ意識・医療情報- | G60: 1 | H60: ○ | I60: ○ | J60: ○
A68: ⑧ 「実データ・実課題（学術データ等を含む）を用いた演習など、社会での実例を題材として、「データを読む、説明する、扱う」といった数理・データサイエンス・ＡＩの基本的な活用法に関するもの」の内容を含む授業科目
B70: 授業科目 | F70: 単位数 | G70: 必須 | H70: 2-1 | I70: 2-2 | J70: 2-3 | K70: 授業科目 | Q70: 単位数 | R70: 必須 | S70: 2-1 | T70: 2-2 | U70: 2-3
B71: 心理学統計法Ⅰ（単変量解析講義・データリテラシー） | F71: 2 | G71: ○ | H71: ○ | I71: ○ | J71: ○
A79: ⑨ 選択「４．オプション」の内容を含む授業科目
B80: 授業科目 | G80: 選択項目 | K80: 授業科目 | R80: 選択項目
A89: ⑩ プログラムを構成する授業の内容
B90: 授業に含まれている内容・要素 | D90: 講義内容
B91: （１）現在進行中の社会変化（第４次産業革命、Society 5.0、データ駆動型社会等）に深く寄与しているものであり、それが自らの生活と密接に結びついている | C91: 1-1 | D91: 心理学統計法Ⅰ 第1回 データリテラシー入門 （ビックデータ、IoT、AI、第4次産業革命、Society 5.0、データ駆動型社会、データ量の増加、人間の知的活動とAIの関係性）
C92: 1-6 | D92: 医療必修 第14回 ICT・AIの医学・医療への応用とセキュリティ （AI最新技術の活用例、Society 5.0）
B93: （２）「社会で活用されているデータ」や「データの活用領域」は非常に広範囲であって、日常生活や社会の課題を解決する有用なツールになり得るもの | C93: 1-2 | D93: 心理学統計法Ⅰ 第1回 データリテラシー入門 （調査データ、実験データ、ログデータ、1次データ、2次データ、データのメタ化、構造化データ、非構造化データ、オープンデータ） 医療必修 第9回 社会におけるデータ・AI利活用 （データ・AI活用領域の広がり、仮説検証、調査データ、実験データ、ログデータ、1次データ、2次データ、データのメタ化、構造化データ、非構造化データ、オープンデータ、生成AI）
C94: 1-3 | D94: 医療必修 第9回 社会におけるデータ・AI利活用 （データ・AI活用領域の広がり、仮説検証、調査データ、実験データ、ログデータ、1次データ、2次データ、データのメタ化、構造化データ、非構造化データ、オープンデータ、生成AI）
B95: （３）様々なデータ利活用の現場におけるデータ利活用事例が示され、様々な適用領域（流通、製造、金融、サービス、インフラ、公共、ヘルスケア等）の知見と組み合わせることで価値を創出するもの | C95: 1-4 | D95: 医療必修 第9回 社会におけるデータ・AI利活用 医療必修 第13回 医療データ管理と病院管理・データ利活用の現場 医療必修 第14回 ICT・AIの医学・医療への応用とセキュリティ
C96: 1-5 | D96: 医療必修 第13回 医療データ管理と病院管理・データ利活用の現場 医療必修 第14回 ICT・AIの医学・医療への応用とセキュリティ
...

Sheet 様式１-４　プログラムを構成する授業科目 (赤坂医マネ)
T1: 様式１-４ | V1: 「学部・学科によって、修了要件は相違する」場合は、本シートを複製の上＜様式１－〇＞と枝番号を付してください
B2: 大学等名 | C2: 国際医療福祉大学
B3: プログラム名 | C3: 国際医療福祉大学数理・データサイエンス・AI教育プログラム
A5: プログラムを構成する授業科目について
A7: ① 教育プログラムの修了要件 | L7: 学部・学科によって、修了要件は相違する
A9: ② 対象となる学部・学科名称
B11: 赤坂心理・医療福祉マネジメント学部医療マネジメント学科
A14: ③ 修了要件
B15: 以下３科目、合計５単位を修得すること。 ・医療統計Ⅰ（統計理論・データリテラシー）【２単位】 ・データ処理Ⅰ（初級・データリテラシー）【２単位】 ・医療必修-医療の倫理とプロ意識・医療情報-【１単位】 | X15: 【プルダウンリスト】
X16: 令和５年度以前より、履修することが必須のプログラムとして実施
X17: 令和８年度までに履修必須とする計画
X18: 令和９年度以降に履修必須とする計画、又は未定
B22: 必要最低科目数・単位数 | E22: 3 | F22: 科目 | H22: 5 | I22: 単位 | M22: 履修必須の有無 | N22: 令和５年度以前より、履修することが必須のプログラムとして実施
A24: ④ 現在進行中の社会変化（第４次産業革命、Society 5.0、データ駆動型社会等）に深く寄与しているものであり、それが自らの生活と密接に結びついている」の内容を含む授業科目
B26: 授業科目 | G26: 単位数 | H26: 必須 | I26: 1-1 | J26: 1-6 | K26: 授業科目 | R26: 単位数 | S26: 必須 | T26: 1-1 | U26: 1-6
B27: データ処理Ⅰ（初級・データリテラシー） | G27: 2 | H27: ○ | I27: ○
B28: 医療必修-医療の倫理とプロ意識・医療情報- | G28: 1 | H28: ○ | J28: ○
A35: ⑤ 「社会で活用されているデータ」や「データの活用領域」は非常に広範囲であって、日常生活や社会の課題を解決する有用なツールになり得るもの」の内容を含む授業科目
B37: 授業科目 | G37: 単位数 | H37: 必須 | I37: 1-2 | J37: 1-3 | K37: 授業科目 | R37: 単位数 | S37: 必須 | T37: 1-2 | U37: 1-3
B38: データ処理Ⅰ（初級・データリテラシー） | G38: 2 | H38: ○ | I38: ○
B39: 医療必修-医療の倫理とプロ意識・医療情報- | G39: 1 | H39: ○ | I39: ○ | J39: ○
A46: ⑥ 「様々なデータ利活用の現場におけるデータ利活用事例が示され、様々な適用領域（流通、製造、金融、サービス、インフラ、公共、ヘルスケア等）の知見と組み合わせることで価値を創出するもの」の内容を含む授業科目
B48: 授業科目 | G48: 単位数 | H48: 必須 | I48: 1-4 | J48: 1-5 | K48: 授業科目 | R48: 単位数 | S48: 必須 | T48: 1-4 | U48: 1-5
B49: 医療必修-医療の倫理とプロ意識・医療情報- | G49: 1 | H49: ○ | I49: ○ | J49: ○
A57: ⑦ 「活用に当たっての様々な留意事項（ELSI、個人情報、データ倫理、ＡＩ社会原則等）を考慮し、情報セキュリティや情報漏洩等、データを守る上での留意事項への理解をする」の内容を含む授業科目
B59: 授業科目 | G59: 単位数 | H59: 必須 | I59: 3-1 | J59: 3-2 | K59: 授業科目 | R59: 単位数 | S59: 必須 | T59: 3-1 | U59: 3-2
B60: 医療必修-医療の倫理とプロ意識・医療情報- | G60: 1 | H60: ○ | I60: ○ | J60: ○
A68: ⑧ 「実データ・実課題（学術データ等を含む）を用いた演習など、社会での実例を題材として、「データを読む、説明する、扱う」といった数理・データサイエンス・ＡＩの基本的な活用法に関するもの」の内容を含む授業科目
B70: 授業科目 | F70: 単位数 | G70: 必須 | H70: 2-1 | I70: 2-2 | J70: 2-3 | K70: 授業科目 | Q70: 単位数 | R70: 必須 | S70: 2-1 | T70: 2-2 | U70: 2-3
B71: 医療統計Ⅰ（統計理論・データリテラシー） | F71: 2 | G71: ○ | H71: ○
B72: データ処理Ⅰ（初級・データリテラシー） | F72: 2 | G72: ○ | I72: ○ | J72: ○
A79: ⑨ 選択「４．オプション」の内容を含む授業科目
B80: 授業科目 | G80: 選択項目 | K80: 授業科目 | R80: 選択項目
A89: ⑩ プログラムを構成する授業の内容
B90: 授業に含まれている内容・要素 | D90: 講義内容
B91: （１）現在進行中の社会変化（第４次産業革命、Society 5.0、データ駆動型社会等）に深く寄与しているものであり、それが自らの生活と密接に結びついている | C91: 1-1 | D91: データ処理Ⅰ（初級・データリテラシー） 第1回～第4回 まず、データに触れてみよう（ビックデータ、IoT、第4次産業革命、Society 5.0、データ駆動型社会、データ量の増加） データ処理Ⅰ（初級・データリテラシー） 第5回 医療現場の課題解決に向けたAIの利用（AI、人間の知的活動とAIの関係性）
C92: 1-6 | D92: 医療必修 第14回 ICT・AIの医学・医療への応用とセキュリティ （AI最新技術の活用例、Society 5.0）
B93: （２）「社会で活用されているデータ」や「データの活用領域」は非常に広範囲であって、日常生活や社会の課題を解決する有用なツールになり得るもの | C93: 1-2 | D93: データ処理Ⅰ（初級・データリテラシー） 第1回～第4回 まず、データに触れてみよう （調査データ、実験データ、ログデータ、1次データ、2次データ、データのメタ化、構造化データ、非構造化データ、オープンデータ） データ処理Ⅰ（初級・データリテラシー） 第5回 医療現場の課題解決に向けたAIの利用 医療必修 第9回 社会におけるデータ・AI利活用 （データ・AI活用領域の広がり、仮説検証、調査データ、実験データ、ログデータ、1次データ、2次データ、データのメタ化、構造化データ、非構造化データ、オープンデータ、生成AI）
C94: 1-3 | D94: 医療必修 第9回 社会におけるデータ・AI利活用 （データ・AI活用領域の広がり、仮説検証、調査データ、実験データ、ログデータ、1次データ、2次データ、データのメタ化、構造化データ、非構造化データ、オープンデータ、生成AI）
B95: （３）様々なデータ利活用の現場におけるデータ利活用事例が示され、様々な適用領域（流通、製造、金融、サービス、インフラ、公共、ヘルスケア等）の知見と組み合わせることで価値を創出するもの | C95: 1-4 | D95: 医療必修 第9回 社会におけるデータ・AI利活用 医療必修 第13回 医療データ管理と病院管理・データ利活用の現場 医療必修 第14回 ICT・AIの医学・医療への応用とセキュリティ
...

Sheet 様式１-５　プログラムを構成する授業科目 (福岡NS)
T1: 様式１-５ | V1: 「学部・学科によって、修了要件は相違する」場合は、本シートを複製の上＜様式１－〇＞と枝番号を付してください
B2: 大学等名 | C2: 国際医療福祉大学
B3: プログラム名 | C3: 国際医療福祉大学数理・データサイエンス・AI教育プログラム
A5: プログラムを構成する授業科目について
A7: ① 教育プログラムの修了要件 | L7: 学部・学科によって、修了要件は相違する
A9: ② 対象となる学部・学科名称
B11: 福岡保健医療学部看護学科
A14: ③ 修了要件
B15: 以下２科目、合計２単位を修得すること。 ・情報処理Ⅰ（基礎）【１単位】 ・医療必修-医療の倫理とプロ意識・医療情報-【１単位】 | X15: 【プルダウンリスト】
X16: 令和５年度以前より、履修することが必須のプログラムとして実施
X17: 令和８年度までに履修必須とする計画
X18: 令和９年度以降に履修必須とする計画、又は未定
B22: 必要最低科目数・単位数 | E22: 2 | F22: 科目 | H22: 2 | I22: 単位 | M22: 履修必須の有無 | N22: 令和５年度以前より、履修することが必須のプログラムとして実施
A24: ④ 現在進行中の社会変化（第４次産業革命、Society 5.0、データ駆動型社会等）に深く寄与しているものであり、それが自らの生活と密接に結びついている」の内容を含む授業科目
B26: 授業科目 | G26: 単位数 | H26: 必須 | I26: 1-1 | J26: 1-6 | K26: 授業科目 | R26: 単位数 | S26: 必須 | T26: 1-1 | U26: 1-6
B27: 情報処理Ⅰ（基礎） | G27: 1 | H27: ○ | I27: ○
B28: 医療必修-医療の倫理とプロ意識・医療情報- | G28: 1 | H28: ○ | J28: ○
A35: ⑤ 「社会で活用されているデータ」や「データの活用領域」は非常に広範囲であって、日常生活や社会の課題を解決する有用なツールになり得るもの」の内容を含む授業科目
B37: 授業科目 | G37: 単位数 | H37: 必須 | I37: 1-2 | J37: 1-3 | K37: 授業科目 | R37: 単位数 | S37: 必須 | T37: 1-2 | U37: 1-3
B38: 情報処理Ⅰ（基礎） | G38: 1 | H38: ○ | I38: ○
B39: 医療必修-医療の倫理とプロ意識・医療情報- | G39: 1 | H39: ○ | I39: ○ | J39: ○
A46: ⑥ 「様々なデータ利活用の現場におけるデータ利活用事例が示され、様々な適用領域（流通、製造、金融、サービス、インフラ、公共、ヘルスケア等）の知見と組み合わせることで価値を創出するもの」の内容を含む授業科目
B48: 授業科目 | G48: 単位数 | H48: 必須 | I48: 1-4 | J48: 1-5 | K48: 授業科目 | R48: 単位数 | S48: 必須 | T48: 1-4 | U48: 1-5
B49: 医療必修-医療の倫理とプロ意識・医療情報- | G49: 1 | H49: ○ | I49: ○ | J49: ○
A57: ⑦ 「活用に当たっての様々な留意事項（ELSI、個人情報、データ倫理、ＡＩ社会原則等）を考慮し、情報セキュリティや情報漏洩等、データを守る上での留意事項への理解をする」の内容を含む授業科目
B59: 授業科目 | G59: 単位数 | H59: 必須 | I59: 3-1 | J59: 3-2 | K59: 授業科目 | R59: 単位数 | S59: 必須 | T59: 3-1 | U59: 3-2
B60: 医療必修-医療の倫理とプロ意識・医療情報- | G60: 1 | H60: ○ | I60: ○ | J60: ○
A68: ⑧ 「実データ・実課題（学術データ等を含む）を用いた演習など、社会での実例を題材として、「データを読む、説明する、扱う」といった数理・データサイエンス・ＡＩの基本的な活用法に関するもの」の内容を含む授業科目
B70: 授業科目 | F70: 単位数 | G70: 必須 | H70: 2-1 | I70: 2-2 | J70: 2-3 | K70: 授業科目 | Q70: 単位数 | R70: 必須 | S70: 2-1 | T70: 2-2 | U70: 2-3
B71: 情報処理Ⅰ（基礎） | F71: 1 | G71: ○ | H71: ○ | I71: ○ | J71: ○
A79: ⑨ 選択「４．オプション」の内容を含む授業科目
B80: 授業科目 | G80: 選択項目 | K80: 授業科目 | R80: 選択項目
A89: ⑩ プログラムを構成する授業の内容
B90: 授業に含まれている内容・要素 | D90: 講義内容
B91: （１）現在進行中の社会変化（第４次産業革命、Society 5.0、データ駆動型社会等）に深く寄与しているものであり、それが自らの生活と密接に結びついている | C91: 1-1 | D91: 情報処理Ⅰ（基礎） 第1回 データリテラシー入門（ビックデータ、IoT、AI、第4次産業革命、Society 5.0、データ駆動型社会、データ量の増加、人間の知的活動とAIの関係性）
C92: 1-6 | D92: 医療必修 第14回 ICT・AIの医学・医療への応用とセキュリティ （AI最新技術の活用例、Society 5.0）
B93: （２）「社会で活用されているデータ」や「データの活用領域」は非常に広範囲であって、日常生活や社会の課題を解決する有用なツールになり得るもの | C93: 1-2 | D93: 情報処理Ⅰ（基礎） 第1回 データリテラシー入門（調査データ、実験データ、ログデータ、1次データ、2次データ、データのメタ化、構造化データ、非構造化データ、オープンデータ） 医療必修 第9回 社会におけるデータ・AI利活用 （データ・AI活用領域の広がり、仮説検証、調査データ、実験データ、ログデータ、1次データ、2次データ、データのメタ化、構造化データ、非構造化データ、オープンデータ、生成AI）
C94: 1-3 | D94: 医療必修 第9回 社会におけるデータ・AI利活用 （データ・AI活用領域の広がり、仮説検証、調査データ、実験データ、ログデータ、1次データ、2次データ、データのメタ化、構造化データ、非構造化データ、オープンデータ、生成AI）
B95: （３）様々なデータ利活用の現場におけるデータ利活用事例が示され、様々な適用領域（流通、製造、金融、サービス、インフラ、公共、ヘルスケア等）の知見と組み合わせることで価値を創出するもの | C95: 1-4 | D95: 医療必修 第9回 社会におけるデータ・AI利活用 医療必修 第13回 医療データ管理と病院管理・データ利活用の現場 医療必修 第14回 ICT・AIの医学・医療への応用とセキュリティ
C96: 1-5 | D96: 医療必修 第13回 医療データ管理と病院管理・データ利活用の現場 医療必修 第14回 ICT・AIの医学・医療への応用とセキュリティ
...

Sheet 様式１-６　プログラムを構成する授業科目 (福岡PS)
T1: 様式１-６ | V1: 「学部・学科によって、修了要件は相違する」場合は、本シートを複製の上＜様式１－〇＞と枝番号を付してください
B2: 大学等名 | C2: 国際医療福祉大学
B3: プログラム名 | C3: 国際医療福祉大学数理・データサイエンス・AI教育プログラム
A5: プログラムを構成する授業科目について
A7: ① 教育プログラムの修了要件 | L7: 学部・学科によって、修了要件は相違する
A9: ② 対象となる学部・学科名称
B11: 福岡薬学部
A14: ③ 修了要件
B15: 以下４科目、合計６単位を修得すること。 ・情報処理【１単位】 ・医薬品情報学Ⅰ（医薬品情報の収集と活用）【２単位】 ・医薬品情報学Ⅱ（EBMと臨床研究）【１単位】 ・病院・薬局事前実習Ⅰ（実務実習で必要な基本的知識）【２単位】 | X15: 【プルダウンリスト】
X16: 令和５年度以前より、履修することが必須のプログラムとして実施
X17: 令和８年度までに履修必須とする計画
X18: 令和９年度以降に履修必須とする計画、又は未定
B22: 必要最低科目数・単位数 | E22: 4 | F22: 科目 | H22: 6 | I22: 単位 | M22: 履修必須の有無 | N22: 令和５年度以前より、履修することが必須のプログラムとして実施
A24: ④ 現在進行中の社会変化（第４次産業革命、Society 5.0、データ駆動型社会等）に深く寄与しているものであり、それが自らの生活と密接に結びついている」の内容を含む授業科目
B26: 授業科目 | G26: 単位数 | H26: 必須 | I26: 1-1 | J26: 1-6 | K26: 授業科目 | R26: 単位数 | S26: 必須 | T26: 1-1 | U26: 1-6
B27: 情報処理 | G27: 1 | H27: ○ | I27: ○
B28: 医薬品情報学Ⅱ（EBMと臨床研究） | G28: 1 | H28: ○ | J28: ○
A35: ⑤ 「社会で活用されているデータ」や「データの活用領域」は非常に広範囲であって、日常生活や社会の課題を解決する有用なツールになり得るもの」の内容を含む授業科目
B37: 授業科目 | G37: 単位数 | H37: 必須 | I37: 1-2 | J37: 1-3 | K37: 授業科目 | R37: 単位数 | S37: 必須 | T37: 1-2 | U37: 1-3
B38: 情報処理 | G38: 1 | H38: ○ | I38: ○
B39: 医薬品情報学Ⅱ（EBMと臨床研究） | G39: 1 | H39: ○ | I39: ○ | J39: ○
A46: ⑥ 「様々なデータ利活用の現場におけるデータ利活用事例が示され、様々な適用領域（流通、製造、金融、サービス、インフラ、公共、ヘルスケア等）の知見と組み合わせることで価値を創出するもの」の内容を含む授業科目
B48: 授業科目 | G48: 単位数 | H48: 必須 | I48: 1-4 | J48: 1-5 | K48: 授業科目 | R48: 単位数 | S48: 必須 | T48: 1-4 | U48: 1-5
B49: 医薬品情報学Ⅰ（医薬品情報の収集と活用） | G49: 2 | H49: ○ | I49: ○ | J49: ○
B50: 医薬品情報学Ⅱ（EBMと臨床研究） | G50: 1 | H50: ○ | I50: ○ | J50: ○
A57: ⑦ 「活用に当たっての様々な留意事項（ELSI、個人情報、データ倫理、ＡＩ社会原則等）を考慮し、情報セキュリティや情報漏洩等、データを守る上での留意事項への理解をする」の内容を含む授業科目
B59: 授業科目 | G59: 単位数 | H59: 必須 | I59: 3-1 | J59: 3-2 | K59: 授業科目 | R59: 単位数 | S59: 必須 | T59: 3-1 | U59: 3-2
B60: 医薬品情報学Ⅰ（医薬品情報の収集と活用） | G60: 2 | H60: ○ | J60: ○
B61: 病院・薬局事前実習Ⅰ（実務実習で必要な基本的知識） | G61: 2 | H61: ○ | I61: ○ | J61: ○
A68: ⑧ 「実データ・実課題（学術データ等を含む）を用いた演習など、社会での実例を題材として、「データを読む、説明する、扱う」といった数理・データサイエンス・ＡＩの基本的な活用法に関するもの」の内容を含む授業科目
B70: 授業科目 | F70: 単位数 | G70: 必須 | H70: 2-1 | I70: 2-2 | J70: 2-3 | K70: 授業科目 | Q70: 単位数 | R70: 必須 | S70: 2-1 | T70: 2-2 | U70: 2-3
B71: 情報処理 | F71: 1 | G71: ○ | H71: ○ | I71: ○ | J71: ○
A79: ⑨ 選択「４．オプション」の内容を含む授業科目
B80: 授業科目 | G80: 選択項目 | K80: 授業科目 | R80: 選択項目
A89: ⑩ プログラムを構成する授業の内容
B90: 授業に含まれている内容・要素 | D90: 講義内容
B91: （１）現在進行中の社会変化（第４次産業革命、Society 5.0、データ駆動型社会等）に深く寄与しているものであり、それが自らの生活と密接に結びついている | C91: 1-1 | D91: 情報処理 第2回 情報リテラシー（２）データリテラシー入門（ビックデータ、IoT、AI、第4次産業革命、Society 5.0、データ駆動型社会、データ量の増加、人間の知的活動とAIの関係性）
C92: 1-6 | D92: 医薬品情報学Ⅱ 第7回 ICT・AIの医学・医療への応用とセキュリティー（AI最新技術の活用例、Society 5.0）
B93: （２）「社会で活用されているデータ」や「データの活用領域」は非常に広範囲であって、日常生活や社会の課題を解決する有用なツールになり得るもの | C93: 1-2 | D93: 情報処理 第2回 情報リテラシー（２）データリテラシー入門 （調査データ、実験データ、ログデータ、1次データ、2次データ、データのメタ化、構造化データ、非構造化データ、オープンデータ） 医薬品情報学Ⅱ 第6回 社会におけるデータ・AI利活用 （データ・AI活用領域の広がり、仮説検証、調査データ、実験データ、ログデータ、1次データ、2次データ、データのメタ化、構造化データ、非構造化データ、オープンデータ、生成AI）
C94: 1-3 | D94: 医薬品情報学Ⅱ 第6回 社会におけるデータ・AI利活用 （データ・AI活用領域の広がり、仮説検証、調査データ、実験データ、ログデータ、1次データ、2次データ、データのメタ化、構造化データ、非構造化データ、オープンデータ、生成AI）
...

Sheet 様式２ 履修者等数の実績
S1: 様式２
Q2: ='様式１-1 プログラムを構成する授業科目'!C2 -> 国際医療福祉大学
A3: プログラムの履修者数等の実績について
A5: ①プログラム開設年度 | C5: 令和5 | E5: 年度
A7: ②大学等全体の男女別学生数 | E7: 男性 | F7: 3139 | G7: 人 | H7: 女性 | I7: 5884 | J7: 人 | K7: （ | L7: 合計 | M7: =F7+I7 -> 9023 | N7: 人 | O7: ）
A9: ③履修者・修了者の実績
B11: 学部・学科名称 | C11: 学生数 | D11: 入学 定員 | E11: 収容 定員 | F11: 令和5年度 | H11: 令和4年度 | J11: 令和3年度 | L11: 令和2年度 | N11: 令和元年度 | P11: 平成30年度 | R11: 履修者数 合計 | S11: 履修率
F12: 履修者数 | G12: 修了者数 | H12: 履修者数 | I12: 修了者数 | J12: 履修者数 | K12: 修了者数 | L12: 履修者数 | M12: 修了者数 | N12: 履修者数 | O12: 修了者数 | P12: 履修者数 | Q12: 修了者数
B13: 保健医療学部 | C13: 2201 | D13: 535 | E13: 2140 | F13: 551 | G13: 453 | R13: =F13+H13+J13+L13+N13+P13 -> 551 | S13: =R13/E13 -> 0.25747664
B14: 医療福祉学部 | C14: 566 | D14: 140 | E14: 570 | F14: 134 | G14: 132 | R14: =F14+H14+J14+L14+N14+P14 -> 134 | S14: =R14/E14 -> 0.23508772
B15: 薬学部 | C15: 1060 | D15: 180 | E15: 1080 | F15: 189 | G15: 184 | R15: =F15+H15+J15+L15+N15+P15 -> 189 | S15: =R15/E15 -> 0.175
B16: 赤坂心理・医療福祉マネジメント学部 | C16: 474 | D16: 120 | E16: 480 | F16: 121 | G16: 115 | R16: =F16+H16+J16+L16+N16+P16 -> 121 | S16: =R16/E16 -> 0.25208333
B17: 医学部 | C17: 830 | D17: 140 | E17: 840 | F17: 142 | G17: 115 | R17: =F17+H17+J17+L17+N17+P17 -> 142 | S17: =R17/E17 -> 0.16904762
B18: 成田看護学部 | C18: 425 | D18: 100 | E18: 400 | F18: 102 | G18: 98 | R18: =F18+H18+J18+L18+N18+P18 -> 102 | S18: =R18/E18 -> 0.255
B19: 成田保健医療学部 | C19: 1213 | D19: 290 | E19: 1160 | F19: 307 | G19: 301 | R19: =F19+H19+J19+L19+N19+P19 -> 307 | S19: =R19/E19 -> 0.26465517
B20: 小田原保健医療学部 | C20: 855 | D20: 200 | E20: 800 | F20: 217 | G20: 216 | R20: =F20+H20+J20+L20+N20+P20 -> 217 | S20: =R20/E20 -> 0.27125
B21: 福岡保健医療学部 | C21: 912 | D21: 220 | E21: 880 | F21: 229 | G21: 223 | R21: =F21+H21+J21+L21+N21+P21 -> 229 | S21: =R21/E21 -> 0.26022727
B22: 福岡薬学部 | C22: 487 | D22: 120 | E22: 480 | F22: 123 | G22: 0 | R22: =F22+H22+J22+L22+N22+P22 -> 123 | S22: =R22/E22 -> 0.25625
R23: =F23+H23+J23+L23+N23+P23 -> 0 | S23: =R23/E23 -> #DIV/0!
R24: =F24+H24+J24+L24+N24+P24 -> 0 | S24: =R24/E24 -> #DIV/0!
R25: =F25+H25+J25+L25+N25+P25 -> 0 | S25: =R25/E25 -> #DIV/0!
R26: =F26+H26+J26+L26+N26+P26 -> 0 | S26: =R26/E26 -> #DIV/0!
R27: =F27+H27+J27+L27+N27+P27 -> 0 | S27: =R27/E27 -> #DIV/0!
R28: =F28+H28+J28+L28+N28+P28 -> 0 | S28: =R28/E28 -> #DIV/0!
R29: =F29+H29+J29+L29+N29+P29 -> 0 | S29: =R29/E29 -> #DIV/0!
R30: =F30+H30+J30+L30+N30+P30 -> 0 | S30: =R30/E30 -> #DIV/0!
R31: =F31+H31+J31+L31+N31+P31 -> 0 | S31: =R31/E31 -> #DIV/0!
R32: =F32+H32+J32+L32+N32+P32 -> 0 | S32: =R32/E32 -> #DIV/0!
B33: 合 計 | C33: =SUM(C13:C32) -> 9023 | D33: =SUM(D13:D32) -> 2045 | E33: =SUM(E13:E32) -> 8830 | F33: =SUM(F13:F32) -> 2115 | G33: =SUM(G13:G32) -> 1837 | H33: =SUM(H13:H32) -> 0 | I33: =SUM(I13:I32) -> 0 | J33: =SUM(J13:J32) -> 0 | ... R33: =SUM(R13:R32) -> 2115 | S33: =R33/E33 -> 0.23952435

Sheet 様式３ 教育の質・履修者数を向上させるための体制・計画
I1: 様式３
G2: 大学等名 | H2: ='様式１-1 プログラムを構成する授業科目'!C2 -> 国際医療福祉大学
A4: 教育の質・履修者数を向上させるための体制・計画について
A6: ① | B6: 全学の教員数 | C6: (常勤） | E6: 1112 | F6: 人 | G6: （非常勤） | H6: 210 | I6: 人
A8: ② | B8: プログラムの授業を教えている教員数 | H8: 34 | I8: 人
A10: ③ | B10: プログラムの運営責任者
B11: （責任者名） | C11: 西田 裕介 | G11: （役職名） | H11: 総合教育センター長
A13: ④ | B13: プログラムを改善・進化させるための体制（委員会・組織等）
B14: 教務統括委員会
B16: （責任者名） | C16: 三浦 総一郎 | G16: （役職名） | H16: 専務理事
A18: ⑤ | B18: プログラムを改善・進化させるための体制を定める規則名称
B19: 国際医療福祉大学教務委員会規程
A21: ⑥ | B21: 体制の目的
B22: データを活用し社会の課題を発見、解決できる人材を育成することを目的に、数理・データサイエンス・AI教育の全学的な普及、関連科目の整備を行い、学内共同施設として教務統括委員会内にワーキンググループを設置する。本部門では医療分野における統計学と情報工学を融合した人材の育成を目的に数理・データサイエンス・AIへの関心を高め、かつ、それらを適切に理解し、活用する基礎的な能力を育成することを目的とする。さらに医療情報に関する今日の基本的な知識と扱い方を学習することにより、医療系学生として、将来、各専門分野で活躍するために必要な医療情報リテラシー、および医療データリテラシーに関する能力を高めることを目的とする。
A34: ⑦ | B34: 具体的な構成員
B35: 総合教育センター長 西田裕介 総合教育センター 教授 宮嶋宏行 ワーキンググループ構成委員として 専務理事 三浦総一郎 教務企画部 秋田裕貴 大田原キャンパス 教務委員長 教授 橋本光康 教授 島田直樹 准教授 石川 徹 成田キャンパス 教務委員長 教授 西田裕介 教授 宮嶋宏行 教授 稲垣誠一 准教授 岡村直利 東京赤坂キャンパス 教務委員長 教授 石川ベンジャミン光一 准教授 篠原信夫 小田原キャンパス 教務委員長 石村佳代子 講師 永井 朋子 大川キャンパス 教務委員長 教授 佐藤謙一 准教授 安本誠一 准教授 吉武康之 講師 上野民生
A48: ⑧ | B48: 履修者数・履修率の向上に向けた計画 ※様式１の「履修必須の有無」で「計画がある」としている場合は詳細について記載すること
B49: 令和５年度実績 | C49: ='様式２ 履修者等数の実績'!S33 -> 0.23952435 | E49: 令和６年度予定 | F49: 0.5 | H49: 令和７年度予定 | I49: 0.7
B50: 令和８年度予定 | C50: 0.9 | E50: 令和９年度予定 | F50: 1 | H50: 収容定員（名） | I50: ='様式２ 履修者等数の実績'!E33 -> 8830
B51: 具体的な計画
B52: 令和４年度まで情報処理Ⅰ、情報処理Ⅱ、情報処理Ⅲ、統計学など、学部・学科で科目名とシラバスがばらばらであったものを、令和４年度に全学部代表者からなるワーキンググループを立ち上げ統一プログラム導入を検討した。その結果、令和５年度よりプログラムを構成する「データリテラシー」「医療必修-医療の倫理とプロ意識・医療情報-」を全学必修化し、数理・データサイエンス・AI（リテラシーレベル）に関する内容を提供する。また令和６年度より「医療データサイエンスⅠ（DS基礎）」「医療データサイエンスⅡ（AI基礎）」を選択科目として全学に設置する。この２つの科目により数理・データサイエンス・AI（応用基礎）に関する内容を提供する。 本プログラムの目標を実現するために、ワーキンググループでは、令和５年度より、学生学修支援のためのWEBサイト、授業動画配信および受講管理システムを立ち上げ、授業時間内外での学習指導、質問を受け付ける仕組みや教育上の工夫、学生指導・支援等の学修サポートを実施し、学生のプログラム履修を促進する。
A65: ⑨ | B65: 学部・学科に関係なく希望する学生全員が受講可能となるような必要な体制・取組等
B66: ワーキンググループの設置により全学的な教育コンテンツを作成支援し、プログラムの基礎部分である科目「医療必修-医療の倫理とプロ意識・医療情報-」については全学生がオンラインで受講できるようオンデマンド教材を整備した。また５つの各キャンパス内にプログラム運営に関わる科目責任者および教務職員を配置し、キャンパス内の学部学生の履修を支援・促進している。またワーキンググループは、各キャンパスの運営課題を集約し、全学で統一されたプログラムの運用を支援する。
A79: ⑩ | B79: できる限り多くの学生が履修できるような具体的な周知方法・取組
B80: 入学後のガイダンスでの周知や、本学のWEBサイトホームページトップ画面にプログラム専用ページへのリンクを掲載して、学生が情報を受け取りやすい環境を整備している。各キャンパスで学生が履修できるように授業を開講する。ワーキンググループでは各キャンパスの統一された授業内容の運営に関して定期的な意見交換会を開催している。
A93: ⑪ | B93: できる限り多くの学生が履修・修得できるようなサポート体制
B94: 本教育プログラムの授業について、学習管理システムにアーカイブを蓄積し、多くの学生がいつでも講義の閲覧が可能な環境を構築している。受講後には確認テストの受験も義務付ける。
A107: ⑫ | B107: 授業時間内外で学習指導、質問を受け付ける具体的な仕組み
B108: 本教育プログラムについての履修を学習管理システムにて管理し、学生は授業時間以外に不明点等を、学習管理システムを通じて確認することができ、質問はGoogle Classroomを通して科目責任者が返答する体制を整備している。

Sheet 様式４　自己点検・評価
I1: 様式４
H2: 大学等名 | I2: ='様式１-1 プログラムを構成する授業科目'!C2 -> 国際医療福祉大学
A3: 自己点検・評価について
A5: ① | B5: プログラムの自己点検・評価を行う体制（委員会・組織等）
B6: 自己点検・評価委員会
D8: （責任者名） | E8: 西田 裕介 | G8: （役職名） | H8: 総合教育センター長
A10: ② | B10: 自己点検・評価体制における意見等
B11: 自己点検・評価の視点 | E11: 自己点検・評価体制における意見・結果・改善に向けた取組等
B12: 学内からの視点
C13: プログラムの履修・修得状況 | E13: 国際医療福祉大学数理・データサイエンス・AI教育プログラムでは、全学部・学科において、プログラムを構成する授業科目を必修科目として開講し、卒業までに全ての授業科目の単位を取得した場合にプログラム修了とする。2023年度（令和5年度）の履修・修得状況は以下のとおりである。 ※完成年度前・直後の一部の学部・学科では、「データリテラシー」及び「医療必修-医療の倫理とプロ意識・医療情報（以下、「医療必修」とする。）」を次の科目で読替えて、必修科目として開講している。将来的に、プログラムを構成する授業科目を全学で統一することを検討している。 ※これ以降の項目での「データリテラシー」及び「医療必修」についても、次の科目群を含めたものである。 【データリテラシー】 ・成田保健医療学部放射線・情報科学科・・・「情報処理Ⅱ（基礎）」 ・赤坂心理・医療福祉マネジメント学部心理学科・・・「心理学統計法Ⅰ（単変量解析講義・データリテラシー）」 ・赤坂心理・医療福祉マネジメント学部医療マネジメント学科・・・「医療統計Ⅰ（統計理論・データリテラシー）」及び「データ処理Ⅰ（初級・データリテラシー）」 ・福岡保健医療部看護学科・・・「情報処理Ⅰ（基礎）」 ・福岡薬学部薬学科・・・「情報処理」 【医療必修-医療の倫理とプロ意識・医療情報】 ・福岡薬学部薬学科・・・「医薬品情報学Ⅰ（医薬品情報の収集と活用）」、「医薬品情報学Ⅱ（EBMと臨床研究）及び「病院・薬局事前実習Ⅰ（実務実習で必要な基本的知識）」
C15: 学修成果 | E15: 国際医療福祉大学数理・データサイエンス・AI教育プログラムでは、全科目共通で実施している学期末の「授業アンケート」および「データリテラシー」科目で「履修前アンケート」、「履修後アンケート」を実施している。主に学修成果は同じ内容の「履修前アンケート」と「履修後アンケート」で確認している。また授業の中ではGoogle Classroom等を利用して課題や小テストを実施し各学生の修得状況を確認している。
C16: 学生アンケート等を通じた学生の内容の理解度 | E16: 「データリテラシー」の全履修者を対象に、履修前と履修後に、科目の到達目標に対する学生の達成度（自己評価）に関するアンケートを実施した。ほとんどの学科において「データを分析」の項目（設問13から25）で「できる」と回答した自己評価が履修前は低かった（14と17を除いて25%以下）が、履修後には大きく改善したことが確認できた。設問20、24、25は履修後でも50%を切っているが、次年度の課題であると考えている。 「医療必修」では、定量的な学修成果（自己評価）の指標として全履修者を対象に、授業アンケートを実施した。それぞれのプログラムについての（Q3.知的に刺激された）では、「そう思う」と「とてもそう思う」を合わせ概ね70%を超えている。
C18: 学生アンケート等を通じた後輩等他の学生への推奨度 | E18: 1年次終了時に、本プログラムに関して「１．リテラシーとしての数理・データサイエンス・ＡＩ教育は重要と考えますか」、「２．本学の数理・データサイエンス・ＡＩ教育を後輩等他の学生への推奨しますか」の2つの質問を行った。「とてもそう思う」、「そう思う」を合わせると、それぞれの質問ともに90%を超えていることから、本プログラムの必要性を理解し、後輩学生にも薦めたいと多くの学生が考えていることが分かる。
C19: 全学的な履修者数、履修率向上に向けた計画の達成・進捗状況 | E19: 国際医療福祉大学数理・データサイエンス・AI教育プログラムを構成する「データリテラシー」「医療必修」の２科目が2023年度より必修科目としており、履修率は100%である。
B20: 学外からの視点
C21: 教育プログラム修了者の進路、活躍状況、企業等の評価 | E21: 国際医療福祉大学数理・データサイエンス・AI教育プログラムを構成する科目は、2023年度開始したため修了生は在学中である。2027年度以降、卒業アンケートにより修了生の活躍状況・企業からの評価を調査する予定である。
C22: 産業界からの視点を含めた教育プログラム内容・手法等への意見 | E22: 2023年度に公益財団法人年金シニアプラン総合研究機構とデータ提供に関する協定を結び、「年金加入履歴に基づく新型コロナウィルス感染症の影響調査」のデータを数理・データサイエンス・AI教育に関連する科目の実習教材として利用する体制を構築した。この協定を利用して2024年度以降に「産業界からの視点を含めた教育プログラム内容・手法等への意見」を本プログラムへ反映させていく予定である。
B23: 数理・データサイエンス・ＡＩを「学ぶ楽しさ」「学ぶことの意義」を理解させること | E23: 各学期末に実施する授業アンケートでは、「9.総合的にこの演習・グループワークには満足だった」の設問に対して、「そう思う」「ややそう思う」の回答が「データリテラシー」、「医療必修」共に90%を超え、演習・グループワークについては「数理・データサイエンス・ＡＩを「学ぶ楽しさ」「学ぶことの意義」を理解させること」は浸透させることが一定程度達成できたと考えられる。
B24: 内容・水準を維持・向上しつつ、より「分かりやすい」授業とすること ※社会の変化や生成AI等の技術の発展を踏まえて教育内容を継続的に見直すなど、より教育効果の高まる授業内容・方法とするための取組や仕組みについても該当があれば記載 | E24: 授業担当者、教務委員会、および教務課職員からなるワーキンググループを構成し、授業担当教員の意見や学生アンケートの結果を参考に、学生にとって「分かりやすさ」の観点から講義内容や実施方法を見直す活動を各学期に実施している。また、内容や水準を維持向上し「分かりやすい」授業とするために「数理・データサイエンス・AI」のクラスルームを作成し、担当教職員間で教材やアンケートの集計結果を共有している。生成AI等の新しい内容の追加については、シラバスの変更を伴わない範囲で授業内容の見直しを常に図っていきたい。
