Workbook

Sheet 様式１-１　プログラムを構成する授業科目
T1: 様式１－１ | V1: 「学部・学科によって、修了要件は相違する」場合は、本シートを複製の上＜様式１－〇＞と枝番号を付してください
B2: 大学等名 | C2: 埼玉工業大学
B3: プログラム名 | C3: SAIKOデータサイエンスプログラム（リテラシーレベル）
A5: プログラムを構成する授業科目について
A7: ① 教育プログラムの修了要件 | L7: 学部・学科によって、修了要件は相違する
A9: ② 対象となる学部・学科名称
B11: 工学部 情報システム学科
A14: ③ 修了要件
B15: 「ICTリテラシー（１）」（2単位）、「人工知能入門（１）」（2単位）の合計4単位を修得すること。 | X15: 【プルダウンリスト】
X16: 令和５年度以前より、履修することが必須のプログラムとして実施
X17: 令和８年度までに履修必須とする計画
X18: 令和９年度以降に履修必須とする計画、又は未定
B22: 必要最低科目数・単位数 | E22: 2 | F22: 科目 | H22: 4 | I22: 単位 | M22: 履修必須の有無 | N22: 令和９年度以降に履修必須とする計画、又は未定
A24: ④ 現在進行中の社会変化（第４次産業革命、Society 5.0、データ駆動型社会等）に深く寄与しているものであり、それが自らの生活と密接に結びついている」の内容を含む授業科目
B26: 授業科目 | G26: 単位数 | H26: 必須 | I26: 1-1 | J26: 1-6 | K26: 授業科目 | R26: 単位数 | S26: 必須 | T26: 1-1 | U26: 1-6
B27: ICTリテラシー（１） | G27: 2 | H27: ○ | I27: ○
B28: 人工知能入門（１） | G28: 2 | H28: ○ | I28: ○ | J28: ○
A35: ⑤ 「社会で活用されているデータ」や「データの活用領域」は非常に広範囲であって、日常生活や社会の課題を解決する有用なツールになり得るもの」の内容を含む授業科目
B37: 授業科目 | G37: 単位数 | H37: 必須 | I37: 1-2 | J37: 1-3 | K37: 授業科目 | R37: 単位数 | S37: 必須 | T37: 1-2 | U37: 1-3
B38: ICTリテラシー（１） | G38: 2 | H38: ○ | I38: ○ | J38: ○
B39: 人工知能入門（１） | G39: 2 | H39: ○ | I39: ○ | J39: ○
A46: ⑥ 「様々なデータ利活用の現場におけるデータ利活用事例が示され、様々な適用領域（流通、製造、金融、サービス、インフラ、公共、ヘルスケア等）の知見と組み合わせることで価値を創出するもの」の内容を含む授業科目
B48: 授業科目 | G48: 単位数 | H48: 必須 | I48: 1-4 | J48: 1-5 | K48: 授業科目 | R48: 単位数 | S48: 必須 | T48: 1-4 | U48: 1-5
B49: ICTリテラシー（１） | G49: 2 | H49: ○ | I49: ○ | J49: ○
B50: 人工知能入門（１） | G50: 2 | H50: ○ | I50: ○ | J50: ○
A57: ⑦ 「活用に当たっての様々な留意事項（ELSI、個人情報、データ倫理、ＡＩ社会原則等）を考慮し、情報セキュリティや情報漏洩等、データを守る上での留意事項への理解をする」の内容を含む授業科目
B59: 授業科目 | G59: 単位数 | H59: 必須 | I59: 3-1 | J59: 3-2 | K59: 授業科目 | R59: 単位数 | S59: 必須 | T59: 3-1 | U59: 3-2
B60: ICTリテラシー（１） | G60: 2 | H60: ○ | I60: ○ | J60: ○
B61: 人工知能入門（１） | G61: 2 | H61: ○ | I61: ○
A68: ⑧ 「実データ・実課題（学術データ等を含む）を用いた演習など、社会での実例を題材として、「データを読む、説明する、扱う」といった数理・データサイエンス・ＡＩの基本的な活用法に関するもの」の内容を含む授業科目
B70: 授業科目 | F70: 単位数 | G70: 必須 | H70: 2-1 | I70: 2-2 | J70: 2-3 | K70: 授業科目 | Q70: 単位数 | R70: 必須 | S70: 2-1 | T70: 2-2 | U70: 2-3
B71: ICTリテラシー（１） | F71: 2 | G71: ○ | H71: ○ | I71: ○ | J71: ○
A79: ⑨ 選択「４．オプション」の内容を含む授業科目
B80: 授業科目 | G80: 選択項目 | K80: 授業科目 | R80: 選択項目
B81: 人工知能入門（１） | G81: 4‐4時系列データ解析
B82: 人工知能入門（１） | G82: 4‐6画像解析
B83: 人工知能入門（１） | G83: 4‐8データ活用実践（教師あり学習）
B84: 人工知能入門（１） | G84: 4‐9データ活用実践（教師なし学習）
A89: ⑩ プログラムを構成する授業の内容
B90: 授業に含まれている内容・要素 | D90: 講義内容
...

Sheet 様式１-2　プログラムを構成する授業科目
T1: 様式１－２ | V1: 「学部・学科によって、修了要件は相違する」場合は、本シートを複製の上＜様式１－〇＞と枝番号を付してください
B2: 大学等名 | C2: 埼玉工業大学
B3: プログラム名 | C3: SAIKOデータサイエンスプログラム（リテラシーレベル）
A5: プログラムを構成する授業科目について
A7: ① 教育プログラムの修了要件 | L7: 学部・学科によって、修了要件は相違する
A9: ② 対象となる学部・学科名称
B11: 工学部 機械工学科・生命環境化学科
A14: ③ 修了要件
B15: 「ICTリテラシー（２）」（2単位）を修得すること。 また、AIの幅広い知識を身につけるため「人工知能入門（２）」（2単位）の修得を推奨する。 | X15: 【プルダウンリスト】
X16: 令和５年度以前より、履修することが必須のプログラムとして実施
X17: 令和８年度までに履修必須とする計画
X18: 令和９年度以降に履修必須とする計画、又は未定
B22: 必要最低科目数・単位数 | E22: 1 | F22: 科目 | H22: 2 | I22: 単位 | M22: 履修必須の有無 | N22: 令和９年度以降に履修必須とする計画、又は未定
A24: ④ 現在進行中の社会変化（第４次産業革命、Society 5.0、データ駆動型社会等）に深く寄与しているものであり、それが自らの生活と密接に結びついている」の内容を含む授業科目
B26: 授業科目 | G26: 単位数 | H26: 必須 | I26: 1-1 | J26: 1-6 | K26: 授業科目 | R26: 単位数 | S26: 必須 | T26: 1-1 | U26: 1-6
B27: ICTリテラシー（２） | G27: 2 | H27: ○ | I27: ○ | J27: ○
A35: ⑤ 「社会で活用されているデータ」や「データの活用領域」は非常に広範囲であって、日常生活や社会の課題を解決する有用なツールになり得るもの」の内容を含む授業科目
B37: 授業科目 | G37: 単位数 | H37: 必須 | I37: 1-2 | J37: 1-3 | K37: 授業科目 | R37: 単位数 | S37: 必須 | T37: 1-2 | U37: 1-3
B38: ICTリテラシー（２） | G38: 2 | H38: ○ | I38: ○ | J38: ○
A46: ⑥ 「様々なデータ利活用の現場におけるデータ利活用事例が示され、様々な適用領域（流通、製造、金融、サービス、インフラ、公共、ヘルスケア等）の知見と組み合わせることで価値を創出するもの」の内容を含む授業科目
B48: 授業科目 | G48: 単位数 | H48: 必須 | I48: 1-4 | J48: 1-5 | K48: 授業科目 | R48: 単位数 | S48: 必須 | T48: 1-4 | U48: 1-5
B49: ICTリテラシー（２） | G49: 2 | H49: ○ | I49: ○ | J49: ○
A57: ⑦ 「活用に当たっての様々な留意事項（ELSI、個人情報、データ倫理、ＡＩ社会原則等）を考慮し、情報セキュリティや情報漏洩等、データを守る上での留意事項への理解をする」の内容を含む授業科目
B59: 授業科目 | G59: 単位数 | H59: 必須 | I59: 3-1 | J59: 3-2 | K59: 授業科目 | R59: 単位数 | S59: 必須 | T59: 3-1 | U59: 3-2
B60: ICTリテラシー（２） | G60: 2 | H60: ○ | I60: ○ | J60: ○
A68: ⑧ 「実データ・実課題（学術データ等を含む）を用いた演習など、社会での実例を題材として、「データを読む、説明する、扱う」といった数理・データサイエンス・ＡＩの基本的な活用法に関するもの」の内容を含む授業科目
B70: 授業科目 | F70: 単位数 | G70: 必須 | H70: 2-1 | I70: 2-2 | J70: 2-3 | K70: 授業科目 | Q70: 単位数 | R70: 必須 | S70: 2-1 | T70: 2-2 | U70: 2-3
B71: ICTリテラシー（２） | F71: 2 | G71: ○ | H71: ○ | I71: ○ | J71: ○
A79: ⑨ 選択「４．オプション」の内容を含む授業科目
B80: 授業科目 | G80: 選択項目 | K80: 授業科目 | R80: 選択項目
B81: 人工知能入門（２） | G81: 4‐4時系列データ解析
B82: 人工知能入門（２） | G82: 4‐6画像解析
B83: 人工知能入門（２） | G83: 4‐8データ活用実践（教師あり学習）
B84: 人工知能入門（２） | G84: 4‐9データ活用実践（教師なし学習）
A89: ⑩ プログラムを構成する授業の内容
B90: 授業に含まれている内容・要素 | D90: 講義内容
B91: （１）現在進行中の社会変化（第４次産業革命、Society 5.0、データ駆動型社会等）に深く寄与しているものであり、それが自らの生活と密接に結びついている | C91: 1-1 | D91: ビッグデータ、IoT、AI、ロボット「ICTリテラシー（２）」（2回目） データ量の増加、計算機の処理性能の向上、AIの非連続的進化「ICTリテラシー（２）」（2回目） 第4次産業革命、Society 5.0、データ駆動型社会「ICTリテラシー（２）」（2回目） 人間の知的活動とAIの関係性「ICTリテラシー（２）」（2回目）
C92: 1-6 | D92: AI等を活用した新しいビジネスモデル（シェアリングエコノミー、商品のレコメンデーションなど）「ICTリテラシー（２）」（4回目） AI最新技術の活用例（深層生成モデル、敵対的生成ネットワーク、強化学習、転移学習など）「ICTリテラシー（２）」（4回目）
B93: （２）「社会で活用されているデータ」や「データの活用領域」は非常に広範囲であって、日常生活や社会の課題を解決する有用なツールになり得るもの | C93: 1-2 | D93: 調査データ、実験データ、人の行動ログデータ、機械の稼働ログデータ「ICTリテラシー（２）」（3回目） 1次データ、2次データ、データのメタ化「ICTリテラシー（２）」（3回目） 構造化データ、非構造化データ（文章、画像/動画、音声/音楽など）「ICTリテラシー（２）」（3回目） データのオープン化（オープンデータ）「ICTリテラシー（２）」（3回目）
C94: 1-3 | D94: データ・AI活用領域の広がり（生産、消費、文化活動など）「ICTリテラシー（２）」（4回目） 仮説検証、知識発見、原因究明、計画策定、判断支援、活動代替、新規生成など「ICTリテラシー（２）」（4回目）
...

Sheet 様式１-３　プログラムを構成する授業科目
T1: 様式１－３ | V1: 「学部・学科によって、修了要件は相違する」場合は、本シートを複製の上＜様式１－〇＞と枝番号を付してください
B2: 大学等名 | C2: 埼玉工業大学
B3: プログラム名 | C3: SAIKOデータサイエンスプログラム（リテラシーレベル）
A5: プログラムを構成する授業科目について
A7: ① 教育プログラムの修了要件 | L7: 学部・学科によって、修了要件は相違する
A9: ② 対象となる学部・学科名称
B11: 人間社会学部
A14: ③ 修了要件
B15: 「ICTリテラシー（３）」（2単位）を修得すること。 また、AIの幅広い知識を身につけるため「人工知能入門（２）」（2単位）の修得を推奨する。 | X15: 【プルダウンリスト】
X16: 令和５年度以前より、履修することが必須のプログラムとして実施
X17: 令和８年度までに履修必須とする計画
X18: 令和９年度以降に履修必須とする計画、又は未定
B22: 必要最低科目数・単位数 | E22: 1 | F22: 科目 | H22: 2 | I22: 単位 | M22: 履修必須の有無 | N22: 令和９年度以降に履修必須とする計画、又は未定
A24: ④ 現在進行中の社会変化（第４次産業革命、Society 5.0、データ駆動型社会等）に深く寄与しているものであり、それが自らの生活と密接に結びついている」の内容を含む授業科目
B26: 授業科目 | G26: 単位数 | H26: 必須 | I26: 1-1 | J26: 1-6 | K26: 授業科目 | R26: 単位数 | S26: 必須 | T26: 1-1 | U26: 1-6
B27: ICTリテラシー（３） | G27: 2 | H27: ○ | I27: ○ | J27: ○
A35: ⑤ 「社会で活用されているデータ」や「データの活用領域」は非常に広範囲であって、日常生活や社会の課題を解決する有用なツールになり得るもの」の内容を含む授業科目
B37: 授業科目 | G37: 単位数 | H37: 必須 | I37: 1-2 | J37: 1-3 | K37: 授業科目 | R37: 単位数 | S37: 必須 | T37: 1-2 | U37: 1-3
B38: ICTリテラシー（３） | G38: 2 | H38: ○ | I38: ○ | J38: ○
A46: ⑥ 「様々なデータ利活用の現場におけるデータ利活用事例が示され、様々な適用領域（流通、製造、金融、サービス、インフラ、公共、ヘルスケア等）の知見と組み合わせることで価値を創出するもの」の内容を含む授業科目
B48: 授業科目 | G48: 単位数 | H48: 必須 | I48: 1-4 | J48: 1-5 | K48: 授業科目 | R48: 単位数 | S48: 必須 | T48: 1-4 | U48: 1-5
B49: ICTリテラシー（３） | G49: 2 | H49: ○ | I49: ○ | J49: ○
A57: ⑦ 「活用に当たっての様々な留意事項（ELSI、個人情報、データ倫理、ＡＩ社会原則等）を考慮し、情報セキュリティや情報漏洩等、データを守る上での留意事項への理解をする」の内容を含む授業科目
B59: 授業科目 | G59: 単位数 | H59: 必須 | I59: 3-1 | J59: 3-2 | K59: 授業科目 | R59: 単位数 | S59: 必須 | T59: 3-1 | U59: 3-2
B60: ICTリテラシー（３） | G60: 2 | H60: ○ | I60: ○ | J60: ○
A68: ⑧ 「実データ・実課題（学術データ等を含む）を用いた演習など、社会での実例を題材として、「データを読む、説明する、扱う」といった数理・データサイエンス・ＡＩの基本的な活用法に関するもの」の内容を含む授業科目
B70: 授業科目 | F70: 単位数 | G70: 必須 | H70: 2-1 | I70: 2-2 | J70: 2-3 | K70: 授業科目 | Q70: 単位数 | R70: 必須 | S70: 2-1 | T70: 2-2 | U70: 2-3
B71: ICTリテラシー（３） | F71: 2 | G71: ○ | H71: ○ | I71: ○ | J71: ○
A79: ⑨ 選択「４．オプション」の内容を含む授業科目
B80: 授業科目 | G80: 選択項目 | K80: 授業科目 | R80: 選択項目
B81: ICTリテラシー（３） | G81: 4‐3データ構造とプログラミング基礎 | K81: 人工知能入門（２） | P81: 人工知能入門（２） | R81: 4‐9データ活用実践（教師なし学習）
B82: ICTリテラシー（３） | G82: 4‐4時系列データ解析
B83: ICTリテラシー（３） | G83: 4‐5テキスト解析
B84: ICTリテラシー（３） | G84: 4‐6画像解析
B85: 人工知能入門（２） | G85: 4‐4時系列データ解析
B86: 人工知能入門（２） | G86: 4‐6画像解析
B87: 人工知能入門（２） | G87: 4‐8データ活用実践（教師あり学習）
A89: ⑩ プログラムを構成する授業の内容
B90: 授業に含まれている内容・要素 | D90: 講義内容
B91: （１）現在進行中の社会変化（第４次産業革命、Society 5.0、データ駆動型社会等）に深く寄与しているものであり、それが自らの生活と密接に結びついている | C91: 1-1 | D91: ビッグデータ、IoT、AI、ロボット「ICTリテラシー（３）」（11,12回目） データ量の増加、計算機の処理性能の向上、AIの非連続的進化「ICTリテラシー（３）」（10回目） 第4次産業革命、Society 5.0、データ駆動型社会「ICTリテラシー（３）」（12回目） 人間の知的活動とAIの関係性「ICTリテラシー（３）」（5,10回目）
...

Sheet 様式２ 履修者等数の実績
S1: 様式２
Q2: ='様式１-１ プログラムを構成する授業科目'!C2 -> 埼玉工業大学
A3: プログラムの履修者数等の実績について
A5: ①プログラム開設年度 | C5: 令和2 | E5: 年度
A7: ②大学等全体の男女別学生数 | E7: 男性 | F7: 1959 | G7: 人 | H7: 女性 | I7: 223 | J7: 人 | K7: （ | L7: 合計 | M7: =F7+I7 -> 2182 | N7: 人 | O7: ）
A9: ③履修者・修了者の実績
B11: 学部・学科名称 | C11: 学生数 | D11: 入学 定員 | E11: 収容 定員 | F11: 令和5年度 | H11: 令和4年度 | J11: 令和3年度 | L11: 令和2年度 | N11: 令和元年度 | P11: 平成30年度 | R11: 履修者数 合計 | S11: 履修率
F12: 履修者数 | G12: 修了者数 | H12: 履修者数 | I12: 修了者数 | J12: 履修者数 | K12: 修了者数 | L12: 履修者数 | M12: 修了者数 | N12: 履修者数 | O12: 修了者数 | P12: 履修者数 | Q12: 修了者数
B13: 工学部 | C13: 1564 | D13: 360 | E13: 1440 | F13: 135 | G13: 122 | H13: 181 | I13: 172 | J13: 140 | K13: 122 | L13: 121 | M13: 91 | R13: =F13+H13+J13+L13+N13+P13 -> 577 | S13: =R13/E13 -> 0.40069444
B14: 人間社会学部 | C14: 618 | D14: 140 | E14: 560 | F14: 40 | G14: 33 | H14: 108 | I14: 87 | J14: 79 | K14: 63 | L14: 38 | M14: 34 | R14: =F14+H14+J14+L14+N14+P14 -> 265 | S14: =R14/E14 -> 0.47321429
R15: =F15+H15+J15+L15+N15+P15 -> 0 | S15: =R15/E15 -> #DIV/0!
R16: =F16+H16+J16+L16+N16+P16 -> 0 | S16: =R16/E16 -> #DIV/0!
R17: =F17+H17+J17+L17+N17+P17 -> 0 | S17: =R17/E17 -> #DIV/0!
R18: =F18+H18+J18+L18+N18+P18 -> 0 | S18: =R18/E18 -> #DIV/0!
R19: =F19+H19+J19+L19+N19+P19 -> 0 | S19: =R19/E19 -> #DIV/0!
R20: =F20+H20+J20+L20+N20+P20 -> 0 | S20: =R20/E20 -> #DIV/0!
R21: =F21+H21+J21+L21+N21+P21 -> 0 | S21: =R21/E21 -> #DIV/0!
R22: =F22+H22+J22+L22+N22+P22 -> 0 | S22: =R22/E22 -> #DIV/0!
R23: =F23+H23+J23+L23+N23+P23 -> 0 | S23: =R23/E23 -> #DIV/0!
R24: =F24+H24+J24+L24+N24+P24 -> 0 | S24: =R24/E24 -> #DIV/0!
R25: =F25+H25+J25+L25+N25+P25 -> 0 | S25: =R25/E25 -> #DIV/0!
R26: =F26+H26+J26+L26+N26+P26 -> 0 | S26: =R26/E26 -> #DIV/0!
... R32: =F32+H32+J32+L32+N32+P32 -> 0 | S32: =R32/E32 -> #DIV/0!
B33: 合 計 | C33: =SUM(C13:C32) -> 2182 | D33: =SUM(D13:D32) -> 500 | E33: =SUM(E13:E32) -> 2000 | F33: =SUM(F13:F32) -> 175 | G33: =SUM(G13:G32) -> 155 | H33: =SUM(H13:H32) -> 289 | I33: =SUM(I13:I32) -> 259 | J33: =SUM(J13:J32) -> 219 | ... R33: =SUM(R13:R32) -> 842 | S33: =R33/E33 -> 0.421

Sheet 様式３ 教育の質・履修者数を向上させるための体制・計画
I1: 様式３
G2: 大学等名 | H2: ='様式１-１ プログラムを構成する授業科目'!C2 -> 埼玉工業大学
A4: 教育の質・履修者数を向上させるための体制・計画について
A6: ① | B6: 全学の教員数 | C6: (常勤） | E6: 75 | F6: 人 | G6: （非常勤） | H6: 151 | I6: 人
A8: ② | B8: プログラムの授業を教えている教員数 | H8: 3 | I8: 人
A10: ③ | B10: プログラムの運営責任者
B11: （責任者名） | C11: 吉澤 浩和 | G11: （役職名） | H11: 教務部長
A13: ④ | B13: プログラムを改善・進化させるための体制（委員会・組織等）
B14: 埼玉工業大学教務委員会（工学部・人間社会学部）
B16: （責任者名） | C16: 吉澤浩和(工)・田中克明(人) | G16: （役職名） | H16: 教務委員長
A18: ⑤ | B18: プログラムを改善・進化させるための体制を定める規則名称
B19: 埼玉工業大学教務委員会規程
A21: ⑥ | B21: 体制の目的
B22: ・教育課程の実施及び実施内容の検証に関すること ・授業科目及び授業時間割に関すること ・学生の履修指導に関すること ・試験、成績、単位の取得及び修了に関すること ・内部質保証及び大学認証評価に関すること なお、令和６年度から、埼玉工業大学教務委員会に、数理・データサイエンス・ＡＩ教育推進専門委員会を設け、以下の事項を検討する。 ・数理・データサイエンス・AI教育プログラムの運営に関する事項 ・数理・データサイエンス・AI教育プログラム認定制度の申請に関する事項 ・その他、前各号に関連する事項
A34: ⑦ | B34: 具体的な構成員
B35: 【工学部】 【委員長】 吉澤 浩和（情報システム学科教授） 【委員】 福地 亜宝郎（機械工学科准教授）、萩原 隆明（機械工学科准教授）、岩崎 政和（生命環境化学科教授）、木下 基（生命環境化学科教授）、藤田 和広（情報システム学科准教授）、村田 仁樹（情報システム学科講師）、松田 智裕（基礎教育センター工学部会教授）、原 正彦（教学部次長） 【人間社会学部】 【委員長】 曾我 重司（心理学科教授） 【委員】 田中 克明（情報社会学科教授）、檀上 誠（情報社会学科教授）、村山 要司（情報社会学科教授）、永本 義弘（情報社会学科教授）、村中 昌紀（心理学科准教授）、田中 崇恵（心理学科講師）
A48: ⑧ | B48: 履修者数・履修率の向上に向けた計画 ※様式１の「履修必須の有無」で「計画がある」としている場合は詳細について記載すること
B49: 令和５年度実績 | C49: ='様式２ 履修者等数の実績'!S33 -> 0.421 | E49: 令和６年度予定 | F49: 0.5 | H49: 令和７年度予定 | I49: 0.75
B50: 令和８年度予定 | C50: 0.8 | E50: 令和９年度予定 | F50: 1 | H50: 収容定員（名） | I50: ='様式２ 履修者等数の実績'!E33 -> 2000
B51: 具体的な計画
B52: 本プログラムの科目は、学生が履修時に容易に識別できるように全学で名称を統一している。その一方、学修内容や扱うテーマを学部・学科ごとに調整することにより、学生が興味を持って積極的に履修できるように工夫している。 また、令和６年度以降、本プログラムを扱う全学横断的な専門委員会において、本プログラムとの各学部・学科における学修との関連を整理し、学生にもわかりやすく提示するなど、本プログラムの意義をさらに高める計画である。 さらに、現在まで対面形式のみで実施してきた授業内容を、一部オンデマンド化する、あるいは外部コンテンツを利用するなど、授業の実施方式を工夫することにより、令和９年度以降の必修化を目指す。
A65: ⑨ | B65: 学部・学科に関係なく希望する学生全員が受講可能となるような必要な体制・取組等
B66: 令和２年度より全学共通の科目区分として「情報系科目」を設け、本プログラムの科目や、本プログラムと並行して履修することが望ましい科目を配置している。 また、多くの学生が履修しやすいように、本プログラムの科目と他の科目との重複ができるだけ無いよう、時間割設計を行っている。
A79: ⑩ | B79: できる限り多くの学生が履修できるような具体的な周知方法・取組
B80: 各学期に行う履修ガイダンスにおいて、学生への周知を図っている。 また、履修を促すために、一部の学科では、令和５年度よりプログラム内の科目を選択必修科目としている。 今後、履修登録期間中に、学内のサイネージへの掲示など学生の目に止まりやすい告知方法の展開を進める。
A93: ⑪ | B93: できる限り多くの学生が履修・修得できるようなサポート体制
B94: 授業時間外でも学生が容易に学修を行えるようにするため、LMSを通して本プログラム科目の資料を参照可能とするとともに、各回に実施する課題もLMSから提出可能としている。 さらに、多くの学生が履修可能となるよう、前述の通り、本プログラムの科目と他の科目との重複ができるだけ無いように時間割設計を行っている。
A107: ⑫ | B107: 授業時間内外で学習指導、質問を受け付ける具体的な仕組み
B108: 授業内容に関する質問を授業時間外でもLMSを通して受け付けており、授業担当者が随時対応している。また、担当教員のオフィスアワーを設け、適宜質問対応を行っている。

Sheet 様式４　自己点検・評価
I1: 様式４
H2: 大学等名 | I2: ='様式１-１ プログラムを構成する授業科目'!C2 -> 埼玉工業大学
A3: 自己点検・評価について
A5: ① | B5: プログラムの自己点検・評価を行う体制（委員会・組織等）
B6: 埼玉工業大学数理・データサイエンス・AI教育推進専門委員会
D8: （責任者名） | E8: 井上 聡 | G8: （役職名） | H8: 推進専門委員会委員長
A10: ② | B10: 自己点検・評価体制における意見等
B11: 自己点検・評価の視点 | E11: 自己点検・評価体制における意見・結果・改善に向けた取組等
B12: 学内からの視点
C13: プログラムの履修・修得状況 | E13: 学内学修ポータルシステムにより、学生の各科目の履修状況および学期中の出欠状況を把握している。また、LMSにより、受講者ごと、各授業ごとの課題の進捗状況および回答状況を把握することができる。
C14: 学修成果 | E14: 全学FD委員会により、全学の科目を対象に学部ごとに質問は一部異なるが授業アンケートを実施しており、本プログラムの科目も対象である。 令和５年度アンケートにおいて、「予習、復習を含めて、あなたはこの授業に熱心に取り組みましたか？（両学部共通）」では、「非常にそう思う」「ややそう思う」が本プログラムの科目平均で70.2%を占め、学生が授業に熱心に取り組んだと考えられる。 また、「この授業の満足度はどのくらいですか？（工学部）」「この授業を受けて、有益でしたか（人間社会学部）」は「かなり満足」「かなり満足」「とても有益だった」「有益だった」が76.5%と、成果を自覚できる授業を実施できたと考えられる。
C15: 学生アンケート等を通じた学生の内容の理解度 | E15: 上述のアンケートにおいて、 - 設問「あなたにとって、この授業のレベルはどうでしたか？（両学部共通）」は、「やや高い」「やや難しかった」が28.1%、「ちょうど良い」「ちょうどよかった」との回答が52.0% - 設問「授業の進行速度はどうでしたか？（工学部）」「授業の進行速度は適切でしたか？（人間社会学部）」は、「やや速い」「少し速かった」が13.3%、「ちょうど良い」「適切だった」との回答が78.4% であり、学生にとって適切からわずかに難易度が高いと感じられるレベルの授業を、適切な進行速度で実施できていたと考えられる。
C16: 学生アンケート等を通じた後輩等他の学生への推奨度 | E16: 上述のアンケートでは、後輩学生や他の学生への推奨度に関する設問はない。しかし、満足度、有益度では比較的高い評価を得られており、推奨度合いも比例するものと考えられる。 今後、全学共通のアンケートとは別に後輩等他の学生への推奨度を直接質問するアンケートを実施する、あるいは、全学アンケートに同項目を設けるなど、検討を行う。 なお、令和５年度の人間社会学部履修者数減少の原因として、科目名変更（教職課程完成年度の令和４年度まで同内容を別科目名で実施）による、認知度の低下が考えられる。時間割に旧科目名を併記するなど認知に努めたが、今後、学生間の情報共有に働きかける方法を検討する。
C17: 全学的な履修者数、履修率向上に向けた計画の達成・進捗状況 | E17: 令和２年度より科目区分「情報系科目」を科目表に設け、全学的な履修者数の向上を図っている。 令和６年度には、本プログラムを推進してきた教務委員会の中に「数理・データサイエンス・AI教育推進専門委員会」を設け、本プログラムの内容と各学科の学修内容の連携を深め、これを学生にも示すことにより、履修率を向上させる。また、「応用基礎レベル」相当のカリキュラム構築も進めており、本プログラムの発展性を示すことにより、あわせて学生の履修を推進する。 また、現在は対面で実施している授業内容の一部のオンデマンド化や外部コンテンツの導入など、学修時間の多様化を図ることにより、本プログラムの全学必修化を進める。
B18: 学外からの視点
C19: 教育プログラム修了者の進路、活躍状況、企業等の評価 | E19: 本プログラムは令和２年度に開設し、プログラム修了者の卒業者は、科目設置学年などの関係から、令和５年度終了時点では全学にわたってそろっていない。全学において修了者が卒業する令和７年度以降、本学の就職課とも協力して、本プログラム修了者の進路や活躍状況などを追跡できるように整備を進める。また、活躍状況や企業等の評価を取り入れた点検・評価を行う手順の準備も進め、全学必修化以降は本プログラムに限らない取り組みとして、全学に展開する。
C20: 産業界からの視点を含めた教育プログラム内容・手法等への意見 | E20: 埼玉工業大学先端科学研究所協力会参加企業や、埼玉工業大学公開講座への参加者などを対象にアンケートを実施し、数理・データサイエンス・AI教育に関する意見を収集、要望を本プログラムの改善へ活用する準備を進めている。
B21: 数理・データサイエンス・ＡＩを「学ぶ楽しさ」「学ぶことの意義」を理解させること | E21: 学生に対して、数理・データサイエンス・AIを「学ぶ楽しさ」「学ぶことの意義」を理解させるためには、これらの分野が私たちの生活の中どのように関わっているのか、その事例を多く紹介することにより、興味を持ってもらうことが重要であり、そのような話題提供を行っている。また学生の専門性や専攻の特性に応じて、理論中心の授業ではなく、授業の中に事例をふんだんに取り入れて、学生同士のグループディスカッションを実施し、その過程を通じて「学ぶ楽しさ」「学ぶことの意義」を理解させる取り組みを実施している。
B22: 内容・水準を維持・向上しつつ、より「分かりやすい」授業とすること ※社会の変化や生成AI等の技術の発展を踏まえて教育内容を継続的に見直すなど、より教育効果の高まる授業内容・方法とするための取組や仕組みについても該当があれば記載 | E22: 授業評価アンケートの結果を分析し、「授業の満足度」「授業のレベル」「授業の進行速度」「教員の説明のわかりやすさ」等の項目に加え、自由記述欄も分析し、数理・データサイエンス・AI教育推進専門委員会において，授業内容や方法の改善を進める。またデータサイエンス・AIの分野は新しい技術の登場や、その応用範囲の拡充が非常に速いため、その変化を感じられるよう、新しい活用事例、ツールの登場などはいち早く紹介、ないしは体験をするような柔軟な講義進行を行っている。
