Workbook

Sheet 様式１-１　プログラムを構成する授業科目 (教養)
T1: 様式１-１ | V1: 「学部・学科によって、修了要件は相違する」場合は、本シートを複製の上＜様式１－〇＞と枝番号を付してください
B2: 大学等名 | C2: 埼玉大学
B3: プログラム名 | C3: 数理・データサイエンス・ＡＩリテラシー教育プログラム
A5: プログラムを構成する授業科目について
A7: ① 教育プログラムの修了要件 | L7: 学部・学科によって、修了要件は相違する
A9: ② 対象となる学部・学科名称
B11: 教養学部
A14: ③ 修了要件
B15: データサイエンス入門（１単位）、情報基礎（２単位）の計３単位を修得すること。 | X15: 【プルダウンリスト】
X16: 令和５年度以前より、履修することが必須のプログラムとして実施
X17: 令和８年度までに履修必須とする計画
X18: 令和９年度以降に履修必須とする計画、又は未定
B22: 必要最低科目数・単位数 | E22: 2 | F22: 科目 | H22: 3 | I22: 単位 | M22: 履修必須の有無 | N22: 令和５年度以前より、履修することが必須のプログラムとして実施
A24: ④ 現在進行中の社会変化（第４次産業革命、Society 5.0、データ駆動型社会等）に深く寄与しているものであり、それが自らの生活と密接に結びついている」の内容を含む授業科目
B26: 授業科目 | G26: 単位数 | H26: 必須 | I26: 1-1 | J26: 1-6 | K26: 授業科目 | R26: 単位数 | S26: 必須 | T26: 1-1 | U26: 1-6
B27: 情報基礎（教養学部） | G27: 2 | H27: ○ | I27: ○
B28: データサイエンス入門（教養学部） | G28: 1 | H28: ○ | I28: ○ | J28: ○
A35: ⑤ 「社会で活用されているデータ」や「データの活用領域」は非常に広範囲であって、日常生活や社会の課題を解決する有用なツールになり得るもの」の内容を含む授業科目
B37: 授業科目 | G37: 単位数 | H37: 必須 | I37: 1-2 | J37: 1-3 | K37: 授業科目 | R37: 単位数 | S37: 必須 | T37: 1-2 | U37: 1-3
B38: 情報基礎（教養学部） | G38: 2 | H38: ○ | I38: ○ | J38: ○
B39: データサイエンス入門（教養学部） | G39: 1 | H39: ○ | I39: ○ | J39: ○
A46: ⑥ 「様々なデータ利活用の現場におけるデータ利活用事例が示され、様々な適用領域（流通、製造、金融、サービス、インフラ、公共、ヘルスケア等）の知見と組み合わせることで価値を創出するもの」の内容を含む授業科目
B48: 授業科目 | G48: 単位数 | H48: 必須 | I48: 1-4 | J48: 1-5 | K48: 授業科目 | R48: 単位数 | S48: 必須 | T48: 1-4 | U48: 1-5
B49: 情報基礎（教養学部） | G49: 2 | H49: ○ | I49: ○ | J49: ○
B50: データサイエンス入門（教養学部） | G50: 1 | H50: ○ | I50: ○ | J50: ○
A57: ⑦ 「活用に当たっての様々な留意事項（ELSI、個人情報、データ倫理、ＡＩ社会原則等）を考慮し、情報セキュリティや情報漏洩等、データを守る上での留意事項への理解をする」の内容を含む授業科目
B59: 授業科目 | G59: 単位数 | H59: 必須 | I59: 3-1 | J59: 3-2 | K59: 授業科目 | R59: 単位数 | S59: 必須 | T59: 3-1 | U59: 3-2
B60: 情報基礎（教養学部） | G60: 2 | H60: ○ | I60: ○ | J60: ○
B61: データサイエンス入門（教養学部） | G61: 1 | H61: ○ | I61: ○ | J61: ○
A68: ⑧ 「実データ・実課題（学術データ等を含む）を用いた演習など、社会での実例を題材として、「データを読む、説明する、扱う」といった数理・データサイエンス・ＡＩの基本的な活用法に関するもの」の内容を含む授業科目
B70: 授業科目 | F70: 単位数 | G70: 必須 | H70: 2-1 | I70: 2-2 | J70: 2-3 | K70: 授業科目 | Q70: 単位数 | R70: 必須 | S70: 2-1 | T70: 2-2 | U70: 2-3
B71: 情報基礎（教養学部） | F71: 2 | G71: ○ | H71: ○ | I71: ○ | J71: ○
B72: データサイエンス入門（教養学部） | F72: 1 | G72: ○ | H72: ○ | I72: ○ | J72: ○
A79: ⑨ 選択「４．オプション」の内容を含む授業科目
B80: 授業科目 | G80: 選択項目 | K80: 授業科目 | R80: 選択項目
A89: ⑩ プログラムを構成する授業の内容
B90: 授業に含まれている内容・要素 | D90: 講義内容
B91: （１）現在進行中の社会変化（第４次産業革命、Society 5.0、データ駆動型社会等）に深く寄与しているものであり、それが自らの生活と密接に結びついている | C91: 1-1 | D91: ・ビッグデータ、IoT、AI、ロボット「データサイエンス入門」(第1回) ・データ量の増加、計算機の処理性能の向上、AIの非連続的進化「情報基礎（教養）」(第2回)、「データサイエンス入門」(第3回) ・第4次産業革命、Society 5.0、データ駆動型社会「データサイエンス入門」(第1回) ・複数技術を組み合わせたAIサービス「データサイエンス入門」(第1回) ・人間の知的活動とAIの関係性「情報基礎（教養）」(第2回) ・データを起点としたものの見方、人間の知的活動を起点としたものの見方「情報基礎（教養）」(第2回)
C92: 1-6 | D92: ・AI等を活用した新しいビジネスモデル(シェアリングエコノミー、商品のレコメンデーションなど)「データサイエンス入門」(第3回) ・AI最新技術の活用例（深層生成モデル、敵対的生成ネットワーク、強化学習、転移学習など）「データサイエンス入門」(第3回)
B93: （２）「社会で活用されているデータ」や「データの活用領域」は非常に広範囲であって、日常生活や社会の課題を解決する有用なツールになり得るもの | C93: 1-2 | D93: ・調査データ、実験データ、人の行動ログデータ、機械の稼働ログデータなど「データサイエンス入門」(第2回) ・1次データ、2次データ、データのメタ化「データサイエンス入門」(第2回)、「情報基礎（教養）」(第2回) ・構造化データ、非構造化データ（文章、画像/動画、音声/音楽など）「情報基礎（教養）」(第2回) ・データ作成（ビッグデータとアノテーション）「情報基礎（教養）」(第10回)(第12回) ・データのオープン化（オープンデータ）「情報基礎（教養）」(第2回)(第4回)(第10回)
...

Sheet 様式１-２　プログラムを構成する授業科目 (経済)
T1: 様式１-２ | V1: 「学部・学科によって、修了要件は相違する」場合は、本シートを複製の上＜様式１－〇＞と枝番号を付してください
B2: 大学等名 | C2: 埼玉大学
B3: プログラム名 | C3: 数理・データサイエンス・ＡＩリテラシー教育プログラム
A5: プログラムを構成する授業科目について
A7: ① 教育プログラムの修了要件 | L7: 学部・学科によって、修了要件は相違する
A9: ② 対象となる学部・学科名称
B11: 経済学部
A14: ③ 修了要件
B15: データサイエンス入門（１単位）、経済情報リテラシー（２単位）の計３単位を修得すること。 | X15: 【プルダウンリスト】
X16: 令和５年度以前より、履修することが必須のプログラムとして実施
X17: 令和８年度までに履修必須とする計画
X18: 令和９年度以降に履修必須とする計画、又は未定
B22: 必要最低科目数・単位数 | E22: 2 | F22: 科目 | H22: 3 | I22: 単位 | M22: 履修必須の有無 | N22: 令和５年度以前より、履修することが必須のプログラムとして実施
A24: ④ 現在進行中の社会変化（第４次産業革命、Society 5.0、データ駆動型社会等）に深く寄与しているものであり、それが自らの生活と密接に結びついている」の内容を含む授業科目
B26: 授業科目 | G26: 単位数 | H26: 必須 | I26: 1-1 | J26: 1-6 | K26: 授業科目 | R26: 単位数 | S26: 必須 | T26: 1-1 | U26: 1-6
B27: データサイエンス入門（経済学部） | G27: 1 | H27: ○ | I27: ○ | J27: ○
A35: ⑤ 「社会で活用されているデータ」や「データの活用領域」は非常に広範囲であって、日常生活や社会の課題を解決する有用なツールになり得るもの」の内容を含む授業科目
B37: 授業科目 | G37: 単位数 | H37: 必須 | I37: 1-2 | J37: 1-3 | K37: 授業科目 | R37: 単位数 | S37: 必須 | T37: 1-2 | U37: 1-3
B38: データサイエンス入門（経済学部） | G38: 1 | H38: ○ | I38: ○ | J38: ○
A46: ⑥ 「様々なデータ利活用の現場におけるデータ利活用事例が示され、様々な適用領域（流通、製造、金融、サービス、インフラ、公共、ヘルスケア等）の知見と組み合わせることで価値を創出するもの」の内容を含む授業科目
B48: 授業科目 | G48: 単位数 | H48: 必須 | I48: 1-4 | J48: 1-5 | K48: 授業科目 | R48: 単位数 | S48: 必須 | T48: 1-4 | U48: 1-5
B49: 経済情報リテラシー | G49: 2 | H49: ○ | I49: ○
B50: データサイエンス入門（経済学部） | G50: 1 | H50: ○ | I50: ○ | J50: ○
A57: ⑦ 「活用に当たっての様々な留意事項（ELSI、個人情報、データ倫理、ＡＩ社会原則等）を考慮し、情報セキュリティや情報漏洩等、データを守る上での留意事項への理解をする」の内容を含む授業科目
B59: 授業科目 | G59: 単位数 | H59: 必須 | I59: 3-1 | J59: 3-2 | K59: 授業科目 | R59: 単位数 | S59: 必須 | T59: 3-1 | U59: 3-2
B60: データサイエンス入門（経済学部） | G60: 1 | H60: ○ | I60: ○ | J60: ○
A68: ⑧ 「実データ・実課題（学術データ等を含む）を用いた演習など、社会での実例を題材として、「データを読む、説明する、扱う」といった数理・データサイエンス・ＡＩの基本的な活用法に関するもの」の内容を含む授業科目
B70: 授業科目 | F70: 単位数 | G70: 必須 | H70: 2-1 | I70: 2-2 | J70: 2-3 | K70: 授業科目 | Q70: 単位数 | R70: 必須 | S70: 2-1 | T70: 2-2 | U70: 2-3
B71: 経済情報リテラシー | F71: 2 | G71: ○ | H71: ○ | I71: ○ | J71: ○
B72: データサイエンス入門（経済学部） | F72: 1 | G72: ○ | H72: ○ | I72: ○ | J72: ○
A79: ⑨ 選択「４．オプション」の内容を含む授業科目
B80: 授業科目 | G80: 選択項目 | K80: 授業科目 | R80: 選択項目
A89: ⑩ プログラムを構成する授業の内容
B90: 授業に含まれている内容・要素 | D90: 講義内容
B91: （１）現在進行中の社会変化（第４次産業革命、Society 5.0、データ駆動型社会等）に深く寄与しているものであり、それが自らの生活と密接に結びついている | C91: 1-1 | D91: ビッグデータ、IoT、AI、ロボット/データ量の増加、計算機の処理性能の向上、AIの非連続的進化/第4次産業革命、Society 5.0、データ駆動型社会/複数技術を組み合わせたAIサービス/人間の知的活動とAIの関係性/データを起点としたものの見方、人間の知的活動を起点としたものの見方(「データサイエンス入門」(第1回))
C92: 1-6 | D92: AI等を活用した新しいビジネスモデル(シェアリングエコノミー、商品のレコメンデーションなど)/AI最新技術の活用例（深層生成モデル、敵対的生成ネットワーク、強化学習、転移学習など）(「データサイエンス入門」(第3回))
B93: （２）「社会で活用されているデータ」や「データの活用領域」は非常に広範囲であって、日常生活や社会の課題を解決する有用なツールになり得るもの | C93: 1-2 | D93: 調査データ、実験データ、人の行動ログデータ、機械の稼働ログデータなど/1次データ、2次データ、データのメタ化/構造化データ、非構造化データ（文章、画像/動画、音声/音楽など）/データ作成（ビッグデータとアノテーション）/データのオープン化（オープンデータ）(「データサイエンス入門」(第2回))
C94: 1-3 | D94: データ・AI活用領域の広がり(生産、消費、文化活動など)/研究開発、調達、製造、物流、販売、マーケティング、サービスなど/仮説検証、知識発見、原因究明、計画策定、判断支援、活動代替、新規生成など(「データサイエンス入門」(第3回))
B95: （３）様々なデータ利活用の現場におけるデータ利活用事例が示され、様々な適用領域（流通、製造、金融、サービス、インフラ、公共、ヘルスケア等）の知見と組み合わせることで価値を創出するもの | C95: 1-4 | D95: 特化型AIと汎用AI、今のAIで出来ることと出来ないこと、AIとビッグデータ/認識技術、自動化技術(「データサイエンス入門」(第1回)) データ可視化：複合グラフ、2軸グラフ、多次元の可視化、関係性の可視化、地図上の可視化、挙動・軌跡の可視化、リアルタイム可視化など(「経済情報リテラシー」(第4回))
C96: 1-5 | D96: 流通、製造、金融、サービス、インフラ、公共、ヘルスケア等におけるデータ/AI利活用事例紹介(「データサイエンス入門」(第3回))
...

Sheet 様式１-３　プログラムを構成する授業科目 (教育)
T1: 様式１-３ | V1: 「学部・学科によって、修了要件は相違する」場合は、本シートを複製の上＜様式１－〇＞と枝番号を付してください
B2: 大学等名 | C2: 埼玉大学
B3: プログラム名 | C3: 数理・データサイエンス・ＡＩリテラシー教育プログラム
A5: プログラムを構成する授業科目について
A7: ① 教育プログラムの修了要件 | L7: 学部・学科によって、修了要件は相違する
A9: ② 対象となる学部・学科名称
B11: 教育学部
A14: ③ 修了要件
B15: 情報基礎（２単位）を修得すること。 | X15: 【プルダウンリスト】
X16: 令和５年度以前より、履修することが必須のプログラムとして実施
X17: 令和８年度までに履修必須とする計画
X18: 令和９年度以降に履修必須とする計画、又は未定
B22: 必要最低科目数・単位数 | E22: 1 | F22: 科目 | H22: 2 | I22: 単位 | M22: 履修必須の有無 | N22: 令和５年度以前より、履修することが必須のプログラムとして実施
A24: ④ 現在進行中の社会変化（第４次産業革命、Society 5.0、データ駆動型社会等）に深く寄与しているものであり、それが自らの生活と密接に結びついている」の内容を含む授業科目
B26: 授業科目 | G26: 単位数 | H26: 必須 | I26: 1-1 | J26: 1-6 | K26: 授業科目 | R26: 単位数 | S26: 必須 | T26: 1-1 | U26: 1-6
B27: 情報基礎（教育学部） | G27: 2 | H27: ○ | I27: ○ | J27: ○
A35: ⑤ 「社会で活用されているデータ」や「データの活用領域」は非常に広範囲であって、日常生活や社会の課題を解決する有用なツールになり得るもの」の内容を含む授業科目
B37: 授業科目 | G37: 単位数 | H37: 必須 | I37: 1-2 | J37: 1-3 | K37: 授業科目 | R37: 単位数 | S37: 必須 | T37: 1-2 | U37: 1-3
B38: 情報基礎（教育学部） | G38: 2 | H38: ○ | I38: ○ | J38: ○
A46: ⑥ 「様々なデータ利活用の現場におけるデータ利活用事例が示され、様々な適用領域（流通、製造、金融、サービス、インフラ、公共、ヘルスケア等）の知見と組み合わせることで価値を創出するもの」の内容を含む授業科目
B48: 授業科目 | G48: 単位数 | H48: 必須 | I48: 1-4 | J48: 1-5 | K48: 授業科目 | R48: 単位数 | S48: 必須 | T48: 1-4 | U48: 1-5
B49: 情報基礎（教育学部） | G49: 2 | H49: ○ | I49: ○ | J49: ○
A57: ⑦ 「活用に当たっての様々な留意事項（ELSI、個人情報、データ倫理、ＡＩ社会原則等）を考慮し、情報セキュリティや情報漏洩等、データを守る上での留意事項への理解をする」の内容を含む授業科目
B59: 授業科目 | G59: 単位数 | H59: 必須 | I59: 3-1 | J59: 3-2 | K59: 授業科目 | R59: 単位数 | S59: 必須 | T59: 3-1 | U59: 3-2
B60: 情報基礎（教育学部） | G60: 2 | H60: ○ | I60: ○ | J60: ○
A68: ⑧ 「実データ・実課題（学術データ等を含む）を用いた演習など、社会での実例を題材として、「データを読む、説明する、扱う」といった数理・データサイエンス・ＡＩの基本的な活用法に関するもの」の内容を含む授業科目
B70: 授業科目 | F70: 単位数 | G70: 必須 | H70: 2-1 | I70: 2-2 | J70: 2-3 | K70: 授業科目 | Q70: 単位数 | R70: 必須 | S70: 2-1 | T70: 2-2 | U70: 2-3
B71: 情報基礎（教育学部） | F71: 2 | G71: ○ | H71: ○ | I71: ○ | J71: ○
A79: ⑨ 選択「４．オプション」の内容を含む授業科目
B80: 授業科目 | G80: 選択項目 | K80: 授業科目 | R80: 選択項目
A89: ⑩ プログラムを構成する授業の内容
B90: 授業に含まれている内容・要素 | D90: 講義内容
B91: （１）現在進行中の社会変化（第４次産業革命、Society 5.0、データ駆動型社会等）に深く寄与しているものであり、それが自らの生活と密接に結びついている | C91: 1-1 | D91: データを起点としたものの見方、人間の知的活動を起点としたものの見方「情報基礎（教育）」(第1回) 第4次産業革命、Society 5.0、データ駆動型社会/人間の知的活動とAIの関係性「情報基礎（教育）」(第9回)
C92: 1-6 | D92: AI等を活用した新しいビジネスモデル(シェアリングエコノミー、商品のレコメンデーションなど)/AI最新技術の活用例（深層生成モデル、敵対的生成ネットワーク、強化学習、転移学習など）「情報基礎（教育）」(第10回)
B93: （２）「社会で活用されているデータ」や「データの活用領域」は非常に広範囲であって、日常生活や社会の課題を解決する有用なツールになり得るもの | C93: 1-2 | D93: 調査データ/1次データ、2次データ、データのメタ化/構造化データ/データのオープン化（オープンデータ）「情報基礎（教育）」(第11回)
C94: 1-3 | D94: データ・AI活用領域の広がり(生産、消費、文化活動など)/仮説検証、知識発見、原因究明、計画策定、判断支援、活動代替、新規生成など「情報基礎（教育）」(第11回)
B95: （３）様々なデータ利活用の現場におけるデータ利活用事例が示され、様々な適用領域（流通、製造、金融、サービス、インフラ、公共、ヘルスケア等）の知見と組み合わせることで価値を創出するもの | C95: 1-4 | D95: データ可視化：複合グラフ、2軸グラフ、多次元の可視化、関係性の可視化、地図上の可視化、挙動・軌跡の可視化「情報基礎（教育）」(第11回) データ解析：予測、グルーピング、パターン発見、最適化、シミュレーション・データ同化「情報基礎（教育）」(第12回)
C96: 1-5 | D96: データサイエンスのサイクル（課題抽出と定式化、データの取得・管理・加工、探索的データ解析、データ解析と推論、結果の共有・伝達、課題解決に向けた提案）/流通、製造、金融、サービス、インフラ、公共、ヘルスケア等におけるデータ・AI利活用事例紹介「情報基礎（教育）」(第14回)
B97: （４）活用に当たっての様々な留意事項（ELSI、個人情報、データ倫理、ＡＩ社会原則等）を考慮し、情報セキュリティや情報漏洩等、データを守る上での留意事項への理解をする | C97: 3-1 | D97: 個人情報保護、EU一般データ保護規則(GDPR)、忘れられる権利、オプトアウト「情報基礎（教育）」(第6回) ELSI（Ethical, Legal and Social Issues）/データ倫理：データのねつ造、改ざん、盗用、プライバシー保護/データバイアス、アルゴリズムバイアス/データ・AI活用における負の事例紹介「情報基礎（教育）」(第7回、第11回)
C98: 3-2 | D98: 情報セキュリティ：機密性、完全性、可用性/匿名加工情報、暗号化、パスワード、悪意ある情報搾取/情報漏洩等によるセキュリティ事故の事例紹介「情報基礎（教育）」(第6回、第7回)
...

Sheet 様式１-４　プログラムを構成する授業科目 (理)
T1: 様式１-４ | V1: 「学部・学科によって、修了要件は相違する」場合は、本シートを複製の上＜様式１－〇＞と枝番号を付してください
B2: 大学等名 | C2: 埼玉大学
B3: プログラム名 | C3: 数理・データサイエンス・ＡＩリテラシー教育プログラム
A5: プログラムを構成する授業科目について
A7: ① 教育プログラムの修了要件 | L7: 学部・学科によって、修了要件は相違する
A9: ② 対象となる学部・学科名称
B11: 理学部
A14: ③ 修了要件
B15: 数理データサイエンス基礎（２単位）を修得すること。 | X15: 【プルダウンリスト】
X16: 令和５年度以前より、履修することが必須のプログラムとして実施
X17: 令和８年度までに履修必須とする計画
X18: 令和９年度以降に履修必須とする計画、又は未定
B22: 必要最低科目数・単位数 | E22: 1 | F22: 科目 | H22: 2 | I22: 単位 | M22: 履修必須の有無 | N22: 令和５年度以前より、履修することが必須のプログラムとして実施
A24: ④ 現在進行中の社会変化（第４次産業革命、Society 5.0、データ駆動型社会等）に深く寄与しているものであり、それが自らの生活と密接に結びついている」の内容を含む授業科目
B26: 授業科目 | G26: 単位数 | H26: 必須 | I26: 1-1 | J26: 1-6 | K26: 授業科目 | R26: 単位数 | S26: 必須 | T26: 1-1 | U26: 1-6
B27: 数理データサイエンス基礎 | G27: 2 | H27: ○ | I27: ○ | J27: ○
A35: ⑤ 「社会で活用されているデータ」や「データの活用領域」は非常に広範囲であって、日常生活や社会の課題を解決する有用なツールになり得るもの」の内容を含む授業科目
B37: 授業科目 | G37: 単位数 | H37: 必須 | I37: 1-2 | J37: 1-3 | K37: 授業科目 | R37: 単位数 | S37: 必須 | T37: 1-2 | U37: 1-3
B38: 数理データサイエンス基礎 | G38: 2 | H38: ○ | I38: ○ | J38: ○
A46: ⑥ 「様々なデータ利活用の現場におけるデータ利活用事例が示され、様々な適用領域（流通、製造、金融、サービス、インフラ、公共、ヘルスケア等）の知見と組み合わせることで価値を創出するもの」の内容を含む授業科目
B48: 授業科目 | G48: 単位数 | H48: 必須 | I48: 1-4 | J48: 1-5 | K48: 授業科目 | R48: 単位数 | S48: 必須 | T48: 1-4 | U48: 1-5
B49: 数理データサイエンス基礎 | G49: 2 | H49: ○ | I49: ○ | J49: ○
A57: ⑦ 「活用に当たっての様々な留意事項（ELSI、個人情報、データ倫理、ＡＩ社会原則等）を考慮し、情報セキュリティや情報漏洩等、データを守る上での留意事項への理解をする」の内容を含む授業科目
B59: 授業科目 | G59: 単位数 | H59: 必須 | I59: 3-1 | J59: 3-2 | K59: 授業科目 | R59: 単位数 | S59: 必須 | T59: 3-1 | U59: 3-2
B60: 数理データサイエンス基礎 | G60: 2 | H60: ○ | I60: ○ | J60: ○
A68: ⑧ 「実データ・実課題（学術データ等を含む）を用いた演習など、社会での実例を題材として、「データを読む、説明する、扱う」といった数理・データサイエンス・ＡＩの基本的な活用法に関するもの」の内容を含む授業科目
B70: 授業科目 | F70: 単位数 | G70: 必須 | H70: 2-1 | I70: 2-2 | J70: 2-3 | K70: 授業科目 | Q70: 単位数 | R70: 必須 | S70: 2-1 | T70: 2-2 | U70: 2-3
B71: 数理データサイエンス基礎 | F71: 2 | G71: ○ | H71: ○ | I71: ○ | J71: ○
A79: ⑨ 選択「４．オプション」の内容を含む授業科目
B80: 授業科目 | G80: 選択項目 | K80: 授業科目 | R80: 選択項目
B81: 数理データサイエンス基礎 | G81: 4‐3データ構造とプログラミング基礎
A89: ⑩ プログラムを構成する授業の内容
B90: 授業に含まれている内容・要素 | D90: 講義内容
B91: （１）現在進行中の社会変化（第４次産業革命、Society 5.0、データ駆動型社会等）に深く寄与しているものであり、それが自らの生活と密接に結びついている | C91: 1-1 | D91: ビッグデータ、IoT、AI、ロボット「数理データサイエンス基礎」(第1回、第3回) 第4次産業革命、Society 5.0、データ駆動型社会「数理データサイエンス基礎」(第1回) 人間の知的活動とAIの関係性「数理データサイエンス基礎」(第7回)
C92: 1-6 | D92: AI等を活用した新しいビジネスモデル(シェアリングエコノミー、商品のレコメンデーションなど)、AI最新技術の活用例（深層生成モデル、敵対的生成ネットワーク、強化学習、転移学習など）「数理データサイエンス基礎」(第8回)
B93: （２）「社会で活用されているデータ」や「データの活用領域」は非常に広範囲であって、日常生活や社会の課題を解決する有用なツールになり得るもの | C93: 1-2 | D93: 調査データ、実験データ、人の行動ログデータ、機械の稼働ログデータなど、1次データ、2次データ、データのメタ化、データのオープン化（オープンデータ）「数理データサイエンス基礎」(第3回) データ・AI利活用「数理データサイエンス基礎」(第7回)
C94: 1-3 | D94: データ・AI活用領域の広がり(生産、消費、文化活動など)、研究開発、調達、製造、物流、販売、マーケティング、サービスなど、仮説検証、知識発見、原因究明、計画策定、判断支援、活動代替、新規生成など「数理データサイエンス基礎」(第7回)
B95: （３）様々なデータ利活用の現場におけるデータ利活用事例が示され、様々な適用領域（流通、製造、金融、サービス、インフラ、公共、ヘルスケア等）の知見と組み合わせることで価値を創出するもの | C95: 1-4 | D95: 特化型AIと汎用AI、今のAIで出来ることと出来ないこと、AIとビッグデータ「数理データサイエンス基礎」(第7回)
C96: 1-5 | D96: データサイエンスのサイクル（課題抽出と定式化、データの取得・管理・加工、探索的データ解析、データ解析と推論、結果の共有・伝達、課題解決に向けた提案）「数理データサイエンス基礎」(第3回) 流通、製造、金融、サービス、インフラ、公共、ヘルスケア等におけるデータ・AI利活用事例紹介「数理データサイエンス基礎」(第7回)
B97: （４）活用に当たっての様々な留意事項（ELSI、個人情報、データ倫理、ＡＩ社会原則等）を考慮し、情報セキュリティや情報漏洩等、データを守る上での留意事項への理解をする | C97: 3-1 | D97: ELSI（Ethical, Legal and Social Issues）、個人情報保護、EU一般データ保護規則(GDPR)、忘れられる権利、オプトアウト、データ倫理：データのねつ造、改ざん、盗用、プライバシー保護、AI社会原則（公平性、説明責任、透明性、人間中心の判断）、AIサービスの責任論「数理データサイエンス基礎」(第2回)
...

Sheet 様式１-５　プログラムを構成する授業科目 (工)
T1: 様式１-５ | V1: 「学部・学科によって、修了要件は相違する」場合は、本シートを複製の上＜様式１－〇＞と枝番号を付してください
B2: 大学等名 | C2: 埼玉大学
B3: プログラム名 | C3: 数理・データサイエンス・ＡＩリテラシー教育プログラム
A5: プログラムを構成する授業科目について
A7: ① 教育プログラムの修了要件 | L7: 学部・学科によって、修了要件は相違する
A9: ② 対象となる学部・学科名称
B11: 工学部（機械工学・システムデザイン学科、電気電子物理工学科、応用化学科、環境社会デザイン学科）
A14: ③ 修了要件
B15: 理工学と現代社会（２単位）、工学入門セミナー（２単位）、情報基礎（２単位）の計６単位を修得すること。 | X15: 【プルダウンリスト】
X16: 令和５年度以前より、履修することが必須のプログラムとして実施
X17: 令和８年度までに履修必須とする計画
X18: 令和９年度以降に履修必須とする計画、又は未定
B22: 必要最低科目数・単位数 | E22: 3 | F22: 科目 | H22: 6 | I22: 単位 | M22: 履修必須の有無 | N22: 令和５年度以前より、履修することが必須のプログラムとして実施
A24: ④ 現在進行中の社会変化（第４次産業革命、Society 5.0、データ駆動型社会等）に深く寄与しているものであり、それが自らの生活と密接に結びついている」の内容を含む授業科目
B26: 授業科目 | G26: 単位数 | H26: 必須 | I26: 1-1 | J26: 1-6 | K26: 授業科目 | R26: 単位数 | S26: 必須 | T26: 1-1 | U26: 1-6
B27: 理工学と現代社会 | G27: 2 | H27: ○ | I27: ○ | J27: ○
B28: 情報基礎（電気電子物理工学科） | G28: 2 | H28: ○ | I28: ○ | J28: ○
B29: 情報基礎（応用化学科） | G29: 2 | H29: ○ | I29: ○ | J29: ○
B30: 工学入門セミナー | G30: 2 | H30: ○ | I30: ○
A35: ⑤ 「社会で活用されているデータ」や「データの活用領域」は非常に広範囲であって、日常生活や社会の課題を解決する有用なツールになり得るもの」の内容を含む授業科目
B37: 授業科目 | G37: 単位数 | H37: 必須 | I37: 1-2 | J37: 1-3 | K37: 授業科目 | R37: 単位数 | S37: 必須 | T37: 1-2 | U37: 1-3
B38: 理工学と現代社会 | G38: 2 | H38: ○ | I38: ○ | J38: ○
B39: 情報基礎（機械工学・システムデザイン学科） | G39: 2 | H39: ○ | I39: ○
B40: 情報基礎（電気電子物理工学科） | G40: 2 | H40: ○ | I40: ○ | J40: ○
B41: 情報基礎（応用化学科） | G41: 2 | H41: ○ | I41: ○ | J41: ○
B42: 情報基礎（環境社会デザイン学科） | G42: 2 | H42: ○ | I42: ○
B43: 工学入門セミナー | G43: 2 | H43: ○ | J43: ○
A46: ⑥ 「様々なデータ利活用の現場におけるデータ利活用事例が示され、様々な適用領域（流通、製造、金融、サービス、インフラ、公共、ヘルスケア等）の知見と組み合わせることで価値を創出するもの」の内容を含む授業科目
B48: 授業科目 | G48: 単位数 | H48: 必須 | I48: 1-4 | J48: 1-5 | K48: 授業科目 | R48: 単位数 | S48: 必須 | T48: 1-4 | U48: 1-5
B49: 理工学と現代社会 | G49: 2 | H49: ○ | I49: ○ | J49: ○
B50: 情報基礎（機械工学・システムデザイン学科） | G50: 2 | H50: ○ | I50: ○
B51: 情報基礎（電気電子物理工学科） | G51: 2 | H51: ○
B52: 情報基礎（応用化学科） | G52: 2 | H52: ○ | J52: ○
B53: 情報基礎（環境社会デザイン学科） | G53: 2 | H53: ○ | I53: ○ | J53: ○
B54: 工学入門セミナー | G54: 2 | H54: ○ | I54: ○
A57: ⑦ 「活用に当たっての様々な留意事項（ELSI、個人情報、データ倫理、ＡＩ社会原則等）を考慮し、情報セキュリティや情報漏洩等、データを守る上での留意事項への理解をする」の内容を含む授業科目
B59: 授業科目 | G59: 単位数 | H59: 必須 | I59: 3-1 | J59: 3-2 | K59: 授業科目 | R59: 単位数 | S59: 必須 | T59: 3-1 | U59: 3-2
B60: 理工学と現代社会 | G60: 2 | H60: ○ | I60: ○ | J60: ○
B61: 情報基礎（機械工学・システムデザイン学科） | G61: 2 | H61: ○ | I61: ○ | J61: ○
B62: 情報基礎（電気電子物理工学科） | G62: 2 | H62: ○ | I62: ○ | J62: ○
...

Sheet 様式１-６　プログラムを構成する授業科目 (工・情報)
T1: 様式１-６ | V1: 「学部・学科によって、修了要件は相違する」場合は、本シートを複製の上＜様式１－〇＞と枝番号を付してください
B2: 大学等名 | C2: 埼玉大学
B3: プログラム名 | C3: 数理・データサイエンス・ＡＩリテラシー教育プログラム
A5: プログラムを構成する授業科目について
A7: ① 教育プログラムの修了要件 | L7: 学部・学科によって、修了要件は相違する
A9: ② 対象となる学部・学科名称
B11: 工学部（情報工学科）
A14: ③ 修了要件
B15: 理工学と現代社会（２単位）、工学入門セミナー（２単位）、情報システム工学入門（２単位）、情報倫理（２単位）の計８単位を修得すること。 | X15: 【プルダウンリスト】
X16: 令和５年度以前より、履修することが必須のプログラムとして実施
X17: 令和８年度までに履修必須とする計画
X18: 令和９年度以降に履修必須とする計画、又は未定
B22: 必要最低科目数・単位数 | E22: 4 | F22: 科目 | H22: 8 | I22: 単位 | M22: 履修必須の有無 | N22: 令和５年度以前より、履修することが必須のプログラムとして実施
A24: ④ 現在進行中の社会変化（第４次産業革命、Society 5.0、データ駆動型社会等）に深く寄与しているものであり、それが自らの生活と密接に結びついている」の内容を含む授業科目
B26: 授業科目 | G26: 単位数 | H26: 必須 | I26: 1-1 | J26: 1-6 | K26: 授業科目 | R26: 単位数 | S26: 必須 | T26: 1-1 | U26: 1-6
B27: 理工学と現代社会 | G27: 2 | H27: ○ | I27: ○ | J27: ○
B28: 情報システム工学入門 | G28: 2 | H28: ○ | I28: ○ | J28: ○
B29: 工学入門セミナー | G29: 2 | H29: ○ | I29: ○
A35: ⑤ 「社会で活用されているデータ」や「データの活用領域」は非常に広範囲であって、日常生活や社会の課題を解決する有用なツールになり得るもの」の内容を含む授業科目
B37: 授業科目 | G37: 単位数 | H37: 必須 | I37: 1-2 | J37: 1-3 | K37: 授業科目 | R37: 単位数 | S37: 必須 | T37: 1-2 | U37: 1-3
B38: 理工学と現代社会 | G38: 2 | H38: ○ | I38: ○ | J38: ○
B39: 情報システム工学入門 | G39: 2 | H39: ○ | I39: ○ | J39: ○
B40: 工学入門セミナー | G40: 2 | H40: ○ | J40: ○
A46: ⑥ 「様々なデータ利活用の現場におけるデータ利活用事例が示され、様々な適用領域（流通、製造、金融、サービス、インフラ、公共、ヘルスケア等）の知見と組み合わせることで価値を創出するもの」の内容を含む授業科目
B48: 授業科目 | G48: 単位数 | H48: 必須 | I48: 1-4 | J48: 1-5 | K48: 授業科目 | R48: 単位数 | S48: 必須 | T48: 1-4 | U48: 1-5
B49: 理工学と現代社会 | G49: 2 | H49: ○ | I49: ○ | J49: ○
B50: 情報システム工学入門 | G50: 2 | H50: ○ | I50: ○ | J50: ○
B51: 工学入門セミナー | G51: 2 | H51: ○ | I51: ○
A57: ⑦ 「活用に当たっての様々な留意事項（ELSI、個人情報、データ倫理、ＡＩ社会原則等）を考慮し、情報セキュリティや情報漏洩等、データを守る上での留意事項への理解をする」の内容を含む授業科目
B59: 授業科目 | G59: 単位数 | H59: 必須 | I59: 3-1 | J59: 3-2 | K59: 授業科目 | R59: 単位数 | S59: 必須 | T59: 3-1 | U59: 3-2
B60: 理工学と現代社会 | G60: 2 | H60: ○ | I60: ○ | J60: ○
B61: 情報倫理 | G61: 2 | H61: ○ | I61: ○ | J61: ○
B62: 工学入門セミナー | G62: 2 | H62: ○ | I62: ○ | J62: ○
A68: ⑧ 「実データ・実課題（学術データ等を含む）を用いた演習など、社会での実例を題材として、「データを読む、説明する、扱う」といった数理・データサイエンス・ＡＩの基本的な活用法に関するもの」の内容を含む授業科目
B70: 授業科目 | F70: 単位数 | G70: 必須 | H70: 2-1 | I70: 2-2 | J70: 2-3 | K70: 授業科目 | Q70: 単位数 | R70: 必須 | S70: 2-1 | T70: 2-2 | U70: 2-3
B71: 理工学と現代社会 | F71: 2 | G71: ○ | H71: ○
B72: 工学入門セミナー | F72: 2 | G72: ○ | H72: ○ | I72: ○ | J72: ○
A79: ⑨ 選択「４．オプション」の内容を含む授業科目
B80: 授業科目 | G80: 選択項目 | K80: 授業科目 | R80: 選択項目
A89: ⑩ プログラムを構成する授業の内容
...

Sheet 様式２ 履修者等数の実績
S1: 様式２
Q2: ='様式１-１ プログラムを構成する授業科目 (教養)'!C2 -> 埼玉大学
A3: プログラムの履修者数等の実績について
A5: ①プログラム開設年度 | C5: 令和５ | E5: 年度
A7: ②大学等全体の男女別学生数 | E7: 男性 | F7: 4397 | G7: 人 | H7: 女性 | I7: 2274 | J7: 人 | K7: （ | L7: 合計 | M7: =F7+I7 -> 6671 | N7: 人 | O7: ）
A9: ③履修者・修了者の実績
B11: 学部・学科名称 | C11: 学生数 | D11: 入学 定員 | E11: 収容 定員 | F11: 令和5年度 | H11: 令和4年度 | J11: 令和3年度 | L11: 令和2年度 | N11: 令和元年度 | P11: 平成30年度 | R11: 履修者数 合計 | S11: 履修率
F12: 履修者数 | G12: 修了者数 | H12: 履修者数 | I12: 修了者数 | J12: 履修者数 | K12: 修了者数 | L12: 履修者数 | M12: 修了者数 | N12: 履修者数 | O12: 修了者数 | P12: 履修者数 | Q12: 修了者数
B13: 教養学部 | C13: 781 | D13: 160 | E13: 700 | F13: 167 | G13: 149 | R13: =F13+H13+J13+L13+N13+P13 -> 167 | S13: =R13/E13 -> 0.23857143
B14: 経済学部（昼間コース） | C14: 1284 | D14: 280 | E14: 1140 | F14: 285 | G14: 247 | R14: =F14+H14+J14+L14+N14+P14 -> 285 | S14: =R14/E14 -> 0.25
B15: 教育学部 | C15: 1605 | D15: 380 | E15: 1520 | F15: 394 | G15: 364 | R15: =F15+H15+J15+L15+N15+P15 -> 394 | S15: =R15/E15 -> 0.25921053
B16: 理学部 | C16: 884 | D16: 210 | E16: 840 | F16: 215 | G16: 195 | R16: =F16+H16+J16+L16+N16+P16 -> 215 | S16: =R16/E16 -> 0.25595238
B17: 工学部 | C17: 2117 | D17: 490 | E17: 1960 | F17: 500 | G17: 452 | R17: =F17+H17+J17+L17+N17+P17 -> 500 | S17: =R17/E17 -> 0.25510204
R18: =F18+H18+J18+L18+N18+P18 -> 0 | S18: =R18/E18 -> #DIV/0!
R19: =F19+H19+J19+L19+N19+P19 -> 0 | S19: =R19/E19 -> #DIV/0!
R20: =F20+H20+J20+L20+N20+P20 -> 0 | S20: =R20/E20 -> #DIV/0!
R21: =F21+H21+J21+L21+N21+P21 -> 0 | S21: =R21/E21 -> #DIV/0!
R22: =F22+H22+J22+L22+N22+P22 -> 0 | S22: =R22/E22 -> #DIV/0!
R23: =F23+H23+J23+L23+N23+P23 -> 0 | S23: =R23/E23 -> #DIV/0!
R24: =F24+H24+J24+L24+N24+P24 -> 0 | S24: =R24/E24 -> #DIV/0!
R25: =F25+H25+J25+L25+N25+P25 -> 0 | S25: =R25/E25 -> #DIV/0!
R26: =F26+H26+J26+L26+N26+P26 -> 0 | S26: =R26/E26 -> #DIV/0!
R27: =F27+H27+J27+L27+N27+P27 -> 0 | S27: =R27/E27 -> #DIV/0!
R28: =F28+H28+J28+L28+N28+P28 -> 0 | S28: =R28/E28 -> #DIV/0!
R29: =F29+H29+J29+L29+N29+P29 -> 0 | S29: =R29/E29 -> #DIV/0!
... R32: =F32+H32+J32+L32+N32+P32 -> 0 | S32: =R32/E32 -> #DIV/0!
B33: 合 計 | C33: =SUM(C13:C32) -> 6671 | D33: =SUM(D13:D32) -> 1520 | E33: =SUM(E13:E32) -> 6160 | F33: =SUM(F13:F32) -> 1561 | G33: =SUM(G13:G32) -> 1407 | H33: =SUM(H13:H32) -> 0 | I33: =SUM(I13:I32) -> 0 | J33: =SUM(J13:J32) -> 0 | ... R33: =SUM(R13:R32) -> 1561 | S33: =R33/E33 -> 0.25340909

Sheet 様式３ 教育の質・履修者数を向上させるための体制・計画
I1: 様式３
G2: 大学等名 | H2: ='様式１-１ プログラムを構成する授業科目 (教養)'!C2 -> 埼玉大学
A4: 教育の質・履修者数を向上させるための体制・計画について
A6: ① | B6: 全学の教員数 | C6: (常勤） | E6: 422 | F6: 人 | G6: （非常勤） | H6: 339 | I6: 人
A8: ② | B8: プログラムの授業を教えている教員数 | H8: 38 | I8: 人
A10: ③ | B10: プログラムの運営責任者
B11: （責任者名） | C11: 市川 裕介 | G11: （役職名） | H11: 基盤教育研究センター教授
A13: ④ | B13: プログラムを改善・進化させるための体制（委員会・組織等）
B14: データサイエンス教育実施委員会
B16: （責任者名） | C16: 市川 裕介 | G16: （役職名） | H16: 基盤教育研究センター教授
A18: ⑤ | B18: プログラムを改善・進化させるための体制を定める規則名称
B19: 国立大学法人埼玉大学データサイエンス教育実施委員会要項
A21: ⑥ | B21: 体制の目的
B22: 学生の数理・データサイエンス・ＡＩへの関心を高め、それを適切に理解し活用する基礎的な能力、数理・データサイエンス・ＡＩを異分野協働の共通の基盤であるコミュニケーションツールとして取り扱える能力を育成することを目的に、数理・データサイエンス・ＡＩ教育プログラムを整備し、同プログラムを運営するデータサイエンス教育実施委員会を設置している。本委員会は、全学教育に係る事項の実施及び推進並びに評価及び改善等を行う教育推進室のもとに設置している。
A34: ⑦ | B34: 具体的な構成員
B35: 基盤教育研究センター 教授 市川 裕介（委員長） 教育学部 准教授 野村 泰朗 人文社会科学研究科 教授 内木 哲也 人文社会科学研究科 准教授 高松 亮 理工学研究科 教授 長澤 壯之 理工学研究科 教授 大久保 潤
A48: ⑧ | B48: 履修者数・履修率の向上に向けた計画 ※様式１の「履修必須の有無」で「計画がある」としている場合は詳細について記載すること
B49: 令和５年度実績 | C49: ='様式２ 履修者等数の実績'!S33 -> 0.25340909 | E49: 令和６年度予定 | F49: 0.5 | H49: 令和７年度予定 | I49: 0.75
B50: 令和８年度予定 | C50: 1 | E50: 令和９年度予定 | F50: 1 | H50: 収容定員（名） | I50: ='様式２ 履修者等数の実績'!E33 -> 6160
B51: 具体的な計画
B52: 令和５年度から教養学部、経済学部（昼間コース）、教育学部、理学部、工学部学生の必修科目でプログラムを構成しており、経年的に履修者数・履修率を増加・向上させる計画である。
A65: ⑨ | B65: 学部・学科に関係なく希望する学生全員が受講可能となるような必要な体制・取組等
B66: 本学では、学部単位で科目を開設しすべて必修科目とすることで、すべての学生が受講可能な体制としている。
A79: ⑩ | B79: できる限り多くの学生が履修できるような具体的な周知方法・取組
B80: 本学では、⑨に記載のとおり各学部ごとにすべて必修科目として開設しており、その旨をウェブサイトや履修案内に掲載し、ガイダンスで周知している。
A93: ⑪ | B93: できる限り多くの学生が履修・修得できるようなサポート体制
B94: 本学では、⑨に記載のとおり各学部ごとにすべて必修科目として開設しており、すべての学生が卒業までにプログラム構成科目を履修・修得する。
A107: ⑫ | B107: 授業時間内外で学習指導、質問を受け付ける具体的な仕組み
B108: 本教育プログラムを構成する授業科目について、オフィスアワーを設けるほか、LMSを活用して質問や不明点等を授業担当教員に直接問い合わせることができる体制を整備している。

Sheet 様式４　自己点検・評価
I1: 様式４
H2: 大学等名 | I2: ='様式１-１ プログラムを構成する授業科目 (教養)'!C2 -> 埼玉大学
A3: 自己点検・評価について
A5: ① | B5: プログラムの自己点検・評価を行う体制（委員会・組織等）
B6: データサイエンス教育実施委員会
D8: （責任者名） | E8: 市川 裕介 | G8: （役職名） | H8: 基盤教育研究センター教授
A10: ② | B10: 自己点検・評価体制における意見等
B11: 自己点検・評価の視点 | E11: 自己点検・評価体制における意見・結果・改善に向けた取組等
B12: 学内からの視点
C13: プログラムの履修・修得状況 | E13: データサイエンス教育実施委員会において、プログラムの履修・修得状況（受講者数、単位修得者数およびその割合）の分析を実施し、プログラム履修者毎の進捗状況を把握する。
C14: 学修成果 | E14: 教育推進室で実施している在学生調査のうち、「数理情報やデータを処理する能力（データサイエンスや統計の知識を含む）」「ITリテラシー（デバイス（PC等）の基本的な操作スキル、情報倫理並びに情報セキュリティの基礎知識等）」が身についた等の項目をデータサイエンス教育実施委員会で分析することにより、授業内容の理解度を把握し、本教育プログラムの評価・改善に活用する。また、プログラムの履修・修得状況（受講者数、単位修得者数およびその割合）の分析を実施し、プログラム履修者毎の進捗状況を把握する。
C15: 学生アンケート等を通じた学生の内容の理解度 | E15: 受講生に対する授業評価アンケートにおいて、教員が授業への参加を促したか、質問に分かるように回答してくれたか、思考力涵養・専門知識向上に役立ったかについて確認し、本教育プログラムの評価・改善に活用する。
C16: 学生アンケート等を通じた後輩等他の学生への推奨度 | E16: 授業評価アンケートにて推奨度は計っていないため、当該科目の総合的な満足度を推奨度とみなして確認する。この結果をデータサイエンス教育実施委員会で分析することにより、本教育プログラムの評価・改善に活用する。
C17: 全学的な履修者数、履修率向上に向けた計画の達成・進捗状況 | E17: 本教育プログラムの科目は必修科目としている。令和５年度入学者から受講者が増加することを通じて経年的に履修者数・履修率を増加・向上させる計画である。毎年度、開講科目数、履修者数・履修率等をデータサイエンス実施委員会で確認することを通じて、進捗状況を評価する。
B18: 学外からの視点
C19: 教育プログラム修了者の進路、活躍状況、企業等の評価 | E19: 教育推進室で実施している卒業生を対象とした調査のうち、本学卒業生が「数理情報やデータを処理する能力」「情報倫理や情報セキュリティの基礎的知識等」が身につけた等の項目をデータサイエンス教育実施委員会で分析することにより、本教育プログラムの評価・改善に活用する。
C20: 産業界からの視点を含めた教育プログラム内容・手法等への意見 | E20: 教育推進室で実施している企業・官公庁を対象とした調査のうち、本学卒業生が「数理情報やデータを処理する能力」「情報倫理や情報セキュリティの基礎的知識等」が身につけた等の項目をデータサイエンス教育実施委員会で分析することにより、本教育プログラムの評価・改善に活用する。
B21: 数理・データサイエンス・ＡＩを「学ぶ楽しさ」「学ぶことの意義」を理解させること | E21: 現代で重要性が増しているデータサイエンス、人工知能（AI）に関する基礎知識やインターネット社会を安全に利用するための基礎知識を学ぶべく、数理・データサイエンスを学部の特性にあわせてカスタマイズしているため、より自身の大学生活や将来デザインにそった学びとすることで「楽しさ」を感じながら学べることを目指している。 シラバスの授業の内容、授業の展開欄から「学ぶことの意義」を理解させる授業構成になっているか、「学ぶ楽しさが」感じられる授業構成になっているかをデータサイエンス教育実施委員会で分析することにより、本教育プログラムの評価・改善に活用する。
B22: 内容・水準を維持・向上しつつ、より「分かりやすい」授業とすること ※社会の変化や生成AI等の技術の発展を踏まえて教育内容を継続的に見直すなど、より教育効果の高まる授業内容・方法とするための取組や仕組みについても該当があれば記載 | E22: シラバスの記載が適切か、本制度申請時の水準を満たしているか、授業アンケートの各回答や自由記述の内容を毎年度データサイエンス教育実施委員会で分析することにより、本教育プログラムの評価・改善に活用する。 また、授業担当教員へフィードバックすることにより、より「分かりやすい」授業への改善に活用する。
