Workbook

Sheet 様式１-１　プログラムを構成する授業科目
T1: 様式１-１ | V1: 「学部・学科によって、修了要件は相違する」場合は、本シートを複製の上＜様式１－〇＞と枝番号を付してください
B2: 大学等名 | C2: 大妻女子大学
B3: プログラム名 | C3: 大妻データサイエンス・AIプログラム
A5: プログラムを構成する授業科目について
A7: ① 教育プログラムの修了要件 | L7: 学部・学科によって、修了要件は相違する
A9: ② 対象となる学部・学科名称
B11: 家政学部・文学部・人間関係学部・比較文化学部
A14: ③ 修了要件
B15: 次の２科目４単位の単位修得をプログラムの修了要件とする。 全学共通科目：「データサイエンス・ＡＩ概論」「コンピュータ基礎Ｂ」 | X15: 【プルダウンリスト】
X16: 令和５年度以前より、履修することが必須のプログラムとして実施
X17: 令和８年度までに履修必須とする計画
X18: 令和９年度以降に履修必須とする計画、又は未定
B22: 必要最低科目数・単位数 | E22: 2 | F22: 科目 | H22: 4 | I22: 単位 | M22: 履修必須の有無 | N22: 令和９年度以降に履修必須とする計画、又は未定
A24: ④ 現在進行中の社会変化（第４次産業革命、Society 5.0、データ駆動型社会等）に深く寄与しているものであり、それが自らの生活と密接に結びついている」の内容を含む授業科目
B26: 授業科目 | G26: 単位数 | H26: 必須 | I26: 1-1 | J26: 1-6 | K26: 授業科目 | R26: 単位数 | S26: 必須 | T26: 1-1 | U26: 1-6
B27: データサイエンス・ＡＩ概論 | G27: 2 | H27: ○ | I27: ○ | J27: ○
A35: ⑤ 「社会で活用されているデータ」や「データの活用領域」は非常に広範囲であって、日常生活や社会の課題を解決する有用なツールになり得るもの」の内容を含む授業科目
B37: 授業科目 | G37: 単位数 | H37: 必須 | I37: 1-2 | J37: 1-3 | K37: 授業科目 | R37: 単位数 | S37: 必須 | T37: 1-2 | U37: 1-3
B38: データサイエンス・ＡＩ概論 | G38: 2 | H38: ○ | I38: ○ | J38: ○
A46: ⑥ 「様々なデータ利活用の現場におけるデータ利活用事例が示され、様々な適用領域（流通、製造、金融、サービス、インフラ、公共、ヘルスケア等）の知見と組み合わせることで価値を創出するもの」の内容を含む授業科目
B48: 授業科目 | G48: 単位数 | H48: 必須 | I48: 1-4 | J48: 1-5 | K48: 授業科目 | R48: 単位数 | S48: 必須 | T48: 1-4 | U48: 1-5
B49: データサイエンス・ＡＩ概論 | G49: 2 | H49: ○ | I49: ○ | J49: ○
A57: ⑦ 「活用に当たっての様々な留意事項（ELSI、個人情報、データ倫理、ＡＩ社会原則等）を考慮し、情報セキュリティや情報漏洩等、データを守る上での留意事項への理解をする」の内容を含む授業科目
B59: 授業科目 | G59: 単位数 | H59: 必須 | I59: 3-1 | J59: 3-2 | K59: 授業科目 | R59: 単位数 | S59: 必須 | T59: 3-1 | U59: 3-2
B60: データサイエンス・ＡＩ概論 | G60: 2 | H60: ○ | I60: ○ | J60: ○
A68: ⑧ 「実データ・実課題（学術データ等を含む）を用いた演習など、社会での実例を題材として、「データを読む、説明する、扱う」といった数理・データサイエンス・ＡＩの基本的な活用法に関するもの」の内容を含む授業科目
B70: 授業科目 | F70: 単位数 | G70: 必須 | H70: 2-1 | I70: 2-2 | J70: 2-3 | K70: 授業科目 | Q70: 単位数 | R70: 必須 | S70: 2-1 | T70: 2-2 | U70: 2-3
B71: コンピュータ基礎B | F71: 2 | G71: ○ | H71: ○ | I71: ○ | J71: ○
A79: ⑨ 選択「４．オプション」の内容を含む授業科目
B80: 授業科目 | G80: 選択項目 | K80: 授業科目 | R80: 選択項目
A89: ⑩ プログラムを構成する授業の内容
B90: 授業に含まれている内容・要素 | D90: 講義内容
B91: （１）現在進行中の社会変化（第４次産業革命、Society 5.0、データ駆動型社会等）に深く寄与しているものであり、それが自らの生活と密接に結びついている | C91: 1-1 | D91: ・人間の知的活動とAIの関係性「データサイエンス・AI概論」（第１回） ・データを起点としたものの見方、人間の知的活動を起点としたものの見方「データサイエンス・AI概論」（第１５回）
C92: 1-6 | D92: ・AI等を活用した新しいビジネスモデル(シェアリングエコノミー、商品のレコメンデーションなど)「データサイエンス・AI概論」（第１回、第１１回、第１５回） ・AI最新技術の活用例（深層生成モデル、敵対的生成ネットワーク、強化学習、転移学習など）「データサイエンス・AI概論」（第１１回）
B93: （２）「社会で活用されているデータ」や「データの活用領域」は非常に広範囲であって、日常生活や社会の課題を解決する有用なツールになり得るもの | C93: 1-2 | D93: ・調査データ、実験データ、人の行動ログデータ、機械の稼働ログデータなど「データサイエンス・AI概論」（第２～４回、第８回） ・構造化データ、非構造化データ（文章、画像/動画、音声/音楽など）「データサイエンス・AI概論」（第６回） ・データのオープン化（オープンデータ）「データサイエンス・AI概論」（第５回）
C94: 1-3 | D94: ・データ・AI活用領域の広がり（生産、消費、文化活動など）「データサイエンス・AI概論」（第２回、第７回、第１５回） ・研究開発、調達、製造、物流、販売、マーケティング、サービスなど「データサイエンス・AI概論」（第５回） ・仮説検証、知識発見、原因究明、計画策定、判断支援、活動代替、新規生成など「データサイエンス・AI概論」（第４回）
B95: （３）様々なデータ利活用の現場におけるデータ利活用事例が示され、様々な適用領域（流通、製造、金融、サービス、インフラ、公共、ヘルスケア等）の知見と組み合わせることで価値を創出するもの | C95: 1-4 | D95: ・データ解析：予測、グル－ピング、パターン発見、最適化、シミュレーション・データ同化など「データサイエンス・AI概論」（第８回～第１２回） ・非構造化データ処理：言語処理、画像/動画処理、音声/音楽処理など「データサイエンス・AI概論」（第６回、第７回） ・認識技術、ルールベース、自動化技術「データサイエンス・AI概論」（第８回）
C96: 1-5 | D96: ・流通、製造、金融、サービス、インフラ、公共、ヘルスケア等におけるデータ・AI利活用事例紹介「データサイエンス・AI概論」（第８回～第１２回） ・データサイエンスのサイクル（課題抽出と定式化、データの取得・管理・加工、探索的データ解析、データ解析と推論、結果の共有・伝達、課題解決に向けた提案）「データサイエンス・AI概論」（第４回）
B97: （４）活用に当たっての様々な留意事項（ELSI、個人情報、データ倫理、ＡＩ社会原則等）を考慮し、情報セキュリティや情報漏洩等、データを守る上での留意事項への理解をする | C97: 3-1 | D97: ・ELSI（Ethical, Legal and Social Issues）「データサイエンス・AI概論」（第１３回） ・個人情報保護、EU一般データ保護規則(GDPR)、忘れられる権利、オプトアウト「データサイエンス・AI概論」（第１１回、第１３回） ・データ倫理：データのねつ造、改ざん、盗用、プライバシー保護「データサイエンス・AI概論」（第１３回） ・AI社会原則（公平性、説明責任、透明性、人間中心の判断）「データサイエンス・AI概論」（第１５回） ・AIサービスの責任論「データサイエンス・AI概論」（第１３回）
C98: 3-2 | D98: ・情報セキュリティ：機密性、完全性、可用性「データサイエンス・AI概論」（第１４回） ・匿名加工情報、暗号化、パスワード、悪意ある情報搾取「データサイエンス・AI概論」（第１４回） ・情報漏洩等によるセキュリティ事故の事例紹介「データサイエンス・AI概論」（第１４回）
...

Sheet 様式１-２　プログラムを構成する授業科目
T1: 様式１-２ | V1: 「学部・学科によって、修了要件は相違する」場合は、本シートを複製の上＜様式１－〇＞と枝番号を付してください
B2: 大学等名 | C2: 大妻女子大学
B3: プログラム名 | C3: 大妻データサイエンス・AIプログラム
A5: プログラムを構成する授業科目について
A7: ① 教育プログラムの修了要件 | L7: 学部・学科によって、修了要件は相違する
A9: ② 対象となる学部・学科名称
B11: 社会情報学部社会情報学科社会生活情報学専攻・環境情報学専攻
A14: ③ 修了要件
B15: 次の２科目４単位の単位修得をプログラムの修了要件とする。 全学共通科目：「データサイエンス・ＡＩ概論」 社会情報学部学部共通科目：「情報処理実習Ｂ」 | X15: 【プルダウンリスト】
X16: 令和５年度以前より、履修することが必須のプログラムとして実施
X17: 令和８年度までに履修必須とする計画
X18: 令和９年度以降に履修必須とする計画、又は未定
B22: 必要最低科目数・単位数 | E22: 2 | F22: 科目 | H22: 4 | I22: 単位 | M22: 履修必須の有無 | N22: 令和９年度以降に履修必須とする計画、又は未定
A24: ④ 現在進行中の社会変化（第４次産業革命、Society 5.0、データ駆動型社会等）に深く寄与しているものであり、それが自らの生活と密接に結びついている」の内容を含む授業科目
B26: 授業科目 | G26: 単位数 | H26: 必須 | I26: 1-1 | J26: 1-6 | K26: 授業科目 | R26: 単位数 | S26: 必須 | T26: 1-1 | U26: 1-6
B27: データサイエンス・ＡＩ概論 | G27: 2 | H27: ○ | I27: ○ | J27: ○
A35: ⑤ 「社会で活用されているデータ」や「データの活用領域」は非常に広範囲であって、日常生活や社会の課題を解決する有用なツールになり得るもの」の内容を含む授業科目
B37: 授業科目 | G37: 単位数 | H37: 必須 | I37: 1-2 | J37: 1-3 | K37: 授業科目 | R37: 単位数 | S37: 必須 | T37: 1-2 | U37: 1-3
B38: データサイエンス・ＡＩ概論 | G38: 2 | H38: ○ | I38: ○ | J38: ○
A46: ⑥ 「様々なデータ利活用の現場におけるデータ利活用事例が示され、様々な適用領域（流通、製造、金融、サービス、インフラ、公共、ヘルスケア等）の知見と組み合わせることで価値を創出するもの」の内容を含む授業科目
B48: 授業科目 | G48: 単位数 | H48: 必須 | I48: 1-4 | J48: 1-5 | K48: 授業科目 | R48: 単位数 | S48: 必須 | T48: 1-4 | U48: 1-5
B49: データサイエンス・ＡＩ概論 | G49: 2 | H49: ○ | I49: ○ | J49: ○
A57: ⑦ 「活用に当たっての様々な留意事項（ELSI、個人情報、データ倫理、ＡＩ社会原則等）を考慮し、情報セキュリティや情報漏洩等、データを守る上での留意事項への理解をする」の内容を含む授業科目
B59: 授業科目 | G59: 単位数 | H59: 必須 | I59: 3-1 | J59: 3-2 | K59: 授業科目 | R59: 単位数 | S59: 必須 | T59: 3-1 | U59: 3-2
B60: データサイエンス・ＡＩ概論 | G60: 2 | H60: ○ | I60: ○ | J60: ○
A68: ⑧ 「実データ・実課題（学術データ等を含む）を用いた演習など、社会での実例を題材として、「データを読む、説明する、扱う」といった数理・データサイエンス・ＡＩの基本的な活用法に関するもの」の内容を含む授業科目
B70: 授業科目 | F70: 単位数 | G70: 必須 | H70: 2-1 | I70: 2-2 | J70: 2-3 | K70: 授業科目 | Q70: 単位数 | R70: 必須 | S70: 2-1 | T70: 2-2 | U70: 2-3
B71: 情報処理実習Ｂ | F71: 2 | G71: ○ | H71: ○ | I71: ○ | J71: ○
A79: ⑨ 選択「４．オプション」の内容を含む授業科目
B80: 授業科目 | G80: 選択項目 | K80: 授業科目 | R80: 選択項目
A89: ⑩ プログラムを構成する授業の内容
B90: 授業に含まれている内容・要素 | D90: 講義内容
B91: （１）現在進行中の社会変化（第４次産業革命、Society 5.0、データ駆動型社会等）に深く寄与しているものであり、それが自らの生活と密接に結びついている | C91: 1-1 | D91: ・人間の知的活動とAIの関係性「データサイエンス・AI概論」（第１回） ・データを起点としたものの見方、人間の知的活動を起点としたものの見方「データサイエンス・AI概論」（第１５回）
C92: 1-6 | D92: ・AI等を活用した新しいビジネスモデル(シェアリングエコノミー、商品のレコメンデーションなど)「データサイエンス・AI概論」（第１回、第１１回、第１５回） ・AI最新技術の活用例（深層生成モデル、敵対的生成ネットワーク、強化学習、転移学習など）「データサイエンス・AI概論」（第１１回）
B93: （２）「社会で活用されているデータ」や「データの活用領域」は非常に広範囲であって、日常生活や社会の課題を解決する有用なツールになり得るもの | C93: 1-2 | D93: ・調査データ、実験データ、人の行動ログデータ、機械の稼働ログデータなど「データサイエンス・AI概論」（第２～４回、第８回） ・構造化データ、非構造化データ（文章、画像/動画、音声/音楽など）「データサイエンス・AI概論」（第６回） ・データのオープン化（オープンデータ）「データサイエンス・AI概論」（第５回）
C94: 1-3 | D94: ・データ・AI活用領域の広がり（生産、消費、文化活動など）「データサイエンス・AI概論」（第２回、第７回、第１５回） ・研究開発、調達、製造、物流、販売、マーケティング、サービスなど「データサイエンス・AI概論」（第５回） ・仮説検証、知識発見、原因究明、計画策定、判断支援、活動代替、新規生成など「データサイエンス・AI概論」（第４回）
B95: （３）様々なデータ利活用の現場におけるデータ利活用事例が示され、様々な適用領域（流通、製造、金融、サービス、インフラ、公共、ヘルスケア等）の知見と組み合わせることで価値を創出するもの | C95: 1-4 | D95: ・データ解析：予測、グル－ピング、パターン発見、最適化、シミュレーション・データ同化など「データサイエンス・AI概論」（第８回～第１２回） ・非構造化データ処理：言語処理、画像/動画処理、音声/音楽処理など「データサイエンス・AI概論」（第６回、第７回） ・認識技術、ルールベース、自動化技術「データサイエンス・AI概論」（第８回）
C96: 1-5 | D96: ・流通、製造、金融、サービス、インフラ、公共、ヘルスケア等におけるデータ・AI利活用事例紹介「データサイエンス・AI概論」（第８回～第１２回） ・データサイエンスのサイクル（課題抽出と定式化、データの取得・管理・加工、探索的データ解析、データ解析と推論、結果の共有・伝達、課題解決に向けた提案）「データサイエンス・AI概論」（第４回）
B97: （４）活用に当たっての様々な留意事項（ELSI、個人情報、データ倫理、ＡＩ社会原則等）を考慮し、情報セキュリティや情報漏洩等、データを守る上での留意事項への理解をする | C97: 3-1 | D97: ・ELSI（Ethical, Legal and Social Issues）「データサイエンス・AI概論」（第１３回） ・個人情報保護、EU一般データ保護規則(GDPR)、忘れられる権利、オプトアウト「データサイエンス・AI概論」（第１１回、第１３回） ・データ倫理：データのねつ造、改ざん、盗用、プライバシー保護「データサイエンス・AI概論」（第１３回） ・AI社会原則（公平性、説明責任、透明性、人間中心の判断）「データサイエンス・AI概論」（第１５回） ・AIサービスの責任論「データサイエンス・AI概論」（第１３回）
C98: 3-2 | D98: ・情報セキュリティ：機密性、完全性、可用性「データサイエンス・AI概論」（第１４回） ・匿名加工情報、暗号化、パスワード、悪意ある情報搾取「データサイエンス・AI概論」（第１４回） ・情報漏洩等によるセキュリティ事故の事例紹介「データサイエンス・AI概論」（第１４回）
...

Sheet 様式１-３　プログラムを構成する授業科目
T1: 様式１-３ | V1: 「学部・学科によって、修了要件は相違する」場合は、本シートを複製の上＜様式１－〇＞と枝番号を付してください
B2: 大学等名 | C2: 大妻女子大学
B3: プログラム名 | C3: 大妻データサイエンス・AIプログラム
A5: プログラムを構成する授業科目について
A7: ① 教育プログラムの修了要件 | L7: 学部・学科によって、修了要件は相違する
A9: ② 対象となる学部・学科名称
B11: 社会情報学部社会情報学科情報デザイン専攻
A14: ③ 修了要件
B15: 次の２科目４単位の単位修得をプログラムの修了要件とする。 全学共通科目：「データサイエンス・ＡＩ概論」 社会情報学部学部共通科目：「情報処理実習Ａ」 | X15: 【プルダウンリスト】
X16: 令和５年度以前より、履修することが必須のプログラムとして実施
X17: 令和８年度までに履修必須とする計画
X18: 令和９年度以降に履修必須とする計画、又は未定
B22: 必要最低科目数・単位数 | E22: 2 | F22: 科目 | H22: 4 | I22: 単位 | M22: 履修必須の有無 | N22: 令和９年度以降に履修必須とする計画、又は未定
A24: ④ 現在進行中の社会変化（第４次産業革命、Society 5.0、データ駆動型社会等）に深く寄与しているものであり、それが自らの生活と密接に結びついている」の内容を含む授業科目
B26: 授業科目 | G26: 単位数 | H26: 必須 | I26: 1-1 | J26: 1-6 | K26: 授業科目 | R26: 単位数 | S26: 必須 | T26: 1-1 | U26: 1-6
B27: データサイエンス・ＡＩ概論 | G27: 2 | H27: ○ | I27: ○ | J27: ○
A35: ⑤ 「社会で活用されているデータ」や「データの活用領域」は非常に広範囲であって、日常生活や社会の課題を解決する有用なツールになり得るもの」の内容を含む授業科目
B37: 授業科目 | G37: 単位数 | H37: 必須 | I37: 1-2 | J37: 1-3 | K37: 授業科目 | R37: 単位数 | S37: 必須 | T37: 1-2 | U37: 1-3
B38: データサイエンス・ＡＩ概論 | G38: 2 | H38: ○ | I38: ○ | J38: ○
A46: ⑥ 「様々なデータ利活用の現場におけるデータ利活用事例が示され、様々な適用領域（流通、製造、金融、サービス、インフラ、公共、ヘルスケア等）の知見と組み合わせることで価値を創出するもの」の内容を含む授業科目
B48: 授業科目 | G48: 単位数 | H48: 必須 | I48: 1-4 | J48: 1-5 | K48: 授業科目 | R48: 単位数 | S48: 必須 | T48: 1-4 | U48: 1-5
B49: データサイエンス・ＡＩ概論 | G49: 2 | H49: ○ | I49: ○ | J49: ○
A57: ⑦ 「活用に当たっての様々な留意事項（ELSI、個人情報、データ倫理、ＡＩ社会原則等）を考慮し、情報セキュリティや情報漏洩等、データを守る上での留意事項への理解をする」の内容を含む授業科目
B59: 授業科目 | G59: 単位数 | H59: 必須 | I59: 3-1 | J59: 3-2 | K59: 授業科目 | R59: 単位数 | S59: 必須 | T59: 3-1 | U59: 3-2
B60: データサイエンス・ＡＩ概論 | G60: 2 | H60: ○ | I60: ○ | J60: ○
A68: ⑧ 「実データ・実課題（学術データ等を含む）を用いた演習など、社会での実例を題材として、「データを読む、説明する、扱う」といった数理・データサイエンス・ＡＩの基本的な活用法に関するもの」の内容を含む授業科目
B70: 授業科目 | F70: 単位数 | G70: 必須 | H70: 2-1 | I70: 2-2 | J70: 2-3 | K70: 授業科目 | Q70: 単位数 | R70: 必須 | S70: 2-1 | T70: 2-2 | U70: 2-3
B71: 情報処理実習Ａ | F71: 2 | G71: ○ | H71: ○ | I71: ○ | J71: ○
A79: ⑨ 選択「４．オプション」の内容を含む授業科目
B80: 授業科目 | G80: 選択項目 | K80: 授業科目 | R80: 選択項目
A89: ⑩ プログラムを構成する授業の内容
B90: 授業に含まれている内容・要素 | D90: 講義内容
B91: （１）現在進行中の社会変化（第４次産業革命、Society 5.0、データ駆動型社会等）に深く寄与しているものであり、それが自らの生活と密接に結びついている | C91: 1-1 | D91: ・人間の知的活動とAIの関係性「データサイエンス・AI概論」（第１回） ・データを起点としたものの見方、人間の知的活動を起点としたものの見方「データサイエンス・AI概論」（第１５回）
C92: 1-6 | D92: ・AI等を活用した新しいビジネスモデル(シェアリングエコノミー、商品のレコメンデーションなど)「データサイエンス・AI概論」（第１回、第１１回、第１５回） ・AI最新技術の活用例（深層生成モデル、敵対的生成ネットワーク、強化学習、転移学習など）「データサイエンス・AI概論」（第１１回）
B93: （２）「社会で活用されているデータ」や「データの活用領域」は非常に広範囲であって、日常生活や社会の課題を解決する有用なツールになり得るもの | C93: 1-2 | D93: ・調査データ、実験データ、人の行動ログデータ、機械の稼働ログデータなど「データサイエンス・AI概論」（第２～４回、第８回） ・構造化データ、非構造化データ（文章、画像/動画、音声/音楽など）「データサイエンス・AI概論」（第６回） ・データのオープン化（オープンデータ）「データサイエンス・AI概論」（第５回）
C94: 1-3 | D94: ・データ・AI活用領域の広がり（生産、消費、文化活動など）「データサイエンス・AI概論」（第２回、第７回、第１５回） ・研究開発、調達、製造、物流、販売、マーケティング、サービスなど「データサイエンス・AI概論」（第５回） ・仮説検証、知識発見、原因究明、計画策定、判断支援、活動代替、新規生成など「データサイエンス・AI概論」（第４回）
B95: （３）様々なデータ利活用の現場におけるデータ利活用事例が示され、様々な適用領域（流通、製造、金融、サービス、インフラ、公共、ヘルスケア等）の知見と組み合わせることで価値を創出するもの | C95: 1-4 | D95: ・データ解析：予測、グル－ピング、パターン発見、最適化、シミュレーション・データ同化など「データサイエンス・AI概論」（第８回～第１２回） ・非構造化データ処理：言語処理、画像/動画処理、音声/音楽処理など「データサイエンス・AI概論」（第６回、第７回） ・認識技術、ルールベース、自動化技術「データサイエンス・AI概論」（第８回）
C96: 1-5 | D96: ・流通、製造、金融、サービス、インフラ、公共、ヘルスケア等におけるデータ・AI利活用事例紹介「データサイエンス・AI概論」（第８回～第１２回） ・データサイエンスのサイクル（課題抽出と定式化、データの取得・管理・加工、探索的データ解析、データ解析と推論、結果の共有・伝達、課題解決に向けた提案）「データサイエンス・AI概論」（第４回）
B97: （４）活用に当たっての様々な留意事項（ELSI、個人情報、データ倫理、ＡＩ社会原則等）を考慮し、情報セキュリティや情報漏洩等、データを守る上での留意事項への理解をする | C97: 3-1 | D97: ・ELSI（Ethical, Legal and Social Issues）「データサイエンス・AI概論」（第１３回） ・個人情報保護、EU一般データ保護規則(GDPR)、忘れられる権利、オプトアウト「データサイエンス・AI概論」（第１１回、第１３回） ・データ倫理：データのねつ造、改ざん、盗用、プライバシー保護「データサイエンス・AI概論」（第１３回） ・AI社会原則（公平性、説明責任、透明性、人間中心の判断）「データサイエンス・AI概論」（第１５回） ・AIサービスの責任論「データサイエンス・AI概論」（第１３回）
C98: 3-2 | D98: ・情報セキュリティ：機密性、完全性、可用性「データサイエンス・AI概論」（第１４回） ・匿名加工情報、暗号化、パスワード、悪意ある情報搾取「データサイエンス・AI概論」（第１４回） ・情報漏洩等によるセキュリティ事故の事例紹介「データサイエンス・AI概論」（第１４回）
...

Sheet 様式２ 履修者等数の実績
S1: 様式２
Q2: ='様式１-１ プログラムを構成する授業科目'!C2 -> 大妻女子大学
A3: プログラムの履修者数等の実績について
A5: ①プログラム開設年度 | C5: 令和５ | E5: 年度
A7: ②大学等全体の男女別学生数 | E7: 男性 | F7: 0 | G7: 人 | H7: 女性 | I7: 6650 | J7: 人 | K7: （ | L7: 合計 | M7: =F7+I7 -> 6650 | N7: 人 | O7: ）
A9: ③履修者・修了者の実績
B11: 学部・学科名称 | C11: 学生数 | D11: 入学 定員 | E11: 収容 定員 | F11: 令和5年度 | H11: 令和4年度 | J11: 令和3年度 | L11: 令和2年度 | N11: 令和元年度 | P11: 平成30年度 | R11: 履修者数 合計 | S11: 履修率
F12: 履修者数 | G12: 修了者数 | H12: 履修者数 | I12: 修了者数 | J12: 履修者数 | K12: 修了者数 | L12: 履修者数 | M12: 修了者数 | N12: 履修者数 | O12: 修了者数 | P12: 履修者数 | Q12: 修了者数
B13: 家政学部 | C13: 2072 | D13: 490 | E13: 1998 | F13: 13 | G13: 8 | H13: 0 | I13: 0 | J13: 0 | K13: 0 | L13: 0 | M13: 0 | N13: 0 | O13: 0 | P13: 0 | Q13: 0 | R13: =F13+H13+J13+L13+N13+P13 -> 13 | S13: =R13/E13 -> 0.0065065065
B14: 文学部 | C14: 1512 | D14: 360 | E14: 1482 | F14: 1 | G14: 0 | H14: 0 | I14: 0 | J14: 0 | K14: 0 | L14: 0 | M14: 0 | N14: 0 | O14: 0 | P14: 0 | Q14: 0 | R14: =F14+H14+J14+L14+N14+P14 -> 1 | S14: =R14/E14 -> 0.00067476383
B15: 社会情報学部 | C15: 1259 | D15: 300 | E15: 1230 | F15: 87 | G15: 78 | H15: 0 | I15: 0 | J15: 0 | K15: 0 | L15: 0 | M15: 0 | N15: 0 | O15: 0 | P15: 0 | Q15: 0 | R15: =F15+H15+J15+L15+N15+P15 -> 87 | S15: =R15/E15 -> 0.070731707
B16: 人間関係学部 | C16: 1111 | D16: 260 | E16: 1060 | F16: 19 | G16: 16 | H16: 0 | I16: 0 | J16: 0 | K16: 0 | L16: 0 | M16: 0 | N16: 0 | O16: 0 | P16: 0 | Q16: 0 | R16: =F16+H16+J16+L16+N16+P16 -> 19 | S16: =R16/E16 -> 0.017924528
B17: 比較文化学部 | C17: 696 | D17: 165 | E17: 670 | F17: 12 | G17: 11 | H17: 0 | I17: 0 | J17: 0 | K17: 0 | L17: 0 | M17: 0 | N17: 0 | O17: 0 | P17: 0 | Q17: 0 | R17: =F17+H17+J17+L17+N17+P17 -> 12 | S17: =R17/E17 -> 0.017910448
R18: =F18+H18+J18+L18+N18+P18 -> 0 | S18: =R18/E18 -> #DIV/0!
R19: =F19+H19+J19+L19+N19+P19 -> 0 | S19: =R19/E19 -> #DIV/0!
R20: =F20+H20+J20+L20+N20+P20 -> 0 | S20: =R20/E20 -> #DIV/0!
R21: =F21+H21+J21+L21+N21+P21 -> 0 | S21: =R21/E21 -> #DIV/0!
R22: =F22+H22+J22+L22+N22+P22 -> 0 | S22: =R22/E22 -> #DIV/0!
R23: =F23+H23+J23+L23+N23+P23 -> 0 | S23: =R23/E23 -> #DIV/0!
R24: =F24+H24+J24+L24+N24+P24 -> 0 | S24: =R24/E24 -> #DIV/0!
R25: =F25+H25+J25+L25+N25+P25 -> 0 | S25: =R25/E25 -> #DIV/0!
R26: =F26+H26+J26+L26+N26+P26 -> 0 | S26: =R26/E26 -> #DIV/0!
R27: =F27+H27+J27+L27+N27+P27 -> 0 | S27: =R27/E27 -> #DIV/0!
R28: =F28+H28+J28+L28+N28+P28 -> 0 | S28: =R28/E28 -> #DIV/0!
R29: =F29+H29+J29+L29+N29+P29 -> 0 | S29: =R29/E29 -> #DIV/0!
... R32: =F32+H32+J32+L32+N32+P32 -> 0 | S32: =R32/E32 -> #DIV/0!
B33: 合 計 | C33: =SUM(C13:C32) -> 6650 | D33: =SUM(D13:D32) -> 1575 | E33: =SUM(E13:E32) -> 6440 | F33: =SUM(F13:F32) -> 132 | G33: =SUM(G13:G32) -> 113 | H33: =SUM(H13:H32) -> 0 | I33: =SUM(I13:I32) -> 0 | J33: =SUM(J13:J32) -> 0 | ... R33: =SUM(R13:R32) -> 132 | S33: =R33/E33 -> 0.020496894

Sheet 様式３ 教育の質・履修者数を向上させるための体制・計画
I1: 様式３
G2: 大学等名 | H2: ='様式１-１ プログラムを構成する授業科目'!C2 -> 大妻女子大学
A4: 教育の質・履修者数を向上させるための体制・計画について
A6: ① | B6: 全学の教員数 | C6: (常勤） | E6: 239 | F6: 人 | G6: （非常勤） | H6: 499 | I6: 人
A8: ② | B8: プログラムの授業を教えている教員数 | H8: 23 | I8: 人
A10: ③ | B10: プログラムの運営責任者
B11: （責任者名） | C11: 山倉 健嗣 | G11: （役職名） | H11: 副学長（教育担当）
A13: ④ | B13: プログラムを改善・進化させるための体制（委員会・組織等）
B14: 情報リテラシー教育検討部会
B16: （責任者名） | C16: 山倉 健嗣 | G16: （役職名） | H16: 部会長
A18: ⑤ | B18: プログラムを改善・進化させるための体制を定める規則名称
B19: 情報リテラシー教育検討部会内規
A21: ⑥ | B21: 体制の目的
B22: 部会は、大妻女子大学全学共通科目調整委員会（以下「調整委員会」という。）の運営方針に基づき、次の各号に掲げる事項に関する業務を行う。 (1) 全学共通科目の基礎科目区分Ⅱリテラシーのうち、情報リテラシー科目の企画・運営・人事等に関する事項 (2) 大妻データサイエンス・ＡIプログラムの自己点検・評価および改善に関する事項 (3) 部会内規の改廃に関する事項 (4) その他、調整委員会委員長からの依頼事項
K26: =LEN(B22) -> 204
A34: ⑦ | B34: 具体的な構成員
B35: 部会は、次の各号に掲げる委員をもって組織する。 (1) 調整委員会委員長の指名する専任教員 若干名 ・山倉 健嗣 全学共通科目調整委員会委員長・副学長（教育担当）／部会長 ・市川 博 家政学部ライフデザイン学科教授 ・小野 茂 社会情報学部社会情報学科教授 ・八城 薫 人間関係学部人間関係学科教授 ・豊田 雄彦 短期大学部家政科教授 (2) 安倍 達哉 教育支援センター部長 (3) 西田 裕貴 教育支援グループ課長 (4) 桝渕 富士子 メディア教育開発グループ課長 (5) その他部会長の推薦する者 若干名 R5は推薦者なし。
K39: =LEN(B35) -> 273
A48: ⑧ | B48: 履修者数・履修率の向上に向けた計画 ※様式１の「履修必須の有無」で「計画がある」としている場合は詳細について記載すること
B49: 令和５年度実績 | C49: ='様式２ 履修者等数の実績'!S33 -> 0.020496894 | E49: 令和６年度予定 | F49: 0.023 | H49: 令和７年度予定 | I49: 0.031
B50: 令和８年度予定 | C50: 0.038 | E50: 令和９年度予定 | F50: 0.046 | H50: 収容定員（名） | I50: ='様式２ 履修者等数の実績'!E33 -> 6440
B51: 具体的な計画
B52: プログラムの科目はすべて配当年次が1年次のため、入学前に配付する冊子『新入生案内』に大妻データサイエンス・ＡＩプログラムの案内を掲載するとともに、4月の履修登録時に行われるクラス別ガイダンスにおいても、クラス指導主任から『履修登録の手引き』を通して、このプログラムを履修することの利点を説明している。また、プログラム修了者アンケートの結果は、HPで公表し、プログラム履修への意欲向上を図っている。 さらに本プログラムの修了者には修了証をオープンバッジで発行し、学習歴のデジタル化にも対応している。その他、プログラムに関係する科目のうち、共通科目である「データサイエンス・AI概論」は、後期のオンデマンド科目として配置することで、前期履修登録の結果、上限人数に満たないコマについては後期履修登録の機会を設けることを可能としている。
K57: =LEN(B52) -> 365
A65: ⑨ | B65: 学部・学科に関係なく希望する学生全員が受講可能となるような必要な体制・取組等
B66: 本プログラムの科目は、家政学部、文学部、人間関係学部、比較文化学部は全学共通科目２科目（「データサイエンス・ＡＩ概論」「コンピュータ基礎Ｂ」）で構成している。社会情報学部社会情報学科社会生活情報学専攻、環境情報学専攻は全学共通科目「データサイエンス・ＡＩ概論」、専門教育科目の必修科目「情報処理実習Ｂ」の２科目で構成されており、社会情報学科情報デザイン専攻は全学共通科目「データサイエンス・ＡＩ概論」、専門教育科目の必修科目「情報処理実習A」の２科目で構成されている。このとおり、希望する学生全員が受講可能となっている。 また、プログラムを進化・改善する組織である情報リテラシー教育検討部会は、全学共通科目の教育課程の運営・管理を所掌している全学共通科目調整委員会の部会に位置付けられており、各学部教授会には当該委員会委員を通じて情報共有が行われており、全学的な連携体制が整っている。
K69: =LEN(B66) -> 392
A79: ⑩ | B79: できる限り多くの学生が履修できるような具体的な周知方法・取組
B80: できる限り多くの学生が履修できるよう、次のような取り組みを行っている。 ・新入生発送資料やガイダンス配付資料を活用し周知するとともに、1年次全員にポータルサイト（UNIPA）から周知をしている。 ・ホームページに特設ページを設け、学修成果や後輩等他の学生への推奨度を確認するアンケートなどの結果を積極的に公開している。 ・プログラムの共通科目である「データサイエンス・ＡＩ概論」は、複数学部の教員が担当することで特定の学部に偏らない内容になるよう工夫している。 ・前期教務委員会において、後期履修登録、他キャンパス履修、単位互換の日時や手続き方法を教職員で共有しており、上限に達していないプログラム科目について追加登録をするよう促している。
K86: =LEN(B80) -> 320
A93: ⑪ | B93: できる限り多くの学生が履修・修得できるようなサポート体制
B94: できる限り多くの学生が履修・修得できるように次のようなサポート体制をとっている。 ・プログラムの共通科目である「データサイエンス・ＡＩ概論」は、オンデマンド授業で実施しており、学生の理解度によって、繰り返し視聴可能としている。 ・「データサイエンス・ＡＩ概論」は複数学部の教員が担当することで、多様な学生からの質問にも柔軟な対応が可能となっている。 ・プログラム上、パソコンを使用する演習科目「コンピュータ基礎Ｂ」「情報処理実習Ａ」「情報処理実習Ｂ」は、「データサイエンス・ＡＩ概論」と異なり、対面形式で実施し、パソコンの習熟度によって担当教員やＴＡがサポートする体制を整えている。 ・PCの利用やネットワーク接続等に関する質問については、専門部署が学生対応をしている。 ・学内全域で無線LANを整備し、BYODに対応している。
K100: =LEN(B94) -> 364
A107: ⑫ | B107: 授業時間内外で学習指導、質問を受け付ける具体的な仕組み
B108: 授業時間内外で学習指導、質問を受け付ける仕組みとして、次のようなものを設けている。 ・プログラムを構成する科目を担当する専任教員は、オフィスアワーを活用し、学習指導や質問を受け付けている。 ・その他、manaba（学修支援システム）のスレッド機能を活用し、いつでも質問を受け付ける仕組みを設けており、他の学生が質問した内容とその答えをすべての履修者が閲覧可能な状態としている。
K113: =LEN(B108) -> 188

Sheet 様式４　自己点検・評価
I1: 様式４
H2: 大学等名 | I2: ='様式１-１ プログラムを構成する授業科目'!C2 -> 大妻女子大学
A3: 自己点検・評価について
A5: ① | B5: プログラムの自己点検・評価を行う体制（委員会・組織等）
B6: 情報リテラシー教育検討部会
D8: （責任者名） | E8: 山倉 健嗣 | G8: （役職名） | H8: 部会長
A10: ② | B10: 自己点検・評価体制における意見等
B11: 自己点検・評価の視点 | E11: 自己点検・評価体制における意見・結果・改善に向けた取組等
B12: 学内からの視点
C13: プログラムの履修・修得状況 | E13: 情報リテラシー教育検討部会は、大妻データサイエンス・AIプログラムの履修・修得状況を調査の上、プログラムに関する自己点検・評価報告書に掲載し公表する。 | K13: =LEN(E13) -> 75
C14: 学修成果 | E14: 情報リテラシー教育検討部会は、当該部会が実施する「大妻データサイエンス・AIプログラム修了者アンケート」において、プログラムを構成する科目の到達目標に達したか確認し、自己点検・評価報告書に掲載し公表する。また、大妻データサイエンス・AIプログラムの共通科目である「データサイエンス・AI概論」の成績分布を調査し、本教育プログラムの評価・改善に活用している。 | K14: =LEN(E14) -> 178
C15: 学生アンケート等を通じた学生の内容の理解度 | E15: 学生の内容の理解度については、大学が組織的に実施している「授業改善のためのアンケート」にある設問９「この授業によって、新しい知識・技能・ものの見方や考え方を習得できましたか」、設問10「あなたは授業に満足しましたか」において確認し、本教育プログラムの評価・改善に活用している。その結果は、情報リテラシー教育検討部会でも情報共有されるとともに、自己点検・評価報告書に記載し公表する。 | K15: =LEN(E15) -> 190
C16: 学生アンケート等を通じた後輩等他の学生への推奨度 | E16: 後輩等他の学生への推奨度は、情報リテラシー教育検討部会が実施する「大妻データサイエンス・AIプログラム修了者アンケート」において、「友だちや後輩に受講を検討している人がいたら、プログラムをお勧めすることができますか」という設問を設け確認し、本教育プログラムの評価・改善に活用している。その他、同アンケートでは「プログラムについての感想や、改善してほしい点等があれば記入してください」という自由記述設問も設け、学生視点の改善点も確認している。 なお、これらの結果については、本学ホームページで公表するとともに、自己点検・評価報告書にも記載する。 | K16: =LEN(E16) -> 271
C17: 全学的な履修者数、履修率向上に向けた計画の達成・進捗状況 | E17: 全学的な履修者数、履修率については、毎年情報リテラシー教育検討部会において共有し、現在行っている計画の効果を点検する。また、履修希望者の経年変化を踏まえ、希望者数が計画通り増加した場合は、他の情報リテラシー科目の開講コマ数と調整の上、増コマすることを全学共通科目調整委員会（全学共通科目のコマ数を審議する委員会）に提案する。 なお、本プログラムは令和５年度入学生から履修可能となったプログラムであり、令和５年度は１年生のみが対象だった。令和６年度以降は、対象者が１学年ずつ増えるため、履修者や修了者も増えていくことが見込まれる。 | K17: =LEN(E17) -> 264
B18: 学外からの視点 | K18: =LEN(E18) -> 0
C19: 教育プログラム修了者の進路、活躍状況、企業等の評価 | E19: 本プログラムは令和５年度入学生から履修可能となったプログラムのため、初年度修了者の卒業は令和8年度末になる。そのため、令和9年度以降に修了者の進路、活躍状況等を確認していくこととなる。 | K19: =LEN(E19) -> 92
C20: 産業界からの視点を含めた教育プログラム内容・手法等への意見 | E20: 本学が提携や協力をお願いしている企業等産業界から、教育プログラムの内容や手法等への意見を聴取する機会を年に１回設けている。その意見は整理した上で自己点検・評価報告書に記載し公表する。 | K20: =LEN(E20) -> 91
B21: 数理・データサイエンス・ＡＩを「学ぶ楽しさ」「学ぶことの意義」を理解させること | E21: プログラムの共通科目である「データサイエンス・ＡＩ概論」では、授業のガイダンスとして、初回授業の前にプレ授業を設け、「学ぶことの楽しさ」「学ぶことの意義」を説明している。 また、複数学部の教員がオムニバスで担当することにより、学生自身の今後の学修と関係のある内容も含めることでデータサイエンスやAIについて「学ぶことの意義」を伝える工夫をしている。 さらに担当教員がシラバスを執筆する際に参考とする『授業概要』では、データサイエンス・AIを活用することの「楽しさ」や「学ぶことの意義」に重きを置くことを記した。 | K21: =LEN(E21) -> 255
B22: 内容・水準を維持・向上しつつ、より「分かりやすい」授業とすること ※社会の変化や生成AI等の技術の発展を踏まえて教育内容を継続的に見直すなど、より教育効果の高まる授業内容・方法とするための取組や仕組みについても該当があれば記載 | E22: 本学では、情報リテラシー教育検討部会において、各種アンケート調査、成績分布などを参考に自己点検・評価を行うとともに、データサイエンス分野に関する協定を締結した企業との意見交換を年に１回行い、社会の変化や生成AI等の技術の発展を踏まえた教育内容の見直しを行っている。 | K22: =LEN(E22) -> 132
