Workbook

Sheet 様式１-１　プログラムを構成する授業科目
T1: 様式１－１ | V1: 「学部・学科によって、修了要件は相違する」場合は、本シートを複製の上＜様式１－〇＞と枝番号を付してください
B2: 大学等名 | C2: 徳島文理大学
B3: プログラム名 | C3: 徳島文理大学 数理・データサイエンス・ＡＩリテラシープログラム
A5: プログラムを構成する授業科目について
A7: ① 教育プログラムの修了要件 | L7: 学部・学科によって、修了要件は相違する
A9: ② 対象となる学部・学科名称
B11: 人間生活学部、音楽学部、総合政策学部、保健福祉学部（看護学科以外）、文学部、理工学部
A14: ③ 修了要件
B15: 「文理学」2単位と「情報処理」2単位の計2科目、4単位を取得すること。 | X15: 【プルダウンリスト】
X16: 令和５年度以前より、履修することが必須のプログラムとして実施
X17: 令和８年度までに履修必須とする計画
X18: 令和９年度以降に履修必須とする計画、又は未定
B22: 必要最低科目数・単位数 | E22: 2 | F22: 科目 | H22: 4 | I22: 単位 | M22: 履修必須の有無 | N22: 令和９年度以降に履修必須とする計画、又は未定
A24: ④ 現在進行中の社会変化（第４次産業革命、Society 5.0、データ駆動型社会等）に深く寄与しているものであり、それが自らの生活と密接に結びついている」の内容を含む授業科目
B26: 授業科目 | G26: 単位数 | H26: 必須 | I26: 1-1 | J26: 1-6 | K26: 授業科目 | R26: 単位数 | S26: 必須 | T26: 1-1 | U26: 1-6
B27: 文理学 | G27: 2 | H27: ○ | I27: ○ | J27: ○
A35: ⑤ 「社会で活用されているデータ」や「データの活用領域」は非常に広範囲であって、日常生活や社会の課題を解決する有用なツールになり得るもの」の内容を含む授業科目
B37: 授業科目 | G37: 単位数 | H37: 必須 | I37: 1-2 | J37: 1-3 | K37: 授業科目 | R37: 単位数 | S37: 必須 | T37: 1-2 | U37: 1-3
B38: 文理学 | G38: 2 | H38: ○ | I38: ○ | J38: ○
A46: ⑥ 「様々なデータ利活用の現場におけるデータ利活用事例が示され、様々な適用領域（流通、製造、金融、サービス、インフラ、公共、ヘルスケア等）の知見と組み合わせることで価値を創出するもの」の内容を含む授業科目
B48: 授業科目 | G48: 単位数 | H48: 必須 | I48: 1-4 | J48: 1-5 | K48: 授業科目 | R48: 単位数 | S48: 必須 | T48: 1-4 | U48: 1-5
B49: 文理学 | G49: 2 | H49: ○ | I49: ○ | J49: ○
A57: ⑦ 「活用に当たっての様々な留意事項（ELSI、個人情報、データ倫理、ＡＩ社会原則等）を考慮し、情報セキュリティや情報漏洩等、データを守る上での留意事項への理解をする」の内容を含む授業科目
B59: 授業科目 | G59: 単位数 | H59: 必須 | I59: 3-1 | J59: 3-2 | K59: 授業科目 | R59: 単位数 | S59: 必須 | T59: 3-1 | U59: 3-2
B60: 文理学 | G60: 2 | H60: ○ | I60: ○ | J60: ○
A68: ⑧ 「実データ・実課題（学術データ等を含む）を用いた演習など、社会での実例を題材として、「データを読む、説明する、扱う」といった数理・データサイエンス・ＡＩの基本的な活用法に関するもの」の内容を含む授業科目
B70: 授業科目 | F70: 単位数 | G70: 必須 | H70: 2-1 | I70: 2-2 | J70: 2-3 | K70: 授業科目 | Q70: 単位数 | R70: 必須 | S70: 2-1 | T70: 2-2 | U70: 2-3
B71: 文理学 | F71: 2 | G71: ○ | H71: ○
B72: 情報処理 | F72: 2 | G72: ○ | H72: ○ | I72: ○ | J72: ○
A79: ⑨ 選択「４．オプション」の内容を含む授業科目
B80: 授業科目 | G80: 選択項目 | K80: 授業科目 | R80: 選択項目
A89: ⑩ プログラムを構成する授業の内容
B90: 授業に含まれている内容・要素 | D90: 講義内容
B91: （１）現在進行中の社会変化（第４次産業革命、Society 5.0、データ駆動型社会等）に深く寄与しているものであり、それが自らの生活と密接に結びついている | C91: 1-1 | D91: ・ビッグデータ、IoT、AI、ロボット 「文理学『数理・データサイエンスＡＩ入門』｣（1回目～4回目） ・データ量の増加、計算機の処理性能の向上、AIの非連続的進化 「文理学『数理・データサイエンスＡＩ入門』｣（1回目、4回目、5回目） ・第4次産業革命、Society 5.0、データ駆動型社会 「文理学『数理・データサイエンスＡＩ入門』｣（1回目、5回目） ・複数技術を組み合わせたAIサービス 「文理学『数理・データサイエンスＡＩ入門』｣（4回目、5回目） ・人間の知的活動とAIの関係性 「文理学『数理・データサイエンスＡＩ入門』｣（2回目、4回目） ・データを起点としたものの見方、人間の知的活動を起点としたものの見方 「文理学『数理・データサイエンスＡＩ入門』｣（1回目、5回目）
C92: 1-6 | D92: ・AI等を活用した新しいビジネスモデル(シェアリングエコノミー、商品のレコメンデーションなど) 「文理学『数理・データサイエンスＡＩ入門』｣（6回目） ・AI最新技術の活用例（深層生成モデル、敵対的生成ネットワーク、強化学習、転移学習など） 「文理学『数理・データサイエンスＡＩ入門』｣（5回目、 6回目）
B93: （２）「社会で活用されているデータ」や「データの活用領域」は非常に広範囲であって、日常生活や社会の課題を解決する有用なツールになり得るもの | C93: 1-2 | D93: ・調査データ、実験データ、人の行動ログデータ、機械の稼働ログデータなど 「文理学『数理・データサイエンスＡＩ入門』｣（3回目） ・1次データ、2次データ、データのメタ化 「文理学『数理・データサイエンスＡＩ入門』｣（3回目、5回目） ・構造化データ、非構造化データ（文章、画像/動画、音声/音楽など） 「文理学『数理・データサイエンスＡＩ入門』｣（3回目、5回目） ・データ作成（ビッグデータとアノテーション） 「文理学『数理・データサイエンスＡＩ入門』｣（3回目） ・データのオープン化（オープンデータ） 「文理学｢数理・データサイエンスＡＩ入門』｣（5回目）
C94: 1-3 | D94: ・データ・AI活用領域の広がり(生産、消費、文化活動など) 「文理学『数理・データサイエンスＡＩ入門』｣（4回目、5回目） ・研究開発、調達、製造、物流、販売、マーケティング、サービスなど 「文理学『数理・データサイエンスＡＩ入門』｣（3回目、4回目） ・仮説検証、知識発見、原因究明、計画策定、判断支援、活動代替、新規生成など 「文理学『数理・データサイエンスＡＩ入門』｣（3回目、4回目）
B95: （３）様々なデータ利活用の現場におけるデータ利活用事例が示され、様々な適用領域（流通、製造、金融、サービス、インフラ、公共、ヘルスケア等）の知見と組み合わせることで価値を創出するもの | C95: 1-4 | D95: ・データ解析：予測、グルーピング、パターン発見、最適化、シミュレーション・データ同化など 「文理学『数理・データサイエンスＡＩ入門』｣（5回目、 6回目） ・データ可視化：複合グラフ、2軸グラフ、多次元の可視化、関係性の可視化、地図上の可視化、挙動・軌跡の可視化、リアルタイム可視化など 「文理学『｢数理・データサイエンスＡＩ入門』｣（6回目） ・非構造化データ処理：言語処理、画像/動画処理、音声/音楽処理など 「文理学『数理・データサイエンスＡＩ入門』｣（5回目） ・特化型AIと汎用AI、今のAIで出来ることと出来ないこと、AIとビッグデータ 「文理学『数理・データサイエンスＡＩ入門』｣（4回目～6回目） ・認識技術、ルールベース、自動化技術 「文理学『数理・データサイエンスＡＩ入門』｣（5回目）
C96: 1-5 | D96: ・データサイエンスのサイクル（課題抽出と定式化、データの取得・管理・加工、探索的データ解析、データ解析と推論、結果の共有・伝達、課題解決 に向けた提案） 「文理学『数理・データサイエンスＡＩ入門』｣（6回目） ・流通、製造、金融、サービス、インフラ、公共、ヘルスケア等におけるデータ・AI利活用事例紹介 「文理学『数理・データサイエンスＡＩ入門』｣ （3回目～6回目）
B97: （４）活用に当たっての様々な留意事項（ELSI、個人情報、データ倫理、ＡＩ社会原則等）を考慮し、情報セキュリティや情報漏洩等、データを守る上での留意事項への理解をする | C97: 3-1 | D97: ・ELSI（Ethical, Legal and Social Issues） 「文理学『数理・データサイエンスＡＩ入門』｣（2回目、5回目）、「情報処理」（2回目） ・個人情報保護、EU一般データ保護規則(GDPR)、忘れられる権利、オプトアウト 「文理学『数理・データサイエンスＡＩ入門』｣（2回目、5回目）、 「情報処理」 （11回目） ・データ倫理：データのねつ造、改ざん、盗用、プライバシー保護 「文理学『数理・データサイエンスＡＩ入門』｣（2回目、4回目） ・AI社会原則（公平性、説明責任、透明性、人間中心の判断） 「文理学『数理・データサイエンスＡＩ入門』｣（2回目） ・データバイアス、アルゴリズムバイアス 「文理学『数理・データサイエンスＡＩ入門』｣（2回目） ・AIサービスの責任論 「文理学『数理・データサイエンスＡＩ入門』｣（4回目、5回目） ・データ・AI活用における負の事例紹介 「文理学『数理・データサイエンスＡＩ入門』｣（4回目、5回目）
...

Sheet 様式１-２　プログラムを構成する授業科目
T1: 様式１－２ | V1: 「学部・学科によって、修了要件は相違する」場合は、本シートを複製の上＜様式１－〇＞と枝番号を付してください
B2: 大学等名 | C2: 徳島文理大学
B3: プログラム名 | C3: 徳島文理大学 数理・データサイエンス・ＡＩリテラシープログラム
A5: プログラムを構成する授業科目について
A7: ① 教育プログラムの修了要件 | L7: 学部・学科によって、修了要件は相違する
A9: ② 対象となる学部・学科名称
B11: 薬学部、香川薬学部
A14: ③ 修了要件
B15: 「文理学」2単位と「基礎薬学情報処理」1.5単位の計2科目、3.5単位を取得すること。 | X15: 【プルダウンリスト】
X16: 令和５年度以前より、履修することが必須のプログラムとして実施
X17: 令和８年度までに履修必須とする計画
X18: 令和９年度以降に履修必須とする計画、又は未定
B22: 必要最低科目数・単位数 | E22: 2 | F22: 科目 | H22: 3.5 | I22: 単位 | M22: 履修必須の有無 | N22: 令和９年度以降に履修必須とする計画、又は未定
A24: ④ 現在進行中の社会変化（第４次産業革命、Society 5.0、データ駆動型社会等）に深く寄与しているものであり、それが自らの生活と密接に結びついている」の内容を含む授業科目
B26: 授業科目 | G26: 単位数 | H26: 必須 | I26: 1-1 | J26: 1-6 | K26: 授業科目 | R26: 単位数 | S26: 必須 | T26: 1-1 | U26: 1-6
B27: 文理学 | G27: 2 | H27: ○ | I27: ○ | J27: ○
A35: ⑤ 「社会で活用されているデータ」や「データの活用領域」は非常に広範囲であって、日常生活や社会の課題を解決する有用なツールになり得るもの」の内容を含む授業科目
B37: 授業科目 | G37: 単位数 | H37: 必須 | I37: 1-2 | J37: 1-3 | K37: 授業科目 | R37: 単位数 | S37: 必須 | T37: 1-2 | U37: 1-3
B38: 文理学 | G38: 2 | H38: ○ | I38: ○ | J38: ○
A46: ⑥ 「様々なデータ利活用の現場におけるデータ利活用事例が示され、様々な適用領域（流通、製造、金融、サービス、インフラ、公共、ヘルスケア等）の知見と組み合わせることで価値を創出するもの」の内容を含む授業科目
B48: 授業科目 | G48: 単位数 | H48: 必須 | I48: 1-4 | J48: 1-5 | K48: 授業科目 | R48: 単位数 | S48: 必須 | T48: 1-4 | U48: 1-5
B49: 文理学 | G49: 2 | H49: ○ | I49: ○ | J49: ○
A57: ⑦ 「活用に当たっての様々な留意事項（ELSI、個人情報、データ倫理、ＡＩ社会原則等）を考慮し、情報セキュリティや情報漏洩等、データを守る上での留意事項への理解をする」の内容を含む授業科目
B59: 授業科目 | G59: 単位数 | H59: 必須 | I59: 3-1 | J59: 3-2 | K59: 授業科目 | R59: 単位数 | S59: 必須 | T59: 3-1 | U59: 3-2
B60: 文理学 | G60: 2 | H60: ○ | I60: ○ | J60: ○
A68: ⑧ 「実データ・実課題（学術データ等を含む）を用いた演習など、社会での実例を題材として、「データを読む、説明する、扱う」といった数理・データサイエンス・ＡＩの基本的な活用法に関するもの」の内容を含む授業科目
B70: 授業科目 | F70: 単位数 | G70: 必須 | H70: 2-1 | I70: 2-2 | J70: 2-3 | K70: 授業科目 | Q70: 単位数 | R70: 必須 | S70: 2-1 | T70: 2-2 | U70: 2-3
B71: 文理学 | F71: 2 | G71: ○ | H71: ○
B72: 基礎薬学情報処理 | F72: 1.5 | G72: ○ | H72: ○ | I72: ○ | J72: ○
A79: ⑨ 選択「４．オプション」の内容を含む授業科目
B80: 授業科目 | G80: 選択項目 | K80: 授業科目 | R80: 選択項目
A89: ⑩ プログラムを構成する授業の内容
B90: 授業に含まれている内容・要素 | D90: 講義内容
B91: （１）現在進行中の社会変化（第４次産業革命、Society 5.0、データ駆動型社会等）に深く寄与しているものであり、それが自らの生活と密接に結びついている | C91: 1-1 | D91: ・ビッグデータ、IoT、AI、ロボット 「文理学『数理・データサイエンスＡＩ入門』｣（1回目～4回目） ・データ量の増加、計算機の処理性能の向上、AIの非連続的進化 「文理学『数理・データサイエンスＡＩ入門』｣（1回目、4回目、5回目） ・第4次産業革命、Society 5.0、データ駆動型社会 「文理学『数理・データサイエンスＡＩ入門』｣（1回目、5回目） ・複数技術を組み合わせたAIサービス 「文理学『数理・データサイエンスＡＩ入門』｣（4回目、5回目） ・人間の知的活動とAIの関係性 「文理学『数理・データサイエンスＡＩ入門』｣（2回目、4回目） ・データを起点としたものの見方、人間の知的活動を起点としたものの見方 「文理学『数理・データサイエンスＡＩ入門』｣（1回目、5回目）
C92: 1-6 | D92: ・AI等を活用した新しいビジネスモデル(シェアリングエコノミー、商品のレコメンデーションなど) 「文理学『数理・データサイエンスＡＩ入門』｣（6回目） ・AI最新技術の活用例（深層生成モデル、敵対的生成ネットワーク、強化学習、転移学習など） 「文理学『数理・データサイエンスＡＩ入門』｣（5回目、 6回目）
B93: （２）「社会で活用されているデータ」や「データの活用領域」は非常に広範囲であって、日常生活や社会の課題を解決する有用なツールになり得るもの | C93: 1-2 | D93: ・調査データ、実験データ、人の行動ログデータ、機械の稼働ログデータなど 「文理学『数理・データサイエンスＡＩ入門』｣（3回目） ・1次データ、2次データ、データのメタ化 「文理学『数理・データサイエンスＡＩ入門』｣（3回目、5回目） ・構造化データ、非構造化データ（文章、画像/動画、音声/音楽など） 「文理学『数理・データサイエンスＡＩ入門』｣（3回目、5回目） ・データ作成（ビッグデータとアノテーション） 「文理学『数理・データサイエンスＡＩ入門』｣（3回目） ・データのオープン化（オープンデータ） 「文理学｢数理・データサイエンスＡＩ入門』｣（5回目）
C94: 1-3 | D94: ・データ・AI活用領域の広がり(生産、消費、文化活動など) 「文理学『数理・データサイエンスＡＩ入門』｣（4回目、5回目） ・研究開発、調達、製造、物流、販売、マーケティング、サービスなど 「文理学『数理・データサイエンスＡＩ入門』｣（3回目） ・仮説検証、知識発見、原因究明、計画策定、判断支援、活動代替、新規生成など 「文理学『数理・データサイエンスＡＩ入門』｣（3回目、4回目）
B95: （３）様々なデータ利活用の現場におけるデータ利活用事例が示され、様々な適用領域（流通、製造、金融、サービス、インフラ、公共、ヘルスケア等）の知見と組み合わせることで価値を創出するもの | C95: 1-4 | D95: ・データ解析：予測、グルーピング、パターン発見、最適化、シミュレーション・データ同化など 「文理学『数理・データサイエンスＡＩ入門』｣（5回目、 6回目） ・データ可視化：複合グラフ、2軸グラフ、多次元の可視化、関係性の可視化、地図上の可視化、挙動・軌跡の可視化、リアルタイム可視化など 「文理学『｢数理・データサイエンスＡＩ入門』｣（6回目） ・非構造化データ処理：言語処理、画像/動画処理、音声/音楽処理など 「文理学『数理・データサイエンスＡＩ入門』｣（5回目） ・特化型AIと汎用AI、今のAIで出来ることと出来ないこと、AIとビッグデータ 「文理学『数理・データサイエンスＡＩ入門』｣（4回目～6回目） ・認識技術、ルールベース、自動化技術 「文理学『数理・データサイエンスＡＩ入門』｣（5回目）
C96: 1-5 | D96: ・データサイエンスのサイクル（課題抽出と定式化、データの取得・管理・加工、探索的データ解析、データ解析と推論、結果の共有・伝達、課題解決 に向けた提案） 「文理学『数理・データサイエンスＡＩ入門』｣（6回目） ・流通、製造、金融、サービス、インフラ、公共、ヘルスケア等におけるデータ・AI利活用事例紹介 「文理学『数理・データサイエンスＡＩ入門』｣ （3回目～4回目）
B97: （４）活用に当たっての様々な留意事項（ELSI、個人情報、データ倫理、ＡＩ社会原則等）を考慮し、情報セキュリティや情報漏洩等、データを守る上での留意事項への理解をする | C97: 3-1 | D97: ・ELSI（Ethical, Legal and Social Issues） 「文理学『数理・データサイエンスＡＩ入門』｣（2回目、5回目） 「基礎薬学情報処理」（1回目、6回目） ・個人情報保護、EU一般データ保護規則(GDPR)、忘れられる権利、オプトアウト 「文理学『数理・データサイエンスＡＩ入門』｣（2回目、5回目） ・データ倫理：データのねつ造、改ざん、盗用、プライバシー保護 「文理学『数理・データサイエンスＡＩ入門』｣（2回目） ・AI社会原則（公平性、説明責任、透明性、人間中心の判断） 「文理学『数理・データサイエンスＡＩ入門』｣（2回目、4回目） 「基礎薬学情報処理」 （1回目） ・データバイアス、アルゴリズムバイアス 「文理学『数理・データサイエンスＡＩ入門』｣（2回目） 「基礎薬学情報処理」（6回目） ・AIサービスの責任論 「文理学『数理・データサイエンスＡＩ入門』｣（4回目、5回目） ・データ・AI活用における負の事例紹介 「文理学『数理・データサイエンスＡＩ入門』｣（4回目、5回目）
...

Sheet 様式１-3　プログラムを構成する授業科目
T1: 様式１－３ | V1: 「学部・学科によって、修了要件は相違する」場合は、本シートを複製の上＜様式１－〇＞と枝番号を付してください
B2: 大学等名 | C2: 徳島文理大学
B3: プログラム名 | C3: 徳島文理大学 数理・データサイエンス・ＡＩリテラシープログラム
A5: プログラムを構成する授業科目について
A7: ① 教育プログラムの修了要件 | L7: 学部・学科によって、修了要件は相違する
A9: ② 対象となる学部・学科名称
B11: 保健福祉学部看護学科
A14: ③ 修了要件
B15: 「文理学」2単位と「情報処理・統計学」2単位の計2科目、4単位を取得すること。 | X15: 【プルダウンリスト】
X16: 令和５年度以前より、履修することが必須のプログラムとして実施
X17: 令和８年度までに履修必須とする計画
X18: 令和９年度以降に履修必須とする計画、又は未定
B22: 必要最低科目数・単位数 | E22: 2 | F22: 科目 | H22: 4 | I22: 単位 | M22: 履修必須の有無 | N22: 令和９年度以降に履修必須とする計画、又は未定
A24: ④ 現在進行中の社会変化（第４次産業革命、Society 5.0、データ駆動型社会等）に深く寄与しているものであり、それが自らの生活と密接に結びついている」の内容を含む授業科目
B26: 授業科目 | G26: 単位数 | H26: 必須 | I26: 1-1 | J26: 1-6 | K26: 授業科目 | R26: 単位数 | S26: 必須 | T26: 1-1 | U26: 1-6
B27: 文理学 | G27: 2 | H27: ○ | I27: ○ | J27: ○
A35: ⑤ 「社会で活用されているデータ」や「データの活用領域」は非常に広範囲であって、日常生活や社会の課題を解決する有用なツールになり得るもの」の内容を含む授業科目
B37: 授業科目 | G37: 単位数 | H37: 必須 | I37: 1-2 | J37: 1-3 | K37: 授業科目 | R37: 単位数 | S37: 必須 | T37: 1-2 | U37: 1-3
B38: 文理学 | G38: 2 | H38: ○ | I38: ○ | J38: ○
A46: ⑥ 「様々なデータ利活用の現場におけるデータ利活用事例が示され、様々な適用領域（流通、製造、金融、サービス、インフラ、公共、ヘルスケア等）の知見と組み合わせることで価値を創出するもの」の内容を含む授業科目
B48: 授業科目 | G48: 単位数 | H48: 必須 | I48: 1-4 | J48: 1-5 | K48: 授業科目 | R48: 単位数 | S48: 必須 | T48: 1-4 | U48: 1-5
B49: 文理学 | G49: 2 | H49: ○ | I49: ○ | J49: ○
A57: ⑦ 「活用に当たっての様々な留意事項（ELSI、個人情報、データ倫理、ＡＩ社会原則等）を考慮し、情報セキュリティや情報漏洩等、データを守る上での留意事項への理解をする」の内容を含む授業科目
B59: 授業科目 | G59: 単位数 | H59: 必須 | I59: 3-1 | J59: 3-2 | K59: 授業科目 | R59: 単位数 | S59: 必須 | T59: 3-1 | U59: 3-2
B60: 文理学 | G60: 2 | H60: ○ | I60: ○ | J60: ○
A68: ⑧ 「実データ・実課題（学術データ等を含む）を用いた演習など、社会での実例を題材として、「データを読む、説明する、扱う」といった数理・データサイエンス・ＡＩの基本的な活用法に関するもの」の内容を含む授業科目
B70: 授業科目 | F70: 単位数 | G70: 必須 | H70: 2-1 | I70: 2-2 | J70: 2-3 | K70: 授業科目 | Q70: 単位数 | R70: 必須 | S70: 2-1 | T70: 2-2 | U70: 2-3
B71: 文理学 | F71: 2 | G71: ○ | H71: ○
B72: 情報処理・統計学 | F72: 2 | G72: ○ | H72: ○ | I72: ○ | J72: ○
A79: ⑨ 選択「４．オプション」の内容を含む授業科目
B80: 授業科目 | G80: 選択項目 | K80: 授業科目 | R80: 選択項目
A89: ⑩ プログラムを構成する授業の内容
B90: 授業に含まれている内容・要素 | D90: 講義内容
B91: （１）現在進行中の社会変化（第４次産業革命、Society 5.0、データ駆動型社会等）に深く寄与しているものであり、それが自らの生活と密接に結びついている | C91: 1-1 | D91: ・ビッグデータ、IoT、AI、ロボット 「文理学『数理・データサイエンスＡＩ入門』｣（1回目～4回目） ・データ量の増加、計算機の処理性能の向上、AIの非連続的進化 「文理学『数理・データサイエンスＡＩ入門』｣（1回目、4回目、5回目） ・第4次産業革命、Society 5.0、データ駆動型社会 「文理学『数理・データサイエンスＡＩ入門』｣（1回目、5回目） ・複数技術を組み合わせたAIサービス 「文理学『数理・データサイエンスＡＩ入門』｣（4回目、5回目） ・人間の知的活動とAIの関係性 「文理学『数理・データサイエンスＡＩ入門』｣（2回目、4回目） ・データを起点としたものの見方、人間の知的活動を起点としたものの見方 「文理学『数理・データサイエンスＡＩ入門』｣（1回目、5回目）
C92: 1-6 | D92: ・AI等を活用した新しいビジネスモデル(シェアリングエコノミー、商品のレコメンデーションなど) 「文理学『数理・データサイエンスＡＩ入門』｣（6回目） ・AI最新技術の活用例（深層生成モデル、敵対的生成ネットワーク、強化学習、転移学習など） 「文理学『数理・データサイエンスＡＩ入門』｣ （5回目、6回目）
B93: （２）「社会で活用されているデータ」や「データの活用領域」は非常に広範囲であって、日常生活や社会の課題を解決する有用なツールになり得るもの | C93: 1-2 | D93: ・調査データ、実験データ、人の行動ログデータ、機械の稼働ログデータなど 「文理学『数理・データサイエンスＡＩ入門』｣（3回目） ・1次データ、2次データ、データのメタ化 「文理学『数理・データサイエンスＡＩ入門』｣（3回目、5回目） ・構造化データ、非構造化データ（文章、画像/動画、音声/音楽など） 「文理学『数理・データサイエンスＡＩ入門』｣（3回目、5回目） ・データ作成（ビッグデータとアノテーション） 「文理学『数理・データサイエンスＡＩ入門』｣（3回目） ・データのオープン化（オープンデータ） 「文理学｢数理・データサイエンスＡＩ入門』｣（5回目）
C94: 1-3 | D94: ・データ・AI活用領域の広がり(生産、消費、文化活動など) 「文理学『数理・データサイエンスＡＩ入門』｣（4回目、5回目） ・研究開発、調達、製造、物流、販売、マーケティング、サービスなど 「文理学『数理・データサイエンスＡＩ入門』｣（3回目） ・仮説検証、知識発見、原因究明、計画策定、判断支援、活動代替、新規生成など 「文理学『数理・データサイエンスＡＩ入門』｣（3回目、4回目）
B95: （３）様々なデータ利活用の現場におけるデータ利活用事例が示され、様々な適用領域（流通、製造、金融、サービス、インフラ、公共、ヘルスケア等）の知見と組み合わせることで価値を創出するもの | C95: 1-4 | D95: ・データ解析：予測、グルーピング、パターン発見、最適化、シミュレーション・データ同化など 「文理学『数理・データサイエンスＡＩ入門』｣（5回目、 6回目） ・データ可視化：複合グラフ、2軸グラフ、多次元の可視化、関係性の可視化、地図上の可視化、挙動・軌跡の可視化、リアルタイム可視化など 「文理学『｢数理・データサイエンスＡＩ入門』｣（6回目） ・非構造化データ処理：言語処理、画像/動画処理、音声/音楽処理など 「文理学『数理・データサイエンスＡＩ入門』｣（5回目） ・特化型AIと汎用AI、今のAIで出来ることと出来ないこと、AIとビッグデータ 「文理学『数理・データサイエンスＡＩ入門』｣（4回目～6回目） ・認識技術、ルールベース、自動化技術 「文理学『数理・データサイエンスＡＩ入門』｣（5回目）
C96: 1-5 | D96: ・データサイエンスのサイクル（課題抽出と定式化、データの取得・管理・加工、探索的データ解析、データ解析と推論、結果の共有・伝達、課題解決 に向けた提案） 「文理学『数理・データサイエンスＡＩ入門』｣（6回目） ・流通、製造、金融、サービス、インフラ、公共、ヘルスケア等におけるデータ・AI利活用事例紹介 「文理学『数理・データサイエンスＡＩ入門』｣ （3回目～6回目）
B97: （４）活用に当たっての様々な留意事項（ELSI、個人情報、データ倫理、ＡＩ社会原則等）を考慮し、情報セキュリティや情報漏洩等、データを守る上での留意事項への理解をする | C97: 3-1 | D97: ・ELSI（Ethical, Legal and Social Issues） 「文理学『数理・データサイエンスＡＩ入門』｣（2回目、5回目） ・個人情報保護、EU一般データ保護規則(GDPR)、忘れられる権利、オプトアウト 「文理学『数理・データサイエンスＡＩ入門』｣（2回目、5回目） ・データ倫理：データのねつ造、改ざん、盗用、プライバシー保護 「文理学『数理・データサイエンスＡＩ入門』｣（2回目） ・AI社会原則（公平性、説明責任、透明性、人間中心の判断） 「文理学『数理・データサイエンスＡＩ入門』｣（2回目、4回目） ・データバイアス、アルゴリズムバイアス 「文理学『数理・データサイエンスＡＩ入門』｣（2回目） ・AIサービスの責任論 「文理学『数理・データサイエンスＡＩ入門』｣（4回目、5回目） ・データ・AI活用における負の事例紹介 「文理学『数理・データサイエンスＡＩ入門』｣（4回目、5回目）
...

Sheet 様式２ 履修者等数の実績
S1: 様式２
Q2: ='様式１-１ プログラムを構成する授業科目'!C2 -> 徳島文理大学
A3: プログラムの履修者数等の実績について
A5: ①プログラム開設年度 | C5: 令和５ | E5: 年度
A7: ②大学等全体の男女別学生数 | E7: 男性 | F7: 1890 | G7: 人 | H7: 女性 | I7: 2076 | J7: 人 | K7: （ | L7: 合計 | M7: =F7+I7 -> 3966 | N7: 人 | O7: ）
A9: ③履修者・修了者の実績
B11: 学部・学科名称 | C11: 学生数 | D11: 入学 定員 | E11: 収容 定員 | F11: 令和5年度 | H11: 令和4年度 | J11: 令和3年度 | L11: 令和2年度 | N11: 令和元年度 | P11: 平成30年度 | R11: 履修者数 合計 | S11: 履修率
F12: 履修者数 | G12: 修了者数 | H12: 履修者数 | I12: 修了者数 | J12: 履修者数 | K12: 修了者数 | L12: 履修者数 | M12: 修了者数 | N12: 履修者数 | O12: 修了者数 | P12: 履修者数 | Q12: 修了者数
B13: 人間生活学部 | C13: 1136 | D13: 405 | E13: 1620 | F13: 258 | G13: 246 | R13: =F13+H13+J13+L13+N13+P13 -> 258 | S13: =R13/E13 -> 0.15925926
B14: 音楽学部 | C14: 42 | D14: 30 | E14: 120 | F14: 7 | G14: 7 | R14: =F14+H14+J14+L14+N14+P14 -> 7 | S14: =R14/E14 -> 0.058333333
B15: 薬学部 | C15: 421 | D15: 150 | E15: 960 | F15: 54 | G15: 52 | R15: =F15+H15+J15+L15+N15+P15 -> 54 | S15: =R15/E15 -> 0.05625
B16: 総合政策学部 | C16: 326 | D16: 100 | E16: 400 | F16: 47 | G16: 36 | R16: =F16+H16+J16+L16+N16+P16 -> 47 | S16: =R16/E16 -> 0.1175
B17: 保健福祉学部 | C17: 1179 | D17: 345 | E17: 1380 | F17: 303 | G17: 287 | R17: =F17+H17+J17+L17+N17+P17 -> 303 | S17: =R17/E17 -> 0.21956522
B18: 文学部 | C18: 287 | D18: 90 | E18: 360 | F18: 59 | G18: 55 | R18: =F18+H18+J18+L18+N18+P18 -> 59 | S18: =R18/E18 -> 0.16388889
B19: 理工学部 | C19: 340 | D19: 110 | E19: 440 | F19: 76 | G19: 66 | R19: =F19+H19+J19+L19+N19+P19 -> 76 | S19: =R19/E19 -> 0.17272727
B20: 香川薬学部 | C20: 235 | D20: 90 | E20: 540 | F20: 33 | G20: 31 | R20: =F20+H20+J20+L20+N20+P20 -> 33 | S20: =R20/E20 -> 0.061111111
R21: =F21+H21+J21+L21+N21+P21 -> 0 | S21: =R21/E21 -> #DIV/0!
R22: =F22+H22+J22+L22+N22+P22 -> 0 | S22: =R22/E22 -> #DIV/0!
R23: =F23+H23+J23+L23+N23+P23 -> 0 | S23: =R23/E23 -> #DIV/0!
R24: =F24+H24+J24+L24+N24+P24 -> 0 | S24: =R24/E24 -> #DIV/0!
R25: =F25+H25+J25+L25+N25+P25 -> 0 | S25: =R25/E25 -> #DIV/0!
R26: =F26+H26+J26+L26+N26+P26 -> 0 | S26: =R26/E26 -> #DIV/0!
R27: =F27+H27+J27+L27+N27+P27 -> 0 | S27: =R27/E27 -> #DIV/0!
R28: =F28+H28+J28+L28+N28+P28 -> 0 | S28: =R28/E28 -> #DIV/0!
R29: =F29+H29+J29+L29+N29+P29 -> 0 | S29: =R29/E29 -> #DIV/0!
R30: =F30+H30+J30+L30+N30+P30 -> 0 | S30: =R30/E30 -> #DIV/0!
R31: =F31+H31+J31+L31+N31+P31 -> 0 | S31: =R31/E31 -> #DIV/0!
R32: =F32+H32+J32+L32+N32+P32 -> 0 | S32: =R32/E32 -> #DIV/0!
B33: 合 計 | C33: =SUM(C13:C32) -> 3966 | D33: =SUM(D13:D32) -> 1320 | E33: =SUM(E13:E32) -> 5820 | F33: =SUM(F13:F32) -> 837 | G33: =SUM(G13:G32) -> 780 | H33: =SUM(H13:H32) -> 0 | I33: =SUM(I13:I32) -> 0 | J33: =SUM(J13:J32) -> 0 | ... R33: =SUM(R13:R32) -> 837 | S33: =R33/E33 -> 0.14381443

Sheet 様式３ 教育の質・履修者数を向上させるための体制・計画
I1: 様式３
G2: 大学等名 | H2: ='様式１-１ プログラムを構成する授業科目'!C2 -> 徳島文理大学
A4: 教育の質・履修者数を向上させるための体制・計画について
A6: ① | B6: 全学の教員数 | C6: (常勤） | E6: 310 | F6: 人 | G6: （非常勤） | H6: 115 | I6: 人
A8: ② | B8: プログラムの授業を教えている教員数 | H8: 17 | I8: 人
A10: ③ | B10: プログラムの運営責任者
B11: （責任者名） | C11: 梶山 博司 | G11: （役職名） | H11: 副学長・理工学部長・教授
A13: ④ | B13: プログラムを改善・進化させるための体制（委員会・組織等）
B14: 数理・データサイエンス・AI教育推進委員会
B16: （責任者名） | C16: 梶山 博司 | G16: （役職名） | H16: 委員長
A18: ⑤ | B18: プログラムを改善・進化させるための体制を定める規則名称
B19: 数理・データサイエンス・AI教育推進委員会規程
A21: ⑥ | B21: 体制の目的
B22: これからのデジタル社会において「数理・データサイエンス・AI」に関する基礎的な知識や技能を身につけ、日常生活や仕事等で使いこなせることが、文理を問わず全ての学生に求められている。そのため、本学では、文部科学省の「数理・データサイエンス・AI教育プログラム認定制度」に準拠した教育プログラム（リテラシーレベル）を大学と短期大学部の全学科に、また、（応用基礎レベル）を理工学部と人間生活学部に開設し、令和５ 年度から実施しており、令和６年度の認定を目指している。そこで、学内に「数理・データサイエンス教育推進委員会」を置き、本学の数理・データサイエンス・AI 教育プログラムの構成・内容・サポート体制を充実させ、点検・評価を行い、本プログラムの改善・進化を図る。
A34: ⑦ | B34: 具体的な構成員
B35: 委員長 理工学部 ナノ物質工学科 副学長･学部長･教授 梶山 博司 委 員 人間生活学部 建築デザイン学科 副学長･学部長･教授 森田 孝夫 委 員 短期大学部 生活科学科 学部長･科長・教授 岡部 千鶴 委 員 理工学部 電子情報工学科 学科長･教授 古谷 彰教 委 員 人間生活学部 ﾒﾃﾞｨｱﾃﾞｻﾞｲﾝ学科 学科長･教授 篠原 靖典 委 員 短期大学部 商科 科長･教授 則包 光徳 委 員 理工学部 電子情報工学科 教授 山本 由和 委 員 理工学部 電子情報工学科 教授 河合 浩行 委 員 人間生活学部 ﾒﾃﾞｨｱﾃﾞｻﾞｲﾝ学科 教授 古本奈奈代 委 員 人間生活学部 ﾒﾃﾞｨｱﾃﾞｻﾞｲﾝ学科 准教授 加治 芳雄 委 員 情報センター センター長 田尾 公生 委 員 情報センター 係長 松田 和也 事務局 徳島キャンパス 教務部 部長 佐々木 尊 事務局 香川キャンパス 教育研究支援課 課長 細川 典宏 事務局 徳島キャンパス 教務部教務課 係長 多田 一子 事務局 香川キャンパス 教務部教務課 係長 安藝 和加
A48: ⑧ | B48: 履修者数・履修率の向上に向けた計画 ※様式１の「履修必須の有無」で「計画がある」としている場合は詳細について記載すること
B49: 令和５年度実績 | C49: ='様式２ 履修者等数の実績'!S33 -> 0.14381443 | E49: 令和６年度予定 | F49: 0.3 | H49: 令和７年度予定 | I49: 0.45
B50: 令和８年度予定 | C50: 0.6 | E50: 令和９年度予定 | F50: 0.75 | H50: 収容定員（名） | I50: ='様式２ 履修者等数の実績'!E33 -> 5820
B51: 具体的な計画
B52: 本学の「徳島文理大学数理・データサイエンス・AIリテラシープログラム」は全１年生を対象とする全学共通教育科目である「文理学」の「数理・データサイエンス・AI入門」７コマと情報処理系科目１科目（薬学部・香川薬学部の「基礎薬学情報処理」、看護学科の「情報処理・統計学」から構成されており、令和５年度の履修率の実績としては、14％である。このプログラムでは、「文理学」と薬学部の「基礎薬学情報処理」、保健福祉学部看護学科の「情報処理・統計学」は必修であるが、薬学部、看護学科以外の学部・学科の「情報処理」と香川薬学部の「基礎薬学情報処理」が選択となっている。今後、この２科目を必修または選択必修とすることを検討し、履修者数・履修率の向上を図りたい。
A65: ⑨ | B65: 学部・学科に関係なく希望する学生全員が受講可能となるような必要な体制・取組等
B66: 本プログラムの「文理学」は理事長の「建学の精神について」、学長の「大学でなぜ学ぶのか」などにはじまり、各学科ごとの「スタディ・スキルズ」、「地域学」など新入生の大学生活のスタートアップを支援する授業であり、必修科目である。さらに、この「文理学」の授業は各学科ごとの「スタディスキルズ」以外の時間は、徳島キャンパス、香川キャンパでそれぞれのホールで両キャンパスの１年生全員がそろって授業を受けている。情報処理系科目は選択科目もあるが、大学において、基礎的な情報スキルを身につけるということで、もともとほとんどの学生が履修している。
A79: ⑩ | B79: できる限り多くの学生が履修できるような具体的な周知方法・取組
B80: 令和５年度のプログラムの開始にあわせて、本学のHPに本プログラムについてのページを開設するとともに、新入生ガイドに「数理・データサイエンス・AI教育プログラム（リテラシーレベル）が始まります！」のページを掲載し、各学科の新入生オリエンテーションで、担任から学科毎に新入生全員の本プログラムの履修を呼びかけている。
A93: ⑪ | B93: できる限り多くの学生が履修・修得できるようなサポート体制
B94: 令和４年度中に令和５年度の４月当初から実施期間としてのプログラムが実施できるよう、プログラムを策定し、令和６年度の認定制度への申請を目標に計画を進める旨を定例部局長会、定例合同教授会にかけ、学内に共通理解を図るとともに、できるだけ全員の履修を呼びかける旨、各学部・学科の教員に依頼した。また、本学では担任・チューター制度を導入しており、入学後、個別面談を実施するなど、細やかなサポート体制をとっている。学生部学生支援課では事務職員が各学科の学生生活支援を担当しており、履修指導、生活指導等を行っている。教務課、教育研究支援課の担当者は単位修得、各種資格取得状況などを管理し、様々な学生相談にも応じる体制をとっている。
A107: ⑫ | B107: 授業時間内外で学習指導、質問を受け付ける具体的な仕組み
B108: 本学では、全ての教員がオフィスアワーを設定しており、シラバスにはオフィスアワー曜日、時間、場所を記載しており、授業内容の質問等について、対面による相談体制が整っており、多くの学生が活用している。また、本学はGoogleと契約しており、GoogleClassroom、GoogleMeetｓ、GoogleFormｓなどを全教職員が無料で使えるようになっている。特に教員は対面の授業であっても、学生をサポートするツールとして、個別の質問に答えたり、授業の資料、課題等をデータで配布するなど、GoogleClassroomを様々に活用している。本学はウィングネットとも契約しており、オンディマンド形式の学修補助教材「ベーシックウィング」を学生が学内外からアクセスして、高等学校、中学校等の各教科の授業コンテンツを視聴することができるようになっている。令和５年度からは、高校の「情報Ⅰ」も視聴可能となっている。また、本プログラムが実施されるようになり、「ベーシックウイング」の数学の視聴数が急増している。

Sheet 様式４　自己点検・評価
I1: 様式４
H2: 大学等名 | I2: ='様式１-１ プログラムを構成する授業科目'!C2 -> 徳島文理大学
A3: 自己点検・評価について
A5: ① | B5: プログラムの自己点検・評価を行う体制（委員会・組織等）
B6: 徳島文理大学数理・データサイエンス・AI教育推進委員会
D8: （責任者名） | E8: 梶山 博司 | G8: （役職名） | H8: 委員長
A10: ② | B10: 自己点検・評価体制における意見等
B11: 自己点検・評価の視点 | E11: 自己点検・評価体制における意見・結果・改善に向けた取組等
B12: 学内からの視点
C13: プログラムの履修・修得状況 | E13: 教員は学内システム（教職員グループウェアー・学生ポータルシステム）やGoogleClassroomにより学生の出欠状況の確認、レポートや課題の配信、提出状況を把握できるようになっており、学修状況を随時把握できるようにしている。また、プログラムの履修・取得状況及び成績評価等のデータは教務部教務課において学務システムよりダウンロードし、「数理・データサイエンス・ＡＩ教育推進委員会」に送られ、委員会で各学科ごとのプログラムの履修・取得及び成績評価等の状況を分析・検証している。令和５年は対象科目の履修者数が837名、修了者数が780名、履修者数を収用定員で割った履修率は14％であった。今後は本プログラムの改善・充実を図り、本プログラムの履修について、新入生オリエンテーション等での履修指導をさらに強化し、履修者、修了者の増加に繋げていく。
C14: 学修成果 | E14: 本プログラムを履修することで、次のような能力（学修成果）を身につけることを目的として実施している。 ・今後のデジタル社会において、数理・データサイエンス・AIを日常の生活、仕事等の場で使いこなすことができる基礎的素養を主体的に身に付けること。 ・学修した数理・データサイエンス・AIに関する知識・技能をもとに、これらを扱う際には、人間中心の適切な判断ができ、不安なく自らの意志でAI等の恩恵を享受し、これらを説明し、活用できるようになること。 このため、ＦＤ研究部会により全学的に実施している「全学授業アンケート」の結果等をもとに「数理・データサイエンス・ＡＩ教育推進委員会」において、これらの学修成果を総合的に分析することによって、本プログラムを検証・評価し、プログラムの改善充実に繋げている。
C15: 学生アンケート等を通じた学生の内容の理解度 | E15: 本学においては、全ての科目、全ての学生を対象にＦＤ研究部会が「全学授業アンケート」を前・後期ごとに実施しており、本プログラムの構成科目についても、受講者全員に授業アンケートを実施し、学生の理解度等を分析している。アンケート項目のうち、「わかりやすさ」について、プログラムの構成科目の「文理学」では、「わかりやすい内容であった」「どちらかというとわかりやすい内容であった」をあわせて、85.1％、もう一つの構成科目の「情報系科目」では、「わかりやすい内容であった」「どちらかというとわかりやすい内容であった」をあわせて、88.1％となっており、本学の教育プログラムについて、学生の内容の理解度はかなり高いということができる。今後も本教育プログラムの改善充実に努め、理解度をさらに一層向上させていきたいと考えている。
C16: 学生アンケート等を通じた後輩等他の学生への推奨度 | E16: 全学授業アンケートの結果で満足度について、「文理学」では満足、どちらかといえば満足をあわせて、92.0％、「情報処理系科目」では、満足、どちらかといえば満足をあわせて、94.2％となっており、本学の教育プログラムはかなり高い満足度であったと言える。また、「授業をとおして、もっと学んでみたいと思うようになった」など、本教育プログラムに対して、さらに発展的な学修を希望するなどの意見も多く見られた。こうしたことから、本教育プログラムの修得者の後輩等他の学生への推奨度は高いものと推察される。また、本教育プログラムの専用ページにおいて受講の感想等の意見を掲示し、講義受講の推奨に活用していく予定である。
C17: 全学的な履修者数、履修率向上に向けた計画の達成・進捗状況 | E17: 本学では新入生が大学の使命や目的、建学精神を理解して勉学に邁進する強い意志と卒業に至る勤勉な態度を自ら育てることを目的として全学共通教育科目として「文理学」を実施しており、全学部・学科で必修科目としている。令和５年度から、この「文理学」に「数理・データサイエンス・ＡＩ入門」を７コマ、７人の教員が１コマずつ担当するオムニバス方式で設定し、徳島キャンパスは「むらさきホール（収用定員1314人）」、香川キャンパスは「村崎サイメモリアルホ-ル（収用定員896人）」にキャンパスごとに1年生全員が入り、対面で実施している。本教育プログラムはこの「文理学」と各学部ともに、「情報処理」などの情報処理系科目１科目とで構成されている。特に一般総合科目の「情報処理」は選択科目であるが、大学での学修に欠かせないパソコンをうまく使いこなすために必要な科目として、もともと履修率が高い科目であり、令和６年度からは選択必修としている。
B18: 学外からの視点
C19: 教育プログラム修了者の進路、活躍状況、企業等の評価 | E19: 本プログラムは令和５年度の入学生から実施しており、修了者は卒業していない状況である。また、本学では就職支援部が今年度より卒業生や卒業生の就職先の企業、団体等に対してアンケートを実施する予定となっており、今後は、本教育プログラムを修了した卒業生における採用状況や企業評価を把握する仕組みを構築し、プログラムの改善・充実に繋げていきたい。
C20: 産業界からの視点を含めた教育プログラム内容・手法等への意見 | E20: 本学では、就職支援部が地元企業等と本学の教育内容や学修成果に関すする意見交換会を実施しており、今後は本プログラム修了者の学修成果についても、学生の採用者側としての意見や提言を聴取し、プログラムの改善・充実に繋げていきたい。また、自己点検評価・評価活動の客観性、公平性を担保し、教育の内部質保障を図ることを目的として、経済産業界関係者、県教委、県高等学校長協会進学指導部会長等外部の評価委員に本学の自己点検・評価報告書の点検・評価を依頼し、各評価基準項目についての意見を聴取しているが、令和６年度の自己点検・評価報告書には特記事項として、本学の「数理・データサイエンス・AI教育プログラム」を取り上げており、本プログラムについての外部評価委員からの意見も聴取し、プログラムの改善・充実に繋げたい。
B21: 数理・データサイエンス・ＡＩを「学ぶ楽しさ」「学ぶことの意義」を理解させること | E21: 本プログラムは、①数理・データサイエンス・AIを活用することの「楽しさ」や「学ぶことの意義」を重点的に教え、学生に好奇心や関心を高く持ってもらう魅力的かつ特色ある教育を行うこと、また、数理・データサイエンス・AIを活用することが「好き」な人材を育成し、それが自分・他人を含めて、次の学修への意欲、動機付けになるような「学びの相乗効果」を生み出すことを狙うこと、②カリキュラムを実施するにあたっては、本学の教育目的、分野の特性、個々の学生の学習歴や習熟度合い等に応じて、モデルカリキュラムの中から適切かつ柔軟に選択・抽出し、有機性を考慮した教育を行うこと、③実データ、実課題を用いた演習など、社会での実例を題材に数理・データサイエンス・AIを活用することを通じ、現実の課題と適切な活用法を学ぶことをカリキュラムに取り入れること、などを念頭に置いて教育プログラムを策定した。本プログラムの構成科目における授業アンケート結果から、前述の①～③の観点について、各授業科目レベルでの検証・評価を実施し、改善充実に繋げている。
B22: 内容・水準を維持・向上しつつ、より「分かりやすい」授業とすること ※社会の変化や生成AI等の技術の発展を踏まえて教育内容を継続的に見直すなど、より教育効果の高まる授業内容・方法とするための取組や仕組みについても該当があれば記載 | E22: 本学では、全学的に学生に対して「授業評価アンケート」を前・後期末に実施している。本教育プログラムの構成科目全てにおいても授業アンケートを行っており、授業の分かりやすさ、学生の満足度、改善点などの把握に努めている。さらに、授業評価アンケート結果について、本教育プログラムの授業科目レベルにおいて、点検・評価を行うことで、授業の「分かりやすさ」、授業内容・水準が学生に適切であるかどうか教育の質向上に向けた改善を行っている。令和６年度は令和５年度の授業アンケート結果をもとに「数理・データサイエンス・AI教育推進委員会」で本教育プログラムの検証・評価を行い、プログラムの見直しを行うとともに、質の向上に取り組む予定である。
