Workbook

Sheet 様式１ー１　プログラムを構成する授業科目
T1: 様式１－１ | V1: 「学部・学科によって、修了要件は相違する」場合は、本シートを複製の上＜様式１－〇＞と枝番号を付してください
B2: 大学等名 | C2: 愛知医科大学
B3: プログラム名 | C3: 愛知医科大学メディカルデータサイエンス教育プログラム
A5: プログラムを構成する授業科目について
A7: ① 教育プログラムの修了要件 | L7: 学部・学科によって、修了要件は相違する
A9: ② 対象となる学部・学科名称
B11: 医学部
A14: ③ 修了要件
B15: プログラムを構成する「医療のための情報学」２単位、「アカデミックリテラシー」１単位、「行動科学１ａ」１単位、「医療のための数学」２単位の計6単位を取得すること。 （選択講座1は選択科目につき、履修を必須としない。） | X15: 【プルダウンリスト】
X16: 令和５年度以前より、履修することが必須のプログラムとして実施
X17: 令和８年度までに履修必須とする計画
X18: 令和９年度以降に履修必須とする計画、又は未定
B22: 必要最低科目数・単位数 | E22: 4 | F22: 科目 | H22: 6 | I22: 単位 | M22: 履修必須の有無 | N22: 令和５年度以前より、履修することが必須のプログラムとして実施
A24: ④ 現在進行中の社会変化（第４次産業革命、Society 5.0、データ駆動型社会等）に深く寄与しているものであり、それが自らの生活と密接に結びついている」の内容を含む授業科目
B26: 授業科目 | G26: 単位数 | H26: 必須 | I26: 1-1 | J26: 1-6 | K26: 授業科目 | R26: 単位数 | S26: 必須 | T26: 1-1 | U26: 1-6
B27: 医療のための情報学 | G27: 2 | H27: ○ | I27: ○
B28: 行動科学1a | G28: 1 | H28: ○ | I28: ○ | J28: ○
B29: 選択講座１（AIリテラシー入門） | G29: 0.5 | J29: ○
A35: ⑤ 「社会で活用されているデータ」や「データの活用領域」は非常に広範囲であって、日常生活や社会の課題を解決する有用なツールになり得るもの」の内容を含む授業科目
B37: 授業科目 | G37: 単位数 | H37: 必須 | I37: 1-2 | J37: 1-3 | K37: 授業科目 | R37: 単位数 | S37: 必須 | T37: 1-2 | U37: 1-3
B38: 医療のための情報学 | G38: 2 | H38: ○ | I38: ○
B39: 行動科学1a | G39: 1 | H39: ○ | I39: ○ | J39: ○
B40: 選択講座１（AIリテラシー入門） | G40: 0.5 | J40: ○
A46: ⑥ 「様々なデータ利活用の現場におけるデータ利活用事例が示され、様々な適用領域（流通、製造、金融、サービス、インフラ、公共、ヘルスケア等）の知見と組み合わせることで価値を創出するもの」の内容を含む授業科目
B48: 授業科目 | G48: 単位数 | H48: 必須 | I48: 1-4 | J48: 1-5 | K48: 授業科目 | R48: 単位数 | S48: 必須 | T48: 1-4 | U48: 1-5
B49: 行動科学1a | G49: 1 | H49: ○ | I49: ○ | J49: ○
B50: 選択講座１（AIリテラシー入門） | G50: 0.5 | I50: ○ | J50: ○
A57: ⑦ 「活用に当たっての様々な留意事項（ELSI、個人情報、データ倫理、ＡＩ社会原則等）を考慮し、情報セキュリティや情報漏洩等、データを守る上での留意事項への理解をする」の内容を含む授業科目
B59: 授業科目 | G59: 単位数 | H59: 必須 | I59: 3-1 | J59: 3-2 | K59: 授業科目 | R59: 単位数 | S59: 必須 | T59: 3-1 | U59: 3-2
B60: 医療のための情報学 | G60: 2 | H60: ○ | I60: ○ | J60: ○
B61: アカデミックリテラシー | G61: 1 | H61: ○ | I61: ○ | J61: ○
A68: ⑧ 「実データ・実課題（学術データ等を含む）を用いた演習など、社会での実例を題材として、「データを読む、説明する、扱う」といった数理・データサイエンス・ＡＩの基本的な活用法に関するもの」の内容を含む授業科目
B70: 授業科目 | F70: 単位数 | G70: 必須 | H70: 2-1 | I70: 2-2 | J70: 2-3 | K70: 授業科目 | Q70: 単位数 | R70: 必須 | S70: 2-1 | T70: 2-2 | U70: 2-3
B71: 医療のための情報学 | F71: 2 | G71: ○ | H71: ○ | I71: ○ | J71: ○
B72: 医療のための数学 | F72: 2 | G72: ○ | H72: ○ | I72: ○ | J72: ○
B73: 選択講座１（AIリテラシー入門） | F73: 0.5 | J73: ○
A79: ⑨ 選択「４．オプション」の内容を含む授業科目
B80: 授業科目 | G80: 選択項目 | K80: 授業科目 | R80: 選択項目
B81: 医療のための数学 | G81: 4-1統計および数理基礎
A89: ⑩ プログラムを構成する授業の内容
...

Sheet 様式１ー２　プログラムを構成する授業科目
T1: 様式１ー２ | V1: 「学部・学科によって、修了要件は相違する」場合は、本シートを複製の上＜様式１－〇＞と枝番号を付してください
B2: 大学等名 | C2: 愛知医科大学
B3: プログラム名 | C3: 愛知医科大学メディカルデータサイエンス教育プログラム
A5: プログラムを構成する授業科目について
A7: ① 教育プログラムの修了要件 | L7: 学部・学科によって、修了要件は相違する
A9: ② 対象となる学部・学科名称
B11: 看護学部
A14: ③ 修了要件
B15: プログラムを構成する「情報科学I」１単位、「情報科学II」１単位、「統計学」２単位の計4単位を取得すること。 | X15: 【プルダウンリスト】
X16: 令和５年度以前より、履修することが必須のプログラムとして実施
X17: 令和８年度までに履修必須とする計画
X18: 令和９年度以降に履修必須とする計画、又は未定
B22: 必要最低科目数・単位数 | E22: 3 | F22: 科目 | H22: 4 | I22: 単位 | M22: 履修必須の有無 | N22: 令和５年度以前より、履修することが必須のプログラムとして実施
A24: ④ 現在進行中の社会変化（第４次産業革命、Society 5.0、データ駆動型社会等）に深く寄与しているものであり、それが自らの生活と密接に結びついている」の内容を含む授業科目
B26: 授業科目 | G26: 単位数 | H26: 必須 | I26: 1-1 | J26: 1-6 | K26: 授業科目 | R26: 単位数 | S26: 必須 | T26: 1-1 | U26: 1-6
B27: 情報科学I | G27: 1 | H27: ○ | I27: ○ | J27: ○
A35: ⑤ 「社会で活用されているデータ」や「データの活用領域」は非常に広範囲であって、日常生活や社会の課題を解決する有用なツールになり得るもの」の内容を含む授業科目
B37: 授業科目 | G37: 単位数 | H37: 必須 | I37: 1-2 | J37: 1-3 | K37: 授業科目 | R37: 単位数 | S37: 必須 | T37: 1-2 | U37: 1-3
B38: 情報科学I | G38: 1 | H38: ○ | I38: ○ | J38: ○
A46: ⑥ 「様々なデータ利活用の現場におけるデータ利活用事例が示され、様々な適用領域（流通、製造、金融、サービス、インフラ、公共、ヘルスケア等）の知見と組み合わせることで価値を創出するもの」の内容を含む授業科目
B48: 授業科目 | G48: 単位数 | H48: 必須 | I48: 1-4 | J48: 1-5 | K48: 授業科目 | R48: 単位数 | S48: 必須 | T48: 1-4 | U48: 1-5
B49: 情報科学I | G49: 1 | H49: ○ | I49: ○ | J49: ○
A57: ⑦ 「活用に当たっての様々な留意事項（ELSI、個人情報、データ倫理、ＡＩ社会原則等）を考慮し、情報セキュリティや情報漏洩等、データを守る上での留意事項への理解をする」の内容を含む授業科目
B59: 授業科目 | G59: 単位数 | H59: 必須 | I59: 3-1 | J59: 3-2 | K59: 授業科目 | R59: 単位数 | S59: 必須 | T59: 3-1 | U59: 3-2
B60: 情報科学I | G60: 1 | H60: ○ | I60: ○ | J60: ○
A68: ⑧ 「実データ・実課題（学術データ等を含む）を用いた演習など、社会での実例を題材として、「データを読む、説明する、扱う」といった数理・データサイエンス・ＡＩの基本的な活用法に関するもの」の内容を含む授業科目
B70: 授業科目 | F70: 単位数 | G70: 必須 | H70: 2-1 | I70: 2-2 | J70: 2-3 | K70: 授業科目 | Q70: 単位数 | R70: 必須 | S70: 2-1 | T70: 2-2 | U70: 2-3
B71: 情報科学II | F71: 1 | G71: ○ | J71: ○
B72: 統計学 | F72: 2 | G72: ○ | H72: ○ | I72: ○
A79: ⑨ 選択「４．オプション」の内容を含む授業科目
B80: 授業科目 | G80: 選択項目 | K80: 授業科目 | R80: 選択項目
B81: 統計学 | G81: 4-1統計および数理基礎
A89: ⑩ プログラムを構成する授業の内容
B90: 授業に含まれている内容・要素 | D90: 講義内容
B91: （１）現在進行中の社会変化（第４次産業革命、Society 5.0、データ駆動型社会等）に深く寄与しているものであり、それが自らの生活と密接に結びついている | C91: 1-1 | D91: ・ビッグデータ、IoT、第４次産業革命、Society5.0、データ駆動型社会「情報科学Ⅰ」(１回目)
C92: 1-6 | D92: ・AI最新技術の活用例(強化学習など)「情報科学Ⅰ」(７回目)
B93: （２）「社会で活用されているデータ」や「データの活用領域」は非常に広範囲であって、日常生活や社会の課題を解決する有用なツールになり得るもの | C93: 1-2 | D93: ・ビッグデータ、IoT、第４次産業革命、Society5.0、データ駆動型社会「情報科学Ⅰ」(１回目)
C94: 1-3 | D94: ・研究開発、調達、製造、物流、マーケティング、販売、サービス「情報科学Ⅰ」(１回目)
B95: （３）様々なデータ利活用の現場におけるデータ利活用事例が示され、様々な適用領域（流通、製造、金融、サービス、インフラ、公共、ヘルスケア等）の知見と組み合わせることで価値を創出するもの | C95: 1-4 | D95: ・データ解析(予測、発見)、データの可視化(グラフ、地図)、非構造化データの処理(自然言語処理、画像/動画処理、音声/音楽処理)「情報科学Ⅰ」(７回目)
C96: 1-5 | D96: ・データサイエンスのサイクル、ヘルスケアにおけるデータ利活用事例「情報科学Ⅰ」(３回目)
...

Sheet 様式２ 履修者等数の実績
S1: 様式２
Q2: ='様式１ー２ プログラムを構成する授業科目'!C2 -> 愛知医科大学
A3: プログラムの履修者数等の実績について
A5: ①プログラム開設年度 | C5: 令和5 | E5: 年度
A7: ②大学等全体の男女別学生数 | E7: 男性 | F7: 448 | G7: 人 | H7: 女性 | I7: 685 | J7: 人 | K7: （ | L7: 合計 | M7: =F7+I7 -> 1133 | N7: 人 | O7: ）
A9: ③履修者・修了者の実績
B11: 学部・学科名称 | C11: 学生数 | D11: 入学 定員 | E11: 収容 定員 | F11: 令和5年度 | H11: 令和4年度 | J11: 令和3年度 | L11: 令和2年度 | N11: 令和元年度 | P11: 平成30年度 | R11: 履修者数 合計 | S11: 履修率
F12: 履修者数 | G12: 修了者数 | H12: 履修者数 | I12: 修了者数 | J12: 履修者数 | K12: 修了者数 | L12: 履修者数 | M12: 修了者数 | N12: 履修者数 | O12: 修了者数 | P12: 履修者数 | Q12: 修了者数
B13: 医学部 | C13: 721 | D13: 115 | E13: 690 | F13: 116 | G13: 111 | R13: =F13+H13+J13+L13+N13+P13 -> 116 | S13: =R13/E13 -> 0.16811594
B14: 看護学部 | C14: 412 | D14: 100 | E14: 400 | F14: 103 | G14: 100 | R14: =F14+H14+J14+L14+N14+P14 -> 103 | S14: =R14/E14 -> 0.2575
R15: =F15+H15+J15+L15+N15+P15 -> 0
R16: =F16+H16+J16+L16+N16+P16 -> 0
R17: =F17+H17+J17+L17+N17+P17 -> 0
R18: =F18+H18+J18+L18+N18+P18 -> 0
R19: =F19+H19+J19+L19+N19+P19 -> 0
R20: =F20+H20+J20+L20+N20+P20 -> 0
R21: =F21+H21+J21+L21+N21+P21 -> 0
R22: =F22+H22+J22+L22+N22+P22 -> 0
R23: =F23+H23+J23+L23+N23+P23 -> 0
R24: =F24+H24+J24+L24+N24+P24 -> 0
R25: =F25+H25+J25+L25+N25+P25 -> 0
R26: =F26+H26+J26+L26+N26+P26 -> 0
... R32: =F32+H32+J32+L32+N32+P32 -> 0
B33: 合 計 | C33: =SUM(C13:C32) -> 1133 | D33: =SUM(D13:D32) -> 215 | E33: =SUM(E13:E32) -> 1090 | F33: =SUM(F13:F32) -> 219 | G33: =SUM(G13:G32) -> 211 | H33: =SUM(H13:H32) -> 0 | I33: =SUM(I13:I32) -> 0 | J33: =SUM(J13:J32) -> 0 | ... R33: =SUM(R13:R32) -> 219 | S33: =R33/E33 -> 0.20091743

Sheet 様式３ 教育の質・履修者数を向上させるための体制・計画
I1: 様式３
G2: 大学等名 | H2: ='様式１ー２ プログラムを構成する授業科目'!C2 -> 愛知医科大学
A4: 教育の質・履修者数を向上させるための体制・計画について
A6: ① | B6: 全学の教員数 | C6: (常勤） | E6: 663 | F6: 人 | G6: （非常勤） | H6: 342 | I6: 人
A8: ② | B8: プログラムの授業を教えている教員数 | H8: 5 | I8: 人
A10: ③ | B10: プログラムの運営責任者
B11: （責任者名） | C11: 祖父江元 | G11: （役職名） | H11: 学長
A13: ④ | B13: プログラムを改善・進化させるための体制（委員会・組織等）
B14: 愛知医科大学メディカルデータサイエンス教育プログラム委員会
B16: （責任者名） | C16: 橋本貴宏 | G16: （役職名） | H16: 愛知医科大学メディカルデータサイエンス教育プログラム委員会委員長・教授
A18: ⑤ | B18: プログラムを改善・進化させるための体制を定める規則名称
B19: 愛知医科大学メディカルデータサイエンス教育プログラム委員会規程
A21: ⑥ | B21: 体制の目的
B22: 本学では医学部、看護学部両学部の教務委員会が学部教育全般を担当している。数理・データサイエンス・AI教育を実施するため、全学的な組織として「愛知医科大学メディカルデータサイエンス教育プログラム委員会」を令和５年度に設置した。
A34: ⑦ | B34: 具体的な構成員
B35: 総合学術情報センターICT支援部門長 橋本貴宏教授 医学部教務部長 鈴木耕次郎教授 看護学部教務学生部長 若杉里実教授 医学部公衆衛生学講座 菱田朝陽教授 医学教育センター長 早稲田勝久教授 看護学部基礎看護学講座 山中真教授 看護学部母子看護学講座 山本弘江准教授 学生委員 ４名
A48: ⑧ | B48: 履修者数・履修率の向上に向けた計画 ※様式１の「履修必須の有無」で「計画がある」としている場合は詳細について記載すること
B49: 令和５年度実績 | C49: ='様式２ 履修者等数の実績'!S33 -> 0.20091743 | E49: 令和６年度予定 | F49: 0.4 | H49: 令和７年度予定 | I49: 0.6
B50: 令和８年度予定 | C50: 0.8 | E50: 令和９年度予定 | F50: 0.9 | H50: 収容定員（名） | I50: ='様式２ 履修者等数の実績'!E33 -> 1090
B51: 具体的な計画
B52: 医学部、看護学部ともに必修科目のみでプログラムの修了要件を満たすことができるため、看護学部は令和８年度、医学部は令和１０年度には履修率が100%になる予定である。
A65: ⑨ | B65: 学部・学科に関係なく希望する学生全員が受講可能となるような必要な体制・取組等
B66: 令和５年度は医学部の１部科目が選択科目であったが、希望者は全員受講可能であった。今後はすべての科目が必修科目となるようにカリキュラムが変更される予定である。
A79: ⑩ | B79: できる限り多くの学生が履修できるような具体的な周知方法・取組
B80: 必修科目であるので、全ての学生が履修できることになっている。取り組みについては大学ホームページにて公開している。新入生のガイダンスでも教育プログラムを周知していく。
A93: ⑪ | B93: できる限り多くの学生が履修・修得できるようなサポート体制
B94: PC端末室に情報基盤部門・ICT支援部門が隣接しており、実習においてハード・ソフト両面でのサポート体制が整っている。また、両学部ともに講義は収録されており、学生がオンデマンドで振り返りを行うことができる。
A107: ⑫ | B107: 授業時間内外で学習指導、質問を受け付ける具体的な仕組み
B108: 授業時間内においては、特にPCを使った授業では実習的な要素もあり、各教員の学習指導が行き届いているといえる。授業時間外においては、プログラムを構成する授業科目のシラバスにオフィスアワーが記載されており、学生が教員に質問に行くことができる。また、それ以外の時間にも本学設置の授業支援システム及びメールシステムを通じて疑問点について質問ができる仕組みは構築されている。

Sheet 様式４　自己点検・評価
I1: 様式４
H2: 大学等名 | I2: ='様式１ー２ プログラムを構成する授業科目'!C2 -> 愛知医科大学
A3: 自己点検・評価について
A5: ① | B5: プログラムの自己点検・評価を行う体制（委員会・組織等）
B6: 愛知医科大学メディカルデータサイエンス教育プログラム評価委員会
D8: （責任者名） | E8: 春日井邦夫 | G8: （役職名） | H8: 愛知医科大学メディカルデータサイエンス教育プログラム評価委員会委員長・教授
A10: ② | B10: 自己点検・評価体制における意見等
B11: 自己点検・評価の視点 | E11: 自己点検・評価体制における意見・結果・改善に向けた取組等
B12: 学内からの視点
C13: プログラムの履修・修得状況 | E13: 令和5年度においては、医学部は「医療のための情報学」「アカデミックリテラシー」「行動科学１a」「医療のための数学」「選択講座（AIリテラシー入門）」の5科目、看護学部は「情報科学I」「情報科学II」「統計学」の3科目によりプログラムは構成されている。それらは全て1学年次開講の科目である。そのうち「選択講座」は履修を必須としない科目であり、それ以外は全ての科目が必修科目である。ゆえに全ての学生が履修することとなっている。 プログラムの修得状況は、医学部の修了者数は 111名、看護学部の修了者数は 100名であり、医学部と看護学部の修得率はそれぞれ 96% と 97% であった。
C14: 学修成果 | E14: 学習支援システム (Moodle) により各授業ごとの課題提出・フィードバックがなされており、定期的に学習成果の把握ができている。各学部ごとに授業アンケートが実施されている。医学部では「シラバス」「講義内容」「教員の態度」「講義資料」などが評価され、看護学部では「シラバス」「講義の構成・内容」「教材」「評価」などが評価された。両学部とも、アンケート結果は教員へフィードバックされ、授業改善に活用されている。今後は、その結果を教育プログラム委員会と共有することにより、本教育プログラムの改善にも活用していきたい。
C15: 学生アンケート等を通じた学生の内容の理解度 | E15: 理解度について検証するために、上の科目別のアンケートとは別に、必須項目の「導入」「基礎」「心得」の３つの項目についてアンケート調査を行った。「理解できた」「概ね理解できた」と回答したのは以下のとおりである。医学部については、導入：87%、基礎：87%、心得：89% となった。看護学部については、導入：70%、基礎：77%、心得：83% となった。自由記述のコメントにも、医学部は「理解できた」看護学部は「難しかった」という記載があった。
C16: 学生アンケート等を通じた後輩等他の学生への推奨度 | E16: 本教育プログラムはほぼ必修科目で構成されており、履修に関する推奨については考慮されていない。唯一存在する「選択講座」は年度ごとに公募され開講する講座であるため、こちらも後輩への推奨などは行われていないが、今後データサイエンス系の（選択）講座が充実されれば、後輩への推奨も行われるようになると期待される。
C17: 全学的な履修者数、履修率向上に向けた計画の達成・進捗状況 | E17: 現在は、必修科目のみで教育プログラムの課程を修得できるようになっている。将来、科目が拡充されて選択科目が増えてきた時にこの問題を検討していきたい。
B18: 学外からの視点
C19: 教育プログラム修了者の進路、活躍状況、企業等の評価 | E19: 初年度の1学年次のプログラムが終了したところである。3年後（看護学部）もしくは5年後（医学部）に就職先（研修先）と共同で卒業生の状況を調査していく。
C20: 産業界からの視点を含めた教育プログラム内容・手法等への意見 | E20: 教育プログラム評価委員会において、学外委員の方々より産業界の視点を含めた形でご意見をいただいた。「学生が卒業する頃には電子カルテ情報が共有化，標準化されると思われるので，今のうちに情報やAIに関する教育が行われているのはありがたい」「高校で情報を学ぶ授業が必須になっている。データサイエンスに関する基礎を身に付けて入学してくると考えられるが，医療におけるデータサイエンスをどのように教えていくのかが課題となるため，接続性が良くなるとよいのではないか」などの意見があった。次年度以降のプログラムの改善に活用していきたい。
B21: 数理・データサイエンス・ＡＩを「学ぶ楽しさ」「学ぶことの意義」を理解させること | E21: 医学部では、「生成AI」についてグループディスカッションを行い、学生たちにAIを扱うことについての関心を深めることに効果があった。また、地元の企業でデータサイエンスを活用している研究者を招き、講義を行った（行動科学1a）。学生たちはいろいろな事例について興味を持っているようであった。看護学部では、AIを用いた病理診断を示し、学ぶことの意義を理解させている。
B22: 内容・水準を維持・向上しつつ、より「分かりやすい」授業とすること ※社会の変化や生成AI等の技術の発展を踏まえて教育内容を継続的に見直すなど、より教育効果の高まる授業内容・方法とするための取組や仕組みについても該当があれば記載 | E22: モデルカリキュラムに準拠した教科書を選定し、それを使用することによって、一定水準を維持している。学生アンケートによると、医学部では「理解できた」「概ね理解できた」との回答が85%を超え、看護学部では「理解できた」「概ね理解できた」との回答が75%程度であった。これより「分かりやすさ」についてはある程度満たされているといえる。
