Workbook

Sheet 様式１-1　プログラムを構成する授業科目
T1: 様式１-１ | V1: 「学部・学科によって、修了要件は相違する」場合は、本シートを複製の上＜様式１－〇＞と枝番号を付してください
B2: 大学等名 | C2: 日本福祉大学
B3: プログラム名 | C3: 日本福祉大学数理・データサイエンス・AI教育（リテラシーレベル）プログラム
A5: プログラムを構成する授業科目について
A7: ① 教育プログラムの修了要件 | L7: 学部・学科によって、修了要件は相違する
A9: ② 対象となる学部・学科名称
B11: 社会福祉学部、経済学部、教育・心理学部、国際福祉開発学部、スポーツ科学部
A14: ③ 修了要件
B15: 「情報処理演習Ⅰ」（2単位）を修了すること。 | X15: 【プルダウンリスト】
X16: 令和５年度以前より、履修することが必須のプログラムとして実施
X17: 令和８年度までに履修必須とする計画
X18: 令和９年度以降に履修必須とする計画、又は未定
B22: 必要最低科目数・単位数 | E22: 1 | F22: 科目 | H22: 2 | I22: 単位 | M22: 履修必須の有無 | N22: 令和９年度以降に履修必須とする計画、又は未定
A24: ④ 現在進行中の社会変化（第４次産業革命、Society 5.0、データ駆動型社会等）に深く寄与しているものであり、それが自らの生活と密接に結びついている」の内容を含む授業科目
B26: 授業科目 | G26: 単位数 | H26: 必須 | I26: 1-1 | J26: 1-6 | K26: 授業科目 | R26: 単位数 | S26: 必須 | T26: 1-1 | U26: 1-6
B27: 情報処理演習Ⅰ | G27: 2 | H27: ○ | I27: ○ | J27: ○
A35: ⑤ 「社会で活用されているデータ」や「データの活用領域」は非常に広範囲であって、日常生活や社会の課題を解決する有用なツールになり得るもの」の内容を含む授業科目
B37: 授業科目 | G37: 単位数 | H37: 必須 | I37: 1-2 | J37: 1-3 | K37: 授業科目 | R37: 単位数 | S37: 必須 | T37: 1-2 | U37: 1-3
B38: 情報処理演習Ⅰ | G38: 2 | H38: ○ | I38: ○ | J38: ○
A46: ⑥ 「様々なデータ利活用の現場におけるデータ利活用事例が示され、様々な適用領域（流通、製造、金融、サービス、インフラ、公共、ヘルスケア等）の知見と組み合わせることで価値を創出するもの」の内容を含む授業科目
B48: 授業科目 | G48: 単位数 | H48: 必須 | I48: 1-4 | J48: 1-5 | K48: 授業科目 | R48: 単位数 | S48: 必須 | T48: 1-4 | U48: 1-5
B49: 情報処理演習Ⅰ | G49: 2 | H49: ○ | I49: ○ | J49: ○
A57: ⑦ 「活用に当たっての様々な留意事項（ELSI、個人情報、データ倫理、ＡＩ社会原則等）を考慮し、情報セキュリティや情報漏洩等、データを守る上での留意事項への理解をする」の内容を含む授業科目
B59: 授業科目 | G59: 単位数 | H59: 必須 | I59: 3-1 | J59: 3-2 | K59: 授業科目 | R59: 単位数 | S59: 必須 | T59: 3-1 | U59: 3-2
B60: 情報処理演習Ⅰ | G60: 2 | H60: ○ | I60: ○ | J60: ○
A68: ⑧ 「実データ・実課題（学術データ等を含む）を用いた演習など、社会での実例を題材として、「データを読む、説明する、扱う」といった数理・データサイエンス・ＡＩの基本的な活用法に関するもの」の内容を含む授業科目
B70: 授業科目 | F70: 単位数 | G70: 必須 | H70: 2-1 | I70: 2-2 | J70: 2-3 | K70: 授業科目 | Q70: 単位数 | R70: 必須 | S70: 2-1 | T70: 2-2 | U70: 2-3
B71: 情報処理演習Ⅰ | F71: 2 | G71: ○ | H71: ○ | I71: ○ | J71: ○
A79: ⑨ 選択「４．オプション」の内容を含む授業科目
B80: 授業科目 | G80: 選択項目 | K80: 授業科目 | R80: 選択項目
A89: ⑩ プログラムを構成する授業の内容
B90: 授業に含まれている内容・要素 | D90: 講義内容
B91: （１）現在進行中の社会変化（第４次産業革命、Society 5.0、データ駆動型社会等）に深く寄与しているものであり、それが自らの生活と密接に結びついている | C91: 1-1 | D91: ・ビッグデータ、IoT、AI、ロボット「情報処理演習Ⅰ」（第５回） ・データ量の増加、計算機の処理性能の向上「情報処理演習Ⅰ」（第５回） ・第4次産業革命、Society 5.0、データ駆動型社会「情報処理演習Ⅰ」（第５回） ・データを起点としたものの見方、人間の知的活動を起点としたものの見方「情報処理演習Ⅰ」（第４回）
C92: 1-6 | D92: ・AI最新技術の活用例(「情報処理演習Ⅰ」第１４回) ・AI等を活用した新しいビジネスモデル「情報処理演習Ⅰ」(第８回)
B93: （２）「社会で活用されているデータ」や「データの活用領域」は非常に広範囲であって、日常生活や社会の課題を解決する有用なツールになり得るもの | C93: 1-2 | D93: ・調査データ、実験データ、人の行動ログデータ、機械の稼働ログデータなど「情報処理演習Ⅰ」（第５回）
C94: 1-3 | D94: ・データ・AI活用領域の広がり「情報処理演習Ⅰ」（第８回） ・研究開発、調達、製造、物流、販売、マーケティング、サービスなど「情報処理演習Ⅰ」（第５回、第８回） ・翻訳・要約・執筆支援、コーディング支援など生成AIの応用「情報処理演習Ⅰ」（第１４回）
B95: （３）様々なデータ利活用の現場におけるデータ利活用事例が示され、様々な適用領域（流通、製造、金融、サービス、インフラ、公共、ヘルスケア等）の知見と組み合わせることで価値を創出するもの | C95: 1-4 | D95: ・データ可視化:複合グラフ、2軸グラフ、多次元の可視化、関係性の可視化「情報処理演習Ⅰ」（第１２回）
C96: 1-5 | D96: ・教育、サービス、公共におけるデータ・AI利活用事例紹介「情報処理演習Ⅰ」（第８回）
B97: （４）活用に当たっての様々な留意事項（ELSI、個人情報、データ倫理、ＡＩ社会原則等）を考慮し、情報セキュリティや情報漏洩等、データを守る上での留意事項への理解をする | C97: 3-1 | D97: ・倫理的・法的・社会的課題(ELSI:Ethical, Legal and Social Issues)「情報処理演習Ⅰ」（第10回、第11回） ・個人情報保護、EU一般データ保護規則(GDPR)、忘れられる権利、オプトアウト「情報処理演習Ⅰ」（第10回、第11回）
C98: 3-2 | D98: ・情報セキュリティ:機密性、完全性、可用性情報セキュリティの3要素「情報処理演習Ⅰ」(第10回、第11回) ・匿名加工情報、暗号化と復号、ユーザ認証と、パスワード、アクセス制御、悪意ある情報搾取「情報処理演習Ⅰ」(第10回、第11回) ・情報漏洩等によるセキュリティ事故の事例紹介「情報処理演習Ⅰ」(第10回、第11回)
...

Sheet 様式１-2　プログラムを構成する授業科目 
T1: 様式１-２ | V1: 「学部・学科によって、修了要件は相違する」場合は、本シートを複製の上＜様式１－〇＞と枝番号を付してください
B2: 大学等名 | C2: 日本福祉大学
B3: プログラム名 | C3: 日本福祉大学数理・データサイエンス・AI教育（リテラシーレベル）プログラム
A5: プログラムを構成する授業科目について
A7: ① 教育プログラムの修了要件 | L7: 学部・学科によって、修了要件は相違する
A9: ② 対象となる学部・学科名称
B11: 看護学部、健康科学部リハビリテーション学科、健康科学部福祉工学科建築バリアフリー専修
A14: ③ 修了要件
B15: 「情報処理演習」（2単位）を修了すること。 | X15: 【プルダウンリスト】
X16: 令和５年度以前より、履修することが必須のプログラムとして実施
X17: 令和８年度までに履修必須とする計画
X18: 令和９年度以降に履修必須とする計画、又は未定
B22: 必要最低科目数・単位数 | E22: 1 | F22: 科目 | H22: 2 | I22: 単位 | M22: 履修必須の有無 | N22: 令和９年度以降に履修必須とする計画、又は未定
A24: ④ 現在進行中の社会変化（第４次産業革命、Society 5.0、データ駆動型社会等）に深く寄与しているものであり、それが自らの生活と密接に結びついている」の内容を含む授業科目
B26: 授業科目 | G26: 単位数 | H26: 必須 | I26: 1-1 | J26: 1-6 | K26: 授業科目 | R26: 単位数 | S26: 必須 | T26: 1-1 | U26: 1-6
B27: 情報処理演習 | G27: 2 | H27: ○ | I27: ○ | J27: ○
A35: ⑤ 「社会で活用されているデータ」や「データの活用領域」は非常に広範囲であって、日常生活や社会の課題を解決する有用なツールになり得るもの」の内容を含む授業科目
B37: 授業科目 | G37: 単位数 | H37: 必須 | I37: 1-2 | J37: 1-3 | K37: 授業科目 | R37: 単位数 | S37: 必須 | T37: 1-2 | U37: 1-3
B38: 情報処理演習 | G38: 2 | H38: ○ | I38: ○ | J38: ○
A46: ⑥ 「様々なデータ利活用の現場におけるデータ利活用事例が示され、様々な適用領域（流通、製造、金融、サービス、インフラ、公共、ヘルスケア等）の知見と組み合わせることで価値を創出するもの」の内容を含む授業科目
B48: 授業科目 | G48: 単位数 | H48: 必須 | I48: 1-4 | J48: 1-5 | K48: 授業科目 | R48: 単位数 | S48: 必須 | T48: 1-4 | U48: 1-5
B49: 情報処理演習 | G49: 2 | H49: ○ | I49: ○ | J49: ○
A57: ⑦ 「活用に当たっての様々な留意事項（ELSI、個人情報、データ倫理、ＡＩ社会原則等）を考慮し、情報セキュリティや情報漏洩等、データを守る上での留意事項への理解をする」の内容を含む授業科目
B59: 授業科目 | G59: 単位数 | H59: 必須 | I59: 3-1 | J59: 3-2 | K59: 授業科目 | R59: 単位数 | S59: 必須 | T59: 3-1 | U59: 3-2
B60: 情報処理演習 | G60: 2 | H60: ○ | I60: ○ | J60: ○
A68: ⑧ 「実データ・実課題（学術データ等を含む）を用いた演習など、社会での実例を題材として、「データを読む、説明する、扱う」といった数理・データサイエンス・ＡＩの基本的な活用法に関するもの」の内容を含む授業科目
B70: 授業科目 | F70: 単位数 | G70: 必須 | H70: 2-1 | I70: 2-2 | J70: 2-3 | K70: 授業科目 | Q70: 単位数 | R70: 必須 | S70: 2-1 | T70: 2-2 | U70: 2-3
B71: 情報処理演習 | F71: 2 | G71: ○ | H71: ○ | I71: ○ | J71: ○
A79: ⑨ 選択「４．オプション」の内容を含む授業科目
B80: 授業科目 | G80: 選択項目 | K80: 授業科目 | R80: 選択項目
A89: ⑩ プログラムを構成する授業の内容
B90: 授業に含まれている内容・要素 | D90: 講義内容
B91: （１）現在進行中の社会変化（第４次産業革命、Society 5.0、データ駆動型社会等）に深く寄与しているものであり、それが自らの生活と密接に結びついている | C91: 1-1 | D91: ・ビッグデータ、IoT、AI、ロボット「情報処理演習」（第５回） ・データ量の増加、計算機の処理性能の向上「情報処理演習」（第５回） ・第4次産業革命、Society 5.0、データ駆動型社会「情報処理演習」（第５回） ・データを起点としたものの見方、人間の知的活動を起点としたものの見方「情報処理演習」（第４回）
C92: 1-6 | D92: ・AI最新技術の活用例「情報処理演習」(第１４回) ・AI等を活用した新しいビジネスモデル「情報処理演習」(第８回)
B93: （２）「社会で活用されているデータ」や「データの活用領域」は非常に広範囲であって、日常生活や社会の課題を解決する有用なツールになり得るもの | C93: 1-2 | D93: ・調査データ、実験データ、人の行動ログデータ、機械の稼働ログデータなど「情報処理演習」（第５回）
C94: 1-3 | D94: ・データ・AI活用領域の広がり「情報処理演習」（第８回） ・研究開発、調達、製造、物流、販売、マーケティング、サービスなど「情報処理演習」（第５回、第８回） ・翻訳・要約・執筆支援、コーディング支援など生成AIの応用「情報処理演習」（第１４回）
B95: （３）様々なデータ利活用の現場におけるデータ利活用事例が示され、様々な適用領域（流通、製造、金融、サービス、インフラ、公共、ヘルスケア等）の知見と組み合わせることで価値を創出するもの | C95: 1-4 | D95: ・データ可視化:複合グラフ、2軸グラフ、多次元の可視化、関係性の可視化「情報処理演習」（第１２回）
C96: 1-5 | D96: ・教育、サービス、公共におけるデータ・AI利活用事例紹介「情報処理演習」（第８回）
B97: （４）活用に当たっての様々な留意事項（ELSI、個人情報、データ倫理、ＡＩ社会原則等）を考慮し、情報セキュリティや情報漏洩等、データを守る上での留意事項への理解をする | C97: 3-1 | D97: ・倫理的・法的・社会的課題(ELSI:Ethical, Legal and Social Issues)「情報処理演習」（第10回、第11回） ・個人情報保護、EU一般データ保護規則(GDPR)、忘れられる権利、オプトアウト「情報処理演習」（第10回、第11回）
C98: 3-2 | D98: ・情報セキュリティ:機密性、完全性、可用性情報セキュリティの3要素「情報処理演習」(第10回、第11回) ・匿名加工情報、暗号化と復号、ユーザ認証と、パスワード、アクセス制御、悪意ある情報搾取「情報処理演習」(第10回、第11回) ・情報漏洩等によるセキュリティ事故の事例紹介「情報処理演習」(第10回、第11回)
...

Sheet 様式１-3　プログラムを構成する授業科目
T1: 様式１-３ | V1: 「学部・学科によって、修了要件は相違する」場合は、本シートを複製の上＜様式１－〇＞と枝番号を付してください
B2: 大学等名 | C2: 日本福祉大学
B3: プログラム名 | C3: 日本福祉大学数理・データサイエンス・AI教育（リテラシーレベル）プログラム
A5: プログラムを構成する授業科目について
A7: ① 教育プログラムの修了要件 | L7: 学部・学科によって、修了要件は相違する
A9: ② 対象となる学部・学科名称
B11: 健康科学部福祉工学科情報工学専修
A14: ③ 修了要件
B15: 「情報処理」（2単位）を修了すること | X15: 【プルダウンリスト】
X16: 令和５年度以前より、履修することが必須のプログラムとして実施
X17: 令和８年度までに履修必須とする計画
X18: 令和９年度以降に履修必須とする計画、又は未定
B22: 必要最低科目数・単位数 | E22: 1 | F22: 科目 | H22: 2 | I22: 単位 | M22: 履修必須の有無 | N22: 令和９年度以降に履修必須とする計画、又は未定
A24: ④ 現在進行中の社会変化（第４次産業革命、Society 5.0、データ駆動型社会等）に深く寄与しているものであり、それが自らの生活と密接に結びついている」の内容を含む授業科目
B26: 授業科目 | G26: 単位数 | H26: 必須 | I26: 1-1 | J26: 1-6 | K26: 授業科目 | R26: 単位数 | S26: 必須 | T26: 1-1 | U26: 1-6
B27: 情報処理 | G27: 2 | H27: ○ | I27: ○ | J27: ○
A35: ⑤ 「社会で活用されているデータ」や「データの活用領域」は非常に広範囲であって、日常生活や社会の課題を解決する有用なツールになり得るもの」の内容を含む授業科目
B37: 授業科目 | G37: 単位数 | H37: 必須 | I37: 1-2 | J37: 1-3 | K37: 授業科目 | R37: 単位数 | S37: 必須 | T37: 1-2 | U37: 1-3
B38: 情報処理 | G38: 2 | H38: ○ | I38: ○ | J38: ○
A46: ⑥ 「様々なデータ利活用の現場におけるデータ利活用事例が示され、様々な適用領域（流通、製造、金融、サービス、インフラ、公共、ヘルスケア等）の知見と組み合わせることで価値を創出するもの」の内容を含む授業科目
B48: 授業科目 | G48: 単位数 | H48: 必須 | I48: 1-4 | J48: 1-5 | K48: 授業科目 | R48: 単位数 | S48: 必須 | T48: 1-4 | U48: 1-5
B49: 情報処理 | G49: 2 | H49: ○ | I49: ○ | J49: ○
A57: ⑦ 「活用に当たっての様々な留意事項（ELSI、個人情報、データ倫理、ＡＩ社会原則等）を考慮し、情報セキュリティや情報漏洩等、データを守る上での留意事項への理解をする」の内容を含む授業科目
B59: 授業科目 | G59: 単位数 | H59: 必須 | I59: 3-1 | J59: 3-2 | K59: 授業科目 | R59: 単位数 | S59: 必須 | T59: 3-1 | U59: 3-2
B60: 情報処理 | G60: 2 | H60: ○ | I60: ○ | J60: ○
A68: ⑧ 「実データ・実課題（学術データ等を含む）を用いた演習など、社会での実例を題材として、「データを読む、説明する、扱う」といった数理・データサイエンス・ＡＩの基本的な活用法に関するもの」の内容を含む授業科目
B70: 授業科目 | F70: 単位数 | G70: 必須 | H70: 2-1 | I70: 2-2 | J70: 2-3 | K70: 授業科目 | Q70: 単位数 | R70: 必須 | S70: 2-1 | T70: 2-2 | U70: 2-3
B71: 情報処理 | F71: 2 | G71: ○ | H71: ○ | I71: ○ | J71: ○
A79: ⑨ 選択「４．オプション」の内容を含む授業科目
B80: 授業科目 | G80: 選択項目 | K80: 授業科目 | R80: 選択項目
A89: ⑩ プログラムを構成する授業の内容
B90: 授業に含まれている内容・要素 | D90: 講義内容
B91: （１）現在進行中の社会変化（第４次産業革命、Society 5.0、データ駆動型社会等）に深く寄与しているものであり、それが自らの生活と密接に結びついている | C91: 1-1 | D91: ・ビッグデータ、IoT、AI、ロボット「情報処理」（第２回） ・データ量の増加、計算機の処理性能の向上「情報処理」（第２回） ・第4次産業革命、Society 5.0、データ駆動型社会「情報処理」（第２回） ・データを起点としたものの見方、人間の知的活動を起点としたものの見方「情報処理」（第１回）
C92: 1-6 | D92: ・AI最新技術の活用例(「情報処理」（第10回) ・AI等を活用した新しいビジネスモデル「情報処理」(第５回)
B93: （２）「社会で活用されているデータ」や「データの活用領域」は非常に広範囲であって、日常生活や社会の課題を解決する有用なツールになり得るもの | C93: 1-2 | D93: ・調査データ、実験データ、人の行動ログデータ、機械の稼働ログデータなど「情報処理」（第２回）
C94: 1-3 | D94: ・データ・AI活用領域の広がり「情報処理」（第５回） ・研究開発、調達、製造、物流、販売、マーケティング、サービスなど「情報処理」（第２回、第５回） ・翻訳・要約・執筆支援、コーディング支援など生成AIの応用「情報処理」（第10回）
B95: （３）様々なデータ利活用の現場におけるデータ利活用事例が示され、様々な適用領域（流通、製造、金融、サービス、インフラ、公共、ヘルスケア等）の知見と組み合わせることで価値を創出するもの | C95: 1-4 | D95: ・データ可視化:複合グラフ、2軸グラフ、多次元の可視化、関係性の可視化「情報処理」（第８回）
C96: 1-5 | D96: ・教育、サービス、公共におけるデータ・AI利活用事例紹介「情報処理」（第５回）
B97: （４）活用に当たっての様々な留意事項（ELSI、個人情報、データ倫理、ＡＩ社会原則等）を考慮し、情報セキュリティや情報漏洩等、データを守る上での留意事項への理解をする | C97: 3-1 | D97: ・倫理的・法的・社会的課題(ELSI:Ethical, Legal and Social Issues)「情報処理」（第６回、第７回） ・個人情報保護、EU一般データ保護規則(GDPR)、忘れられる権利、オプトアウト「情報処理」（第６回、第７回）
C98: 3-2 | D98: ・情報セキュリティ:機密性、完全性、可用性情報セキュリティの3要素「情報処理」(第６回、第７回) ・匿名加工情報、暗号化と復号、ユーザ認証と、パスワード、アクセス制御、悪意ある情報搾取「情報処理」(第６回、第７回) ・情報漏洩等によるセキュリティ事故の事例紹介「情報処理」(第６回、第７回)
...

Sheet 様式２ 履修者等数の実績
S1: 様式２
Q2: ='様式１-1 プログラムを構成する授業科目'!C2 -> 日本福祉大学
A3: プログラムの履修者数等の実績について
A5: ①プログラム開設年度 | C5: 令和５ | E5: 年度
A7: ②大学等全体の男女別学生数 | E7: 男性 | F7: 3087 | G7: 人 | H7: 女性 | I7: 2131 | J7: 人 | K7: （ | L7: 合計 | M7: =F7+I7 -> 5218 | N7: 人 | O7: ）
A9: ③履修者・修了者の実績
B11: 学部・学科名称 | C11: 学生数 | D11: 入学 定員 | E11: 収容 定員 | F11: 令和5年度 | H11: 令和4年度 | J11: 令和3年度 | L11: 令和2年度 | N11: 令和元年度 | P11: 平成30年度 | R11: 履修者数 合計 | S11: 履修率
F12: 履修者数 | G12: 修了者数 | H12: 履修者数 | I12: 修了者数 | J12: 履修者数 | K12: 修了者数 | L12: 履修者数 | M12: 修了者数 | N12: 履修者数 | O12: 修了者数 | P12: 履修者数 | Q12: 修了者数
B13: 社会福祉学部 | C13: 1275 | D13: 400 | E13: 1680 | F13: 260 | G13: 245 | R13: =F13+H13+J13+L13+N13+P13 -> 260 | S13: =R13/E13 -> 0.1547619
B14: 経済学部 | C14: 868 | D14: 200 | E14: 800 | F14: 206 | G14: 178 | R14: =F14+H14+J14+L14+N14+P14 -> 206 | S14: =R14/E14 -> 0.2575
B15: 健康科学部 | C15: 718 | D15: 220 | E15: 850 | F15: 161 | G15: 156 | R15: =F15+H15+J15+L15+N15+P15 -> 161 | S15: =R15/E15 -> 0.18941176
B16: 教育・心理学部 | C16: 956 | D16: 315 | E16: 1260 | F16: 191 | G16: 178 | R16: =F16+H16+J16+L16+N16+P16 -> 191 | S16: =R16/E16 -> 0.1515873
B17: 国際福祉開発学部 | C17: 234 | D17: 80 | E17: 320 | F17: 32 | G17: 32 | R17: =F17+H17+J17+L17+N17+P17 -> 32 | S17: =R17/E17 -> 0.1
B18: 看護学部 | C18: 426 | D18: 100 | E18: 400 | F18: 107 | G18: 106 | R18: =F18+H18+J18+L18+N18+P18 -> 107 | S18: =R18/E18 -> 0.2675
B19: スポーツ科学部 | C19: 702 | D19: 180 | E19: 720 | F19: 200 | G19: 188 | R19: =F19+H19+J19+L19+N19+P19 -> 200 | S19: =R19/E19 -> 0.27777778
B20: 子ども発達学部 | C20: 39 | D20: 0 | E20: 0 | F20: 0 | G20: 0 | R20: =F20+H20+J20+L20+N20+P20 -> 0 | S20: =R20/E20 -> #DIV/0!
R21: =F21+H21+J21+L21+N21+P21 -> 0 | S21: =R21/E21 -> #DIV/0!
R22: =F22+H22+J22+L22+N22+P22 -> 0 | S22: =R22/E22 -> #DIV/0!
R23: =F23+H23+J23+L23+N23+P23 -> 0 | S23: =R23/E23 -> #DIV/0!
R24: =F24+H24+J24+L24+N24+P24 -> 0 | S24: =R24/E24 -> #DIV/0!
R25: =F25+H25+J25+L25+N25+P25 -> 0 | S25: =R25/E25 -> #DIV/0!
R26: =F26+H26+J26+L26+N26+P26 -> 0 | S26: =R26/E26 -> #DIV/0!
R27: =F27+H27+J27+L27+N27+P27 -> 0 | S27: =R27/E27 -> #DIV/0!
R28: =F28+H28+J28+L28+N28+P28 -> 0 | S28: =R28/E28 -> #DIV/0!
R29: =F29+H29+J29+L29+N29+P29 -> 0 | S29: =R29/E29 -> #DIV/0!
R30: =F30+H30+J30+L30+N30+P30 -> 0 | S30: =R30/E30 -> #DIV/0!
R31: =F31+H31+J31+L31+N31+P31 -> 0 | S31: =R31/E31 -> #DIV/0!
R32: =F32+H32+J32+L32+N32+P32 -> 0 | S32: =R32/E32 -> #DIV/0!
B33: 合 計 | C33: =SUM(C13:C32) -> 5218 | D33: =SUM(D13:D32) -> 1495 | E33: =SUM(E13:E32) -> 6030 | F33: =SUM(F13:F32) -> 1157 | G33: =SUM(G13:G32) -> 1083 | H33: =SUM(H13:H32) -> 0 | I33: =SUM(I13:I32) -> 0 | J33: =SUM(J13:J32) -> 0 | ... R33: =SUM(R13:R32) -> 1157 | S33: =R33/E33 -> 0.19187396

Sheet 様式３ 教育の質・履修者数を向上させるための体制・計画
I1: 様式３
G2: 大学等名 | H2: ='様式１-1 プログラムを構成する授業科目'!C2 -> 日本福祉大学
A4: 教育の質・履修者数を向上させるための体制・計画について
A6: ① | B6: 全学の教員数 | C6: (常勤） | E6: 253 | F6: 人 | G6: （非常勤） | H6: 560 | I6: 人
A8: ② | B8: プログラムの授業を教えている教員数 | H8: 7 | I8: 人
A10: ③ | B10: プログラムの運営責任者
B11: （責任者名） | C11: 野尻紀恵 | G11: （役職名） | H11: 学長補佐・全学教育センター長
A13: ④ | B13: プログラムを改善・進化させるための体制（委員会・組織等）
B14: 日本福祉大学全学教育センター教員会議
B16: （責任者名） | C16: 野尻紀恵 | G16: （役職名） | H16: 学長補佐・全学教育センター長
A18: ⑤ | B18: プログラムを改善・進化させるための体制を定める規則名称
B19: 日本福祉大学全学教育センター教員会議規程
A21: ⑥ | B21: 体制の目的
B22: 全学教育センターは全学共通教育科目の開発と運営全般及び学部間共通科目に関わる教育計画編成と授業運営を業務の1つとしている。 プログラムを実施する科目は、全学教育センターが各学部から移管を受けて内容構成をする科目であり、同科目は統括担当教員が各クラスの状況を把握し、毎年度の授業評価とともに次年度の内容の構築、改善・進化を図っている。また、そのプロセスについては「全学教育センター教員会議規程」に基づき設置される全学教育センター教員会議にて点検・評価を行っている。（「全学教育センター教員会議規程」第6条第5号、第6号に規定） ただし、プログラムの改善・進化については、多角的な視点から評価されるべきことから、必要に応じ、全学教育センターから大学組織に対し、審議、確認の要請を行うほか、全学部の教務事項を統括する業務執行機関である全学教務委員会の審議に付し、全学教育センターでその結果を基に協議している。
A34: ⑦ | B34: 具体的な構成員
B35: 全学教育センター長 野尻紀恵 教授 全学教育センター副センター長、共通教育部門長 石田知美 准教授 学修管理・支援部門長 村川弘城 講師 教育開発部門長 髙村秀史 講師 地域連携教育部門長 佐藤大介 講師 ＜事務局体制＞ 学務部学務課 学務部長 中村太郎 学務課長 河合太郎 全学教育センター事務長 吉澤智文
A48: ⑧ | B48: 履修者数・履修率の向上に向けた計画 ※様式１の「履修必須の有無」で「計画がある」としている場合は詳細について記載すること
B49: 令和５年度実績 | C49: ='様式２ 履修者等数の実績'!S33 -> 0.19187396 | E49: 令和６年度予定 | F49: 0.44 | H49: 令和７年度予定 | I49: 0.68
B50: 令和８年度予定 | C50: 0.93 | E50: 令和９年度予定 | F50: 0.99 | H50: 収容定員（名） | I50: ='様式２ 履修者等数の実績'!E33 -> 6030
B51: 具体的な計画
B52: 当該プログラムを実施する科目は、以前より日本福祉大学健康科学部福祉工学科情報工学専修を除き卒業に必要な必修科目、もしくは全員履修科目として位置付けている。健康科学部福祉工学科情報工学専修においても卒業に必要な必修科目である「卒業研究Ⅱ」の履修前提条件科目として位置付けられており、実質的に学生は必ず履修すべき科目として位置付けられている。ただし、編入生・転入生は任意履修科目。 プログラム自体は、令和5年度より実施しており、当該年度の1年生（新入生）の履修率は100％となっている。 今後も当該科目を履修することは必須であるため、履修率についてはほぼ100％を維持する見込みである。
A65: ⑨ | B65: 学部・学科に関係なく希望する学生全員が受講可能となるような必要な体制・取組等
B66: 希望する学生問わず、これまで卒業必修科目、全員履修科目、卒業必修科目を履修するための履修前提条件科目としてきた「情報処理」に関する科目について、内容改訂、コンテンツ作成をすることで、1年生の全学生が受講できるように整備している。 「情報処理演習」「情報処理演習Ⅰ」は健康科学部福祉工学科情報工学専修を除き、学部の総合基礎科目として開設されており、その教育内容は全学教育センターに移管されて実施している。 健康科学部福祉工学科情報工学専修では令和5年度より「情報処理」の教育内容を全学教育センターに移管して実施しており、全学部でプログラム修了に必要なカリキュラムを実施できる体制を整えている。
A79: ⑩ | B79: できる限り多くの学生が履修できるような具体的な周知方法・取組
B80: 卒業必修科目、全員履修科目、卒業必修科目を履修するための履修前提条件科目に位置づいており全学生が履修する構造となっている。 履修要項、時間割、履修システム等を用いて、履修に必要な情報が確認できるようにしている。 また科目の開講時に、担当教員を通じて、科目の趣旨や目的について伝えるようにしている。
A93: ⑪ | B93: できる限り多くの学生が履修・修得できるようなサポート体制
B94: 専任教員、および外部委託講師による指導教員を配置、また履修人数によりティーチング・アシスタントを配置し、学生の履修や修学についての相談を受けている。 またICT推進室でも事務職員が履修などのサポートを行っている。 2021年度よりBYODを推進しつつ、PCを携行できない学生向けに貸し出しサービスを提供している。また、図書館で関連分野の学生向け書籍を整備している。
A107: ⑫ | B107: 授業時間内外で学習指導、質問を受け付ける具体的な仕組み
B108: 授業時間内に質問を受け付けているほか、学内LMSを用いて授業時間外でも質問を受け 付け、回答を行っている。またオフィスアワーを設け、受講生が直接教員の研究室を訪ねて学習指導が受けられるようにしている。

Sheet 様式４　自己点検・評価
I1: 様式４
H2: 大学等名 | I2: ='様式１-1 プログラムを構成する授業科目'!C2 -> 日本福祉大学
A3: 自己点検・評価について
A5: ① | B5: プログラムの自己点検・評価を行う体制（委員会・組織等）
B6: 日本福祉大学全学教育センター教員会議
D8: （責任者名） | E8: 野尻紀恵 | G8: （役職名） | H8: 学長補佐・全学教育センター長
A10: ② | B10: 自己点検・評価体制における意見等
B11: 自己点検・評価の視点 | E11: 自己点検・評価体制における意見・結果・改善に向けた取組等
B12: 学内からの視点
C13: プログラムの履修・修得状況 | E13: プログラムは、通学課程全学部で開講されている科目で構成しており、該当の科目は各学部の卒業必修科目、全員履修科目、卒業必修科目を履修するための履修前提条件科目として位置付けている。1年次に全ての学生が履修登録を行っている。修得に向けては、各講における課題提出状況、オンデマンドコンテンツ視聴履歴、進捗を本学LMSシステム（nfu.jp）にて把握することができる。今年度においては、履修者数1157名のうち、修了者1083名（93.6％）という結果となった。本プログラムの実施は2023（令和5）年度からとなるため、経年での比較はできないが導入前の授業内容での修了者の割合と大きな差は見られなかった。
C14: 学修成果 | E14: 学修成果としては、社会の変化と数理・データサイエンス・A Iとの関係性と、それらが自らに対して与える影響について理解することを目指している。このため学生に対しては、一般的な影響などに関してはオンデマンドで、自らに対する影響などは、ディスカッションやレポートによって考える機会を与えている。これらのレポートにおける理解度に加え、授業評価アンケートによる理解や満足度などをもとに、本講義の担当者や事務局などが一体となってプログラムの評価・改善を行っている。
C15: 学生アンケート等を通じた学生の内容の理解度 | E15: 数理・データサイエンス・AI教育に関する問いに関して、教員の説明のわかりやすさ、グループワークが学びを深めるのに役に立ったかなどに関しては、肯定的な意見が8割を超えていた。また、より高度な内容を受講したいかの質問に関しても、肯定的な意見が50%を超えており、教育内容や学修効果を満たしていたといえる。 授業内容の一部で導入したオンデマンドコンテンツに関する質問に関しては、全体的に集中していたと答えた学生は半数を超え、コンテンツの利点を生かした教育内容がおおむね達成できたと評価できる。 また、7割の学生が当該教育内容についてオンデマンドでの学びやすさは対面の講義と同等かそれ以上であると答えていた。
C16: 学生アンケート等を通じた後輩等他の学生への推奨度 | E16: プログラムについては、通学課程全学部で開講されている科目で構成しており、該当の科目は各学部の卒業必修科目、全員履修科目、卒業必修科目を履修するための履修前提条件科目として位置付けており、1年次入学生は履修推奨度によらず履修するものであるが、授業評価アンケートの結果を踏まえると、教員の説明のわかりやすさ、グループワークが学びを深めるのに役に立ったかなどに関しては、肯定的な意見が8割を超えていた。また授業全体の満足度、将来に役に立つと思うか、といった問いに対しても肯定的な意見が8割を超えており、特に将来に役に立つと感じた学生は9割を超えていた、内容としては十分に履修を推奨できるものであると言える。
C17: 全学的な履修者数、履修率向上に向けた計画の達成・進捗状況 | E17: 通学課程全学部で開講されている科目で構成しており、該当の科目は各学部の卒業必修科目、全員履修科目、卒業必修科目を履修するための前提条件科目として位置付けているため、現状対応することは見受けられない。 ただし、本学の全ての学生が履修するプログラムとして、また今後の各学部カリキュラム改正等においても、有効的な必修科目、全員履修科目として編成されるべく、履修者の状況を見ながらプログラムの見直しや点検を行っていくこととしている。
B18: 学外からの視点
C19: 教育プログラム修了者の進路、活躍状況、企業等の評価 | E19: プログラムは2024（令和5）年度より実施しているため、現段階での進路、活躍状況、企業等の評価を計ることはできないが、今後就職支援を行う部局との連携により進路調査や卒後調査も含めて集約の実施を検討する。
C20: 産業界からの視点を含めた教育プログラム内容・手法等への意見 | E20: 本学の外部評価委員会にて教育プログラム内容や手法について報告を実施し、多様な分野の委員より意見聴取を行う機会を設けている。 ＜主な意見＞ 福祉分野：ICT導入（AI、UDトーク、ロボットなど）が近年話題となることも多く、機器トラブルへの対応については知識の有無に大きな差を感じる。またスキルを有する職員がいると業務の効率化がかなり進む印象があり、基礎的な知識を持って社会に出ることを期待したい。 企業分野：収集したデータの分析・活用方法を知ることは重要であるため、そうした視点での活用事例を提供するなど、協力できることもある。 など、プログラムの充実に対しての助言も得ることができている。
B21: 数理・データサイエンス・ＡＩを「学ぶ楽しさ」「学ぶことの意義」を理解させること | E21: 数理・データサイエンス・AIに関する話題は、ゲームでの戦略などをもとにAIの話題に触れたりすることで、学生の興味に沿うようにしている。普段の暮らしの中で興味があるような内容と数理・データサイエンス・AIとの関わりを示し、学ぶことによって生活がより鮮明になり、これからの社会への予測が立てられるようになることから、学ぶことが楽しくなるように工夫している。また、卒業後の進路や将来と新しい技術やそれに伴う心構えとを常に意識させながら実施している。グループワークやレポートなどにおいても卒業後を意識するテーマにしており、それぞれの学生の目指す専門的なものとの関係性を見出し、学ぶことの意義へとつなげている。
B22: 内容・水準を維持・向上しつつ、より「分かりやすい」授業とすること ※社会の変化や生成AI等の技術の発展を踏まえて教育内容を継続的に見直すなど、より教育効果の高まる授業内容・方法とするための取組や仕組みについても該当があれば記載 | E22: 本学は、全学生が履修する形で行なうこと、異なった視点を持つ他の人と価値観をすり合わせつつ知見を共有させること、また、聴覚障害などの学生に対する情報保障を行うことといった条件の中で仕組みを検討してきた。このため、日進月歩で進化していく内容に関しては、グループワークの中で新しい情報を調査、共有させることとし、これまでの歴史や、考え方、目指すものなど、すぐに変わらず、知識として伝達できるものに関しては、オンデマンドで実施することとした。内容の質やレベルに関しては、高等学校までの習熟度にも沿うように徐々に改修を進めていくことを最初期から検討しており、今後、より良い教材へと向上していくことも見込まれる。
