Workbook

Sheet 様式１ー１　プログラムを構成する授業科目
T1: 様式１ー１ | V1: 「学部・学科によって、修了要件は相違する」場合は、本シートを複製の上＜様式１－〇＞と枝番号を付してください
B2: 大学等名 | C2: 朝日大学
B3: プログラム名 | C3: 朝日大学情報リテラシー教育プログラム
A5: プログラムを構成する授業科目について
A7: ① 教育プログラムの修了要件 | L7: 学部・学科によって、修了要件は相違する
A9: ② 対象となる学部・学科名称
B11: 法学部
A14: ③ 修了要件
B15: プログラムを構成する「一般的包括的教育科目」（情報リテラシー）２単位、「一般的包括的教育科目」（数理・データサイエンス・ＡＩ）２単位の合計４単位を取得すること。 | X15: 【プルダウンリスト】
X16: 令和５年度以前より、履修することが必須のプログラムとして実施
X17: 令和８年度までに履修必須とする計画
X18: 令和９年度以降に履修必須とする計画、又は未定
B22: 必要最低科目数・単位数 | E22: 2 | F22: 科目 | H22: 4 | I22: 単位 | M22: 履修必須の有無 | N22: 令和５年度以前より、履修することが必須のプログラムとして実施
A24: ④ 現在進行中の社会変化（第４次産業革命、Society 5.0、データ駆動型社会等）に深く寄与しているものであり、それが自らの生活と密接に結びついている」の内容を含む授業科目
B26: 授業科目 | G26: 単位数 | H26: 必須 | I26: 1-1 | J26: 1-6 | K26: 授業科目 | R26: 単位数 | S26: 必須 | T26: 1-1 | U26: 1-6
B27: 情報リテラシー | G27: 2 | H27: ○ | I27: ○ | J27: ○
B28: 数理・データサイエンス・ＡＩ | G28: 2 | H28: ○ | I28: ○ | J28: ○
A35: ⑤ 「社会で活用されているデータ」や「データの活用領域」は非常に広範囲であって、日常生活や社会の課題を解決する有用なツールになり得るもの」の内容を含む授業科目
B37: 授業科目 | G37: 単位数 | H37: 必須 | I37: 1-2 | J37: 1-3 | K37: 授業科目 | R37: 単位数 | S37: 必須 | T37: 1-2 | U37: 1-3
B38: 情報リテラシー | G38: 2 | H38: ○ | I38: ○
B39: 数理・データサイエンス・ＡＩ | G39: 2 | H39: ○ | I39: ○ | J39: ○
A46: ⑥ 「様々なデータ利活用の現場におけるデータ利活用事例が示され、様々な適用領域（流通、製造、金融、サービス、インフラ、公共、ヘルスケア等）の知見と組み合わせることで価値を創出するもの」の内容を含む授業科目
B48: 授業科目 | G48: 単位数 | H48: 必須 | I48: 1-4 | J48: 1-5 | K48: 授業科目 | R48: 単位数 | S48: 必須 | T48: 1-4 | U48: 1-5
B49: 数理・データサイエンス・ＡＩ | G49: 2 | H49: ○ | I49: ○ | J49: ○
A57: ⑦ 「活用に当たっての様々な留意事項（ELSI、個人情報、データ倫理、ＡＩ社会原則等）を考慮し、情報セキュリティや情報漏洩等、データを守る上での留意事項への理解をする」の内容を含む授業科目
B59: 授業科目 | G59: 単位数 | H59: 必須 | I59: 3-1 | J59: 3-2 | K59: 授業科目 | R59: 単位数 | S59: 必須 | T59: 3-1 | U59: 3-2
B60: 情報リテラシー | G60: 2 | H60: ○ | I60: ○ | J60: ○
B61: 数理・データサイエンス・ＡＩ | G61: 2 | H61: ○ | I61: ○ | J61: ○
A68: ⑧ 「実データ・実課題（学術データ等を含む）を用いた演習など、社会での実例を題材として、「データを読む、説明する、扱う」といった数理・データサイエンス・ＡＩの基本的な活用法に関するもの」の内容を含む授業科目
B70: 授業科目 | F70: 単位数 | G70: 必須 | H70: 2-1 | I70: 2-2 | J70: 2-3 | K70: 授業科目 | Q70: 単位数 | R70: 必須 | S70: 2-1 | T70: 2-2 | U70: 2-3
B71: 数理・データサイエンス・ＡＩ | F71: 2 | G71: ○ | H71: ○ | I71: ○ | J71: ○
B72: 情報リテラシー | F72: 2 | G72: ○ | I72: ○ | J72: ○
A79: ⑨ 選択「４．オプション」の内容を含む授業科目
B80: 授業科目 | G80: 選択項目 | K80: 授業科目 | R80: 選択項目
A89: ⑩ プログラムを構成する授業の内容
B90: 授業に含まれている内容・要素 | D90: 講義内容
B91: （１）現在進行中の社会変化（第４次産業革命、Society 5.0、データ駆動型社会等）に深く寄与しているものであり、それが自らの生活と密接に結びついている | C91: 1-1 | D91: ・現在進行中の社会変化やそれに応じて学ぶべき情報倫理、情報セキュリティについて学ぶ 「情報リテラシー」（１回目、３回目、４回目） ・データサイエンスAI概論、サイバー法、IoT・データ駆動型社会 「数理データサイエンス・ＡＩ」（１回目）
C92: 1-6 | D92: ・高度情報化社会に必要とされる知識や求められる人材について学ぶ 「情報リテラシー」（１回目） ・データ・AIの活用事例、法的推論モデル（法的三段論法）、法的推論モデル（高度な法的推論モデル）、法的推論モデル（ニューラルネットと深層学習） 「数理データサイエンス・ＡＩ」（２回目）
B93: （２）「社会で活用されているデータ」や「データの活用領域」は非常に広範囲であって、日常生活や社会の課題を解決する有用なツールになり得るもの | C93: 1-2 | D93: ・データサイエンスやオープンデータについて触れる 「情報リテラシー」（１回目） ・オープンデータ（犯罪統計データ・犯罪オープンデータ） 「数理・データサイエンス・ＡＩ」（４回目） ・オープンデータ (国保年金・厚生年金データ) 「数理・データサイエンス・ＡＩ」（７回目） ・量的データと質的データ、離散データと連続データ 「数理・データサイエンス・ＡＩ」（６回目）
C94: 1-3 | D94: ・AIの活用領域の広がり 「数理・データサイエンス・ＡＩ」（１回目・２回目） ・深層学習の活用領域の広がり 「数理・データサイエンス・ＡＩ」（１回目・２回目）
...

Sheet 様式１ー２　プログラムを構成する授業科目
T1: 様式１ー２ | V1: 「学部・学科によって、修了要件は相違する」場合は、本シートを複製の上＜様式１－〇＞と枝番号を付してください
B2: 大学等名 | C2: 朝日大学
B3: プログラム名 | C3: 朝日大学情報リテラシー教育プログラム
A5: プログラムを構成する授業科目について
A7: ① 教育プログラムの修了要件 | L7: 学部・学科によって、修了要件は相違する
A9: ② 対象となる学部・学科名称
B11: 経営学部
A14: ③ 修了要件
B15: プログラムを構成する「基礎教育科目」（情報リテラシー）２単位、「基礎教育科目」（数理・データサイエンス）２単位の合計４単位を取得すること。 | X15: 【プルダウンリスト】
X16: 令和５年度以前より、履修することが必須のプログラムとして実施
X17: 令和８年度までに履修必須とする計画
X18: 令和９年度以降に履修必須とする計画、又は未定
B22: 必要最低科目数・単位数 | E22: 2 | F22: 科目 | H22: 4 | I22: 単位 | M22: 履修必須の有無 | N22: 令和５年度以前より、履修することが必須のプログラムとして実施
A24: ④ 現在進行中の社会変化（第４次産業革命、Society 5.0、データ駆動型社会等）に深く寄与しているものであり、それが自らの生活と密接に結びついている」の内容を含む授業科目
B26: 授業科目 | G26: 単位数 | H26: 必須 | I26: 1-1 | J26: 1-6 | K26: 授業科目 | R26: 単位数 | S26: 必須 | T26: 1-1 | U26: 1-6
B27: 情報リテラシー | G27: 2 | H27: ○ | I27: ○ | J27: ○
B28: 数理・データサイエンス | G28: 2 | H28: ○ | I28: ○ | J28: ○
A35: ⑤ 「社会で活用されているデータ」や「データの活用領域」は非常に広範囲であって、日常生活や社会の課題を解決する有用なツールになり得るもの」の内容を含む授業科目
B37: 授業科目 | G37: 単位数 | H37: 必須 | I37: 1-2 | J37: 1-3 | K37: 授業科目 | R37: 単位数 | S37: 必須 | T37: 1-2 | U37: 1-3
B38: 情報リテラシー | G38: 2 | H38: ○ | I38: ○
B39: 数理・データサイエンス | G39: 2 | H39: ○ | I39: ○ | J39: ○
A46: ⑥ 「様々なデータ利活用の現場におけるデータ利活用事例が示され、様々な適用領域（流通、製造、金融、サービス、インフラ、公共、ヘルスケア等）の知見と組み合わせることで価値を創出するもの」の内容を含む授業科目
B48: 授業科目 | G48: 単位数 | H48: 必須 | I48: 1-4 | J48: 1-5 | K48: 授業科目 | R48: 単位数 | S48: 必須 | T48: 1-4 | U48: 1-5
B49: 数理・データサイエンス | G49: 2 | H49: ○ | I49: ○ | J49: ○
A57: ⑦ 「活用に当たっての様々な留意事項（ELSI、個人情報、データ倫理、ＡＩ社会原則等）を考慮し、情報セキュリティや情報漏洩等、データを守る上での留意事項への理解をする」の内容を含む授業科目
B59: 授業科目 | G59: 単位数 | H59: 必須 | I59: 3-1 | J59: 3-2 | K59: 授業科目 | R59: 単位数 | S59: 必須 | T59: 3-1 | U59: 3-2
B60: 情報リテラシー | G60: 2 | H60: ○ | I60: ○ | J60: ○
A68: ⑧ 「実データ・実課題（学術データ等を含む）を用いた演習など、社会での実例を題材として、「データを読む、説明する、扱う」といった数理・データサイエンス・ＡＩの基本的な活用法に関するもの」の内容を含む授業科目
B70: 授業科目 | F70: 単位数 | G70: 必須 | H70: 2-1 | I70: 2-2 | J70: 2-3 | K70: 授業科目 | Q70: 単位数 | R70: 必須 | S70: 2-1 | T70: 2-2 | U70: 2-3
B71: 数理・データサイエンス | F71: 2 | G71: ○ | H71: ○ | J71: ○
B72: 情報リテラシー | F72: 2 | G72: ○ | I72: ○ | J72: ○
A79: ⑨ 選択「４．オプション」の内容を含む授業科目
B80: 授業科目 | G80: 選択項目 | K80: 授業科目 | R80: 選択項目
A89: ⑩ プログラムを構成する授業の内容
B90: 授業に含まれている内容・要素 | D90: 講義内容
B91: （１）現在進行中の社会変化（第４次産業革命、Society 5.0、データ駆動型社会等）に深く寄与しているものであり、それが自らの生活と密接に結びついている | C91: 1-1 | D91: ・現在進行中の社会変化やそれに応じて学ぶべき情報倫理、情報セキュリティについて学ぶ 「情報リテラシー」（１回目、３回目、４回目） ・データ駆動型社会について学ぶ 「数理データサイエンス」（１回目、１３回目）
C92: 1-6 | D92: ・高度情報化社会に必要とされる知識や求められる人材について学ぶ 「情報リテラシー」（１回目） ・AIについて知識や使い方を学ぶ 「数理データサイエンス」（１１回目、１３回目）
B93: （２）「社会で活用されているデータ」や「データの活用領域」は非常に広範囲であって、日常生活や社会の課題を解決する有用なツールになり得るもの | C93: 1-2 | D93: ・データサイエンスやオープンデータについて触れる 「情報リテラシー」（１回目） ・オープンデータについて学び、実際にデータをダウンロードしながら活用法を学ぶ 「数理・データサイエンス」（１回目）
C94: 1-3 | D94: ・オープンデータについて学び、実際にデータをダウンロードしながら活用法を学ぶ 「数理・データサイエンス」（１回目） ・AIの活用領域について学び、実習をしながら使い方や気をつけるべき点を学ぶ 「数理・データサイエンス」（９回目、１１回目）
B95: （３）様々なデータ利活用の現場におけるデータ利活用事例が示され、様々な適用領域（流通、製造、金融、サービス、インフラ、公共、ヘルスケア等）の知見と組み合わせることで価値を創出するもの | C95: 1-4 | D95: ・データ分析の基礎から活用までを学ぶ。データ分析の知識だけでなくデータから得られる結果を報告書にまとめ、分析に関わる一連の流れを理解し、その技術を身につける 「数理・データサイエンス」（２回目～７回目）
...

Sheet 様式１ー３　プログラムを構成する授業科目
T1: 様式１ー３ | V1: 「学部・学科によって、修了要件は相違する」場合は、本シートを複製の上＜様式１－〇＞と枝番号を付してください
B2: 大学等名 | C2: 朝日大学
B3: プログラム名 | C3: 朝日大学情報リテラシー教育プログラム
A5: プログラムを構成する授業科目について
A7: ① 教育プログラムの修了要件 | L7: 学部・学科によって、修了要件は相違する
A9: ② 対象となる学部・学科名称
B11: 保健医療学部
A14: ③ 修了要件
B15: 看護学科は、プログラムを構成する「教養基礎科目」（情報リテラシー）1単位、「教養基礎科目」（数理・データサイエンス）1単位の合計２単位を取得すること。 健康スポーツ科学科は、プログラムを構成する「基礎教育科目」（情報リテラシー）１単位、「基礎教育科目」（数理・データサイエンス）１単位の合計２単位を取得すること。 | X15: 【プルダウンリスト】
X16: 令和５年度以前より、履修することが必須のプログラムとして実施
X17: 令和８年度までに履修必須とする計画
X18: 令和９年度以降に履修必須とする計画、又は未定
B22: 必要最低科目数・単位数 | E22: 2 | F22: 科目 | H22: 2 | I22: 単位 | M22: 履修必須の有無 | N22: 令和５年度以前より、履修することが必須のプログラムとして実施
A24: ④ 現在進行中の社会変化（４次産業革命、Society 5.0、データ駆動型社会等）に深く寄与しているものであり、それが自らの生活と密接に結びついている」の内容を含む授業科目
B26: 授業科目 | G26: 単位数 | H26: 必須 | I26: 1-1 | J26: 1-6 | K26: 授業科目 | R26: 単位数 | S26: 必須 | T26: 1-1 | U26: 1-6
B27: 情報リテラシー | G27: 1 | H27: ○ | I27: ○ | J27: ○
B28: 数理・データサイエンス | G28: 1 | H28: ○ | I28: ○ | J28: ○
A35: ⑤ 「社会で活用されているデータ」や「データの活用領域」は非常に広範囲であって、日常生活や社会の課題を解決する有用なツールになり得るもの」の内容を含む授業科目
B37: 授業科目 | G37: 単位数 | H37: 必須 | I37: 1-2 | J37: 1-3 | K37: 授業科目 | R37: 単位数 | S37: 必須 | T37: 1-2 | U37: 1-3
B38: 情報リテラシー | G38: 1 | H38: ○ | I38: ○
B39: 数理・データサイエンス | G39: 1 | H39: ○ | I39: ○ | J39: ○
A46: ⑥ 「様々なデータ利活用の現場におけるデータ利活用事例が示され、様々な適用領域（流通、製造、金融、サービス、インフラ、公共、ヘルスケア等）の知見と組み合わせることで価値を創出するもの」の内容を含む授業科目
B48: 授業科目 | G48: 単位数 | H48: 必須 | I48: 1-4 | J48: 1-5 | K48: 授業科目 | R48: 単位数 | S48: 必須 | T48: 1-4 | U48: 1-5
B49: 数理･データサイエンス | G49: 1 | H49: ○ | I49: ○ | J49: ○
A57: ⑦ 「活用に当たっての様々な留意事項（ELSI、個人情報、データ倫理、ＡＩ社会原則等）を考慮し、情報セキュリティや情報漏洩等、データを守る上での留意事項への理解をする」の内容を含む授業科目
B59: 授業科目 | G59: 単位数 | H59: 必須 | I59: 3-1 | J59: 3-2 | K59: 授業科目 | R59: 単位数 | S59: 必須 | T59: 3-1 | U59: 3-2
B60: 情報リテラシー | G60: 1 | H60: ○ | I60: ○ | J60: ○
A68: ⑧ 「実データ・実課題（学術データ等を含む）を用いた演習など、社会での実例を題材として、「データを読む、説明する、扱う」といった数理・データサイエンス・ＡＩの基本的な活用法に関するもの」の内容を含む授業科目
B70: 授業科目 | F70: 単位数 | G70: 必須 | H70: 2-1 | I70: 2-2 | J70: 2-3 | K70: 授業科目 | Q70: 単位数 | R70: 必須 | S70: 2-1 | T70: 2-2 | U70: 2-3
B71: 情報リテラシー | F71: 1 | G71: ○ | H71: ○ | I71: ○ | J71: ○
B72: 数理･データサイエンス | F72: 1 | G72: ○ | H72: ○ | I72: ○ | J72: ○
A79: ⑨ 選択「４．オプション」の内容を含む授業科目
B80: 授業科目 | G80: 選択項目 | K80: 授業科目 | R80: 選択項目
B81: 数理･データサイエンス | G81: 4‐2アルゴリズム基礎
B82: 数理･データサイエンス | G82: 4‐3データ構造とプログラミング基礎
B83: 数理･データサイエンス | G83: 4‐4時系列データ解析
A89: ⑩ プログラムを構成する授業の内容
B90: 授業に含まれている内容・要素 | D90: 講義内容
B91: （１）現在進行中の社会変化（４次産業革命、Society 5.0、データ駆動型社会等）に深く寄与しているものであり、それが自らの生活と密接に結びついている | C91: 1-1 | D91: 看護学科 ・社会の移り変わり、これからの社会 「数理･データサイエンス」(１回目） ・第4次産業革命、Society5.0、情報通信技術の進歩 「数理･データサイエンス」(１回目） ・人工知能（AI)、ビッグデータ、AIとビッグデータを活用したテクノロジー 「数理･データサイエンス」(１回目） ・AIで変わる私たちのくらし 「数理･データサイエンス」（１目） 健康スポーツ科学科 ・現在進行中の社会変化やそれに応じて学ぶべき情報倫理、情報セキュリティについて学ぶ 「情報リテラシー」（１回目、３回目、４回目） ・データ駆動型社会について学ぶ 「数理データサイエンス」（第１回、第１３回）
C92: 1-6 | D92: 看護学科 ・人とAIの共存、求められる人材 「数理･データサイエンス」(１回目） ・ＡＩ最新技術の活用事例 「数理･データサイエンス」(１回目） 健康スポーツ科学科 ・高度情報化社会に必要とされる知識や求められる人材について学ぶ 「情報リテラシー」（１回目） ・AIについて知識や使い方を学ぶ 「数理データサイエンス」（１１回目、１３回目）
...

Sheet 様式１ー４　プログラムを構成する授業科目
T1: 様式１ー４ | V1: 「学部・学科によって、修了要件は相違する」場合は、本シートを複製の上＜様式１－〇＞と枝番号を付してください
B2: 大学等名 | C2: 朝日大学
B3: プログラム名 | C3: 朝日大学情報リテラシー教育プログラム
A5: プログラムを構成する授業科目について
A7: ① 教育プログラムの修了要件 | L7: 学部・学科によって、修了要件は相違する
A9: ② 対象となる学部・学科名称
B11: 歯学部
A14: ③ 修了要件
B15: プログラムを構成する「基礎教養系」（情報処理演習）２単位、「基礎教養系」（数理基礎）２単位、「基礎教養系」（データサイエンス）1単位の合計５単位を取得すること。 | X15: 【プルダウンリスト】
X16: 令和５年度以前より、履修することが必須のプログラムとして実施
X17: 令和８年度までに履修必須とする計画
X18: 令和９年度以降に履修必須とする計画、又は未定
B22: 必要最低科目数・単位数 | E22: 3 | F22: 科目 | H22: 5 | I22: 単位 | M22: 履修必須の有無 | N22: 令和５年度以前より、履修することが必須のプログラムとして実施
A24: ④ 現在進行中の社会変化（第４次産業革命、Society 5.0、データ駆動型社会等）に深く寄与しているものであり、それが自らの生活と密接に結びついている」の内容を含む授業科目
B26: 授業科目 | G26: 単位数 | H26: 必須 | I26: 1-1 | J26: 1-6 | K26: 授業科目 | R26: 単位数 | S26: 必須 | T26: 1-1 | U26: 1-6
B27: 情報処理演習 | G27: 2 | H27: ○ | I27: ○ | J27: ○
A35: ⑤ 「社会で活用されているデータ」や「データの活用領域」は非常に広範囲であって、日常生活や社会の課題を解決する有用なツールになり得るもの」の内容を含む授業科目
B37: 授業科目 | G37: 単位数 | H37: 必須 | I37: 1-2 | J37: 1-3 | K37: 授業科目 | R37: 単位数 | S37: 必須 | T37: 1-2 | U37: 1-3
B38: 数理基礎 | G38: 2 | H38: ○ | I38: ○
B39: データサイエンス | G39: 1 | H39: ○ | J39: ○
A46: ⑥ 「様々なデータ利活用の現場におけるデータ利活用事例が示され、様々な適用領域（流通、製造、金融、サービス、インフラ、公共、ヘルスケア等）の知見と組み合わせることで価値を創出するもの」の内容を含む授業科目
B48: 授業科目 | G48: 単位数 | H48: 必須 | I48: 1-4 | J48: 1-5 | K48: 授業科目 | R48: 単位数 | S48: 必須 | T48: 1-4 | U48: 1-5
B49: 数理基礎 | G49: 2 | H49: ○ | I49: ○ | J49: ○
B50: データサイエンス | G50: 1 | H50: ○ | I50: ○
A57: ⑦ 「活用に当たっての様々な留意事項（ELSI、個人情報、データ倫理、ＡＩ社会原則等）を考慮し、情報セキュリティや情報漏洩等、データを守る上での留意事項への理解をする」の内容を含む授業科目
B59: 授業科目 | G59: 単位数 | H59: 必須 | I59: 3-1 | J59: 3-2 | K59: 授業科目 | R59: 単位数 | S59: 必須 | T59: 3-1 | U59: 3-2
B60: 情報処理演習 | G60: 2 | H60: ○ | I60: ○ | J60: ○
B61: 数理基礎 | G61: 2 | H61: ○ | I61: ○
A68: ⑧ 「実データ・実課題（学術データ等を含む）を用いた演習など、社会での実例を題材として、「データを読む、説明する、扱う」といった数理・データサイエンス・ＡＩの基本的な活用法に関するもの」の内容を含む授業科目
B70: 授業科目 | F70: 単位数 | G70: 必須 | H70: 2-1 | I70: 2-2 | J70: 2-3 | K70: 授業科目 | Q70: 単位数 | R70: 必須 | S70: 2-1 | T70: 2-2 | U70: 2-3
B71: 情報処理演習 | F71: 2 | G71: ○ | I71: ○ | J71: ○
B72: 数理基礎 | F72: 2 | G72: ○ | H72: ○ | I72: ○
B73: データサイエンス | F73: 1 | G73: ○ | H73: ○ | I73: ○
A79: ⑨ 選択「４．オプション」の内容を含む授業科目
B80: 授業科目 | G80: 選択項目 | K80: 授業科目 | R80: 選択項目
B81: 情報処理演習 | G81: 4‐2アルゴリズム基礎
B82: 情報処理演習 | G82: 4‐3データ構造とプログラミング基礎
B83: 数理基礎 | G83: 4-1統計および数理基礎
B84: データサイエンス | G84: 4-1統計および数理基礎
A89: ⑩ プログラムを構成する授業の内容
...

Sheet 様式２ 履修者等数の実績
S1: 様式２
Q2: ='様式１ー１ プログラムを構成する授業科目'!C2 -> 朝日大学
A3: プログラムの履修者数等の実績について
A5: ①プログラム開設年度 | C5: 令和５ | E5: 年度
A7: ②大学等全体の男女別学生数 | E7: 男性 | F7: 1493 | G7: 人 | H7: 女性 | I7: 882 | J7: 人 | K7: （ | L7: 合計 | M7: =F7+I7 -> 2375 | N7: 人 | O7: ）
A9: ③履修者・修了者の実績
B11: 学部・学科名称 | C11: 学生数 | D11: 入学 定員 | E11: 収容 定員 | F11: 令和5年度 | H11: 令和4年度 | J11: 令和3年度 | L11: 令和2年度 | N11: 令和元年度 | P11: 平成30年度 | R11: 履修者数 合計 | S11: 履修率
F12: 履修者数 | G12: 修了者数 | H12: 履修者数 | I12: 修了者数 | J12: 履修者数 | K12: 修了者数 | L12: 履修者数 | M12: 修了者数 | N12: 履修者数 | O12: 修了者数 | P12: 履修者数 | Q12: 修了者数
B13: 法学部法学科 | C13: 297 | D13: 80 | E13: 320 | F13: 72 | G13: 67 | R13: =F13+H13+J13+L13+N13+P13 -> 72 | S13: =R13/E13 -> 0.225
B14: 経営学部経営学科 | C14: 455 | D14: 100 | E14: 400 | F14: 107 | G14: 101 | R14: =F14+H14+J14+L14+N14+P14 -> 107 | S14: =R14/E14 -> 0.2675
B15: 保健医療学部 | C15: 783 | D15: 200 | E15: 800 | F15: 221 | G15: 207 | R15: =F15+H15+J15+L15+N15+P15 -> 221 | S15: =R15/E15 -> 0.27625
B16: 歯学部歯学科 | C16: 840 | D16: 140 | E16: 840 | F16: 150 | G16: 130 | R16: =F16+H16+J16+L16+N16+P16 -> 150 | S16: =R16/E16 -> 0.17857143
R17: =F17+H17+J17+L17+N17+P17 -> 0 | S17: =R17/E17 -> #DIV/0!
R18: =F18+H18+J18+L18+N18+P18 -> 0 | S18: =R18/E18 -> #DIV/0!
R19: =F19+H19+J19+L19+N19+P19 -> 0 | S19: =R19/E19 -> #DIV/0!
R20: =F20+H20+J20+L20+N20+P20 -> 0 | S20: =R20/E20 -> #DIV/0!
R21: =F21+H21+J21+L21+N21+P21 -> 0 | S21: =R21/E21 -> #DIV/0!
R22: =F22+H22+J22+L22+N22+P22 -> 0 | S22: =R22/E22 -> #DIV/0!
R23: =F23+H23+J23+L23+N23+P23 -> 0 | S23: =R23/E23 -> #DIV/0!
R24: =F24+H24+J24+L24+N24+P24 -> 0 | S24: =R24/E24 -> #DIV/0!
R25: =F25+H25+J25+L25+N25+P25 -> 0 | S25: =R25/E25 -> #DIV/0!
R26: =F26+H26+J26+L26+N26+P26 -> 0 | S26: =R26/E26 -> #DIV/0!
R27: =F27+H27+J27+L27+N27+P27 -> 0 | S27: =R27/E27 -> #DIV/0!
R28: =F28+H28+J28+L28+N28+P28 -> 0 | S28: =R28/E28 -> #DIV/0!
... R32: =F32+H32+J32+L32+N32+P32 -> 0 | S32: =R32/E32 -> #DIV/0!
B33: 合 計 | C33: =SUM(C13:C32) -> 2375 | D33: =SUM(D13:D32) -> 520 | E33: =SUM(E13:E32) -> 2360 | F33: =SUM(F13:F32) -> 550 | G33: =SUM(G13:G32) -> 505 | H33: =SUM(H13:H32) -> 0 | I33: =SUM(I13:I32) -> 0 | J33: =SUM(J13:J32) -> 0 | ... R33: =SUM(R13:R32) -> 550 | S33: =R33/E33 -> 0.23305085

Sheet 様式３ 教育の質・履修者数を向上させるための体制・計画
I1: 様式３
G2: 大学等名 | H2: ='様式１ー１ プログラムを構成する授業科目'!C2 -> 朝日大学
A4: 教育の質・履修者数を向上させるための体制・計画について
A6: ① | B6: 全学の教員数 | C6: (常勤） | E6: 306 | F6: 人 | G6: （非常勤） | H6: 523 | I6: 人
A8: ② | B8: プログラムの授業を教えている教員数 | H8: 16 | I8: 人
A10: ③ | B10: プログラムの運営責任者
B11: （責任者名） | C11: 森下 伊三男 | G11: （役職名） | H11: 副学長
A13: ④ | B13: プログラムを改善・進化させるための体制（委員会・組織等）
B14: 朝日大学ＦＤ活動推進委員会数理・データサイエンス・ＡＩ教育専門部会
B16: （責任者名） | C16: 森下 伊三男 | G16: （役職名） | H16: 副学長
A18: ⑤ | B18: プログラムを改善・進化させるための体制を定める規則名称
B19: 朝日大学ＦＤ活動推進委員会数理・データサイエンス・ＡＩ教育専門部会規程
A21: ⑥ | B21: 体制の目的
B22: 学部及び研究科等における分野を超えた数理・データサイエンス・ＡＩ教育や、データサイエンスが社会においてどのように活用しうるか等をテーマとした、大学等並びに大学院の授業の内容及び方法の改善を図るために朝日大学ＦＤ活動推進委員会の専門部会として設置する。なお、授業改善のためのアンケートの実施・分析については、全学的に朝日大学ＦＤ活動推進委員会により実施されており、その結果を踏まえて、プログラムの改善を行う。
A34: ⑦ | B34: 具体的な構成員
B35: 副学長 森下 伊三男 経営学部 教授 矢守 恭子 経営学部 准教授 曽我部 雄樹
A48: ⑧ | B48: 履修者数・履修率の向上に向けた計画 ※様式１の「履修必須の有無」で「計画がある」としている場合は詳細について記載すること
B49: 令和５年度実績 | C49: ='様式２ 履修者等数の実績'!S33 -> 0.23305085 | E49: 令和６年度予定 | F49: 0.44 | H49: 令和７年度予定 | I49: 0.66
B50: 令和８年度予定 | C50: 0.88 | E50: 令和９年度予定 | F50: 0.94 | H50: 収容定員（名） | I50: ='様式２ 履修者等数の実績'!E33 -> 2360
B51: 具体的な計画
B52: 本教育プログラムは全学１年次必修科目のみの構成であり、卒業要件として全員履修することを前提としているため、本項目に関する特段の取り組みは行われていない。なお、歯学部が６学年制であることから、令和１０年度以降に履修率が１００％となる予定である。
A65: ⑨ | B65: 学部・学科に関係なく希望する学生全員が受講可能となるような必要な体制・取組等
B66: 本教育プログラムは必修項目のみから構成され、卒業要件として全員履修することが前提となっているため、本項目に関する特段の取り組みは行われていない。
A79: ⑩ | B79: できる限り多くの学生が履修できるような具体的な周知方法・取組
B80: 本教育プログラムは必修項目のみから構成され、卒業要件として全員履修することが前提となっているため、本項目に関する特段の取り組みは行われていない。
A93: ⑪ | B93: できる限り多くの学生が履修・修得できるようなサポート体制
B94: 履修について、本教育プログラムは必修項目のみから構成され、卒業要件として全員履修することが前提となっているため、本項目に関する特段の取り組みは行われていない。 修得については、専任教員による指導教員を配置して、学生の履修や学修についての相談を受けている。コンピュータの利用については、学部・学科に関係なく、学生が自由に利用できるようオープン利用室を設けている。さらに、図書館（本館・分室）には、可動式の椅子や机を自由に組み替え、仲間と学修ができる「フレキシブルワーク・エリア」と、大型ディスプレイ付きパソコンを利用し、議論しながら授業の課題作成などができる「グループワーク・エリア」を設けている。さらに、インターネット検索、文書作成や印刷ができる検索エリアも設けている。
A107: ⑫ | B107: 授業時間内外で学習指導、質問を受け付ける具体的な仕組み
B108: 本教育プログラムに限らず、本大学の授業は基本的に、授業時間内に質問を受け付けているほか、リアクションペーパーによる質問等は、授業中又はMoodleのメッセージやE-mailによって、全体に対して又は個別に回答している。また、専任教員における授業についてはオフィスアワーを設け、学生が直接教員の研究室を訪ねて学修指導が受けられるようにしている。

Sheet 様式４　自己点検・評価
I1: 様式４
H2: 大学等名 | I2: ='様式１ー１ プログラムを構成する授業科目'!C2 -> 朝日大学
A3: 自己点検・評価について
A5: ① | B5: プログラムの自己点検・評価を行う体制（委員会・組織等）
B6: 朝日大学内部質保証推進委員会
D8: （責任者名） | E8: 大友 克之 | G8: （役職名） | H8: 学長
A10: ② | B10: 自己点検・評価体制における意見等
B11: 自己点検・評価の視点 | E11: 自己点検・評価体制における意見・結果・改善に向けた取組等
B12: 学内からの視点
C13: プログラムの履修・修得状況 | E13: 朝日大学ＦＤ活動推進委員会が半学期ごとに実施する「授業改善のためのアンケート」調査の回答状況から、学生たちのプログラム内容の履修・修得状況を把握・分析している。この分析結果は、朝日大学内部質保証推進委員会で審議され、全学で本プログラム全体の履修・修得状況を把握している。 令和５年度の履修率は全学で23％であるが、本プログラムは令和５年度からスタートしたものであり、プログラムを構成する授業科目が卒業要件の必修科目となっていることから、年次進行により100％の履修率を達成できるものと見込んでいる。
C14: 学修成果 | E14: 「授業改善のためのアンケート」調査のうち、本プログラムを構成する授業科目に関する履修者の回答データを分析することによって、授業内容の学生の理解度や満足度を把握している。分析結果に基づき、朝日大学ＦＤ活動推進委員会数理・データサイエンス・ＡＩ教育専門部会では、授業内容及び方法を見直すことでプログラムの評価・改善を行っている。 本プログラムの修得は、全学部・学科の卒業要件となっている。つまり、プログラム修得のために履修した授業単位は卒業要件単位として認められるため、卒業を目指した履修指導は、プログラム修得を目指した履修指導を兼ねていることになり、全学的な不断の改善等が実施されている。
C15: 学生アンケート等を通じた学生の内容の理解度 | E15: 本プログラムを構成する全ての授業科目で「授業改善のためのアンケート」を実施しており、学生の理解度や満足度等を把握し、授業内容及び方法の改善を図っている。授業改善のためのアンケートでは、9割以上の学生が概ね授業内容を理解し、その内容に満足しているものとなったが、さらに理解度が向上するよう授業内容の改善に取り組む。
C16: 学生アンケート等を通じた後輩等他の学生への推奨度 | E16: 授業改善のためのアンケート調査結果分析報告書を大学ホームページに公開しており、後輩学生や他の学生はその評価結果を履修前に確認することができるようになっている。また、全ての授業科目のシラバスには、「学生の意見等からの気づき」として、「授業改善のためのアンケート」の調査結果に応じた、授業の成果を高めるための工夫、改善方法が掲載されており、後輩学生や他の学生は履修前にその内容を確認することができるようになっている。
C17: 全学的な履修者数、履修率向上に向けた計画の達成・進捗状況 | E17: 本プログラムを構成する授業科目は全学必修科目であり、卒業要件として全員がこのプログラムを修了することが前提となっているため、履修者数・履修率向上に向けての取り組みは行っていない。ただし、学生が履修を完了できるように、リアクションペーパー等による質問や提出された課題へのフィードバックによって、履修者の状況に応じて対応している。
B18: 学外からの視点
C19: 教育プログラム修了者の進路、活躍状況、企業等の評価 | E19: 学生の就職状況と履修状況を確認することにより、本教育プログラムを修了した卒業生の進路先については、把握することが可能である。また、教育プログラムを修了した卒業生の活躍状況や企業等の評価については、就職支援課が把握している卒業生の活躍状況を収集するとともに、本学が実施する「朝日大学卒業生に関するアンケート（企業を対象としたアンケート）」における「朝日大学卒業生への印象、本学に求めること」に関する設問から、企業から本大学卒業生に対する評価を把握できるよう検討している。 本プログラムは2023年度より開始した教育プログラムであり、教育プログラム修了者の進路、活動状況、企業等の評価の情報は得られないが、現状では、2022年度に全学で企業・団体に就職した学生は417名であり、そのうち数理・データサイエンス・ＡＩに関連すると考えられる情報通信業に就職した学生は12名（2.9％）であった。今後は本プログラムを修了した学生がどのような進路を選択するかについて調査を続けていく予定である。
C20: 産業界からの視点を含めた教育プログラム内容・手法等への意見 | E20: 本大学では、複数の企業と産学連携協定を締結しており、毎年「産学連携協議会」を実施し、地域の課題を共有するとともに、教育内容等への意見を聴取している。聴取した意見については、プログラムを改善・進化させるための委員会（朝日大学ＦＤ活動推進委員会数理・データサイエンス・ＡＩ教育専門部会）において、プログラムの検証・改善に活用している。
B21: 数理・データサイエンス・ＡＩを「学ぶ楽しさ」「学ぶことの意義」を理解させること | E21: 授業において、モデルカリキュラムリテラシーレベルの導入部分であるデータサイエンスの活用事例を紹介することで、学生の興味関心を高め、学ぶ楽しさや学ぶことの意義を理解させている。また、授業時の課題提出物や学生による授業改善のためのアンケート等を比較・検討することで授業改善を図っている。
B22: 内容・水準を維持・向上しつつ、より「分かりやすい」授業とすること ※社会の変化や生成AI等の技術の発展を踏まえて教育内容を継続的に見直すなど、より教育効果の高まる授業内容・方法とするための取組や仕組みについても該当があれば記載 | E22: 内容・水準の維持・向上は、授業においてモデルカリキュラム（リテラシーレベル）の内容がシラバスに盛り込まれていることを確認するとともに、授業時の課題提出物及び学生による授業改善のためのアンケート等から、学生の理解度や満足度を把握し、講義の内容・実施方法の検討を行い、分かりやすい授業となるよう工夫している。
