Workbook

Sheet 様式１ー１　プログラムを構成する授業科目（BCME）
T1: 様式１-１ | V1: 「学部・学科によって、修了要件は相違する」場合は、本シートを複製の上＜様式１－〇＞と枝番号を付してください
B2: 大学等名 | C2: 東京工科大学
B3: プログラム名 | C3: 東京工科大学 数理・データサイエンス・AI教育プログラム
A5: プログラムを構成する授業科目について
A7: ① 教育プログラムの修了要件 | L7: 学部・学科によって、修了要件は相違する
A9: ② 対象となる学部・学科名称
B11: 応用生物学部、コンピュータサイエンス学部、メディア学部、工学部
A14: ③ 修了要件
B15: 応用生物学部、コンピュータサイエンス学部、メディア学部、工学部では、必修科目である「データサイエンス入門」2単位の修得を修了要件とする。 | X15: 【プルダウンリスト】
X16: 令和５年度以前より、履修することが必須のプログラムとして実施
X17: 令和８年度までに履修必須とする計画
X18: 令和９年度以降に履修必須とする計画、又は未定
B22: 必要最低科目数・単位数 | E22: 1 | F22: 科目 | H22: 2 | I22: 単位 | M22: 履修必須の有無 | N22: 令和５年度以前より、履修することが必須のプログラムとして実施
A24: ④ 現在進行中の社会変化（第４次産業革命、Society 5.0、データ駆動型社会等）に深く寄与しているものであり、それが自らの生活と密接に結びついている」の内容を含む授業科目
B26: 授業科目 | G26: 単位数 | H26: 必須 | I26: 1-1 | J26: 1-6 | K26: 授業科目 | R26: 単位数 | S26: 必須 | T26: 1-1 | U26: 1-6
B27: データサイエンス入門 | G27: 2 | H27: ○ | I27: ○ | J27: ○
A35: ⑤ 「社会で活用されているデータ」や「データの活用領域」は非常に広範囲であって、日常生活や社会の課題を解決する有用なツールになり得るもの」の内容を含む授業科目
B37: 授業科目 | G37: 単位数 | H37: 必須 | I37: 1-2 | J37: 1-3 | K37: 授業科目 | R37: 単位数 | S37: 必須 | T37: 1-2 | U37: 1-3
B38: データサイエンス入門 | G38: 2 | H38: ○ | I38: ○ | J38: ○
A46: ⑥ 「様々なデータ利活用の現場におけるデータ利活用事例が示され、様々な適用領域（流通、製造、金融、サービス、インフラ、公共、ヘルスケア等）の知見と組み合わせることで価値を創出するもの」の内容を含む授業科目
B48: 授業科目 | G48: 単位数 | H48: 必須 | I48: 1-4 | J48: 1-5 | K48: 授業科目 | R48: 単位数 | S48: 必須 | T48: 1-4 | U48: 1-5
B49: データサイエンス入門 | G49: 2 | H49: ○ | I49: ○ | J49: ○
A57: ⑦ 「活用に当たっての様々な留意事項（ELSI、個人情報、データ倫理、ＡＩ社会原則等）を考慮し、情報セキュリティや情報漏洩等、データを守る上での留意事項への理解をする」の内容を含む授業科目
B59: 授業科目 | G59: 単位数 | H59: 必須 | I59: 3-1 | J59: 3-2 | K59: 授業科目 | R59: 単位数 | S59: 必須 | T59: 3-1 | U59: 3-2
B60: データサイエンス入門 | G60: 2 | H60: ○ | I60: ○ | J60: ○
A68: ⑧ 「実データ・実課題（学術データ等を含む）を用いた演習など、社会での実例を題材として、「データを読む、説明する、扱う」といった数理・データサイエンス・ＡＩの基本的な活用法に関するもの」の内容を含む授業科目
B70: 授業科目 | F70: 単位数 | G70: 必須 | H70: 2-1 | I70: 2-2 | J70: 2-3 | K70: 授業科目 | Q70: 単位数 | R70: 必須 | S70: 2-1 | T70: 2-2 | U70: 2-3
B71: データサイエンス入門 | F71: 2 | G71: ○ | H71: ○ | I71: ○ | J71: ○
A79: ⑨ 選択「４．オプション」の内容を含む授業科目
B80: 授業科目 | G80: 選択項目 | K80: 授業科目 | R80: 選択項目
B81: データサイエンス入門 | G81: 4-1統計および数理基礎
B82: データサイエンス入門 | G82: 4‐8データ活用実践（教師あり学習）
B83: データサイエンス入門 | G83: 4‐9データ活用実践（教師なし学習）
A89: ⑩ プログラムを構成する授業の内容
B90: 授業に含まれている内容・要素 | D90: 講義内容
B91: （１）現在進行中の社会変化（第４次産業革命、Society 5.0、データ駆動型社会等）に深く寄与しているものであり、それが自らの生活と密接に結びついている | C91: 1-1 | D91: ・ビッグデータ、IoT、AI「データサイエンス入門」(1回目) ・データ量の増加、計算機の処理性能の向上「データサイエンス入門」(1回目、11回目、14回目) ・データ駆動型社会「データサイエンス入門」(1回目) ・データを起点としたものの見方、人間の知的活動を起点としたものの見方「データサイエンス入門」(1回目)
C92: 1-6 | D92: ・AI等を活用した新しいビジネスモデル「データサイエンス入門」(1回目) ・AI最新技術の活用例「データサイエンス入門」(11回目、14回目)
B93: （２）「社会で活用されているデータ」や「データの活用領域」は非常に広範囲であって、日常生活や社会の課題を解決する有用なツールになり得るもの | C93: 1-2 | D93: ・調査データ、実験データ、人の行動ログデータ「データサイエンス入門」(2回目) ・データのオープン化「データサイエンス入門」(14回目)
C94: 1-3 | D94: ・データ・AI活用領域の広がり「データサイエンス入門」(1回目) ・研究開発、調達、製造、物流、販売、マーケティング、サービスなど「データサイエンス入門」(1回目) ・仮説検証「データサイエンス入門」(13回目)
B95: （３）様々なデータ利活用の現場におけるデータ利活用事例が示され、様々な適用領域（流通、製造、金融、サービス、インフラ、公共、ヘルスケア等）の知見と組み合わせることで価値を創出するもの | C95: 1-4 | D95: ・データ解析:予測、グルーピング、最適化「データサイエンス入門」(7回目、9回目) ・データ可視化:複合グラフ、2軸グラフ、関係性の可視化「データサイエンス入門」(3回目、8回目)
...

Sheet 様式１ー２　プログラムを構成する授業科目（HS）
T1: 様式１-２ | V1: 「学部・学科によって、修了要件は相違する」場合は、本シートを複製の上＜様式１－〇＞と枝番号を付してください
B2: 大学等名 | C2: 東京工科大学
B3: プログラム名 | C3: 東京工科大学 数理・データサイエンス・AI教育プログラム
A5: プログラムを構成する授業科目について
A7: ① 教育プログラムの修了要件 | L7: 学部・学科によって、修了要件は相違する
A9: ② 対象となる学部・学科名称
B11: 医療保健学部
A14: ③ 修了要件
B15: 医療保健学部 臨床工学科では、必修科目である「データサイエンス入門」2単位の修得を修了要件とする。 医療保健学部 看護学科、臨床検査学科、リハビリテーション学科では、選択科目である「コンピュータ概論Ⅱ」2単位の修得を修了要件とする。 | X15: 【プルダウンリスト】
X16: 令和５年度以前より、履修することが必須のプログラムとして実施
X17: 令和８年度までに履修必須とする計画
X18: 令和９年度以降に履修必須とする計画、又は未定
B22: 必要最低科目数・単位数 | E22: 1 | F22: 科目 | H22: 2 | I22: 単位 | M22: 履修必須の有無 | N22: 令和９年度以降に履修必須とする計画、又は未定
A24: ④ 現在進行中の社会変化（第４次産業革命、Society 5.0、データ駆動型社会等）に深く寄与しているものであり、それが自らの生活と密接に結びついている」の内容を含む授業科目
B26: 授業科目 | G26: 単位数 | H26: 必須 | I26: 1-1 | J26: 1-6 | K26: 授業科目 | R26: 単位数 | S26: 必須 | T26: 1-1 | U26: 1-6
B27: データサイエンス入門 | G27: 2 | H27: ○ | I27: ○ | J27: ○
B28: コンピュータ概論Ⅱ | G28: 2 | H28: ○ | I28: ○ | J28: ○
A35: ⑤ 「社会で活用されているデータ」や「データの活用領域」は非常に広範囲であって、日常生活や社会の課題を解決する有用なツールになり得るもの」の内容を含む授業科目
B37: 授業科目 | G37: 単位数 | H37: 必須 | I37: 1-2 | J37: 1-3 | K37: 授業科目 | R37: 単位数 | S37: 必須 | T37: 1-2 | U37: 1-3
B38: データサイエンス入門 | G38: 2 | H38: ○ | I38: ○ | J38: ○
B39: コンピュータ概論Ⅱ | G39: 2 | H39: ○ | I39: ○ | J39: ○
A46: ⑥ 「様々なデータ利活用の現場におけるデータ利活用事例が示され、様々な適用領域（流通、製造、金融、サービス、インフラ、公共、ヘルスケア等）の知見と組み合わせることで価値を創出するもの」の内容を含む授業科目
B48: 授業科目 | G48: 単位数 | H48: 必須 | I48: 1-4 | J48: 1-5 | K48: 授業科目 | R48: 単位数 | S48: 必須 | T48: 1-4 | U48: 1-5
B49: データサイエンス入門 | G49: 2 | H49: ○ | I49: ○ | J49: ○
B50: コンピュータ概論Ⅱ | G50: 2 | H50: ○ | I50: ○ | J50: ○
A57: ⑦ 「活用に当たっての様々な留意事項（ELSI、個人情報、データ倫理、ＡＩ社会原則等）を考慮し、情報セキュリティや情報漏洩等、データを守る上での留意事項への理解をする」の内容を含む授業科目
B59: 授業科目 | G59: 単位数 | H59: 必須 | I59: 3-1 | J59: 3-2 | K59: 授業科目 | R59: 単位数 | S59: 必須 | T59: 3-1 | U59: 3-2
B60: データサイエンス入門 | G60: 2 | H60: ○ | I60: ○ | J60: ○
B61: コンピュータ概論Ⅱ | G61: 2 | H61: ○ | I61: ○ | J61: ○
A68: ⑧ 「実データ・実課題（学術データ等を含む）を用いた演習など、社会での実例を題材として、「データを読む、説明する、扱う」といった数理・データサイエンス・ＡＩの基本的な活用法に関するもの」の内容を含む授業科目
B70: 授業科目 | F70: 単位数 | G70: 必須 | H70: 2-1 | I70: 2-2 | J70: 2-3 | K70: 授業科目 | Q70: 単位数 | R70: 必須 | S70: 2-1 | T70: 2-2 | U70: 2-3
B71: データサイエンス入門 | F71: 2 | G71: ○ | H71: ○ | I71: ○ | J71: ○
B72: コンピュータ概論Ⅱ | F72: 2 | G72: ○ | H72: ○ | I72: ○ | J72: ○
A79: ⑨ 選択「４．オプション」の内容を含む授業科目
B80: 授業科目 | G80: 選択項目 | K80: 授業科目 | R80: 選択項目
B81: データサイエンス入門 | G81: 4-1統計および数理基礎
B82: データサイエンス入門 | G82: 4‐4時系列データ解析
B83: コンピュータ概論Ⅱ | G83: 4-1統計および数理基礎
B84: コンピュータ概論Ⅱ | G84: 4‐4時系列データ解析
A89: ⑩ プログラムを構成する授業の内容
...

Sheet 様式１ー３　プログラムを構成する授業科目（DS）
T1: 様式１-３ | V1: 「学部・学科によって、修了要件は相違する」場合は、本シートを複製の上＜様式１－〇＞と枝番号を付してください
B2: 大学等名 | C2: 東京工科大学
B3: プログラム名 | C3: 東京工科大学 数理・データサイエンス・AI教育プログラム
A5: プログラムを構成する授業科目について
A7: ① 教育プログラムの修了要件 | L7: 学部・学科によって、修了要件は相違する
A9: ② 対象となる学部・学科名称
B11: デザイン学部
A14: ③ 修了要件
B15: デザイン学部では、選択科目である「コンピュータ概論Ⅱ」2単位の修得を修了要件とする。 | X15: 【プルダウンリスト】
X16: 令和５年度以前より、履修することが必須のプログラムとして実施
X17: 令和８年度までに履修必須とする計画
X18: 令和９年度以降に履修必須とする計画、又は未定
B22: 必要最低科目数・単位数 | E22: 1 | F22: 科目 | H22: 2 | I22: 単位 | M22: 履修必須の有無 | N22: 令和９年度以降に履修必須とする計画、又は未定
A24: ④ 現在進行中の社会変化（第４次産業革命、Society 5.0、データ駆動型社会等）に深く寄与しているものであり、それが自らの生活と密接に結びついている」の内容を含む授業科目
B26: 授業科目 | G26: 単位数 | H26: 必須 | I26: 1-1 | J26: 1-6 | K26: 授業科目 | R26: 単位数 | S26: 必須 | T26: 1-1 | U26: 1-6
B27: コンピュータ概論Ⅱ | G27: 2 | H27: ○ | I27: ○ | J27: ○
A35: ⑤ 「社会で活用されているデータ」や「データの活用領域」は非常に広範囲であって、日常生活や社会の課題を解決する有用なツールになり得るもの」の内容を含む授業科目
B37: 授業科目 | G37: 単位数 | H37: 必須 | I37: 1-2 | J37: 1-3 | K37: 授業科目 | R37: 単位数 | S37: 必須 | T37: 1-2 | U37: 1-3
B38: コンピュータ概論Ⅱ | G38: 2 | H38: ○ | I38: ○ | J38: ○
A46: ⑥ 「様々なデータ利活用の現場におけるデータ利活用事例が示され、様々な適用領域（流通、製造、金融、サービス、インフラ、公共、ヘルスケア等）の知見と組み合わせることで価値を創出するもの」の内容を含む授業科目
B48: 授業科目 | G48: 単位数 | H48: 必須 | I48: 1-4 | J48: 1-5 | K48: 授業科目 | R48: 単位数 | S48: 必須 | T48: 1-4 | U48: 1-5
B49: コンピュータ概論Ⅱ | G49: 2 | H49: ○ | I49: ○ | J49: ○
A57: ⑦ 「活用に当たっての様々な留意事項（ELSI、個人情報、データ倫理、ＡＩ社会原則等）を考慮し、情報セキュリティや情報漏洩等、データを守る上での留意事項への理解をする」の内容を含む授業科目
B59: 授業科目 | G59: 単位数 | H59: 必須 | I59: 3-1 | J59: 3-2 | K59: 授業科目 | R59: 単位数 | S59: 必須 | T59: 3-1 | U59: 3-2
B60: コンピュータ概論Ⅱ | G60: 2 | H60: ○ | I60: ○ | J60: ○
A68: ⑧ 「実データ・実課題（学術データ等を含む）を用いた演習など、社会での実例を題材として、「データを読む、説明する、扱う」といった数理・データサイエンス・ＡＩの基本的な活用法に関するもの」の内容を含む授業科目
B70: 授業科目 | F70: 単位数 | G70: 必須 | H70: 2-1 | I70: 2-2 | J70: 2-3 | K70: 授業科目 | Q70: 単位数 | R70: 必須 | S70: 2-1 | T70: 2-2 | U70: 2-3
B71: コンピュータ概論Ⅱ | F71: 2 | G71: ○ | H71: ○ | I71: ○ | J71: ○
A79: ⑨ 選択「４．オプション」の内容を含む授業科目
B80: 授業科目 | G80: 選択項目 | K80: 授業科目 | R80: 選択項目
B81: コンピュータ概論Ⅱ | G81: 4-1統計および数理基礎
B82: コンピュータ概論Ⅱ | G82: 4‐4時系列データ解析
A89: ⑩ プログラムを構成する授業の内容
B90: 授業に含まれている内容・要素 | D90: 講義内容
B91: （１）現在進行中の社会変化（第４次産業革命、Society 5.0、データ駆動型社会等）に深く寄与しているものであり、それが自らの生活と密接に結びついている | C91: 1-1 | D91: ・第4次産業革命、Society 5.0、データ駆動型社会「コンピュータ概論Ⅱ」(1回目) ・複数技術を組み合わせたAiサービス「コンピュータ概論Ⅱ」(13回目)
C92: 1-6 | D92: ・AI最新技術の活用例「コンピュータ概論Ⅱ」(2回目)
B93: （２）「社会で活用されているデータ」や「データの活用領域」は非常に広範囲であって、日常生活や社会の課題を解決する有用なツールになり得るもの | C93: 1-2 | D93: ・構造化データ、非構造化データ「コンピュータ概論Ⅱ」(3回目) ・データのオープン化「コンピュータ概論Ⅱ」(3回目)
C94: 1-3 | D94: ・データ・AI活用領域の広がり「コンピュータ概論Ⅱ」(1回目） ・研究開発、調達、製造、物流、販売、マーケティング、サービスなど「コンピュータ概論Ⅱ」(2回目)
B95: （３）様々なデータ利活用の現場におけるデータ利活用事例が示され、様々な適用領域（流通、製造、金融、サービス、インフラ、公共、ヘルスケア等）の知見と組み合わせることで価値を創出するもの | C95: 1-4 | D95: ・データの可視化「コンピュータ概論Ⅱ」(4回目) ・特化型AIと汎用AI、今のAIで出来ることと出来ないこと、AIとビッグデータ「コンピュータ概論Ⅱ」(2回目)
C96: 1-5 | D96: ・データサイエンスのサイクル「コンピュータ概論Ⅱ」(3回目、7回目、8回目、9回目) ・流通、製造、金融、サービス、インフラ、公共、ヘルスケア等におけるデータ・AI利活用事例紹介「コンピュータ概論Ⅱ」(2回目)
...

Sheet 様式２ 履修者等数の実績
S1: 様式２
Q2: ='様式１ー２ プログラムを構成する授業科目（HS）'!C2 -> 東京工科大学
A3: プログラムの履修者数等の実績について
A5: ①プログラム開設年度 | C5: 令和５ | E5: 年度
A7: ②大学等全体の男女別学生数 | E7: 男性 | F7: 4911 | G7: 人 | H7: 女性 | I7: 2694 | J7: 人 | K7: （ | L7: 合計 | M7: =F7+I7 -> 7605 | N7: 人 | O7: ）
A9: ③履修者・修了者の実績
B11: 学部・学科名称 | C11: 学生数 | D11: 入学 定員 | E11: 収容 定員 | F11: 令和5年度 | H11: 令和4年度 | J11: 令和3年度 | L11: 令和2年度 | N11: 令和元年度 | P11: 平成30年度 | R11: 履修者数 合計 | S11: 履修率
F12: 履修者数 | G12: 修了者数 | H12: 履修者数 | I12: 修了者数 | J12: 履修者数 | K12: 修了者数 | L12: 履修者数 | M12: 修了者数 | N12: 履修者数 | O12: 修了者数 | P12: 履修者数 | Q12: 修了者数
B13: 応用生物学部 | C13: 1137 | D13: 260 | E13: 1103 | F13: 304 | G13: 270 | R13: =F13+H13+J13+L13+N13+P13 -> 304 | S13: =R13/E13 -> 0.27561197
B14: コンピュータサイエンス学部 | C14: 1373 | D14: 290 | E14: 1238 | F14: 333 | G14: 306 | R14: =F14+H14+J14+L14+N14+P14 -> 333 | S14: =R14/E14 -> 0.26898223
B15: メディア学部 | C15: 1359 | D15: 290 | E15: 1235 | F15: 316 | G15: 287 | R15: =F15+H15+J15+L15+N15+P15 -> 316 | S15: =R15/E15 -> 0.25587045
B16: 工学部 | C16: 1252 | D16: 280 | E16: 1159 | F16: 346 | G16: 281 | R16: =F16+H16+J16+L16+N16+P16 -> 346 | S16: =R16/E16 -> 0.29853322
B17: 医療保健学部 | C17: 1633 | D17: 400 | E17: 1600 | F17: 157 | G17: 152 | R17: =F17+H17+J17+L17+N17+P17 -> 157 | S17: =R17/E17 -> 0.098125
B18: デザイン学部 | C18: 851 | D18: 200 | E18: 800 | F18: 83 | G18: 73 | R18: =F18+H18+J18+L18+N18+P18 -> 83 | S18: =R18/E18 -> 0.10375
R19: =F19+H19+J19+L19+N19+P19 -> 0 | S19: =R19/E19 -> #DIV/0!
R20: =F20+H20+J20+L20+N20+P20 -> 0 | S20: =R20/E20 -> #DIV/0!
R21: =F21+H21+J21+L21+N21+P21 -> 0 | S21: =R21/E21 -> #DIV/0!
R22: =F22+H22+J22+L22+N22+P22 -> 0 | S22: =R22/E22 -> #DIV/0!
R23: =F23+H23+J23+L23+N23+P23 -> 0 | S23: =R23/E23 -> #DIV/0!
R24: =F24+H24+J24+L24+N24+P24 -> 0 | S24: =R24/E24 -> #DIV/0!
R25: =F25+H25+J25+L25+N25+P25 -> 0 | S25: =R25/E25 -> #DIV/0!
R26: =F26+H26+J26+L26+N26+P26 -> 0 | S26: =R26/E26 -> #DIV/0!
R27: =F27+H27+J27+L27+N27+P27 -> 0 | S27: =R27/E27 -> #DIV/0!
R28: =F28+H28+J28+L28+N28+P28 -> 0 | S28: =R28/E28 -> #DIV/0!
R29: =F29+H29+J29+L29+N29+P29 -> 0 | S29: =R29/E29 -> #DIV/0!
R30: =F30+H30+J30+L30+N30+P30 -> 0 | S30: =R30/E30 -> #DIV/0!
... R32: =F32+H32+J32+L32+N32+P32 -> 0 | S32: =R32/E32 -> #DIV/0!
B33: 合 計 | C33: =SUM(C13:C32) -> 7605 | D33: =SUM(D13:D32) -> 1720 | E33: =SUM(E13:E32) -> 7135 | F33: =SUM(F13:F32) -> 1539 | G33: =SUM(G13:G32) -> 1369 | H33: =SUM(H13:H32) -> 0 | I33: =SUM(I13:I32) -> 0 | J33: =SUM(J13:J32) -> 0 | ... R33: =SUM(R13:R32) -> 1539 | S33: =R33/E33 -> 0.21569727

Sheet 様式３ 教育の質・履修者数を向上させるための体制・計画
I1: 様式３
G2: 大学等名 | H2: ='様式１ー２ プログラムを構成する授業科目（HS）'!C2 -> 東京工科大学
A4: 教育の質・履修者数を向上させるための体制・計画について
A6: ① | B6: 全学の教員数 | C6: (常勤） | E6: 292 | F6: 人 | G6: （非常勤） | H6: 183 | I6: 人
A8: ② | B8: プログラムの授業を教えている教員数 | H8: 5 | I8: 人
A10: ③ | B10: プログラムの運営責任者
B11: （責任者名） | C11: 浦瀬 太郎 | G11: （役職名） | H11: 教務部長
A13: ④ | B13: プログラムを改善・進化させるための体制（委員会・組織等）
B14: 東京工科大学数理・データサイエンス・AI教育プログラム運営委員会
B16: （責任者名） | C16: 浦瀬 太郎 | G16: （役職名） | H16: 教務部長
A18: ⑤ | B18: プログラムを改善・進化させるための体制を定める規則名称
B19: 東京工科大学数理・データサイエンス・AI教育プログラム運営委員会規程
A21: ⑥ | B21: 体制の目的
B22: 本委員会は、数理・データサイエンス・AI教育プログラムの実施・運営に関すること、本学における数理・データサイエンス・AI教育プログラムの普及、促進に関すること、自己点検・評価の実施、公表に関すること等を目的に設置している。
A34: ⑦ | B34: 具体的な構成員
B35: 教務部長（応用生物学部 教授） 浦瀬 太郎 教養学環 教務委員長・教授 加用 一者 教養学環 教授 亀井 聡 教養学環 准教授 須田 拓馬 教養学環 講師 藤澤 幸太郎 学務部 学務課 課長 田口 朗
A48: ⑧ | B48: 履修者数・履修率の向上に向けた計画 ※様式１の「履修必須の有無」で「計画がある」としている場合は詳細について記載すること
B49: 令和５年度実績 | C49: ='様式２ 履修者等数の実績'!S33 -> 0.21569727 | E49: 令和６年度予定 | F49: 0.35 | H49: 令和７年度予定 | I49: 0.55
B50: 令和８年度予定 | C50: 0.75 | E50: 令和９年度予定 | F50: 0.85 | H50: 収容定員（名） | I50: ='様式２ 履修者等数の実績'!E33 -> 7135
B51: 具体的な計画
B52: 数理・データサイエンス・AI教育プログラムを編成する2科目は、 過年度より開講されていた科目である。本プログラムの実施と合わせ、令和4年度に履修項目を全面的に刷新し、データサイエンス、AIの利活用に関する基礎的な知見を身につけられるよう教育設計を行った上で、令和５年度から教育を実施した。 令和５年度の履修率は、全学では22%であった。 とりわけ、選択科目の履修により、本プログラムの修了を目指す学部・学科に所属する受講生に対して、本プログラム履修の意義と、現在の社会と将来的に有用な知識と技術を身につけることができることを啓蒙することで、履修者数と履修率の増加を図っている。
A65: ⑨ | B65: 学部・学科に関係なく希望する学生全員が受講可能となるような必要な体制・取組等
B66: 本教育プログラムでは、すでに、すべての学部の学生全員が本プログラム関連科目の受講を可能とする科目編成を整えている。 学部学科により、数理・データサイエンス・ＡＩに馴染みがない入学者、高度な知識の修得を望む入学者がいる。そこで、過年度の履修状況を踏まえ、本プログラム関連科目構成を、受講生のリテラシーレベルと適切に対応する2科目を準備した。また、本学では、全学生に対してノートＰＣを必携としており、授業内におけるノートPCの活用をおし進めてきている。本プログラムで進める知識と技術の習得のための演習の準備はできている。
A79: ⑩ | B79: できる限り多くの学生が履修できるような具体的な周知方法・取組
B80: 八王子に設置している4学部および医療保健学部臨床工学科では、本プログラムの科目が必修科目となっているため、1年次入学生全員が履修する。その他の学部学科では、選択科目であるため、ガイダンスや学生ポータルサイトなどで、数理・データサイエンス・AIに関する現状と基礎知識を学ぶ意義と重要性を説明する。本プログラム関連科目における履修内容は、これからの社会人の基礎的素養をなすことを強調するとともに、本プログラム修了者には修了認定証が授与され、同認定書はデジタル・バッジ形式であることも周知する。それにより履修意識、学びへの動機付けを高めるようにする。
A93: ⑪ | B93: できる限り多くの学生が履修・修得できるようなサポート体制
B94: 本学では学習支援システムとしてMoodleを利用している。本学生はMoodleを利用して学習に馴れているため、学習に関連する付随情報をできるだけMoodleを利用して提供するとともに、課題提出、小テスト、授業アンケートなどをMoodle上で一括して管理し、教員が受講生の理解度や習熟度を的確に把握するように務める。それらMoodle上の学習記録・データを元にして、受講生にとり適切な学習支援情報の提供と、学習支援を進める。加えて、本学では、学生の個別指導、適切な学習支援を実現するために、学修支援センターを設置している。ここでは、数学や物理、プログラミングなどに関する指導員を配し、学生は自分の好きな時間にセンターを訪ねて、個別を受けることができる。
A107: ⑫ | B107: 授業時間内外で学習指導、質問を受け付ける具体的な仕組み
B108: 本プログラム関連の2科目では、統計計算手法などの手順をVOD(Video On Demand)化しており、履修者は授業内だけでなく課外においても、同ビデオを視聴することで復習や確認に役立てることができる。 学習指導に関しては、オフィスアワーを実施し質問対応に当たるほか、担当教員のメールアドレスを受講生に公開し、メール等を利用したオンデマンドでの質問対応も行うことで受講生の利便性を上げる。学修支援センター職員も受講生からの質問を受け付けており、複数の窓口を用意することで、柔軟な学習者支援体制を構築している。

Sheet 様式４　自己点検・評価
I1: 様式４
H2: 大学等名 | I2: ='様式１ー２ プログラムを構成する授業科目（HS）'!C2 -> 東京工科大学
A3: 自己点検・評価について
A5: ① | B5: プログラムの自己点検・評価を行う体制（委員会・組織等）
B6: 東京工科大学数理・データサイエンス・AI教育プログラム運営委員会
D8: （責任者名） | E8: 浦瀬 太郎 | G8: （役職名） | H8: 教務部長
A10: ② | B10: 自己点検・評価体制における意見等
B11: 自己点検・評価の視点 | E11: 自己点検・評価体制における意見・結果・改善に向けた取組等
B12: 学内からの視点
C13: プログラムの履修・修得状況 | E13: 応用生物学部、コンピュータサイエンス学部、メディア学部、工学部並びに医療保健学部臨床工学科では、「データサイエンス入門」の履修および単位取得が必須(卒業要件)となっている。令和5年度では、これらの学部学科の学生のうち1382名が履修し、1224名が単位修得した。 一方、医療保健学部看護学科・臨床検査学科・リハビリテーション学科並びにデザイン学部では選択科目となっている「コンピュータ概論II」の履修者数は、157名であり、145名が単位修得した。 授業期間中の学習進捗・取り組み状況については、オンラインテスト受験回数、学習成果物の提出状況などから把握に努めている。 | K13: =LEN(E13) -> 284
C14: 学修成果 | E14: 学修成果については、プログラム必須科目の単位取得率により評価する。 令和5年度の本プログラム関連2科目の単位取得率は、89％といずれも高い取得率を保っており、履修項目・学修内容は十分学生に伝わり、十分な学修成果が得られていると評価する。 | K14: =LEN(E14) -> 118
C15: 学生アンケート等を通じた学生の内容の理解度 | E15: 本学では、開講している全科目を対象に、履修者への授業アンケートを毎学期実施している。アンケート項目には、科目受講に対する満足度のほか、シラバスに記載された学習目標の修得度の自己評価、自由記述による改善希望の提示等を含んでいる。本プログラム対象科目においても同アンケートを実施し、受講生の習熟度の自己評価を把握するとともに、ニーズを把握し、プログラムの改善、高度化に務める。 | K15: =LEN(E15) -> 186
C16: 学生アンケート等を通じた後輩等他の学生への推奨度 | E16: 本学Webサイト内の本プログラムWebページを活用して新入学生への周知とともに、履修を促進する。同ページには、履修内容に加えて、授業アンケートを通して得られた過年度受講生からの授業に対する評価等を掲載することで、受講希望を促し、受講希望者の増進に繋げる。 | K16: =LEN(E16) -> 127
C17: 全学的な履修者数、履修率向上に向けた計画の達成・進捗状況 | E17: 本プログラム必須科目の履修を必修化している学部・学科(応用生物学部、コンピュータサイエンス学部、メディア学部、工学部、医療保健学部臨床工学科)では、十分な単位取得率を保っている。一方、受講者の選択による履修を促す学部・学科(デザイン学部、医療保健学部 看護学科、臨床検査学科、リハビリテーション学科)においても、同学部・学科の入学定員に対する1年生の履修率は27.8％であり、一定数の受講者数を確保している。 Webサイトを利用した広報に加え、各学部の新入生ガイダンスなどでの本プログラムの案内を通して、受講者のさらなる増加と履修率の向上を目指す。 | K17: =LEN(E17) -> 274
B18: 学外からの視点 | K18: =LEN(E18) -> 0
C19: 教育プログラム修了者の進路、活躍状況、企業等の評価 | E19: 本プログラムは令和5年度1年次新入生から展開しているため、まだ学士課程を卒業したものが出ていない。本プログラムを修了した卒業生が出てからは、企業等との交流会の機会を利用して、修了者の活動状況について聞き取りを行う予定である。 | K19: =LEN(E19) -> 112
C20: 産業界からの視点を含めた教育プログラム内容・手法等への意見 | E20: 本学が変化する社会に真に求められる成果を創出する大学であるために、キャンパスのある東京都八王子市や大田区をはじめとする地域社会と緊密に連携を取り合い、大学全体、各学部の活動を通し、地域貢献につながるさまざまな取り組みを展開している。同取り組みを通して、本プログラム修了者の雇用者を中心に意見や要望を聴取するとともに、産業界や行政を含めた地域社会における課題の発掘、数理・データサイエンスを通した連携のあり方など、多角的に取り組んていく。 | K20: =LEN(E20) -> 218
B21: 数理・データサイエンス・ＡＩを「学ぶ楽しさ」「学ぶことの意義」を理解させること | E21: 授業アンケートの結果、特に、自由記述項目において示された本プログラム必須科目への意見や要望を積極的に取り入れ本プログラムでの学びの充実を図る。 受講生の興味・関心にあわせて、本学教員が研究者視点で最先端の数理・データサイエンス・ＡＩの実践利用事例の紹介を交えた質の高い学習コンテンツを提供・拡充していくことで受講生の興味の喚起に努める。それにより受講生に、「学ぶ楽しさ」「学ぶことの意義」を高めるための動機付けを図る。 | K21: =LEN(E21) -> 209
B22: 内容・水準を維持・向上しつつ、より「分かりやすい」授業とすること ※社会の変化や生成AI等の技術の発展を踏まえて教育内容を継続的に見直すなど、より教育効果の高まる授業内容・方法とするための取組や仕組みについても該当があれば記載 | E22: 本プログラム必須科目の単位取得状況、授業アンケートの結果及び、Moodleコースにおいて取得、記録された学習成果関連データを利用し、本プログラム実施の現状把握に努め、受講者のニーズとレベルにあった学習情報の改善と提供を進める。それを以て、学習内容と水準の維持、向上に努める。 | K22: =LEN(E22) -> 137
