Workbook

Sheet 様式１-1　プログラムを構成する授業科目
T1: 様式１-1 | V1: 「学部・学科によって、修了要件は相違する」場合は、本シートを複製の上＜様式１－〇＞と枝番号を付してください
B2: 大学等名 | C2: 東京国際大学
B3: プログラム名 | C3: 数理・データサイエンス・AI教育プログラム
A5: プログラムを構成する授業科目について
A7: ① 教育プログラムの修了要件 | L7: 学部・学科によって、修了要件は相違する
A9: ② 対象となる学部・学科名称
B11: 商学部・言語コミュニケーション学部・人間社会学部・医療健康学部
A14: ③ 修了要件
B15: 基礎教育分野に設置の「ICT基礎」2単位を修得すること。 | X15: 【プルダウンリスト】
X16: 令和５年度以前より、履修することが必須のプログラムとして実施
X17: 令和８年度までに履修必須とする計画
X18: 令和９年度以降に履修必須とする計画、又は未定
B22: 必要最低科目数・単位数 | E22: 1 | F22: 科目 | H22: 2 | I22: 単位 | M22: 履修必須の有無 | N22: 令和４年度以前より、履修することが必須のプログラムとして実施
A24: ④ 現在進行中の社会変化（第４次産業革命、Society 5.0、データ駆動型社会等）に深く寄与しているものであり、それが自らの生活と密接に結びついている」の内容を含む授業科目
B26: 授業科目 | G26: 単位数 | H26: 必須 | I26: 1-1 | J26: 1-6 | K26: 授業科目 | R26: 単位数 | S26: 必須 | T26: 1-1 | U26: 1-6
B27: ICT基礎 | G27: 2 | H27: ○ | I27: ○ | J27: ○
A35: ⑤ 「社会で活用されているデータ」や「データの活用領域」は非常に広範囲であって、日常生活や社会の課題を解決する有用なツールになり得るもの」の内容を含む授業科目
B37: 授業科目 | G37: 単位数 | H37: 必須 | I37: 1-2 | J37: 1-3 | K37: 授業科目 | R37: 単位数 | S37: 必須 | T37: 1-2 | U37: 1-3
B38: ICT基礎 | G38: 2 | H38: ○ | I38: ○ | J38: ○
A46: ⑥ 「様々なデータ利活用の現場におけるデータ利活用事例が示され、様々な適用領域（流通、製造、金融、サービス、インフラ、公共、ヘルスケア等）の知見と組み合わせることで価値を創出するもの」の内容を含む授業科目
B48: 授業科目 | G48: 単位数 | H48: 必須 | I48: 1-4 | J48: 1-5 | K48: 授業科目 | R48: 単位数 | S48: 必須 | T48: 1-4 | U48: 1-5
B49: ICT基礎 | G49: 2 | H49: ○ | I49: ○ | J49: ○
A57: ⑦ 「活用に当たっての様々な留意事項（ELSI、個人情報、データ倫理、ＡＩ社会原則等）を考慮し、情報セキュリティや情報漏洩等、データを守る上での留意事項への理解をする」の内容を含む授業科目
B59: 授業科目 | G59: 単位数 | H59: 必須 | I59: 3-1 | J59: 3-2 | K59: 授業科目 | R59: 単位数 | S59: 必須 | T59: 3-1 | U59: 3-2
B60: ICT基礎 | G60: 2 | H60: ○ | I60: ○ | J60: ○
A68: ⑧ 「実データ・実課題（学術データ等を含む）を用いた演習など、社会での実例を題材として、「データを読む、説明する、扱う」といった数理・データサイエンス・ＡＩの基本的な活用法に関するもの」の内容を含む授業科目
B70: 授業科目 | F70: 単位数 | G70: 必須 | H70: 2-1 | I70: 2-2 | J70: 2-3 | K70: 授業科目 | Q70: 単位数 | R70: 必須 | S70: 2-1 | T70: 2-2 | U70: 2-3
B71: ICT基礎 | F71: 2 | G71: ○ | H71: ○ | I71: ○ | J71: ○
A79: ⑨ 選択「４．オプション」の内容を含む授業科目
B80: 授業科目 | G80: 選択項目 | K80: 授業科目 | R80: 選択項目
A89: ⑩ プログラムを構成する授業の内容
B90: 授業に含まれている内容・要素 | D90: 講義内容
B91: （１）現在進行中の社会変化（第４次産業革命、Society 5.0、データ駆動型社会等）に深く寄与しているものであり、それが自らの生活と密接に結びついている | C91: 1-1 | D91: ■データサイエンス・AIの進展による社会の変化 ［第2回 データサイエンスの役割］ ビッグデータ、IoT、AIによる社会の変化、第4次産業革命への流れ、Society5.0、データ駆動型社会 【PowerPoint演習】［第6回～第8回］ プレゼン資料「現代社会のデータサイエンス」作成（第8回の課題） スライド2 ビックデータ蓄積の収集経路 スライド3 Society5.0の概念（図形による作図） スライド4 4つの巨大企業「GAFA」のサービスの特徴 スライド5 データ駆動型社会に必要な知識と人材 スライド6 日本企業のAI（人工知能）の活用事例（調べ学習）
C92: 1-6 | D92: ■ データ・AI利活用の最新動向 ［第2回 データサイエンスの役割］ GAFAの実態（サービスの特徴）、深層学習と強化学習の急速な発展 ［第7回 マーケティングでの活用事例］ 金融業や保険業における活用事例
B93: （２）「社会で活用されているデータ」や「データの活用領域」は非常に広範囲であって、日常生活や社会の課題を解決する有用なツールになり得るもの | C93: 1-2 | D93: ■社会で活用されているデータ ［第2回 データサイエンスの役割］ さまざまなビックデータの集積経路、ビックデータの活用事例、IOTの活用事例、データ駆動型社会 ［第4回 データサイエンスと情報倫理2］オープンデータの扱い方 ［第12回 オープンデータの取得方法］ e-Stat/RESAS/Yahooファイナンス/データ分析コンペサイト/取得したデータの前処理
C94: 1-3 | D94: ■データAIの活用領域 ［第7回 マーケティングでの活用事例］ マーケティングでの活用領域（消費者ビーズの把握/需要予測/セグメンテーション/推薦システム/アソシエーション分析/ポートフォリオセレクション/デフォルト確率の分析） ［第9回］Robotic Process Automation（RPA）を利用したAIの活用
B95: （３）様々なデータ利活用の現場におけるデータ利活用事例が示され、様々な適用領域（流通、製造、金融、サービス、インフラ、公共、ヘルスケア等）の知見と組み合わせることで価値を創出するもの | C95: 1-4 | D95: ■データ・AI利活用のための技術 ［第1回］ Windowsの基本操作、大学生活でのICTの活用法 ［第10回データ分析のための取得と管理］ データの形式、データの単位と容量 【Word演習】［第2回～第5回］ レポート「個人情報・著作物の利用とルール」の作成（第5回の課題） レポートを作成することにより、書式設定・図や表などの作成やレイアウトの設定技術の習得、Excelとの連携機能の習得。
C96: 1-5 | D96: ■データAI利活用の現場 ［第6回 PowerPointでのプレゼン資料作成］スライド6におけるに日本企業のAI活用事例の作成（1-1参照） ［第9回 金融での活用事例］ 金融業や保険業における活用事例
B97: （４）活用に当たっての様々な留意事項（ELSI、個人情報、データ倫理、ＡＩ社会原則等）を考慮し、情報セキュリティや情報漏洩等、データを守る上での留意事項への理解をする | C97: 3-1 | D97: ■データAIを扱う上での留意事項 ［第6回 ネット社会の危険と対策］ ウイルスの侵入経路・対策/パスワード管理/ネットショップでのトラブル ［第6回 データサイエンスと情報倫理3］ 情報の不正行為、情報の死角（フェイクニュース・データバイアス）、AI社会の論点 ［第7回 メールによるコミュニケーション］ 悪意のメール、メールのマナー ［第9回 Weｂによるコミュニケーション1］ 情報の信憑性、SNSなどの利用時の注意点など ［第10回 Webによるコミュニケーション2］ インスタ、出会い系サイト、クラウド利用のメリット ［第11回 モバイル機器の活用と管理］ スマホのカメラルールと紛失、オンライン授業、Wi-Fiの安全性
C98: 3-2 | D98: ■データを守る上での留意事項 ［第2回 情報化社会のモラルとセキュリティ］ 情報モラルとは、情報セキュリティとは ［第3回 個人情報の適切な取り扱い］ 個人情報保護法、個人情報とは ［第3回 データサイエンスと情報倫理1］ データの保護規則(GDPR)、データ活用における倫理・法律・社会的含意(ELSI) ［第4回 デジタル時代の著作権］ 著作権とは、コピべレポート、CDなどの貸し借り、デジタルデータの扱い ［第4回 データサイエンスと情報倫理2］情報の機密性・完全性・可用性
...

Sheet 様式１-2　プログラムを構成する授業科目
T1: 様式１-2 | V1: 「学部・学科によって、修了要件は相違する」場合は、本シートを複製の上＜様式１－〇＞と枝番号を付してください
B2: 大学等名 | C2: 東京国際大学
B3: プログラム名 | C3: 数理・データサイエンス・AI教育プログラム
A5: プログラムを構成する授業科目について
A7: ① 教育プログラムの修了要件 | L7: 学部・学科によって、修了要件は相違する
A9: ② 対象となる学部・学科名称
B11: 経済学部・国際関係学部
A14: ③ 修了要件
B15: 【Eトラックプログラム所属以外の学部生】 基礎教育分野に設置の「ICT基礎」2単位を修得すること。（履修必須） 【イングリッシュ・トラックプログラム(E-Track)所属学生】 Liberal Arts 分野に設置の「IT Literacy」4単位、または、Liberal Arts 分野に設置の「StatisticsⅠ」（4単位）及び「Introduction to Informatics ＆ Computing」（4単位）の2科目8単位を修得すること。（「IT Literacy」と「Introduction to Informatics ＆ Computing」は履修必須ではない。「StatisticsⅠ」は、Business Economics専攻とDigital Business ＆Innovation専攻の学生には、履修必須科目である） | X15: 【プルダウンリスト】
X16: 令和５年度以前より、履修することが必須のプログラムとして実施
X17: 令和８年度までに履修必須とする計画
X18: 令和９年度以降に履修必須とする計画、又は未定
B22: 必要最低科目数・単位数 | E22: 1 | F22: 科目 | H22: 2 | I22: 単位 | M22: 履修必須の有無 | N22: 令和４年度以前より、履修することが必須のプログラムとして実施
A24: ④ 現在進行中の社会変化（第４次産業革命、Society 5.0、データ駆動型社会等）に深く寄与しているものであり、それが自らの生活と密接に結びついている」の内容を含む授業科目
B26: 授業科目 | G26: 単位数 | H26: 必須 | I26: 1-1 | J26: 1-6 | K26: 授業科目 | R26: 単位数 | S26: 必須 | T26: 1-1 | U26: 1-6
B27: ICT基礎 | G27: 2 | H27: ○ | I27: ○ | J27: ○
B28: IT Literacy | G28: 4 | I28: ○ | J28: ○
B29: Statistcs I | G29: 4
B30: Introduction to Informatics ＆Computing | G30: 4 | I30: ○ | J30: ○
A35: ⑤ 「社会で活用されているデータ」や「データの活用領域」は非常に広範囲であって、日常生活や社会の課題を解決する有用なツールになり得るもの」の内容を含む授業科目
B37: 授業科目 | G37: 単位数 | H37: 必須 | I37: 1-2 | J37: 1-3 | K37: 授業科目 | R37: 単位数 | S37: 必須 | T37: 1-2 | U37: 1-3
B38: ICT基礎 | G38: 2 | H38: ○ | I38: ○ | J38: ○
B39: IT Literacy | G39: 4 | I39: ○ | J39: ○
B40: Statistcs I | G40: 4
B41: Introduction to Informatics ＆Computing | G41: 4 | I41: ○ | J41: ○
A46: ⑥ 「様々なデータ利活用の現場におけるデータ利活用事例が示され、様々な適用領域（流通、製造、金融、サービス、インフラ、公共、ヘルスケア等）の知見と組み合わせることで価値を創出するもの」の内容を含む授業科目
B48: 授業科目 | G48: 単位数 | H48: 必須 | I48: 1-4 | J48: 1-5 | K48: 授業科目 | R48: 単位数 | S48: 必須 | T48: 1-4 | U48: 1-5
B49: ICT基礎 | G49: 2 | H49: ○ | I49: ○ | J49: ○
B50: IT Literacy | G50: 4 | I50: ○ | J50: ○
B51: Statistcs I | G51: 4
B52: Introduction to Informatics ＆Computing | G52: 4 | I52: ○ | J52: ○
A57: ⑦ 「活用に当たっての様々な留意事項（ELSI、個人情報、データ倫理、ＡＩ社会原則等）を考慮し、情報セキュリティや情報漏洩等、データを守る上での留意事項への理解をする」の内容を含む授業科目
B59: 授業科目 | G59: 単位数 | H59: 必須 | I59: 3-1 | J59: 3-2 | K59: 授業科目 | R59: 単位数 | S59: 必須 | T59: 3-1 | U59: 3-2
B60: ICT基礎 | G60: 2 | H60: ○ | I60: ○ | J60: ○
B61: IT Literacy | G61: 4 | I61: ○ | J61: ○
B62: Statistcs I | G62: 4
B63: Introduction to Informatics ＆Computing | G63: 4 | I63: ○ | J63: ○
A68: ⑧ 「実データ・実課題（学術データ等を含む）を用いた演習など、社会での実例を題材として、「データを読む、説明する、扱う」といった数理・データサイエンス・ＡＩの基本的な活用法に関するもの」の内容を含む授業科目
B70: 授業科目 | F70: 単位数 | G70: 必須 | H70: 2-1 | I70: 2-2 | J70: 2-3 | K70: 授業科目 | Q70: 単位数 | R70: 必須 | S70: 2-1 | T70: 2-2 | U70: 2-3
B71: ICT基礎 | F71: 2 | G71: ○ | H71: ○ | I71: ○ | J71: ○
...

Sheet 様式２ 履修者等数の実績
S1: 様式２
Q2: ='様式１-2 プログラムを構成する授業科目'!C2 -> 東京国際大学
A3: プログラムの履修者数等の実績について
A5: ①プログラム開設年度 | C5: 令和5 | E5: 年度
A7: ②大学等全体の男女別学生数 | E7: 男性 | F7: 4634 | G7: 人 | H7: 女性 | I7: 2135 | J7: 人 | K7: （ | L7: 合計 | M7: =F7+I7 -> 6769 | N7: 人 | O7: ）
A9: ③履修者・修了者の実績
B11: 学部・学科名称 | C11: 学生数 | D11: 入学 定員 | E11: 収容 定員 | F11: 令和5年度 | H11: 令和4年度 | J11: 令和3年度 | L11: 令和2年度 | N11: 令和元年度 | P11: 平成30年度 | R11: 履修者数 合計 | S11: 履修率
F12: 履修者数 | G12: 修了者数 | H12: 履修者数 | I12: 修了者数 | J12: 履修者数 | K12: 修了者数 | L12: 履修者数 | M12: 修了者数 | N12: 履修者数 | O12: 修了者数 | P12: 履修者数 | Q12: 修了者数
B13: 商学部 | C13: 793 | D13: 260 | E13: 880 | F13: 242 | G13: 202 | H13: 0 | I13: 0 | J13: 0 | K13: 0 | L13: 0 | M13: 0 | N13: 0 | O13: 0 | P13: 0 | Q13: 0 | R13: =F13+H13+J13+L13+N13+P13 -> 242 | S13: =R13/E13 -> 0.275
B14: 経済学部 | C14: =944+897 -> 1841 | D14: 475 | E14: 1860 | F14: 916 | G14: 846 | H14: 0 | I14: 0 | J14: 0 | K14: 0 | L14: 0 | M14: 0 | N14: 0 | O14: 0 | P14: 0 | Q14: 0 | R14: =F14+H14+J14+L14+N14+P14 -> 916 | S14: =R14/E14 -> 0.49247312
B15: 言語コミュニケーション学部 | C15: 819 | D15: 250 | E15: 980 | F15: 246 | G15: 202 | H15: 0 | I15: 0 | J15: 0 | K15: 0 | L15: 0 | M15: 0 | N15: 0 | O15: 0 | P15: 0 | Q15: 0 | R15: =F15+H15+J15+L15+N15+P15 -> 246 | S15: =R15/E15 -> 0.25102041
B16: 国際関係学部 | C16: 1311 | D16: 370 | E16: 1415 | F16: 394 | G16: 344 | H16: 0 | I16: 0 | J16: 0 | K16: 0 | L16: 0 | M16: 0 | N16: 0 | O16: 0 | P16: 0 | Q16: 0 | R16: =F16+H16+J16+L16+N16+P16 -> 394 | S16: =R16/E16 -> 0.27844523
B17: 人間社会学部 | C17: 1795 | D17: 500 | E17: 1885 | F17: 507 | G17: 456 | H17: 0 | I17: 0 | J17: 0 | K17: 0 | L17: 0 | M17: 0 | N17: 0 | O17: 0 | P17: 0 | Q17: 0 | R17: =F17+H17+J17+L17+N17+P17 -> 507 | S17: =R17/E17 -> 0.26896552
B18: 医療健康学部 | C18: 210 | D18: 80 | E18: 240 | F18: 79 | G18: 78 | H18: 0 | I18: 0 | J18: 0 | K18: 0 | L18: 0 | M18: 0 | N18: 0 | O18: 0 | P18: 0 | Q18: 0 | R18: =F18+H18+J18+L18+N18+P18 -> 79 | S18: =R18/E18 -> 0.32916667
B29: 合 計 | C29: =SUM(C13:C28) -> 6769 | D29: =SUM(D13:D28) -> 1935 | E29: =SUM(E13:E28) -> 7260 | F29: =SUM(F13:F28) -> 2384 | G29: =SUM(G13:G28) -> 2128 | H29: =SUM(H13:H28) -> 0 | I29: =SUM(I13:I28) -> 0 | J29: =SUM(J13:J28) -> 0 | ... R29: =SUM(R13:R28) -> 2384 | S29: =R29/E29 -> 0.32837466

Sheet 様式３ 教育の質・履修者数を向上させるための体制・計画
I1: 様式３
G2: 大学等名 | H2: ='様式１-2 プログラムを構成する授業科目'!C2 -> 東京国際大学
A4: 教育の質・履修者数を向上させるための体制・計画について
A6: ① | B6: 全学の教員数 | C6: (常勤） | E6: 250 | F6: 人 | G6: （非常勤） | H6: 108 | I6: 人
A8: ② | B8: プログラムの授業を教えている教員数 | H8: 16 | I8: 人
A10: ③ | B10: プログラムの運営責任者
B11: （責任者名） | C11: 小室 広佐子 | G11: （役職名） | H11: 副学長
A13: ④ | B13: プログラムを改善・進化させるための体制（委員会・組織等）
B14: データサイエンス教育研究所
B16: （責任者名） | C16: 松尾 博文 | G16: （役職名） | H16: データサイエンス教育研究所長
A18: ⑤ | B18: プログラムを改善・進化させるための体制を定める規則名称
B19: 東京国際大学データサイエンス教育研究所設置規程
A21: ⑥ | B21: 体制の目的
B22: データサイエンス分野における研究教育の広範な事業展開を推進するとともに、数理・データサイエンス・AI教育に関係する授業科目の点検、評価、改善、充実に取り組んでいる。 【東京国際大学データサイエンス教育研究所設置規程 第2条・第3条：抜粋】 (設置) 第2 条 東京国際大学に，データサイエンス教育研究活動展開のため，その基本組織として， データサイエンス教育研究所を設置する。 (所管) 第3 条 データサイエンス教育研究所は，次の事項を所管する。 (1) データサイエンス分野における,研究教育での広範な事業展開 (2) 国内外の研究機関との共同研究 (3) その他常務会において必要と認めた前各号に準ずる事項
A34: ⑦ | B34: 具体的な構成員
B35: データサイエンス教育研究所 教授 松尾 博文（データサイエンス教育研究所長） データサイエンス教育研究所 教授 竹田 恒 データサイエンス教育研究所 教授 土屋 健 データサイエンス教育研究所 教授 山口 智弘
A48: ⑧ | B48: 履修者数・履修率の向上に向けた計画 ※様式１の「履修必須の有無」で「計画がある」としている場合は詳細について記載すること
B49: 令和５年度実績 | C49: ='様式２ 履修者等数の実績'!S29 -> 0.32837466 | E49: 令和６年度予定 | F49: 0.59 | H49: 令和７年度予定 | I49: 0.76
B50: 令和８年度予定 | C50: 0.92 | E50: 令和９年度予定 | F50: 0.95 | H50: 収容定員（名） | I50: ='様式２ 履修者等数の実績'!E29 -> 7260
B51: 具体的な計画
B52: 2016年度（平成28年）度入学生以降カリキュラムの「基礎教育分野」に「ICT基礎」（2単位）を設置し、所属学部学科にかかわらず1年次から履修を義務付けている。 同科目は、「初年次演習」、「大学生活デザイン演習」とともに「TIUコア科目」として位置付けており、入学時のガイダンスで履修に関する説明をする他、「学生ガイドブック【履修編】」でも専用の説明ページを設けている。 なお、経済学部、国際関係学部にはイングリッシュ・トラックプログラム（E-Trackプログラム＝英語による授業により学位取得が可能なコース）を設置している。本プログラムにはLiberal Arts 分野に「IT Literacy」（4単位）、「StatisticsⅠ」（4単位）、「Introduction to Informatics ＆ Computing」(4単位)を開講し、上記「ICT基礎」に相当する授業を実施している。 なお、令和７年度以降は、学生からのニーズが多い「IT Literacy」、「Introduction to Informatics ＆ Computing」についてクラス数を増やし、履修者数の増加を図る予定である。
A65: ⑨ | B65: 学部・学科に関係なく希望する学生全員が受講可能となるような必要な体制・取組等
B66: 上記⑧の他、履修者の成績が向上するよう総括責任者、データサイエンス教育研究所構成員及び教務部部課長をメンバーとした期中の中間報告、授業終了後の総括を実施し、授業の進め方、内容が履修者にマッチするよう確認をしている。
A79: ⑩ | B79: できる限り多くの学生が履修できるような具体的な周知方法・取組
B80: 不合格となった科目の再履修を認めている。
A93: ⑪ | B93: できる限り多くの学生が履修・修得できるようなサポート体制
B94: いづれの科目も1年次から履修ができる科目に位置付けており、履修の機会を広げている。 情報モラルと情報セキュリティ・データサイエンスの講義では、重要点が理解しやすいように、スライドの投影を行っている。スライドがあることにより、各クラスの進捗度・理解度の差を防ぐことができる。 受講にはBYODとして各自パソコンを持つことを必須としており、推奨パソコンの紹介や必要スペックなどの情報を提供している。学内のWi-Fi環境を整え、Microsoft365を無償利用ができる。
A107: ⑫ | B107: 授業時間内外で学習指導、質問を受け付ける具体的な仕組み
B108: オフィスアワーを活用し、授業以外でも担当教員に質問ができるシステムを構築している。 大学全体で使用している学習支援システム「Moodle」を活用し、学習指導内容の提供体制も整えている。 授業時間外に資格試験を受験することに対する支援として、MOS資格試験対策、ＩＴパスポート対策講座の実施をしている。

Sheet 様式４　自己点検・評価
I1: 様式４
H2: 大学等名 | I2: ='様式１-2 プログラムを構成する授業科目'!C2 -> 東京国際大学
A3: 自己点検・評価について
A5: ① | B5: プログラムの自己点検・評価を行う体制（委員会・組織等）
B6: データサイエンス教育研究所
D8: （責任者名） | E8: 松尾 博文 | G8: （役職名） | H8: データサイエンス教育研究所長
A10: ② | B10: 自己点検・評価体制における意見等
B11: 自己点検・評価の視点 | E11: 自己点検・評価体制における意見・結果・改善に向けた取組等
B12: 学内からの視点
C13: プログラムの履修・修得状況 | E13: 「ICT基礎」、「IT Literacy」、「StatisticsⅠ」、「Introduction to Informatics ＆ Computing」は1年次から履修が可能としている。また、不合格になった場合でも再履修ができる。 各クラスの履修・習得状況は、Excelの成績評価シートから確認できるようになっている。クラスごとのシートにより各回の履修状況がわかる。 令和5年度の「ICT基礎」/「IT Literacy」の履修状況は次のとおりである。 「ICT基礎」：履修者1,683名、単位認定者1,453名、合格率86.3％ 「IT Literacy」：履修者475名、単位認定者452、合格率 95.2％ 「StatisticsⅠ」+「Introduction to Informatics ＆ Computing」：履修者382名、単位認定者371、合格率 97.1％
C14: 学修成果 | E14: 【ICT基礎】本プログラムの学修成果は、Excelの成績評価シートから把握できるようになっている。成績評価のつけ方は、大きく分けて出席点と課題点に分けられる。出席点は出席（50分以上の出席必須）すれば「○」となる。（1回2.5点） 課題点は、毎回の確認テスト（4 肢択一式 10問）とOfficeの課題日に行う実技実習を実施している。 毎回の確認テストは、6点以上で合格となり、「○」となる。（1回2.5点）基準点に達するまで再トライできる仕組みを取り入れている。Officeの実技演習課題は、作成データを提出させ、すべて目視にて学修成果を確認している。基準点に達していれば「○」となる。14回分の出席点＋課題点の評価は全体の70％となっている。残り30％は、定期試験での小テスト（各回の確認テストから抜粋して出題）の点数が加えられる。 【IT Literacy】プレゼンテーション、ディスカッション、フィールドワーク、実習を重視した授業を実施した。また、宿題に対するフィードバックをMoodleを通じて学生に伝達することで、学習意欲の持続を図っている。 【StatisticsⅠ】講義中心の科目であり、ほぼ毎回、授業中に小テストがあり、採点後、フィードバックを学生に与えている。小テストの成績は平常点として成績に反映させている。学期内に試験を２から３回実施し成績に反映させている。 【Introduction to Informatics ＆ Computing】講義を中心とした授業であるが、ウェブサイトの作成の演習指導も行っている。成績評価は、毎回ごとのMoodleを用いた小テスト、2回実施する試験、個人ウエッブサイトの作成とそれに関するレポートの提出をもとにしている。
C15: 学生アンケート等を通じた学生の内容の理解度 | E15: 講義終了後に受講者を対象に授業評価アンケートを実施している。授業評価アンケートによる理解度は、概ね良好であり、小テストでは高得点を取得する比率が高いため、理解度は高いと考えている。 「この授業で教わったことを理解し、身につけられたと思いますか？」の質問事項に対して、「とてもそう思う」「そう思う」と回答した割合は、クラスによるが6割～7割となっており、中立まで入れると8割～9割となっている。 また、各回の確認テストや課題によって理解度を深めることができたと考えている。
C16: 学生アンケート等を通じた後輩等他の学生への推奨度 | E16: 授業評価アンケートの「この科目を友人や後輩等にすすめたいと思いますか？」の質問事項に対しては、6割程度が「とてもそう思う」、「そう思う」と回答しており、中立まで入れると7.5割程度となっている。「まったくそう思わない」「そう思わない」と回答したのは1割未満となっている。 授業評価アンケートの自由記述内容からは、授業のスピードがよい、理解しやすい、スライドがわかりやすい、パソコンのスキルが身に着く、質問しやすい環境などの意見が多数ある。
C17: 全学的な履修者数、履修率向上に向けた計画の達成・進捗状況 | E17: 全学的な履修者数、履修率については、学期途中の中間報告と学期末において、分析結果をデータサイエンス教育研究所構成員及び教務部部課長、総括責任者、教員をメンバーとする総括会議にて、フィードバックし検証を行っている。 総括会議では、今後の課題点や問題点の洗い出しを行い、次年度以降の授業運営に役立てている。 令和6年度は、単位取得率の向上を目指している。
B18: 学外からの視点
C19: 教育プログラム修了者の進路、活躍状況、企業等の評価 | E19: 現状では学外からの評価は受けていない。今後、本プログラムの認定後の第１期卒業生に向けて就職先に卒業生の状況の聞き取りを行う予定である。
C20: 産業界からの視点を含めた教育プログラム内容・手法等への意見 | E20: 現状では産業界から意見を徴収する機会がないが、本プログラム第1期生の卒業後2026年以降には、卒業生からの視点での意見を取り入れると共に、卒業生の就職先企業等からの視点で意見を取り入れることが出来るように、聴取時期や聴取者、聴取内容などを検討し、教育プログラムへ反映できるように構築する予定である。 また、本プログラムの教員には、産業界の外部企業教員が担当している。これらの教員からも教育プログラムの内容や手法についての意見を取り入れ見直しができるシステムを継続的に構築している。
B21: 数理・データサイエンス・ＡＩを「学ぶ楽しさ」「学ぶことの意義」を理解させること | E21: 【ICT基礎】【IT Literacy】数理・データサイエンス・AIを学ぶことになった経緯や意義をスライドを基に説明している。内容としては、Society5.0の新しい情報社会は、スマートフォンやセンサー情報、人工衛星などから集積した多種・多様なビックデータの情報があり、これらの利用がイノベーションを生み出すことや現代社会の移り変わりについて、データを加工・分析する技術を持ち、データから価値を引き出すことができる専門的な人材（データサイエンティスト）が必要であることなどを説明している。 本プログラムはOffice製品を学び、データを扱う実技演習を含めている。実技演習は、教員と一緒に画面を操作するが、パソコンに慣れていない学生やOfficeアプリを体系的に学んでいない学生が多いが、授業評価アンケートからは、知らなかった多くのことを学べる機会があり、興味を持って学んだことが分かる。Word課題では、情報倫理についてのレポート作成、PowerPoint課題では、現在社会のデータサイエンスのスライド作成、Excel課題では、売上データ分析を行い、数理・データサイエンス・AIの内容と絡めており、学ぶ楽しさや学ぶことの意義が伝わるプログラムとしている。 座学講義では、学生が数理・データサイエンス・ＡＩの内容を把握しやすいように、スライドを用いて身近な事例を紹介し、興味を持てるよう授業を実施している。 【StatisticsⅠ】【Introduction to Informatics ＆ Computing】数理・データサイエンス・AIを学ぶ楽しさと意義を単に社会科学的な視点からだけではなくて、文理融合的な視点を強調することにより、理解させるように努めている。両科目は、欧米で使用されている標準的な教科書に沿う形で、統計学の基礎とコンピュータのハードとソフトについての工学的な理解を求めている。Eトラックプログラムにおいては、AI、パイソンプログラミング、デジタルマーケティング、ブロックチェーン等のAI・データサイエンス関連の専門科目が多いので、カリキュラムの初期に当該分野全体の基礎となる統計学とハード・ソフトの知識を理解することは、カリキュラム全体での学ぶ楽しさと意義を増大させることになる。
B22: 内容・水準を維持・向上しつつ、より「分かりやすい」授業とすること ※社会の変化や生成AI等の技術の発展を踏まえて教育内容を継続的に見直すなど、より教育効果の高まる授業内容・方法とするための取組や仕組みについても該当があれば記載 | E22: 本プログラムの内容・水準を維持・向上するために、学期末に行う授業評価アンケートを活用している。学生からのコメントとして、「分かりやすくてためになった」「理解が深まった」「授業テンポが丁度よい」「質問がしやすい」「パソコンの知識を多く学べた」などの肯定的な意見が多くあったが、改善点や要望として、「テンポが速い時がある」「進みが遅い」「サブ教員を増やしてほしい」などの意見もあった。これらの意見を問題点・課題点として捉え、さらなる「分かりやすい」授業へと改善し工夫していきたい。 全学必修の本プログラムでは、全クラスのシラバス、資料を共有している。目的・目標が分かりやすいシラバスを提示し、「分かりやすい」授業とするために、共有資料は継続的に見直していく予定である。 日本企業の活用事例を調べ、プレゼン資料に適時反映させ、社会の変化や生成AI等のICT技術の発展を身近に感じさせることで教育効果を高める取り組みを行っている。
