Workbook

Sheet 様式１ー１　プログラムを構成する授業科目 (薬学)
T1: 様式１-1 | V1: 「学部・学科によって、修了要件は相違する」場合は、本シートを複製の上＜様式１－〇＞と枝番号を付してください
B2: 大学等名 | C2: 東京薬科大学
B3: プログラム名 | C3: 東京薬科大学データサイエンス教育プログラム
A5: プログラムを構成する授業科目について
A7: ① 教育プログラムの修了要件 | L7: 学部・学科によって、修了要件は相違する
A9: ② 対象となる学部・学科名称
B11: 薬学部
A14: ③ 修了要件
B15: 「データサイエンス入門」（1年前期・1単位）を履修し、単位を取得すること。 | X15: 【プルダウンリスト】
X16: 令和５年度以前より、履修することが必須のプログラムとして実施
X17: 令和８年度までに履修必須とする計画
X18: 令和９年度以降に履修必須とする計画、又は未定
B22: 必要最低科目数・単位数 | E22: 1 | F22: 科目 | H22: 1 | I22: 単位 | M22: 履修必須の有無 | N22: 令和８年度までに履修必須とする計画
A24: ④ 現在進行中の社会変化（第４次産業革命、Society 5.0、データ駆動型社会等）に深く寄与しているものであり、それが自らの生活と密接に結びついている」の内容を含む授業科目
B26: 授業科目 | G26: 単位数 | H26: 必須 | I26: 1-1 | J26: 1-6 | K26: 授業科目 | R26: 単位数 | S26: 必須 | T26: 1-1 | U26: 1-6
B27: データサイエンス入門 | G27: 1 | H27: ○ | I27: ○ | J27: ○
A35: ⑤ 「社会で活用されているデータ」や「データの活用領域」は非常に広範囲であって、日常生活や社会の課題を解決する有用なツールになり得るもの」の内容を含む授業科目
B37: 授業科目 | G37: 単位数 | H37: 必須 | I37: 1-2 | J37: 1-3 | K37: 授業科目 | R37: 単位数 | S37: 必須 | T37: 1-2 | U37: 1-3
B38: データサイエンス入門 | G38: 1 | H38: ○ | I38: ○ | J38: ○
A46: ⑥ 「様々なデータ利活用の現場におけるデータ利活用事例が示され、様々な適用領域（流通、製造、金融、サービス、インフラ、公共、ヘルスケア等）の知見と組み合わせることで価値を創出するもの」の内容を含む授業科目
B48: 授業科目 | G48: 単位数 | H48: 必須 | I48: 1-4 | J48: 1-5 | K48: 授業科目 | R48: 単位数 | S48: 必須 | T48: 1-4 | U48: 1-5
B49: データサイエンス入門 | G49: 1 | H49: ○ | I49: ○ | J49: ○
A57: ⑦ 「活用に当たっての様々な留意事項（ELSI、個人情報、データ倫理、ＡＩ社会原則等）を考慮し、情報セキュリティや情報漏洩等、データを守る上での留意事項への理解をする」の内容を含む授業科目
B59: 授業科目 | G59: 単位数 | H59: 必須 | I59: 3-1 | J59: 3-2 | K59: 授業科目 | R59: 単位数 | S59: 必須 | T59: 3-1 | U59: 3-2
B60: データサイエンス入門 | G60: 1 | H60: ○ | I60: ○ | J60: ○
A68: ⑧ 「実データ・実課題（学術データ等を含む）を用いた演習など、社会での実例を題材として、「データを読む、説明する、扱う」といった数理・データサイエンス・ＡＩの基本的な活用法に関するもの」の内容を含む授業科目
B70: 授業科目 | F70: 単位数 | G70: 必須 | H70: 2-1 | I70: 2-2 | J70: 2-3 | K70: 授業科目 | Q70: 単位数 | R70: 必須 | S70: 2-1 | T70: 2-2 | U70: 2-3
B71: データサイエンス入門 | F71: 1 | G71: ○ | H71: ○ | I71: ○ | J71: ○
A79: ⑨ 選択「４．オプション」の内容を含む授業科目
B80: 授業科目 | G80: 選択項目 | K80: 授業科目 | R80: 選択項目
A89: ⑩ プログラムを構成する授業の内容
B90: 授業に含まれている内容・要素 | D90: 講義内容
B91: （１）現在進行中の社会変化（第４次産業革命、Society 5.0、データ駆動型社会等）に深く寄与しているものであり、それが自らの生活と密接に結びついている | C91: 1-1 | D91: 1-1. データサイエンスとは（1回目） ・データサイエンスとは ・データサイエンスが重要視される背景 ・データ活用を支援するデジタル技術のキーワード：ビッグデータ、IoT、AI、ロボット 1-1. 社会で起きている変化（任意受講） ・日本企業の国際競争力低下 ・市場の大きな変化 ・デジタル技術の発展 ・デジタル社会の提言：第4次産業革命、Industrie4.0、Society5.0
C92: 1-6 | D92: 1-6. データ・AI利活用の最新動向（任意受講） ・データ・AIを活用した新しいビジネス：犯罪を予測する、売却物件を予測する、農作業の意思決定支援を行う、送金取引を相殺させる、個人信用評価 ・データ・AIに関連した新技術：敵対的生成ネットワーク、強化学習、転移学習 1-6. AI・データサイエンストレンド2023（13回目） ・ロシアのウクライナ侵攻における「ハイブリッド戦」 ・生成型AIの台頭 ・メタバースへの注目 ・マイナンバーカードの普及 ・DX銘柄2022の選出 ・「医療DX令和ビジョン2030」の策定 ・「夏のDigi田（デジデン）甲子園」の開催 ・アナログ規制の見直しに係る工程表 ・自動走行車・ドローン活用に向けた法制度改正 ・デジタルスキル標準の策定
B93: （２）「社会で活用されているデータ」や「データの活用領域」は非常に広範囲であって、日常生活や社会の課題を解決する有用なツールになり得るもの | C93: 1-2 | D93: 1-2. 社会で活用されているデータ（任意受講） ・統計データ；国勢調査、人口推移、人口ピラミッド ・人の行動ログデータ：モバイル空間統計、混雑予想 ・機械の稼働ログデータ：自動車、テレマティック保険、通行情報実績 ・データの分類：1次／2次データ、外部／内部データ、構造化／準構造化／非構造化データ、CSVファイル ・オープンデータ：新型コロナウィルス対策感染症病床数、衛生検査結果データ、犯罪発生情報データ 1-2. 医療におけるデータ利活用（12回目） ・データサイエンスで医療薬学研究に挑戦しよう ・医療データサイエンスに関するソフトの話 ・ファーマコビジランスで用いられる医療情報データベースについて ・医療情報データベースについて ・治療用アプリについて ・ePRO ・解析に使うそのデータ、大丈夫？
C94: 1-3 | D94: 1-3. データ・AIの活用領域（2回目） ・AIの定義 ・AIの歴史 ・業種別のAI活用領域（製造業、小売業、物流業、医療・介護分野） ・人間に近づくＡＩ（絵画を描くＡＩ、作曲をするＡＩ、小説を書くＡＩ、入試に合格するＡＩ） 1-3. データ活用とは（4回目） ・データの定義 ・データ活用のモデル：データ・情報・知識・知恵のモデル、SECI（セキ）モデル ・データ分析のアプローチ：目的設定、分析計画、データ設計、データ収集・保存、データの前処理、分析手法選択と適用、分析結果の解釈施策の提案、実施と検証
B95: （３）様々なデータ利活用の現場におけるデータ利活用事例が示され、様々な適用領域（流通、製造、金融、サービス、インフラ、公共、ヘルスケア等）の知見と組み合わせることで価値を創出するもの | C95: 1-4 | D95: 1-4. データ・AIの活用のための技術（3回目） ・データ認識技術：画像認識、文字認識、音声認識、顔認証 ・AI技術；機械学習、強化学習、ディープラーニング ・AIの課題、AIの難問：未学習・過学習、フレーム問題、モラベックのパラドックス、シンボルグラウンディング問題、ウォズニアックテスト ・AIがもたらす影響；シンギュラリティ
C96: 1-5 | D96: 1-5. データ・AI利活用の現場（5回目） ・製造業のデータ・AI活用：建設機械の挙動・状況把握、デジタル複合機のリモート管理、電気自動車、スマートグラス、IoTスキンケアシステム ・小売業のデータ・AI活用：ID-POS、Amazon GO ・サービス業のデータ・AI活用：資産運用、無担保融資、オンライン融資 ・公共・インフラのデータ・AI活用：スマートメーター、橋梁モニタリング、MaaS ・データ・AI活用による新しいビジネス：シェアリングエコノミー、D2C、スマートシティ ・データ・AI利活用の分類
B97: （４）活用に当たっての様々な留意事項（ELSI、個人情報、データ倫理、ＡＩ社会原則等）を考慮し、情報セキュリティや情報漏洩等、データを守る上での留意事項への理解をする | C97: 3-1 | D97: 3-1. データ・AIを扱う上での留意事項（１）（10回目） ・ELSI（Ethical, Legal and Social Issues） ・データに関する不正行為：ねつ造・改ざん・盗用 ・個人情報の保護：個人情報保護法、オプトイン／オプトアウト、Midata、EU一般データ保護規則（GDPR）、忘れられる権利、カリフォルニア州消費者プライバシー法（CCPA） ・個人情報は誰が管理すべきか：日本vs.中国、管理主体によるメリット・デメリット 3-1. データ・AIを扱う上での留意事項（２）（任意受講） ・バイアス：データ収集におけるバイアス：スナップショット調査におけるバイアス、継続調査におけるバイアス、データ収集でのバイアス、アンケート対象者によるバイアス、トランスレーション・バイアス、インタビュアーによるバイアス、質問票によるバイアス、サンプル抽出におけるバイアス ・データ・AIを扱う上でのバイアス：アルゴリズムバイアスの発生事例 ・AIの正しい活用に向けて：人工知能学会「倫理指針」、人工知能学会「機械学習と公平性に関する声明」、AIに関するOECD原則、人間中心のAI社会原則、民間企業におけるAI倫理指針
C98: 3-2 | D98: 3-2. データを守る上での留意事項とまとめ（11回目） ・情報セキュリティ：機密性・完全性・可用性、情報漏洩 ・従業員等による内部不正 ・コンピュータウィルスへの感染 ・サイバー攻撃 ・情報セキュリティ脅威事例 ・セキュリティ技術：暗号技術、認証技術
...

Sheet 様式１ー２　プログラムを構成する授業科目（生命）
T1: 様式１-2 | V1: 「学部・学科によって、修了要件は相違する」場合は、本シートを複製の上＜様式１－〇＞と枝番号を付してください
B2: 大学等名 | C2: 東京薬科大学
B3: プログラム名 | C3: 東京薬科大学データサイエンス教育プログラム
A5: プログラムを構成する授業科目について
A7: ① 教育プログラムの修了要件 | L7: 学部・学科によって、修了要件は相違する
A9: ② 対象となる学部・学科名称
B11: 生命科学部
A14: ③ 修了要件
B15: 生命科学部では、データサイエンスプログラムを構成する下記科目のうち、13単位以上を取得すること。 ★学部の必修科目（5単位） 数学Ⅰ、情報科学Ⅰ、生物統計学 ★認定証の必須科目（7単位） 数学Ⅱ、情報科学Ⅱ、情報科学Ⅲ、生命科学Ⅳ（基礎情報学）、生命科学Ⅴ（計算機の論理とデータ構造）、分子生命科学Ⅵ（バイオインフォマティクス） ★認定証の選択必須科目 ＊１科目以上取得 ICT活用の理論と実践、生命医科学Ⅹ（ゲノム情報医科学）、生命科学VI（応用統計学) | X15: 【プルダウンリスト】
X16: 令和５年度以前より、履修することが必須のプログラムとして実施
X17: 令和８年度までに履修必須とする計画
X18: 令和９年度以降に履修必須とする計画、又は未定
B22: 必要最低科目数・単位数 | E22: 10 | F22: 科目 | H22: 13 | I22: 単位 | M22: 履修必須の有無 | N22: 令和９年度以降に履修必須とする計画、又は未定
A24: ④ 現在進行中の社会変化（第４次産業革命、Society 5.0、データ駆動型社会等）に深く寄与しているものであり、それが自らの生活と密接に結びついている」の内容を含む授業科目
B26: 授業科目 | G26: 単位数 | H26: 必須 | I26: 1-1 | J26: 1-6 | K26: 授業科目 | R26: 単位数 | S26: 必須 | T26: 1-1 | U26: 1-6
B27: 情報科学 Ｉ | G27: 1 | H27: ○ | I27: ○ | J27: ○
B28: 情報科学 II | G28: 1 | I28: ○ | J28: ○
B29: 生命科学 IV（基礎情報学） | G29: 1 | I29: ○ | J29: ○
B30: 情報科学III | G30: 1 | I30: ○ | J30: ○
A35: ⑤ 「社会で活用されているデータ」や「データの活用領域」は非常に広範囲であって、日常生活や社会の課題を解決する有用なツールになり得るもの」の内容を含む授業科目
B37: 授業科目 | G37: 単位数 | H37: 必須 | I37: 1-2 | J37: 1-3 | K37: 授業科目 | R37: 単位数 | S37: 必須 | T37: 1-2 | U37: 1-3
B38: 情報科学 Ｉ | G38: 1 | H38: ○ | I38: ○ | J38: ○
B39: 情報科学 II | G39: 1 | I39: ○
B40: 生命科学 IV（基礎情報学） | G40: 1 | J40: ○
B41: ICT活用の理論と実践 | G41: 1 | I41: ○
A46: ⑥ 「様々なデータ利活用の現場におけるデータ利活用事例が示され、様々な適用領域（流通、製造、金融、サービス、インフラ、公共、ヘルスケア等）の知見と組み合わせることで価値を創出するもの」の内容を含む授業科目
B48: 授業科目 | G48: 単位数 | H48: 必須 | I48: 1-4 | J48: 1-5 | K48: 授業科目 | R48: 単位数 | S48: 必須 | T48: 1-4 | U48: 1-5
B49: 情報科学 Ｉ | G49: 1 | H49: ○ | I49: ○ | J49: ○
B50: 情報科学 II | G50: 1 | I50: ○ | J50: ○
B51: 生命科学 IV（基礎情報学） | G51: 1 | I51: ○
B52: 情報科学III | G52: 1 | I52: ○
A57: ⑦ 「活用に当たっての様々な留意事項（ELSI、個人情報、データ倫理、ＡＩ社会原則等）を考慮し、情報セキュリティや情報漏洩等、データを守る上での留意事項への理解をする」の内容を含む授業科目
B59: 授業科目 | G59: 単位数 | H59: 必須 | I59: 3-1 | J59: 3-2 | K59: 授業科目 | R59: 単位数 | S59: 必須 | T59: 3-1 | U59: 3-2
B60: 情報科学 Ｉ | G60: 1 | H60: ○ | I60: ○ | J60: ○
A68: ⑧ 「実データ・実課題（学術データ等を含む）を用いた演習など、社会での実例を題材として、「データを読む、説明する、扱う」といった数理・データサイエンス・ＡＩの基本的な活用法に関するもの」の内容を含む授業科目
B70: 授業科目 | F70: 単位数 | G70: 必須 | H70: 2-1 | I70: 2-2 | J70: 2-3 | K70: 授業科目 | Q70: 単位数 | R70: 必須 | S70: 2-1 | T70: 2-2 | U70: 2-3
B71: 情報科学I | F71: 1 | G71: ○ | H71: ○ | I71: ○ | J71: ○
B72: 情報科学II | F72: 1 | H72: ○ | I72: ○ | J72: ○
B73: 分子生命科学Ⅵ（バイオインフォマティクス） | F73: 1 | H73: ○
B74: ICT活用の理論と実践 | F74: 1 | H74: ○ | J74: ○
...

Sheet 様式２ 履修者等数の実績
S1: 様式２
Q2: ='様式１ー２ プログラムを構成する授業科目（生命）'!C2 -> 東京薬科大学
A3: プログラムの履修者数等の実績について
A5: ①プログラム開設年度 | C5: 令和５ | E5: 年度
A7: ②大学等全体の男女別学生数 | E7: 男性 | F7: 1701 | G7: 人 | H7: 女性 | I7: 2065 | J7: 人 | K7: （ | L7: 合計 | M7: =F7+I7 -> 3766 | N7: 人 | O7: ）
A9: ③履修者・修了者の実績
B11: 学部・学科名称 | C11: 学生数 | D11: 入学 定員 | E11: 収容 定員 | F11: 令和5年度 | H11: 令和4年度 | J11: 令和3年度 | L11: 令和2年度 | N11: 令和元年度 | P11: 平成30年度 | R11: 履修者数 合計 | S11: 履修率
F12: 履修者数 | G12: 修了者数 | H12: 履修者数 | I12: 修了者数 | J12: 履修者数 | K12: 修了者数 | L12: 履修者数 | M12: 修了者数 | N12: 履修者数 | O12: 修了者数 | P12: 履修者数 | Q12: 修了者数
B13: 薬学部 | C13: 2801 | D13: 420 | E13: 2520 | F13: 50 | G13: 43 | R13: =F13+H13+J13+L13+N13+P13 -> 50 | S13: =R13/E13 -> 0.01984127
B14: 生命科学部 | C14: 965 | D14: 220 | E14: 886 | F14: 262 | G14: 0 | R14: =F14+H14+J14+L14+N14+P14 -> 262 | S14: =R14/E14 -> 0.29571106
R15: =F15+H15+J15+L15+N15+P15 -> 0 | S15: =R15/E15 -> #DIV/0!
R16: =F16+H16+J16+L16+N16+P16 -> 0 | S16: =R16/E16 -> #DIV/0!
R17: =F17+H17+J17+L17+N17+P17 -> 0 | S17: =R17/E17 -> #DIV/0!
R18: =F18+H18+J18+L18+N18+P18 -> 0 | S18: =R18/E18 -> #DIV/0!
R19: =F19+H19+J19+L19+N19+P19 -> 0 | S19: =R19/E19 -> #DIV/0!
R20: =F20+H20+J20+L20+N20+P20 -> 0 | S20: =R20/E20 -> #DIV/0!
R21: =F21+H21+J21+L21+N21+P21 -> 0 | S21: =R21/E21 -> #DIV/0!
R22: =F22+H22+J22+L22+N22+P22 -> 0 | S22: =R22/E22 -> #DIV/0!
R23: =F23+H23+J23+L23+N23+P23 -> 0 | S23: =R23/E23 -> #DIV/0!
R24: =F24+H24+J24+L24+N24+P24 -> 0 | S24: =R24/E24 -> #DIV/0!
R25: =F25+H25+J25+L25+N25+P25 -> 0 | S25: =R25/E25 -> #DIV/0!
R26: =F26+H26+J26+L26+N26+P26 -> 0 | S26: =R26/E26 -> #DIV/0!
... R32: =F32+H32+J32+L32+N32+P32 -> 0 | S32: =R32/E32 -> #DIV/0!
B33: 合 計 | C33: =SUM(C13:C32) -> 3766 | D33: =SUM(D13:D32) -> 640 | E33: =SUM(E13:E32) -> 3406 | F33: =SUM(F13:F32) -> 312 | G33: =SUM(G13:G32) -> 43 | H33: =SUM(H13:H32) -> 0 | I33: =SUM(I13:I32) -> 0 | J33: =SUM(J13:J32) -> 0 | ... R33: =SUM(R13:R32) -> 312 | S33: =R33/E33 -> 0.091603053

Sheet 様式３ 教育の質・履修者数を向上させるための体制・計画
I1: 様式３
G2: 大学等名 | H2: ='様式１ー２ プログラムを構成する授業科目（生命）'!C2 -> 東京薬科大学
A4: 教育の質・履修者数を向上させるための体制・計画について
A6: ① | B6: 全学の教員数 | C6: (常勤） | E6: 201 | F6: 人 | G6: （非常勤） | H6: 68 | I6: 人
A8: ② | B8: プログラムの授業を教えている教員数 | H8: 11 | I8: 人
A10: ③ | B10: プログラムの運営責任者
B11: （責任者名） | C11: 小島正樹 | G11: （役職名） | H11: 教授
A13: ④ | B13: プログラムを改善・進化させるための体制（委員会・組織等）
B14: データサイエンス教育推進委員会
B16: （責任者名） | C16: 小島正樹 | G16: （役職名） | H16: 教授
A18: ⑤ | B18: プログラムを改善・進化させるための体制を定める規則名称
B19: 東京薬科大学データサイエンス教育推進委員会規程
A21: ⑥ | B21: 体制の目的
B22: 本学は、全学において「データを活用し、社会の課題を発見・解決できる人材」を育成することを目的として「データサイエンス教育推進委員会」を2021年10月に設置した。同委員会は薬学部および生命科学部において数理・データサイエンス・AI関連の授業科目を担当する教員により構成されているため、履修学生へのアンケートや学修状況の把握などによる情報収集がスムーズに実施でき、プログラムの改善に必要な情報収集と意思決定を速やかに行うことが出来る。また、履修学生や産業界等の意見を取り入れながらプログラムの改善、自己点検・評価を実施し、その結果を公表する。
A34: ⑦ | B34: 具体的な構成員
B35: 委員長 小島正樹（生命科学部・教授） 委員 薬学部 陳 惠一 教授、川口 崇 准教授、恩田健二 講師、倉田香織 助教 山田寛尚 助教、長谷川 要 特命講師 生命科学部 高須昌子 教授、野口 航 教授、細道一善 教授、土方敦司 准教授 森河良太 准教授、野口 瑶 助教 事務局 学務部長 高山知久、教学IR研究推進課長 千葉まこと
A48: ⑧ | B48: 履修者数・履修率の向上に向けた計画 ※様式１の「履修必須の有無」で「計画がある」としている場合は詳細について記載すること
B49: 令和５年度実績 | C49: ='様式２ 履修者等数の実績'!S33 -> 0.091603053 | E49: 令和６年度予定 | F49: 0.28 | H49: 令和７年度予定 | I49: 0.47
B50: 令和８年度予定 | C50: 0.66 | E50: 令和９年度予定 | F50: 0.84 | H50: 収容定員（名） | I50: ='様式２ 履修者等数の実績'!E33 -> 3406
B51: 具体的な計画
B52: 薬学部の「データサイエンス入門」は、令和４年度に１年生の一般教養・選択科目として開講した。数理・データサイエンス・AIに関する教養レベルの知識はベネッセ社のオンデマンド教材を活用し、薬剤師向けの医薬データサイエンスに特化したオリジナル教材を組み合わせて特徴のあるプログラムを構成し受講できるように開講した。令和6年度より1年生の一般教養・必修科目とし、学生全員が受講できるように履修を促進する。 生命科学部では、令和2年度より実施している新カリキュラムにおいて、新しい時代のニーズに応える特別プログラムの1つとしてデータサイエンスプログラムを導入した。指定対象科目の単位を取得すれば、認定証を発行されるシステムとなっている。「AI戦略2019」のモデルカリキュラムに基づいた科目群で構成されているため、MDASHのスキルセットが自動的に履修できるようになっている。令和5年度における修了者数は6%であったが、令和6年度よりオープンバッジを導入して学修成果の可視化をはかり（マイクロクレデンシャル）、履修のモチベーション向上を計画している。現時点で必修化の予定はないが、令和3年に策定した本学中長期計画「TOUYAKU150」にKPIとして掲げるデータサイエンティスト関連資格取得件数30%以上（4年在籍人数比）に準じた履修率の向上を目指す。
A65: ⑨ | B65: 学部・学科に関係なく希望する学生全員が受講可能となるような必要な体制・取組等
B66: 薬学部の「データサイエンス入門」は、令和４年度から選択科目として開講したが、令和６年度以降より、1年生の一般教養・必修科目とし、学生全員が受講できるように履修を促進する予定。 生命科学部のカリキュラムでは、必修・選択科目ともに全学科の学生が受講できるように時間割が構成されている。受講者の多い科目では、学科単位で複数のクラスに分けているが、同一教員が同一内容で授業を担当し、試験や成績評価も同一基準で行っている。また選択科目は、上位学年に進級後でも履修可能な機会を提供している。
A79: ⑩ | B79: できる限り多くの学生が履修できるような具体的な周知方法・取組
B80: 薬学部の「データサイエンス入門」は、１年生の選択科目としてシラバスで周知している。また、入学時のガイダンスにて周知を行い、履修者数の向上に努めた。 生命科学部では、上記⑧のとおり、既にMDASHに準拠した学部独自のデータサイエンスプログラム認定証を発行しており、履修の動機付けに役立てている。またプログラムの詳細について、毎年度初めに実施する入学生向けガイダンスや学年ごとの教務ガイダンスで全学生に周知している。
A93: ⑪ | B93: できる限り多くの学生が履修・修得できるようなサポート体制
B94: 薬学部の「データサイエンス入門」は入学後間もない１年生が受講することから、オンデマンド型の教材により、いつでも、何度でも受講できるよう配慮した。また、演習などの準備（ソフトウェアのインストール、ソフトウェアの操作方法など）やトラブルに対応するための専任の教員３名を担当させ、学生のデータサイエンスの教養習得を向上させる工夫を行った。 生命科学部の数理・データサイエンス系の基礎科目は全て1年次で必修化しており、全学科の入学生に対して裾野を広げている。学年の進行とともに内容が深化するようにカリキュラムマップが系統化されており、科目によっては履修前提を設けて円滑に連携している。また全科目でLMSを活用した授業支援体制が完成している。
A107: ⑫ | B107: 授業時間内外で学習指導、質問を受け付ける具体的な仕組み
B108: 薬学部の「データサイエンス入門」は、オンデマンド型の教材により開講したことから、学生はいつでもメールもしくはオフィスアワーに直接専任の教員へ質問できる体制を整備した。また、過去の質問を蓄積し、Q&AとしてLMS上に公開対応を行った。 生命科学部では、本教育プログラムについての履修をLMSにて管理し、学生はシステムを通じて授業で使用した全ての実データと解析の手順書を確認し、復習することができる。質問を受け付ける仕組みとして、データ解析用の実習スペースを設けており、専任教員とともに解析を実施することで問題点を解決する体制を整備している。学生は授業時間以外に不明点等をシステムを通じて確認することができ、質問はセンターの教員を通じて返答する体制を整備している。またデータサイエンスを含む情報教育に関する学生の質問の自由な場として、週1回「よろづ相談室」が，コンピュータ端末室において開催されている。

Sheet 様式４　自己点検・評価
I1: 様式４
H2: 大学等名 | I2: ='様式１ー２ プログラムを構成する授業科目（生命）'!C2 -> 東京薬科大学
A3: 自己点検・評価について
A5: ① | B5: プログラムの自己点検・評価を行う体制（委員会・組織等）
B6: データサイエンス教育推進委員会
D8: （責任者名） | E8: 小島正樹 | G8: （役職名） | H8: 教授
A10: ② | B10: 自己点検・評価体制における意見等
B11: 自己点検・評価の視点 | E11: 自己点検・評価体制における意見・結果・改善に向けた取組等
B12: 学内からの視点
C13: プログラムの履修・修得状況 | E13: 薬学部の「データサイエンス入門」は令和4（2022）年度に選択科目として開講した。令和5年度は薬学部1年生550名の学生のうち50名が履修・修得した。なお、令和6年度以降は必修科目化することで、全ての学生が履修できるよう計画している。 生命科学部の「数学Ⅰ」「情報科学Ⅰ」「生物統計学」は必修科目であり、全学科の学生が履修する。その他の対象科目の令和5年度の履修者は、「数学Ⅱ」が52%、「情報科学Ⅱ」が46%、「情報科学III」が21%、「生命科学VI（応用統計学）」が35%、「生命科学 IV（基礎情報学）」が31%、「生命科学V（計算機の論理とデータ構造）」が25%、「ICT活用の理論と実践」が32%、「分子生命科学Ⅵ（バイオインフォマティクス）」が29%、「生命医科学Ⅹ（ゲノム情報医科学）」が65%であった。
C14: 学修成果 | E14: 薬学部の「データサイエンス入門」では、毎回のオンデマンド講義受講後に確認テスト又は課題を提出させることで、学生の履修・習得状況と課題達成状況をリアルタイムに把握した。必要に応じて履修・習得状況を学生にフィードバックを行い、学習のモチベーションを高める等の対応を行った。 生命科学部のデータサイエンス系科目では、毎回の講義内容に関するCBT形式の小テストをLMSで行い、結果を直ちにフィードバックしている。小テストは期間中に何度も受験可能なため、各学生の理解の進展状況を即時に確認することができる。また授業内にプログラミングや問題演習の時間を設けるなどして、学生が主体的に学ぶ環境を提供している。
C15: 学生アンケート等を通じた学生の内容の理解度 | E15: 薬学部の「データサイエンス入門」に対する「授業改善のためのアンケート」を実施して、その結果を分析し授業内容の適切性について点検・評価を行っている。令和5年度の学生アンケートの結果、全ての項目において80％以上の肯定回答があり、学生からの理解が得られている様子が確認できた。また、自由記載欄を設けて授業についての感想や要望コメントを収集したが、理解度に関するコメントはすべて肯定的であった。 生命科学部では学期ごとに授業アンケートを実施して学生の理解度を分析しているが、令和5年度は「満足できる」「どちらかといえば満足」と回答した学生が「数学I」95%、「数学II」92%、「情報科学III」90%、「生命科学VI (応用統計学）」92%、「生命科学Ⅳ(基礎情報学)」87%、「生命科学Ⅴ（計算機の論理とデータ構造）」100%、「分子生命科学VI(バイオインフォマティクス)」97%であった。なお「情報科学I」「情報科学II」「ICT活用の理論と実践」では、毎回授業の理解度に関する5段階のアンケートを実施しており、それぞれ78%、76%、77%の学生が半分以上理解していると回答していた。また「生物統計学」と「生命科学Ⅴ（計算機の論理とデータ構造）」では、毎回の課題で学生の理解度を分析しながら進めている。
C16: 学生アンケート等を通じた後輩等他の学生への推奨度 | E16: 令和5年度に実施した薬学部の「データサイエンス入門」に対する学生アンケートの結果、総合的な満足度は88％で良好であった。以上のことから、間接的ではあるが、後輩などへの推奨度についても高いものと推察される。 「情報科学 II」の最後の授業で実施したアンケートでは、72%が「データサイエンスプログラム」に興味があり、40%が今後も履修したいと回答した。他の学生への推奨度も後者と同程度と考えられる。「生物統計学」では中間・期末試験において、講義への感想や修繕点などを書いてもらい、次年度の講義に反映している。「生命科学Ⅴ（計算機の論理とデータ構造）」では、就職活動に役立つことをシラバスで言及している。
C17: 全学的な履修者数、履修率向上に向けた計画の達成・進捗状況 | E17: 薬学部の「データサイエンス入門」は令和４年度より選択科目として開講したが、令和６年度以降は必修科目とすることが決まり、全ての学生が履修できるよう推進している。 生命科学部では、データサイエンスプログラム認定証の発行対象となる学生数の数値目標を30%として大学長期計画で措定している。また統計・データサイエンスや情報系の資格取得を奨励し、その対策に学部として取り組んでいる。
B18: 学外からの視点
C19: 教育プログラム修了者の進路、活躍状況、企業等の評価 | E19: 薬学部の「データサイエンス入門」は令和４年に開講間もないため、現時点において本科目を選択した卒業生は輩出していない。今後卒業生の調査を計画的に実施し、本教育プログラムを終了した卒業生の進路先や活躍状況の把握に努めることとする。 生命科学部では2020年度入学生より、今回の申請内容に該当するカリキュラム内容を学部独自の「データサイエンスプログラム」として既に実施している。本学部卒業生も在籍するバイオデータサイエンス関連企業からは、学生のニーズと社会の動向に合った教育プログラムであると高い評価を得た。
C20: 産業界からの視点を含めた教育プログラム内容・手法等への意見 | E20: 薬学部の「データサイエンス入門」の教育プログラムに対する外部有識者からの意見を収集するため、令和５年度は製薬企業から意見収集を行った。現時点で教育プログラムに変更を要する意見は挙げられていないが、今後も薬学生の進路先となる病院・薬局・企業など様々な分野の外部有識者からの意見を反映させながら、教育プログラムの改善を図る計画である。 生命科学部の教育プログラムに関して、バイオデータサイエンス分野の企業から意見聴取を行った。基礎力の養成を重視した望ましい内容で、過度の応用に偏ることなく、現行カリキュラムを継続してほしいとのことであった。
B21: 数理・データサイエンス・ＡＩを「学ぶ楽しさ」「学ぶことの意義」を理解させること | E21: 薬学部の「データサイエンス入門」は、リテラシーレベルの導入部分に準じた内容を展開し、時事やトレンドなど社会での実例をもとにAI等がどのような活用をされているかを中心に好奇心を促す講義内容としている。また、医薬系に特化したオリジナルコンテンツも含めることで、薬学専門分野に紐づいた内容を学ぶことができる。 生命科学部の低学年科目では、数理・データサイエンス・AIの基礎理論を扱い、高校の内容から無理なく連携できるように工夫がなされている。学年の進行に応じて、バイオインフォマティクスやゲノム情報医科学など生命科学に特化した内容を扱うことにより、学生は自身の興味ある分野について学ぶことができる。
B22: 内容・水準を維持・向上しつつ、より「分かりやすい」授業とすること ※社会の変化や生成AI等の技術の発展を踏まえて教育内容を継続的に見直すなど、より教育効果の高まる授業内容・方法とするための取組や仕組みについても該当があれば記載 | E22: 薬学部の「データサイエンス入門」は、学生から「授業改善のためのアンケート」により意見を収集するとともに、外部有識者からの客観的な評価も踏まえて、教育プログラムの改善を図っている。また、当該科目を担当する教員も医薬分野における数理・AI・データサイエンスの最新動向を常に把握しつつ教育コンテンツに反映することに努めている。 生命科学部では、学期ごとに全科目の「授業改善のためのアンケート」を実施して意見を収集するとともに、教員間で情報を共有して、教育プログラムの改善を図っている。また外部有識者からの客観的な評価も踏まえ、毎年度のシラバス執筆時に常に最新の動向を教育コンテンツに反映するように努めている。
