Workbook

Sheet 様式１-１　プログラムを構成する授業科目（その他学部）
T1: 様式１-１ | V1: 「学部・学科によって、修了要件は相違する」場合は、本シートを複製の上＜様式１－〇＞と枝番号を付してください
B2: 大学等名 | C2: 東洋大学
B3: プログラム名 | C3: 東洋大学 数理・データサイエンス・AI教育プログラム
A5: プログラムを構成する授業科目について
A7: ① 教育プログラムの修了要件 | L7: 学部・学科によって、修了要件は相違する
A9: ② 対象となる学部・学科名称
B11: 文学部（第1部、第2部）、経済学部（第1部、第2部）、経営学部（第1部、第2部）、法学部（第1部、第2部）、社会学部（第1部、第2部）、理工学部、国際学部国際地域学科、国際観光学部、生命科学部、食環境科学部、福祉社会デザイン学部、健康スポーツ科学部、ライフデザイン学部
A14: ③ 修了要件
B15: プログラムを構成する科目である「全学総合D」（2単位）および「全学総合E」（2単位）の2科目4単位を修得する。 | X15: 【プルダウンリスト】
X16: 令和５年度以前より、履修することが必須のプログラムとして実施
X17: 令和８年度までに履修必須とする計画
X18: 令和９年度以降に履修必須とする計画、又は未定
B22: 必要最低科目数・単位数 | E22: 2 | F22: 科目 | H22: 4 | I22: 単位 | M22: 履修必須の有無 | N22: 令和９年度以降に履修必須とする計画、又は未定
A24: ④ 現在進行中の社会変化（第４次産業革命、Society 5.0、データ駆動型社会等）に深く寄与しているものであり、それが自らの生活と密接に結びついている」の内容を含む授業科目
B26: 授業科目 | G26: 単位数 | H26: 必須 | I26: 1-1 | J26: 1-6 | K26: 授業科目 | R26: 単位数 | S26: 必須 | T26: 1-1 | U26: 1-6
B27: 全学総合D | G27: 2 | H27: ○ | I27: ○ | J27: ○
B28: 全学総合E | G28: 2 | H28: ○ | I28: ○ | J28: ○
A35: ⑤ 「社会で活用されているデータ」や「データの活用領域」は非常に広範囲であって、日常生活や社会の課題を解決する有用なツールになり得るもの」の内容を含む授業科目
B37: 授業科目 | G37: 単位数 | H37: 必須 | I37: 1-2 | J37: 1-3 | K37: 授業科目 | R37: 単位数 | S37: 必須 | T37: 1-2 | U37: 1-3
B38: 全学総合D | G38: 2 | H38: ○ | I38: ○ | J38: ○
B39: 全学総合E | G39: 2 | H39: ○ | I39: ○ | J39: ○
A46: ⑥ 「様々なデータ利活用の現場におけるデータ利活用事例が示され、様々な適用領域（流通、製造、金融、サービス、インフラ、公共、ヘルスケア等）の知見と組み合わせることで価値を創出するもの」の内容を含む授業科目
B48: 授業科目 | G48: 単位数 | H48: 必須 | I48: 1-4 | J48: 1-5 | K48: 授業科目 | R48: 単位数 | S48: 必須 | T48: 1-4 | U48: 1-5
B49: 全学総合D | G49: 2 | H49: ○ | I49: ○ | J49: ○
A57: ⑦ 「活用に当たっての様々な留意事項（ELSI、個人情報、データ倫理、ＡＩ社会原則等）を考慮し、情報セキュリティや情報漏洩等、データを守る上での留意事項への理解をする」の内容を含む授業科目
B59: 授業科目 | G59: 単位数 | H59: 必須 | I59: 3-1 | J59: 3-2 | K59: 授業科目 | R59: 単位数 | S59: 必須 | T59: 3-1 | U59: 3-2
B60: 全学総合E | G60: 2 | H60: ○ | I60: ○ | J60: ○
A68: ⑧ 「実データ・実課題（学術データ等を含む）を用いた演習など、社会での実例を題材として、「データを読む、説明する、扱う」といった数理・データサイエンス・ＡＩの基本的な活用法に関するもの」の内容を含む授業科目
B70: 授業科目 | F70: 単位数 | G70: 必須 | H70: 2-1 | I70: 2-2 | J70: 2-3 | K70: 授業科目 | Q70: 単位数 | R70: 必須 | S70: 2-1 | T70: 2-2 | U70: 2-3
B71: 全学総合D | F71: 2 | G71: ○ | H71: ○ | I71: ○ | J71: ○
A79: ⑨ 選択「４．オプション」の内容を含む授業科目
B80: 授業科目 | G80: 選択項目 | K80: 授業科目 | R80: 選択項目
B81: 全学総合D | G81: 4-1統計および数理基礎 | K81: 全学総合D | R81: 4‐9データ活用実践（教師なし学習）
B82: 全学総合D | G82: 4‐3データ構造とプログラミング基礎 | K82: 全学総合E | R82: 4‐3データ構造とプログラミング基礎
B83: 全学総合D | G83: 4‐4時系列データ解析 | K83: 全学総合E | R83: 4‐5テキスト解析
B84: 全学総合D | G84: 4‐5テキスト解析 | K84: 全学総合E | R84: 4‐6画像解析
B85: 全学総合D | G85: 4‐6画像解析
B86: 全学総合D | G86: 4‐7データハンドリング
B87: 全学総合D | G87: 4‐8データ活用実践（教師あり学習）
A89: ⑩ プログラムを構成する授業の内容
...

Sheet 様式１-2　プログラムを構成する授業科目（グローバル・イノベ）
T1: 様式１-2 | V1: 「学部・学科によって、修了要件は相違する」場合は、本シートを複製の上＜様式１－〇＞と枝番号を付してください
B2: 大学等名 | C2: 東洋大学
B3: プログラム名 | C3: 東洋大学 数理・データサイエンス・AI教育プログラム
A5: プログラムを構成する授業科目について
A7: ① 教育プログラムの修了要件 | L7: 学部・学科によって、修了要件は相違する
A9: ② 対象となる学部・学科名称
B11: 国際学部グローバル・イノベーション学科
A14: ③ 修了要件
B15: プログラムを構成する科目である「Science, Technology and Society」（2単位）および「Statistics」（2単位）の2科目4単位を修得する。 | X15: 【プルダウンリスト】
X16: 令和５年度以前より、履修することが必須のプログラムとして実施
X17: 令和８年度までに履修必須とする計画
X18: 令和９年度以降に履修必須とする計画、又は未定
B22: 必要最低科目数・単位数 | E22: 2 | F22: 科目 | H22: 4 | I22: 単位 | M22: 履修必須の有無 | N22: 令和９年度以降に履修必須とする計画、又は未定
A24: ④ 現在進行中の社会変化（第４次産業革命、Society 5.0、データ駆動型社会等）に深く寄与しているものであり、それが自らの生活と密接に結びついている」の内容を含む授業科目
B26: 授業科目 | G26: 単位数 | H26: 必須 | I26: 1-1 | J26: 1-6 | K26: 授業科目 | R26: 単位数 | S26: 必須 | T26: 1-1 | U26: 1-6
B27: Science, Technology and Society | G27: 2 | H27: ○ | I27: ○ | J27: ○
B28: Statistics | G28: 2 | H28: ○ | J28: ○
A35: ⑤ 「社会で活用されているデータ」や「データの活用領域」は非常に広範囲であって、日常生活や社会の課題を解決する有用なツールになり得るもの」の内容を含む授業科目
B37: 授業科目 | G37: 単位数 | H37: 必須 | I37: 1-2 | J37: 1-3 | K37: 授業科目 | R37: 単位数 | S37: 必須 | T37: 1-2 | U37: 1-3
B38: Science, Technology and Society | G38: 2 | H38: ○ | I38: ○ | J38: ○
B39: Statistics | G39: 2 | H39: ○ | I39: ○
A46: ⑥ 「様々なデータ利活用の現場におけるデータ利活用事例が示され、様々な適用領域（流通、製造、金融、サービス、インフラ、公共、ヘルスケア等）の知見と組み合わせることで価値を創出するもの」の内容を含む授業科目
B48: 授業科目 | G48: 単位数 | H48: 必須 | I48: 1-4 | J48: 1-5 | K48: 授業科目 | R48: 単位数 | S48: 必須 | T48: 1-4 | U48: 1-5
B49: Science, Technology and Society | G49: 2 | H49: ○ | I49: ○ | J49: ○
B50: Statistics | G50: 2 | H50: ○ | I50: ○ | J50: ○
A57: ⑦ 「活用に当たっての様々な留意事項（ELSI、個人情報、データ倫理、ＡＩ社会原則等）を考慮し、情報セキュリティや情報漏洩等、データを守る上での留意事項への理解をする」の内容を含む授業科目
B59: 授業科目 | G59: 単位数 | H59: 必須 | I59: 3-1 | J59: 3-2 | K59: 授業科目 | R59: 単位数 | S59: 必須 | T59: 3-1 | U59: 3-2
B60: Science, Technology and Society | G60: 2 | H60: ○ | I60: ○ | J60: ○
B61: Statistics | G61: 2 | H61: ○ | I61: ○
A68: ⑧ 「実データ・実課題（学術データ等を含む）を用いた演習など、社会での実例を題材として、「データを読む、説明する、扱う」といった数理・データサイエンス・ＡＩの基本的な活用法に関するもの」の内容を含む授業科目
B70: 授業科目 | F70: 単位数 | G70: 必須 | H70: 2-1 | I70: 2-2 | J70: 2-3 | K70: 授業科目 | Q70: 単位数 | R70: 必須 | S70: 2-1 | T70: 2-2 | U70: 2-3
B71: Statistics | F71: 2 | G71: ○ | H71: ○ | I71: ○ | J71: ○
A79: ⑨ 選択「４．オプション」の内容を含む授業科目
B80: 授業科目 | G80: 選択項目 | K80: 授業科目 | R80: 選択項目
B81: Statistics | G81: 4-1統計および数理基礎
A89: ⑩ プログラムを構成する授業の内容
B90: 授業に含まれている内容・要素 | D90: 講義内容
B91: （１）現在進行中の社会変化（第４次産業革命、Society 5.0、データ駆動型社会等）に深く寄与しているものであり、それが自らの生活と密接に結びついている | C91: 1-1 | D91: ・第4次産業革命、Society 5.0、データ駆動型社会 「Science, Technology and Society」（第８回）
C92: 1-6 | D92: ・AI等を活用した新しいビジネスモデル 「Statistics」（第１４回） ・AI最新技術の活用例 「Science, Technology and Society」（第１４回）、「Statistics」（第１４回）
B93: （２）「社会で活用されているデータ」や「データの活用領域」は非常に広範囲であって、日常生活や社会の課題を解決する有用なツールになり得るもの | C93: 1-2 | D93: ・1次データ、2次データ、データのメタ化 「Statistics」（第５回） ・構造化データ、非構造化データ 「Statistics」（第５回） ・データのオープン化 「Science, Technology and Society」（第１２回）、「Statistics」（第５回）
...

Sheet 様式１-3　プログラムを構成する授業科目（総合情報学部）
T1: 様式１-3 | V1: 「学部・学科によって、修了要件は相違する」場合は、本シートを複製の上＜様式１－〇＞と枝番号を付してください
B2: 大学等名 | C2: 東洋大学
B3: プログラム名 | C3: 東洋大学 数理・データサイエンス・AI教育プログラム
A5: プログラムを構成する授業科目について
A7: ① 教育プログラムの修了要件 | L7: 学部・学科によって、修了要件は相違する
A9: ② 対象となる学部・学科名称
B11: 総合情報学部
A14: ③ 修了要件
B15: プログラムを構成する科目である「データサイエンス概論」（2単位）および「AI基礎」（2単位）の2科目4単位を修得する。 | X15: 【プルダウンリスト】
X16: 令和５年度以前より、履修することが必須のプログラムとして実施
X17: 令和８年度までに履修必須とする計画
X18: 令和９年度以降に履修必須とする計画、又は未定
B22: 必要最低科目数・単位数 | E22: 2 | F22: 科目 | H22: 4 | I22: 単位 | M22: 履修必須の有無 | N22: 令和９年度以降に履修必須とする計画、又は未定
A24: ④ 現在進行中の社会変化（第４次産業革命、Society 5.0、データ駆動型社会等）に深く寄与しているものであり、それが自らの生活と密接に結びついている」の内容を含む授業科目
B26: 授業科目 | G26: 単位数 | H26: 必須 | I26: 1-1 | J26: 1-6 | K26: 授業科目 | R26: 単位数 | S26: 必須 | T26: 1-1 | U26: 1-6
B27: データサイエンス概論 | G27: 2 | H27: ○ | I27: ○ | J27: ○
B28: AI基礎 | G28: 2 | H28: ○ | I28: ○ | J28: ○
A35: ⑤ 「社会で活用されているデータ」や「データの活用領域」は非常に広範囲であって、日常生活や社会の課題を解決する有用なツールになり得るもの」の内容を含む授業科目
B37: 授業科目 | G37: 単位数 | H37: 必須 | I37: 1-2 | J37: 1-3 | K37: 授業科目 | R37: 単位数 | S37: 必須 | T37: 1-2 | U37: 1-3
B38: データサイエンス概論 | G38: 2 | H38: ○ | I38: ○ | J38: ○
B39: AI基礎 | G39: 2 | H39: ○ | I39: ○ | J39: ○
A46: ⑥ 「様々なデータ利活用の現場におけるデータ利活用事例が示され、様々な適用領域（流通、製造、金融、サービス、インフラ、公共、ヘルスケア等）の知見と組み合わせることで価値を創出するもの」の内容を含む授業科目
B48: 授業科目 | G48: 単位数 | H48: 必須 | I48: 1-4 | J48: 1-5 | K48: 授業科目 | R48: 単位数 | S48: 必須 | T48: 1-4 | U48: 1-5
B49: データサイエンス概論 | G49: 2 | H49: ○ | I49: ○ | J49: ○
A57: ⑦ 「活用に当たっての様々な留意事項（ELSI、個人情報、データ倫理、ＡＩ社会原則等）を考慮し、情報セキュリティや情報漏洩等、データを守る上での留意事項への理解をする」の内容を含む授業科目
B59: 授業科目 | G59: 単位数 | H59: 必須 | I59: 3-1 | J59: 3-2 | K59: 授業科目 | R59: 単位数 | S59: 必須 | T59: 3-1 | U59: 3-2
B60: AI基礎 | G60: 2 | H60: ○ | I60: ○ | J60: ○
A68: ⑧ 「実データ・実課題（学術データ等を含む）を用いた演習など、社会での実例を題材として、「データを読む、説明する、扱う」といった数理・データサイエンス・ＡＩの基本的な活用法に関するもの」の内容を含む授業科目
B70: 授業科目 | F70: 単位数 | G70: 必須 | H70: 2-1 | I70: 2-2 | J70: 2-3 | K70: 授業科目 | Q70: 単位数 | R70: 必須 | S70: 2-1 | T70: 2-2 | U70: 2-3
B71: データサイエンス概論 | F71: 2 | G71: ○ | H71: ○ | I71: ○ | J71: ○
A79: ⑨ 選択「４．オプション」の内容を含む授業科目
B80: 授業科目 | G80: 選択項目 | K80: 授業科目 | R80: 選択項目
B81: データサイエンス概論 | G81: 4-1統計および数理基礎 | K81: データサイエンス概論 | R81: 4‐9データ活用実践（教師なし学習）
B82: データサイエンス概論 | G82: 4‐3データ構造とプログラミング基礎 | K82: AI基礎 | R82: 4‐3データ構造とプログラミング基礎
B83: データサイエンス概論 | G83: 4‐4時系列データ解析 | K83: AI基礎 | R83: 4‐5テキスト解析
B84: データサイエンス概論 | G84: 4‐5テキスト解析 | K84: AI基礎 | R84: 4‐6画像解析
B85: データサイエンス概論 | G85: 4‐6画像解析
B86: データサイエンス概論 | G86: 4‐7データハンドリング
B87: データサイエンス概論 | G87: 4‐8データ活用実践（教師あり学習）
A89: ⑩ プログラムを構成する授業の内容
...

Sheet 様式１-4　プログラムを構成する授業科目（情報連携学部）
T1: 様式１-4 | V1: 「学部・学科によって、修了要件は相違する」場合は、本シートを複製の上＜様式１－〇＞と枝番号を付してください
B2: 大学等名 | C2: 東洋大学
B3: プログラム名 | C3: 東洋大学 数理・データサイエンス・AI教育プログラム
A5: プログラムを構成する授業科目について
A7: ① 教育プログラムの修了要件 | L7: 学部・学科によって、修了要件は相違する
A9: ② 対象となる学部・学科名称
B11: 情報連携学部
A14: ③ 修了要件
B15: プログラムを構成する科目である「情報連携学概論Ⅰ」（2単位）、「情報連携基礎実習Ⅰ」（1単位）、「情報連携学概論Ⅱ」（2単位）、「情報連携基礎実習Ⅱ」（1単位）、「コンピュータ・サイエンス概論Ⅲ」（2単位）、「コンピュータ・サイエンス基礎演習Ⅲ」（2単位）の6科目10単位を修得すること。 | X15: 【プルダウンリスト】
X16: 令和５年度以前より、履修することが必須のプログラムとして実施
X17: 令和８年度までに履修必須とする計画
X18: 令和９年度以降に履修必須とする計画、又は未定
B22: 必要最低科目数・単位数 | E22: 6 | F22: 科目 | H22: 10 | I22: 単位 | M22: 履修必須の有無 | N22: 令和９年度以降に履修必須とする計画、又は未定
A24: ④ 現在進行中の社会変化（第４次産業革命、Society 5.0、データ駆動型社会等）に深く寄与しているものであり、それが自らの生活と密接に結びついている」の内容を含む授業科目
B26: 授業科目 | G26: 単位数 | H26: 必須 | I26: 1-1 | J26: 1-6 | K26: 授業科目 | R26: 単位数 | S26: 必須 | T26: 1-1 | U26: 1-6
B27: 情報連携学概論Ⅰ | G27: 2 | H27: ○ | I27: ○ | J27: ○
B28: 情報連携学概論Ⅱ | G28: 2 | H28: ○ | I28: ○ | J28: ○
A35: ⑤ 「社会で活用されているデータ」や「データの活用領域」は非常に広範囲であって、日常生活や社会の課題を解決する有用なツールになり得るもの」の内容を含む授業科目
B37: 授業科目 | G37: 単位数 | H37: 必須 | I37: 1-2 | J37: 1-3 | K37: 授業科目 | R37: 単位数 | S37: 必須 | T37: 1-2 | U37: 1-3
B38: 情報連携学概論Ⅰ | G38: 2 | H38: ○ | I38: ○ | J38: ○
B39: 情報連携基礎実習Ⅰ | G39: 1 | H39: ○ | I39: ○
B40: 情報連携基礎実習Ⅱ | G40: 1 | H40: ○ | I40: ○
A46: ⑥ 「様々なデータ利活用の現場におけるデータ利活用事例が示され、様々な適用領域（流通、製造、金融、サービス、インフラ、公共、ヘルスケア等）の知見と組み合わせることで価値を創出するもの」の内容を含む授業科目
B48: 授業科目 | G48: 単位数 | H48: 必須 | I48: 1-4 | J48: 1-5 | K48: 授業科目 | R48: 単位数 | S48: 必須 | T48: 1-4 | U48: 1-5
B49: 情報連携学概論Ⅰ | G49: 2 | H49: ○ | I49: ○ | J49: ○
A57: ⑦ 「活用に当たっての様々な留意事項（ELSI、個人情報、データ倫理、ＡＩ社会原則等）を考慮し、情報セキュリティや情報漏洩等、データを守る上での留意事項への理解をする」の内容を含む授業科目
B59: 授業科目 | G59: 単位数 | H59: 必須 | I59: 3-1 | J59: 3-2 | K59: 授業科目 | R59: 単位数 | S59: 必須 | T59: 3-1 | U59: 3-2
B60: 情報連携学概論Ⅱ | G60: 2 | H60: ○ | I60: ○ | J60: ○
A68: ⑧ 「実データ・実課題（学術データ等を含む）を用いた演習など、社会での実例を題材として、「データを読む、説明する、扱う」といった数理・データサイエンス・ＡＩの基本的な活用法に関するもの」の内容を含む授業科目
B70: 授業科目 | F70: 単位数 | G70: 必須 | H70: 2-1 | I70: 2-2 | J70: 2-3 | K70: 授業科目 | Q70: 単位数 | R70: 必須 | S70: 2-1 | T70: 2-2 | U70: 2-3
B71: コンピュータ・サイエンス概論Ⅲ | F71: 2 | G71: ○ | H71: ○ | I71: ○ | J71: ○
B72: コンピュータ・サイエンス基礎演習Ⅲ | F72: 2 | G72: ○ | H72: ○ | I72: ○ | J72: ○
A79: ⑨ 選択「４．オプション」の内容を含む授業科目
B80: 授業科目 | G80: 選択項目 | K80: 授業科目 | R80: 選択項目
B81: コンピュータ・サイエンス概論Ⅲ | G81: 4‐4時系列データ解析 | K81: コンピュータ・サイエンス基礎演習Ⅲ | R81: 4‐7データハンドリング
B82: コンピュータ・サイエンス概論Ⅲ | G82: 4‐6画像解析 | K82: コンピュータ・サイエンス基礎演習Ⅲ | R82: 4‐8データ活用実践（教師あり学習）
B83: コンピュータ・サイエンス概論Ⅲ | G83: 4‐7データハンドリング | K83: コンピュータ・サイエンス基礎演習Ⅲ | R83: 4‐9データ活用実践（教師なし学習）
B84: コンピュータ・サイエンス概論Ⅲ | G84: 4‐8データ活用実践（教師あり学習）
B85: コンピュータ・サイエンス概論Ⅲ | G85: 4‐9データ活用実践（教師なし学習）
B86: コンピュータ・サイエンス基礎演習Ⅲ | G86: 4‐4時系列データ解析
...

Sheet 様式２ 履修者等数の実績
S1: 様式２
Q2: ='様式１-１ プログラムを構成する授業科目（その他学部）'!C2 -> 東洋大学
A3: プログラムの履修者数等の実績について
A5: ①プログラム開設年度 | C5: 令和5 | E5: 年度
A7: ②大学等全体の男女別学生数 | E7: 男性 | F7: 17507 | G7: 人 | H7: 女性 | I7: 12451 | J7: 人 | K7: （ | L7: 合計 | M7: =F7+I7 -> 29958 | N7: 人 | O7: ）
A9: ③履修者・修了者の実績
B11: 学部・学科名称 | C11: 学生数 | D11: 入学 定員 | E11: 収容 定員 | F11: 令和5年度 | H11: 令和4年度 | J11: 令和3年度 | L11: 令和2年度 | N11: 令和元年度 | P11: 平成30年度 | R11: 履修者数 合計 | S11: 履修率
F12: 履修者数 | G12: 修了者数 | H12: 履修者数 | I12: 修了者数 | J12: 履修者数 | K12: 修了者数 | L12: 履修者数 | M12: 修了者数 | N12: 履修者数 | O12: 修了者数 | P12: 履修者数 | Q12: 修了者数
B13: 文学部 | C13: 4014 | D13: 969 | E13: 3876 | F13: 10 | G13: 0 | R13: =F13+H13+J13+L13+N13+P13 -> 10 | S13: =R13/E13 -> 0.0025799794
B14: 経済学部 | C14: 3214 | D14: 766 | E14: 3064 | F14: 102 | G14: 16 | R14: =F14+H14+J14+L14+N14+P14 -> 102 | S14: =R14/E14 -> 0.033289817
B15: 経営学部 | C15: 3306 | D15: 792 | E15: 3168 | F15: 71 | G15: 6 | R15: =F15+H15+J15+L15+N15+P15 -> 71 | S15: =R15/E15 -> 0.022411616
B16: 法学部 | C16: 2587 | D16: 620 | E16: 2480 | F16: 77 | G16: 12 | R16: =F16+H16+J16+L16+N16+P16 -> 77 | S16: =R16/E16 -> 0.031048387
B17: 社会学部 | C17: 3540 | D17: 730 | E17: 3420 | F17: 81 | G17: 5 | R17: =F17+H17+J17+L17+N17+P17 -> 81 | S17: =R17/E17 -> 0.023684211
B18: 理工学部 | C18: 3380 | D18: 811 | E18: 3244 | F18: 71 | G18: 3 | R18: =F18+H18+J18+L18+N18+P18 -> 71 | S18: =R18/E18 -> 0.02188656
B19: 国際学部 | C19: 1662 | D19: 390 | E19: 1560 | F19: 128 | G19: 7 | R19: =F19+H19+J19+L19+N19+P19 -> 128 | S19: =R19/E19 -> 0.082051282
B20: 国際観光学部 | C20: 1502 | D20: 366 | E20: 1464 | F20: 8 | G20: 0 | R20: =F20+H20+J20+L20+N20+P20 -> 8 | S20: =R20/E20 -> 0.0054644809
B21: 生命科学部 | C21: 909 | D21: 226 | E21: 904 | F21: 41 | G21: 2 | R21: =F21+H21+J21+L21+N21+P21 -> 41 | S21: =R21/E21 -> 0.045353982
B22: 総合情報学部 | C22: 1068 | D22: 260 | E22: 1040 | F22: 171 | G22: 33 | R22: =F22+H22+J22+L22+N22+P22 -> 171 | S22: =R22/E22 -> 0.16442308
B23: 食環境科学部 | C23: 829 | D23: 170 | E23: 830 | F23: 30 | G23: 2 | R23: =F23+H23+J23+L23+N23+P23 -> 30 | S23: =R23/E23 -> 0.036144578
B24: 情報連携学部 | C24: 1449 | D24: 300 | E24: 1400 | F24: 689 | G24: 0 | R24: =F24+H24+J24+L24+N24+P24 -> 689 | S24: =R24/E24 -> 0.49214286
... B26: 健康スポーツ科学部 | C26: 339 | D26: 330 | E26: 330 | F26: 6 | G26: 0 | R26: =F26+H26+J26+L26+N26+P26 -> 6 | S26: =R26/E26 -> 0.018181818
B27: 国際地域学部（募集停止） | C27: 2 | D27: 0 | E27: 0 | F27: 0 | G27: 0 | R27: =F27+H27+J27+L27+N27+P27 -> 0 | S27: 0
B28: ライフデザイン学部（募集停止） | C28: 1667 | D28: 0 | E28: 1668 | F28: 71 | G28: 1 | R28: =F28+H28+J28+L28+N28+P28 -> 71 | S28: =R28/E28 -> 0.042565947
B33: 合 計 | C33: =SUM(C13:C32) -> 29958 | D33: =SUM(D13:D32) -> 7206 | E33: =SUM(E13:E32) -> 28924 | F33: =SUM(F13:F32) -> 1560 | G33: =SUM(G13:G32) -> 87 | H33: =SUM(H13:H32) -> 0 | I33: =SUM(I13:I32) -> 0 | J33: =SUM(J13:J32) -> 0 | ... R33: =SUM(R13:R32) -> 1560 | S33: =R33/E33 -> 0.053934449

Sheet 様式３ 教育の質・履修者数を向上させるための体制・計画
I1: 様式３
G2: 大学等名 | H2: ='様式１-１ プログラムを構成する授業科目（その他学部）'!C2 -> 東洋大学
A4: 教育の質・履修者数を向上させるための体制・計画について
A6: ① | B6: 全学の教員数 | C6: (常勤） | E6: 786 | F6: 人 | G6: （非常勤） | H6: 1410 | I6: 人
A8: ② | B8: プログラムの授業を教えている教員数 | H8: 25 | I8: 人
A10: ③ | B10: プログラムの運営責任者
B11: （責任者名） | C11: 東海林 克彦 | G11: （役職名） | H11: 副学長
A13: ④ | B13: プログラムを改善・進化させるための体制（委員会・組織等）
B14: 全学カリキュラム委員会
B16: （責任者名） | C16: 東海林 克彦 | G16: （役職名） | H16: 副学長
A18: ⑤ | B18: プログラムを改善・進化させるための体制を定める規則名称
B19: 東洋大学全学カリキュラム委員会規程
A21: ⑥ | B21: 体制の目的
B22: 東洋大学における特色ある全学的教育の展開と一層の発展を図るとともに、全学に係るカリキュラムの企画及び調整並びに複数学部のカリキュラムに係る事項の調整を行うことを目的として、東洋大学全学カリキュラム委員会が設置されている。
A34: ⑦ | B34: 具体的な構成員
B35: 全学カリキュラム委員会は、東洋大学全学カリキュラム委員会規程第2条により、次の委員をもって構成しており、令和5年度は52名の委員で委員会を開催した。 1. 学長が指名する副学長1名、教務部長（1名）：東海林克彦（教育担当副学長・教務部長） 2. 学部長（14名）：山口しのぶ（文学部教授）、郝仁平（経済学部教授）、長島広太（経営学部教授）、多田英明（法学部教授）、桐生正幸（社会学部教授）、松元明弘（理工学部教授）、荒巻俊也（国際学部教授）、中挾知延子（国際観光学部教授）、鳴海一成（生命科学部教授）、加藤千恵子（総合情報学部教授）、福森文康（食環境科学部教授）、坂村健（情報連携学部教授）、水村容子（福祉社会デザイン学部教授）、齊藤恭平（健康スポーツ科学部教授） 3. 各学部から選出された専任教員各１名（14名）：鈴木道也（文学部教授）、加賀見一彰（経済学部教授）、今泉淳（経営学部教授）、上田知亮（法学部准教授）、村上一基（社会学部准教授）、村野昭人（理工学部教授）、岡村敏之（国際学部教授）、古屋秀樹（国際観光学部教授）、道久則之（生命科学部教授）、藤本貴之（総合情報学部教授）、後藤顕一（食環境科学部教授）、別所正博（情報連携学部教授）、嶺也守寛（福祉社会デザイン学部教授）、内山有子（健康スポーツ科学部教授） 4. 高等教育推進支援室長（1名）：井上敏生 5. 教務担当課長（18名）：鎌田陽二（教職支援課）、今井学（全学学務推進課）、矢口信行・愛甲泰之（文学部教務課）、植木さえ子（経済学部教務課）、市橋篤（経営学部教務課）、田中明紀（法学部教務課）、吉田邦子（社会学部教務課）、鈴木裕一（川越事務部教学課（理工学部））、和久津健司（国際学部教務課）、長沼洋一（国際観光学部教務課）、及川知子（板倉事務部板倉事務課（生命科学部））、粕谷俊介（川越事務部教学課（総合情報学部））、田中秀樹（板倉事務部板倉事務課（食環境科学部））、安田祥子・渥美元康（赤羽台事務部赤羽台事務課（情報連携学部））、若林大輔（赤羽台事務部赤羽台事務課（福祉社会デザイン学部））、佐藤真樹（赤羽台事務部赤羽台事務課（健康スポーツ科学部）） 6. 学長が指名する者 若干名（4名）：高橋一男（国際教育センター ）、牛窪隆太（国際教育センター ）、根岸哲也（国際部長）、玉田誠（国際課長）
A48: ⑧ | B48: 履修者数・履修率の向上に向けた計画 ※様式１の「履修必須の有無」で「計画がある」としている場合は詳細について記載すること
B49: 令和５年度実績 | C49: ='様式２ 履修者等数の実績'!S33 -> 0.053934449 | E49: 令和６年度予定 | F49: 0.07 | H49: 令和７年度予定 | I49: 0.09
B50: 令和８年度予定 | C50: 0.12 | E50: 令和９年度予定 | F50: 0.15 | H50: 収容定員（名） | I50: ='様式２ 履修者等数の実績'!E33 -> 28924 | K50: =I50*0.15 -> 4338.6
B51: 具体的な計画
B52: 各学部・学科のカリキュラムに即したかたちで４つのプログラムを編成している。「情報連携学部」は必修科目のため卒業時点で全ての学生が本プログラムの修了者となる。「総合情報学部」は選択科目で配当学年を特定しているが、上位学年でも履修が可能でありこれまでも履修実績があることから次年度以降の履修者が見込まれる。「国際学部グローバル・イノベーション学科」、「その他の学部」は選択科目となるが、配当学年が2年次以降あるいは複数年次にまたがっているため次年度以降の履修者が見込まれる。 以前より開講されている科目であるためにプログラムとして実施することの意識改革（認知度向上）を行うことが課題となっていたが、大学ホームページによるプログラムの周知や本学公式アプリでのお知らせ配信等で学生へ直接働きかけを行うとともに、各プログラムや対象に適したアプローチを行い、より多くの学生の興味・関心を促していくことで、令和5年度実績から履修者数・履修率が年々増加するよう目指していく。将来的には全学部・学科において必修にすることで全体の底上げを図り、数理・データサイエンス・AI教育を強化していくことを検討している。 | K52: =LEN(B52) -> 495
A65: ⑨ | B65: 学部・学科に関係なく希望する学生全員が受講可能となるような必要な体制・取組等
B66: 「総合情報学部」、「情報連携学部」は学問分野の専門性からそれぞれ専門科目を教育プログラムの科目に位置付けており、「国際学部グローバル・イノベーション学科」は英語トラック科目の開講により英語科目をプログラム対象科目としている。「それ以外の学部」については共通の科目をプログラム対象科目に位置付けており、学部学科の縛りなく履修できるようになっている。履修者数についても基本的には定員の上限なく履修希望学生が受講できるような仕組みとなっており、各学部・学科のカリキュラムに即した受講体制を整えている。「それ以外の学部」については受講者が複数キャンパスにまたがることを考慮して、同時双方向型授業を取り入れており、履修しやすい体制としている。 | K66: =LEN(B66) -> 316
A79: ⑩ | B79: できる限り多くの学生が履修できるような具体的な周知方法・取組
B80: 令和5年度に開設した教育プログラムの周知や履修希望学生に対する情報提供を強化するために、プログラム対象者全員に対して年度初めに本学公式アプリ（スマートフォンアプリの他、PC・スマートフォン内のwebブラウザから利用可能）で情報を配信している。公式アプリでの発信のほか、入学後のガイダンスでの周知、SNSを活用した情報提供、プログラム専用の特設サイトでの数理・データサイエンス・AI教育に関する情報発信を行い、学生の認知度や興味・関心を高めていく。 | K80: =LEN(B80) -> 223
A93: ⑪ | B93: できる限り多くの学生が履修・修得できるようなサポート体制
B94: 専任教職員に対しては学内の教職員ポータルサイトにおいて情報共有を行い、非常勤講師には授業支援システム等を通じて全員に周知を行っている。授業時間割の編成においても、開講学期・開講曜時限・配当学年に留意して組み立てることで学生が不利益を被ることがないように留意している。また、授業内容の理解度を確認するための小テスト、考える力を養うための双方向型のディスカッションやグループ学習、プレゼンテーションを授業に盛り込むことで、単位修得に繋がるようケアをしている。 | K94: =LEN(B94) -> 227
A107: ⑫ | B107: 授業時間内外で学習指導、質問を受け付ける具体的な仕組み
B108: 学生はオフィスアワーを確認した上で学習指導を受けることができる。また、シラバス・教員プロフィールにおいて教員は連絡先を公開しており、学生からの質問をメール等で受け付けることができる体制を組んでいる。また、授業支援システムにおいて授業ごとに質問を受け付ける設定ができるようになっており、授業時間内外で双方向の質疑応答が可能となっている。 | K108: =LEN(B108) -> 167

Sheet 様式４　自己点検・評価
I1: 様式４
H2: 大学等名 | I2: ='様式１-１ プログラムを構成する授業科目（その他学部）'!C2 -> 東洋大学
A3: 自己点検・評価について
A5: ① | B5: プログラムの自己点検・評価を行う体制（委員会・組織等）
B6: 東洋大学 数理・データサイエンス・AI教育プログラム
D8: （責任者名） | E8: 東海林 克彦 | G8: （役職名） | H8: 副学長
A10: ② | B10: 自己点検・評価体制における意見等
B11: 自己点検・評価の視点 | E11: 自己点検・評価体制における意見・結果・改善に向けた取組等
B12: 学内からの視点
C13: プログラムの履修・修得状況 | E13: 令和5年度入学生は、「情報連携学部（1年次配当4科目）」で305名中301名（98.7%）が履修し269名～299名（89.4%～99.3%）が単位を修得、「総合情報学部（2科目）」で271名中68名・99名（25.1%・36.5%）が履修し65名・88名（95.6%・88.9%）が単位を修得、「その他学部（2科目）※2年次配当の国際学部グローバル・イノベーション学科を除く」で6951名中94名・215名（1.4%・3.1%）が履修し80名・168名（85.1%・78.1%）が単位を修得した。これらを教務部全学学務推進課が教務システムで確認し、全学カリキュラム委員会で点検・評価を行っている。 | K13: =LEN(E13) -> 299
C14: 学修成果 | E14: ４つのプログラムについて受講対象に合わせて講義の目的・内容、学習到達目標を設定しており、授業や指導の方法についても学習効果を高めるため工夫を凝らしている。理解度を確認するための小テスト、考える力を養うための双方向型のディスカッションやグループ学習、プレゼンテーションを盛り込み、理解の定着を図っている。 プログラムあるいは科目単位の授業アンケートやプログラム全体の外部評価を実施し、それらを含む実施結果を全学カリキュラム委員会で確認し、学部長会議へも報告している。 | K14: =LEN(E14) -> 232
C15: 学生アンケート等を通じた学生の内容の理解度 | E15: プログラムあるいは科目に適した方法で授業アンケートを実施し、学修内容の理解度を確認するとともに分析に役立てている（令和5年度入学生に限定せず受講者全体へ実施）。 理解度に関するアンケート結果は、プログラム、科目、学部（キャンパス）によって異なる傾向であったが、これはプログラムや科目によって授業の内容や方法、位置づけや難易度が異なることが影響していると考えられる。授業アンケートの結果を授業担当教員へフィードバックし授業改善に活用するとともに、全学カリキュラム委員会で確認しプログラムや科目の在り方について客観的に点検・評価することで、更なる向上に役立てる。 | K15: =LEN(E15) -> 279
C16: 学生アンケート等を通じた後輩等他の学生への推奨度 | E16: プログラムあるいは科目に適した方法で授業アンケートを実施し、推薦度を確認するとともに分析に役立てている（令和5年度入学生に限定せず受講者全体へ実施）。 推薦度に関するアンケート結果は、理解度に関するアンケート結果と同じ傾向であった。低めの傾向が出ていた学部（キャンパス）については理解度を向上させることによって推薦度が高まるよう改善していき、この取り組みの結果を活かした広報も積極的に展開していく。 | K16: =LEN(E16) -> 199
C17: 全学的な履修者数、履修率向上に向けた計画の達成・進捗状況 | E17: 令和5年度入学生全員に対して、年度初めに本学公式アプリで本プログラムの周知を行った。また学内教職員に対しては、全学カリキュラム委員会を通じてプログラム醸成の協力を仰ぎ、各学部における推奨で履修者数の向上を目指してきた。まだ十分にプログラムが浸透していないため、今後はその他の媒体や方法を活用した働きかけも行っていく。また、真の意味で学びが活きるよう学習成果を実感できる仕組みやプログラム修得における就職活動等への利用を検討していきたい。また、将来的には全学部・学科で必修とすることで全体の底上げを図り、数理・データサイエンス・AI教育を強化していきたい。 | K17: =LEN(E17) -> 277
B18: 学外からの視点
C19: 教育プログラム修了者の進路、活躍状況、企業等の評価 | E19: 令和5年度からプログラムを開始しており、プログラムを修得した卒業生がいないため、プログラム修了者の進路、活躍状況、企業等の評価を得るところまでは至っていないが、今後は学長室や就職・キャリア支援部と連携し、卒業生を対象に実施している卒業生アンケートや就職・進路状況調査を活用した分析を行いたいと考えている。その際は数理・データサイエンス・AI分野に直結する企業のみならず、当該分野の知識を活かし多種多様な進路で活躍する人材を含めて広く分析し、その結果を活用して在校生の学びを後押ししていきたい。 | K19: =LEN(E19) -> 246
C20: 産業界からの視点を含めた教育プログラム内容・手法等への意見 | E20: 外部評価者2名にプログラムの内容・手法、実施結果、実施体制を評価いただき、全体を通して概ね肯定的な意見をいただいた。内容・手法については網羅的かつ実践的な内容であり、次世代の社会と産業界のニーズに合わせた柔軟で適応性の高い教育を行っているとの評価をいただいた。その一方で改善点やより発展させるための方策についても助言があったため、これらについて全学カリキュラム委員会へ報告しプログラムの検証を行うとともに、授業担当教員へもフィードバックし授業内容の見直しの参考とした。 | K20: =LEN(E20) -> 234
B21: 数理・データサイエンス・ＡＩを「学ぶ楽しさ」「学ぶことの意義」を理解させること | E21: データを実際に活用することが楽しさを実感することと捉え、どのようなシーン、手法でデータが活用されているか事例を盛り込みながら説明しており、理解を深めながら身近なものとして捉えてもらう工夫をしている。専門性も志向も様々な学生がいる中で満遍なく教育を行うには、当該分野と親和性が低い学部の学生へ丁寧に働きかけることが特に重要と考えていることから、多様な専門領域を擁する本学ならではの方法を検討し、学生によりマッチした内容を展開できればと考えている。本プログラムを契機として、今後も全学カリキュラム委員会や外部評価者のアイディアを確認する等して、開けたかたちで可能性を模索していきたい。 | K21: =LEN(E21) -> 290
B22: 内容・水準を維持・向上しつつ、より「分かりやすい」授業とすること ※社会の変化や生成AI等の技術の発展を踏まえて教育内容を継続的に見直すなど、より教育効果の高まる授業内容・方法とするための取組や仕組みについても該当があれば記載 | E22: 学部独自の専門教育を展開している「総合情報学部」や「情報連携学部」は、プログラムの範囲に留まらず、学生が更に高度な知識や技術を習得することを目指し授業を展開し、「その他の学部」においてはボトムアップを図り、モデルカリキュラムや最新の話題を踏まえた授業を展開し、学生のレベルや希望に応じた段階的・体系的な授業を行う。当該分野を専門とする教員のノウハウを最大限に活用し、本学の特徴を捉えた内容や手法を精査することで、更なる向上を図りたい。併せて学生の学習環境や体制の促進、授業アンケート結果を踏まえた改善を行い、より分かりやすい授業を目指していく。 | K22: =LEN(E22) -> 272
