Workbook

Sheet 様式１-①　プログラムを構成する授業科目
T1: 様式１-① | V1: 「学部・学科によって、修了要件は相違する」場合は、本シートを複製の上＜様式１－〇＞と枝番号を付してください
B2: 大学等名 | C2: 桃山学院大学
B3: プログラム名 | C3: 数理・データサイエンス・AI教育プログラム（リテラシーレベル）
A5: プログラムを構成する授業科目について
A7: ① 教育プログラムの修了要件 | L7: 学部・学科によって、修了要件は相違する
A9: ② 対象となる学部・学科名称
B11: 経済学部経済学科、社会学部社会学科、社会学部ソーシャルデザイン学科、経営学部経営学科、国際教養学部英語・国際文化学科、法学部法律学科
A14: ③ 修了要件
B15: 共通教育機構が開講する基礎教育科目「学びの基礎（リテラシー）」区分の科目の内、「データサイエンス基礎」の2単位を修得すること。 | X15: 【プルダウンリスト】
X16: 令和５年度以前より、履修することが必須のプログラムとして実施
X17: 令和８年度までに履修必須とする計画
X18: 令和９年度以降に履修必須とする計画、又は未定
B22: 必要最低科目数・単位数 | E22: 1 | F22: 科目 | H22: 2 | I22: 単位 | M22: 履修必須の有無 | N22: 令和９年度以降に履修必須とする計画、又は未定
A24: ④ 現在進行中の社会変化（第４次産業革命、Society 5.0、データ駆動型社会等）に深く寄与しているものであり、それが自らの生活と密接に結びついている」の内容を含む授業科目
B26: 授業科目 | G26: 単位数 | H26: 必須 | I26: 1-1 | J26: 1-6 | K26: 授業科目 | R26: 単位数 | S26: 必須 | T26: 1-1 | U26: 1-6
B27: データサイエンス基礎 | G27: 2 | H27: ○ | I27: ○ | J27: ○
A35: ⑤ 「社会で活用されているデータ」や「データの活用領域」は非常に広範囲であって、日常生活や社会の課題を解決する有用なツールになり得るもの」の内容を含む授業科目
B37: 授業科目 | G37: 単位数 | H37: 必須 | I37: 1-2 | J37: 1-3 | K37: 授業科目 | R37: 単位数 | S37: 必須 | T37: 1-2 | U37: 1-3
B38: データサイエンス基礎 | G38: 2 | H38: ○ | I38: ○ | J38: ○
A46: ⑥ 「様々なデータ利活用の現場におけるデータ利活用事例が示され、様々な適用領域（流通、製造、金融、サービス、インフラ、公共、ヘルスケア等）の知見と組み合わせることで価値を創出するもの」の内容を含む授業科目
B48: 授業科目 | G48: 単位数 | H48: 必須 | I48: 1-4 | J48: 1-5 | K48: 授業科目 | R48: 単位数 | S48: 必須 | T48: 1-4 | U48: 1-5
B49: データサイエンス基礎 | G49: 2 | H49: ○ | I49: ○ | J49: ○
A57: ⑦ 「活用に当たっての様々な留意事項（ELSI、個人情報、データ倫理、ＡＩ社会原則等）を考慮し、情報セキュリティや情報漏洩等、データを守る上での留意事項への理解をする」の内容を含む授業科目
B59: 授業科目 | G59: 単位数 | H59: 必須 | I59: 3-1 | J59: 3-2 | K59: 授業科目 | R59: 単位数 | S59: 必須 | T59: 3-1 | U59: 3-2
B60: データサイエンス基礎 | G60: 2 | H60: ○ | I60: ○ | J60: ○
A68: ⑧ 「実データ・実課題（学術データ等を含む）を用いた演習など、社会での実例を題材として、「データを読む、説明する、扱う」といった数理・データサイエンス・ＡＩの基本的な活用法に関するもの」の内容を含む授業科目
B70: 授業科目 | F70: 単位数 | G70: 必須 | H70: 2-1 | I70: 2-2 | J70: 2-3 | K70: 授業科目 | Q70: 単位数 | R70: 必須 | S70: 2-1 | T70: 2-2 | U70: 2-3
B71: データサイエンス基礎 | F71: 2 | G71: ○ | H71: ○ | I71: ○ | J71: ○
A79: ⑨ 選択「４．オプション」の内容を含む授業科目
B80: 授業科目 | G80: 選択項目 | K80: 授業科目 | R80: 選択項目
B81: データサイエンス基礎 | G81: 4‐8データ活用実践（教師あり学習）
A89: ⑩ プログラムを構成する授業の内容
B90: 授業に含まれている内容・要素 | D90: 講義内容
B91: （１）現在進行中の社会変化（第４次産業革命、Society 5.0、データ駆動型社会等）に深く寄与しているものであり、それが自らの生活と密接に結びついている | C91: 1-1 | D91: 「社会で起きている変化」 ・データを起点としたものの見方、人間の知的活動を起点としたものの見方「データサイエンス基礎」（１回目）
C92: 1-6 | D92: 「データ・AI 利活用の最新動向」 ・AI等を活用した新しいビジネスモデル「データサイエンス基礎」（2回目、3回目、4回目）
B93: （２）「社会で活用されているデータ」や「データの活用領域」は非常に広範囲であって、日常生活や社会の課題を解決する有用なツールになり得るもの | C93: 1-2 | D93: 「社会で活用されているデータ」 ・調査データ、実験データ、人の行動ログデータ、機械の稼働ログデータなど「データサイエンス基礎」（2回目、3回目、4回目） ・1次データ、2次データ、データのメタ化「データサイエンス基礎」（2回目、3回目、4回目）
C94: 1-3 | D94: 「データ・AIの活用領域」 ・データ・AI活用領域の広がり「データサイエンス基礎」（2回目、3回目、4回目） ・研究開発、調達、製造、物流、販売、マーケティング、サービスなど「データサイエンス基礎」（2回目、3回目、4回目）
B95: （３）様々なデータ利活用の現場におけるデータ利活用事例が示され、様々な適用領域（流通、製造、金融、サービス、インフラ、公共、ヘルスケア等）の知見と組み合わせることで価値を創出するもの | C95: 1-4 | D95: 「データ・AIの活用のための技術」 ・データ解析：予測、グルーピング、パターン発見、最適化、シミュレーション・データ同化など「データサイエンス基礎」（2回目、3回目、4回目） ・特化型AIと汎用AI、今のAIに出来ることと、出来ないこと、AIとビッグデータ「データサイエンス基礎」（2回目、3回目、4回目）
C96: 1-5 | D96: 「データ・AIの利活用の現場」 ・データサイエンスのサイクル「データサイエンス基礎」（2回目、3回目、4回目） ・流通、製造、金融、サービス、インフラ、公共、ヘルスケア等におけるデータ・AI利活用事例紹介「データサイエンス基礎」（2回目、3回目、4回目）
B97: （４）活用に当たっての様々な留意事項（ELSI、個人情報、データ倫理、ＡＩ社会原則等）を考慮し、情報セキュリティや情報漏洩等、データを守る上での留意事項への理解をする | C97: 3-1 | D97: 「データ・AIを扱う上での留意事項」 ・個人情報保護、EU一般データ保護規則（GDPR）、忘れられる権利、オプトアウト「データサイエンス基礎」（12回目、13回目） ・データ倫理：データのねつ造、改ざん、盗用、プライバシー保護「データサイエンス基礎」（12回目、13回目）
...

Sheet 様式１-②　プログラムを構成する授業科目 
T1: 様式１-② | V1: 「学部・学科によって、修了要件は相違する」場合は、本シートを複製の上＜様式１－〇＞と枝番号を付してください
B2: 大学等名 | C2: 桃山学院大学
B3: プログラム名 | C3: 数理・データサイエンス・AI教育プログラム（リテラシーレベル）
A5: プログラムを構成する授業科目について
A7: ① 教育プログラムの修了要件 | L7: 学部・学科によって、修了要件は相違する
A9: ② 対象となる学部・学科名称
B11: ビジネスデザイン学部ビジネスデザイン学科
A14: ③ 修了要件
B15: ビジネスデザイン学部ビジネスデザイン学科教育科目「データサイエンス入門」の2単位を修得すること。 | X15: 【プルダウンリスト】
X16: 令和５年度以前より、履修することが必須のプログラムとして実施
X17: 令和８年度までに履修必須とする計画
X18: 令和９年度以降に履修必須とする計画、又は未定
B22: 必要最低科目数・単位数 | E22: 1 | F22: 科目 | H22: 2 | I22: 単位 | M22: 履修必須の有無 | N22: 令和９年度以降に履修必須とする計画、又は未定
A24: ④ 現在進行中の社会変化（第４次産業革命、Society 5.0、データ駆動型社会等）に深く寄与しているものであり、それが自らの生活と密接に結びついている」の内容を含む授業科目
B26: 授業科目 | G26: 単位数 | H26: 必須 | I26: 1-1 | J26: 1-6 | K26: 授業科目 | R26: 単位数 | S26: 必須 | T26: 1-1 | U26: 1-6
B27: データサイエンス入門 | G27: 2 | H27: ○ | I27: ○ | J27: ○
A35: ⑤ 「社会で活用されているデータ」や「データの活用領域」は非常に広範囲であって、日常生活や社会の課題を解決する有用なツールになり得るもの」の内容を含む授業科目
B37: 授業科目 | G37: 単位数 | H37: 必須 | I37: 1-2 | J37: 1-3 | K37: 授業科目 | R37: 単位数 | S37: 必須 | T37: 1-2 | U37: 1-3
B38: データサイエンス入門 | G38: 2 | H38: ○ | I38: ○ | J38: ○
A46: ⑥ 「様々なデータ利活用の現場におけるデータ利活用事例が示され、様々な適用領域（流通、製造、金融、サービス、インフラ、公共、ヘルスケア等）の知見と組み合わせることで価値を創出するもの」の内容を含む授業科目
B48: 授業科目 | G48: 単位数 | H48: 必須 | I48: 1-4 | J48: 1-5 | K48: 授業科目 | R48: 単位数 | S48: 必須 | T48: 1-4 | U48: 1-5
B49: データサイエンス入門 | G49: 2 | H49: ○ | I49: ○ | J49: ○
A57: ⑦ 「活用に当たっての様々な留意事項（ELSI、個人情報、データ倫理、ＡＩ社会原則等）を考慮し、情報セキュリティや情報漏洩等、データを守る上での留意事項への理解をする」の内容を含む授業科目
B59: 授業科目 | G59: 単位数 | H59: 必須 | I59: 3-1 | J59: 3-2 | K59: 授業科目 | R59: 単位数 | S59: 必須 | T59: 3-1 | U59: 3-2
B60: データサイエンス入門 | G60: 2 | H60: ○ | I60: ○ | J60: ○
A68: ⑧ 「実データ・実課題（学術データ等を含む）を用いた演習など、社会での実例を題材として、「データを読む、説明する、扱う」といった数理・データサイエンス・ＡＩの基本的な活用法に関するもの」の内容を含む授業科目
B70: 授業科目 | F70: 単位数 | G70: 必須 | H70: 2-1 | I70: 2-2 | J70: 2-3 | K70: 授業科目 | Q70: 単位数 | R70: 必須 | S70: 2-1 | T70: 2-2 | U70: 2-3
B71: データサイエンス入門 | F71: 2 | G71: ○ | H71: ○ | I71: ○ | J71: ○
A79: ⑨ 選択「４．オプション」の内容を含む授業科目
B80: 授業科目 | G80: 選択項目 | K80: 授業科目 | R80: 選択項目
B81: データサイエンス入門 | G81: 4‐8データ活用実践（教師あり学習）
A89: ⑩ プログラムを構成する授業の内容
B90: 授業に含まれている内容・要素 | D90: 講義内容
B91: （１）現在進行中の社会変化（第４次産業革命、Society 5.0、データ駆動型社会等）に深く寄与しているものであり、それが自らの生活と密接に結びついている | C91: 1-1 | D91: 「社会で起きている変化」 ・データを起点としたものの見方、人間の知的活動を起点としたものの見方「データサイエンス入門」（１回目）
C92: 1-6 | D92: 「データ・AI 利活用の最新動向」 ・AI等を活用した新しいビジネスモデル「データサイエンス入門」（2回目、3回目、4回目）
B93: （２）「社会で活用されているデータ」や「データの活用領域」は非常に広範囲であって、日常生活や社会の課題を解決する有用なツールになり得るもの | C93: 1-2 | D93: 「社会で活用されているデータ」 ・調査データ、実験データ、人の行動ログデータ、機械の稼働ログデータなど「データサイエンス入門」（2回目、3回目、4回目） ・1次データ、2次データ、データのメタ化「データサイエンス入門」（2回目、3回目、4回目）
C94: 1-3 | D94: 「データ・AIの活用領域」 ・データ・AI活用領域の広がり「データサイエンス入門」（2回目、3回目、4回目） ・研究開発、調達、製造、物流、販売、マーケティング、サービスなど「データサイエンス入門」（2回目、3回目、4回目）
B95: （３）様々なデータ利活用の現場におけるデータ利活用事例が示され、様々な適用領域（流通、製造、金融、サービス、インフラ、公共、ヘルスケア等）の知見と組み合わせることで価値を創出するもの | C95: 1-4 | D95: 「データ・AIの活用のための技術」 ・データ解析：予測、グルーピング、パターン発見、最適化、シミュレーション・データ同化など「データサイエンス入門」（2回目、3回目、4回目） ・特化型AIと汎用AI、今のAIに出来ることと、出来ないこと、AIとビッグデータ「データサイエンス入門」（2回目、3回目、4回目）
C96: 1-5 | D96: 「データ・AIの利活用の現場」 ・データサイエンスのサイクル「データサイエンス入門」（2回目、3回目、4回目） ・流通、製造、金融、サービス、インフラ、公共、ヘルスケア等におけるデータ・AI利活用事例紹介「データサイエンス入門」（2回目、3回目、4回目）
B97: （４）活用に当たっての様々な留意事項（ELSI、個人情報、データ倫理、ＡＩ社会原則等）を考慮し、情報セキュリティや情報漏洩等、データを守る上での留意事項への理解をする | C97: 3-1 | D97: 「データ・AIを扱う上での留意事項」 ・個人情報保護、EU一般データ保護規則（GDPR）、忘れられる権利、オプトアウト「データサイエンス入門」（12回目、13回目） ・データ倫理：データのねつ造、改ざん、盗用、プライバシー保護「データサイエンス入門」（12回目、13回目）
...

Sheet 様式２ 履修者等数の実績
S1: 様式２
Q2: ='様式１-① プログラムを構成する授業科目'!C2 -> 桃山学院大学
A3: プログラムの履修者数等の実績について
A5: ①プログラム開設年度 | C5: 令和５ | E5: 年度
A7: ②大学等全体の男女別学生数 | E7: 男性 | F7: 4791 | G7: 人 | H7: 女性 | I7: 2023 | J7: 人 | K7: （ | L7: 合計 | M7: =F7+I7 -> 6814 | N7: 人 | O7: ）
A9: ③履修者・修了者の実績
B11: 学部・学科名称 | C11: 学生数 | D11: 入学 定員 | E11: 収容 定員 | F11: 令和5年度 | H11: 令和4年度 | J11: 令和3年度 | L11: 令和2年度 | N11: 令和元年度 | P11: 平成30年度 | R11: 履修者数 合計 | S11: 履修率
F12: 履修者数 | G12: 修了者数 | H12: 履修者数 | I12: 修了者数 | J12: 履修者数 | K12: 修了者数 | L12: 履修者数 | M12: 修了者数 | N12: 履修者数 | O12: 修了者数 | P12: 履修者数 | Q12: 修了者数
B13: 経済学部 | C13: 1513 | D13: 360 | E13: 1440 | F13: 26 | G13: 22 | R13: =F13+H13+J13+L13+N13+P13 -> 26 | S13: =R13/E13 -> 0.018055556
B14: 社会学部 | C14: 1524 | D14: 360 | E14: 1440 | F14: 5 | G14: 4 | R14: =F14+H14+J14+L14+N14+P14 -> 5 | S14: =R14/E14 -> 0.0034722222
B15: 経営学部 | C15: 1224 | D15: 295 | E15: 1110 | F15: 19 | G15: 9 | R15: =F15+H15+J15+L15+N15+P15 -> 19 | S15: =R15/E15 -> 0.017117117
B16: 国際教養学部 | C16: 1069 | D16: 275 | E16: 1100 | F16: 15 | G16: 5 | R16: =F16+H16+J16+L16+N16+P16 -> 15 | S16: =R16/E16 -> 0.013636364
B17: 法学部 | C17: 823 | D17: 200 | E17: 800 | F17: 3 | G17: 2 | R17: =F17+H17+J17+L17+N17+P17 -> 3 | S17: =R17/E17 -> 0.00375
B18: ビジネスデザイン学部 | C18: 661 | D18: 200 | E18: 670 | F18: 177 | G18: 119 | R18: =F18+H18+J18+L18+N18+P18 -> 177 | S18: =R18/E18 -> 0.2641791
R19: =F19+H19+J19+L19+N19+P19 -> 0 | S19: =R19/E19 -> #DIV/0!
R20: =F20+H20+J20+L20+N20+P20 -> 0 | S20: =R20/E20 -> #DIV/0!
R21: =F21+H21+J21+L21+N21+P21 -> 0 | S21: =R21/E21 -> #DIV/0!
R22: =F22+H22+J22+L22+N22+P22 -> 0 | S22: =R22/E22 -> #DIV/0!
R23: =F23+H23+J23+L23+N23+P23 -> 0 | S23: =R23/E23 -> #DIV/0!
R24: =F24+H24+J24+L24+N24+P24 -> 0 | S24: =R24/E24 -> #DIV/0!
R25: =F25+H25+J25+L25+N25+P25 -> 0 | S25: =R25/E25 -> #DIV/0!
R26: =F26+H26+J26+L26+N26+P26 -> 0 | S26: =R26/E26 -> #DIV/0!
R27: =F27+H27+J27+L27+N27+P27 -> 0 | S27: =R27/E27 -> #DIV/0!
R28: =F28+H28+J28+L28+N28+P28 -> 0 | S28: =R28/E28 -> #DIV/0!
R29: =F29+H29+J29+L29+N29+P29 -> 0 | S29: =R29/E29 -> #DIV/0!
R30: =F30+H30+J30+L30+N30+P30 -> 0 | S30: =R30/E30 -> #DIV/0!
... R32: =F32+H32+J32+L32+N32+P32 -> 0 | S32: =R32/E32 -> #DIV/0!
B33: 合 計 | C33: =SUM(C13:C32) -> 6814 | D33: =SUM(D13:D32) -> 1690 | E33: =SUM(E13:E32) -> 6560 | F33: =SUM(F13:F32) -> 245 | G33: =SUM(G13:G32) -> 161 | H33: =SUM(H13:H32) -> 0 | I33: =SUM(I13:I32) -> 0 | J33: =SUM(J13:J32) -> 0 | ... R33: =SUM(R13:R32) -> 245 | S33: =R33/E33 -> 0.037347561

Sheet 様式３ 教育の質・履修者数を向上させるための体制・計画
I1: 様式３
G2: 大学等名 | H2: ='様式１-① プログラムを構成する授業科目'!C2 -> 桃山学院大学
A4: 教育の質・履修者数を向上させるための体制・計画について
A6: ① | B6: 全学の教員数 | C6: (常勤） | E6: 172 | F6: 人 | G6: （非常勤） | H6: 281 | I6: 人
A8: ② | B8: プログラムの授業を教えている教員数 | H8: 2 | I8: 人
A10: ③ | B10: プログラムの運営責任者
B11: （責任者名） | C11: 藤間 真 | G11: （役職名） | H11: データサイエンス教育運営会議長
A13: ④ | B13: プログラムを改善・進化させるための体制（委員会・組織等）
B14: データサイエンス教育運営会議
B16: （責任者名） | C16: 藤間 真 | G16: （役職名） | H16: データサイエンス教育運営会議長
A18: ⑤ | B18: プログラムを改善・進化させるための体制を定める規則名称
B19: 桃山学院大学データサイエンス教育運営会議内規
A21: ⑥ | B21: 体制の目的
B22: 本学では、他者とのコミュニケーションを図る方法や、学業や社会活動で必要となる基礎的なアカデミックスキルを養うため、共通教育機構が開講する全学共通の基礎教育科目に「学びの基礎（リテラシー）」科目区分を設けている。この「学びの基礎（リテラシー）」科目区分の内、ITの基礎的な知識とスキルを習得することを目的とした「IT基礎」、数理・データサイエンス・AIに関する基礎的な知識とスキルを習得することを目的とした「データサイエンス基礎」等、本学における「データサイエンス教育」を適切かつ円滑に運営し、その充実・向上に資することを目的として共通教育機構の下に「データサイエンス教育運営会議（以下、会議）」を設置している。会議では、「データサイエンス教育」科目の開講、運営の他、その目的の達成度、運営の適切性を自己点検・評価し、学部の専門教育にも資するものとするため不断のプログラム改善を行うものとする。
A34: ⑦ | B34: 具体的な構成員
B35: 2023年度（令和5年度）データサイエンス教育運営会議構成員 議 長 藤間 真（経済学部 教授） 構成員 井田 憲計（経済学部 教授） 村上 あかね（社会学部 教授） 大田 靖（経営学部 教授） ※プログラム科目担当教員 森下 裕三（国際教養学部 准教授） 井口 祐貴（法学部 講師） 水谷 直樹（共通教育機構 教授） ※プログラム科目担当教員 事務局 高良 要多（教務課 課長補佐） 叶屋 真一（共通教育機構事務課）
A48: ⑧ | B48: 履修者数・履修率の向上に向けた計画 ※様式１の「履修必須の有無」で「計画がある」としている場合は詳細について記載すること
B49: 令和５年度実績 | C49: ='様式２ 履修者等数の実績'!S33 -> 0.037347561 | E49: 令和６年度予定 | F49: 0.1 | H49: 令和７年度予定 | I49: 0.15
B50: 令和８年度予定 | C50: 0.2 | E50: 令和９年度予定 | F50: 0.25 | H50: 収容定員（名） | I50: ='様式２ 履修者等数の実績'!E33 -> 6560
B51: 具体的な計画
B52: 「データサイエンス基礎」は全学共通科目として令和５年度より開講し、1年次からの初修科目として履修するように履修推奨している。また、本科目を完全なオンデマンド科目として開講し、時間割の制約を受けずに自律的学習ができるように開講している。更に、本科目を教育職員養成課程の「基礎資格に関する科目」の選択科目として位置づけ、課程履修生の受講を促している。 令和５年の実績では半期（秋学期）のみの開講であったことから、令和６年度については通期開講（春学期、秋学期）のため倍増以上の10％（650名）を目指す。また、令和６年度入学生向けカリキュラムから日本語教員養成課程の選択必修科目として位置づけたことで課程履修生の受講を促している。 年次進行のため、令和７年度以降には単年度の新規履修生が300名程度ずつ増えることを想定し、令和７年度15％（1,000名）、令和８年度20％（1,300名）、令和９年度25％（1,650名）を目標とする。各年度の具体的な方策は次のとおり。令和７年度：本学のデータサイエンティスト養成プログラム「SDP(スーパー・データサイエンス・プログラム)」の参加学生に対し、選択科目として履修推奨を行う。令和８年度：理系新学部設置を予定（設置申請構想中）しており、理系学部新入生への履修推奨を行う。令和９年度：前年度にプログラムの完成年度となることから、卒業生をロールモデルとする周知を行い履修推奨を行う。
A65: ⑨ | B65: 学部・学科に関係なく希望する学生全員が受講可能となるような必要な体制・取組等
B66: 「データサイエンス基礎」は全学部生を対象とし、１年次生から履修できる共通科目として開講している。特に、基礎的なアカデミックスキルの涵養を目的とした科目区分「基礎教育科目」の「学びの基礎（リテラシー）」に位置付け、「数理・データサイエンス・AIに関する基礎的な知識とスキルを習得する」ことをカリキュラムのポリシーとしている。そのため、多くの学生が履修することを想定し、LMSを利用した完全なオンデマンド科目として設計し、学生が時間割の制約を受けずに自律的な学習によって単位修得できる環境を提供している。
A79: ⑩ | B79: できる限り多くの学生が履修できるような具体的な周知方法・取組
B80: 「データサイエンス基礎」の履修を促進するため、履修要項において「学びの基礎（リテラシー）」に位置付け、「数理・データサイエンス・AIに関する基礎的な知識とスキルを習得する」ことを周知し、更に、各学部の科目一覧に科目名を明記している。また、通常の履修登録授業期間開始前に履修登録を促す、「予備登録科目」として履修を周知しており、開講初年次であった令和５年度秋学期以降、対象年次生にポータルサイトを通じて履修推奨を行った。 更に、本科目を教育職員養成課程の「基礎資格に関する科目」の選択科目、日本語教員養成課程の選択必修科目として位置づけ、各課程の履修要項に明記し受講を促している。
A93: ⑪ | B93: できる限り多くの学生が履修・修得できるようなサポート体制
B94: 「データサイエンス基礎」は本学のデータサイエンティスト養成プログラム「SDP(スーパー・データサイエンス・プログラム)」の科目を主体的に運営する、２名の教員が担当しており、共通シラバス、共通成績評価に基づき開講されている。LMSに保存された講義動画、資料、課題を元に、履修学生の自律的学習により個人個人の学習進度、学習理解度を求めることができる。また、15回の講義の内、14回の講義で学生に複数の問いからなる小課題の提出を求め、理解をより深いものとさせる定着方法をとっており、この課題への回答は自己点検・評価の際にも活用される。
A107: ⑫ | B107: 授業時間内外で学習指導、質問を受け付ける具体的な仕組み
B108: 「データサイエンス基礎」は完全なオンデマンド科目として開講されており、学生は履修期間中は常時、LMSに保存された講義動画、資料、課題を閲覧することが可能である。また、履修期間中に課される小課題に質問をすることや、授業全体に関する内容を質問できるコメントシート、LMSの「Q&A」機能を用いて質問をすることが可能であり、次の講義時にフィードバックしている。更に、担当教員のオフィスアワーを設定しているため、授業時間に関わらず学習指導を受けることができる。

Sheet 様式４　自己点検・評価
I1: 様式４
H2: 大学等名 | I2: ='様式１-① プログラムを構成する授業科目'!C2 -> 桃山学院大学
A3: 自己点検・評価について
A5: ① | B5: プログラムの自己点検・評価を行う体制（委員会・組織等）
B6: データサイエンス教育運営会議
D8: （責任者名） | E8: 藤間 真 | G8: （役職名） | H8: データサイエンス教育運営会議長
A10: ② | B10: 自己点検・評価体制における意見等
B11: 自己点検・評価の視点 | E11: 自己点検・評価体制における意見・結果・改善に向けた取組等
B12: 学内からの視点
C13: プログラムの履修・修得状況 | E13: 全学部の学生に本プログラムの履修機会を提供するため、全学共通科目として「データサイエンス基礎」を開講した。開講初年次であった令和５年度は245名の履修があった。履修者の内、161名（65.7％）が単位修得に至っており、リテラシーレベルとして適切であったと考える。 本プログラムの履修の理由は「興味があった」が72.7％で学生の科目に対する学習意欲が高いことが伺える。また、本プログラムの履修を促すための対策である「完全オンデマンド化」について、「対面授業と同程度に知識は習得できたか」の項目では、54.5％が「そう思う」と回答し、「対面授業とオンデマンド型授業両方で開講されていた場合、どちらの形態を受講するか」の項目では、63.6％が「オンデマンド型」と回答しており、完全オンデマンド化に一定の需要と成果があったと考えている。
C14: 学修成果 | E14: 受講学生アンケートの「この授業は、総合的に判断して有益な授業でしたか」の項目に対し、54.5％が「そう思う」と回答し、36.7％が「どちらかと言えばそう思う」と回答していることから、本プログラムの運営は総合的に適切であったと考える。 更に、自由記述の項目では「オンデマンドのため自分のペースで学習できた」、「後半は難しかったが、とても面白い授業であった」と好意的に評価する声が多いことからも開講初年次としての講義導入の目的は果たせたと考える。 ただし、次のステップに進みたいという声も一定数あることから、本プログラムからの発展的科目の開設についても今後の検討が必要であると考える。
C15: 学生アンケート等を通じた学生の内容の理解度 | E15: 受講学生アンケートの「この授業をどのくらい理解できましたか」の項目に対し、回答者の45.5％が「良く理解できた」と回答し、残り54.5％も「まあまあ理解できた」と回答していることから、受講者に対する科目内容、レベルは適切であったと考える。 更に、「この授業に集中して取り組むことができましたか」の項目に対し、回答者の54.5％が「そう思う」と回答しており、授業は履修生が集中して取り組め、理解を得られる内容になっていたと考える。 ただし、自由記述において「難しい内容を理解する時間がかかった」、「全部は理解できなかったけど、ある程度分かった」等の難易度に関し「難しい」ととらえる声も一定数あることから、本プログラムの講義内容について、履修学生からの意見を集約、分析し、改善していくことが必要であると考える。
C16: 学生アンケート等を通じた後輩等他の学生への推奨度 | E16: 受講学生アンケートの「この授業の受講を同級生や後輩にお勧めできますか」の項目に対し、54.5％が「そう思う」と回答し、27.3％が「どちらかと言えばそう思う」と回答しており、81.8%が同級生や後輩に推奨できるとしており、本プログラムの履修が、今後、多くの学生に波及していくことが期待できる。 本プログラムの運営側が主体的となって履修推奨を取り進めることはもちろん、履修学生の実際の受講体験から得られた意見を学生に周知する活動が有効であろうと考えている。
C17: 全学的な履修者数、履修率向上に向けた計画の達成・進捗状況 | E17: 本プログラムは令和５年度に開設され、初年度は秋学期3クラスで開講し、履修者が245名（4％）の実績となった。2年目である令和６年の春学期には1クラス開講で既に139名が履修し、昨年度実績の56.7％を満たしており、更に秋学期に3クラスを開講することから、目標である650名（10％）は十分に達成できる進捗である。 本学における履修登録は学期ごとに実施されることから、秋学期に向け、履修対象年次生への訴求によって、更なる履修者数の増加を目指したい。
B18: 学外からの視点
C19: 教育プログラム修了者の進路、活躍状況、企業等の評価 | E19: 本プログラムは令和５年度に開設されたため、現状では教育プログラム修了者の進路等の情報は得られていないため、本項目について評価はできないが、修了者の進路等の情報は履修者数を増やし、本プログラムの内容精査、分析のために必要不可欠であると考えている。 そのため、学生の進路支援を主管する「キャリアセンター」と連携し、毎年実施している「卒業生アンケート」に質問項目を設ける等、調査・分析方法を確立する予定である。
C20: 産業界からの視点を含めた教育プログラム内容・手法等への意見 | E20: 本プログラムを実社会の現状に合わせ、実際のデータを得て、分析し得る体制が求められているとの認識から、「データサイエンス基礎」は、本学専任教員２名の他、多業種におよぶ産業界５社５名のゲスト講師によるオムニバス形式で開講されている。 履修学生からは講義の都度、課題提出と意見を求めており、ゲスト講師にも共有の上、講義内容に関する意見を収集している。得られた意見についてはプログラム運営母体である「データサイエンス教育運営会議」で共有され、本プログラムの内容の精査、改善に活用される。 ただし、産業界の外部評価者が科目を担当しているため、今後は第三者としての外部評価者の視点を導入する必要があると認識している。
B21: 数理・データサイエンス・ＡＩを「学ぶ楽しさ」「学ぶことの意義」を理解させること | E21: リテラシーレベルのモデルカリキュラムに講義内容を展開しつつ、多業種５社５名の産業界からの実務者講師の協力を得て、実社会のデータについて学べる手法をとっており、履修学生が興味関心を得られるように科目内容を構成している。 受講者アンケートの「授業内容は、あなたの興味・関心を呼び起こしましたか」の項目に対し、回答者の91.2％が「そう思う」、「どちらかというとそう思う」と回答していることから、受講者の興味関心を触発させる内容であったと考えている。
B22: 内容・水準を維持・向上しつつ、より「分かりやすい」授業とすること ※社会の変化や生成AI等の技術の発展を踏まえて教育内容を継続的に見直すなど、より教育効果の高まる授業内容・方法とするための取組や仕組みについても該当があれば記載 | E22: 本プログラムの「データサイエンス基礎」を担当する２名の専任教員が講義全15回の内、14回において課題提出と意見を求めており、履修生から講義回ごとに意見を収集でき、即時、即応的に科目運営の改善ができたと考えている。講義は学生の理解度の状況を見て判断しつつ、進めていく必要があり、学生の意見を得たことで、これが可能となった。 対面授業において、学生の反応をみながら授業運営することと同じく、完全オンデマンドの本プログラムにおいては、意見の収集こそ改善に向けた重要な因子であると考えている。
