Workbook

Sheet 様式１-1　プログラムを構成する授業科目
T1: 様式１－１ | V1: 「学部・学科によって、修了要件は相違する」場合は、本シートを複製の上＜様式１－〇＞と枝番号を付してください
B2: 大学等名 | C2: 環太平洋大学
B3: プログラム名 | C3: 教育とスポーツの融合を用いた地方創生に利活用できるリテラシー教育プログラム
A5: プログラムを構成する授業科目について
A7: ① 教育プログラムの修了要件 | L7: 学部・学科によって、修了要件は相違する
A9: ② 対象となる学部・学科名称
B11: 体育学部
A14: ③ 修了要件
B15: 全学必修科目である、「コンピュータリテラシーI」・「コンピュータリテラシーII」の4単位を取得すること。 更に、体育学部は「スポーツデータサイエンス入門」の２単位を取得すること。 ただし、健康科学科は、他学科履修にて「スポーツデータサイエンス入門」の２単位を取得すること。 | X15: 【プルダウンリスト】
X16: 令和５年度以前より、履修することが必須のプログラムとして実施
X17: 令和８年度までに履修必須とする計画
X18: 令和９年度以降に履修必須とする計画、又は未定
B22: 必要最低科目数・単位数 | E22: 3 | F22: 科目 | H22: 6 | I22: 単位 | M22: 履修必須の有無 | N22: 令和５年度以前より、履修することが必須のプログラムとして実施
A24: ④ 現在進行中の社会変化（第４次産業革命、Society 5.0、データ駆動型社会等）に深く寄与しているものであり、それが自らの生活と密接に結びついている」の内容を含む授業科目
B26: 授業科目 | G26: 単位数 | H26: 必須 | I26: 1-1 | J26: 1-6 | K26: 授業科目 | R26: 単位数 | S26: 必須 | T26: 1-1 | U26: 1-6
B27: コンピュータリテラシーⅠ | G27: 2 | H27: ○ | I27: ○
B28: スポーツデータサイエンス入門 | G28: 2 | H28: ○ | J28: ○
A35: ⑤ 「社会で活用されているデータ」や「データの活用領域」は非常に広範囲であって、日常生活や社会の課題を解決する有用なツールになり得るもの」の内容を含む授業科目
B37: 授業科目 | G37: 単位数 | H37: 必須 | I37: 1-2 | J37: 1-3 | K37: 授業科目 | R37: 単位数 | S37: 必須 | T37: 1-2 | U37: 1-3
B38: コンピュータリテラシーⅠ | G38: 2 | H38: ○ | I38: ○
B39: コンピュータリテラシーⅡ | G39: 2 | H39: ○ | J39: ○
A46: ⑥ 「様々なデータ利活用の現場におけるデータ利活用事例が示され、様々な適用領域（流通、製造、金融、サービス、インフラ、公共、ヘルスケア等）の知見と組み合わせることで価値を創出するもの」の内容を含む授業科目
B48: 授業科目 | G48: 単位数 | H48: 必須 | I48: 1-4 | J48: 1-5 | K48: 授業科目 | R48: 単位数 | S48: 必須 | T48: 1-4 | U48: 1-5
B49: コンピュータリテラシーⅡ | G49: 2 | H49: ○ | I49: ○
B50: スポーツデータサイエンス入門 | G50: 2 | J50: ○
A57: ⑦ 「活用に当たっての様々な留意事項（ELSI、個人情報、データ倫理、ＡＩ社会原則等）を考慮し、情報セキュリティや情報漏洩等、データを守る上での留意事項への理解をする」の内容を含む授業科目
B59: 授業科目 | G59: 単位数 | H59: 必須 | I59: 3-1 | J59: 3-2 | K59: 授業科目 | R59: 単位数 | S59: 必須 | T59: 3-1 | U59: 3-2
B60: コンピュータリテラシーⅠ | G60: 2 | H60: ○ | I60: ○
B61: コンピュータリテラシーⅡ | G61: 2 | H61: ○ | J61: ○
A68: ⑧ 「実データ・実課題（学術データ等を含む）を用いた演習など、社会での実例を題材として、「データを読む、説明する、扱う」といった数理・データサイエンス・ＡＩの基本的な活用法に関するもの」の内容を含む授業科目
B70: 授業科目 | F70: 単位数 | G70: 必須 | H70: 2-1 | I70: 2-2 | J70: 2-3 | K70: 授業科目 | Q70: 単位数 | R70: 必須 | S70: 2-1 | T70: 2-2 | U70: 2-3
B71: コンピュータリテラシーⅡ | F71: 2 | G71: ○ | I71: ○
B72: スポーツデータサイエンス入門 | F72: 2 | H72: ○ | I72: ○ | J72: ○
A79: ⑨ 選択「４．オプション」の内容を含む授業科目
B80: 授業科目 | G80: 選択項目 | K80: 授業科目 | R80: 選択項目
B81: 統計学 | G81: 4-1統計および数理基礎
B82: コンピュータリテラシーⅢ | G82: 4‐3データ構造とプログラミング基礎
B83: コンピュータリテラシーⅣ | G83: 4‐3データ構造とプログラミング基礎
A89: ⑩ プログラムを構成する授業の内容
B90: 授業に含まれている内容・要素 | D90: 講義内容
...

Sheet 様式１-2　プログラムを構成する授業科目
T1: 様式１－２ | V1: 「学部・学科によって、修了要件は相違する」場合は、本シートを複製の上＜様式１－〇＞と枝番号を付してください
B2: 大学等名 | C2: 環太平洋大学
B3: プログラム名 | C3: 教育とスポーツの融合を用いた地方創生に利活用できるリテラシー教育プログラム
A5: プログラムを構成する授業科目について
A7: ① 教育プログラムの修了要件 | L7: 学部・学科によって、修了要件は相違する
A9: ② 対象となる学部・学科名称
B11: 経済経営学部
A14: ③ 修了要件
B15: 全学必修科目である、「コンピュータリテラシーI」・「コンピュータリテラシーII」の4単位を取得すること。 更に、経済経営学部は「データサイエンス入門」の２単位を取得すること。 | X15: 【プルダウンリスト】
X16: 令和５年度以前より、履修することが必須のプログラムとして実施
X17: 令和８年度までに履修必須とする計画
X18: 令和９年度以降に履修必須とする計画、又は未定
B22: 必要最低科目数・単位数 | E22: 3 | F22: 科目 | H22: 6 | I22: 単位 | M22: 履修必須の有無 | N22: 令和５年度以前より、履修することが必須のプログラムとして実施
A24: ④ 現在進行中の社会変化（第４次産業革命、Society 5.0、データ駆動型社会等）に深く寄与しているものであり、それが自らの生活と密接に結びついている」の内容を含む授業科目
B26: 授業科目 | G26: 単位数 | H26: 必須 | I26: 1-1 | J26: 1-6 | K26: 授業科目 | R26: 単位数 | S26: 必須 | T26: 1-1 | U26: 1-6
B27: コンピュータリテラシーⅠ | G27: 2 | H27: ○ | I27: ○
B28: データサイエンス入門 | G28: 2 | H28: ○ | J28: ○
A35: ⑤ 「社会で活用されているデータ」や「データの活用領域」は非常に広範囲であって、日常生活や社会の課題を解決する有用なツールになり得るもの」の内容を含む授業科目
B37: 授業科目 | G37: 単位数 | H37: 必須 | I37: 1-2 | J37: 1-3 | K37: 授業科目 | R37: 単位数 | S37: 必須 | T37: 1-2 | U37: 1-3
B38: コンピュータリテラシーⅠ | G38: 2 | H38: ○ | I38: ○
B39: コンピュータリテラシーⅡ | G39: 2 | H39: ○ | J39: ○
A46: ⑥ 「様々なデータ利活用の現場におけるデータ利活用事例が示され、様々な適用領域（流通、製造、金融、サービス、インフラ、公共、ヘルスケア等）の知見と組み合わせることで価値を創出するもの」の内容を含む授業科目
B48: 授業科目 | G48: 単位数 | H48: 必須 | I48: 1-4 | J48: 1-5 | K48: 授業科目 | R48: 単位数 | S48: 必須 | T48: 1-4 | U48: 1-5
B49: コンピュータリテラシーⅡ | G49: 2 | H49: ○ | I49: ○
B50: データサイエンス入門 | G50: 2 | J50: ○
A57: ⑦ 「活用に当たっての様々な留意事項（ELSI、個人情報、データ倫理、ＡＩ社会原則等）を考慮し、情報セキュリティや情報漏洩等、データを守る上での留意事項への理解をする」の内容を含む授業科目
B59: 授業科目 | G59: 単位数 | H59: 必須 | I59: 3-1 | J59: 3-2 | K59: 授業科目 | R59: 単位数 | S59: 必須 | T59: 3-1 | U59: 3-2
B60: コンピュータリテラシーⅠ | G60: 2 | H60: ○ | I60: ○
B61: コンピュータリテラシーⅡ | G61: 2 | H61: ○ | J61: ○
A68: ⑧ 「実データ・実課題（学術データ等を含む）を用いた演習など、社会での実例を題材として、「データを読む、説明する、扱う」といった数理・データサイエンス・ＡＩの基本的な活用法に関するもの」の内容を含む授業科目
B70: 授業科目 | F70: 単位数 | G70: 必須 | H70: 2-1 | I70: 2-2 | J70: 2-3 | K70: 授業科目 | Q70: 単位数 | R70: 必須 | S70: 2-1 | T70: 2-2 | U70: 2-3
B71: コンピュータリテラシーⅡ | F71: 2 | G71: ○ | I71: ○
B72: データサイエンス入門 | F72: 2 | H72: ○ | I72: ○ | J72: ○
A79: ⑨ 選択「４．オプション」の内容を含む授業科目
B80: 授業科目 | G80: 選択項目 | K80: 授業科目 | R80: 選択項目
B81: 統計学 | G81: 4-1統計および数理基礎
B82: コンピュータリテラシーⅢ | G82: 4‐3データ構造とプログラミング基礎
B83: コンピュータリテラシーⅣ | G83: 4‐3データ構造とプログラミング基礎
A89: ⑩ プログラムを構成する授業の内容
B90: 授業に含まれている内容・要素 | D90: 講義内容
...

Sheet 様式１-3　プログラムを構成する授業科目
T1: 様式１－３ | V1: 「学部・学科によって、修了要件は相違する」場合は、本シートを複製の上＜様式１－〇＞と枝番号を付してください
B2: 大学等名 | C2: 環太平洋大学
B3: プログラム名 | C3: 教育とスポーツの融合を用いた地方創生に利活用できるリテラシー教育プログラム
A5: プログラムを構成する授業科目について
A7: ① 教育プログラムの修了要件 | L7: 学部・学科によって、修了要件は相違する
A9: ② 対象となる学部・学科名称
B11: 次世代教育学部
A14: ③ 修了要件
B15: 全学必修科目である、「コンピュータリテラシーI」・「コンピュータリテラシーII」の4単位を取得すること。 更に、次世代教育学部は他学科履修で「スポーツデータサイエンス入門」「データサイエンス入門」のいずれか２単位を取得すること。 | X15: 【プルダウンリスト】
X16: 令和５年度以前より、履修することが必須のプログラムとして実施
X17: 令和８年度までに履修必須とする計画
X18: 令和９年度以降に履修必須とする計画、又は未定
B22: 必要最低科目数・単位数 | E22: 3 | F22: 科目 | H22: 6 | I22: 単位 | M22: 履修必須の有無 | N22: 令和５年度以前より、履修することが必須のプログラムとして実施
A24: ④ 現在進行中の社会変化（第４次産業革命、Society 5.0、データ駆動型社会等）に深く寄与しているものであり、それが自らの生活と密接に結びついている」の内容を含む授業科目
B26: 授業科目 | G26: 単位数 | H26: 必須 | I26: 1-1 | J26: 1-6 | K26: 授業科目 | R26: 単位数 | S26: 必須 | T26: 1-1 | U26: 1-6
B27: コンピュータリテラシーⅠ | G27: 2 | H27: ○ | I27: ○
B28: スポーツデータサイエンス入門 | G28: 2 | H28: ○ | J28: ○
B29: データサイエンス入門 | G29: 2 | H29: ○ | J29: ○
A35: ⑤ 「社会で活用されているデータ」や「データの活用領域」は非常に広範囲であって、日常生活や社会の課題を解決する有用なツールになり得るもの」の内容を含む授業科目
B37: 授業科目 | G37: 単位数 | H37: 必須 | I37: 1-2 | J37: 1-3 | K37: 授業科目 | R37: 単位数 | S37: 必須 | T37: 1-2 | U37: 1-3
B38: コンピュータリテラシーⅠ | G38: 2 | H38: ○ | I38: ○
B39: コンピュータリテラシーⅡ | G39: 2 | H39: ○ | J39: ○
A46: ⑥ 「様々なデータ利活用の現場におけるデータ利活用事例が示され、様々な適用領域（流通、製造、金融、サービス、インフラ、公共、ヘルスケア等）の知見と組み合わせることで価値を創出するもの」の内容を含む授業科目
B48: 授業科目 | G48: 単位数 | H48: 必須 | I48: 1-4 | J48: 1-5 | K48: 授業科目 | R48: 単位数 | S48: 必須 | T48: 1-4 | U48: 1-5
B49: コンピュータリテラシーⅡ | G49: 2 | H49: ○ | I49: ○
B50: スポーツデータサイエンス入門 | G50: 2 | J50: ○
B51: データサイエンス入門 | G51: 2 | J51: ○
A57: ⑦ 「活用に当たっての様々な留意事項（ELSI、個人情報、データ倫理、ＡＩ社会原則等）を考慮し、情報セキュリティや情報漏洩等、データを守る上での留意事項への理解をする」の内容を含む授業科目
B59: 授業科目 | G59: 単位数 | H59: 必須 | I59: 3-1 | J59: 3-2 | K59: 授業科目 | R59: 単位数 | S59: 必須 | T59: 3-1 | U59: 3-2
B60: コンピュータリテラシーⅠ | G60: 2 | H60: ○ | I60: ○
B61: コンピュータリテラシーⅡ | G61: 2 | H61: ○ | J61: ○
A68: ⑧ 「実データ・実課題（学術データ等を含む）を用いた演習など、社会での実例を題材として、「データを読む、説明する、扱う」といった数理・データサイエンス・ＡＩの基本的な活用法に関するもの」の内容を含む授業科目
B70: 授業科目 | F70: 単位数 | G70: 必須 | H70: 2-1 | I70: 2-2 | J70: 2-3 | K70: 授業科目 | Q70: 単位数 | R70: 必須 | S70: 2-1 | T70: 2-2 | U70: 2-3
B71: コンピュータリテラシーⅡ | F71: 2 | G71: ○ | I71: ○
B72: スポーツデータサイエンス入門 | F72: 2 | H72: ○ | I72: ○ | J72: ○
B73: データサイエンス入門 | F73: 2 | H73: ○ | I73: ○ | J73: ○
A79: ⑨ 選択「４．オプション」の内容を含む授業科目
B80: 授業科目 | G80: 選択項目 | K80: 授業科目 | R80: 選択項目
B81: 統計学 | G81: 4-1統計および数理基礎
B82: コンピュータリテラシーⅢ | G82: 4‐3データ構造とプログラミング基礎
...

Sheet 様式２ 履修者等数の実績
S1: 様式２
Q2: ='様式１-1 プログラムを構成する授業科目'!C2 -> 環太平洋大学
A3: プログラムの履修者数等の実績について
A5: ①プログラム開設年度 | C5: 令和５ | E5: 年度
A7: ②大学等全体の男女別学生数 | E7: 男性 | F7: 1925 | G7: 人 | H7: 女性 | I7: 1019 | J7: 人 | K7: （ | L7: 合計 | M7: =F7+I7 -> 2944 | N7: 人 | O7: ）
A9: ③履修者・修了者の実績
B11: 学部・学科名称 | C11: 学生数 | D11: 入学 定員 | E11: 収容 定員 | F11: 令和5年度 | H11: 令和4年度 | J11: 令和3年度 | L11: 令和2年度 | N11: 令和元年度 | P11: 平成30年度 | R11: 履修者数 合計 | S11: 履修率
F12: 履修者数 | G12: 修了者数 | H12: 履修者数 | I12: 修了者数 | J12: 履修者数 | K12: 修了者数 | L12: 履修者数 | M12: 修了者数 | N12: 履修者数 | O12: 修了者数 | P12: 履修者数 | Q12: 修了者数
B13: 体育学部 | C13: 1479 | D13: 360 | E13: 1440 | F13: 848 | G13: 664 | R13: =F13+H13+J13+L13+N13+P13 -> 848 | S13: =R13/E13 -> 0.58888889
B14: 経済経営学部 | C14: 724 | D14: 250 | E14: 1000 | F14: 426 | G14: 395 | R14: =F14+H14+J14+L14+N14+P14 -> 426 | S14: =R14/E14 -> 0.426
B15: 次世代教育学部 | C15: 741 | D15: 200 | E15: 800 | F15: 345 | G15: 0 | R15: =F15+H15+J15+L15+N15+P15 -> 345 | S15: =R15/E15 -> 0.43125
R16: =F16+H16+J16+L16+N16+P16 -> 0 | S16: =R16/E16 -> #DIV/0!
R17: =F17+H17+J17+L17+N17+P17 -> 0 | S17: =R17/E17 -> #DIV/0!
R18: =F18+H18+J18+L18+N18+P18 -> 0 | S18: =R18/E18 -> #DIV/0!
R19: =F19+H19+J19+L19+N19+P19 -> 0 | S19: =R19/E19 -> #DIV/0!
R20: =F20+H20+J20+L20+N20+P20 -> 0 | S20: =R20/E20 -> #DIV/0!
R21: =F21+H21+J21+L21+N21+P21 -> 0 | S21: =R21/E21 -> #DIV/0!
R22: =F22+H22+J22+L22+N22+P22 -> 0 | S22: =R22/E22 -> #DIV/0!
R23: =F23+H23+J23+L23+N23+P23 -> 0 | S23: =R23/E23 -> #DIV/0!
R24: =F24+H24+J24+L24+N24+P24 -> 0 | S24: =R24/E24 -> #DIV/0!
R25: =F25+H25+J25+L25+N25+P25 -> 0 | S25: =R25/E25 -> #DIV/0!
R26: =F26+H26+J26+L26+N26+P26 -> 0 | S26: =R26/E26 -> #DIV/0!
R27: =F27+H27+J27+L27+N27+P27 -> 0 | S27: =R27/E27 -> #DIV/0!
... R32: =F32+H32+J32+L32+N32+P32 -> 0 | S32: =R32/E32 -> #DIV/0!
B33: 合 計 | C33: =SUM(C13:C32) -> 2944 | D33: =SUM(D13:D32) -> 810 | E33: =SUM(E13:E32) -> 3240 | F33: =SUM(F13:F32) -> 1619 | G33: =SUM(G13:G32) -> 1059 | H33: =SUM(H13:H32) -> 0 | I33: =SUM(I13:I32) -> 0 | J33: =SUM(J13:J32) -> 0 | ... R33: =SUM(R13:R32) -> 1619 | S33: =R33/E33 -> 0.49969136

Sheet 様式３ 教育の質・履修者数を向上させるための体制・計画
I1: 様式３
G2: 大学等名 | H2: ='様式１-1 プログラムを構成する授業科目'!C2 -> 環太平洋大学
A4: 教育の質・履修者数を向上させるための体制・計画について
A6: ① | B6: 全学の教員数 | C6: (常勤） | E6: 124 | F6: 人 | G6: （非常勤） | H6: 48 | I6: 人
A8: ② | B8: プログラムの授業を教えている教員数 | H8: 12 | I8: 人
A10: ③ | B10: プログラムの運営責任者
B11: （責任者名） | C11: 早田 剛 | G11: （役職名） | H11: 次世代情報センター長
A13: ④ | B13: プログラムを改善・進化させるための体制（委員会・組織等）
B14: 次世代情報センター
B16: （責任者名） | C16: 早田 剛 | G16: （役職名） | H16: 次世代情報センター長
A18: ⑤ | B18: プログラムを改善・進化させるための体制を定める規則名称
B19: 環太平洋大学 次世代情報センター規程
A21: ⑥ | B21: 体制の目的
B22: 本学では、今日の進展がめざましい情報通信技術の分野およびデジタル技術科学分野において、その成果を高度に活用し、様々な産業やビジネス分野で効果的に利活用できる人材の育成を目指す。 次世代情報センターは、情報ネットワークに関する専門的業務を行い、情報を広く教育、研究に活用することを図ることを目的とする。さらに、国内外の教育・研究機関・企業等と連携協力しながら先端の教育体制に関する研究を推進するとともに、その研究成果を実教育に還元し、データを活用し現代社会の課題を発見、解決できる人材を育成することも目的とする。 同センターは、本学学長の下に、数理・データサイエンス・AI教育の全学的な普及を視野に置き、学内の異なる分野の学部との横断的なカリキュラムの研究開発を行うとともに、各学部・学科と連携して関連科目の整備・新設を行い、体育系・経済経営系・教育系大学として将来のDX社会に活躍できる人材教育を実現して行く。
A34: ⑦ | B34: 具体的な構成員
B35: 環太平洋大学 次世代情報センター センター長：早田 剛（体育学部体育学科学科長） センター構成員： 教員：木戸和彦（次世代教育学部教育経営学科准教授）、本庄慶樹（次世代教育学部こども発達学科准教授）、倉田知秋（経済経営学部現代経営学科講師）、佐々木史之（体育学部競技スポーツ科学科講師）、坂本賢広（体育学部健康科学科講師）、仙波慎平（体育学部体育学科講師） 職員：戸田康（教育事務局局長）、北﨑 潤（教育事務局次長・教務課長）、大賀吉功（総務事務局情報システム課課長）
A48: ⑧ | B48: 履修者数・履修率の向上に向けた計画 ※様式１の「履修必須の有無」で「計画がある」としている場合は詳細について記載すること
B49: 令和５年度実績 | C49: ='様式２ 履修者等数の実績'!S33 -> 0.49969136 | E49: 令和６年度予定 | F49: 0.6 | H49: 令和７年度予定 | I49: 0.7
B50: 令和８年度予定 | C50: 0.8 | E50: 令和９年度予定 | F50: 0.85 | H50: 収容定員（名） | I50: ='様式２ 履修者等数の実績'!E33 -> 3240
B51: 具体的な計画
B52: 本申請プログラムに関し、体育学部・経済経営学部では「コンピュータリテラシーⅠ」「コンピュータリテラシーⅡ」が教養科目の必修科目であり、基本的に全員が履修する。さらに本プログラムの選択科目の「スポーツデータサイエンス入門（体育学部）」、「データサイエンス入門（経済経営学部）」の履修者数と履修率が現在のデータとなるが、同時に本申請プログラムの主旨に沿って全学的な構成科目の改善と実質化を段階的に進めており、全学的な協力のもと、科目名変更、新設、演習科目などの実質化、既設数理・ICT関連科目の全学的履修可能への科目変更などカリキュラムとシラバスの段階的充実を図り、履修者数・履修率の目標値を達成する予定である。
A65: ⑨ | B65: 学部・学科に関係なく希望する学生全員が受講可能となるような必要な体制・取組等
B66: 全学的な協力のもとで、体育学部・経済経営学部で整備されてきた数理・データサイエンス・AI・ICT関連の教育コンテンツ、および本申請プログラムの最適化に向け、全学的な教育、座学・演習内容の見直し、および全学学生の受講（他学部・他学科受講制度の活用）が可能となるシステムの構築支援を令和５年度より段階的に開始している。具体的には令和５年度よりさらに、両学部必修科目・選択科目の最適配置、全学共通教養科目に相当する本申請プログラム関連の演習科目設置やオンデマンド教材開発などを進め、希望する学生全員が受講可能となる体制を整備して行く。さらに、先端的なICTを活用する教育プログラムや教材の開発、国内外の他機関との連携、地域・産学連携も含め、DX社会に関するシンポジウム等を通して、学生の進路とDX社会の密接な関係性と興味を啓発する。
A79: ⑩ | B79: できる限り多くの学生が履修できるような具体的な周知方法・取組
B80: 環太平洋大学では入学予定者に対する入学前教育を実施して、本学教育プログラムの周知徹底を図っている。本申請プログラムに関連するPC機器の必携化、ICT、情報リテラシープログラム入門等の入学前教育を一層充実させている。また入学後のガイダンス、オリエンテーションや両学部授業開始時などにおいて新入生に広く周知させる体制を構築した。今年度からは段階的に入学後のガイダンスやSNSなどを利用した周知、また本学HPのトップ画面に本申請プログラム専用ページへのリンクを掲載し、周知方法の最適化に取り組む。さらに次年度以降本申請プログラムに関連する内容として、履修学生の感想や関連進路などを順次発信し、最新のDXとやAI・データサイエンスの進展と社会への実装状況を発信して、体育・経済経営系の学生が現代社会と教育プログラムとの関連情報を受け取り、身近に感じられるような環境を整備する。
A93: ⑪ | B93: できる限り多くの学生が履修・修得できるようなサポート体制
B94: 本学が開学から実施している総合教育成果（教育とスポーツの融合）の蓄積に基づき、体育学部・経済経営学部の両学部の教育研究活動や運営、教養教育プログラム、情報システム課と密に連携し、大学内のLMSやオンデマンド・アーカイブ教育試行等、できる限り多くの学生が履修・習得できるようなサポート体制確立を試みている。特に、体育学部、経済経営学部の専門性とカリキュラムの特徴を踏まえ、体育・経済経営系学生への数理・データサイエンス・AIの先端的利活用に関して、分かりやすく、取り組みやすい座学・演習の研究開発を行っている。今後もさらに現代DX社会の要請に答え、最適の教育・学生サポート体制を構築してゆく。4年制大学の1～2年次という教養教育全般のもと、本教育プログラムの横串を全学に通し、できる限り多くの学生への学修の機会を設けて、各自の専門に対する興味と直結するDX社会への対応スキルを身につけることを目指し、教育研究開発を続けている。
A107: ⑫ | B107: 授業時間内外で学習指導、質問を受け付ける具体的な仕組み
B108: 本教育プログラムの履修に関しては、ハイブリッド型授業の実施に際してLMSシステムを利用して全学生にGoogleシステムによるメールアドレスを付与し、Google classroom等のアプリケーションを利活用した授業体系を構築している。 このアプリ利用システムを充分に活用し、学生の出欠、資料の作成配布、授業の実施とその感想、授業時間内外の質問の受付、さらに各授業における学生アンケート集計等をシステム化している。現在、体育学部・経済経営学部の学生に関して本プログラム実施の各授業に対する演習やレポート・アンケート等を集め、本教育システムの内容向上に反映させている。今後は授業・演習の実施画像・動画等のアーカイビングと、学生のQ＆A集やインタビュー画像・動画なども充実させて行く。

Sheet 様式４　自己点検・評価
I1: 様式４
H2: 大学等名 | I2: ='様式１-1 プログラムを構成する授業科目'!C2 -> 環太平洋大学
A3: 自己点検・評価について
A5: ① | B5: プログラムの自己点検・評価を行う体制（委員会・組織等）
B6: 環太平洋大学 自己点検評価委員会規程
D8: （責任者名） | E8: 井上 聡 | G8: （役職名） | H8: 委員長・大学評価・IR室長
A10: ② | B10: 自己点検・評価体制における意見等
B11: 自己点検・評価の視点 | E11: 自己点検・評価体制における意見・結果・改善に向けた取組等
B12: 学内からの視点
C13: プログラムの履修・修得状況 | E13: 自己点検評価委員会等の意見を踏まえ、新入生ガイダンス、オリエンテーション、1・２年の「基礎ゼミナール」・３・４年の「専門ゼミナール」等により、体育学部・経済経営学部で、ICTの基礎や現代社会経済との関連を教育し、学生アンケート等で教育に反映している。 全学のICT関連では、本プログラムの必修科目と関連選択科目以外に、まだ共通の履修体制が十分ではなく、今後、全学的な体制確立が必要である。なお、経済経営学部ではMOS資格を取得推奨しており、学科教育の評価も高いが、まだ履修体制に偏りがあり、全学的な実質科目単位への移行を目指す。
C14: 学修成果 | E14: 本学では、全学生にPC端末の必携化を実施しているため、各学生にICT教育やゼミナール等の授業ができ、学内ポータルサイト（ユニバーサルパスポート）によるWeb登録申請やWebアンケート実施が可能であるが、大学全体では、試行的にGoogle系アプリを利用した授業と素早い学生アンケート等で、学生の授業の理解度把握を実施し学修成果を挙げている。さらに現在、上記の結果を踏まえ、DX関連教育の全学的学修調査の充実のため上記Google系のLMSアプリ運用と全学LMSシステムの有機的利用を目指している。これらの活動は今後、全学生のより高い学修成果に反映できる。
C15: 学生アンケート等を通じた学生の内容の理解度 | E15: 体育学部・経済経営学部の全科目に対し学生による授業評価アンケートを前期・後期の中間で実施し、授業への満足度（含理解度）等を調査している。その他に学生に対しては、予定者の入学前教育、入学後のガイダンス、オリエンテーション、1・２年の「基礎ゼミナール」・３・４年の「専門ゼミナール」で、ICTの入門基礎教育や現代社会との関連を教育しアンケートを取得している。学生アンケートに関しては、回転の速いGoogleアプリによる経営総合学科内LMSの中でも有効に試行しており、学生の理解度に関し高い評価が得られているが、本教育プログラムに関しては、これを敷衍して全学LMSシステムとの有機的結合を図り、学生理解度の向上、PBL、反転授業等、今後の授業展開を進める。
C16: 学生アンケート等を通じた後輩等他の学生への推奨度 | E16: COVID-19（新型コロナウィルス）の影響でハイブリッド型授業であったが、学生による授業評価や学修時間等に関するアンケートも実施して学生の履修状況や理解度も把握でき、各学生へのアドバイスやサポート、他学生や後輩への推奨も可能となった。今はまだ後輩推奨度の定量的評価には至らないが、今後、本プログラムの改善も含めた推奨度の全学データを集めることが可能である。本学は体育学部・経済経営学部・次世代教育学部の３学部を有し、教育内容や学生志向が広範囲に渡るので、本申請プログラムを新入学生へ推奨できるよう、入学時からのデータ社会との各学生の関わりを明示し学修意欲を向上させ、目標の可視化や各自の将来との関連性を構築する。
C17: 全学的な履修者数、履修率向上に向けた計画の達成・進捗状況 | E17: 本教育プログラムを構成する「コンピュータリテラシーⅠ」「コンピュータリテラシーⅡ」が教養科目の必修科目であり、基本的に全員が履修する。また体育学部・経済経営学部では数理・データサイエンス・AI教育に関し、現在まで科目新設等の整備・充実が進んでいるが、次世代教育学部（保育者・教育者養成学部）のカリキュラムにまだ必要十分な授業設定の検討を要している。なお、本プログラムの計画に従い、今後もカリキュラム・シラバスの改善を続け、ICT・DX関連の正規演習科目への新設・改編など、本プログラムの一層の充実を図る。
B18: 学外からの視点
C19: 教育プログラム修了者の進路、活躍状況、企業等の評価 | E19: 本学では卒業生の進路先や活躍状況の把握を従来より実施し、また、企業などの評価も教育に反映させているが、本教育プログラムに関してはまだ体系的な学外評価はできていない。しかし、企業等学外からの要請も高く、教育充実をはかり本プログラム申請に至っている。今後は民間企業、公務員団体に対して企業調査を実施し、本プログラム修了卒業生の採用状況や企業評価を把握する仕組みを設けて、全学的な協力体制のもとで産学連携、企業等の評価、プログラム修了者の進路や活躍状況を体系的に評価・集計し、全学的な教育体制充実を実現して行く。
C20: 産業界からの視点を含めた教育プログラム内容・手法等への意見 | E20: 産業界からの視点については、これまで外部団体との連携協定など通して外部視点を反映させてきた。現行の体育学部・経済経営学部から本教育プログラム関連学科目の充実を進め全学教育への浸透を図っている。これまでの外部意見から、学生に対しては数理やデータサイエンス開発を直接前面に出すことよりも、学生各自の将来の専門分野にICT・データやDXがどう関わっているかを可視化する教育手法が重要と判断している。今後は理数・データ科学の本質に迫り得る教育カリキュラムの構築、興味を引く入門の概念と、最新の社会情勢と関連進路への可視化などを重視する。
B21: 数理・データサイエンス・ＡＩを「学ぶ楽しさ」「学ぶことの意義」を理解させること | E21: 現代社会では数理・データ科学・AIが人々の前面に出ることは少ないが、GAFAに代表される現代企業では活動の基本全てに大きな影響を及ぼしている。一方で全ての若い世代にスマホやWeb・ Youtubeが浸透している。本教育プログラムはこれらの現象のギャップを教育的に埋めるものとして極めて重要であり、本学でも、学生の向かう将来の社会とICT/DXとが密接に結びつくことが分かりやすく可視化できることを重点にプログラムを構築する。例えば簿記とExcelやVBA・スクリプト言語などの関連、体育系企業やスポーツ団体、起業、アントレプレナーなどとICT・AIとの関連など、各学生の将来と社会の実例を繋ぎ、学ぶ楽しさと意義を実感できるような座学・演習の構築を図る。
B22: 内容・水準を維持・向上しつつ、より「分かりやすい」授業とすること ※社会の変化や生成AI等の技術の発展を踏まえて教育内容を継続的に見直すなど、より教育効果の高まる授業内容・方法とするための取組や仕組みについても該当があれば記載 | E22: 元々開学からは体育系・教育系大学であった本学では、従来は数理・データサイエンス・AI教育の充分な展開は難しかった。しかし、今後の国内外の産業やビジネスの進展を考慮すると、DXの社会浸透に対し、ICTを利活用できる若く有意な人材育成の必要性は極めて大きい。よって、体育学部・経済経営学部・次世代教育学部の幅広い分野に教育的横串を通せるよう、３学部と協働して、ICT系企業や外部意見も参考に、必要な教育水準と内容を維持し向上をはかる。
