Workbook

Sheet 様式１-1　プログラムを構成する授業科目
R1: 様式１-1 | T1: 「学部・学科によって、修了要件は相違する」場合は、本シートを複製の上＜様式１－〇＞と枝番号を付してください
B2: 大学等名 | C2: 中央学院大学
B3: プログラム名 | C3: 中央学院大学データサイエンス・AI入門プログラム
A5: プログラムを構成する授業科目について
A7: ① 対象となる学部・学科名称 | J7: ② 教育プログラムの修了要件 | K7: 学部・学科によって、修了要件は相違する
B9: 商学部
A12: ③ 修了要件
B13: 本プログラムを構成する全学共通科目の「データサイエンス（選択：2単位）」および商学部設置科目である、「情報リテラシー（必修：2単位）」、「情報処理論（必修：2単位）」の合計6単位を修得すること。 | V13: 【プルダウンリスト】
V14: 令和４年度以前より、履修することが必須のプログラムとして実施
V15: 令和７年度までに履修必須とする計画
V16: 令和８年度以降に履修必須とする計画、又は未定
B20: 必要最低単位数 | C20: 6 | E20: 単位 | J20: 履修必須の有無 | K20: 令和８年度以降に履修必須とする計画、又は未定
A22: ④ 現在進行中の社会変化（第４次産業革命、Society 5.0、データ駆動型社会等）に深く寄与しているものであり、それが自らの生活と密接に結びついている」の内容を含む授業科目
B24: 授業科目 | F24: 単位数 | G24: 必須 | H24: 1-1 | I24: 1-6 | J24: 授業科目 | P24: 単位数 | Q24: 必須 | R24: 1-1 | S24: 1-6
B25: データサイエンス | F25: 2 | G25: ○ | H25: ○ | I25: ○
A33: ⑤ 「社会で活用されているデータ」や「データの活用領域」は非常に広範囲であって、日常生活や社会の課題を解決する有用なツールになり得るもの」の内容を含む授業科目
B35: 授業科目 | F35: 単位数 | G35: 必須 | H35: 1-2 | I35: 1-3 | J35: 授業科目 | P35: 単位数 | Q35: 必須 | R35: 1-2 | S35: 1-3
B36: データサイエンス | F36: 2 | G36: ○ | H36: ○ | I36: ○
A44: ⑥ 「様々なデータ利活用の現場におけるデータ利活用事例が示され、様々な適用領域（流通、製造、金融、サービス、インフラ、公共、ヘルスケア等）の知見と組み合わせることで価値を創出するもの」の内容を含む授業科目
B46: 授業科目 | F46: 単位数 | G46: 必須 | H46: 1-4 | I46: 1-5 | J46: 授業科目 | P46: 単位数 | Q46: 必須 | R46: 1-4 | S46: 1-5
B47: データサイエンス | F47: 2 | G47: ○ | H47: ○ | I47: ○
A55: ⑦ 「活用に当たっての様々な留意事項（ELSI、個人情報、データ倫理、ＡＩ社会原則等）を考慮し、情報セキュリティや情報漏洩等、データを守る上での留意事項への理解をする」の内容を含む授業科目
B57: 授業科目 | F57: 単位数 | G57: 必須 | H57: 3-1 | I57: 3-2 | J57: 授業科目 | P57: 単位数 | Q57: 必須 | R57: 3-1 | S57: 3-2
B58: データサイエンス | F58: 2 | G58: ○ | H58: ○ | I58: ○
B59: 情報リテラシー | F59: 2 | G59: ○ | H59: ○ | I59: ○
A63: ⑧ 「実データ・実課題（学術データ等を含む）を用いた演習など、社会での実例を題材として、「データを読む、説明する、扱う」といった数理・データサイエンス・ＡＩの基本的な活用法に関するもの」の内容を含む授業科目
B65: 授業科目 | E65: 単位数 | F65: 必須 | G65: 2-1 | H65: 2-2 | I65: 2-3 | J65: 授業科目 | O65: 単位数 | P65: 必須 | Q65: 2-1 | R65: 2-2 | S65: 2-3
B66: データサイエンス | E66: 2 | F66: ○ | G66: ○ | H66: ○ | I66: ○
B67: 情報処理論 | E67: 2 | F67: ○ | G67: ○ | H67: ○ | I67: ○
A71: ⑨ 選択「４．オプション」の内容を含む授業科目
B72: 授業科目 | F72: 選択項目 | J72: 授業科目 | P72: 選択項目
B73: データサイエンス | F73: 4‐3データ構造とプログラミング基礎
A81: ⑩ プログラムを構成する授業の内容
B82: 授業に含まれている内容・要素 | D82: 講義内容
B83: （１）現在進行中の社会変化（第４次産業革命、Society 5.0、データ駆動型社会等）に深く寄与しているものであり、それが自らの生活と密接に結びついている | C83: 1-1 | D83: ビッグデータ、IoT、AI、ロボット 「データサイエンス」 （第１回） データ量の増加、計算機の処理性能の向上 「データサイエンス」 （第１回、第２回） 第4次産業革命、Society 5.0、データ駆動型社会 「データサイエンス」 （第１回）
C84: 1-6 | D84: AI等を活用した新しいビジネスモデル(商品のレコメンデーションなど) 「データサイエンス」 （第４回、第６回） AI最新技術の活用例（深層生成モデル、敵対的生成ネットワーク、強化学習）「データサイエンス」 （第４～６回）
B85: （２）「社会で活用されているデータ」や「データの活用領域」は非常に広範囲であって、日常生活や社会の課題を解決する有用なツールになり得るもの | C85: 1-2 | D85: 調査データ、実験データ、人の行動ログデータ、機械の稼働ログデータなど 「データサイエンス」 （第１回） 構造化データ、非構造化データ（文章、画像/動画、音声/音楽など） 「データサイエンス」 （第３回） データのオープン化（オープンデータ） 「データサイエンス」 （第１１回）
C86: 1-3 | D86: データ・AI活用領域の広がり(生産、消費、文化活動など) 「データサイエンス」 （第６回） 研究開発、製造、物流、販売、マーケティング、サービスなど 「データサイエンス」 （第７回）
B87: （３）様々なデータ利活用の現場におけるデータ利活用事例が示され、様々な適用領域（流通、製造、金融、サービス、インフラ、公共、ヘルスケア等）の知見と組み合わせることで価値を創出するもの | C87: 1-4 | D87: データ解析：予測、パターン発見、最適化など 「データサイエンス」（第４回） データ可視化：複合グラフ、2軸グラフ、関係性の可視化など 「データサイエンス」 （第１２回、第１５回） 非構造化データ処理：言語処理、画像/動画処理 「データサイエンス」 （第６回） 特化型AIと汎用AI、今のAIで出来ることと出来ないこと、AIとビッグデータ 「データサイエンス」 （第８回）
C88: 1-5 | D88: データサイエンスのサイクル（課題抽出と定式化、データの取得・管理・加工、探索的データ解析、データ解析と推論、結果の共有・伝達、課題解決に向けた提案） 「データサイエンス」（第２回） 流通、製造、金融、サービス、ヘルスケア等におけるデータ・AI利活用事例紹介 「データサイエンス」（第６回、第７回）
...

Sheet 様式1-2
R1: 様式１-2 | T1: 「学部・学科によって、修了要件は相違する」場合は、本シートを複製の上＜様式１－〇＞と枝番号を付してください
B2: 大学等名 | C2: 中央学院大学
B3: プログラム名 | C3: 中央学院大学データサイエンス・AI入門プログラム
A5: プログラムを構成する授業科目について
A7: ① 対象となる学部・学科名称 | J7: ② 教育プログラムの修了要件 | K7: 学部・学科によって、修了要件は相違する
B9: 法学部
A12: ③ 修了要件
B13: 本プログラムを構成する全学共通科目の「データサイエンス（選択：2単位）」および法学部設置科目である、「情報処理Ⅰ（必修：4単位）」の合計6単位を修得すること。 | V13: 【プルダウンリスト】
V14: 令和４年度以前より、履修することが必須のプログラムとして実施
V15: 令和７年度までに履修必須とする計画
V16: 令和８年度以降に履修必須とする計画、又は未定
B20: 必要最低単位数 | C20: 6 | E20: 単位 | J20: 履修必須の有無 | K20: 令和８年度以降に履修必須とする計画、又は未定
A22: ④ 現在進行中の社会変化（第４次産業革命、Society 5.0、データ駆動型社会等）に深く寄与しているものであり、それが自らの生活と密接に結びついている」の内容を含む授業科目
B24: 授業科目 | F24: 単位数 | G24: 必須 | H24: 1-1 | I24: 1-6 | J24: 授業科目 | P24: 単位数 | Q24: 必須 | R24: 1-1 | S24: 1-6
B25: データサイエンス | F25: 2 | G25: ○ | H25: ○ | I25: ○
B26: 情報処理Ⅰ | F26: 4 | G26: ○ | H26: ○
A33: ⑤ 「社会で活用されているデータ」や「データの活用領域」は非常に広範囲であって、日常生活や社会の課題を解決する有用なツールになり得るもの」の内容を含む授業科目
B35: 授業科目 | F35: 単位数 | G35: 必須 | H35: 1-2 | I35: 1-3 | J35: 授業科目 | P35: 単位数 | Q35: 必須 | R35: 1-2 | S35: 1-3
B36: データサイエンス | F36: 2 | G36: ○ | H36: ○ | I36: ○
A44: ⑥ 「様々なデータ利活用の現場におけるデータ利活用事例が示され、様々な適用領域（流通、製造、金融、サービス、インフラ、公共、ヘルスケア等）の知見と組み合わせることで価値を創出するもの」の内容を含む授業科目
B46: 授業科目 | F46: 単位数 | G46: 必須 | H46: 1-4 | I46: 1-5 | J46: 授業科目 | P46: 単位数 | Q46: 必須 | R46: 1-4 | S46: 1-5
B47: データサイエンス | F47: 2 | G47: ○ | H47: ○ | I47: ○
A55: ⑦ 「活用に当たっての様々な留意事項（ELSI、個人情報、データ倫理、ＡＩ社会原則等）を考慮し、情報セキュリティや情報漏洩等、データを守る上での留意事項への理解をする」の内容を含む授業科目
B57: 授業科目 | F57: 単位数 | G57: 必須 | H57: 3-1 | I57: 3-2 | J57: 授業科目 | P57: 単位数 | Q57: 必須 | R57: 3-1 | S57: 3-2
B58: データサイエンス | F58: 2 | G58: ○ | H58: ○ | I58: ○
A66: ⑧ 「実データ・実課題（学術データ等を含む）を用いた演習など、社会での実例を題材として、「データを読む、説明する、扱う」といった数理・データサイエンス・ＡＩの基本的な活用法に関するもの」の内容を含む授業科目
B68: 授業科目 | E68: 単位数 | F68: 必須 | G68: 2-1 | H68: 2-2 | I68: 2-3 | J68: 授業科目 | O68: 単位数 | P68: 必須 | Q68: 2-1 | R68: 2-2 | S68: 2-3
B69: データサイエンス | E69: 2 | F69: ○ | G69: ○ | H69: ○ | I69: ○
B70: 情報処理Ⅰ | E70: 4 | F70: ○ | G70: ○ | H70: ○ | I70: ○
A77: ⑨ 選択「４．オプション」の内容を含む授業科目
B78: 授業科目 | F78: 選択項目 | J78: 授業科目 | P78: 選択項目
B79: データサイエンス | F79: 4‐3データ構造とプログラミング基礎
A87: ⑩ プログラムを構成する授業の内容
B88: 授業に含まれている内容・要素 | D88: 講義内容
B89: （１）現在進行中の社会変化（第４次産業革命、Society 5.0、データ駆動型社会等）に深く寄与しているものであり、それが自らの生活と密接に結びついている | C89: 1-1 | D89: ビッグデータ、IoT、AI、ロボット 「データサイエンス」 （第１回） データ量の増加、計算機の処理性能の向上 「データサイエンス」 （第１回、第２回） 第4次産業革命、Society 5.0、データ駆動型社会 「データサイエンス」 （第１回） 第4次産業革命、Society 5.0、データ駆動型社会 「情報処理I」 （第１回、第２回）
C90: 1-6 | D90: AI等を活用した新しいビジネスモデル(商品のレコメンデーションなど) 「データサイエンス」 （第４回、第６回） AI最新技術の活用例（深層生成モデル、敵対的生成ネットワーク、強化学習）「データサイエンス」 （第４～６回）
B91: （２）「社会で活用されているデータ」や「データの活用領域」は非常に広範囲であって、日常生活や社会の課題を解決する有用なツールになり得るもの | C91: 1-2 | D91: 調査データ、実験データ、人の行動ログデータ、機械の稼働ログデータなど 「データサイエンス」 （第１回） 構造化データ、非構造化データ（文章、画像/動画、音声/音楽など） 「データサイエンス」 （第３回） データのオープン化（オープンデータ） 「データサイエンス」 （第１１回）
C92: 1-3 | D92: データ・AI活用領域の広がり(生産、消費、文化活動など) 「データサイエンス」 （第６回） 研究開発、製造、物流、販売、マーケティング、サービスなど 「データサイエンス」 （第７回）
B93: （３）様々なデータ利活用の現場におけるデータ利活用事例が示され、様々な適用領域（流通、製造、金融、サービス、インフラ、公共、ヘルスケア等）の知見と組み合わせることで価値を創出するもの | C93: 1-4 | D93: データ解析：予測、パターン発見、最適化など 「データサイエンス」（第４回） データ可視化：複合グラフ、2軸グラフ、関係性の可視化など 「データサイエンス」 （第１２回、第１５回） 非構造化データ処理：言語処理、画像/動画処理 「データサイエンス」 （第６回） 特化型AIと汎用AI、今のAIで出来ることと出来ないこと、AIとビッグデータ 「データサイエンス」 （第８回）
C94: 1-5 | D94: データサイエンスのサイクル（課題抽出と定式化、データの取得・管理・加工、探索的データ解析、データ解析と推論、結果の共有・伝達、課題解決に向けた提案） 「データサイエンス」（第２回） 流通、製造、金融、サービス、ヘルスケア等におけるデータ・AI利活用事例紹介 「データサイエンス」（第６回、第７回）
...

Sheet 様式1-3
R1: 様式１-3 | T1: 「学部・学科によって、修了要件は相違する」場合は、本シートを複製の上＜様式１－〇＞と枝番号を付してください
B2: 大学等名 | C2: 中央学院大学
B3: プログラム名 | C3: 中央学院大学データサイエンス・AI入門プログラム
A5: プログラムを構成する授業科目について
A7: ① 対象となる学部・学科名称 | J7: ② 教育プログラムの修了要件 | K7: 学部・学科によって、修了要件は相違する
B9: 現代教養学部
A12: ③ 修了要件
B13: 本プログラムを構成する現代教養学部配当科目である、「情報リテラシー（必修：2単位）」、「情報処理論の基礎（必修：2単位）および「データサイエンス（選択必修：2単位）の合計6単位を修得すること。 | V13: 【プルダウンリスト】
V14: 令和４年度以前より、履修することが必須のプログラムとして実施
V15: 令和７年度までに履修必須とする計画
V16: 令和８年度以降に履修必須とする計画、又は未定
B20: 必要最低単位数 | C20: 6 | E20: 単位 | J20: 履修必須の有無 | K20: 令和８年度以降に履修必須とする計画、又は未定
A22: ④ 現在進行中の社会変化（第４次産業革命、Society 5.0、データ駆動型社会等）に深く寄与しているものであり、それが自らの生活と密接に結びついている」の内容を含む授業科目
B24: 授業科目 | F24: 単位数 | G24: 必須 | H24: 1-1 | I24: 1-6 | J24: 授業科目 | P24: 単位数 | Q24: 必須 | R24: 1-1 | S24: 1-6
B25: データサイエンス | F25: 2 | G25: ○ | H25: ○ | I25: ○
B26: 情報リテラシー | F26: 2 | G26: ○ | H26: ○
A33: ⑤ 「社会で活用されているデータ」や「データの活用領域」は非常に広範囲であって、日常生活や社会の課題を解決する有用なツールになり得るもの」の内容を含む授業科目
B35: 授業科目 | F35: 単位数 | G35: 必須 | H35: 1-2 | I35: 1-3 | J35: 授業科目 | P35: 単位数 | Q35: 必須 | R35: 1-2 | S35: 1-3
B36: データサイエンス | F36: 2 | G36: ○ | H36: ○ | I36: ○
A44: ⑥ 「様々なデータ利活用の現場におけるデータ利活用事例が示され、様々な適用領域（流通、製造、金融、サービス、インフラ、公共、ヘルスケア等）の知見と組み合わせることで価値を創出するもの」の内容を含む授業科目
B46: 授業科目 | F46: 単位数 | G46: 必須 | H46: 1-4 | I46: 1-5 | J46: 授業科目 | P46: 単位数 | Q46: 必須 | R46: 1-4 | S46: 1-5
B47: データサイエンス | F47: 2 | G47: ○ | H47: ○ | I47: ○
A55: ⑦ 「活用に当たっての様々な留意事項（ELSI、個人情報、データ倫理、ＡＩ社会原則等）を考慮し、情報セキュリティや情報漏洩等、データを守る上での留意事項への理解をする」の内容を含む授業科目
B57: 授業科目 | F57: 単位数 | G57: 必須 | H57: 3-1 | I57: 3-2 | J57: 授業科目 | P57: 単位数 | Q57: 必須 | R57: 3-1 | S57: 3-2
B58: 情報リテラシー | F58: 2 | G58: ○ | H58: ○
B59: データサイエンス | F59: 2 | G59: ○ | H59: ○ | I59: ○
A66: ⑧ 「実データ・実課題（学術データ等を含む）を用いた演習など、社会での実例を題材として、「データを読む、説明する、扱う」といった数理・データサイエンス・ＡＩの基本的な活用法に関するもの」の内容を含む授業科目
B68: 授業科目 | E68: 単位数 | F68: 必須 | G68: 2-1 | H68: 2-2 | I68: 2-3 | J68: 授業科目 | O68: 単位数 | P68: 必須 | Q68: 2-1 | R68: 2-2 | S68: 2-3
B69: 情報処理論の基礎 | E69: 2 | F69: ○ | H69: ○
B70: データサイエンス | E70: 2 | F70: ○ | G70: ○ | H70: ○ | I70: ○
A77: ⑨ 選択「４．オプション」の内容を含む授業科目
B78: 授業科目 | F78: 選択項目 | J78: 授業科目 | P78: 選択項目
B79: データサイエンス | F79: 4‐3データ構造とプログラミング基礎
A87: ⑩ プログラムを構成する授業の内容
B88: 授業に含まれている内容・要素 | D88: 講義内容
B89: （１）現在進行中の社会変化（第４次産業革命、Society 5.0、データ駆動型社会等）に深く寄与しているものであり、それが自らの生活と密接に結びついている | C89: 1-1 | D89: ビッグデータ、IoT、AI、ロボット 「データサイエンス」 （第１回） データ量の増加、計算機の処理性能の向上 「データサイエンス」 （第１回、第２回）「情報リテラシー」 （第15回） 第4次産業革命、Society 5.0、データ駆動型社会 「データサイエンス」 （第１回）
C90: 1-6 | D90: AI等を活用した新しいビジネスモデル(商品のレコメンデーションなど) 「データサイエンス」 （第４回、第６回） AI最新技術の活用例（深層生成モデル、敵対的生成ネットワーク、強化学習）「データサイエンス」 （第４～６回）
B91: （２）「社会で活用されているデータ」や「データの活用領域」は非常に広範囲であって、日常生活や社会の課題を解決する有用なツールになり得るもの | C91: 1-2 | D91: 調査データ、実験データ、人の行動ログデータ、機械の稼働ログデータなど 「データサイエンス」 （第１回） 構造化データ、非構造化データ（文章、画像/動画、音声/音楽など） 「データサイエンス」 （第３回） データのオープン化（オープンデータ） 「データサイエンス」 （第１１回）
C92: 1-3 | D92: データ・AI活用領域の広がり(生産、消費、文化活動など) 「データサイエンス」 （第６回） 研究開発、製造、物流、販売、マーケティング、サービスなど 「データサイエンス」 （第７回）
B93: （３）様々なデータ利活用の現場におけるデータ利活用事例が示され、様々な適用領域（流通、製造、金融、サービス、インフラ、公共、ヘルスケア等）の知見と組み合わせることで価値を創出するもの | C93: 1-4 | D93: データ解析：予測、パターン発見、最適化など 「データサイエンス」（第４回） データ可視化：複合グラフ、2軸グラフ、関係性の可視化など 「データサイエンス」 （第１２回、第１５回） 非構造化データ処理：言語処理、画像/動画処理 「データサイエンス」 （第６回） 特化型AIと汎用AI、今のAIで出来ることと出来ないこと、AIとビッグデータ 「データサイエンス」 （第８回）
...

Sheet 様式２ 履修者等数の実績
AQ1: 様式２
AL2: 大学等名 | AM2: ='様式１-1 プログラムを構成する授業科目'!C2 -> 中央学院大学
A3: プログラムの履修者数等の実績について
A5: ①プログラム開設年度 | C5: 令和4 | E5: 年度
A7: ②履修者・修了者の実績
B9: 学部・学科名称 | C9: 学生数 | D9: 入学 定員 | E9: 収容 定員 | F9: 令和4年度 | L9: 令和3年度 | R9: 令和2年度 | X9: 令和元年度 | AD9: 平成30年度 | AJ9: 平成29年度 | AP9: 履修者数 合計 | AQ9: 履修率
F10: 履修者数 | I10: 修了者数 | L10: 履修者数 | O10: 修了者数 | R10: 履修者数 | U10: 修了者数 | X10: 履修者数 | AA10: 修了者数 | AD10: 履修者数 | AG10: 修了者数 | AJ10: 履修者数 | AM10: 修了者数
F11: 合計 | G11: 男性 | H11: 女性 | I11: 合計 | J11: 男性 | K11: 女性 | L11: 合計 | M11: 男性 | N11: 女性 | O11: 合計 | P11: 男性 | Q11: 女性 | R11: 合計 | S11: 男性 | T11: 女性 | U11: 合計 | V11: 男性 | W11: 女性 | X11: 合計 | Y11: 男性 | Z11: 女性 | AA11: 合計 | AB11: 男性 | AC11: 女性 | AD11: 合計 | AE11: 男性 | AF11: 女性 | AG11: 合計 | AH11: 男性 | AI11: 女性 | AJ11: 合計 | AK11: 男性 | AL11: 女性 | AM11: 合計 | AN11: 男性 | AO11: 女性
B12: 商学部商学科 | C12: =1477+232 -> 1709 | D12: 360 | E12: =D12*4 -> 1440 | F12: =G12+H12 -> 92 | G12: 84 | H12: 8 | I12: =J12+K12 -> 69 | J12: 63 | K12: 6 | L12: =M12+N12 -> 0 | O12: =P12+Q12 -> 0 | R12: =S12+T12 -> 0 | U12: =V12+W12 -> 0 | X12: =Y12+Z12 -> 0 | AA12: =AB12+AC12 -> 0 | AD12: =AE12+AF12 -> 0 | AG12: =AH12+AI12 -> 0 | AJ12: =AK12+AL12 -> 0 | AM12: =AN12+AO12 -> 0 | AP12: =F12+L12+R12+X12+AD12+AJ12 -> 92 | AQ12: =AP12/E12 -> 0.063888889
B13: 法学部法学科 | C13: =1010+201 -> 1211 | D13: 260 | E13: =260*4 -> 1040 | F13: =G13+H13 -> 33 | G13: 26 | H13: 7 | I13: =J13+K13 -> 30 | J13: 24 | K13: 6 | L13: =M13+N13 -> 0 | O13: =P13+Q13 -> 0 | R13: =S13+T13 -> 0 | U13: =V13+W13 -> 0 | X13: =Y13+Z13 -> 0 | AA13: =AB13+AC13 -> 0 | AD13: =AE13+AF13 -> 0 | AG13: =AH13+AI13 -> 0 | AJ13: =AK13+AL13 -> 0 | AM13: =AN13+AO13 -> 0 | AP13: =F13+L13+R13+X13+AD13+AJ13 -> 33 | AQ13: =AP13/E13 -> 0.031730769
B14: 現代教養学部 | C14: =290+89 -> 379 | D14: 100 | E14: =100*4 -> 400 | F14: =G14+H14 -> 15 | G14: 12 | H14: 3 | I14: =J14+K14 -> 11 | J14: 8 | K14: 3 | L14: =M14+N14 -> 0 | O14: =P14+Q14 -> 0 | R14: =S14+T14 -> 0 | U14: =V14+W14 -> 0 | X14: =Y14+Z14 -> 0 | AA14: =AB14+AC14 -> 0 | AD14: =AE14+AF14 -> 0 | AG14: =AH14+AI14 -> 0 | AJ14: =AK14+AL14 -> 0 | AM14: =AN14+AO14 -> 0 | AP14: =F14+L14+R14+X14+AD14+AJ14 -> 15 | AQ14: =AP14/E14 -> 0.0375
F15: =G15+H15 -> 0 | I15: =J15+K15 -> 0 | L15: =M15+N15 -> 0 | O15: =P15+Q15 -> 0 | R15: =S15+T15 -> 0 | U15: =V15+W15 -> 0 | X15: =Y15+Z15 -> 0 | AA15: =AB15+AC15 -> 0 | AD15: =AE15+AF15 -> 0 | AG15: =AH15+AI15 -> 0 | AJ15: =AK15+AL15 -> 0 | AM15: =AN15+AO15 -> 0 | AP15: =F15+L15+R15+X15+AD15+AJ15 -> 0 | AQ15: =AP15/E15 -> #DIV/0!
F16: =G16+H16 -> 0 | I16: =J16+K16 -> 0 | L16: =M16+N16 -> 0 | O16: =P16+Q16 -> 0 | R16: =S16+T16 -> 0 | U16: =V16+W16 -> 0 | X16: =Y16+Z16 -> 0 | AA16: =AB16+AC16 -> 0 | AD16: =AE16+AF16 -> 0 | AG16: =AH16+AI16 -> 0 | AJ16: =AK16+AL16 -> 0 | AM16: =AN16+AO16 -> 0 | AP16: =F16+L16+R16+X16+AD16+AJ16 -> 0 | AQ16: =AP16/E16 -> #DIV/0!
F17: =G17+H17 -> 0 | I17: =J17+K17 -> 0 | L17: =M17+N17 -> 0 | O17: =P17+Q17 -> 0 | R17: =S17+T17 -> 0 | U17: =V17+W17 -> 0 | X17: =Y17+Z17 -> 0 | AA17: =AB17+AC17 -> 0 | AD17: =AE17+AF17 -> 0 | AG17: =AH17+AI17 -> 0 | AJ17: =AK17+AL17 -> 0 | AM17: =AN17+AO17 -> 0 | AP17: =F17+L17+R17+X17+AD17+AJ17 -> 0 | AQ17: =AP17/E17 -> #DIV/0!
F18: =G18+H18 -> 0 | I18: =J18+K18 -> 0 | L18: =M18+N18 -> 0 | O18: =P18+Q18 -> 0 | R18: =S18+T18 -> 0 | U18: =V18+W18 -> 0 | X18: =Y18+Z18 -> 0 | AA18: =AB18+AC18 -> 0 | AD18: =AE18+AF18 -> 0 | AG18: =AH18+AI18 -> 0 | AJ18: =AK18+AL18 -> 0 | AM18: =AN18+AO18 -> 0 | AP18: =F18+L18+R18+X18+AD18+AJ18 -> 0 | AQ18: =AP18/E18 -> #DIV/0!
F19: =G19+H19 -> 0 | I19: =J19+K19 -> 0 | L19: =M19+N19 -> 0 | O19: =P19+Q19 -> 0 | R19: =S19+T19 -> 0 | U19: =V19+W19 -> 0 | X19: =Y19+Z19 -> 0 | AA19: =AB19+AC19 -> 0 | AD19: =AE19+AF19 -> 0 | AG19: =AH19+AI19 -> 0 | AJ19: =AK19+AL19 -> 0 | AM19: =AN19+AO19 -> 0 | AP19: =F19+L19+R19+X19+AD19+AJ19 -> 0 | AQ19: =AP19/E19 -> #DIV/0!
F20: =G20+H20 -> 0 | I20: =J20+K20 -> 0 | L20: =M20+N20 -> 0 | O20: =P20+Q20 -> 0 | R20: =S20+T20 -> 0 | U20: =V20+W20 -> 0 | X20: =Y20+Z20 -> 0 | AA20: =AB20+AC20 -> 0 | AD20: =AE20+AF20 -> 0 | AG20: =AH20+AI20 -> 0 | AJ20: =AK20+AL20 -> 0 | AM20: =AN20+AO20 -> 0 | AP20: =F20+L20+R20+X20+AD20+AJ20 -> 0 | AQ20: =AP20/E20 -> #DIV/0!
F21: =G21+H21 -> 0 | I21: =J21+K21 -> 0 | L21: =M21+N21 -> 0 | O21: =P21+Q21 -> 0 | R21: =S21+T21 -> 0 | U21: =V21+W21 -> 0 | X21: =Y21+Z21 -> 0 | AA21: =AB21+AC21 -> 0 | AD21: =AE21+AF21 -> 0 | AG21: =AH21+AI21 -> 0 | AJ21: =AK21+AL21 -> 0 | AM21: =AN21+AO21 -> 0 | AP21: =F21+L21+R21+X21+AD21+AJ21 -> 0 | AQ21: =AP21/E21 -> #DIV/0!
F22: =G22+H22 -> 0 | I22: =J22+K22 -> 0 | L22: =M22+N22 -> 0 | O22: =P22+Q22 -> 0 | R22: =S22+T22 -> 0 | U22: =V22+W22 -> 0 | X22: =Y22+Z22 -> 0 | AA22: =AB22+AC22 -> 0 | AD22: =AE22+AF22 -> 0 | AG22: =AH22+AI22 -> 0 | AJ22: =AK22+AL22 -> 0 | AM22: =AN22+AO22 -> 0 | AP22: =F22+L22+R22+X22+AD22+AJ22 -> 0 | AQ22: =AP22/E22 -> #DIV/0!
F23: =G23+H23 -> 0 | I23: =J23+K23 -> 0 | L23: =M23+N23 -> 0 | O23: =P23+Q23 -> 0 | R23: =S23+T23 -> 0 | U23: =V23+W23 -> 0 | X23: =Y23+Z23 -> 0 | AA23: =AB23+AC23 -> 0 | AD23: =AE23+AF23 -> 0 | AG23: =AH23+AI23 -> 0 | AJ23: =AK23+AL23 -> 0 | AM23: =AN23+AO23 -> 0 | AP23: =F23+L23+R23+X23+AD23+AJ23 -> 0 | AQ23: =AP23/E23 -> #DIV/0!
F24: =G24+H24 -> 0 | I24: =J24+K24 -> 0 | L24: =M24+N24 -> 0 | O24: =P24+Q24 -> 0 | R24: =S24+T24 -> 0 | U24: =V24+W24 -> 0 | X24: =Y24+Z24 -> 0 | AA24: =AB24+AC24 -> 0 | AD24: =AE24+AF24 -> 0 | AG24: =AH24+AI24 -> 0 | AJ24: =AK24+AL24 -> 0 | AM24: =AN24+AO24 -> 0 | AP24: =F24+L24+R24+X24+AD24+AJ24 -> 0 | AQ24: =AP24/E24 -> #DIV/0!
F25: =G25+H25 -> 0 | I25: =J25+K25 -> 0 | L25: =M25+N25 -> 0 | O25: =P25+Q25 -> 0 | R25: =S25+T25 -> 0 | U25: =V25+W25 -> 0 | X25: =Y25+Z25 -> 0 | AA25: =AB25+AC25 -> 0 | AD25: =AE25+AF25 -> 0 | AG25: =AH25+AI25 -> 0 | AJ25: =AK25+AL25 -> 0 | AM25: =AN25+AO25 -> 0 | AP25: =F25+L25+R25+X25+AD25+AJ25 -> 0 | AQ25: =AP25/E25 -> #DIV/0!
F26: =G26+H26 -> 0 | I26: =J26+K26 -> 0 | L26: =M26+N26 -> 0 | O26: =P26+Q26 -> 0 | R26: =S26+T26 -> 0 | U26: =V26+W26 -> 0 | X26: =Y26+Z26 -> 0 | AA26: =AB26+AC26 -> 0 | AD26: =AE26+AF26 -> 0 | AG26: =AH26+AI26 -> 0 | AJ26: =AK26+AL26 -> 0 | AM26: =AN26+AO26 -> 0 | AP26: =F26+L26+R26+X26+AD26+AJ26 -> 0 | AQ26: =AP26/E26 -> #DIV/0!
... F31: =G31+H31 -> 0 | I31: =J31+K31 -> 0 | L31: =M31+N31 -> 0 | O31: =P31+Q31 -> 0 | R31: =S31+T31 -> 0 | U31: =V31+W31 -> 0 | X31: =Y31+Z31 -> 0 | AA31: =AB31+AC31 -> 0 | AD31: =AE31+AF31 -> 0 | AG31: =AH31+AI31 -> 0 | AJ31: =AK31+AL31 -> 0 | AM31: =AN31+AO31 -> 0 | AP31: =F31+L31+R31+X31+AD31+AJ31 -> 0 | AQ31: =AP31/E31 -> #DIV/0!
B32: 合 計 | C32: =SUM(C12:C31) -> 3299 | D32: =SUM(D12:D31) -> 720 | E32: =SUM(E12:E31) -> 2880 | F32: =SUM(F12:F31) -> 140 | G32: =SUM(G12:G31) -> 122 | H32: =SUM(H12:H31) -> 18 | I32: =SUM(I12:I31) -> 110 | J32: =SUM(J12:J31) -> 95 | ... AP32: =SUM(AP12:AP31) -> 140 | AQ32: =AP32/E32 -> 0.048611111

Sheet 様式３ 教育の質・履修者数を向上させるための体制・計画
I1: 様式３
G2: 大学等名 | H2: ='様式１-1 プログラムを構成する授業科目'!C2 -> 中央学院大学
A4: 教育の質・履修者数を向上させるための体制・計画について
A6: ① | B6: 全学の教員数 | C6: (常勤） | E6: 86 | F6: 人 | G6: （非常勤） | H6: 129 | I6: 人
A8: ② | B8: プログラムの授業を教えている教員数 | H8: 10 | I8: 人
A10: ③ | B10: プログラムの運営責任者
B11: （責任者名） | C11: 譚 奕飛 | G11: （役職名） | H11: 商学部教授
A13: ④ | B13: プログラムを改善・進化させるための体制（委員会・組織等）
B14: 数理・データサイエンス・AI教育プログラム検討委員会
B16: （責任者名） | C16: 譚 奕飛 | G16: （役職名） | H16: 商学部教授
A18: ⑤ | B18: プログラムを改善・進化させるための体制を定める規則名称
B19: 中央学院大学委員会設置規程
A21: ⑥ | B21: 体制の目的
B22: 本学は、「公正な社会観と倫理観の涵養」を建学の精神として掲げている。多様化していく現代社会に対応すべく、商学，法学および現代教養学の分野に関わる様々な課題を発見し、解決できる能力を養うことを目的に、数理・データサイエンス・AI教育の全学的な充実を図り、関連科目を整備を行う。本委員会は各学部の情報教育担当教員を中心とした委員で構成し、庶務は教務課が担当する。「データサイエンス力」、「コンピュータ活用力」、「専門力」を向上させることを本プログラムの教育目標とし、対象科目の授業内容の検討・見直しを行い、履修者の興味を引き出す内容となるよう改善を行う。また、より多くの学生が本プログラムに参加できるよう、効果的な運営が行える方策について検討・改善を行う。
A34: ⑦ | B34: 具体的な構成員
B35: 譚 奕飛 商学部／教授（委員長） 浅井 宗海 商学部／教授（オブザーバー） 田村 謙次 商学部／准教授 小林 敬和 法学部／教授 楊 鯤昊 法学部／講師 齋藤 大輔 現代教養学部／准教授 内田 瑛 現代教養学部／助教 早坂 満 法人事務局長兼総務部長 冨田 喜恵 教務課主任
A48: ⑧ | B48: 履修者数・履修率の向上に向けた計画 ※様式１の「履修必須の有無」で「計画がある」としている場合は詳細について記載すること
B49: 令和４年度実績 | C49: ='様式２ 履修者等数の実績'!AQ32 -> 0.048611111 | E49: 令和５年度予定 | F49: 0.06 | H49: 令和６年度予定 | I49: 0.07
B50: 令和７年度予定 | C50: 0.08 | E50: 令和８年度予定 | F50: 0.09 | H50: 収容定員（名） | I50: ='様式２ 履修者等数の実績'!E32 -> 2880
B51: 具体的な計画
B52: 履修者数・履修率の向上を目指し、以下の目標を掲げる。 令和5年度予定 180名（6％） 令和6年度予定 210名（7％） 令和7年度予定 240名（8％） 令和8年度予定 260名（9％） 本プログラムの履修者数を伸ばすためには、選択科目である「データサイエンス」の履修者数を増加させる必要がある。令和4年度はPC教室（定員60名）で実施していたが、教室定員数を超える履修希望者がいたため、授業時間内でのPC利用を最小限に抑えたり、オンデマンド教材を利用して事前事後学習でカバーしたりするなど授業内容の見直しを行い、PC教室以外での授業が実施できるようにすることで教室定員数の多い普通教室で実施できるようにするなどの工夫を検討していく。また、将来的には希望履修者数に対応していくために「データサイエンス」の開講コマ数を増加させていく。令和4年度は各学期1コマずつの開講であったが、履修対象者の増加に伴い令和8年度までに、各学期2コマずつの開講（計4コマ）まで段階的に拡大を目指す。
A65: ⑨ | B65: 学部・学科に関係なく希望する学生全員が受講可能となるような必要な体制・取組等
B66: 本学では、情報リテラシー（商学部）、情報処理論（商学部）、情報処理I（法学部）、情報リテラシー（現代教養学部）、情報処理論の基礎（現代教養学部）は、必修科目となっており、データサイエンスは全学共通科目として設置することで、希望する学生のすべてが受講可能なカリキュラムとなっている。令和4年度においては、対象年次が1年次のみであったことからデータサイエンスは春学期と秋学期に各1コマの開講としていた。今後は履修対象年次が増加し、希望者が増加していくことから、増コマを検討していく。また，現在はPC教室を利用していることから履修者が一般教室より制限されるが、履修者にPCを持参させ受講させる方法や、必要に応じて，非常勤教員などを教員補充についての検討を行っていく。
A76: ⑩ | B76: できる限り多くの学生が履修できるような具体的な周知方法・取組
B77: 入学直後に実施されるプライムセミナー（新入生ガイダンス）においての周知、本学ポータルサイト（CGUポータル）での周知、大学ホームページへの掲載により、広く学生に本プログラムの内容と参加意義を周知している。また、1年次のゼミ科目（プロゼミナール（商学部）、基礎演習Ⅰ（法学部）、基礎演習（現代教養学部））において履修指導を行う際にも本プログラムの内容について周知している。特に、現代教養学部においては、学生要覧に示している履修モデルに本プログラムで必要となる科目のすべてが選択必修科目として含まれるものとなっている。さらに「データサイエンス」のシラバスに記載されている授業計画は具体的に実施内容を記述し、学生に分かりやすいように工夫している。今後は修了者の授業評価や本プログラムに対する感想などをまとめ、履修を検討している学生の後押しとなるように取り組みを検討する。
A88: ⑪ | B88: できる限り多くの学生が履修・修得できるようなサポート体制
B89: 本プログラムは各学部の必修科目（情報リテラシー（商学部、現代教養学部）、情報処理I（法学部）、情報処理論（商学部）、情報処理論の基礎（現代教養学部））と、1年次から全学共通科目である選択科目（データサイエンス）から構成される。情報スキル科目では、情報リテラシーと情報倫理に関する理解を深める。情報社会における諸問題を多く取り上げ、各学部の専門性に合わせた具体例を多く扱う。選択科目のデータサイエンスでは、どの学部の学生にも必要となる内容を中心に扱っている。いずれの科目も学習管理システム等を利用し、事前事後学習にも役立てられている。 本プログラムへの参加は特別な申請手続き等は不要であり、修了後には修了証を発行している。 いずれの科目においても授業評価アンケートを実施しており、授業評価をもとに、担当教員は報告書の提出が義務付けられている。本プログラムの修了に向けた改善などに活用されている。
A102: ⑫ | B102: 授業時間内外で学習指導、質問を受け付ける具体的な仕組み
B103: 本学ポータルサイト（CGUポータル）や学習管理システム（Microsoft TeamsやWebClass）により、授業資料の配布、担当教員との質疑が可能である。課題や試験は採点後、学生へ解説やコメントなどをフィードバックしている。学生はインターネットを介して、教材や課題をキャンパス内外からいつでも振り返ることができる。 各教員はオフィスアワーを設けることが義務付けられており、CGUポータルやメール等から届く質問には積極的に回答するように促されている。学生は新入生ガイダンスでこれらのシステムを利用して質問する方法の説明を受けている。 今後はオンデマンド教材を積極的に取り入れることも検討し、事前事後学習での活用に向けて必要な体制や仕組みづくりを模索していく。

Sheet 様式４　自己点検・評価
I1: 様式４
H2: 大学等名 | I2: ='様式１-1 プログラムを構成する授業科目'!C2 -> 中央学院大学
A3: 自己点検・評価について
A5: ① | B5: プログラムの自己点検・評価を行う体制（委員会・組織等）
B6: 自己点検・評価実施委員会/数理・データサイエンス・AI教育プログラム検討委員会
D8: （責任者名） | E8: 譚 奕飛 | G8: （役職名） | H8: 商学部教授
A10: ② | B10: 自己点検・評価体制における意見等
B11: 自己点検・評価の視点 | E11: 自己点検・評価体制における意見・結果・改善に向けた取組等
B12: 学内からの視点
C13: プログラムの履修・修得状況 | E13: 本学では中央学院大学のポータルサイト（CGUポータル）を通じて、学生のプログラムの履修・修得状況を常に把握している。また、複数の学習管理システム（CGUポータルやWebClass、Teams等）を使用して、各授業の出席状況、課題の提出状況、講義の理解度、目標の達成状況などを把握し、必要に応じて授業内外で学生に個別指導や履修支援を行う体制を整えている。さらに、数理・データサイエンス・AI教育プログラム検討委員会では定期的にプログラムの履修・修得状況を確認・分析する体制を整えている。これらの結果を踏まえて、本教育プログラムの自己点検や改善に取り組み、学生の履修を支援することに努めている。 ２０２２年度において、学生の習熟度に合わせてクラスを分けており、シラバスも一部異なる部分があるが、今後は、授業内容の統一を図っていく計画である。
C14: 学修成果 | E14: 本教育プログラムは「教養としてのデータサイエンス・AI」をコンセプトとしている。その目標は、各学部の学生がそれぞれの専門知識を持ち、課題を発見し解決する「専門力」、コンピューターを効果的に活用する「コンピューター活用力」、さらに情報処理や人工知能を活用して価値を生み出す「データサイエンス力」を育成することである。また、各科目のシラバスは授業の目標と学生が修得できる能力を明確に記載している。 学期末の授業アンケートでは、学生にシラバスに記載されている「授業の達成目標」や「就業力」の達成度について回答させ、その結果を確認・分析することで、教育の質を継続的に向上させている。「データサイエンス」の科目では、毎回の授業において行う「主観アンケート」「興味深さ、分かりやすさ、理解度アンケート」や、それらの結果から得られるポジティブ・ネガティブな評価に関して、平均などだけではなく、時系列での推移やp値による優位性の確認、散布図行列による可視化などを用いて、アンケート自体に対してデータサイエンスの手法を用いて分析することにより、学生自身が明示的に意識していない情報を授業改善に活かしている。
C15: 学生アンケート等を通じた学生の内容の理解度 | E15: 各科目で随時に実施している授業理解度小テストや、本学教務課が学期末に実施している学生授業評価アンケートなどの分析を通して、本教育プログラム科目に関する学生の理解度や、授業満足度、教授活動の適切性に関する学生の評価を把握できる。これらの結果は数理・データサイエンス・AI教育プログラム検討委員会にフィードバックし、本教育プログラムの評価・改善に活用されている。 特に、「データサイエンス」の科目では、毎回の授業終了後に、学生のフィードバックを収集するために、授業理解度や授業の説明のわかりやすさに関するアンケートを実施している。このアンケートの結果をもとに、学生が毎回の授業内容に対する意見を把握し、次回の授業を改善することを試みている。
C16: 学生アンケート等を通じた後輩等他の学生への推奨度 | E16: 「データサイエンス」科目では、第1回目と最終回の授業で、9つの質問を通じて、受講生に情報利活用能力（8つのディメンション）を自己評価させる仕組みを導入している。最初の授業と最後の授業での自己評価点を比較することで、受講生の能力の変化を分析している。結果として、2022年には9割以上の学生が、8つのディメンションすべてにおいて情報利活用能力が向上したと評価した。また、2022年の秋学期には、92.68%の受講生がこの授業を他の学生に推奨すると評価した。 情報リテラシー（商学部）、情報処理論（商学部）、情報処理I（法学部）、情報リテラシー（現代教養学部）、情報処理論の基礎（現代教養学部）は必修科目となっており、1年生は全員が修得する必要がある。そのため、他の学生や後輩学生の推奨度に関するアンケートは実施していないが、教務ガイダンスなどを通じて本教育プログラムの情報を周知するなど、学生の学習モチベーションを高める工夫をしている。また、学生授業評価アンケートなどの結果を通じて、学生の理解度や満足度、教授の活動適切性に関する評価を把握している。
C17: 全学的な履修者数、履修率向上に向けた計画の達成・進捗状況 | E17: 情報リテラシー（商学部）、情報処理論（商学部）、情報処理I（法学部）、情報リテラシー（現代教養学部）、情報処理論の基礎（現代教養学部）は、必須科目となっており、本学1年生は全員が受講しなければならない。従って、この2科目は令和5年度の履修率は100%に達すると見込まれている。 「データサイエンス」は、春学期と秋学期に週1コマの授業を開講している。また、学内では、教務ガイダンスを通じた科目の紹介、大学のホームページを通じた周知など、学修へのモチベーションの向上のための工夫も行っている。これらにより、今後の受講生数の増加に応じて、授業コマ数の増加などの措置も数理・データサイエンス・AI教育プログラム検討委員会で検討されている。
B18: 学外からの視点
C19: 教育プログラム修了者の進路、活躍状況、企業等の評価 | E19: 本教育プログラムは2022年度から開始されているため、現在本プログラムを修了した学生はまだ在学中であり、進路についての確認は出来ない状況である。しかし、今後、就職課が毎年実施している卒業生の進路調査を通して本教育プログラムを修了した卒業生の進路や活躍状況等を把握することは可能である。 また、本教育プログラムに含まれるいくつかの科目（情報リテラシー（商学部）、情報処理論（商学部）、情報処理I（法学部）、情報リテラシー（現代教養学部）、情報処理論の基礎（現代教養学部）は2022年度以前から開講されているもので、それらの授業の履修者については、学部を問わず情報通信業界への就職者が一定数存在する。 【業種別就職状況（2021年度）】情報通信関係への就職率：商学部10%、法学部5%、現代教養学部6%
C20: 産業界からの視点を含めた教育プログラム内容・手法等への意見 | E20: 本教育プログラムは、産業界のニーズやトレンドに合わせた教育が重要であると考え、教育内容や手法、実践的な演習などに力を入れている。また、産業界と定期的な意見交換を行うことが大切と認識しており、教育プログラムを改善することに努めている。科目を担当する教員や数理・データサイエンス・AI教育プログラム検討委員会の委員の多くは、情報教育、経営情報、コンピューターサイエンス、統計解析、人工知能などの分野に専門性を持ち、IT企業やデータ解析コンサルティング企業と共同研究を行っている教員もいる。これらの研究経験から、産業界のニーズを本教育プログラムにフィードバックすることができる。
B21: 数理・データサイエンス・ＡＩを「学ぶ楽しさ」「学ぶことの意義」を理解させること | E21: 商学部、法学部、現代教養学部の学生に対して、数理・データサイエンス・AIを「学ぶ楽しさ」「学ぶことの意義」を理解させるためには、学生の専門性や専攻の特性を生かすことが重要であると考えている。そのため、理論中心の授業からはずれ、授業の中に事例をふんだんに取り入れて、実践的なアプローチを採用することを心がける。例えば、Society5.0の実現する世界をイメージしやすいように、気候、研究開発、製造、物流、販売、マーケティング、サービスなどの業界のデータ分析事例を使って、分析やモデルの作成を通じて、数理・データサイエンス・AIの実用性と楽しさを体験させることに力を入れている。その際に、初心者でも利用できるツールを使い、実践的な学びを工夫している。 また、学生の持つ専門分野との関係も考慮し、学ぶことの意義をより深く理解させるよう工夫しており、「学ぶ楽しさ」の指標として行った「興味深さ」のアンケートでは、0～10の基準においてすべての回の授業において6.5以上、最大は7.41、全授業平均6.82であり、授業全体としては評価基準の中心値以上であり、結果としては良好な値であるといえるが、より学ぶ楽しさや意義に対する理解を促すために数理・データサイエンス・AIの専門家や実務者によるセミナーや講演を通じて、学生に「学ぶことの意義」や「学ぶ楽しさ」を紹介することや、GPSなどのキャリアアセスメントツールを活用し、学生一人ひとりの特性に合ったキャリアアップデザインを提案することなどが検討事項である。
B22: 内容・水準を維持・向上しつつ、より「分かりやすい」授業とすること | E22: 本教育プログラムでは、本学の学生の特性やニーズに合った授業コンテンツの作成に力を入れている。特に、商学部、法学部、現代教養学部の文系学生に考慮し、理論的な授業ではなく、データサイエンスや人工知能が日常生活や仕事において実際に道具として、どのように上手に活用することができるかの基礎素養を修得させることを重視している。授業中にビジネスや社会に関連する実例をふんだんに取り上げ、学生の理解を深めることを心がけている。例えば、商学部や法学部の学生には、ビジネスや法律の観点からデータサイエンスやAIがどのように活用されているかを伝え、現代教養学部の学生には、社会問題の解決にデータサイエンスやAIがどのように使われているかを紹介する。これにより、学生の興味を引き出し、勉強の意欲を高めるとともに、授業の分かりやすさと質を維持することに努めている。 また、期末に実施する授業アンケートの結果を利用して、授業の質向上に努めている。特に、「データサイエンス」の科目では、毎回の授業終了後に、受講生に対して授業理解度や授業の分かりやすさに関するアンケート調査を実施している。この調査によって、学生が毎回の授業内容に対するフィードバックを把握し、次回の授業内容を改善する試みを実践している。
