Workbook

Sheet 様式１ー１（国際商経学部）
R1: 様式１－１ | T1: 「学部・学科によって、修了要件は相違する」場合は、本シートを複製の上＜様式１－〇＞と枝番号を付してください
B2: 大学等名 | C2: 兵庫県立大学
B3: プログラム名 | C3: 数理・データサイエンス・AI教育プログラム
A5: プログラムを構成する授業科目について
A7: ① 対象となる学部・学科名称 | J7: ② 教育プログラムの修了要件 | K7: 学部・学科によって、修了要件は相違する
B9: 国際商経学部
A12: ③ 修了要件
B13: 国際商経学部（経済学コース・経営学コース）：「データサイエンス入門」2単位を修得すること。 国際商経学部（グローバルビジネスコース） ：「Introduction to Data Science」2単位を修得すること。 | V13: 【プルダウンリスト】
V14: 令和４年度以前より、履修することが必須のプログラムとして実施
V15: 令和７年度までに履修必須とする計画
V16: 令和８年度以降に履修必須とする計画、又は未定
B20: 必要最低単位数 | C20: 2 | E20: 単位 | J20: 履修必須の有無 | K20: 令和４年度以前より、履修することが必須のプログラムとして実施
A22: ④ 現在進行中の社会変化（第４次産業革命、Society 5.0、データ駆動型社会等）に深く寄与しているものであり、それが自らの生活と密接に結びついている」の内容を含む授業科目
B24: 授業科目 | F24: 単位数 | G24: 必須 | H24: 1-1 | I24: 1-6 | J24: 授業科目 | P24: 単位数 | Q24: 必須 | R24: 1-1 | S24: 1-6
B25: データサイエンス入門 | F25: 2 | H25: ○ | I25: ○ | J25: Introduction to Data Science | P25: 2 | R25: ○ | S25: ○
A33: ⑤ 「社会で活用されているデータ」や「データの活用領域」は非常に広範囲であって、日常生活や社会の課題を解決する有用なツールになり得るもの」の内容を含む授業科目
B35: 授業科目 | F35: 単位数 | G35: 必須 | H35: 1-2 | I35: 1-3 | J35: 授業科目 | P35: 単位数 | Q35: 必須 | R35: 1-2 | S35: 1-3
B36: データサイエンス入門 | F36: 2 | H36: ○ | I36: ○ | J36: Introduction to Data Science | P36: 2 | R36: ○ | S36: ○
A44: ⑥ 「様々なデータ利活用の現場におけるデータ利活用事例が示され、様々な適用領域（流通、製造、金融、サービス、インフラ、公共、ヘルスケア等）の知見と組み合わせることで価値を創出するもの」の内容を含む授業科目
B46: 授業科目 | F46: 単位数 | G46: 必須 | H46: 1-4 | I46: 1-5 | J46: 授業科目 | P46: 単位数 | Q46: 必須 | R46: 1-4 | S46: 1-5
B47: データサイエンス入門 | F47: 2 | H47: ○ | I47: ○ | J47: Introduction to Data Science | P47: 2 | R47: ○ | S47: ○
A55: ⑦ 「活用に当たっての様々な留意事項（ELSI、個人情報、データ倫理、ＡＩ社会原則等）を考慮し、情報セキュリティや情報漏洩等、データを守る上での留意事項への理解をする」の内容を含む授業科目
B57: 授業科目 | F57: 単位数 | G57: 必須 | H57: 3-1 | I57: 3-2 | J57: 授業科目 | P57: 単位数 | Q57: 必須 | R57: 3-1 | S57: 3-2
B58: データサイエンス入門 | F58: 2 | H58: ○ | I58: ○ | J58: Introduction to Data Science | P58: 2 | R58: ○ | S58: ○
A66: ⑧ 「実データ・実課題（学術データ等を含む）を用いた演習など、社会での実例を題材として、「データを読む、説明する、扱う」といった数理・データサイエンス・ＡＩの基本的な活用法に関するもの」の内容を含む授業科目
B68: 授業科目 | E68: 単位数 | F68: 必須 | G68: 2-1 | H68: 2-2 | I68: 2-3 | J68: 授業科目 | O68: 単位数 | P68: 必須 | Q68: 2-1 | R68: 2-2 | S68: 2-3
B69: データサイエンス入門 | E69: 2 | G69: ○ | H69: ○ | I69: ○ | J69: Introduction to Data Science | O69: 2 | Q69: ○ | R69: ○ | S69: ○
A77: ⑨ 選択「４．オプション」の内容を含む授業科目
B78: 授業科目 | F78: 選択項目 | J78: 授業科目 | P78: 選択項目
A87: ⑩ プログラムを構成する授業の内容
B88: 授業に含まれている内容・要素 | D88: 講義内容
B89: （１）現在進行中の社会変化（第４次産業革命、Society 5.0、データ駆動型社会等）に深く寄与しているものであり、それが自らの生活と密接に結びついている | C89: 1-1 | D89: ビッグデータ、IoT、AI、ロボット、データ量の増加、計算機の処理速度の向上、AIの非連続的進化、第４次産業革命、Society5.0、データ駆動型社会、コンピュータの構成、コンピュータネットワーク（インターネット）等について概説。 キーワード：ビッグデータ、IoT、 AI、ロボット 『データサイエンス入門』 『Introduction to Data Science』 （第2回）「本学の情報処理教育システムの概要(2)」 （第3回）「現代社会におけるデータサイエンス」
C90: 1-6 | D90: AI等を活用した新しいビジネスモデル、及びAI最新技術の活用例等について概説。 キーワード：AI等を活用した新しいビジネスモデル、AI最新技術の活用例 『データサイエンス入門』 『Introduction to Data Science』 （第3回）「現代社会におけるデータサイエンス」
B91: （２）「社会で活用されているデータ」や「データの活用領域」は非常に広範囲であって、日常生活や社会の課題を解決する有用なツールになり得るもの | C91: 1-2 | D91: 調査データ、ログデータ、実験データ、観測データ、1次・2次・3次データ、メタデータ、構造化データ、非構造化データ、データ作成、オープンデータ等について概説。 キーワード：調査データ、実験データなど 『データサイエンス入門』 『Introduction to Data Science』 （第4回）「データ・AI利活用の現場」
C92: 1-3 | D92: 事業活動におけるデータ・AI活用の広がり（研究開発、購買物流・調達等）及び、活用目的ごとのデータ・AI活用の広がり（仮説検証、知識発見等）について概説。 キーワード：データ・ AI活用領域の広がり 『データサイエンス入門』 『Introduction to Data Science』 （第4回）「データ・AI利活用の現場」
B93: （３）様々なデータ利活用の現場におけるデータ利活用事例が示され、様々な適用領域（流通、製造、金融、サービス、インフラ、公共、ヘルスケア等）の知見と組み合わせることで価値を創出するもの | C93: 1-4 | D93: データ解析（予測、補間、グルーピング、クラスタリング、パターン発見、最適化、シミュレーション・データ同化）、非構造化データ処理、データ可視化、パターン認識、人工知能等について概説。 キーワード：データ解析 『データサイエンス入門』 『Introduction to Data Science』 （第4回）「データ・AI利活用の現場」
C94: 1-5 | D94: データ分析による意思決定、情報技術による自動化、データ分析・自動化の実態、組織的考慮点について概説。 キーワード：データサイエンスのサイクル 『データサイエンス入門』 『Introduction to Data Science』 （第4回）「データ・AI利活用の現場」
B95: （４）活用に当たっての様々な留意事項（ELSI、個人情報、データ倫理、ＡＩ社会原則等）を考慮し、情報セキュリティや情報漏洩等、データを守る上での留意事項への理解をする | C95: 3-1 | D95: ELSI、個人情報保護、EU一般データ保護規則（GDPR）、忘れられる権利、オプトアウト、データ倫理、AI社会原則、データバイアス、アルゴリズムバイアス、AIサービスの責任論、データ・AI活用における負の事例等について概説。 キーワード：ELSI、個人情報保護、データ倫理：データのねつ造、改ざん、盗用、プライバシー保護 『データサイエンス入門』 『Introduction to Data Science』 第5回「情報倫理」
C96: 3-2 | D96: 情報セキュリティの定義、匿名加工情報、暗号化、パスワード、悪意ある情報搾取、情報漏洩によるセキュリティ事故の事例。 キーワード：情報セキュリティ、匿名加工情報，暗号化、パスワード、悪意ある情報搾取、情報漏洩等によるセキュリティ事故の事例紹介 『データサイエンス入門』 『Introduction to Data Science』 第6回「情報セキュリティ」
B97: （５）実データ・実課題（学術データ等を含む）を用いた演習など、社会での実例を題材として、「データを読む、説明する、扱う」といった数理・データサイエンス・ＡＩの基本的な活用法に関するもの | C97: 2-1 | D97: ヒストグラム、代表値（平均・中央値・最頻値・外れ値）、ばらつき（分散・標準偏差）等について概説と演習。 キーワード：データの種類、データの分布と代表値 『データサイエンス入門』 『Introduction to Data Science』 （第10回、第11回）「データを要約する(1)(2)」 （第12回）「レポート課題」
...

Sheet 様式１ー２（社会情報科学部）
R1: 様式１－２ | T1: 「学部・学科によって、修了要件は相違する」場合は、本シートを複製の上＜様式１－〇＞と枝番号を付してください
B2: 大学等名 | C2: 兵庫県立大学
B3: プログラム名 | C3: 数理・データサイエンス・AI教育プログラム
A5: プログラムを構成する授業科目について
A7: ① 対象となる学部・学科名称 | J7: ② 教育プログラムの修了要件 | K7: 学部・学科によって、修了要件は相違する
B9: 社会情報科学部
A12: ③ 修了要件
B13: 該当する全ての授業科目の単位を修得すること （データサイエンス入門、社会情報科学概論，情報倫理と法） | V13: 【プルダウンリスト】
V14: 令和４年度以前より、履修することが必須のプログラムとして実施
V15: 令和７年度までに履修必須とする計画
V16: 令和８年度以降に履修必須とする計画、又は未定
B20: 必要最低単位数 | C20: 6 | E20: 単位 | J20: 履修必須の有無 | K20: 令和４年度以前より、履修することが必須のプログラムとして実施
A22: ④ 現在進行中の社会変化（第４次産業革命、Society 5.0、データ駆動型社会等）に深く寄与しているものであり、それが自らの生活と密接に結びついている」の内容を含む授業科目
B24: 授業科目 | F24: 単位数 | G24: 必須 | H24: 1-1 | I24: 1-6 | J24: 授業科目 | P24: 単位数 | Q24: 必須 | R24: 1-1 | S24: 1-6
B25: 社会情報科学概論 | F25: 2 | G25: ○ | H25: ○ | I25: ○
A33: ⑤ 「社会で活用されているデータ」や「データの活用領域」は非常に広範囲であって、日常生活や社会の課題を解決する有用なツールになり得るもの」の内容を含む授業科目
B35: 授業科目 | F35: 単位数 | G35: 必須 | H35: 1-2 | I35: 1-3 | J35: 授業科目 | P35: 単位数 | Q35: 必須 | R35: 1-2 | S35: 1-3
B36: データサイエンス入門 | F36: 2 | G36: ○ | H36: ○
B37: 社会情報科学概論 | F37: 2 | G37: ○ | I37: ○
A44: ⑥ 「様々なデータ利活用の現場におけるデータ利活用事例が示され、様々な適用領域（流通、製造、金融、サービス、インフラ、公共、ヘルスケア等）の知見と組み合わせることで価値を創出するもの」の内容を含む授業科目
B46: 授業科目 | F46: 単位数 | G46: 必須 | H46: 1-4 | I46: 1-5 | J46: 授業科目 | P46: 単位数 | Q46: 必須 | R46: 1-4 | S46: 1-5
B47: 社会情報科学概論 | F47: 2 | G47: ○ | H47: ○ | I47: ○
A55: ⑦ 「活用に当たっての様々な留意事項（ELSI、個人情報、データ倫理、ＡＩ社会原則等）を考慮し、情報セキュリティや情報漏洩等、データを守る上での留意事項への理解をする」の内容を含む授業科目
B57: 授業科目 | F57: 単位数 | G57: 必須 | H57: 3-1 | I57: 3-2 | J57: 授業科目 | P57: 単位数 | Q57: 必須 | R57: 3-1 | S57: 3-2
B58: 情報倫理と法 | F58: 2 | G58: ○ | H58: ○ | I58: ○
A66: ⑧ 「実データ・実課題（学術データ等を含む）を用いた演習など、社会での実例を題材として、「データを読む、説明する、扱う」といった数理・データサイエンス・ＡＩの基本的な活用法に関するもの」の内容を含む授業科目
B68: 授業科目 | E68: 単位数 | F68: 必須 | G68: 2-1 | H68: 2-2 | I68: 2-3 | J68: 授業科目 | O68: 単位数 | P68: 必須 | Q68: 2-1 | R68: 2-2 | S68: 2-3
B69: データサイエンス入門 | E69: 2 | F69: ○ | G69: ○ | H69: ○ | I69: ○
A77: ⑨ 選択「４．オプション」の内容を含む授業科目
B78: 授業科目 | F78: 選択項目 | J78: 授業科目 | P78: 選択項目
B79: 社会情報科学のための数学 | F79: 4-1統計および数理基礎 | J79: 機械学習 | P79: 4‐8データ活用実践（教師あり学習）
B80: データ構造とアルゴリズム | F80: 4‐2アルゴリズム基礎
B81: プログラミングI | F81: 4‐3データ構造とプログラミング基礎
B82: 機械学習 | F82: 4‐4時系列データ解析
B83: データマイニング | F83: 4‐5テキスト解析
B84: 機械学習 | F84: 4‐6画像解析
B85: プログラミングI | F85: 4‐7データハンドリング
A87: ⑩ プログラムを構成する授業の内容
B88: 授業に含まれている内容・要素 | D88: 講義内容
B89: （１）現在進行中の社会変化（第４次産業革命、Society 5.0、データ駆動型社会等）に深く寄与しているものであり、それが自らの生活と密接に結びついている | C89: 1-1 | D89: 現在進行中の社会変化（第４次産業革命、Society 5.0、データ駆動型社会等）と、社会情報科学部で学ぶデータサイエンスとの関係性や、データサイエンスに関する理論科目を学ぶことの大切さ、理論を実際の現場に応用することの難しさを学ぶとともに、卒業後どのような活躍が求められているのか理解する。 キーワード：第４次産業革命、Society 5.0、データ駆動型社会 『社会情報科学概論』（第1回）「イントロダクション」
...

Sheet 様式１ー３（工学部）
R1: 様式１－３ | T1: 「学部・学科によって、修了要件は相違する」場合は、本シートを複製の上＜様式１－〇＞と枝番号を付してください
B2: 大学等名 | C2: 兵庫県立大学
B3: プログラム名 | C3: 数理・データサイエンス・AI教育プログラム
A5: プログラムを構成する授業科目について
A7: ① 対象となる学部・学科名称 | J7: ② 教育プログラムの修了要件 | K7: 学部・学科によって、修了要件は相違する
B9: 工学部
A12: ③ 修了要件
B13: 該当する全ての授業科目の単位を修得すること （基礎ゼミナール、情報処理基礎、工学倫理） | V13: 【プルダウンリスト】
V14: 令和４年度以前より、履修することが必須のプログラムとして実施
V15: 令和７年度までに履修必須とする計画
V16: 令和８年度以降に履修必須とする計画、又は未定
B20: 必要最低単位数 | C20: 6 | E20: 単位 | J20: 履修必須の有無 | K20: 令和８年度以降に履修必須とする計画、又は未定
A22: ④ 現在進行中の社会変化（第４次産業革命、Society 5.0、データ駆動型社会等）に深く寄与しているものであり、それが自らの生活と密接に結びついている」の内容を含む授業科目
B24: 授業科目 | F24: 単位数 | G24: 必須 | H24: 1-1 | I24: 1-6 | J24: 授業科目 | P24: 単位数 | Q24: 必須 | R24: 1-1 | S24: 1-6
B25: 基礎ゼミナール | F25: 2 | G25: ○ | H25: ○ | I25: ○
A33: ⑤ 「社会で活用されているデータ」や「データの活用領域」は非常に広範囲であって、日常生活や社会の課題を解決する有用なツールになり得るもの」の内容を含む授業科目
B35: 授業科目 | F35: 単位数 | G35: 必須 | H35: 1-2 | I35: 1-3 | J35: 授業科目 | P35: 単位数 | Q35: 必須 | R35: 1-2 | S35: 1-3
B36: 基礎ゼミナール | F36: 2 | G36: ○ | H36: ○ | I36: ○
A44: ⑥ 「様々なデータ利活用の現場におけるデータ利活用事例が示され、様々な適用領域（流通、製造、金融、サービス、インフラ、公共、ヘルスケア等）の知見と組み合わせることで価値を創出するもの」の内容を含む授業科目
B46: 授業科目 | F46: 単位数 | G46: 必須 | H46: 1-4 | I46: 1-5 | J46: 授業科目 | P46: 単位数 | Q46: 必須 | R46: 1-4 | S46: 1-5
B47: 基礎ゼミナール | F47: 2 | G47: ○ | H47: ○ | I47: ○
A55: ⑦ 「活用に当たっての様々な留意事項（ELSI、個人情報、データ倫理、ＡＩ社会原則等）を考慮し、情報セキュリティや情報漏洩等、データを守る上での留意事項への理解をする」の内容を含む授業科目
B57: 授業科目 | F57: 単位数 | G57: 必須 | H57: 3-1 | I57: 3-2 | J57: 授業科目 | P57: 単位数 | Q57: 必須 | R57: 3-1 | S57: 3-2
B58: 工学倫理 | F58: 2 | G58: ○ | H58: ○ | I58: ○
A66: ⑧ 「実データ・実課題（学術データ等を含む）を用いた演習など、社会での実例を題材として、「データを読む、説明する、扱う」といった数理・データサイエンス・ＡＩの基本的な活用法に関するもの」の内容を含む授業科目
B68: 授業科目 | E68: 単位数 | F68: 必須 | G68: 2-1 | H68: 2-2 | I68: 2-3 | J68: 授業科目 | O68: 単位数 | P68: 必須 | Q68: 2-1 | R68: 2-2 | S68: 2-3
B69: 情報処理基礎 | E69: 2 | F69: ○ | G69: ○ | H69: ○ | I69: ○
A77: ⑨ 選択「４．オプション」の内容を含む授業科目
B78: 授業科目 | F78: 選択項目 | J78: 授業科目 | P78: 選択項目
B79: 確率・統計 | F79: 4-1統計および数理基礎
B80: 代数学Ⅰ | F80: 4-1統計および数理基礎
B81: 代数学Ⅱ | F81: 4-1統計および数理基礎
A87: ⑩ プログラムを構成する授業の内容
B88: 授業に含まれている内容・要素 | D88: 講義内容
B89: （１）現在進行中の社会変化（第４次産業革命、Society 5.0、データ駆動型社会等）に深く寄与しているものであり、それが自らの生活と密接に結びついている | C89: 1-1 | D89: 第４次産業革命、Society5.0を迎え、ビッグデータ、AIは日常的なものにすでになっている。現在の日常生活や社会で、どのような変化が起きているかを知り、データやAIを活用した新しいビジネス／サービスについて学ぶ。また、Society5.0の実現によって可能となること、新しいビジネス／サービスが自らの生活においてどのように密接に関連しているかを理解する。 キーワード：第４次産業革命、Society 5.0、データ駆動型社会 電気電子情報工学科、『基礎ゼミナール』（第7回）「現代社会におけるデータサイエンス」 機械・材料工学科、『基礎ゼミナール』（第1回）「現代社会におけるデータサイエンス」 応用化学工学科、『基礎ゼミナール』（第12回）「現代社会におけるデータサイエンス」
C90: 1-6 | D90: 電気・電子・機械・化学などのすべての工学分野において、ビッグデータ、AI技術により、その開発手段、研究手段がどのように変わるかを理解する。加えて、それらAI利活用をさらに進める最先端の技術である深層学習、敵対的生成ネットワーク、AIモデルの解釈性などを概説する。 キーワード：AI等を活用した新しいビジネスモデル、AI最新技術の活用例 電気電子情報工学科、『基礎ゼミナール』（第7回）「現代社会におけるデータサイエンス」 機械・材料工学科、『基礎ゼミナール』（第1回）「現代社会におけるデータサイエンス」 応用化学工学科、『基礎ゼミナール』（第12回）「現代社会におけるデータサイエンス」
B91: （２）「社会で活用されているデータ」や「データの活用領域」は非常に広範囲であって、日常生活や社会の課題を解決する有用なツールになり得るもの | C91: 1-2 | D91: 社会で活用されているデータについて、その収集方法、データの所有者、データの表現形式の基本について学ぶ。さらに、AI学習で必要となるアノテーションについて理解する。特に工学分野で取得されるデータについて学ぶ。 キーワード：調査データ、実験データなど 電気電子情報工学科、『基礎ゼミナール』（第8回）「社会・工学分野におけるデータ・AI利活用領域」 機械・材料工学科、『基礎ゼミナール』（第2回）「社会・工学分野におけるデータ・AI利活用領域」 応用化学工学科、『基礎ゼミナール』（第13回）「社会・工学分野におけるデータ・AI利活用領域」
C92: 1-3 | D92: データサイエンスやAIが、日常生活や社会課題の解決、工学分野での研究開発にどのように用いられるかを、いくつかの例を通して学ぶ。 キーワード：データ・ AI活用領域の広がり 電気電子情報工学科、『基礎ゼミナール』（第8回）、社会・工学分野におけるデータ・AI利活用領域 機械・材料工学科、『基礎ゼミナール』（第2回）、社会・工学分野におけるデータ・AI利活用領域 応用化学工学科、『基礎ゼミナール』（第13回）、社会・工学分野におけるデータ・AI利活用領域
B93: （３）様々なデータ利活用の現場におけるデータ利活用事例が示され、様々な適用領域（流通、製造、金融、サービス、インフラ、公共、ヘルスケア等）の知見と組み合わせることで価値を創出するもの | C93: 1-4 | D93: データの一次分析、高次元データの可視化について理解し、課題解決のための技術として、データサイエンス、AIによる予測、クラスタリング、知識抽出、最適化、シミュレーションとデータ同化の概要を学ぶ。 キーワード：データ解析 電気電子情報工学科、『基礎ゼミナール』（第9回）、データ・AI利活用のための技術と応用事例 機械・材料工学科、『基礎ゼミナール』（第3回）、データ・AI利活用のための技術と応用事例 応用化学工学科、『基礎ゼミナール』（第14回）、データ・AI利活用のための技術と応用事例
C94: 1-5 | D94: 日常生活や社会課題の解決に用いられているデータサイエンス、AIの技術について、様々な適用領域の具体的事例を基に、その概要を学ぶと共に、データサイエンスにおける問題解決の基本的考え方を理解する。 キーワード：データサイエンスのサイクル 電気電子情報工学科、『基礎ゼミナール』（第9回）、データ・AI利活用のための技術と応用事例 機械・材料工学科、『基礎ゼミナール』（第3回）、データ・AI利活用のための技術と応用事例 応用化学工学科、『基礎ゼミナール』（第14回）、データ・AI利活用のための技術と応用事例
...

Sheet 様式１ー４ (理学部)
R1: 様式１－４ | T1: 「学部・学科によって、修了要件は相違する」場合は、本シートを複製の上＜様式１－〇＞と枝番号を付してください
B2: 大学等名 | C2: 兵庫県立大学
B3: プログラム名 | C3: 数理・データサイエンス・AI教育プログラム
A5: プログラムを構成する授業科目について
A7: ① 対象となる学部・学科名称 | J7: ② 教育プログラムの修了要件 | K7: 学部・学科によって、修了要件は相違する
B9: 理学部
A12: ③ 修了要件
B13: 「データサイエンス入門」2単位を修得すること。 | V13: 【プルダウンリスト】
V14: 令和４年度以前より、履修することが必須のプログラムとして実施
V15: 令和７年度までに履修必須とする計画
V16: 令和８年度以降に履修必須とする計画、又は未定
B20: 必要最低単位数 | C20: 2 | E20: 単位 | J20: 履修必須の有無 | K20: 令和４年度以前より、履修することが必須のプログラムとして実施
A22: ④ 現在進行中の社会変化（第４次産業革命、Society 5.0、データ駆動型社会等）に深く寄与しているものであり、それが自らの生活と密接に結びついている」の内容を含む授業科目
B24: 授業科目 | F24: 単位数 | G24: 必須 | H24: 1-1 | I24: 1-6 | J24: 授業科目 | P24: 単位数 | Q24: 必須 | R24: 1-1 | S24: 1-6
B25: データサイエンス入門 | F25: 2 | G25: ○ | H25: ○ | I25: ○
A33: ⑤ 「社会で活用されているデータ」や「データの活用領域」は非常に広範囲であって、日常生活や社会の課題を解決する有用なツールになり得るもの」の内容を含む授業科目
B35: 授業科目 | F35: 単位数 | G35: 必須 | H35: 1-2 | I35: 1-3 | J35: 授業科目 | P35: 単位数 | Q35: 必須 | R35: 1-2 | S35: 1-3
B36: データサイエンス入門 | F36: 2 | G36: ○ | H36: ○ | I36: ○
A44: ⑥ 「様々なデータ利活用の現場におけるデータ利活用事例が示され、様々な適用領域（流通、製造、金融、サービス、インフラ、公共、ヘルスケア等）の知見と組み合わせることで価値を創出するもの」の内容を含む授業科目
B46: 授業科目 | F46: 単位数 | G46: 必須 | H46: 1-4 | I46: 1-5 | J46: 授業科目 | P46: 単位数 | Q46: 必須 | R46: 1-4 | S46: 1-5
B47: データサイエンス入門 | F47: 2 | G47: ○ | H47: ○ | I47: ○
A55: ⑦ 「活用に当たっての様々な留意事項（ELSI、個人情報、データ倫理、ＡＩ社会原則等）を考慮し、情報セキュリティや情報漏洩等、データを守る上での留意事項への理解をする」の内容を含む授業科目
B57: 授業科目 | F57: 単位数 | G57: 必須 | H57: 3-1 | I57: 3-2 | J57: 授業科目 | P57: 単位数 | Q57: 必須 | R57: 3-1 | S57: 3-2
B58: データサイエンス入門 | F58: 2 | G58: ○ | H58: ○ | I58: ○
A66: ⑧ 「実データ・実課題（学術データ等を含む）を用いた演習など、社会での実例を題材として、「データを読む、説明する、扱う」といった数理・データサイエンス・ＡＩの基本的な活用法に関するもの」の内容を含む授業科目
B68: 授業科目 | E68: 単位数 | F68: 必須 | G68: 2-1 | H68: 2-2 | I68: 2-3 | J68: 授業科目 | O68: 単位数 | P68: 必須 | Q68: 2-1 | R68: 2-2 | S68: 2-3
B69: データサイエンス入門 | E69: 2 | F69: ○ | G69: ○ | H69: ○ | I69: ○
A77: ⑨ 選択「４．オプション」の内容を含む授業科目
B78: 授業科目 | F78: 選択項目 | J78: 授業科目 | P78: 選択項目
B79: データサイエンス入門 | F79: 4-1統計および数理基礎
A87: ⑩ プログラムを構成する授業の内容
B88: 授業に含まれている内容・要素 | D88: 講義内容
B89: （１）現在進行中の社会変化（第４次産業革命、Society 5.0、データ駆動型社会等）に深く寄与しているものであり、それが自らの生活と密接に結びついている | C89: 1-1 | D89: 情報通信技術や計算機能力の飛躍的な向上によってビッグデータやAIの利用が身近なものとなり、我々を取り巻く環境はデータ駆動型社会へとシフトしてきている。このような社会の変化について、データ駆動型社会によって実現されてきた様々な事例を通じて、データサイエンスの重要性について理解し、データサイエンスの体系の概要について学習する。 キーワード：ビッグデータ、IoT、 AI、ロボット、データ量の増加、計算機の処理性能の向上、AIの非連続的進化、データ駆動型社会、複数技術を組み合わせた AIサービス 『データサイエンス入門』(第3回）「社会で起きている変化」
C90: 1-6 | D90: 情報通信技術や計算機能力の飛躍的な向上によってビッグデータやAIの利用が身近なものとなり、我々を取り巻く環境はデータ駆動型社会へとシフトしてきている。このような社会の変化について、データ駆動型社会によって実現されてきた様々な事例を通じて、データサイエンスの重要性について理解し、データサイエンスの体系の概要について学習する。 キーワード：AI等を活用した新しいビジネスモデル、AI最新技術の活用例 『データサイエンス入門』 （第4回）「データ・AI利活用の最新動向」 （第5回）「データ・AI利活用の現場」
B91: （２）「社会で活用されているデータ」や「データの活用領域」は非常に広範囲であって、日常生活や社会の課題を解決する有用なツールになり得るもの | C91: 1-2 | D91: データ駆動型社会で対象とされるのは調査データや実験データのみに留まらず、画像や音声情報といった身近な情報も対象となり活用されていることを取り上げ、実社会では多様なデータが大量に収集・蓄積されており、文系・理系を問わず様々な分野で専門分野の知見と数理・データサイエンスを掛け合わせることにより、研究の推進やその分野の課題解決がなされていることを学習する。 キーワード：調査データ、実験データ、人の行動ログデータ、機械の稼働ログデータなど 『データサイエンス入門』（第4回）「データ・AI利活用の最新動向」
C92: 1-3 | D92: データ駆動型社会で対象とされるのは調査データや実験データのみに留まらず、画像や音声 情報といった身近な情報も対象となり活用されていることを取り上げ、実社会では多様なデータが大量に収集・蓄積されており、文系・理系を問わず様々な分野で専門分野の知見と数理・データサイエンスを掛け合わせることにより、研究の推進やその分野の課題解決がなされていることを学習する。 キーワード：流通、製造、金融、サービス、インフラ、公共、ヘルスケア等におけるデータ・ AI利活用事例紹介，データ・ AI活用領域の広がり 『データサイエンス入門』 （第4回）「データ・AI利活用の最新動向」 （第5回）「データ・AI利活用の現場」
B93: （３）様々なデータ利活用の現場におけるデータ利活用事例が示され、様々な適用領域（流通、製造、金融、サービス、インフラ、公共、ヘルスケア等）の知見と組み合わせることで価値を創出するもの | C93: 1-4 | D93: 実社会における数理・データサイエンス・AIの適用事例を題材に、回帰や分類などの手法によってどのような情報が得られ、どのような価値を創出しているかを紹介する。また授業で学習する回帰や分類といった分析手法が活用されている実例を学生に調査させ、そこではどのようなデータから、どのような情報を引き出し、どのように価値が見出されたかを報告させる。 キーワード：データ解析 『データサイエンス入門』（第5回）「データ・AI利活用の現場」
C94: 1-5 | D94: 実社会における数理・データサイエンス・AIの適用事例を題材に、回帰や分類などの手法によってどのような情報が得られ、どのような価値を創出しているかを紹介する。また授業で学習する回帰や分類といった分析手法が活用されている実例を学生に調査させ、そこではどのようなデータから、どのような情報を引き出し、どのように価値が見出されたかを報告させる。 キーワード：データサイエンスのサイクル 『データサイエンス入門』（第4回）「データ・AI利活用の最新動向」
B95: （４）活用に当たっての様々な留意事項（ELSI、個人情報、データ倫理、ＡＩ社会原則等）を考慮し、情報セキュリティや情報漏洩等、データを守る上での留意事項への理解をする | C95: 3-1 | D95: 個人情報や著作権の保護・ELSIなどの法的・倫理的側面などを学習し、データおよびそれに付随した情報技術を扱う上での留意事項を学ぶ。また、情報漏洩等によるセキュリティ事故の事例およびそのようなリスクを回避するための情報セキュリティ技術について学ぶ。 キーワード：ELSI（ Ethical, Legal and Social Issues）、個人情報保護、データ倫理：データのねつ造、改ざん、盗用、プライバシー保護 『データサイエンス入門』（第6回）「コンプライアンスと情報倫理」
C96: 3-2 | D96: 個人情報や著作権の保護・ELSIなどの法的・倫理的側面などを学習し、データおよびそれに付随した情報技術を扱う上での留意事項を学ぶ。また、情報漏洩等によるセキュリティ事故の事例およびそのようなリスクを回避するための情報セキュリティ技術について学ぶ。 キーワード：情報セキュリティ、匿名加工情報，暗号化、パスワード、悪意ある情報搾取、情報漏洩等によるセキュリティ事故の事例紹介 『データサイエンス入門』（第7回）「サイバー防犯と情報セキュリティ」
...

Sheet 様式１ー５（環境人間学部）
R1: 様式１－５ | T1: 「学部・学科によって、修了要件は相違する」場合は、本シートを複製の上＜様式１－〇＞と枝番号を付してください
B2: 大学等名 | C2: 兵庫県立大学
B3: プログラム名 | C3: 数理・データサイエンス・AI教育プログラム
A5: プログラムを構成する授業科目について
A7: ① 対象となる学部・学科名称 | J7: ② 教育プログラムの修了要件 | K7: 学部・学科によって、修了要件は相違する
B9: 環境人間学部
A12: ③ 修了要件
B13: 「データサイエンス入門」2単位を修得すること。 | V13: 【プルダウンリスト】
V14: 令和４年度以前より、履修することが必須のプログラムとして実施
V15: 令和７年度までに履修必須とする計画
V16: 令和８年度以降に履修必須とする計画、又は未定
B20: 必要最低単位数 | C20: 2 | E20: 単位 | J20: 履修必須の有無 | K20: 令和４年度以前より、履修することが必須のプログラムとして実施
A22: ④ 現在進行中の社会変化（第４次産業革命、Society 5.0、データ駆動型社会等）に深く寄与しているものであり、それが自らの生活と密接に結びついている」の内容を含む授業科目
B24: 授業科目 | F24: 単位数 | G24: 必須 | H24: 1-1 | I24: 1-6 | J24: 授業科目 | P24: 単位数 | Q24: 必須 | R24: 1-1 | S24: 1-6
B25: データサイエンス入門 | F25: 2 | G25: ○ | H25: ○ | I25: ○
A33: ⑤ 「社会で活用されているデータ」や「データの活用領域」は非常に広範囲であって、日常生活や社会の課題を解決する有用なツールになり得るもの」の内容を含む授業科目
B35: 授業科目 | F35: 単位数 | G35: 必須 | H35: 1-2 | I35: 1-3 | J35: 授業科目 | P35: 単位数 | Q35: 必須 | R35: 1-2 | S35: 1-3
B36: データサイエンス入門 | F36: 2 | G36: ○ | H36: ○ | I36: ○
A44: ⑥ 「様々なデータ利活用の現場におけるデータ利活用事例が示され、様々な適用領域（流通、製造、金融、サービス、インフラ、公共、ヘルスケア等）の知見と組み合わせることで価値を創出するもの」の内容を含む授業科目
B46: 授業科目 | F46: 単位数 | G46: 必須 | H46: 1-4 | I46: 1-5 | J46: 授業科目 | P46: 単位数 | Q46: 必須 | R46: 1-4 | S46: 1-5
B47: データサイエンス入門 | F47: 2 | G47: ○ | H47: ○ | I47: ○
A55: ⑦ 「活用に当たっての様々な留意事項（ELSI、個人情報、データ倫理、ＡＩ社会原則等）を考慮し、情報セキュリティや情報漏洩等、データを守る上での留意事項への理解をする」の内容を含む授業科目
B57: 授業科目 | F57: 単位数 | G57: 必須 | H57: 3-1 | I57: 3-2 | J57: 授業科目 | P57: 単位数 | Q57: 必須 | R57: 3-1 | S57: 3-2
B58: データサイエンス入門 | F58: 2 | G58: ○ | H58: ○ | I58: ○
A66: ⑧ 「実データ・実課題（学術データ等を含む）を用いた演習など、社会での実例を題材として、「データを読む、説明する、扱う」といった数理・データサイエンス・ＡＩの基本的な活用法に関するもの」の内容を含む授業科目
B68: 授業科目 | E68: 単位数 | F68: 必須 | G68: 2-1 | H68: 2-2 | I68: 2-3 | J68: 授業科目 | O68: 単位数 | P68: 必須 | Q68: 2-1 | R68: 2-2 | S68: 2-3
B69: データサイエンス入門 | E69: 2 | F69: ○ | G69: ○ | H69: ○ | I69: ○
A77: ⑨ 選択「４．オプション」の内容を含む授業科目
B78: 授業科目 | F78: 選択項目 | J78: 授業科目 | P78: 選択項目
A87: ⑩ プログラムを構成する授業の内容
B88: 授業に含まれている内容・要素 | D88: 講義内容
B89: （１）現在進行中の社会変化（第４次産業革命、Society 5.0、データ駆動型社会等）に深く寄与しているものであり、それが自らの生活と密接に結びついている | C89: 1-1 | D89: 社会で起きていることを知ると共に、数理・データサイエンス・AIについての基礎を学ぶ意義を理解する キーワード：ビッグデータ、IoT、 AI、ロボット 『データサイエンス入門』 （第1回）「イントロダクション」 （第2回 ）「現代社会におけるデータサイエンス（１）社会で活用されているデータ」
C90: 1-6 | D90: データ・AI利活用について最新動向を知る キーワード：AI等を活用した新しいビジネスモデル、AI最新技術の活用例 『データサイエンス入門』 （第3回）「現代社会におけるデータサイエンス（２）データ・AIの活用領域、データサイエンスの応用事例」
B91: （２）「社会で活用されているデータ」や「データの活用領域」は非常に広範囲であって、日常生活や社会の課題を解決する有用なツールになり得るもの | C91: 1-2 | D91: データの種類や活用方法について、理解する キーワード：調査データ、実験データなど 『データサイエンス入門』 （第2回 ）「現代社会におけるデータサイエンス（１）社会で活用されているデータ」
C92: 1-3 | D92: 社会におけるデータサイエンスやAIの活用について理解する キーワード：データ・ AI活用領域の広がり 『データサイエンス入門』 （第2回）「現代社会におけるデータサイエンス（１）社会で活用されているデータ」 （第3回）「現代社会におけるデータサイエンス（２）データ・AIの活用領域、データサイエンスの応用事例」
B93: （３）様々なデータ利活用の現場におけるデータ利活用事例が示され、様々な適用領域（流通、製造、金融、サービス、インフラ、公共、ヘルスケア等）の知見と組み合わせることで価値を創出するもの | C93: 1-4 | D93: データサイエンスやAIの技術概要を理解する キーワード：データ解析 『データサイエンス入門』 （第3回）「現代社会におけるデータサイエンス（２）データ・AIの活用領域、データサイエンスの応用事例」
C94: 1-5 | D94: データの価値を高めるデータサイエンスやAIの活用を理解する キーワード：データサイエンスのサイクル 『データサイエンス入門』 （第2回）「現代社会におけるデータサイエンス（１）社会で活用されているデータ」 （第3回）「現代社会におけるデータサイエンス（２）データ・AIの活用領域、データサイエンスの応用事例」
B95: （４）活用に当たっての様々な留意事項（ELSI、個人情報、データ倫理、ＡＩ社会原則等）を考慮し、情報セキュリティや情報漏洩等、データを守る上での留意事項への理解をする | C95: 3-1 | D95: データやAIを扱う際の注意事項を理解する キーワード：個人情報保護、データ倫理：データのねつ造、改ざん、盗用、プライバシー保護 『データサイエンス入門』 （第4回）「情報倫理、情報セキュリティ」
C96: 3-2 | D96: データを取り扱い上で知っておくべきことを理解する キーワード：情報セキュリティ、匿名加工情報，暗号化、パスワード、悪意ある情報搾取、情報漏洩等によるセキュリティ事故の事例紹介 『データサイエンス入門』 （第4回）「情報倫理、情報セキュリティ」
B97: （５）実データ・実課題（学術データ等を含む）を用いた演習など、社会での実例を題材として、「データを読む、説明する、扱う」といった数理・データサイエンス・ＡＩの基本的な活用法に関するもの | C97: 2-1 | D97: データを読む力を身につける キーワード：データの種類、データの分布と代表値、データのばらつき 『データサイエンス入門』 （第5回～第10回）「データ分析の基礎 （データの可視化、データの種類・分布、データの代表値・ばらつき、相関・回帰直線、調査・クロス集計、データの比較）」
...

Sheet 様式１ー６（看護学部）
R1: 様式１－６ | T1: 「学部・学科によって、修了要件は相違する」場合は、本シートを複製の上＜様式１－〇＞と枝番号を付してください
B2: 大学等名 | C2: 兵庫県立大学
B3: プログラム名 | C3: 数理・データサイエンス・AI教育プログラム
A5: プログラムを構成する授業科目について
A7: ① 対象となる学部・学科名称 | J7: ② 教育プログラムの修了要件 | K7: 学部・学科によって、修了要件は相違する
B9: 看護学部
A12: ③ 修了要件
B13: 「データサイエンス入門」2単位を修得すること。 | V13: 【プルダウンリスト】
V14: 令和４年度以前より、履修することが必須のプログラムとして実施
V15: 令和７年度までに履修必須とする計画
V16: 令和８年度以降に履修必須とする計画、又は未定
B20: 必要最低単位数 | C20: 2 | E20: 単位 | J20: 履修必須の有無 | K20: 令和４年度以前より、履修することが必須のプログラムとして実施
A22: ④ 現在進行中の社会変化（第４次産業革命、Society 5.0、データ駆動型社会等）に深く寄与しているものであり、それが自らの生活と密接に結びついている」の内容を含む授業科目
B24: 授業科目 | F24: 単位数 | G24: 必須 | H24: 1-1 | I24: 1-6 | J24: 授業科目 | P24: 単位数 | Q24: 必須 | R24: 1-1 | S24: 1-6
B25: データサイエンス入門 | F25: 2 | G25: ○ | H25: ○ | I25: ○
A33: ⑤ 「社会で活用されているデータ」や「データの活用領域」は非常に広範囲であって、日常生活や社会の課題を解決する有用なツールになり得るもの」の内容を含む授業科目
B35: 授業科目 | F35: 単位数 | G35: 必須 | H35: 1-2 | I35: 1-3 | J35: 授業科目 | P35: 単位数 | Q35: 必須 | R35: 1-2 | S35: 1-3
B36: データサイエンス入門 | F36: 2 | G36: ○ | H36: ○ | I36: ○
A44: ⑥ 「様々なデータ利活用の現場におけるデータ利活用事例が示され、様々な適用領域（流通、製造、金融、サービス、インフラ、公共、ヘルスケア等）の知見と組み合わせることで価値を創出するもの」の内容を含む授業科目
B46: 授業科目 | F46: 単位数 | G46: 必須 | H46: 1-4 | I46: 1-5 | J46: 授業科目 | P46: 単位数 | Q46: 必須 | R46: 1-4 | S46: 1-5
B47: データサイエンス入門 | F47: 2 | G47: ○ | H47: ○ | I47: ○
A55: ⑦ 「活用に当たっての様々な留意事項（ELSI、個人情報、データ倫理、ＡＩ社会原則等）を考慮し、情報セキュリティや情報漏洩等、データを守る上での留意事項への理解をする」の内容を含む授業科目
B57: 授業科目 | F57: 単位数 | G57: 必須 | H57: 3-1 | I57: 3-2 | J57: 授業科目 | P57: 単位数 | Q57: 必須 | R57: 3-1 | S57: 3-2
B58: データサイエンス入門 | F58: 2 | G58: ○ | H58: ○ | I58: ○
A66: ⑧ 「実データ・実課題（学術データ等を含む）を用いた演習など、社会での実例を題材として、「データを読む、説明する、扱う」といった数理・データサイエンス・ＡＩの基本的な活用法に関するもの」の内容を含む授業科目
B68: 授業科目 | E68: 単位数 | F68: 必須 | G68: 2-1 | H68: 2-2 | I68: 2-3 | J68: 授業科目 | O68: 単位数 | P68: 必須 | Q68: 2-1 | R68: 2-2 | S68: 2-3
B69: データサイエンス入門 | E69: 2 | F69: ○ | G69: ○ | H69: ○ | I69: ○
A77: ⑨ 選択「４．オプション」の内容を含む授業科目
B78: 授業科目 | F78: 選択項目 | J78: 授業科目 | P78: 選択項目
A87: ⑩ プログラムを構成する授業の内容
B88: 授業に含まれている内容・要素 | D88: 講義内容
B89: （１）現在進行中の社会変化（第４次産業革命、Society 5.0、データ駆動型社会等）に深く寄与しているものであり、それが自らの生活と密接に結びついている | C89: 1-1 | D89: 社会で起きている変化を理解し、人間の知的活動とAIの関係性について学ぶ。 キーワード：ビッグデータ、IoT、 AI、ロボット 『データサイエンス入門』 （第3回）社会の変化とAIの活用事例 最新のAIを体験 （第8回）人の特性と医療過誤 機械と人の協働 人の特性のまとめ: 視覚の盲点
C90: 1-6 | D90: データ・AI利活用の最新動向を知り、AI等を活用した新しいビジネスモデルの事例について学ぶ。 キーワード：AI等を活用した新しいビジネスモデル、AI最新技術の活用例 『データサイエンス入門』 （第3回）社会の変化とAIの活用事例 最新のAIを体験
B91: （２）「社会で活用されているデータ」や「データの活用領域」は非常に広範囲であって、日常生活や社会の課題を解決する有用なツールになり得るもの | C91: 1-2 | D91: 社会で活用されているデータの種類と、利用可能なデータの入手、活用について学ぶ。 キーワード：調査データ、実験データなど 『データサイエンス入門』 （第4回）ビッグデータ・オープンデータの活用1 データの可視化 グラフの種類と使い分け 出生率、医療費、医療施設などの可視化 （第5回）ビッグデータ・オープンデータの活用2 将来予測 回帰分析 医療費、年金、日本の人口の将来の予測・推計と擬似相関
C92: 1-3 | D92: データ・AIの活用領域について、知識発見、原因究明、判断支援などの事例について学ぶ。 キーワード：データ・ AI活用領域の広がり 『データサイエンス入門』 （第3回）社会の変化とAIの活用事例 最新のAIを体験
B93: （３）様々なデータ利活用の現場におけるデータ利活用事例が示され、様々な適用領域（流通、製造、金融、サービス、インフラ、公共、ヘルスケア等）の知見と組み合わせることで価値を創出するもの | C93: 1-4 | D93: データ・AI利活用のための技術について、機械学習を体験しながらAIで出来ることと出来ないことを学ぶ。 キーワード：データ解析 『データサイエンス入門』 （第5回）ビッグデータ・オープンデータの活用2 将来予測 回帰分析 医療費、年金、日本の人口の将来の予測・推計と擬似相関 （第9回）AIを育てる 手書き図形の認識 AIの原理、AIにできること・できないこと(強いAI・弱いAI)、AIをだます・偏見、シンギュラリティ （第10回）AIによるデータ分析・予測 変数の種類、欠損データ 教師あり学習で心臓発作を予測、AIのブラックボックス問題 （第11回）AIによるデータ分類(クラスタリング) 教師なし学習 手書き図形の認識、変数の種類、欠損データ 教師なし学習で心臓発作を予測 （第12回）AIによる物体認識応用1 部屋にいる人数・密集度の判定 データ作成、アノテーション・タグ付け、クリエイティブコモンズ、画像の引用 （第13回）AIによる物体認識応用2 マスク装着割合を判定 独自AIの作成
C94: 1-5 | D94: データ・AI利活用の現場として、ヘルスケア等におけるデータの活用事例などを学ぶ。 キーワード：データサイエンスのサイクル 『データサイエンス入門』 （第8回）人の特性と医療過誤 機械と人の協働 人の特性のまとめ: 視覚の盲点 （第10回）AIによるデータ分析・予測 変数の種類、欠損データ 教師あり学習で心臓発作を予測、AIのブラックボックス問題 （第11回）AIによるデータ分類(クラスタリング) 教師なし学習 手書き図形の認識、変数の種類、欠損データ 教師なし学習で心臓発作を予測 （第13回）AIによる物体認識応用2 マスク装着割合を判定 独自AIの作成
B95: （４）活用に当たっての様々な留意事項（ELSI、個人情報、データ倫理、ＡＩ社会原則等）を考慮し、情報セキュリティや情報漏洩等、データを守る上での留意事項への理解をする | C95: 3-1 | D95: データ・AIを扱う上での留意事項として、個人情報保護、データバイアス、負の事例などを学ぶ。 キーワード：個人情報保護、データ倫理：データのねつ造、改ざん、盗用、プライバシー保護 『データサイエンス入門』 （第1回）情報機器の扱い （第2回）コンピュータ・リテラシー phishing、ポリシー、私的利用、著作権について考える （第14回）データを守る1 エッジとクラウド、情報収集、プラットフォーマーと連絡先、音声入力・文書解析と情報漏えい他
C96: 3-2 | D96: データを守る上での留意事項として、情報セキュリティ、悪意ある情報搾取、セキュリティ事故の事例などを学ぶ。 キーワード：情報セキュリティ、匿名加工情報，暗号化、パスワード、悪意ある情報搾取、情報漏洩等によるセキュリティ事故の事例紹介 『データサイエンス入門』 （第12回）AIによる物体認識応用1 部屋にいる人数・密集度の判定 データ作成、アノテーション・タグ付け、クリエイティブコモンズ、画像の引用 （第13回）AIによる物体認識応用2 マスク装着割合を判定 独自AIの作成 （第14回）データを守る1 エッジとクラウド、情報収集、プラットフォーマーと連絡先、音声入力・文書解析と情報漏えい他 （第15回）データを守る2 看護業務の中の個人情報保護 第3者の定義、災害時の扱いについて考える
B97: （５）実データ・実課題（学術データ等を含む）を用いた演習など、社会での実例を題材として、「データを読む、説明する、扱う」といった数理・データサイエンス・ＡＩの基本的な活用法に関するもの | C97: 2-1 | D97: データを読むために分かりやすく記述する統計について学ぶ。 キーワード：データの種類、データの分布と代表値 『データサイエンス入門』 （第5回）ビッグデータ・オープンデータの活用2 将来予測 回帰分析 医療費、年金、日本の人口の将来の予測・推計と擬似相関 （第6回）データの収集・分析1 代表値、散布度 平均、最大、最小、標準偏差、人の特性: 短期記憶の容量測定・データのクリーニング
...

Sheet 様式２ 履修者等数の実績
AQ1: 様式２
AL2: 大学等名 | AM2: ='様式１ー２（社会情報科学部）'!C2 -> 兵庫県立大学
A3: プログラムの履修者数等の実績について
A5: ①プログラム開設年度 | C5: 4 | E5: 年度
A7: ②履修者・修了者の実績
B9: 学部・学科名称 | C9: 学生数 | D9: 入学 定員 | E9: 収容 定員 | F9: 令和4年度 | L9: 令和3年度 | R9: 令和2年度 | X9: 令和元年度 | AD9: 平成30年度 | AJ9: 平成29年度 | AP9: 履修者数 合計 | AQ9: 履修率
F10: 履修者数 | I10: 修了者数 | L10: 履修者数 | O10: 修了者数 | R10: 履修者数 | U10: 修了者数 | X10: 履修者数 | AA10: 修了者数 | AD10: 履修者数 | AG10: 修了者数 | AJ10: 履修者数 | AM10: 修了者数
F11: 合計 | G11: 男性 | H11: 女性 | I11: 合計 | J11: 男性 | K11: 女性 | L11: 合計 | M11: 男性 | N11: 女性 | O11: 合計 | P11: 男性 | Q11: 女性 | R11: 合計 | S11: 男性 | T11: 女性 | U11: 合計 | V11: 男性 | W11: 女性 | X11: 合計 | Y11: 男性 | Z11: 女性 | AA11: 合計 | AB11: 男性 | AC11: 女性 | AD11: 合計 | AE11: 男性 | AF11: 女性 | AG11: 合計 | AH11: 男性 | AI11: 女性 | AJ11: 合計 | AK11: 男性 | AL11: 女性 | AM11: 合計 | AN11: 男性 | AO11: 女性
B12: 国際商経学部 | C12: 1498 | D12: 360 | E12: 1440 | F12: 364 | I12: 351 | L12: =M12+N12 -> 0 | O12: =P12+Q12 -> 0 | R12: =S12+T12 -> 0 | U12: =V12+W12 -> 0 | X12: =Y12+Z12 -> 0 | AA12: =AB12+AC12 -> 0 | AD12: =AE12+AF12 -> 0 | AG12: =AH12+AI12 -> 0 | AJ12: =AK12+AL12 -> 0 | AM12: =AN12+AO12 -> 0 | AP12: =F12+L12+R12+X12+AD12+AJ12 -> 364 | AQ12: =AP12/E12 -> 0.25277778
B13: 社会情報科学部 | C13: 400 | D13: 100 | E13: 400 | F13: 101 | I13: 0 | L13: =M13+N13 -> 0 | O13: =P13+Q13 -> 0 | R13: =S13+T13 -> 0 | U13: =V13+W13 -> 0 | X13: =Y13+Z13 -> 0 | AA13: =AB13+AC13 -> 0 | AD13: =AE13+AF13 -> 0 | AG13: =AH13+AI13 -> 0 | AJ13: =AK13+AL13 -> 0 | AM13: =AN13+AO13 -> 0 | AP13: =F13+L13+R13+X13+AD13+AJ13 -> 101 | AQ13: =AP13/E13 -> 0.2525
B14: 工学部 | C14: 1509 | D14: 352 | E14: 1408 | F14: 360 | I14: =J14+K14 -> 0 | L14: =M14+N14 -> 0 | O14: =P14+Q14 -> 0 | R14: =S14+T14 -> 0 | U14: =V14+W14 -> 0 | X14: =Y14+Z14 -> 0 | AA14: =AB14+AC14 -> 0 | AD14: =AE14+AF14 -> 0 | AG14: =AH14+AI14 -> 0 | AJ14: =AK14+AL14 -> 0 | AM14: =AN14+AO14 -> 0 | AP14: =F14+L14+R14+X14+AD14+AJ14 -> 360 | AQ14: =AP14/E14 -> 0.25568182
B15: 理学部 | C15: 725 | D15: 175 | E15: 700 | F15: 179 | I15: 178 | L15: =M15+N15 -> 0 | O15: =P15+Q15 -> 0 | R15: =S15+T15 -> 0 | U15: =V15+W15 -> 0 | X15: =Y15+Z15 -> 0 | AA15: =AB15+AC15 -> 0 | AD15: =AE15+AF15 -> 0 | AG15: =AH15+AI15 -> 0 | AJ15: =AK15+AL15 -> 0 | AM15: =AN15+AO15 -> 0 | AP15: =F15+L15+R15+X15+AD15+AJ15 -> 179 | AQ15: =AP15/E15 -> 0.25571429
B16: 環境人間学部 | C16: 854 | D16: 205 | E16: 820 | F16: 206 | I16: 203 | L16: =M16+N16 -> 0 | O16: =P16+Q16 -> 0 | R16: =S16+T16 -> 0 | U16: =V16+W16 -> 0 | X16: =Y16+Z16 -> 0 | AA16: =AB16+AC16 -> 0 | AD16: =AE16+AF16 -> 0 | AG16: =AH16+AI16 -> 0 | AJ16: =AK16+AL16 -> 0 | AM16: =AN16+AO16 -> 0 | AP16: =F16+L16+R16+X16+AD16+AJ16 -> 206 | AQ16: =AP16/E16 -> 0.25121951
B17: 看護学部 | C17: 426 | D17: 105 | E17: 420 | F17: 106 | I17: 106 | L17: =M17+N17 -> 0 | O17: =P17+Q17 -> 0 | R17: =S17+T17 -> 0 | U17: =V17+W17 -> 0 | X17: =Y17+Z17 -> 0 | AA17: =AB17+AC17 -> 0 | AD17: =AE17+AF17 -> 0 | AG17: =AH17+AI17 -> 0 | AJ17: =AK17+AL17 -> 0 | AM17: =AN17+AO17 -> 0 | AP17: =F17+L17+R17+X17+AD17+AJ17 -> 106 | AQ17: =AP17/E17 -> 0.25238095
F18: =G18+H18 -> 0 | I18: =J18+K18 -> 0 | L18: =M18+N18 -> 0 | O18: =P18+Q18 -> 0 | R18: =S18+T18 -> 0 | U18: =V18+W18 -> 0 | X18: =Y18+Z18 -> 0 | AA18: =AB18+AC18 -> 0 | AD18: =AE18+AF18 -> 0 | AG18: =AH18+AI18 -> 0 | AJ18: =AK18+AL18 -> 0 | AM18: =AN18+AO18 -> 0 | AP18: =F18+L18+R18+X18+AD18+AJ18 -> 0 | AQ18: =AP18/E18 -> #DIV/0!
F19: =G19+H19 -> 0 | I19: =J19+K19 -> 0 | L19: =M19+N19 -> 0 | O19: =P19+Q19 -> 0 | R19: =S19+T19 -> 0 | U19: =V19+W19 -> 0 | X19: =Y19+Z19 -> 0 | AA19: =AB19+AC19 -> 0 | AD19: =AE19+AF19 -> 0 | AG19: =AH19+AI19 -> 0 | AJ19: =AK19+AL19 -> 0 | AM19: =AN19+AO19 -> 0 | AP19: =F19+L19+R19+X19+AD19+AJ19 -> 0 | AQ19: =AP19/E19 -> #DIV/0!
F20: =G20+H20 -> 0 | I20: =J20+K20 -> 0 | L20: =M20+N20 -> 0 | O20: =P20+Q20 -> 0 | R20: =S20+T20 -> 0 | U20: =V20+W20 -> 0 | X20: =Y20+Z20 -> 0 | AA20: =AB20+AC20 -> 0 | AD20: =AE20+AF20 -> 0 | AG20: =AH20+AI20 -> 0 | AJ20: =AK20+AL20 -> 0 | AM20: =AN20+AO20 -> 0 | AP20: =F20+L20+R20+X20+AD20+AJ20 -> 0 | AQ20: =AP20/E20 -> #DIV/0!
F21: =G21+H21 -> 0 | I21: =J21+K21 -> 0 | L21: =M21+N21 -> 0 | O21: =P21+Q21 -> 0 | R21: =S21+T21 -> 0 | U21: =V21+W21 -> 0 | X21: =Y21+Z21 -> 0 | AA21: =AB21+AC21 -> 0 | AD21: =AE21+AF21 -> 0 | AG21: =AH21+AI21 -> 0 | AJ21: =AK21+AL21 -> 0 | AM21: =AN21+AO21 -> 0 | AP21: =F21+L21+R21+X21+AD21+AJ21 -> 0 | AQ21: =AP21/E21 -> #DIV/0!
F22: =G22+H22 -> 0 | I22: =J22+K22 -> 0 | L22: =M22+N22 -> 0 | O22: =P22+Q22 -> 0 | R22: =S22+T22 -> 0 | U22: =V22+W22 -> 0 | X22: =Y22+Z22 -> 0 | AA22: =AB22+AC22 -> 0 | AD22: =AE22+AF22 -> 0 | AG22: =AH22+AI22 -> 0 | AJ22: =AK22+AL22 -> 0 | AM22: =AN22+AO22 -> 0 | AP22: =F22+L22+R22+X22+AD22+AJ22 -> 0 | AQ22: =AP22/E22 -> #DIV/0!
F23: =G23+H23 -> 0 | I23: =J23+K23 -> 0 | L23: =M23+N23 -> 0 | O23: =P23+Q23 -> 0 | R23: =S23+T23 -> 0 | U23: =V23+W23 -> 0 | X23: =Y23+Z23 -> 0 | AA23: =AB23+AC23 -> 0 | AD23: =AE23+AF23 -> 0 | AG23: =AH23+AI23 -> 0 | AJ23: =AK23+AL23 -> 0 | AM23: =AN23+AO23 -> 0 | AP23: =F23+L23+R23+X23+AD23+AJ23 -> 0 | AQ23: =AP23/E23 -> #DIV/0!
F24: =G24+H24 -> 0 | I24: =J24+K24 -> 0 | L24: =M24+N24 -> 0 | O24: =P24+Q24 -> 0 | R24: =S24+T24 -> 0 | U24: =V24+W24 -> 0 | X24: =Y24+Z24 -> 0 | AA24: =AB24+AC24 -> 0 | AD24: =AE24+AF24 -> 0 | AG24: =AH24+AI24 -> 0 | AJ24: =AK24+AL24 -> 0 | AM24: =AN24+AO24 -> 0 | AP24: =F24+L24+R24+X24+AD24+AJ24 -> 0 | AQ24: =AP24/E24 -> #DIV/0!
F25: =G25+H25 -> 0 | I25: =J25+K25 -> 0 | L25: =M25+N25 -> 0 | O25: =P25+Q25 -> 0 | R25: =S25+T25 -> 0 | U25: =V25+W25 -> 0 | X25: =Y25+Z25 -> 0 | AA25: =AB25+AC25 -> 0 | AD25: =AE25+AF25 -> 0 | AG25: =AH25+AI25 -> 0 | AJ25: =AK25+AL25 -> 0 | AM25: =AN25+AO25 -> 0 | AP25: =F25+L25+R25+X25+AD25+AJ25 -> 0 | AQ25: =AP25/E25 -> #DIV/0!
F26: =G26+H26 -> 0 | I26: =J26+K26 -> 0 | L26: =M26+N26 -> 0 | O26: =P26+Q26 -> 0 | R26: =S26+T26 -> 0 | U26: =V26+W26 -> 0 | X26: =Y26+Z26 -> 0 | AA26: =AB26+AC26 -> 0 | AD26: =AE26+AF26 -> 0 | AG26: =AH26+AI26 -> 0 | AJ26: =AK26+AL26 -> 0 | AM26: =AN26+AO26 -> 0 | AP26: =F26+L26+R26+X26+AD26+AJ26 -> 0 | AQ26: =AP26/E26 -> #DIV/0!
F27: =G27+H27 -> 0 | I27: =J27+K27 -> 0 | L27: =M27+N27 -> 0 | O27: =P27+Q27 -> 0 | R27: =S27+T27 -> 0 | U27: =V27+W27 -> 0 | X27: =Y27+Z27 -> 0 | AA27: =AB27+AC27 -> 0 | AD27: =AE27+AF27 -> 0 | AG27: =AH27+AI27 -> 0 | AJ27: =AK27+AL27 -> 0 | AM27: =AN27+AO27 -> 0 | AP27: =F27+L27+R27+X27+AD27+AJ27 -> 0 | AQ27: =AP27/E27 -> #DIV/0!
F28: =G28+H28 -> 0 | I28: =J28+K28 -> 0 | L28: =M28+N28 -> 0 | O28: =P28+Q28 -> 0 | R28: =S28+T28 -> 0 | U28: =V28+W28 -> 0 | X28: =Y28+Z28 -> 0 | AA28: =AB28+AC28 -> 0 | AD28: =AE28+AF28 -> 0 | AG28: =AH28+AI28 -> 0 | AJ28: =AK28+AL28 -> 0 | AM28: =AN28+AO28 -> 0 | AP28: =F28+L28+R28+X28+AD28+AJ28 -> 0 | AQ28: =AP28/E28 -> #DIV/0!
F29: =G29+H29 -> 0 | I29: =J29+K29 -> 0 | L29: =M29+N29 -> 0 | O29: =P29+Q29 -> 0 | R29: =S29+T29 -> 0 | U29: =V29+W29 -> 0 | X29: =Y29+Z29 -> 0 | AA29: =AB29+AC29 -> 0 | AD29: =AE29+AF29 -> 0 | AG29: =AH29+AI29 -> 0 | AJ29: =AK29+AL29 -> 0 | AM29: =AN29+AO29 -> 0 | AP29: =F29+L29+R29+X29+AD29+AJ29 -> 0 | AQ29: =AP29/E29 -> #DIV/0!
... F31: =G31+H31 -> 0 | I31: =J31+K31 -> 0 | L31: =M31+N31 -> 0 | O31: =P31+Q31 -> 0 | R31: =S31+T31 -> 0 | U31: =V31+W31 -> 0 | X31: =Y31+Z31 -> 0 | AA31: =AB31+AC31 -> 0 | AD31: =AE31+AF31 -> 0 | AG31: =AH31+AI31 -> 0 | AJ31: =AK31+AL31 -> 0 | AM31: =AN31+AO31 -> 0 | AP31: =F31+L31+R31+X31+AD31+AJ31 -> 0 | AQ31: =AP31/E31 -> #DIV/0!
B32: 合 計 | C32: =SUM(C12:C31) -> 5412 | D32: =SUM(D12:D31) -> 1297 | E32: =SUM(E12:E31) -> 5188 | F32: =SUM(F12:F31) -> 1316 | G32: =SUM(G12:G31) -> 0 | H32: =SUM(H12:H31) -> 0 | I32: =SUM(I12:I31) -> 838 | J32: =SUM(J12:J31) -> 0 | ... AP32: =SUM(AP12:AP31) -> 1316 | AQ32: =AP32/E32 -> 0.2536623

Sheet 様式３ 教育の質・履修者数を向上させるための体制・計画
I1: 様式３
G2: 大学等名 | H2: ='様式１ー２（社会情報科学部）'!C2 -> 兵庫県立大学
A4: 教育の質・履修者数を向上させるための体制・計画について
A6: ① | B6: 全学の教員数 | C6: (常勤） | E6: 519 | F6: 人 | G6: （非常勤） | H6: 323 | I6: 人
A8: ② | B8: プログラムの授業を教えている教員数 | H8: 48 | I8: 人
A10: ③ | B10: プログラムの運営責任者
B11: （責任者名） | C11: 高坂 誠 | G11: （役職名） | H11: 理事・副学長
A13: ④ | B13: プログラムを改善・進化させるための体制（委員会・組織等）
B14: 教養教育改編委員会 情報部会
B16: （責任者名） | C16: 高坂 誠 | G16: （役職名） | H16: 理事・副学長・部会長
A18: ⑤ | B18: プログラムを改善・進化させるための体制を定める規則名称
B19: 教養教育改編委員会 設置要綱
A21: ⑥ | B21: 体制の目的
B22: 数理・データサイエンス・AI教育プログラムの編成、運営および質の向上について審議する。
A34: ⑦ | B34: 具体的な構成員
B35: 教養教育改編委員会 情報部会 副学長（教育担当） 教授 高坂 誠 副学長（教育担当サブ） 教授 樋口芳樹 社会情報科学部 教授 笹嶋宗彦 国際商経学部 教授 兒山真也 工学部 教授 佐藤孝雄 看護学部 教授 片山貴文 理学部 助教 西川幸志 環境人間学部 講師 木村敏文
A48: ⑧ | B48: 履修者数・履修率の向上に向けた計画 ※様式１の「履修必須の有無」で「計画がある」としている場合は詳細について記載すること
B49: 令和４年度実績 | C49: ='様式２ 履修者等数の実績'!AQ32 -> 0.2536623 | E49: 令和５年度予定 | F49: 0.5 | H49: 令和６年度予定 | I49: 0.75
B50: 令和７年度予定 | C50: 1 | E50: 令和８年度予定 | F50: 1 | H50: 収容定員（名） | I50: ='様式２ 履修者等数の実績'!E32 -> 5188
B51: 具体的な計画
B52: （国際商経学部、社会情報科学部、理学部、環境人間学部、看護学部） プログラム対象科目は、いずれの学部においても必修科目であり、全学生が履修する。 また、全学共通教育で提供されるデータサイエンス関連科目についてさらなる周知を図る。 年度進行に伴い当プログラムの履修率は100％となる。 （工学部） プログラム対象科目は、学科に関係なく工学部学生全員が受講可能な体制が整っている。
A65: ⑨ | B65: 学部・学科に関係なく希望する学生全員が受講可能となるような必要な体制・取組等
B66: プログラム対象科目は、学部・学科に関係なく学生全員が受講できる体制が整っている。 学部ごとに受講可能な講義が設定されているため、数理・データサイエンス・AIに関係する講義を受講する学生は全員受講することが可能である。
A79: ⑩ | B79: できる限り多くの学生が履修できるような具体的な周知方法・取組
B80: 新入生ガイダンスで説明を行うとともに、大学ホームページや学習支援システムを通じてプログラムの紹介を行い、データサイエンスの重要性について学生に理解させる。
A93: ⑪ | B93: できる限り多くの学生が履修・修得できるようなサポート体制
B94: プログラムのコア科目を1年生の必修科目としている学部はもちろん、必修に設定していない工学部を含め、入学時の各学部のオリエンテーション時に、きめの細かい履修登録指導がなされている。学生ポータルシステム(UNIVERSAL PASSPORT)等 を利用して授業時間外でも質問ができるようにしている。 また、TA（ティーチング・アシスタント）、SA（スチューデント・アシスタント）を配置しており、担当教員と連携して学生の理解度向上のためのサポートにあたっている。
A107: ⑫ | B107: 授業時間内外で学習指導、質問を受け付ける具体的な仕組み
B108: プログラム担当教員がオフィスアワーを設け、学生から質問や相談を受けている。 オフィスアワーについては、授業の初回に担当教員より説明を行っている。 授業時間外でも学生ポータルシステム(UNIVERSAL PASSPORT)の質問機能やメールなどによる質問を常に受け付けている。 また、TA・SAを活用した質問対応の仕組みを構築することで、授業時間内外での学生の学びを促す取り組みを行っている。

Sheet 様式４　自己点検・評価
I1: 様式４
H2: 大学等名 | I2: ='様式１ー２（社会情報科学部）'!C2 -> 兵庫県立大学
A3: 自己点検・評価について
A5: ① | B5: プログラムの自己点検・評価を行う体制（委員会・組織等）
B6: 教養教育改編委員会 情報部会
D8: （責任者名） | E8: 高坂 誠 | G8: （役職名） | H8: 理事・副学長・部会長
A10: ② | B10: 自己点検・評価体制における意見等
B11: 自己点検・評価の視点 | E11: 自己点検・評価体制における意見・結果・改善に向けた取組等
B12: 学内からの視点
C13: プログラムの履修・修得状況 | E13: 当該科目の取組状況や学習状況は学生ポータルシステム(UNIVERSAL PASSPORT)上に集約され、学務課や担当教員は学生ポータルシステムに記録された学修状況から受講者ごとの講義への取組状況を把握することができる。
C14: 学修成果 | E14: 各科目ごとの履修率、単位修得率、成績分布は教務管理システム(GAKUEN)により確認することができる。 また、科目ごとに実施される授業アンケートにより、学生自身の自己評価、学生の理解度や授業の内容や進度についての意見を集めるようにしている。これらの結果を分析することで、当該科目の今後の教育内容の改善に活用する。 さらに、複数教員が担当している科目では、教員間で情報共有することにより、受講生の学修状況を把握し、次の回の講義で活用している。
C15: 学生アンケート等を通じた学生の内容の理解度 | E15: 科目ごとに実施される授業アンケートにより，学生自身の自己評価，学生の理解度や授業の内容や進度についての意見を分析することができる。 アンケートによると、授業の理解度については、おおむね理解し能力が向上したとの回答を得られた。 分析結果をもとに当該科目の今後の教育内容改善に活用する。
C16: 学生アンケート等を通じた後輩等他の学生への推奨度 | E16: 本プログラムの受講者に対して、「データサイエンスの必要性や重要性についてどのように考えるか」というアンケートを実施しているが、多数の学生がデータサイエンスの必要性・重要性を理解した、と回答している。 また、データを扱う技術やAIへの興味にもつながり、今後の大学での研究に役立つことを学べたと回答している。後輩等他の学生への推奨度に向上にもつながるものと期待できる。
C17: 全学的な履修者数、履修率向上に向けた計画の達成・進捗状況 | E17: 工学部以外では、令和4年度に新たなプログラムを開始したが、必修科目としており、令和4年度入学者全員が履修している。年次進行に伴い履修率は100％となる予定である。 また、工学部における本プログラムは全学生が履修可能である。2年次の配当科目は選択科目が含まれているためガイダンスを通じて履修を促す。
B18: 学外からの視点
C19: 教育プログラム修了者の進路、活躍状況、企業等の評価 | E19: 令和４年度末時点でカリキュラム修了者が輩出されておらず、現時点では評価することができない。修了者が輩出され次第、その就職先等への調査を行い、企業からの評価や修了者の活躍状況を調査することとしている。
C20: 産業界からの視点を含めた教育プログラム内容・手法等への意見 | E20: 産業界で使われているデータの取り扱いやAIの技術紹介を講義で行うことにより、産業界の視点を取り入れることが期待できる。 すでに、社会情報科学部では、リテラシーレベルから実践に軸足を置いているため、産業界からも、演習科目の見学希望や講義そのものを担当したい等の申し出を受けている。また実際に、実データの前処理に関する講義や、企業での最新事例を交えた倫理教育は、企業あるいは企業業務の経験者に担当して頂いている。
B21: 数理・データサイエンス・ＡＩを「学ぶ楽しさ」「学ぶことの意義」を理解させること | E21: データを扱うために基本的なことから講義を始め、実データの取り扱いやAI技術など、身近なデータの分析結果の利用方法を紹介することにより、数理・データサイエンス・AIに興味を持ってもらえるようにすると共に、学ぶ意義についても考え、理解する機会となるようにしている。
B22: 内容・水準を維持・向上しつつ、より「分かりやすい」授業とすること | E22: 学生による授業評価アンケートの意見や講義担当者からのフィードバックにより、分かりにくい部分を分析することで、講義内容、講義資料の改善に努める。 看護学部では、対面授業の中で分からない所がある場合には、追加で動画や資料を作成し、自宅から何度でも閲覧できるようにした。これによって、自分のペースで学習でき、理解できるように対応している。
