Workbook

Sheet 様式１-1　プログラムを構成する授業科目
R1: 様式１−１ | T1: 「学部・学科によって、修了要件は相違する」場合は、本シートを複製の上＜様式１－〇＞と枝番号を付してください
B2: 大学等名 | C2: 函館短期大学
B3: プログラム名 | C3: 栄養士・保育士のためのICT・数理・データサイエンス・AI教育プログラム
A5: プログラムを構成する授業科目について
A7: ① 対象となる学部・学科名称 | J7: ② 教育プログラムの修了要件 | K7: 学部・学科によって、修了要件は相違する
B9: 食物栄養学科
A12: ③ 修了要件
B13: プログラムを構成する「必修科目群（下記１〜５）」の5単位、「選択科目群（下記６〜８）」から１単位以上、合計６単位以上を取得すること。 必修科目群：１．情報機器の操作I（１単位）、２．情報機器の操作II（１単位）、３．給食管理実習I（1単位）、４．栄養指導実習I（１単位）５. データサイエンス入門（１単位） 選択科目群：６．コンピュータリテラシーW（1単位）、７．コンピュータリテラシーE（１単位）、８．コンピュータリテラシーP（１単位） | V13: 【プルダウンリスト】
V14: 令和４年度以前より、履修することが必須のプログラムとして実施
V15: 令和７年度までに履修必須とする計画
V16: 令和８年度以降に履修必須とする計画、又は未定
B20: 必要最低単位数 | C20: 6 | E20: 単位 | J20: 履修必須の有無 | K20: 令和７年度までに履修必須とする計画
A22: ④ 現在進行中の社会変化（第４次産業革命、Society 5.0、データ駆動型社会等）に深く寄与しているものであり、それが自らの生活と密接に結びついている」の内容を含む授業科目
B24: 授業科目 | F24: 単位数 | G24: 必須 | H24: 1-1 | I24: 1-6 | J24: 授業科目 | P24: 単位数 | Q24: 必須 | R24: 1-1 | S24: 1-6
B25: データサイエンス入門 | F25: 1 | G25: ○ | H25: ○ | I25: ○
B26: 情報機器の操作II | F26: 1 | G26: ○ | I26: ○
A33: ⑤ 「社会で活用されているデータ」や「データの活用領域」は非常に広範囲であって、日常生活や社会の課題を解決する有用なツールになり得るもの」の内容を含む授業科目
B35: 授業科目 | F35: 単位数 | G35: 必須 | H35: 1-2 | I35: 1-3 | J35: 授業科目 | P35: 単位数 | Q35: 必須 | R35: 1-2 | S35: 1-3
B36: データサイエンス入門 | F36: 1 | G36: ○ | H36: ○ | I36: ○
B37: 情報機器の操作II | F37: 1 | G37: ○ | I37: ○
B38: 栄養指導実習I | F38: 1 | G38: ○ | H38: ○ | I38: ○
A44: ⑥ 「様々なデータ利活用の現場におけるデータ利活用事例が示され、様々な適用領域（流通、製造、金融、サービス、インフラ、公共、ヘルスケア等）の知見と組み合わせることで価値を創出するもの」の内容を含む授業科目
B46: 授業科目 | F46: 単位数 | G46: 必須 | H46: 1-4 | I46: 1-5 | J46: 授業科目 | P46: 単位数 | Q46: 必須 | R46: 1-4 | S46: 1-5
B47: データサイエンス入門 | F47: 1 | G47: ○ | H47: ○ | I47: ○
B48: 情報機器の操作II | F48: 1 | G48: ○ | H48: ○ | I48: ○
B49: 栄養指導実習I | F49: 1 | G49: ○ | I49: ○
A55: ⑦ 「活用に当たっての様々な留意事項（ELSI、個人情報、データ倫理、ＡＩ社会原則等）を考慮し、情報セキュリティや情報漏洩等、データを守る上での留意事項への理解をする」の内容を含む授業科目
B57: 授業科目 | F57: 単位数 | G57: 必須 | H57: 3-1 | I57: 3-2 | J57: 授業科目 | P57: 単位数 | Q57: 必須 | R57: 3-1 | S57: 3-2
B58: データサイエンス入門 | F58: 1 | G58: ○ | H58: ○ | I58: ○
B59: 情報機器の操作IⅠ | F59: 1 | G59: ○ | H59: ○ | I59: ○
B60: 栄養指導実習I | F60: 1 | G60: ○ | H60: ○ | I60: ○
A66: ⑧ 「実データ・実課題（学術データ等を含む）を用いた演習など、社会での実例を題材として、「データを読む、説明する、扱う」といった数理・データサイエンス・ＡＩの基本的な活用法に関するもの」の内容を含む授業科目
B68: 授業科目 | E68: 単位数 | F68: 必須 | G68: 2-1 | H68: 2-2 | I68: 2-3 | J68: 授業科目 | O68: 単位数 | P68: 必須 | Q68: 2-1 | R68: 2-2 | S68: 2-3
B69: データサイエンス入門 | E69: 1 | F69: ○ | G69: ○ | H69: ○ | I69: ○ | J69: コンピュータリテラシーＰ | O69: 1 | R69: ○ | S69: ○
B70: 情報機器の操作Ⅰ | E70: 1 | F70: ○ | G70: ○ | H70: ○
B71: 情報機器の操作Ⅱ | E71: 1 | F71: ○ | I71: ○
B72: 栄養指導実習I | E72: 1 | F72: ○ | G72: ○ | H72: ○ | I72: ○
B73: 給食管理実習I | E73: 1 | F73: ○ | G73: ○ | I73: ○
B74: コンピュータリテラシーＷ | E74: 1 | H74: ○ | I74: ○
B75: コンピュータリテラシーＥ | E75: 1 | G75: ○ | H75: ○ | I75: ○
...

Sheet 様式１-２　プログラムを構成する授業科目
R1: 様式１−２ | T1: 「学部・学科によって、修了要件は相違する」場合は、本シートを複製の上＜様式１－〇＞と枝番号を付してください
B2: 大学等名 | C2: 函館短期大学
B3: プログラム名 | C3: 栄養士・保育士のためのICT・数理・データサイエンス・AI教育プログラム
A5: プログラムを構成する授業科目について
A7: ① 対象となる学部・学科名称 | J7: ② 教育プログラムの修了要件 | K7: 学部・学科によって、修了要件は相違する
B9: 保育学科
A12: ③ 修了要件
B13: プログラムを構成する「必修科目群（下記１〜４）」の5単位、「選択科目群（下記５〜７）」から１単位以上、合計６単位以上を取得すること。 必修科目群：１．情報機器の操作I（１単位）、２．情報機器の操作II（１単位）、３．保育・教職実践演習（２単位）、４. データサイエンス入門（１単位） 選択科目群：5．コンピュータリテラシーW（1単位）、6．コンピュータリテラシーE（１単位）、7．コンピュータリテラシーP（１単位） | V13: 【プルダウンリスト】
V14: 令和４年度以前より、履修することが必須のプログラムとして実施
V15: 令和７年度までに履修必須とする計画
V16: 令和８年度以降に履修必須とする計画、又は未定
B20: 必要最低単位数 | C20: 6 | E20: 単位 | J20: 履修必須の有無 | K20: 令和７年度までに履修必須とする計画
A22: ④ 現在進行中の社会変化（第４次産業革命、Society 5.0、データ駆動型社会等）に深く寄与しているものであり、それが自らの生活と密接に結びついている」の内容を含む授業科目
B24: 授業科目 | F24: 単位数 | G24: 必須 | H24: 1-1 | I24: 1-6 | J24: 授業科目 | P24: 単位数 | Q24: 必須 | R24: 1-1 | S24: 1-6
B25: データサイエンス入門 | F25: 1 | G25: ○ | H25: ○ | I25: ○
B26: 情報機器の操作II | F26: 1 | G26: ○ | I26: ○
B27: 保育・教職実践演習 | F27: 2 | G27: ○ | H27: ○ | I27: ○
A33: ⑤ 「社会で活用されているデータ」や「データの活用領域」は非常に広範囲であって、日常生活や社会の課題を解決する有用なツールになり得るもの」の内容を含む授業科目
B35: 授業科目 | F35: 単位数 | G35: 必須 | H35: 1-2 | I35: 1-3 | J35: 授業科目 | P35: 単位数 | Q35: 必須 | R35: 1-2 | S35: 1-3
B36: データサイエンス入門 | F36: 1 | G36: ○ | H36: ○ | I36: ○
B37: 情報機器の操作II | F37: 1 | G37: ○ | I37: ○
A44: ⑥ 「様々なデータ利活用の現場におけるデータ利活用事例が示され、様々な適用領域（流通、製造、金融、サービス、インフラ、公共、ヘルスケア等）の知見と組み合わせることで価値を創出するもの」の内容を含む授業科目
B46: 授業科目 | F46: 単位数 | G46: 必須 | H46: 1-4 | I46: 1-5 | J46: 授業科目 | P46: 単位数 | Q46: 必須 | R46: 1-4 | S46: 1-5
B47: データサイエンス入門 | F47: 1 | G47: ○ | H47: ○ | I47: ○
B48: 情報機器の操作II | F48: 1 | G48: ○ | H48: ○ | I48: ○
B49: 保育・教職実践演習 | F49: 2 | G49: ○ | H49: ○ | I49: ○
A55: ⑦ 「活用に当たっての様々な留意事項（ELSI、個人情報、データ倫理、ＡＩ社会原則等）を考慮し、情報セキュリティや情報漏洩等、データを守る上での留意事項への理解をする」の内容を含む授業科目
B57: 授業科目 | F57: 単位数 | G57: 必須 | H57: 3-1 | I57: 3-2 | J57: 授業科目 | P57: 単位数 | Q57: 必須 | R57: 3-1 | S57: 3-2
B58: データサイエンス入門 | F58: 1 | G58: ○ | H58: ○ | I58: ○
B59: 情報機器の操作I | F59: 1 | G59: ○ | H59: ○ | I59: ○
B60: 情報機器の操作II | F60: 1 | G60: ○ | H60: ○ | I60: ○
B61: 保育・教職実践演習 | F61: 2 | G61: ○ | H61: ○ | I61: ○
A66: ⑧ 「実データ・実課題（学術データ等を含む）を用いた演習など、社会での実例を題材として、「データを読む、説明する、扱う」といった数理・データサイエンス・ＡＩの基本的な活用法に関するもの」の内容を含む授業科目
B68: 授業科目 | E68: 単位数 | F68: 必須 | G68: 2-1 | H68: 2-2 | I68: 2-3 | J68: 授業科目 | O68: 単位数 | P68: 必須 | Q68: 2-1 | R68: 2-2 | S68: 2-3
B69: データサイエンス入門 | E69: 1 | F69: ○ | G69: ○ | H69: ○ | I69: ○
B70: 情報機器の操作I | E70: 1 | F70: ○ | H70: ○
B71: 情報機器の操作II | E71: 1 | F71: ○ | I71: ○
B72: 保育・教職実践演習 | E72: 2 | F72: ○ | I72: ○
B73: コンピュータリテラシーW | E73: 1 | H73: ○ | I73: ○
B74: コンピュータリテラシーE | E74: 1 | G74: ○ | H74: ○ | I74: ○
...

Sheet 様式２ 履修者等数の実績
AQ1: 様式２
AL2: 大学等名 | AM2: ='様式１-1 プログラムを構成する授業科目'!C2 -> 函館短期大学
A3: プログラムの履修者数等の実績について
A5: ①プログラム開設年度 | C5: 4 | E5: 年度
A7: ②履修者・修了者の実績
B9: 学部・学科名称 | C9: 学生数 | D9: 入学 定員 | E9: 収容 定員 | F9: 令和4年度 | L9: 令和3年度 | R9: 令和2年度 | X9: 令和元年度 | AD9: 平成30年度 | AJ9: 平成29年度 | AP9: 履修者数 合計 | AQ9: 履修率
F10: 履修者数 | I10: 修了者数 | L10: 履修者数 | O10: 修了者数 | R10: 履修者数 | U10: 修了者数 | X10: 履修者数 | AA10: 修了者数 | AD10: 履修者数 | AG10: 修了者数 | AJ10: 履修者数 | AM10: 修了者数
F11: 合計 | G11: 男性 | H11: 女性 | I11: 合計 | J11: 男性 | K11: 女性 | L11: 合計 | M11: 男性 | N11: 女性 | O11: 合計 | P11: 男性 | Q11: 女性 | R11: 合計 | S11: 男性 | T11: 女性 | U11: 合計 | V11: 男性 | W11: 女性 | X11: 合計 | Y11: 男性 | Z11: 女性 | AA11: 合計 | AB11: 男性 | AC11: 女性 | AD11: 合計 | AE11: 男性 | AF11: 女性 | AG11: 合計 | AH11: 男性 | AI11: 女性 | AJ11: 合計 | AK11: 男性 | AL11: 女性 | AM11: 合計 | AN11: 男性 | AO11: 女性
B12: 食物栄養学科 | C12: 42 | D12: 60 | E12: 120 | F12: =G12+H12 -> 2 | G12: 0 | H12: 2 | I12: =J12+K12 -> 2 | J12: 0 | K12: 2 | L12: =M12+N12 -> 0 | O12: =P12+Q12 -> 0 | R12: =S12+T12 -> 0 | U12: =V12+W12 -> 0 | X12: =Y12+Z12 -> 0 | AA12: =AB12+AC12 -> 0 | AD12: =AE12+AF12 -> 0 | AG12: =AH12+AI12 -> 0 | AJ12: =AK12+AL12 -> 0 | AM12: =AN12+AO12 -> 0 | AP12: =F12+L12+R12+X12+AD12+AJ12 -> 2 | AQ12: =AP12/E12 -> 0.016666667
B13: 保育学科 | C13: 60 | D13: 60 | E13: 120 | F13: =G13+H13 -> 3 | G13: 0 | H13: 3 | I13: =J13+K13 -> 3 | J13: 0 | K13: 3 | L13: =M13+N13 -> 0 | O13: =P13+Q13 -> 0 | R13: =S13+T13 -> 0 | U13: =V13+W13 -> 0 | X13: =Y13+Z13 -> 0 | AA13: =AB13+AC13 -> 0 | AD13: =AE13+AF13 -> 0 | AG13: =AH13+AI13 -> 0 | AJ13: =AK13+AL13 -> 0 | AM13: =AN13+AO13 -> 0 | AP13: =F13+L13+R13+X13+AD13+AJ13 -> 3 | AQ13: =AP13/E13 -> 0.025
F14: =G14+H14 -> 0 | I14: =J14+K14 -> 0 | L14: =M14+N14 -> 0 | O14: =P14+Q14 -> 0 | R14: =S14+T14 -> 0 | U14: =V14+W14 -> 0 | X14: =Y14+Z14 -> 0 | AA14: =AB14+AC14 -> 0 | AD14: =AE14+AF14 -> 0 | AG14: =AH14+AI14 -> 0 | AJ14: =AK14+AL14 -> 0 | AM14: =AN14+AO14 -> 0 | AP14: =F14+L14+R14+X14+AD14+AJ14 -> 0 | AQ14: =AP14/E14 -> #DIV/0!
F15: =G15+H15 -> 0 | I15: =J15+K15 -> 0 | L15: =M15+N15 -> 0 | O15: =P15+Q15 -> 0 | R15: =S15+T15 -> 0 | U15: =V15+W15 -> 0 | X15: =Y15+Z15 -> 0 | AA15: =AB15+AC15 -> 0 | AD15: =AE15+AF15 -> 0 | AG15: =AH15+AI15 -> 0 | AJ15: =AK15+AL15 -> 0 | AM15: =AN15+AO15 -> 0 | AP15: =F15+L15+R15+X15+AD15+AJ15 -> 0 | AQ15: =AP15/E15 -> #DIV/0!
F16: =G16+H16 -> 0 | I16: =J16+K16 -> 0 | L16: =M16+N16 -> 0 | O16: =P16+Q16 -> 0 | R16: =S16+T16 -> 0 | U16: =V16+W16 -> 0 | X16: =Y16+Z16 -> 0 | AA16: =AB16+AC16 -> 0 | AD16: =AE16+AF16 -> 0 | AG16: =AH16+AI16 -> 0 | AJ16: =AK16+AL16 -> 0 | AM16: =AN16+AO16 -> 0 | AP16: =F16+L16+R16+X16+AD16+AJ16 -> 0 | AQ16: =AP16/E16 -> #DIV/0!
F17: =G17+H17 -> 0 | I17: =J17+K17 -> 0 | L17: =M17+N17 -> 0 | O17: =P17+Q17 -> 0 | R17: =S17+T17 -> 0 | U17: =V17+W17 -> 0 | X17: =Y17+Z17 -> 0 | AA17: =AB17+AC17 -> 0 | AD17: =AE17+AF17 -> 0 | AG17: =AH17+AI17 -> 0 | AJ17: =AK17+AL17 -> 0 | AM17: =AN17+AO17 -> 0 | AP17: =F17+L17+R17+X17+AD17+AJ17 -> 0 | AQ17: =AP17/E17 -> #DIV/0!
F18: =G18+H18 -> 0 | I18: =J18+K18 -> 0 | L18: =M18+N18 -> 0 | O18: =P18+Q18 -> 0 | R18: =S18+T18 -> 0 | U18: =V18+W18 -> 0 | X18: =Y18+Z18 -> 0 | AA18: =AB18+AC18 -> 0 | AD18: =AE18+AF18 -> 0 | AG18: =AH18+AI18 -> 0 | AJ18: =AK18+AL18 -> 0 | AM18: =AN18+AO18 -> 0 | AP18: =F18+L18+R18+X18+AD18+AJ18 -> 0 | AQ18: =AP18/E18 -> #DIV/0!
F19: =G19+H19 -> 0 | I19: =J19+K19 -> 0 | L19: =M19+N19 -> 0 | O19: =P19+Q19 -> 0 | R19: =S19+T19 -> 0 | U19: =V19+W19 -> 0 | X19: =Y19+Z19 -> 0 | AA19: =AB19+AC19 -> 0 | AD19: =AE19+AF19 -> 0 | AG19: =AH19+AI19 -> 0 | AJ19: =AK19+AL19 -> 0 | AM19: =AN19+AO19 -> 0 | AP19: =F19+L19+R19+X19+AD19+AJ19 -> 0 | AQ19: =AP19/E19 -> #DIV/0!
F20: =G20+H20 -> 0 | I20: =J20+K20 -> 0 | L20: =M20+N20 -> 0 | O20: =P20+Q20 -> 0 | R20: =S20+T20 -> 0 | U20: =V20+W20 -> 0 | X20: =Y20+Z20 -> 0 | AA20: =AB20+AC20 -> 0 | AD20: =AE20+AF20 -> 0 | AG20: =AH20+AI20 -> 0 | AJ20: =AK20+AL20 -> 0 | AM20: =AN20+AO20 -> 0 | AP20: =F20+L20+R20+X20+AD20+AJ20 -> 0 | AQ20: =AP20/E20 -> #DIV/0!
F21: =G21+H21 -> 0 | I21: =J21+K21 -> 0 | L21: =M21+N21 -> 0 | O21: =P21+Q21 -> 0 | R21: =S21+T21 -> 0 | U21: =V21+W21 -> 0 | X21: =Y21+Z21 -> 0 | AA21: =AB21+AC21 -> 0 | AD21: =AE21+AF21 -> 0 | AG21: =AH21+AI21 -> 0 | AJ21: =AK21+AL21 -> 0 | AM21: =AN21+AO21 -> 0 | AP21: =F21+L21+R21+X21+AD21+AJ21 -> 0 | AQ21: =AP21/E21 -> #DIV/0!
F22: =G22+H22 -> 0 | I22: =J22+K22 -> 0 | L22: =M22+N22 -> 0 | O22: =P22+Q22 -> 0 | R22: =S22+T22 -> 0 | U22: =V22+W22 -> 0 | X22: =Y22+Z22 -> 0 | AA22: =AB22+AC22 -> 0 | AD22: =AE22+AF22 -> 0 | AG22: =AH22+AI22 -> 0 | AJ22: =AK22+AL22 -> 0 | AM22: =AN22+AO22 -> 0 | AP22: =F22+L22+R22+X22+AD22+AJ22 -> 0 | AQ22: =AP22/E22 -> #DIV/0!
F23: =G23+H23 -> 0 | I23: =J23+K23 -> 0 | L23: =M23+N23 -> 0 | O23: =P23+Q23 -> 0 | R23: =S23+T23 -> 0 | U23: =V23+W23 -> 0 | X23: =Y23+Z23 -> 0 | AA23: =AB23+AC23 -> 0 | AD23: =AE23+AF23 -> 0 | AG23: =AH23+AI23 -> 0 | AJ23: =AK23+AL23 -> 0 | AM23: =AN23+AO23 -> 0 | AP23: =F23+L23+R23+X23+AD23+AJ23 -> 0 | AQ23: =AP23/E23 -> #DIV/0!
F24: =G24+H24 -> 0 | I24: =J24+K24 -> 0 | L24: =M24+N24 -> 0 | O24: =P24+Q24 -> 0 | R24: =S24+T24 -> 0 | U24: =V24+W24 -> 0 | X24: =Y24+Z24 -> 0 | AA24: =AB24+AC24 -> 0 | AD24: =AE24+AF24 -> 0 | AG24: =AH24+AI24 -> 0 | AJ24: =AK24+AL24 -> 0 | AM24: =AN24+AO24 -> 0 | AP24: =F24+L24+R24+X24+AD24+AJ24 -> 0 | AQ24: =AP24/E24 -> #DIV/0!
F25: =G25+H25 -> 0 | I25: =J25+K25 -> 0 | L25: =M25+N25 -> 0 | O25: =P25+Q25 -> 0 | R25: =S25+T25 -> 0 | U25: =V25+W25 -> 0 | X25: =Y25+Z25 -> 0 | AA25: =AB25+AC25 -> 0 | AD25: =AE25+AF25 -> 0 | AG25: =AH25+AI25 -> 0 | AJ25: =AK25+AL25 -> 0 | AM25: =AN25+AO25 -> 0 | AP25: =F25+L25+R25+X25+AD25+AJ25 -> 0 | AQ25: =AP25/E25 -> #DIV/0!
... F31: =G31+H31 -> 0 | I31: =J31+K31 -> 0 | L31: =M31+N31 -> 0 | O31: =P31+Q31 -> 0 | R31: =S31+T31 -> 0 | U31: =V31+W31 -> 0 | X31: =Y31+Z31 -> 0 | AA31: =AB31+AC31 -> 0 | AD31: =AE31+AF31 -> 0 | AG31: =AH31+AI31 -> 0 | AJ31: =AK31+AL31 -> 0 | AM31: =AN31+AO31 -> 0 | AP31: =F31+L31+R31+X31+AD31+AJ31 -> 0 | AQ31: =AP31/E31 -> #DIV/0!
B32: 合 計 | C32: =SUM(C12:C31) -> 102 | D32: =SUM(D12:D31) -> 120 | E32: =SUM(E12:E31) -> 240 | F32: =SUM(F12:F31) -> 5 | G32: =SUM(G12:G31) -> 0 | H32: =SUM(H12:H31) -> 5 | I32: =SUM(I12:I31) -> 5 | J32: =SUM(J12:J31) -> 0 | ... AP32: =SUM(AP12:AP31) -> 5 | AQ32: =AP32/E32 -> 0.020833333

Sheet 様式３ 教育の質・履修者数を向上させるための体制・計画
I1: 様式３
G2: 大学等名 | H2: ='様式１-1 プログラムを構成する授業科目'!C2 -> 函館短期大学
A4: 教育の質・履修者数を向上させるための体制・計画について
A6: ① | B6: 全学の教員数 | C6: (常勤） | E6: 16 | F6: 人 | G6: （非常勤） | H6: 53 | I6: 人
A8: ② | B8: プログラムの授業を教えている教員数 | H8: 9 | I8: 人
A10: ③ | B10: プログラムの運営責任者
B11: （責任者名） | C11: 澤辺 桃子 | G11: （役職名） | H11: 学長
A13: ④ | B13: プログラムを改善・進化させるための体制（委員会・組織等）
B14: 教務委員会
B16: （責任者名） | C16: 鈴木 英悟 | G16: （役職名） | H16: 教授
A18: ⑤ | B18: プログラムを改善・進化させるための体制を定める規則名称
B19: 函館短期大学 栄養士・保育士のためのICT・数理・データサイエンス・AI教育プログラム規程
A21: ⑥ | B21: 体制の目的
B22: 「数理・データサイエンス・AI教育プログラム認定制度」に基づいて「函館短期大学 栄養士・保育士のためのICT・数理・データサイエンス・AI教育プログラム規程」を整備した。教務委員会が主たる役割を担い、函館短期大学に栄養士・保育士のためのICT・数理・データサイエンス・AI教育プログラムを設置し、デジタル社会の「読み・書き・そろばん」であるICT・数理・データサイエンス・AIの基礎的素養を持つ人材を育成することを目的とする。教務委員会の構成員による作業チームとして、データサイエンスワーキンググループを作り、プログラムの改善・進化に努める。
A34: ⑦ | B34: 具体的な構成員
B35: 教務委員会 教務委員長：教授 鈴木英悟（食物栄養学科） 教務副委員長：学長 澤辺桃子、准教授 白府士孝（保育学科） 委員：専任教員7名、事務局6名 教務委員会 データサイエンスWG（ワーキンググループ） 食物栄養学科 教授 鈴木英悟 教務委員長 食物栄養学科 専任講師 梅影創 委員（WG座長） 保育学科 専任講師 野呂祐人 委員（WG副座長） 保育学科 教授 白幡俊人 委員 食物栄養学科 助教 伊木亜子 委員 事務局 事務局長 林原和哉 委員 事務局 入試広報課長 山川達也 委員
A48: ⑧ | B48: 履修者数・履修率の向上に向けた計画 ※様式１の「履修必須の有無」で「計画がある」としている場合は詳細について記載すること
B49: 令和４年度実績 | C49: ='様式２ 履修者等数の実績'!AQ32 -> 0.020833333 | E49: 令和５年度予定 | F49: 0.2 | H49: 令和６年度予定 | I49: 0.5
B50: 令和７年度予定 | C50: 1 | E50: 令和８年度予定 | F50: 1 | H50: 収容定員（名） | I50: ='様式２ 履修者等数の実績'!E32 -> 240
B51: 具体的な計画
B52: 令和４年度では、本プログラムの運用を開始し、授業アンケートによる講義内容の改善を実施した。 令和５年度では、本プログラム内容をSNS等さまざまな手段で周知し、さらに、履修登録前に本プログラムの全学説明を実施し、履修者増を目指す。また、授業アンケーをもとに、学生が本プログラム関連科目を履修しやすい時間割を検討する。 令和６年度では、本プログラム修了生の就職先を中心としたヒアリングを行い、現場のニーズを捉えた教育プログラムの充実化を実施する。また、本プログラム必修科目である「データサイエンス入門」の卒業必修科目化のための学則等の変更を実施する。 令和７−８年度では、本プログラム修了生の就職先を中心としたヒアリングを引き続き実施し、現場のニーズを捉えた教育プログラムの充実化を図るとともに、本プログラム選択科目必修化を進め、履修率100%を達成する。
A65: ⑨ | B65: 学部・学科に関係なく希望する学生全員が受講可能となるような必要な体制・取組等
B66: 本学のプログラムでは、食物栄養学科および保育学科の共通科目に全学共通科目である「情報機器の操作I」、「情報機器の操作II」、「データサイエンス入門」をプログラム必修科目として設置しており、学科に関係なく本プログラムを希望する者に対してプログラムを受講できるようにしている。また、本プログラム選択科目である「コンピュータリテラシーW」、「コンピュータリテラシーE」、「コンピュータリテラシーP」においても共通科目として、全学生が等しく本プログラムを受講できるよう設計されている。
A79: ⑩ | B79: できる限り多くの学生が履修できるような具体的な周知方法・取組
B80: 本教育プログラムに関する説明を入学時全体オリエンテーションで行っている。また、プログラム内容に関する説明資料を学生一人一人に配布するとともに、学生用掲示板にもプログラム案内ポスターを設置し学生周知に努めている。また、学生の履修登録作業には教員および教務担当事務員が立ち会い、プログラム受講を迷っている学生への補足説明などを実施し、できる限り多くの学生が取得できるようなサポート体制を敷いている。さらに、夏季休暇明けの後期授業前オリエンテーションにおいても再度本教育プログラムの説明を実施し、学期途中からの追加履修登録を促している。
A93: ⑪ | B93: できる限り多くの学生が履修・修得できるようなサポート体制
B94: 一部の講義についてアーカイブ化した講義の視聴を試験的に実施した。本プログラムを希望する学生がいつでも講義を受講できるよう、講義のオンデマンド化について検討していく。
A107: ⑫ | B107: 授業時間内外で学習指導、質問を受け付ける具体的な仕組み
B108: 学内専用の講義等連絡システム（Campusmate-J）を学生及び教員が常時利用できるようになっている。また、担当教員と対面でのコンタクトを取るための各種情報（オフィスアワー、研究室、メールアドレス、内線番号）を学生に周知している。

Sheet 様式４　自己点検・評価
I1: 様式４
H2: 大学等名 | I2: ='様式１-1 プログラムを構成する授業科目'!C2 -> 函館短期大学
A3: 自己点検・評価について
A5: ① | B5: プログラムの自己点検・評価を行う体制（委員会・組織等）
B6: 自己点検・評価委員会
D8: （責任者名） | E8: 澤辺 桃子 | G8: （役職名） | H8: 学長
A10: ② | B10: 自己点検・評価体制における意見等
B11: 自己点検・評価の視点 | E11: 自己点検・評価体制における意見・結果・改善に向けた取組等
B12: 学内からの視点
C13: プログラムの履修・修得状況 | E13: 本学内のオンライン上の教務システムである「Campusmate-J」を利用することで、学生の出欠、履修状況、レポート等の課題提出状況などを随時取得することができるようになっている。 また、本プログラム開始初年では、必修科目である「データサイエンス入門」および選択科目である「コンピューターリテラシーW/P/E」の履修者数が低い結果となった。これについては、学生の入学時点からの本プログラムに対する説明を十分に行うことができなかったことが主な原因と考えられるため、プログラムの必要性等を履修登録前に丁寧に説明する機会を設けることで対応している。
C14: 学修成果 | E14: 学生には小テスト、期末考査、課題等を課し、各講義科目で設定されるルーブリックにしたがって評価された結果に基づいて学修成果の把握を行っている。また、授業アンケートにおける「授業の内容に興味・関心を持つことができましたか」、「この授業は全体として満足できるものでしたか」の項目、および、自由意見記載欄のコメントをIR委員会が分析することで、評点には表れてこない学生の学修成果度を把握している。
C15: 学生アンケート等を通じた学生の内容の理解度 | E15: 授業アンケートにおける「教員の説明のしかたや話し方がわかりやすいものでしたか」、「授業の進めかた板書やスライドはみやすい（わかりやすい）ものでしたか」、「授業の内容に興味・関心を持つことができましたか」、「授業内容が理解しやすいようにくふうされていましたか」、「この授業は全体として満足できるものでしたか」の結果を基にして学生の内容理解度を把握するようになっている。
C16: 学生アンケート等を通じた後輩等他の学生への推奨度 | E16: プログラム受講者からは、「受けないのが勿体ない」、「エクセルパワポもデータサイエンスの3人の先生から教わりたいです」、「プログラミングに興味があったので、授業内容も楽しく意欲的に取り組むことができました。」「プログラミングやデータと聞くと難しいイメージで、実際むずかしかったのですが、それぞれの先生が噛み砕いて分かりやすく説明をしてくださったので、ためになる授業でした。」、などの肯定的なコメントが寄せられており、プログラム受講者の他学生への推奨度は高い結果が得られている。
C17: 全学的な履修者数、履修率向上に向けた計画の達成・進捗状況 | E17: 履修者増を目指した時間割、周知方法の改善を実施している。また、プログラム面での改善として、プログラム必修科目「データサイエンス入門」の全学生必修化のための学則等の見直しを検討している。さらに、履修率の増加を目指し、選択科目「コンピュータリテラシーP/E/W」の必修化を検討している。
B18: 学外からの視点
C19: 教育プログラム修了者の進路、活躍状況、企業等の評価 | E19: 本プログラムは令和４度が開始年度である。開始年度のプログラム修了者は５名で、進路の内訳は、保育士３名、栄養士１名、事務員１名となっている。修了者の全てが就業開始年度にあたるため、活躍状況や企業等の評価は得られていない。今後、本プログラム修了生の就業先へのヒヤリング等の実施を進めていく予定である。
C20: 産業界からの視点を含めた教育プログラム内容・手法等への意見 | E20: 栄養士、保育士の現場に即応できるようなプログラム内容となるよう、本プログラム修了生の就職先を筆頭とした関係各所から本プログラムに対する要望等を把握する準備を進めている。
B21: 数理・データサイエンス・ＡＩを「学ぶ楽しさ」「学ぶことの意義」を理解させること | E21: 本プログラムは、履修登録前のオリエンテーションにてプログラム担当教員からプログラムの修得がいかに有用であるか説明を受け、その重要性を理解した上でプログラム履修するように徹底されている。また、本プログラムは、将来の就業環境に即応するための実践力が備わるよう、演習中心の講義科目で構成され、各講義で設定された到達目標に向けて主体的に取り組めるよう配慮されている。また、食物栄養学科と保育学科で共通する科目については、所属する学科に違いで講義の理解度に差が生じないよう、初歩的な内容から講義が展開されていくよう配慮がなされている。本学の学生の満足度は5点満点中平均４以上であった。
B22: 内容・水準を維持・向上しつつ、より「分かりやすい」授業とすること | E22: 授業アンケートに講義の良かったところ、および改善点について自由記載できる項目を設けて学生からの要望を受け付け、授業改善に活かしている。また、演習課題を課して学生の理解度を把握し、授業内容の分かりやすさを評価する指標とする。さらに、分野の流行りすたりを考慮し、年度毎に講義内容の見直しを行い、講義内容の陳腐化を防ぐよう努めている。本プログラムに対する期待や要望については、外部（栄養士、保育士の職場）からのヒアリング結果を活かすための準備を進めている。
