Workbook

Sheet 様式１―１　プログラムを構成する授業科目
R1: 様式１―１ | T1: 「学部・学科によって、修了要件は相違する」場合は、本シートを複製の上＜様式１－〇＞と枝番号を付してください
B2: 大学等名 | C2: 北里大学
B3: プログラム名 | C3: 北里大学 数理・データサイエンス・AI教育プログラム
A5: プログラムを構成する授業科目について
A7: ① 対象となる学部・学科名称 | J7: ② 教育プログラムの修了要件 | K7: 学部・学科によって、修了要件は相違する
B9: 薬学部 薬学科、薬学部 生命創薬科学科、獣医学部 獣医学科、獣医学部 動物資源科学科、獣医学部 生物環境科学科、海洋生命科学部 海洋生命科学科、看護学部 看護学科、理学部 物理学科、理学部 化学科、理学部 生物科学科
A12: ③ 修了要件
B13: プログラムを構成する「教養演習Ｃ（データサイエンスとＡＩ）」を1単位を取得すること。 | V13: 【プルダウンリスト】
V14: 令和４年度以前より、履修することが必須のプログラムとして実施
V15: 令和７年度までに履修必須とする計画
V16: 令和８年度以降に履修必須とする計画、又は未定
B20: 必要最低単位数 | C20: 1 | E20: 単位 | J20: 履修必須の有無 | K20: 令和８年度以降に履修必須とする計画、又は未定
A22: ④ 現在進行中の社会変化（第４次産業革命、Society 5.0、データ駆動型社会等）に深く寄与しているものであり、それが自らの生活と密接に結びついている」の内容を含む授業科目
B24: 授業科目 | F24: 単位数 | G24: 必須 | H24: 1-1 | I24: 1-6 | J24: 授業科目 | P24: 単位数 | Q24: 必須 | R24: 1-1 | S24: 1-6
B25: 教養演習Ｃ（データサイエンスとＡＩ） | F25: 1 | G25: ○ | H25: ○ | I25: ○
A33: ⑤ 「社会で活用されているデータ」や「データの活用領域」は非常に広範囲であって、日常生活や社会の課題を解決する有用なツールになり得るもの」の内容を含む授業科目
B35: 授業科目 | F35: 単位数 | G35: 必須 | H35: 1-2 | I35: 1-3 | J35: 授業科目 | P35: 単位数 | Q35: 必須 | R35: 1-2 | S35: 1-3
B36: 教養演習Ｃ（データサイエンスとＡＩ） | F36: 1 | G36: ○ | H36: ○ | I36: ○
A44: ⑥ 「様々なデータ利活用の現場におけるデータ利活用事例が示され、様々な適用領域（流通、製造、金融、サービス、インフラ、公共、ヘルスケア等）の知見と組み合わせることで価値を創出するもの」の内容を含む授業科目
B46: 授業科目 | F46: 単位数 | G46: 必須 | H46: 1-4 | I46: 1-5 | J46: 授業科目 | P46: 単位数 | Q46: 必須 | R46: 1-4 | S46: 1-5
B47: 教養演習Ｃ（データサイエンスとＡＩ） | F47: 1 | G47: ○ | H47: ○ | I47: ○
A55: ⑦ 「活用に当たっての様々な留意事項（ELSI、個人情報、データ倫理、ＡＩ社会原則等）を考慮し、情報セキュリティや情報漏洩等、データを守る上での留意事項への理解をする」の内容を含む授業科目
B57: 授業科目 | F57: 単位数 | G57: 必須 | H57: 3-1 | I57: 3-2 | J57: 授業科目 | P57: 単位数 | Q57: 必須 | R57: 3-1 | S57: 3-2
B58: 教養演習Ｃ（データサイエンスとＡＩ） | F58: 1 | G58: ○ | H58: ○ | I58: ○
A66: ⑧ 「実データ・実課題（学術データ等を含む）を用いた演習など、社会での実例を題材として、「データを読む、説明する、扱う」といった数理・データサイエンス・ＡＩの基本的な活用法に関するもの」の内容を含む授業科目
B68: 授業科目 | E68: 単位数 | F68: 必須 | G68: 2-1 | H68: 2-2 | I68: 2-3 | J68: 授業科目 | O68: 単位数 | P68: 必須 | Q68: 2-1 | R68: 2-2 | S68: 2-3
B69: 教養演習Ｃ（データサイエンスとＡＩ） | E69: 1 | F69: ○ | G69: ○ | H69: ○ | I69: ○
A77: ⑨ 選択「４．オプション」の内容を含む授業科目
B78: 授業科目 | F78: 選択項目 | J78: 授業科目 | P78: 選択項目
A87: ⑩ プログラムを構成する授業の内容
B88: 授業に含まれている内容・要素 | D88: 講義内容
B89: （１）現在進行中の社会変化（第４次産業革命、Society 5.0、データ駆動型社会等）に深く寄与しているものであり、それが自らの生活と密接に結びついている | C89: 1-1 | D89: ・ビッグデータ、データマイニング「教養演習Ｃ」（第2回、第7回） ・ビッグデータが利用される要因となった技術の発展「教養演習Ｃ」（第2回）
C90: 1-6 | D90: ・社会で利用されているデータ（ビッグデータ）、POSの利用「教養演習Ｃ」（第2回） ・データの収集とIoT「教養演習Ｃ」（第2回、第13回） ・教師あり機械学習、教師なし機械学習、強化学習「教養演習Ｃ」（第11回）
B91: （２）「社会で活用されているデータ」や「データの活用領域」は非常に広範囲であって、日常生活や社会の課題を解決する有用なツールになり得るもの | C91: 1-2 | D91: ・社会で利用されているデータ、POSの利用（人の行動ログデータ）「教養演習Ｃ」（第2回） ・AIとは「教養演習Ｃ」（第10回）
C92: 1-3 | D92: ・Pythonによるデータ処理、Kaggle「教養演習Ｃ」（第6回、第7回） ・知能とは何か「教養演習Ｃ」（第10回、第14回） ・AI活用領域の広がり（ヘルスケア）「教養演習Ｃ」（第13回）
B93: （３）様々なデータ利活用の現場におけるデータ利活用事例が示され、様々な適用領域（流通、製造、金融、サービス、インフラ、公共、ヘルスケア等）の知見と組み合わせることで価値を創出するもの | C93: 1-4 | D93: ・AIとヘルスケア、エキスパートシステム「教養演習Ｃ」（第13回） ・データ解析/Pythonによるデータ処理「教養演習Ｃ」（第6回、第7回）
C94: 1-5 | D94: ・ビッグデータ、POSの利用（流通等におけるデータ・利活用事例紹介）「教養演習Ｃ」（第2回） ・新薬開発、健康の維持におけるAIの利用「教養演習Ｃ」（第13回）
B95: （４）活用に当たっての様々な留意事項（ELSI、個人情報、データ倫理、ＡＩ社会原則等）を考慮し、情報セキュリティや情報漏洩等、データを守る上での留意事項への理解をする | C95: 3-1 | D95: ・データ倫理：プライバシー保護「教養演習Ｃ」（第2回）
C96: 3-2 | D96: ・匿名加工情報「教養演習Ｃ」（第2回）
B97: （５）実データ・実課題（学術データ等を含む）を用いた演習など、社会での実例を題材として、「データを読む、説明する、扱う」といった数理・データサイエンス・ＡＩの基本的な活用法に関するもの | C97: 2-1 | D97: ・データリテラシ、データの種類（質的変数、量的変数）「教養演習Ｃ」（第2回） ・代表値とデータのばらつき「教養演習Ｃ」（第2回） ・FACTFULLNESS「教養演習Ｃ」（第2回、第7回） ・偽陰性と偽陽性、適合率と再現率「教養演習Ｃ」（第11回）
...

Sheet 様式１―２　プログラムを構成する授業科目
R1: 様式１―２ | T1: 「学部・学科によって、修了要件は相違する」場合は、本シートを複製の上＜様式１－〇＞と枝番号を付してください
B2: 大学等名 | C2: 北里大学
B3: プログラム名 | C3: 北里大学 数理・データサイエンス・AI教育プログラム
A5: プログラムを構成する授業科目について
A7: ① 対象となる学部・学科名称 | J7: ② 教育プログラムの修了要件 | K7: 学部・学科によって、修了要件は相違する
B9: 医学部 医学科
A12: ③ 修了要件
B13: プログラムを構成する「統計学Ａ」を4単位を取得すること。 | V13: 【プルダウンリスト】
V14: 令和４年度以前より、履修することが必須のプログラムとして実施
V15: 令和７年度までに履修必須とする計画
V16: 令和８年度以降に履修必須とする計画、又は未定
B20: 必要最低単位数 | C20: 4 | E20: 単位 | J20: 履修必須の有無 | K20: 令和４年度以前より、履修することが必須のプログラムとして実施
A22: ④ 現在進行中の社会変化（第４次産業革命、Society 5.0、データ駆動型社会等）に深く寄与しているものであり、それが自らの生活と密接に結びついている」の内容を含む授業科目
B24: 授業科目 | F24: 単位数 | G24: 必須 | H24: 1-1 | I24: 1-6 | J24: 授業科目 | P24: 単位数 | Q24: 必須 | R24: 1-1 | S24: 1-6
B25: 統計学Ａ | F25: 4 | G25: ○ | H25: ○ | I25: ○
A33: ⑤ 「社会で活用されているデータ」や「データの活用領域」は非常に広範囲であって、日常生活や社会の課題を解決する有用なツールになり得るもの」の内容を含む授業科目
B35: 授業科目 | F35: 単位数 | G35: 必須 | H35: 1-2 | I35: 1-3 | J35: 授業科目 | P35: 単位数 | Q35: 必須 | R35: 1-2 | S35: 1-3
B36: 統計学Ａ | F36: 4 | G36: ○ | H36: ○ | I36: ○
A44: ⑥ 「様々なデータ利活用の現場におけるデータ利活用事例が示され、様々な適用領域（流通、製造、金融、サービス、インフラ、公共、ヘルスケア等）の知見と組み合わせることで価値を創出するもの」の内容を含む授業科目
B46: 授業科目 | F46: 単位数 | G46: 必須 | H46: 1-4 | I46: 1-5 | J46: 授業科目 | P46: 単位数 | Q46: 必須 | R46: 1-4 | S46: 1-5
B47: 統計学Ａ | F47: 4 | G47: ○ | H47: ○ | I47: ○
A55: ⑦ 「活用に当たっての様々な留意事項（ELSI、個人情報、データ倫理、ＡＩ社会原則等）を考慮し、情報セキュリティや情報漏洩等、データを守る上での留意事項への理解をする」の内容を含む授業科目
B57: 授業科目 | F57: 単位数 | G57: 必須 | H57: 3-1 | I57: 3-2 | J57: 授業科目 | P57: 単位数 | Q57: 必須 | R57: 3-1 | S57: 3-2
B58: 統計学Ａ | F58: 4 | G58: ○ | H58: ○ | I58: ○
A66: ⑧ 「実データ・実課題（学術データ等を含む）を用いた演習など、社会での実例を題材として、「データを読む、説明する、扱う」といった数理・データサイエンス・ＡＩの基本的な活用法に関するもの」の内容を含む授業科目
B68: 授業科目 | E68: 単位数 | F68: 必須 | G68: 2-1 | H68: 2-2 | I68: 2-3 | J68: 授業科目 | O68: 単位数 | P68: 必須 | Q68: 2-1 | R68: 2-2 | S68: 2-3
B69: 統計学Ａ | E69: 4 | F69: ○ | G69: ○ | H69: ○ | I69: ○
A77: ⑨ 選択「４．オプション」の内容を含む授業科目
B78: 授業科目 | F78: 選択項目 | J78: 授業科目 | P78: 選択項目
A87: ⑩ プログラムを構成する授業の内容
B88: 授業に含まれている内容・要素 | D88: 講義内容
B89: （１）現在進行中の社会変化（第４次産業革命、Society 5.0、データ駆動型社会等）に深く寄与しているものであり、それが自らの生活と密接に結びついている | C89: 1-1 | D89: ・データ量の増加、計算機の処理性能の向上、AIの非連続的進化「統計学Ａ」（第1回） ・17世紀の天文学と現代との違い「統計学Ａ」（第1回）
C90: 1-6 | D90: ・数学・物理学・化学の学問別にみたデータやAI最新技術の活用例（深層生成モデル、敵対的生成ネットワーク、強化学習、転移学習など）「統計学Ａ」（第1回）
B91: （２）「社会で活用されているデータ」や「データの活用領域」は非常に広範囲であって、日常生活や社会の課題を解決する有用なツールになり得るもの | C91: 1-2 | D91: ・構造化データ、非構造化データ（文章、画像/動画、音声/音楽など）「統計学Ａ」（第1回）
C92: 1-3 | D92: ・データ・AI活用領域の広がり(生産、消費、文化活動など)の紹介「統計学Ａ」（第1回）
B93: （３）様々なデータ利活用の現場におけるデータ利活用事例が示され、様々な適用領域（流通、製造、金融、サービス、インフラ、公共、ヘルスケア等）の知見と組み合わせることで価値を創出するもの | C93: 1-4 | D93: ・言語処理、画像/動画処理、音声/音楽処理などの非構造化データ処理の例としてテキストや動画の新規生成技術の紹介「統計学Ａ」（第1回）
C94: 1-5 | D94: ・流通、製造、金融、サービス、インフラ、公共、ヘルスケア等におけるデータ・AI利活用事例紹介「統計学Ａ」（第1回）
B95: （４）活用に当たっての様々な留意事項（ELSI、個人情報、データ倫理、ＡＩ社会原則等）を考慮し、情報セキュリティや情報漏洩等、データを守る上での留意事項への理解をする | C95: 3-1 | D95: ・データ・AI活用における負の事例紹介、帰納的推論と演繹的推論「統計学Ａ」（第1回） ・技術進歩の弊害「統計学Ａ」（第2回）
C96: 3-2 | D96: ・情報セキュリティ対策、RSA暗号「統計学Ａ」（第2回）
B97: （５）実データ・実課題（学術データ等を含む）を用いた演習など、社会での実例を題材として、「データを読む、説明する、扱う」といった数理・データサイエンス・ＡＩの基本的な活用法に関するもの | C97: 2-1 | D97: ・統計情報の正しい理解のための指数関数・対数関数の性質と微分方程式の読み取り方「統計学Ａ」（第2回）
...

Sheet 様式１―３　プログラムを構成する授業科目
R1: 様式１―３ | T1: 「学部・学科によって、修了要件は相違する」場合は、本シートを複製の上＜様式１－〇＞と枝番号を付してください
B2: 大学等名 | C2: 北里大学
B3: プログラム名 | C3: 北里大学 数理・データサイエンス・AI教育プログラム
A5: プログラムを構成する授業科目について
A7: ① 対象となる学部・学科名称 | J7: ② 教育プログラムの修了要件 | K7: 学部・学科によって、修了要件は相違する
B9: 医療衛生学部 保健衛生学科、医療検査学科、医療工学科、リハビリテーション学科
A12: ③ 修了要件
B13: プログラムを構成する「教養演習Ｃ（データサイエンスとＡＩ）」1単位、 または「統計学ＢⅠ」2単位と「情報処理工学Ⅰ」2単位あるいは「情報処理工学」1単位の合計3単位以上、 または「統計学Ａ」4単位と「医療情報学」2単位あるいは「医療統計学」2単位の合計6単位を取得すること | V13: 【プルダウンリスト】
V14: 令和４年度以前より、履修することが必須のプログラムとして実施
V15: 令和７年度までに履修必須とする計画
V16: 令和８年度以降に履修必須とする計画、又は未定
B20: 必要最低単位数 | C20: 1 | E20: 単位 | J20: 履修必須の有無 | K20: 令和８年度以降に履修必須とする計画、又は未定
A22: ④ 現在進行中の社会変化（第４次産業革命、Society 5.0、データ駆動型社会等）に深く寄与しているものであり、それが自らの生活と密接に結びついている」の内容を含む授業科目
B24: 授業科目 | F24: 単位数 | G24: 必須 | H24: 1-1 | I24: 1-6 | J24: 授業科目 | P24: 単位数 | Q24: 必須 | R24: 1-1 | S24: 1-6
B25: 教養演習Ｃ（データサイエンスとＡＩ） | F25: 1 | H25: ○ | I25: ○
B26: 情報処理工学Ⅰ | F26: 2 | H26: ○ | I26: ○
B27: 情報処理工学 | F27: 1 | H27: ○ | I27: ○
B28: 医療情報学 | F28: 2 | H28: ○ | I28: ○
B29: 医療統計学 | F29: 2 | H29: ○ | I29: ○
A33: ⑤ 「社会で活用されているデータ」や「データの活用領域」は非常に広範囲であって、日常生活や社会の課題を解決する有用なツールになり得るもの」の内容を含む授業科目
B35: 授業科目 | F35: 単位数 | G35: 必須 | H35: 1-2 | I35: 1-3 | J35: 授業科目 | P35: 単位数 | Q35: 必須 | R35: 1-2 | S35: 1-3
B36: 教養演習Ｃ（データサイエンスとＡＩ） | F36: 1 | H36: ○ | I36: ○
B37: 情報処理工学Ⅰ | F37: 2 | H37: ○ | I37: ○
B38: 情報処理工学 | F38: 1 | H38: ○ | I38: ○
B39: 医療情報学 | F39: 2 | H39: ○ | I39: ○
B40: 医療統計学 | F40: 2 | H40: ○ | I40: ○
A44: ⑥ 「様々なデータ利活用の現場におけるデータ利活用事例が示され、様々な適用領域（流通、製造、金融、サービス、インフラ、公共、ヘルスケア等）の知見と組み合わせることで価値を創出するもの」の内容を含む授業科目
B46: 授業科目 | F46: 単位数 | G46: 必須 | H46: 1-4 | I46: 1-5 | J46: 授業科目 | P46: 単位数 | Q46: 必須 | R46: 1-4 | S46: 1-5
B47: 教養演習Ｃ（データサイエンスとＡＩ） | F47: 1 | H47: ○ | I47: ○
B48: 情報処理工学Ⅰ | F48: 2 | H48: ○ | I48: ○
B49: 情報処理工学 | F49: 1 | H49: ○ | I49: ○
B50: 医療情報学 | F50: 2 | H50: ○ | I50: ○
B51: 医療統計学 | F51: 2 | H51: ○ | I51: ○
A55: ⑦ 「活用に当たっての様々な留意事項（ELSI、個人情報、データ倫理、ＡＩ社会原則等）を考慮し、情報セキュリティや情報漏洩等、データを守る上での留意事項への理解をする」の内容を含む授業科目
B57: 授業科目 | F57: 単位数 | G57: 必須 | H57: 3-1 | I57: 3-2 | J57: 授業科目 | P57: 単位数 | Q57: 必須 | R57: 3-1 | S57: 3-2
B58: 教養演習Ｃ（データサイエンスとＡＩ） | F58: 1 | H58: ○ | I58: ○
B59: 統計学Ａ | F59: 4 | H59: ○ | I59: ○
B60: 統計学ＢⅠ | F60: 2 | H60: ○ | I60: ○
A66: ⑧ 「実データ・実課題（学術データ等を含む）を用いた演習など、社会での実例を題材として、「データを読む、説明する、扱う」といった数理・データサイエンス・ＡＩの基本的な活用法に関するもの」の内容を含む授業科目
B68: 授業科目 | E68: 単位数 | F68: 必須 | G68: 2-1 | H68: 2-2 | I68: 2-3 | J68: 授業科目 | O68: 単位数 | P68: 必須 | Q68: 2-1 | R68: 2-2 | S68: 2-3
...

Sheet 様式２ 履修者等数の実績
AQ1: 様式２
AL2: 大学等名 | AM2: ='様式１―１ プログラムを構成する授業科目'!C2 -> 北里大学
A3: プログラムの履修者数等の実績について
A5: ①プログラム開設年度 | C5: 令和4 | E5: 年度
A7: ②履修者・修了者の実績
B9: 学部・学科名称 | C9: 学生数 | D9: 入学 定員 | E9: 収容 定員 | F9: 令和4年度 | L9: 令和3年度 | R9: 令和2年度 | X9: 令和元年度 | AD9: 平成30年度 | AJ9: 平成29年度 | AP9: 履修者数 合計 | AQ9: 履修率
F10: 履修者数 | I10: 修了者数 | L10: 履修者数 | O10: 修了者数 | R10: 履修者数 | U10: 修了者数 | X10: 履修者数 | AA10: 修了者数 | AD10: 履修者数 | AG10: 修了者数 | AJ10: 履修者数 | AM10: 修了者数
F11: 合計 | G11: 男性 | H11: 女性 | I11: 合計 | J11: 男性 | K11: 女性 | L11: 合計 | M11: 男性 | N11: 女性 | O11: 合計 | P11: 男性 | Q11: 女性 | R11: 合計 | S11: 男性 | T11: 女性 | U11: 合計 | V11: 男性 | W11: 女性 | X11: 合計 | Y11: 男性 | Z11: 女性 | AA11: 合計 | AB11: 男性 | AC11: 女性 | AD11: 合計 | AE11: 男性 | AF11: 女性 | AG11: 合計 | AH11: 男性 | AI11: 女性 | AJ11: 合計 | AK11: 男性 | AL11: 女性 | AM11: 合計 | AN11: 男性 | AO11: 女性
B12: 薬学部薬学科 | C12: 1596 | D12: 260 | E12: 1560 | F12: =G12+H12 -> 8 | G12: 3 | H12: 5 | I12: =J12+K12 -> 7 | J12: 2 | K12: 5 | L12: =M12+N12 -> 0 | O12: =P12+Q12 -> 0 | R12: =S12+T12 -> 0 | U12: =V12+W12 -> 0 | X12: =Y12+Z12 -> 0 | AA12: =AB12+AC12 -> 0 | AD12: =AE12+AF12 -> 0 | AG12: =AH12+AI12 -> 0 | AJ12: =AK12+AL12 -> 0 | AM12: =AN12+AO12 -> 0 | AP12: =F12+L12+R12+X12+AD12+AJ12 -> 8 | AQ12: =AP12/E12 -> 0.0051282051
B13: 薬学部生命創薬科学科 | C13: 143 | D13: 35 | E13: 140 | F13: =G13+H13 -> 0 | G13: 0 | H13: 0 | I13: =J13+K13 -> 0 | J13: 0 | K13: 0 | L13: =M13+N13 -> 0 | O13: =P13+Q13 -> 0 | R13: =S13+T13 -> 0 | U13: =V13+W13 -> 0 | X13: =Y13+Z13 -> 0 | AA13: =AB13+AC13 -> 0 | AD13: =AE13+AF13 -> 0 | AG13: =AH13+AI13 -> 0 | AJ13: =AK13+AL13 -> 0 | AM13: =AN13+AO13 -> 0 | AP13: =F13+L13+R13+X13+AD13+AJ13 -> 0 | AQ13: =AP13/E13 -> 0
B14: 獣医学部獣医学科 | C14: 780 | D14: 120 | E14: 720 | F14: =G14+H14 -> 7 | G14: 3 | H14: 4 | I14: =J14+K14 -> 7 | J14: 3 | K14: 4 | L14: =M14+N14 -> 0 | O14: =P14+Q14 -> 0 | R14: =S14+T14 -> 0 | U14: =V14+W14 -> 0 | X14: =Y14+Z14 -> 0 | AA14: =AB14+AC14 -> 0 | AD14: =AE14+AF14 -> 0 | AG14: =AH14+AI14 -> 0 | AJ14: =AK14+AL14 -> 0 | AM14: =AN14+AO14 -> 0 | AP14: =F14+L14+R14+X14+AD14+AJ14 -> 7 | AQ14: =AP14/E14 -> 0.0097222222
B15: 獣医学部動物資源科学科 | C15: 500 | D15: 130 | E15: 520 | F15: =G15+H15 -> 5 | G15: 2 | H15: 3 | I15: =J15+K15 -> 4 | J15: 1 | K15: 3 | L15: =M15+N15 -> 0 | O15: =P15+Q15 -> 0 | R15: =S15+T15 -> 0 | U15: =V15+W15 -> 0 | X15: =Y15+Z15 -> 0 | AA15: =AB15+AC15 -> 0 | AD15: =AE15+AF15 -> 0 | AG15: =AH15+AI15 -> 0 | AJ15: =AK15+AL15 -> 0 | AM15: =AN15+AO15 -> 0 | AP15: =F15+L15+R15+X15+AD15+AJ15 -> 5 | AQ15: =AP15/E15 -> 0.0096153846
B16: 獣医学部生物環境科学科 | C16: 288 | D16: 90 | E16: 360 | F16: =G16+H16 -> 17 | G16: 16 | H16: 1 | I16: =J16+K16 -> 8 | J16: 8 | K16: 0 | L16: =M16+N16 -> 0 | O16: =P16+Q16 -> 0 | R16: =S16+T16 -> 0 | U16: =V16+W16 -> 0 | X16: =Y16+Z16 -> 0 | AA16: =AB16+AC16 -> 0 | AD16: =AE16+AF16 -> 0 | AG16: =AH16+AI16 -> 0 | AJ16: =AK16+AL16 -> 0 | AM16: =AN16+AO16 -> 0 | AP16: =F16+L16+R16+X16+AD16+AJ16 -> 17 | AQ16: =AP16/E16 -> 0.047222222
B17: 医学部医学科 | C17: 738 | D17: 120 | E17: 713 | F17: =G17+H17 -> 130 | G17: 82 | H17: 48 | I17: =J17+K17 -> 127 | J17: 79 | K17: 48 | L17: =M17+N17 -> 0 | O17: =P17+Q17 -> 0 | R17: =S17+T17 -> 0 | U17: =V17+W17 -> 0 | X17: =Y17+Z17 -> 0 | AA17: =AB17+AC17 -> 0 | AD17: =AE17+AF17 -> 0 | AG17: =AH17+AI17 -> 0 | AJ17: =AK17+AL17 -> 0 | AM17: =AN17+AO17 -> 0 | AP17: =F17+L17+R17+X17+AD17+AJ17 -> 130 | AQ17: =AP17/E17 -> 0.18232819
B18: 海洋生命科学部海洋生命科学科 | C18: 767 | D18: 180 | E18: 720 | F18: =G18+H18 -> 23 | G18: 16 | H18: 7 | I18: =J18+K18 -> 20 | J18: 14 | K18: 6 | L18: =M18+N18 -> 0 | O18: =P18+Q18 -> 0 | R18: =S18+T18 -> 0 | U18: =V18+W18 -> 0 | X18: =Y18+Z18 -> 0 | AA18: =AB18+AC18 -> 0 | AD18: =AE18+AF18 -> 0 | AG18: =AH18+AI18 -> 0 | AJ18: =AK18+AL18 -> 0 | AM18: =AN18+AO18 -> 0 | AP18: =F18+L18+R18+X18+AD18+AJ18 -> 23 | AQ18: =AP18/E18 -> 0.031944444
B19: 看護学部看護学科 | C19: 518 | D19: 125 | E19: 495 | F19: =G19+H19 -> 2 | G19: 0 | H19: 2 | I19: =J19+K19 -> 1 | J19: 0 | K19: 1 | L19: =M19+N19 -> 0 | O19: =P19+Q19 -> 0 | R19: =S19+T19 -> 0 | U19: =V19+W19 -> 0 | X19: =Y19+Z19 -> 0 | AA19: =AB19+AC19 -> 0 | AD19: =AE19+AF19 -> 0 | AG19: =AH19+AI19 -> 0 | AJ19: =AK19+AL19 -> 0 | AM19: =AN19+AO19 -> 0 | AP19: =F19+L19+R19+X19+AD19+AJ19 -> 2 | AQ19: =AP19/E19 -> 0.004040404
B20: 理学部物理学科 | C20: 234 | D20: 53 | E20: 212 | F20: =G20+H20 -> 1 | G20: 1 | H20: 0 | I20: =J20+K20 -> 1 | J20: 1 | K20: 0 | L20: =M20+N20 -> 0 | O20: =P20+Q20 -> 0 | R20: =S20+T20 -> 0 | U20: =V20+W20 -> 0 | X20: =Y20+Z20 -> 0 | AA20: =AB20+AC20 -> 0 | AD20: =AE20+AF20 -> 0 | AG20: =AH20+AI20 -> 0 | AJ20: =AK20+AL20 -> 0 | AM20: =AN20+AO20 -> 0 | AP20: =F20+L20+R20+X20+AD20+AJ20 -> 1 | AQ20: =AP20/E20 -> 0.0047169811
B21: 理学部化学科 | C21: 340 | D21: 80 | E21: 320 | F21: =G21+H21 -> 1 | G21: 1 | H21: 0 | I21: =J21+K21 -> 0 | J21: 0 | K21: 0 | L21: =M21+N21 -> 0 | O21: =P21+Q21 -> 0 | R21: =S21+T21 -> 0 | U21: =V21+W21 -> 0 | X21: =Y21+Z21 -> 0 | AA21: =AB21+AC21 -> 0 | AD21: =AE21+AF21 -> 0 | AG21: =AH21+AI21 -> 0 | AJ21: =AK21+AL21 -> 0 | AM21: =AN21+AO21 -> 0 | AP21: =F21+L21+R21+X21+AD21+AJ21 -> 1 | AQ21: =AP21/E21 -> 0.003125
B22: 理学部生物科学科 | C22: 343 | D22: 80 | E22: 320 | F22: =G22+H22 -> 3 | G22: 1 | H22: 2 | I22: =J22+K22 -> 3 | J22: 1 | K22: 2 | L22: =M22+N22 -> 0 | O22: =P22+Q22 -> 0 | R22: =S22+T22 -> 0 | U22: =V22+W22 -> 0 | X22: =Y22+Z22 -> 0 | AA22: =AB22+AC22 -> 0 | AD22: =AE22+AF22 -> 0 | AG22: =AH22+AI22 -> 0 | AJ22: =AK22+AL22 -> 0 | AM22: =AN22+AO22 -> 0 | AP22: =F22+L22+R22+X22+AD22+AJ22 -> 3 | AQ22: =AP22/E22 -> 0.009375
B23: 医療衛生学部保健衛生学科 | C23: 159 | D23: 40 | E23: 160 | F23: =G23+H23 -> 0 | G23: 0 | H23: 0 | I23: =J23+K23 -> 0 | J23: 0 | K23: 0 | L23: =M23+N23 -> 0 | O23: =P23+Q23 -> 0 | R23: =S23+T23 -> 0 | U23: =V23+W23 -> 0 | X23: =Y23+Z23 -> 0 | AA23: =AB23+AC23 -> 0 | AD23: =AE23+AF23 -> 0 | AG23: =AH23+AI23 -> 0 | AJ23: =AK23+AL23 -> 0 | AM23: =AN23+AO23 -> 0 | AP23: =F23+L23+R23+X23+AD23+AJ23 -> 0 | AQ23: =AP23/E23 -> 0
... B26: 医療衛生学部リハビリテーション学科 | C26: 624 | D26: 145 | E26: 580 | F26: =G26+H26 -> 5 | G26: 2 | H26: 3 | I26: =J26+K26 -> 4 | J26: 1 | K26: 3 | L26: =M26+N26 -> 0 | O26: =P26+Q26 -> 0 | R26: =S26+T26 -> 0 | U26: =V26+W26 -> 0 | X26: =Y26+Z26 -> 0 | AA26: =AB26+AC26 -> 0 | AD26: =AE26+AF26 -> 0 | AG26: =AH26+AI26 -> 0 | AJ26: =AK26+AL26 -> 0 | AM26: =AN26+AO26 -> 0 | AP26: =F26+L26+R26+X26+AD26+AJ26 -> 5 | AQ26: =AP26/E26 -> 0.0086206897
F27: =G27+H27 -> 0 | I27: =J27+K27 -> 0 | L27: =M27+N27 -> 0 | O27: =P27+Q27 -> 0 | R27: =S27+T27 -> 0 | U27: =V27+W27 -> 0 | X27: =Y27+Z27 -> 0 | AA27: =AB27+AC27 -> 0 | AD27: =AE27+AF27 -> 0 | AG27: =AH27+AI27 -> 0 | AJ27: =AK27+AL27 -> 0 | AM27: =AN27+AO27 -> 0 | AP27: =F27+L27+R27+X27+AD27+AJ27 -> 0 | AQ27: =AP27/E27 -> #DIV/0!
F28: =G28+H28 -> 0 | I28: =J28+K28 -> 0 | L28: =M28+N28 -> 0 | O28: =P28+Q28 -> 0 | R28: =S28+T28 -> 0 | U28: =V28+W28 -> 0 | X28: =Y28+Z28 -> 0 | AA28: =AB28+AC28 -> 0 | AD28: =AE28+AF28 -> 0 | AG28: =AH28+AI28 -> 0 | AJ28: =AK28+AL28 -> 0 | AM28: =AN28+AO28 -> 0 | AP28: =F28+L28+R28+X28+AD28+AJ28 -> 0 | AQ28: =AP28/E28 -> #DIV/0!
F29: =G29+H29 -> 0 | I29: =J29+K29 -> 0 | L29: =M29+N29 -> 0 | O29: =P29+Q29 -> 0 | R29: =S29+T29 -> 0 | U29: =V29+W29 -> 0 | X29: =Y29+Z29 -> 0 | AA29: =AB29+AC29 -> 0 | AD29: =AE29+AF29 -> 0 | AG29: =AH29+AI29 -> 0 | AJ29: =AK29+AL29 -> 0 | AM29: =AN29+AO29 -> 0 | AP29: =F29+L29+R29+X29+AD29+AJ29 -> 0 | AQ29: =AP29/E29 -> #DIV/0!
F30: =G30+H30 -> 0 | I30: =J30+K30 -> 0 | L30: =M30+N30 -> 0 | O30: =P30+Q30 -> 0 | R30: =S30+T30 -> 0 | U30: =V30+W30 -> 0 | X30: =Y30+Z30 -> 0 | AA30: =AB30+AC30 -> 0 | AD30: =AE30+AF30 -> 0 | AG30: =AH30+AI30 -> 0 | AJ30: =AK30+AL30 -> 0 | AM30: =AN30+AO30 -> 0 | AP30: =F30+L30+R30+X30+AD30+AJ30 -> 0 | AQ30: =AP30/E30 -> #DIV/0!
F31: =G31+H31 -> 0 | I31: =J31+K31 -> 0 | L31: =M31+N31 -> 0 | O31: =P31+Q31 -> 0 | R31: =S31+T31 -> 0 | U31: =V31+W31 -> 0 | X31: =Y31+Z31 -> 0 | AA31: =AB31+AC31 -> 0 | AD31: =AE31+AF31 -> 0 | AG31: =AH31+AI31 -> 0 | AJ31: =AK31+AL31 -> 0 | AM31: =AN31+AO31 -> 0 | AP31: =F31+L31+R31+X31+AD31+AJ31 -> 0 | AQ31: =AP31/E31 -> #DIV/0!
B32: 合 計 | C32: =SUM(C12:C31) -> 7957 | D32: =SUM(D12:D31) -> 1678 | E32: =SUM(E12:E31) -> 7700 | F32: =SUM(F12:F31) -> 211 | G32: =SUM(G12:G31) -> 130 | H32: =SUM(H12:H31) -> 81 | I32: =SUM(I12:I31) -> 191 | J32: =SUM(J12:J31) -> 113 | ... AP32: =SUM(AP12:AP31) -> 211 | AQ32: =AP32/E32 -> 0.027402597

Sheet 様式３ 教育の質・履修者数を向上させるための体制・計画
I1: 様式３
G2: 大学等名 | H2: ='様式１―１ プログラムを構成する授業科目'!C2 -> 北里大学
A4: 教育の質・履修者数を向上させるための体制・計画について
A6: ① | B6: 全学の教員数 | C6: (常勤） | E6: 1716 | F6: 人 | G6: （非常勤） | H6: 545 | I6: 人
A8: ② | B8: プログラムの授業を教えている教員数 | H8: 8 | I8: 人
A10: ③ | B10: プログラムの運営責任者
B11: （責任者名） | C11: 江川 徹 | G11: （役職名） | H11: 北里大学教育委員会委員長
A13: ④ | B13: プログラムを改善・進化させるための体制（委員会・組織等）
B14: 北里大学教育委員会
B16: （責任者名） | C16: 江川 徹 | G16: （役職名） | H16: 北里大学教育委員会委員長
A18: ⑤ | B18: プログラムを改善・進化させるための体制を定める規則名称
B19: 北里大学教育委員会規程
A21: ⑥ | B21: 体制の目的
B22: 委員会は、本学における学士課程教育及び大学院教育の基本方針及び教育目標、教育課程、教育内容、教育方法等を協議し、学士課程教育及び大学院教育の円滑な実施とその充実に努めることを目的としており、全学の教育内容や教育・学習環境に関することを協議する。
A34: ⑦ | B34: 具体的な構成員
B35: 北里大学教育委員会委員長 江川 徹（北里大学副学長） 北里大学教育委員会副委員長 松谷 伸二（北里大学学長補佐） 薬学部教育委員長 長光 亨 獣医学部教育委員長 久留主 志朗 医学部教育委員長 小川 元之 海洋生命科学部教育委員長 天野 勝文 看護学部教育委員長 香取 洋子 理学部教育委員長 弓削 秀隆 医療衛生学部教育委員長 石橋 仁 未来工学部教育委員長 渡辺 豪 一般教育部教育委員長 伊藤 真吾 医療系研究科委員長 林 俊治 感染制御科学府委員長 高橋 孝
A48: ⑧ | B48: 履修者数・履修率の向上に向けた計画 ※様式１の「履修必須の有無」で「計画がある」としている場合は詳細について記載すること
B49: 令和４年度実績 | C49: ='様式２ 履修者等数の実績'!AQ32 -> 0.027402597 | E49: 令和５年度予定 | F49: 0.15 | H49: 令和６年度予定 | I49: 0.25
B50: 令和７年度予定 | C50: 0.4 | E50: 令和８年度予定 | F50: 0.6 | H50: 収容定員（名） | I50: ='様式２ 履修者等数の実績'!E32 -> 7700
B51: 具体的な計画
B52: 4月当初の履修登録時のオリエンテーションにてプログラム内容をわかりやすく記載したチラシを配付するなどして、まずはプログラムの普及に努める。なお、医学部や医療衛生学部などの一部の学部・学科では、修了要件科目が必修となっている。 また、修了要件科目を開講している学部等の教育委員会において実施した教育内容の点検・評価内容を元に、北里大学教育委員会においてプログラムの点検・評価を行い、改善・進化をさせることによって履修者数の増加につなげる。
A65: ⑨ | B65: 学部・学科に関係なく希望する学生全員が受講可能となるような必要な体制・取組等
B66: 多くの学部で修了要件となっている「教養演習Ｃ（データサイエンスとAI）」については、全学部の1年生を中心に一般教育を提供する「一般教育部」で開講している科目である。「教養演習Ｃ（データサイエンスとAI）」については、時間割の関係から受講できない状況を避けるため、土曜日にもオンデマンド授業にて開講している。 また、カリキュラムの関係から「教養演習Ｃ（データサイエンスとAI）」を卒業要件にすることが難しい医学部及び医療衛生学部においては、それぞれの学部において必修となっている科目を中心に修了要件を作成している。
A79: ⑩ | B79: できる限り多くの学生が履修できるような具体的な周知方法・取組
B80: プログラム内容をわかりやすくまとめたチラシを作成し、入学後のオリエンテーションや大学ホームページでの周知を行っている。また、「教養演習Ｃ（データサイエンスとAI）」は土曜日にもオンデマンド授業を開講し、できる限り多くの学生が履修できるように取り組んでいる。
A93: ⑪ | B93: できる限り多くの学生が履修・修得できるようなサポート体制
B94: プログラムの問い合わせ窓口をチラシや大学ホームページにおいて周知し、履修のためのサポート体制を整えている。また、科目を開講している学部にもプログラムの内容を周知し、事務室の窓口におけるサポートにも対応している。
A107: ⑫ | B107: 授業時間内外で学習指導、質問を受け付ける具体的な仕組み
B108: 各科目ごとにオフィスアワーを設定し、授業内容に関する質問や解説を実施している。 また、MoodleなどのLMSを用いて質問を受け付けたり、解説を公開したりして、状況に応じて各学生からの質問を全員に還元できるようにしている。

Sheet 様式４　自己点検・評価
I1: 様式４
H2: 大学等名 | I2: ='様式１―１ プログラムを構成する授業科目'!C2 -> 北里大学
A3: 自己点検・評価について
A5: ① | B5: プログラムの自己点検・評価を行う体制（委員会・組織等）
B6: 北里大学教育委員会
D8: （責任者名） | E8: 江川 徹 | G8: （役職名） | H8: 北里大学教育会委員長
A10: ② | B10: 自己点検・評価体制における意見等
B11: 自己点検・評価の視点 | E11: 自己点検・評価体制における意見・結果・改善に向けた取組等
B12: 学内からの視点
C13: プログラムの履修・修得状況 | E13: 本プログラムは令和4（2022）年度に開設され、修了者数は2023年3月31日現在で191名、収容定員に対して3％である。なお、プログラムの履修期間が複数年の場合、履修した初年度に計上することとなるため、2022年度のプログラム修了者は、2023年度末に確定するが、現時点での予測では、415名となっている。履修・修得状況は未だ高いとは言えないが、開設初年度としては概ね良好と言える。 今後はより履修・修得を促すべく、履修率の目標を設定を行った上で、プログラムの周知及び履修率向上に向けて取り組みを行っていくこととする。また、シラバスについて、中間点検として記載内容の確認を行い、プログラムにおける担当項目を教えていることが不明瞭なシラバスにおいては、2023年度シラバスから明記することとした。更に、シラバスの第三者チェックの際に、明記されているかどうかを確認するようにした。
C14: 学修成果 | E14: 学修成果については、教学システムによって修了要件科目の成績を分析することができ、概ね良好な成果を得られている旨、確認できた。また、修了者には学修ポートフォリオ上で修了済みであることや、プログラム構成科目の成績がわかるようになっており、学生の学修成果の把握にも役立っている。
C15: 学生アンケート等を通じた学生の内容の理解度 | E15: 授業評価アンケートを実施して、その結果を分析し、科目を開講している学部等の教育委員会において、授業内容の適切性について点検・評価を行っている。授業評価アンケートの結果、プログラム該当科目において、「興味・関心を持ったか」「この授業は自分にとって意味のある授業だった」といった項目に対し、平均して80％程度の肯定回答があり、学生からの理解が得られている様子が確認できた。 なお、一部の開講科目においては、受講者数が少なかったため、現時点での判断が難しかったことから、来年度以降に今年度の結果を含めて総合的に判断することとした。 よって、次年度のプログラム内容の変更は行わないこととした。
C16: 学生アンケート等を通じた後輩等他の学生への推奨度 | E16: 本学では、「授業評価アンケート」を実施しており、そのアンケート結果から、対象科目について概ね良好な満足度であることが報告されている。以上のことから、間接的ではあるが、推奨度についても良好な評価が得られている推測される。 学生アンケートを通じて、後輩等他の学生への推奨度は確認できているが、間接的であるため、可能であれば直接的な設問の設置を検討してもよい。
C17: 全学的な履修者数、履修率向上に向けた計画の達成・進捗状況 | E17: 北里大学教育委員会が中心となって、本プログラムの履修状況を分析、履修者数や履修率向上に向けた計画を立案し、進捗状況を管理している。また、履修者数や履修率向上に向けて、オリエンテーションや大学ホームページなどでの広報を継続的に推進する。
B18: 学外からの視点
C19: 教育プログラム修了者の進路、活躍状況、企業等の評価 | E19: 本プログラムは令和4年に開設し、プログラム修了者の卒業者は令和5年時点ではいない。修了者が卒業する令和7年度以降に、本学の就職センターとも協力して、活躍状況や企業等の評価を取り入れた点検・評価を行うよう準備を進める。
C20: 産業界からの視点を含めた教育プログラム内容・手法等への意見 | E20: 本学では、点検・評価室において、原則毎年度学外者の客観的な視点を取り入れた自己点検・評価を行っている。また、毎年就職センターにおいて卒業生の進路先企業等にアンケートを実施している。いずれかの手法によって、産業界・教育界からの視点を含めた意見を聴取し、本プログラムの運用に反映することができる。
B21: 数理・データサイエンス・ＡＩを「学ぶ楽しさ」「学ぶことの意義」を理解させること | E21: 本プログラムの構成科目のうち、「教養演習Ｃ」では、実務経験のある教員が実社会でも使われるようなツールを使った実践的な内容を教育して、学ぶことの意義を理解させるようにしている。 また、他の科目においては、医学部や医療衛生学部など、それぞれの専門分野に紐づいた内容を教育しており、分野に応じた実際に社会で活躍できる人材を育成している。
B22: 内容・水準を維持・向上しつつ、より「分かりやすい」授業とすること | E22: 本学では、多くの科目で授業評価アンケートを実施しており、学生の内容の理解度等を把握している。また、学生からの授業評価結果を元に、評価の高い教員への表彰や、FD活動等を実施して、内容・水準を維持・向上に努めている。
