Workbook

Sheet 様式１ー１　プログラムを構成する授業科目
R1: 様式１ー１ | T1: 「学部・学科によって、修了要件は相違する」場合は、本シートを複製の上＜様式１－〇＞と枝番号を付してください
B2: 大学等名 | C2: 大阪工業大学
B3: プログラム名 | C3: OIT MDASH（リテラシー）
A5: プログラムを構成する授業科目について
A7: ① 対象となる学部・学科名称 | J7: ② 教育プログラムの修了要件 | K7: 学部・学科によって、修了要件は相違する
B9: 工学部
A12: ③ 修了要件
B13: プログラムを構成する科目のうち、次の①②いずれも満たすこと。 ①「キャリアデザイン」および「基礎情報処理Ⅱ」を修得すること。 ②以下の科目群のうち、1科目以上を修得すること。 「技術者倫理」「工学倫理」「情報社会と倫理」「環境倫理」「キャリア形成支援」 | V13: 【プルダウンリスト】
V14: 令和４年度以前より、履修することが必須のプログラムとして実施
V15: 令和７年度までに履修必須とする計画
V16: 令和８年度以降に履修必須とする計画、又は未定
B20: 必要最低単位数 | C20: 3 | E20: 単位 | J20: 履修必須の有無 | K20: 令和８年度以降に履修必須とする計画、又は未定
A22: ④ 現在進行中の社会変化（第４次産業革命、Society 5.0、データ駆動型社会等）に深く寄与しているものであり、それが自らの生活と密接に結びついている」の内容を含む授業科目
B24: 授業科目 | F24: 単位数 | G24: 必須 | H24: 1-1 | I24: 1-6 | J24: 授業科目 | P24: 単位数 | Q24: 必須 | R24: 1-1 | S24: 1-6
B25: キャリアデザイン | F25: 1 | G25: ○ | H25: ○
B26: 基礎情報処理Ⅱ | F26: 1 | G26: ○ | I26: ○
A33: ⑤ 「社会で活用されているデータ」や「データの活用領域」は非常に広範囲であって、日常生活や社会の課題を解決する有用なツールになり得るもの」の内容を含む授業科目
B35: 授業科目 | F35: 単位数 | G35: 必須 | H35: 1-2 | I35: 1-3 | J35: 授業科目 | P35: 単位数 | Q35: 必須 | R35: 1-2 | S35: 1-3
B36: キャリアデザイン | F36: 1 | G36: ○ | H36: ○
B37: 基礎情報処理Ⅱ | F37: 1 | G37: ○ | I37: ○
A44: ⑥ 「様々なデータ利活用の現場におけるデータ利活用事例が示され、様々な適用領域（流通、製造、金融、サービス、インフラ、公共、ヘルスケア等）の知見と組み合わせることで価値を創出するもの」の内容を含む授業科目
B46: 授業科目 | F46: 単位数 | G46: 必須 | H46: 1-4 | I46: 1-5 | J46: 授業科目 | P46: 単位数 | Q46: 必須 | R46: 1-4 | S46: 1-5
B47: キャリアデザイン | F47: 1 | G47: ○ | H47: ○
B48: 基礎情報処理Ⅱ | F48: 1 | G48: ○ | I48: ○
A55: ⑦ 「活用に当たっての様々な留意事項（ELSI、個人情報、データ倫理、ＡＩ社会原則等）を考慮し、情報セキュリティや情報漏洩等、データを守る上での留意事項への理解をする」の内容を含む授業科目
B57: 授業科目 | F57: 単位数 | G57: 必須 | H57: 3-1 | I57: 3-2 | J57: 授業科目 | P57: 単位数 | Q57: 必須 | R57: 3-1 | S57: 3-2
B58: 技術者倫理 | F58: 2 | H58: ○ | I58: ○
B59: 工学倫理 | F59: 2 | H59: ○ | I59: ○
B60: 情報社会と倫理 | F60: 2 | H60: ○ | I60: ○
B61: 環境倫理 | F61: 2 | H61: ○ | I61: ○
B62: キャリア形成支援 | F62: 1 | H62: ○ | I62: ○
A66: ⑧ 「実データ・実課題（学術データ等を含む）を用いた演習など、社会での実例を題材として、「データを読む、説明する、扱う」といった数理・データサイエンス・ＡＩの基本的な活用法に関するもの」の内容を含む授業科目
B68: 授業科目 | E68: 単位数 | F68: 必須 | G68: 2-1 | H68: 2-2 | I68: 2-3 | J68: 授業科目 | O68: 単位数 | P68: 必須 | Q68: 2-1 | R68: 2-2 | S68: 2-3
B69: 基礎情報処理Ⅱ | E69: 1 | F69: ○ | G69: ○ | H69: ○ | I69: ○
A77: ⑨ 選択「４．オプション」の内容を含む授業科目
B78: 授業科目 | F78: 選択項目 | J78: 授業科目 | P78: 選択項目
A87: ⑩ プログラムを構成する授業の内容
B88: 授業に含まれている内容・要素 | D88: 講義内容
B89: （１）現在進行中の社会変化（第４次産業革命、Society 5.0、データ駆動型社会等）に深く寄与しているものであり、それが自らの生活と密接に結びついている | C89: 1-1 | D89: ・コンピュータの進化［計算機の処理性能の向上］、IoT, AI, ビックデータ，Society 5.0「キャリアデザイン」 ＜都市デザイン工学科＞10回目 ＜建築学科＞13回目 ＜機械工学科＞9回目 ＜電気電子システム工学科＞13回目 ＜電子情報システム工学科＞3回目 ＜応用化学科＞6回目 ＜環境工学科＞3回目 ＜生命工学科＞10回目
C90: 1-6 | D90: ・AI最新技術の活用例（深層学習，自然言語処理，最適化技術）「基礎情報処理Ⅱ」 ＜都市デザイン工学科＞1回目 ＜建築学科＞1回目 ＜機械工学科＞1回目 ＜電気電子システム工学科＞1回目 ＜電子情報システム工学科＞8回目 ＜応用化学科＞1回目 ＜環境工学科＞1回目 ＜生命工学科＞1回目
...

Sheet 様式１ー２　プログラムを構成する授業科目
R1: 様式１ー２ | T1: 「学部・学科によって、修了要件は相違する」場合は、本シートを複製の上＜様式１－〇＞と枝番号を付してください
B2: 大学等名 | C2: 大阪工業大学
B3: プログラム名 | C3: OIT MDASH（リテラシー）
A5: プログラムを構成する授業科目について
A7: ① 対象となる学部・学科名称 | J7: ② 教育プログラムの修了要件 | K7: 学部・学科によって、修了要件は相違する
B9: ロボティクス＆デザイン工学部
A12: ③ 修了要件
B13: プログラムを構成する科目のうち、次の3科目を修得すること。 「基礎情報処理」「工学倫理」「確率・統計学」 | V13: 【プルダウンリスト】
V14: 令和４年度以前より、履修することが必須のプログラムとして実施
V15: 令和７年度までに履修必須とする計画
V16: 令和８年度以降に履修必須とする計画、又は未定
B20: 必要最低単位数 | C20: 4 | E20: 単位 | J20: 履修必須の有無 | K20: 令和８年度以降に履修必須とする計画、又は未定
A22: ④ 現在進行中の社会変化（第４次産業革命、Society 5.0、データ駆動型社会等）に深く寄与しているものであり、それが自らの生活と密接に結びついている」の内容を含む授業科目
B24: 授業科目 | F24: 単位数 | G24: 必須 | H24: 1-1 | I24: 1-6 | J24: 授業科目 | P24: 単位数 | Q24: 必須 | R24: 1-1 | S24: 1-6
B25: 基礎情報処理 | F25: 1 | G25: ○ | H25: ○ | I25: ○
A33: ⑤ 「社会で活用されているデータ」や「データの活用領域」は非常に広範囲であって、日常生活や社会の課題を解決する有用なツールになり得るもの」の内容を含む授業科目
B35: 授業科目 | F35: 単位数 | G35: 必須 | H35: 1-2 | I35: 1-3 | J35: 授業科目 | P35: 単位数 | Q35: 必須 | R35: 1-2 | S35: 1-3
B36: 基礎情報処理 | F36: 1 | G36: ○ | H36: ○ | I36: ○
A44: ⑥ 「様々なデータ利活用の現場におけるデータ利活用事例が示され、様々な適用領域（流通、製造、金融、サービス、インフラ、公共、ヘルスケア等）の知見と組み合わせることで価値を創出するもの」の内容を含む授業科目
B46: 授業科目 | F46: 単位数 | G46: 必須 | H46: 1-4 | I46: 1-5 | J46: 授業科目 | P46: 単位数 | Q46: 必須 | R46: 1-4 | S46: 1-5
B47: 基礎情報処理 | F47: 1 | G47: ○ | H47: ○ | I47: ○
A55: ⑦ 「活用に当たっての様々な留意事項（ELSI、個人情報、データ倫理、ＡＩ社会原則等）を考慮し、情報セキュリティや情報漏洩等、データを守る上での留意事項への理解をする」の内容を含む授業科目
B57: 授業科目 | F57: 単位数 | G57: 必須 | H57: 3-1 | I57: 3-2 | J57: 授業科目 | P57: 単位数 | Q57: 必須 | R57: 3-1 | S57: 3-2
B58: 工学倫理 | F58: 1 | G58: ○ | H58: ○ | I58: ○
A66: ⑧ 「実データ・実課題（学術データ等を含む）を用いた演習など、社会での実例を題材として、「データを読む、説明する、扱う」といった数理・データサイエンス・ＡＩの基本的な活用法に関するもの」の内容を含む授業科目
B68: 授業科目 | E68: 単位数 | F68: 必須 | G68: 2-1 | H68: 2-2 | I68: 2-3 | J68: 授業科目 | O68: 単位数 | P68: 必須 | Q68: 2-1 | R68: 2-2 | S68: 2-3
B69: 確率・統計学 | E69: 2 | F69: ○ | G69: ○ | H69: ○ | I69: ○
A77: ⑨ 選択「４．オプション」の内容を含む授業科目
B78: 授業科目 | F78: 選択項目 | J78: 授業科目 | P78: 選択項目
B79: 確率・統計学 | F79: 4-1統計および数理基礎
A87: ⑩ プログラムを構成する授業の内容
B88: 授業に含まれている内容・要素 | D88: 講義内容
B89: （１）現在進行中の社会変化（第４次産業革命、Society 5.0、データ駆動型社会等）に深く寄与しているものであり、それが自らの生活と密接に結びついている | C89: 1-1 | D89: ・コンピュータの進化［計算機の処理性能の向上］、IoT, AI, ビックデータ，Society 5.0「基礎情報処理」（6回目）
C90: 1-6 | D90: ・AI最新技術の活用例（深層学習，自然言語処理，最適化技術）「基礎情報処理」（6回目）
B91: （２）「社会で活用されているデータ」や「データの活用領域」は非常に広範囲であって、日常生活や社会の課題を解決する有用なツールになり得るもの | C91: 1-2 | D91: ・調査データ，観測データ，実験データ，ログデータ，オープンデータ、データアノテーション「基礎情報処理」 (8・9回目)
C92: 1-3 | D92: ・データ・AIが活用される分野［データ・ＡＩ活用領域の広がり］(物理・化学・生物学・法律・経済・ビジネスなど)「基礎情報処理」（9回目）
B93: （３）様々なデータ利活用の現場におけるデータ利活用事例が示され、様々な適用領域（流通、製造、金融、サービス、インフラ、公共、ヘルスケア等）の知見と組み合わせることで価値を創出するもの | C93: 1-4 | D93: ・データの可視化，クラスタリング［データ解析］，予測「基礎情報処理」 (13回目)
C94: 1-5 | D94: ・機械学習技術・最適化技術などの概要［探索的データ解析］，データサイエンスのサイクル， IOT・ロボット［ＡＩ利活用の事例紹介］「基礎情報処理」（13・14回目）
B95: （４）活用に当たっての様々な留意事項（ELSI、個人情報、データ倫理、ＡＩ社会原則等）を考慮し、情報セキュリティや情報漏洩等、データを守る上での留意事項への理解をする | C95: 3-1 | D95: ・ELSI、GDPR、プライバシー保護、人間中心のAI社会原理、データ取り扱いの健全性、個人情報とプライバシー、データバイアス、アルゴリズムバイアス、社会的合意の形成、AIサービスの責任論「工学倫理」（7回目）
C96: 3-2 | D96: ・情報セキュリティ、データの保護手法、情報漏洩等によるセキュリティ事故の事例紹介「工学倫理」（7回目）
...

Sheet 様式１ー３　プログラムを構成する授業科目
R1: 様式１ー３ | T1: 「学部・学科によって、修了要件は相違する」場合は、本シートを複製の上＜様式１－〇＞と枝番号を付してください
B2: 大学等名 | C2: 大阪工業大学
B3: プログラム名 | C3: OIT MDASH（リテラシー）
A5: プログラムを構成する授業科目について
A7: ① 対象となる学部・学科名称 | J7: ② 教育プログラムの修了要件 | K7: 学部・学科によって、修了要件は相違する
B9: 情報科学部
A12: ③ 修了要件
B13: プログラムを構成する科目のうち、次の3科目を修得すること。 「コンピュータ入門」「情報技術者論」「確率・統計」 | V13: 【プルダウンリスト】
V14: 令和４年度以前より、履修することが必須のプログラムとして実施
V15: 令和７年度までに履修必須とする計画
V16: 令和８年度以降に履修必須とする計画、又は未定
B20: 必要最低単位数 | C20: 6 | E20: 単位 | J20: 履修必須の有無 | K20: 令和８年度以降に履修必須とする計画、又は未定
A22: ④ 現在進行中の社会変化（第４次産業革命、Society 5.0、データ駆動型社会等）に深く寄与しているものであり、それが自らの生活と密接に結びついている」の内容を含む授業科目
B24: 授業科目 | F24: 単位数 | G24: 必須 | H24: 1-1 | I24: 1-6 | J24: 授業科目 | P24: 単位数 | Q24: 必須 | R24: 1-1 | S24: 1-6
B25: コンピュータ入門 | F25: 2 | G25: ○ | H25: ○ | I25: ○
A33: ⑤ 「社会で活用されているデータ」や「データの活用領域」は非常に広範囲であって、日常生活や社会の課題を解決する有用なツールになり得るもの」の内容を含む授業科目
B35: 授業科目 | F35: 単位数 | G35: 必須 | H35: 1-2 | I35: 1-3 | J35: 授業科目 | P35: 単位数 | Q35: 必須 | R35: 1-2 | S35: 1-3
B36: コンピュータ入門 | F36: 2 | G36: ○ | H36: ○ | I36: ○
A44: ⑥ 「様々なデータ利活用の現場におけるデータ利活用事例が示され、様々な適用領域（流通、製造、金融、サービス、インフラ、公共、ヘルスケア等）の知見と組み合わせることで価値を創出するもの」の内容を含む授業科目
B46: 授業科目 | F46: 単位数 | G46: 必須 | H46: 1-4 | I46: 1-5 | J46: 授業科目 | P46: 単位数 | Q46: 必須 | R46: 1-4 | S46: 1-5
B47: コンピュータ入門 | F47: 2 | G47: ○ | H47: ○ | I47: ○
A55: ⑦ 「活用に当たっての様々な留意事項（ELSI、個人情報、データ倫理、ＡＩ社会原則等）を考慮し、情報セキュリティや情報漏洩等、データを守る上での留意事項への理解をする」の内容を含む授業科目
B57: 授業科目 | F57: 単位数 | G57: 必須 | H57: 3-1 | I57: 3-2 | J57: 授業科目 | P57: 単位数 | Q57: 必須 | R57: 3-1 | S57: 3-2
B58: 情報技術者論 | F58: 2 | G58: ○ | H58: ○ | I58: ○
A66: ⑧ 「実データ・実課題（学術データ等を含む）を用いた演習など、社会での実例を題材として、「データを読む、説明する、扱う」といった数理・データサイエンス・ＡＩの基本的な活用法に関するもの」の内容を含む授業科目
B68: 授業科目 | E68: 単位数 | F68: 必須 | G68: 2-1 | H68: 2-2 | I68: 2-3 | J68: 授業科目 | O68: 単位数 | P68: 必須 | Q68: 2-1 | R68: 2-2 | S68: 2-3
B69: 確率・統計 | E69: 2 | F69: ○ | G69: ○ | H69: ○ | I69: ○
A77: ⑨ 選択「４．オプション」の内容を含む授業科目
B78: 授業科目 | F78: 選択項目 | J78: 授業科目 | P78: 選択項目
B79: 確率・統計 | F79: 4-1統計および数理基礎
A87: ⑩ プログラムを構成する授業の内容
B88: 授業に含まれている内容・要素 | D88: 講義内容
B89: （１）現在進行中の社会変化（第４次産業革命、Society 5.0、データ駆動型社会等）に深く寄与しているものであり、それが自らの生活と密接に結びついている | C89: 1-1 | D89: ・コンピュータの進化［計算機の処理性能の向上］、IoT, AI, ビックデータ，Society 5.0「コンピュータ入門」 ＜データサイエンス学科＞1回目 ＜情報知能学科＞1回目 ＜情報システム学科＞1回目 ＜情報メディア学科＞1回目 ＜ネットワークデザイン学科＞1回目
C90: 1-6 | D90: ・AI最新技術の活用例（深層学習，自然言語処理，最適化技術）「コンピュータ入門」 ＜データサイエンス学科＞1回目 ＜情報知能学科＞1回目 ＜情報システム学科＞1回目 ＜情報メディア学科＞1回目 ＜ネットワークデザイン学科＞1回目
B91: （２）「社会で活用されているデータ」や「データの活用領域」は非常に広範囲であって、日常生活や社会の課題を解決する有用なツールになり得るもの | C91: 1-2 | D91: ・調査データ，観測データ，実験データ，ログデータ，オープンデータ、データアノテーション「コンピュータ入門」 ＜データサイエンス学科＞2回目 ＜情報知能学科＞2回目 ＜情報システム学科＞2回目 ＜情報メディア学科＞2回目 ＜ネットワークデザイン学科＞2回目
C92: 1-3 | D92: ・データ・AIが活用される分野［データ・ＡＩ活用領域の広がり］(物理・化学・生物学・法律・経済・ビジネスなど)「コンピュータ入門」 ＜データサイエンス学科＞2回目 ＜情報知能学科＞2回目 ＜情報システム学科＞2回目 ＜情報メディア学科＞2回目 ＜ネットワークデザイン学科＞2回目
B93: （３）様々なデータ利活用の現場におけるデータ利活用事例が示され、様々な適用領域（流通、製造、金融、サービス、インフラ、公共、ヘルスケア等）の知見と組み合わせることで価値を創出するもの | C93: 1-4 | D93: ・データの可視化，クラスタリング［データ解析］，予測「コンピュータ入門」 ＜データサイエンス学科＞14回目 ＜情報知能学科＞14回目 ＜情報システム学科＞14回目 ＜情報メディア学科＞14回目 ＜ネットワークデザイン学科＞14回目
C94: 1-5 | D94: ・機械学習技術・最適化技術などの概要［探索的データ解析］，データサイエンスのサイクル， IOT・ロボット［ＡＩ利活用の事例紹介］「コンピュータ入門」 ＜データサイエンス学科＞14回目 ＜情報知能学科＞14回目 ＜情報システム学科＞14回目 ＜情報メディア学科＞14回目 ＜ネットワークデザイン学科＞14回目
B95: （４）活用に当たっての様々な留意事項（ELSI、個人情報、データ倫理、ＡＩ社会原則等）を考慮し、情報セキュリティや情報漏洩等、データを守る上での留意事項への理解をする | C95: 3-1 | D95: ・ELSI、GDPR、プライバシー保護、人間中心のAI社会原理、データ取り扱いの健全性、個人情報とプライバシー、データバイアス、アルゴリズムバイアス、社会的合意の形成、AIサービスの責任論「情報技術者論」 ＜情報知能学科＞7回目 ＜情報システム学科＞7回目 ＜情報メディア学科＞7回目 ＜ネットワークデザイン学科＞7回目 ※ データサイエンス学科は2021年度に開設され、3年次配当科目のため2022年度は不開講。2023年度から開講。
C96: 3-2 | D96: ・情報セキュリティ、データの保護手法、情報漏洩等によるセキュリティ事故の事例紹介「情報技術者論」 ＜情報知能学科＞7回目 ＜情報システム学科＞7回目 ＜情報メディア学科＞7回目 ＜ネットワークデザイン学科＞7回目 ※ データサイエンス学科は2021年度に開設され、3年次配当科目のため2022年度は不開講。2023年度から開講。
...

Sheet 様式１ー４　プログラムを構成する授業科目
R1: 様式１ー４ | T1: 「学部・学科によって、修了要件は相違する」場合は、本シートを複製の上＜様式１－〇＞と枝番号を付してください
B2: 大学等名 | C2: 大阪工業大学
B3: プログラム名 | C3: OIT MDASH（リテラシー）
A5: プログラムを構成する授業科目について
A7: ① 対象となる学部・学科名称 | J7: ② 教育プログラムの修了要件 | K7: 学部・学科によって、修了要件は相違する
B9: 知的財産学部
A12: ③ 修了要件
B13: プログラムを構成する科目のうち、次の要件①②いずれも満たすこと。 ①「ICTリテラシー」および「データリテラシー」を修得すること。 ②「情報技術と特許」または「知財情報分析」いずれかを修得すること。 | V13: 【プルダウンリスト】
V14: 令和４年度以前より、履修することが必須のプログラムとして実施
V15: 令和７年度までに履修必須とする計画
V16: 令和８年度以降に履修必須とする計画、又は未定
B20: 必要最低単位数 | C20: 6 | E20: 単位 | J20: 履修必須の有無 | K20: 令和８年度以降に履修必須とする計画、又は未定
A22: ④ 現在進行中の社会変化（第４次産業革命、Society 5.0、データ駆動型社会等）に深く寄与しているものであり、それが自らの生活と密接に結びついている」の内容を含む授業科目
B24: 授業科目 | F24: 単位数 | G24: 必須 | H24: 1-1 | I24: 1-6 | J24: 授業科目 | P24: 単位数 | Q24: 必須 | R24: 1-1 | S24: 1-6
B25: ICTリテラシー | F25: 2 | G25: ○ | H25: ○ | I25: ○
B26: 情報技術と特許 | F26: 2 | H26: ○
A33: ⑤ 「社会で活用されているデータ」や「データの活用領域」は非常に広範囲であって、日常生活や社会の課題を解決する有用なツールになり得るもの」の内容を含む授業科目
B35: 授業科目 | F35: 単位数 | G35: 必須 | H35: 1-2 | I35: 1-3 | J35: 授業科目 | P35: 単位数 | Q35: 必須 | R35: 1-2 | S35: 1-3
B36: データリテラシー | F36: 2 | G36: ○ | H36: ○ | I36: ○
A44: ⑥ 「様々なデータ利活用の現場におけるデータ利活用事例が示され、様々な適用領域（流通、製造、金融、サービス、インフラ、公共、ヘルスケア等）の知見と組み合わせることで価値を創出するもの」の内容を含む授業科目
B46: 授業科目 | F46: 単位数 | G46: 必須 | H46: 1-4 | I46: 1-5 | J46: 授業科目 | P46: 単位数 | Q46: 必須 | R46: 1-4 | S46: 1-5
B47: ICTリテラシー | F47: 2 | G47: ○ | H47: ○ | I47: ○
A55: ⑦ 「活用に当たっての様々な留意事項（ELSI、個人情報、データ倫理、ＡＩ社会原則等）を考慮し、情報セキュリティや情報漏洩等、データを守る上での留意事項への理解をする」の内容を含む授業科目
B57: 授業科目 | F57: 単位数 | G57: 必須 | H57: 3-1 | I57: 3-2 | J57: 授業科目 | P57: 単位数 | Q57: 必須 | R57: 3-1 | S57: 3-2
B58: データリテラシー | F58: 2 | G58: ○ | H58: ○ | I58: ○
A66: ⑧ 「実データ・実課題（学術データ等を含む）を用いた演習など、社会での実例を題材として、「データを読む、説明する、扱う」といった数理・データサイエンス・ＡＩの基本的な活用法に関するもの」の内容を含む授業科目
B68: 授業科目 | E68: 単位数 | F68: 必須 | G68: 2-1 | H68: 2-2 | I68: 2-3 | J68: 授業科目 | O68: 単位数 | P68: 必須 | Q68: 2-1 | R68: 2-2 | S68: 2-3
B69: ICTリテラシー | E69: 2 | F69: ○ | H69: ○ | I69: ○
B70: データリテラシー | E70: 2 | F70: ○ | G70: ○ | H70: ○ | I70: ○
B71: 知財情報分析 | E71: 2 | G71: ○ | H71: ○ | I71: ○
A77: ⑨ 選択「４．オプション」の内容を含む授業科目
B78: 授業科目 | F78: 選択項目 | J78: 授業科目 | P78: 選択項目
B79: 情報技術と特許 | F79: 4‐3データ構造とプログラミング基礎
B80: ＩＣＴリテラシー | F80: 4‐4時系列データ解析
B81: 知財情報分析 | F81: 4‐4時系列データ解析
B82: 知財情報分析 | F82: 4‐5テキスト解析
A87: ⑩ プログラムを構成する授業の内容
B88: 授業に含まれている内容・要素 | D88: 講義内容
B89: （１）現在進行中の社会変化（第４次産業革命、Society 5.0、データ駆動型社会等）に深く寄与しているものであり、それが自らの生活と密接に結びついている | C89: 1-1 | D89: ・コンピュータの進化［計算機の処理性能の向上］、IoT, AI, ビックデータ，Society 5.0「ICTリテラシー」（1・3・5・6回目） ・コンピュータの進化［計算機の処理性能の向上］、IoT, AI, ビックデータ，Society 5.0「情報技術と特許」（2回目）
C90: 1-6 | D90: AI最新技術の活用例（深層学習，自然言語処理，最適化技術）「ICTリテラシー」（3・5回目）
...

Sheet 様式２ 履修者等数の実績
AQ1: 様式２
AL2: 大学等名 | AM2: ='様式１ー１ プログラムを構成する授業科目'!C2 -> 大阪工業大学
A3: プログラムの履修者数等の実績について
A5: ①プログラム開設年度 | C5: 令和４ | E5: 年度
A7: ②履修者・修了者の実績
B9: 学部・学科名称 | C9: 学生数 | D9: 入学 定員 | E9: 収容 定員 | F9: 令和4年度 | L9: 令和3年度 | R9: 令和2年度 | X9: 令和元年度 | AD9: 平成30年度 | AJ9: 平成29年度 | AP9: 履修者数 合計 | AQ9: 履修率
F10: 履修者数 | I10: 修了者数 | L10: 履修者数 | O10: 修了者数 | R10: 履修者数 | U10: 修了者数 | X10: 履修者数 | AA10: 修了者数 | AD10: 履修者数 | AG10: 修了者数 | AJ10: 履修者数 | AM10: 修了者数
F11: 合計 | G11: 男性 | H11: 女性 | I11: 合計 | J11: 男性 | K11: 女性 | L11: 合計 | M11: 男性 | N11: 女性 | O11: 合計 | P11: 男性 | Q11: 女性 | R11: 合計 | S11: 男性 | T11: 女性 | U11: 合計 | V11: 男性 | W11: 女性 | X11: 合計 | Y11: 男性 | Z11: 女性 | AA11: 合計 | AB11: 男性 | AC11: 女性 | AD11: 合計 | AE11: 男性 | AF11: 女性 | AG11: 合計 | AH11: 男性 | AI11: 女性 | AJ11: 合計 | AK11: 男性 | AL11: 女性 | AM11: 合計 | AN11: 男性 | AO11: 女性
B12: 工学部 | C12: 3803 | D12: 900 | E12: 3680 | F12: 899 | G12: 773 | H12: 126 | I12: =J12+K12 -> 0 | L12: =M12+N12 -> 0 | O12: =P12+Q12 -> 0 | R12: =S12+T12 -> 0 | U12: =V12+W12 -> 0 | X12: =Y12+Z12 -> 0 | AA12: =AB12+AC12 -> 0 | AD12: =AE12+AF12 -> 0 | AG12: =AH12+AI12 -> 0 | AJ12: =AK12+AL12 -> 0 | AM12: =AN12+AO12 -> 0 | AP12: =F12+L12+R12+X12+AD12+AJ12 -> 899 | AQ12: =AP12/E12 -> 0.24429348
B13: ロボティクス＆デザイン工学部 | C13: 1233 | D13: 280 | E13: 1150 | F13: 295 | G13: 225 | H13: 70 | I13: =J13+K13 -> 0 | L13: =M13+N13 -> 0 | O13: =P13+Q13 -> 0 | R13: =S13+T13 -> 0 | U13: =V13+W13 -> 0 | X13: =Y13+Z13 -> 0 | AA13: =AB13+AC13 -> 0 | AD13: =AE13+AF13 -> 0 | AG13: =AH13+AI13 -> 0 | AJ13: =AK13+AL13 -> 0 | AM13: =AN13+AO13 -> 0 | AP13: =F13+L13+R13+X13+AD13+AJ13 -> 295 | AQ13: =AP13/E13 -> 0.25652174
B14: 情報科学部 | C14: 1877 | D14: 460 | E14: 1880 | F14: 431 | G14: 381 | H14: 50 | I14: =J14+K14 -> 0 | L14: =M14+N14 -> 0 | O14: =P14+Q14 -> 0 | R14: =S14+T14 -> 0 | U14: =V14+W14 -> 0 | X14: =Y14+Z14 -> 0 | AA14: =AB14+AC14 -> 0 | AD14: =AE14+AF14 -> 0 | AG14: =AH14+AI14 -> 0 | AJ14: =AK14+AL14 -> 0 | AM14: =AN14+AO14 -> 0 | AP14: =F14+L14+R14+X14+AD14+AJ14 -> 431 | AQ14: =AP14/E14 -> 0.22925532
B15: 知的財産学部 | C15: 596 | D15: 140 | E15: 580 | F15: 142 | G15: 123 | H15: 19 | I15: =J15+K15 -> 0 | L15: =M15+N15 -> 0 | O15: =P15+Q15 -> 0 | R15: =S15+T15 -> 0 | U15: =V15+W15 -> 0 | X15: =Y15+Z15 -> 0 | AA15: =AB15+AC15 -> 0 | AD15: =AE15+AF15 -> 0 | AG15: =AH15+AI15 -> 0 | AJ15: =AK15+AL15 -> 0 | AM15: =AN15+AO15 -> 0 | AP15: =F15+L15+R15+X15+AD15+AJ15 -> 142 | AQ15: =AP15/E15 -> 0.24482759
F16: =G16+H16 -> 0 | I16: =J16+K16 -> 0 | L16: =M16+N16 -> 0 | O16: =P16+Q16 -> 0 | R16: =S16+T16 -> 0 | U16: =V16+W16 -> 0 | X16: =Y16+Z16 -> 0 | AA16: =AB16+AC16 -> 0 | AD16: =AE16+AF16 -> 0 | AG16: =AH16+AI16 -> 0 | AJ16: =AK16+AL16 -> 0 | AM16: =AN16+AO16 -> 0 | AP16: =F16+L16+R16+X16+AD16+AJ16 -> 0 | AQ16: =AP16/E16 -> #DIV/0!
F17: =G17+H17 -> 0 | I17: =J17+K17 -> 0 | L17: =M17+N17 -> 0 | O17: =P17+Q17 -> 0 | R17: =S17+T17 -> 0 | U17: =V17+W17 -> 0 | X17: =Y17+Z17 -> 0 | AA17: =AB17+AC17 -> 0 | AD17: =AE17+AF17 -> 0 | AG17: =AH17+AI17 -> 0 | AJ17: =AK17+AL17 -> 0 | AM17: =AN17+AO17 -> 0 | AP17: =F17+L17+R17+X17+AD17+AJ17 -> 0 | AQ17: =AP17/E17 -> #DIV/0!
F18: =G18+H18 -> 0 | I18: =J18+K18 -> 0 | L18: =M18+N18 -> 0 | O18: =P18+Q18 -> 0 | R18: =S18+T18 -> 0 | U18: =V18+W18 -> 0 | X18: =Y18+Z18 -> 0 | AA18: =AB18+AC18 -> 0 | AD18: =AE18+AF18 -> 0 | AG18: =AH18+AI18 -> 0 | AJ18: =AK18+AL18 -> 0 | AM18: =AN18+AO18 -> 0 | AP18: =F18+L18+R18+X18+AD18+AJ18 -> 0 | AQ18: =AP18/E18 -> #DIV/0!
F19: =G19+H19 -> 0 | I19: =J19+K19 -> 0 | L19: =M19+N19 -> 0 | O19: =P19+Q19 -> 0 | R19: =S19+T19 -> 0 | U19: =V19+W19 -> 0 | X19: =Y19+Z19 -> 0 | AA19: =AB19+AC19 -> 0 | AD19: =AE19+AF19 -> 0 | AG19: =AH19+AI19 -> 0 | AJ19: =AK19+AL19 -> 0 | AM19: =AN19+AO19 -> 0 | AP19: =F19+L19+R19+X19+AD19+AJ19 -> 0 | AQ19: =AP19/E19 -> #DIV/0!
F20: =G20+H20 -> 0 | I20: =J20+K20 -> 0 | L20: =M20+N20 -> 0 | O20: =P20+Q20 -> 0 | R20: =S20+T20 -> 0 | U20: =V20+W20 -> 0 | X20: =Y20+Z20 -> 0 | AA20: =AB20+AC20 -> 0 | AD20: =AE20+AF20 -> 0 | AG20: =AH20+AI20 -> 0 | AJ20: =AK20+AL20 -> 0 | AM20: =AN20+AO20 -> 0 | AP20: =F20+L20+R20+X20+AD20+AJ20 -> 0 | AQ20: =AP20/E20 -> #DIV/0!
F21: =G21+H21 -> 0 | I21: =J21+K21 -> 0 | L21: =M21+N21 -> 0 | O21: =P21+Q21 -> 0 | R21: =S21+T21 -> 0 | U21: =V21+W21 -> 0 | X21: =Y21+Z21 -> 0 | AA21: =AB21+AC21 -> 0 | AD21: =AE21+AF21 -> 0 | AG21: =AH21+AI21 -> 0 | AJ21: =AK21+AL21 -> 0 | AM21: =AN21+AO21 -> 0 | AP21: =F21+L21+R21+X21+AD21+AJ21 -> 0 | AQ21: =AP21/E21 -> #DIV/0!
F22: =G22+H22 -> 0 | I22: =J22+K22 -> 0 | L22: =M22+N22 -> 0 | O22: =P22+Q22 -> 0 | R22: =S22+T22 -> 0 | U22: =V22+W22 -> 0 | X22: =Y22+Z22 -> 0 | AA22: =AB22+AC22 -> 0 | AD22: =AE22+AF22 -> 0 | AG22: =AH22+AI22 -> 0 | AJ22: =AK22+AL22 -> 0 | AM22: =AN22+AO22 -> 0 | AP22: =F22+L22+R22+X22+AD22+AJ22 -> 0 | AQ22: =AP22/E22 -> #DIV/0!
F23: =G23+H23 -> 0 | I23: =J23+K23 -> 0 | L23: =M23+N23 -> 0 | O23: =P23+Q23 -> 0 | R23: =S23+T23 -> 0 | U23: =V23+W23 -> 0 | X23: =Y23+Z23 -> 0 | AA23: =AB23+AC23 -> 0 | AD23: =AE23+AF23 -> 0 | AG23: =AH23+AI23 -> 0 | AJ23: =AK23+AL23 -> 0 | AM23: =AN23+AO23 -> 0 | AP23: =F23+L23+R23+X23+AD23+AJ23 -> 0 | AQ23: =AP23/E23 -> #DIV/0!
F24: =G24+H24 -> 0 | I24: =J24+K24 -> 0 | L24: =M24+N24 -> 0 | O24: =P24+Q24 -> 0 | R24: =S24+T24 -> 0 | U24: =V24+W24 -> 0 | X24: =Y24+Z24 -> 0 | AA24: =AB24+AC24 -> 0 | AD24: =AE24+AF24 -> 0 | AG24: =AH24+AI24 -> 0 | AJ24: =AK24+AL24 -> 0 | AM24: =AN24+AO24 -> 0 | AP24: =F24+L24+R24+X24+AD24+AJ24 -> 0 | AQ24: =AP24/E24 -> #DIV/0!
F25: =G25+H25 -> 0 | I25: =J25+K25 -> 0 | L25: =M25+N25 -> 0 | O25: =P25+Q25 -> 0 | R25: =S25+T25 -> 0 | U25: =V25+W25 -> 0 | X25: =Y25+Z25 -> 0 | AA25: =AB25+AC25 -> 0 | AD25: =AE25+AF25 -> 0 | AG25: =AH25+AI25 -> 0 | AJ25: =AK25+AL25 -> 0 | AM25: =AN25+AO25 -> 0 | AP25: =F25+L25+R25+X25+AD25+AJ25 -> 0 | AQ25: =AP25/E25 -> #DIV/0!
F26: =G26+H26 -> 0 | I26: =J26+K26 -> 0 | L26: =M26+N26 -> 0 | O26: =P26+Q26 -> 0 | R26: =S26+T26 -> 0 | U26: =V26+W26 -> 0 | X26: =Y26+Z26 -> 0 | AA26: =AB26+AC26 -> 0 | AD26: =AE26+AF26 -> 0 | AG26: =AH26+AI26 -> 0 | AJ26: =AK26+AL26 -> 0 | AM26: =AN26+AO26 -> 0 | AP26: =F26+L26+R26+X26+AD26+AJ26 -> 0 | AQ26: =AP26/E26 -> #DIV/0!
F27: =G27+H27 -> 0 | I27: =J27+K27 -> 0 | L27: =M27+N27 -> 0 | O27: =P27+Q27 -> 0 | R27: =S27+T27 -> 0 | U27: =V27+W27 -> 0 | X27: =Y27+Z27 -> 0 | AA27: =AB27+AC27 -> 0 | AD27: =AE27+AF27 -> 0 | AG27: =AH27+AI27 -> 0 | AJ27: =AK27+AL27 -> 0 | AM27: =AN27+AO27 -> 0 | AP27: =F27+L27+R27+X27+AD27+AJ27 -> 0 | AQ27: =AP27/E27 -> #DIV/0!
... F31: =G31+H31 -> 0 | I31: =J31+K31 -> 0 | L31: =M31+N31 -> 0 | O31: =P31+Q31 -> 0 | R31: =S31+T31 -> 0 | U31: =V31+W31 -> 0 | X31: =Y31+Z31 -> 0 | AA31: =AB31+AC31 -> 0 | AD31: =AE31+AF31 -> 0 | AG31: =AH31+AI31 -> 0 | AJ31: =AK31+AL31 -> 0 | AM31: =AN31+AO31 -> 0 | AP31: =F31+L31+R31+X31+AD31+AJ31 -> 0 | AQ31: =AP31/E31 -> #DIV/0!
B32: 合 計 | C32: =SUM(C12:C31) -> 7509 | D32: =SUM(D12:D31) -> 1780 | E32: =SUM(E12:E31) -> 7290 | F32: =SUM(F12:F31) -> 1767 | G32: =SUM(G12:G31) -> 1502 | H32: =SUM(H12:H31) -> 265 | I32: =SUM(I12:I31) -> 0 | J32: =SUM(J12:J31) -> 0 | ... AP32: =SUM(AP12:AP31) -> 1767 | AQ32: =AP32/E32 -> 0.24238683

Sheet 様式３ 教育の質・履修者数を向上させるための体制・計画
I1: 様式３
G2: 大学等名 | H2: ='様式１ー１ プログラムを構成する授業科目'!C2 -> 大阪工業大学
A4: 教育の質・履修者数を向上させるための体制・計画について
A6: ① | B6: 全学の教員数 | C6: (常勤） | E6: 292 | F6: 人 | G6: （非常勤） | H6: 396 | I6: 人
A8: ② | B8: プログラムの授業を教えている教員数 | H8: 57 | I8: 人
A10: ③ | B10: プログラムの運営責任者
B11: （責任者名） | C11: 椋平 淳 | G11: （役職名） | H11: 教務部長
A13: ④ | B13: プログラムを改善・進化させるための体制（委員会・組織等）
B14: 大阪工業大学教務委員会
B16: （責任者名） | C16: 椋平 淳 | G16: （役職名） | H16: 教務部長
A18: ⑤ | B18: プログラムを改善・進化させるための体制を定める規則名称
B19: 大阪工業大学教務委員会規定
A21: ⑥ | B21: 体制の目的
B22: 教務委員会は、本学学則に基づき設置された委員会であり、時間割編成や教育課程の改正等、教務に関する重要な事項の審議、ならびに各学部間の連絡調整を行う組織である。 教務委員会では、文理問わず、全学部の学生が数理・データサイエンス・AIへの関心を高め、かつ、数理・データサイエンス・AIを適切に理解し、それを活用する基礎的な能力の育成を目的とした、本プログラムの内容や全学的な普及状況を確認し、必要に応じて全学部に関わるカリキュラムの改訂を検討する。 | K22: =LEN(B22) -> 222
A34: ⑦ | B34: 具体的な構成員
B35: 椋平 淳 教務部長(委員長） 森内隆代 教育センター長（副委員長） 田中 克佳 教務課長 山口 行一 工学部教授（学部長推薦、学長任命） 吉田 準史 工学部教授（学部長推薦、学長任命） 東本 慎也 工学部教授（学部長推薦、学長任命） 谷 保孝 工学部教授（学部長推薦、学長任命） 辻本 智子 工学部教授（学部長推薦、学長任命） 倉前宏行 ロボティクス＆デザイン工学部教授（学部長推薦、学長任命） 中山 学之 ロボティクス＆デザイン工学部教授（学部長推薦、学長任命） 白髪 誠一 ロボティクス＆デザイン工学部教授（学部長推薦、学長任命） 福安 直樹 情報科学部教授（学部長推薦、学長任命） 西口 敏司 情報科学部教授（学部長推薦、学長任命） 廣田 義人 知的財産学部教授（学部長推薦、学長任命） 五丁 龍志 知的財産学部教授（学部長推薦、学長任命） 大塚 理彦 大学院知的財産研究科教授（研究科長推薦、学長任命）
A48: ⑧ | B48: 履修者数・履修率の向上に向けた計画 ※様式１の「履修必須の有無」で「計画がある」としている場合は詳細について記載すること
B49: 令和４年度実績 | C49: ='様式２ 履修者等数の実績'!AQ32 -> 0.24238683 | E49: 令和５年度予定 | F49: 0.4 | H49: 令和６年度予定 | I49: 0.55
B50: 令和７年度予定 | C50: 0.65 | E50: 令和８年度予定 | F50: 0.7 | H50: 収容定員（名） | I50: ='様式２ 履修者等数の実績'!E32 -> 7290
B51: 具体的な計画
B52: 各学部の専門教育において既存の授業科目の学びを通じた教育体制の利点を生かし、学生の半数以上が卒業までに本教育プログラムの修了要件に該当する授業科目を学習している状態をめざす。この達成のために、教務委員会および各学部の教務（担当）委員会が中心となり、本教育プログラムの学内広報を強化し、学生への周知を進める。 具体的には、本教育プログラムの意義や特色の周知について、新入生ガイダンスおよび従来から整備される入学初年次の少人数クラスによる導入教育を通じたクラス担任教員からの指導の両側面から推進する。 また、今後学内ポータルサイトへの掲載や、学生が頻繁に確認する正課課程の履修申請要領における掲載も視野に入れて進める。 | J52: 307 | K52: =LEN(B52) -> 307
A65: ⑨ | B65: 学部・学科に関係なく希望する学生全員が受講可能となるような必要な体制・取組等
B66: 各学部の専門教育において、 既存の授業科目の学びを通じた教育体制を敷いており、希望する学生全員が受講可能である。 | J66: 56 | K66: =LEN(B66) -> 56
A79: ⑩ | B79: できる限り多くの学生が履修できるような具体的な周知方法・取組
B80: 本教育プログラムを構成する科目の大半は低年次配当科目としている。 特に初年次次配当科目では、学部によっては必修科目としているほか、必修ではないものの、所属学科で４年間学修する上で、1年次時の履修が特に望ましい科目と位置付けている。これらの科目は時間割表上において容易に識別できるようマークを付すとともに、原則として必ず履修するよう新入生ガイダンスで徹底的に指導している。 | J80: 185 | K80: =LEN(B80) -> 185
A93: ⑪ | B93: できる限り多くの学生が履修・修得できるようなサポート体制
B94: 各学部とも初年次に少人数クラスによる導入教育を実施しており、円滑に履修・修得できるようクラス担任教員をはじめ、各キャンパス教務部署とも連携し学修支援を行っている。 本教育プログラムを構成する一部の科目において3年次配当科目が用意されているが、本学では高学年次でも卒業研究プレ配属や卒業研究等の指導教員が配属学生の担任となる体制を整えているため、多くの学生が途切れなく履修・修得できるサポート体制を構築している。 | J94: 205 | K94: =LEN(B94) -> 205
A107: ⑫ | B107: 授業時間内外で学習指導、質問を受け付ける具体的な仕組み
B108: 授業内での質疑応答のほか、授業担当者は必ずオフィスアワーを設定（原則週1回）し、曜日・時間・場所等をシラバスに明記することを義務付けており、学生は迷いなく相談に行くことができる環境を整備している。 | J108: 98 | K108: =LEN(B108) -> 98

Sheet 様式４　自己点検・評価
I1: 様式４
H2: 大学等名 | I2: ='様式１ー１ プログラムを構成する授業科目'!C2 -> 大阪工業大学
A3: 自己点検・評価について
A5: ① | B5: プログラムの自己点検・評価を行う体制（委員会・組織等）
B6: 大阪工業大学教務委員会
D8: （責任者名） | E8: 椋平 淳 | G8: （役職名） | H8: 教務部長
A10: ② | B10: 自己点検・評価体制における意見等
B11: 自己点検・評価の視点 | E11: 自己点検・評価体制における意見・結果・改善に向けた取組等
B12: 学内からの視点
C13: プログラムの履修・修得状況 | E13: 教務委員会において、本教育プログラム対象科目の履修者データを基に、履修状況を分析し、プログラム修了をめざす学生の状況を把握している。 本教育プログラムは2022年度から開設し、実績は2022年度の1年間のみである。 履修者が1年次のみのため、収容定員に対する履修率は当然低くなっているが、入学者数に対する履修率はいずれの学部も100％近く、良好な結果となっている。 | K13: 182 | L13: =LEN(E13) -> 182
C14: 学修成果 | E14: シラバスでは授業計画で何を学ぶかを具体的に示し、適切な到達目標を設定している。独自アンケートでは、該当する授業回の理解度を問う設問により、学修成果を把握し、教務委員会（全学・各学部）で評価・改善に活用している。 | K14: 105 | L14: =LEN(E14) -> 105
C15: 学生アンケート等を通じた学生の内容の理解度 | E15: 本教育プログラム受講者全員に対して実施している独自アンケートの該当する授業回の理解度を問う設問により、学生の理解度を把握している。アンケート結果では学部間に多少の差は存在するものの、概ね肯定的な意見が確認された。授業後の小テスト実施や学部学科の学びに応じた独自の資料を作成するなど工夫を凝らした事例が寄与したと推察される。その一方、アンケート回収率が低調な科目も一部確認された。これはMDASHに対する関心度が希薄な学生が一定数存在している可能性が考えられる。授業内はもとより、各年度毎に実施する翌年度履修ガイダンスにおいて一層MDASHに対する意義を周知していく。 | K15: 284 | L15: =LEN(E15) -> 283
C16: 学生アンケート等を通じた後輩等他の学生への推奨度 | E16: 本教育プログラム受講者全員に対して実施している独自アンケートの該当する授業回の重要度を問う設問により、本教育プログラムを通して学んだことを後輩に伝え、推奨していく期待度を確認している。アンケートでは、OIT-MDASHに関係する授業回の受講前後と比べ、重要性の認識が高まったかについて問い、その結果は学部間に多少の差が見受けられるものの、「かなり高まった」「ある程度高まった」が6～7割を占め、後輩に伝え受講を推奨していくことに期待ができる結果となっている。 | K16: 229 | L16: =LEN(E16) -> 229
C17: 全学的な履修者数、履修率向上に向けた計画の達成・進捗状況 | E17: 対象科目の履修状況は、「プログラムの履修・修得状況」に記載のとおり良好である。これは本教育プログラムを構成する科目のうち、１年次に配当している科目において、情報科学部では必修化、それ以外の学部においても学修することが特に望ましい科目に位置付け、原則全員が履修する取り扱いとしているためである。加えて、科目の取り扱いのみにとどまらず、新入生ガイダンスにおける案内チラシの配付・説明を実施し、MDASHへの認知度向上に向けて推進している。 | K17: 207 | L17: =LEN(E17) -> 217
B18: 学外からの視点
C19: 教育プログラム修了者の進路、活躍状況、企業等の評価 | E19: 本学では自己評価・IR委員会の小委員会において外部評価委員会を設置し、産業界からの視点も含めた教育課程に対する検証が図れる仕組みとなっている。本教育プログラムは2022年度から一斉実施しているため、実質的に多数の修了者を輩出する年度は2025年度であり、適正な評価が可能となる年度に達していない。しかし、「卒業生アンケート」（卒業後3年目対象）および「企業アンケート」に関連する設問を追加しており、本プログラム修了生を輩出する前段階で可能な限り企業等のニーズの把握に努めている。 | K19: 202 | L19: =LEN(E19) -> 240
C20: 産業界からの視点を含めた教育プログラム内容・手法等への意見 | E20: 本学の教育の質保証にかかる自己点検・評価にあたり、外部評価委員会を設置し年1回定期的に実施しており、本教育プログラムにおいても同委員会に諮り評価や意見を収集している。 2022年度では、各学部の専門教育における既存の授業科目の学びを通じた教育体制や、教務委員会において自己点検・評価を行った内容に対して、MDASHに関する標準的な能力向上への寄与が見込まれ期待できるとの肯定的な意見が得られた。一方、独自アンケートを通じて得られた改善に向けた課題について、順を追って見直していくことが肝要となる等の意見も付された。得られた意見等については教務委員会を通じて全学的に共有を図っていく。 | K20: 291 | L20: =LEN(E20) -> 291
B21: 数理・データサイエンス・ＡＩを「学ぶ楽しさ」「学ぶことの意義」を理解させること | E21: 本教育プログラム受講者全員に対して実施している該当する授業回の受講によりMDASHに対する興味・関心度が高まったかを問う設問により把握している。「かなり高まった」、「ある程度高まった」が6割近くを占める結果となり、概ね良好な結果となった。本教育プログラムを構成する科目群では、一部はアクティブな手法（グループワーク等）を採り入れるなどの工夫がみられるほか、所属学部学科の学びに即した実社会におけるMDASHの活用事例数を増やしていく等によって、既に一定の理解がある学生に対する向上策の検討も計画されており、今後の改善に期待ができる。 | K21: 266 | L21: =LEN(E21) -> 266
B22: 内容・水準を維持・向上しつつ、より「分かりやすい」授業とすること | E22: 独自アンケートを通じて、該当する授業回の授業が分かりやすかったかを問う設問により、学生の反応をダイレクトに収集している。「強くそう思う」「ややそう思う」が6～7割を占める結果となり概ね肯定的な結果となっている。さらに、当該授業に関する改善要望の有無を問う設問もあわせて収集しており、否定的な意見では、「よくわからなかった」が大半を占めている。具体例を示すだけでなく、所属学科の学びに関連付けた事例を交えたり、グループワークを活用している授業も見受けられており、それらの成功例も参考にアンケート結果を学内全体に共有し、プログラム全体の内容・水準の維持・向上に向けて推進している。 | K22: 290 | L22: =LEN(E22) -> 288
