Workbook

Sheet 様式１ー１　プログラムを構成する授業科目
R1: 様式１－１ | T1: 「学部・学科によって、修了要件は相違する」場合は、本シートを複製の上＜様式１－〇＞と枝番号を付してください
B2: 大学等名 | C2: 宇部工業高等専門学校
B3: プログラム名 | C3: 宇部工業高等専門学校数理・データサイエンス・ＡＩ教育プログラム
A5: プログラムを構成する授業科目について
A7: ① 対象となる学部・学科名称 | J7: ② 教育プログラムの修了要件 | K7: 学部・学科によって、修了要件は相違する
B9: 機械工学科
A12: ③ 修了要件
B13: プログラムを構成する下記の科目すべてを修得すること。 全学科共通科目のジェネリックスキルⅠ～Ⅳ及び機械工学科の計測工学A、工学実験、情報Ⅲ | V13: 【プルダウンリスト】
V14: 令和４年度以前より、履修することが必須のプログラムとして実施
V15: 令和７年度までに履修必須とする計画
V16: 令和８年度以降に履修必須とする計画、又は未定
B20: 必要最低単位数 | C20: 8 | E20: 単位 | J20: 履修必須の有無 | K20: 令和４年度以前より、履修することが必須のプログラムとして実施
A22: ④ 現在進行中の社会変化（第４次産業革命、Society 5.0、データ駆動型社会等）に深く寄与しているものであり、それが自らの生活と密接に結びついている」の内容を含む授業科目
B24: 授業科目 | F24: 単位数 | G24: 必須 | H24: 1-1 | I24: 1-6 | J24: 授業科目 | P24: 単位数 | Q24: 必須 | R24: 1-1 | S24: 1-6
B25: ジェネリックスキルⅠ | F25: 1 | G25: ○ | H25: ○
B26: ジェネリックスキルⅣ | F26: 1 | G26: ○ | I26: ○
A33: ⑤ 「社会で活用されているデータ」や「データの活用領域」は非常に広範囲であって、日常生活や社会の課題を解決する有用なツールになり得るもの」の内容を含む授業科目
B35: 授業科目 | F35: 単位数 | G35: 必須 | H35: 1-2 | I35: 1-3 | J35: 授業科目 | P35: 単位数 | Q35: 必須 | R35: 1-2 | S35: 1-3
B36: ジェネリックスキルⅢ | F36: 1 | G36: ○ | H36: ○
B37: ジェネリックスキルⅠ | F37: 1 | G37: ○ | I37: ○
A44: ⑥ 「様々なデータ利活用の現場におけるデータ利活用事例が示され、様々な適用領域（流通、製造、金融、サービス、インフラ、公共、ヘルスケア等）の知見と組み合わせることで価値を創出するもの」の内容を含む授業科目
B46: 授業科目 | F46: 単位数 | G46: 必須 | H46: 1-4 | I46: 1-5 | J46: 授業科目 | P46: 単位数 | Q46: 必須 | R46: 1-4 | S46: 1-5
B47: ジェネリックスキルⅢ | F47: 1 | G47: ○ | H47: ○
B48: ジェネリックスキルⅣ | F48: 1 | G48: ○ | H48: ○
B49: ジェネリックスキルⅠ | F49: 1 | G49: ○ | I49: ○
A55: ⑦ 「活用に当たっての様々な留意事項（ELSI、個人情報、データ倫理、ＡＩ社会原則等）を考慮し、情報セキュリティや情報漏洩等、データを守る上での留意事項への理解をする」の内容を含む授業科目
B57: 授業科目 | F57: 単位数 | G57: 必須 | H57: 3-1 | I57: 3-2 | J57: 授業科目 | P57: 単位数 | Q57: 必須 | R57: 3-1 | S57: 3-2
B58: ジェネリックスキルⅠ | F58: 1 | G58: ○ | I58: ○
B59: ジェネリックスキルⅡ | F59: 1 | G59: ○ | H59: ○ | I59: ○
B60: ジェネリックスキルⅢ | F60: 1 | G60: ○ | I60: ○
B61: ジェネリックスキルⅣ | F61: 1 | G61: ○ | I61: ○
A66: ⑧ 「実データ・実課題（学術データ等を含む）を用いた演習など、社会での実例を題材として、「データを読む、説明する、扱う」といった数理・データサイエンス・ＡＩの基本的な活用法に関するもの」の内容を含む授業科目
B68: 授業科目 | E68: 単位数 | F68: 必須 | G68: 2-1 | H68: 2-2 | I68: 2-3 | J68: 授業科目 | O68: 単位数 | P68: 必須 | Q68: 2-1 | R68: 2-2 | S68: 2-3
B69: ジェネリックスキルⅠ | E69: 1 | F69: ○ | G69: ○ | H69: ○
B70: 計測工学Ａ | E70: 1 | F70: ○ | G70: ○
B71: 工学実験 | E71: 2 | F71: ○ | H71: ○
B72: 情報Ⅲ | E72: 1 | F72: ○ | I72: ○
A77: ⑨ 選択「４．オプション」の内容を含む授業科目
B78: 授業科目 | F78: 選択項目 | J78: 授業科目 | P78: 選択項目
A87: ⑩ プログラムを構成する授業の内容
...

Sheet 様式１ー２　プログラムを構成する授業科目
R1: 様式１－２ | T1: 「学部・学科によって、修了要件は相違する」場合は、本シートを複製の上＜様式１－〇＞と枝番号を付してください
B2: 大学等名 | C2: 宇部工業高等専門学校
B3: プログラム名 | C3: 宇部工業高等専門学校数理・データサイエンス・ＡＩ教育プログラム
A5: プログラムを構成する授業科目について
A7: ① 対象となる学部・学科名称 | J7: ② 教育プログラムの修了要件 | K7: 学部・学科によって、修了要件は相違する
B9: 電気工学科
A12: ③ 修了要件
B13: プログラムを構成する下記の科目すべてを修得していること。 全学科共通科目のジェネリックスキルⅠ～Ⅳ及び電気工学科の電気工学序論A、電気工学序論C | V13: 【プルダウンリスト】
V14: 令和４年度以前より、履修することが必須のプログラムとして実施
V15: 令和７年度までに履修必須とする計画
V16: 令和８年度以降に履修必須とする計画、又は未定
B20: 必要最低単位数 | C20: 6 | E20: 単位 | J20: 履修必須の有無 | K20: 令和４年度以前より、履修することが必須のプログラムとして実施
A22: ④ 現在進行中の社会変化（第４次産業革命、Society 5.0、データ駆動型社会等）に深く寄与しているものであり、それが自らの生活と密接に結びついている」の内容を含む授業科目
B24: 授業科目 | F24: 単位数 | G24: 必須 | H24: 1-1 | I24: 1-6 | J24: 授業科目 | P24: 単位数 | Q24: 必須 | R24: 1-1 | S24: 1-6
B25: ジェネリックスキルⅠ | F25: 1 | G25: ○ | H25: ○
B26: ジェネリックスキルⅣ | F26: 1 | G26: ○ | I26: ○
A33: ⑤ 「社会で活用されているデータ」や「データの活用領域」は非常に広範囲であって、日常生活や社会の課題を解決する有用なツールになり得るもの」の内容を含む授業科目
B35: 授業科目 | F35: 単位数 | G35: 必須 | H35: 1-2 | I35: 1-3 | J35: 授業科目 | P35: 単位数 | Q35: 必須 | R35: 1-2 | S35: 1-3
B36: ジェネリックスキルⅢ | F36: 1 | G36: ○ | H36: ○
B37: ジェネリックスキルⅠ | F37: 1 | G37: ○ | I37: ○
A44: ⑥ 「様々なデータ利活用の現場におけるデータ利活用事例が示され、様々な適用領域（流通、製造、金融、サービス、インフラ、公共、ヘルスケア等）の知見と組み合わせることで価値を創出するもの」の内容を含む授業科目
B46: 授業科目 | F46: 単位数 | G46: 必須 | H46: 1-4 | I46: 1-5 | J46: 授業科目 | P46: 単位数 | Q46: 必須 | R46: 1-4 | S46: 1-5
B47: ジェネリックスキルⅢ | F47: 1 | G47: ○ | H47: ○
B48: ジェネリックスキルⅣ | F48: 1 | G48: ○ | H48: ○
B49: ジェネリックスキルⅠ | F49: 1 | G49: ○ | I49: ○
A55: ⑦ 「活用に当たっての様々な留意事項（ELSI、個人情報、データ倫理、ＡＩ社会原則等）を考慮し、情報セキュリティや情報漏洩等、データを守る上での留意事項への理解をする」の内容を含む授業科目
B57: 授業科目 | F57: 単位数 | G57: 必須 | H57: 3-1 | I57: 3-2 | J57: 授業科目 | P57: 単位数 | Q57: 必須 | R57: 3-1 | S57: 3-2
B58: ジェネリックスキルⅠ | F58: 1 | G58: ○ | I58: ○
B59: ジェネリックスキルⅡ | F59: 1 | G59: ○ | H59: ○ | I59: ○
B60: ジェネリックスキルⅢ | F60: 1 | G60: ○ | I60: ○
B61: ジェネリックスキルⅣ | F61: 1 | G61: ○ | I61: ○
A66: ⑧ 「実データ・実課題（学術データ等を含む）を用いた演習など、社会での実例を題材として、「データを読む、説明する、扱う」といった数理・データサイエンス・ＡＩの基本的な活用法に関するもの」の内容を含む授業科目
B68: 授業科目 | E68: 単位数 | F68: 必須 | G68: 2-1 | H68: 2-2 | I68: 2-3 | J68: 授業科目 | O68: 単位数 | P68: 必須 | Q68: 2-1 | R68: 2-2 | S68: 2-3
B69: ジェネリックスキルⅠ | E69: 1 | F69: ○ | G69: ○ | H69: ○
B70: 電気工学序論A | E70: 1 | F70: ○ | I70: ○
B71: 電気工学序論C | E71: 1 | F71: ○ | G71: ○ | H71: ○ | I71: ○
A77: ⑨ 選択「４．オプション」の内容を含む授業科目
B78: 授業科目 | F78: 選択項目 | J78: 授業科目 | P78: 選択項目
A87: ⑩ プログラムを構成する授業の内容
B88: 授業に含まれている内容・要素 | D88: 講義内容
...

Sheet 様式１ー３　プログラムを構成する授業科目
R1: 様式１－３ | T1: 「学部・学科によって、修了要件は相違する」場合は、本シートを複製の上＜様式１－〇＞と枝番号を付してください
B2: 大学等名 | C2: 宇部工業高等専門学校
B3: プログラム名 | C3: 宇部工業高等専門学校数理・データサイエンス・ＡＩ教育プログラム
A5: プログラムを構成する授業科目について
A7: ① 対象となる学部・学科名称 | J7: ② 教育プログラムの修了要件 | K7: 学部・学科によって、修了要件は相違する
B9: 制御情報工学科
A12: ③ 修了要件
B13: プログラムを構成する下記の科目すべてを修得していること。 全学科共通科目のジェネリックスキルⅠ～Ⅳ及び制御情報工学科の数値計算 | V13: 【プルダウンリスト】
V14: 令和４年度以前より、履修することが必須のプログラムとして実施
V15: 令和７年度までに履修必須とする計画
V16: 令和８年度以降に履修必須とする計画、又は未定
B20: 必要最低単位数 | C20: 6 | E20: 単位 | J20: 履修必須の有無 | K20: 令和４年度以前より、履修することが必須のプログラムとして実施
A22: ④ 現在進行中の社会変化（第４次産業革命、Society 5.0、データ駆動型社会等）に深く寄与しているものであり、それが自らの生活と密接に結びついている」の内容を含む授業科目
B24: 授業科目 | F24: 単位数 | G24: 必須 | H24: 1-1 | I24: 1-6 | J24: 授業科目 | P24: 単位数 | Q24: 必須 | R24: 1-1 | S24: 1-6
B25: ジェネリックスキルⅠ | F25: 1 | G25: ○ | H25: ○
B26: ジェネリックスキルⅣ | F26: 1 | G26: ○ | I26: ○
A33: ⑤ 「社会で活用されているデータ」や「データの活用領域」は非常に広範囲であって、日常生活や社会の課題を解決する有用なツールになり得るもの」の内容を含む授業科目
B35: 授業科目 | F35: 単位数 | G35: 必須 | H35: 1-2 | I35: 1-3 | J35: 授業科目 | P35: 単位数 | Q35: 必須 | R35: 1-2 | S35: 1-3
B36: ジェネリックスキルⅢ | F36: 1 | G36: ○ | H36: ○
B37: ジェネリックスキルⅠ | F37: 1 | G37: ○ | I37: ○
A44: ⑥ 「様々なデータ利活用の現場におけるデータ利活用事例が示され、様々な適用領域（流通、製造、金融、サービス、インフラ、公共、ヘルスケア等）の知見と組み合わせることで価値を創出するもの」の内容を含む授業科目
B46: 授業科目 | F46: 単位数 | G46: 必須 | H46: 1-4 | I46: 1-5 | J46: 授業科目 | P46: 単位数 | Q46: 必須 | R46: 1-4 | S46: 1-5
B47: ジェネリックスキルⅢ | F47: 1 | G47: ○ | H47: ○
B48: ジェネリックスキルⅣ | F48: 1 | G48: ○ | H48: ○
B49: ジェネリックスキルⅠ | F49: 1 | G49: ○ | I49: ○
A55: ⑦ 「活用に当たっての様々な留意事項（ELSI、個人情報、データ倫理、ＡＩ社会原則等）を考慮し、情報セキュリティや情報漏洩等、データを守る上での留意事項への理解をする」の内容を含む授業科目
B57: 授業科目 | F57: 単位数 | G57: 必須 | H57: 3-1 | I57: 3-2 | J57: 授業科目 | P57: 単位数 | Q57: 必須 | R57: 3-1 | S57: 3-2
B58: ジェネリックスキルⅠ | F58: 1 | G58: ○ | I58: ○
B59: ジェネリックスキルⅡ | F59: 1 | G59: ○ | H59: ○ | I59: ○
B60: ジェネリックスキルⅢ | F60: 1 | G60: ○ | I60: ○
B61: ジェネリックスキルⅣ | F61: 1 | G61: ○ | I61: ○
A66: ⑧ 「実データ・実課題（学術データ等を含む）を用いた演習など、社会での実例を題材として、「データを読む、説明する、扱う」といった数理・データサイエンス・ＡＩの基本的な活用法に関するもの」の内容を含む授業科目
B68: 授業科目 | E68: 単位数 | F68: 必須 | G68: 2-1 | H68: 2-2 | I68: 2-3 | J68: 授業科目 | O68: 単位数 | P68: 必須 | Q68: 2-1 | R68: 2-2 | S68: 2-3
B69: ジェネリックスキルⅠ | E69: 1 | F69: ○ | G69: ○ | H69: ○
B70: 数値計算 | E70: 2 | F70: ○ | G70: ○ | H70: ○ | I70: ○
A77: ⑨ 選択「４．オプション」の内容を含む授業科目
B78: 授業科目 | F78: 選択項目 | J78: 授業科目 | P78: 選択項目
A87: ⑩ プログラムを構成する授業の内容
B88: 授業に含まれている内容・要素 | D88: 講義内容
B89: （１）現在進行中の社会変化（第４次産業革命、Society 5.0、データ駆動型社会等）に深く寄与しているものであり、それが自らの生活と密接に結びついている | C89: 1-1 | D89: ◆ジェネリックスキルⅠ（第9回）：現代は第４次産業革命による創造社会（Society5.0）に位置付けられ、AIを用いた便利な社会形成が進められていることを学ぶ。
...

Sheet 様式１ー４　プログラムを構成する授業科目
R1: 様式１－４ | T1: 「学部・学科によって、修了要件は相違する」場合は、本シートを複製の上＜様式１－〇＞と枝番号を付してください
B2: 大学等名 | C2: 宇部工業高等専門学校
B3: プログラム名 | C3: 宇部工業高等専門学校数理・データサイエンス・ＡＩ教育プログラム
A5: プログラムを構成する授業科目について
A7: ① 対象となる学部・学科名称 | J7: ② 教育プログラムの修了要件 | K7: 学部・学科によって、修了要件は相違する
B9: 物質工学科
A12: ③ 修了要件
B13: プログラムを構成する下記の科目すべてを修得していること。 全学科共通科目のジェネリックスキルⅠ～Ⅳ及び物質工学科の情報処理Ⅱ | V13: 【プルダウンリスト】
V14: 令和４年度以前より、履修することが必須のプログラムとして実施
V15: 令和７年度までに履修必須とする計画
V16: 令和８年度以降に履修必須とする計画、又は未定
B20: 必要最低単位数 | C20: 5 | E20: 単位 | J20: 履修必須の有無 | K20: 令和４年度以前より、履修することが必須のプログラムとして実施
A22: ④ 現在進行中の社会変化（第４次産業革命、Society 5.0、データ駆動型社会等）に深く寄与しているものであり、それが自らの生活と密接に結びついている」の内容を含む授業科目
B24: 授業科目 | F24: 単位数 | G24: 必須 | H24: 1-1 | I24: 1-6 | J24: 授業科目 | P24: 単位数 | Q24: 必須 | R24: 1-1 | S24: 1-6
B25: ジェネリックスキルⅠ | F25: 1 | G25: ○ | H25: ○
B26: ジェネリックスキルⅣ | F26: 1 | G26: ○ | I26: ○
A33: ⑤ 「社会で活用されているデータ」や「データの活用領域」は非常に広範囲であって、日常生活や社会の課題を解決する有用なツールになり得るもの」の内容を含む授業科目
B35: 授業科目 | F35: 単位数 | G35: 必須 | H35: 1-2 | I35: 1-3 | J35: 授業科目 | P35: 単位数 | Q35: 必須 | R35: 1-2 | S35: 1-3
B36: ジェネリックスキルⅢ | F36: 1 | G36: ○ | H36: ○
B37: ジェネリックスキルⅠ | F37: 1 | G37: ○ | I37: ○
A44: ⑥ 「様々なデータ利活用の現場におけるデータ利活用事例が示され、様々な適用領域（流通、製造、金融、サービス、インフラ、公共、ヘルスケア等）の知見と組み合わせることで価値を創出するもの」の内容を含む授業科目
B46: 授業科目 | F46: 単位数 | G46: 必須 | H46: 1-4 | I46: 1-5 | J46: 授業科目 | P46: 単位数 | Q46: 必須 | R46: 1-4 | S46: 1-5
B47: ジェネリックスキルⅢ | F47: 1 | G47: ○ | H47: ○
B48: ジェネリックスキルⅣ | F48: 1 | G48: ○ | H48: ○
B49: ジェネリックスキルⅠ | F49: 1 | G49: ○ | I49: ○
A55: ⑦ 「活用に当たっての様々な留意事項（ELSI、個人情報、データ倫理、ＡＩ社会原則等）を考慮し、情報セキュリティや情報漏洩等、データを守る上での留意事項への理解をする」の内容を含む授業科目
B57: 授業科目 | F57: 単位数 | G57: 必須 | H57: 3-1 | I57: 3-2 | J57: 授業科目 | P57: 単位数 | Q57: 必須 | R57: 3-1 | S57: 3-2
B58: ジェネリックスキルⅠ | F58: 1 | G58: ○ | I58: ○
B59: ジェネリックスキルⅡ | F59: 1 | G59: ○ | H59: ○ | I59: ○
B60: ジェネリックスキルⅢ | F60: 1 | G60: ○ | I60: ○
B61: ジェネリックスキルⅣ | F61: 1 | G61: ○ | I61: ○
A66: ⑧ 「実データ・実課題（学術データ等を含む）を用いた演習など、社会での実例を題材として、「データを読む、説明する、扱う」といった数理・データサイエンス・ＡＩの基本的な活用法に関するもの」の内容を含む授業科目
B68: 授業科目 | E68: 単位数 | F68: 必須 | G68: 2-1 | H68: 2-2 | I68: 2-3 | J68: 授業科目 | O68: 単位数 | P68: 必須 | Q68: 2-1 | R68: 2-2 | S68: 2-3
B69: ジェネリックスキルⅠ | E69: 1 | F69: ○ | G69: ○ | H69: ○
B70: 情報処理Ⅱ | E70: 1 | F70: ○ | G70: ○ | H70: ○ | I70: ○
A77: ⑨ 選択「４．オプション」の内容を含む授業科目
B78: 授業科目 | F78: 選択項目 | J78: 授業科目 | P78: 選択項目
A87: ⑩ プログラムを構成する授業の内容
B88: 授業に含まれている内容・要素 | D88: 講義内容
B89: （１）現在進行中の社会変化（第４次産業革命、Society 5.0、データ駆動型社会等）に深く寄与しているものであり、それが自らの生活と密接に結びついている | C89: 1-1 | D89: ◆ジェネリックスキルⅠ（第9回）：現代は第４次産業革命による創造社会（Society5.0）に位置付けられ、AIを用いた便利な社会形成が進められていることを学ぶ。
...

Sheet 様式１ー５　プログラムを構成する授業科目
R1: 様式１－５ | T1: 「学部・学科によって、修了要件は相違する」場合は、本シートを複製の上＜様式１－〇＞と枝番号を付してください
B2: 大学等名 | C2: 宇部工業高等専門学校
B3: プログラム名 | C3: 宇部工業高等専門学校数理・データサイエンス・ＡＩ教育プログラム
A5: プログラムを構成する授業科目について
A7: ① 対象となる学部・学科名称 | J7: ② 教育プログラムの修了要件 | K7: 学部・学科によって、修了要件は相違する
B9: 経営情報学科
A12: ③ 修了要件
B13: プログラムを構成する下記の科目すべてを修得していること。 全学科共通科目のジェネリックスキルⅠ～Ⅳ及び経営情報学科の統計学Ⅰ、統計学Ⅱ、基礎情報処理論Ⅰ、経営情報論 | V13: 【プルダウンリスト】
V14: 令和４年度以前より、履修することが必須のプログラムとして実施
V15: 令和７年度までに履修必須とする計画
V16: 令和８年度以降に履修必須とする計画、又は未定
B20: 必要最低単位数 | C20: 8 | E20: 単位 | J20: 履修必須の有無 | K20: 令和４年度以前より、履修することが必須のプログラムとして実施
A22: ④ 現在進行中の社会変化（第４次産業革命、Society 5.0、データ駆動型社会等）に深く寄与しているものであり、それが自らの生活と密接に結びついている」の内容を含む授業科目
B24: 授業科目 | F24: 単位数 | G24: 必須 | H24: 1-1 | I24: 1-6 | J24: 授業科目 | P24: 単位数 | Q24: 必須 | R24: 1-1 | S24: 1-6
B25: ジェネリックスキルⅠ | F25: 1 | G25: ○ | H25: ○
B26: ジェネリックスキルⅣ | F26: 1 | G26: ○ | I26: ○
A33: ⑤ 「社会で活用されているデータ」や「データの活用領域」は非常に広範囲であって、日常生活や社会の課題を解決する有用なツールになり得るもの」の内容を含む授業科目
B35: 授業科目 | F35: 単位数 | G35: 必須 | H35: 1-2 | I35: 1-3 | J35: 授業科目 | P35: 単位数 | Q35: 必須 | R35: 1-2 | S35: 1-3
B36: ジェネリックスキルⅢ | F36: 1 | G36: ○ | H36: ○
B37: ジェネリックスキルⅠ | F37: 1 | G37: ○ | I37: ○
A44: ⑥ 「様々なデータ利活用の現場におけるデータ利活用事例が示され、様々な適用領域（流通、製造、金融、サービス、インフラ、公共、ヘルスケア等）の知見と組み合わせることで価値を創出するもの」の内容を含む授業科目
B46: 授業科目 | F46: 単位数 | G46: 必須 | H46: 1-4 | I46: 1-5 | J46: 授業科目 | P46: 単位数 | Q46: 必須 | R46: 1-4 | S46: 1-5
B47: ジェネリックスキルⅢ | F47: 1 | G47: ○ | H47: ○
B48: ジェネリックスキルⅣ | F48: 1 | G48: ○ | H48: ○
B49: ジェネリックスキルⅠ | F49: 1 | G49: ○ | I49: ○
A55: ⑦ 「活用に当たっての様々な留意事項（ELSI、個人情報、データ倫理、ＡＩ社会原則等）を考慮し、情報セキュリティや情報漏洩等、データを守る上での留意事項への理解をする」の内容を含む授業科目
B57: 授業科目 | F57: 単位数 | G57: 必須 | H57: 3-1 | I57: 3-2 | J57: 授業科目 | P57: 単位数 | Q57: 必須 | R57: 3-1 | S57: 3-2
B58: ジェネリックスキルⅠ | F58: 1 | G58: ○ | I58: ○
B59: ジェネリックスキルⅡ | F59: 1 | G59: ○ | H59: ○ | I59: ○
B60: ジェネリックスキルⅢ | F60: 1 | G60: ○ | I60: ○
B61: ジェネリックスキルⅣ | F61: 1 | G61: ○ | I61: ○
A66: ⑧ 「実データ・実課題（学術データ等を含む）を用いた演習など、社会での実例を題材として、「データを読む、説明する、扱う」といった数理・データサイエンス・ＡＩの基本的な活用法に関するもの」の内容を含む授業科目
B68: 授業科目 | E68: 単位数 | F68: 必須 | G68: 2-1 | H68: 2-2 | I68: 2-3 | J68: 授業科目 | O68: 単位数 | P68: 必須 | Q68: 2-1 | R68: 2-2 | S68: 2-3
B69: ジェネリックスキルⅠ | E69: 1 | F69: ○ | G69: ○ | H69: ○
B70: 統計学Ⅰ | E70: 1 | F70: ○ | G70: ○ | H70: ○
B71: 統計学Ⅱ | E71: 1 | F71: ○ | G71: ○ | H71: ○
B72: 基礎情報処理論Ⅰ | E72: 1 | F72: ○ | I72: ○
B73: 経営情報論 | E73: 1 | F73: ○ | I73: ○
A77: ⑨ 選択「４．オプション」の内容を含む授業科目
B78: 授業科目 | F78: 選択項目 | J78: 授業科目 | P78: 選択項目
...

Sheet 様式２ 履修者等数の実績
AQ1: 様式２
AL2: 大学等名 | AM2: ='様式１ー５ プログラムを構成する授業科目'!C2 -> 宇部工業高等専門学校
A3: プログラムの履修者数等の実績について
A5: ①プログラム開設年度 | C5: 令和４ | E5: 年度
A7: ②履修者・修了者の実績
B9: 学部・学科名称 | C9: 学生数 | D9: 入学 定員 | E9: 収容 定員 | F9: 令和4年度 | L9: 令和3年度 | R9: 令和2年度 | X9: 令和元年度 | AD9: 平成30年度 | AJ9: 平成29年度 | AP9: 履修者数 合計 | AQ9: 履修率
F10: 履修者数 | I10: 修了者数 | L10: 履修者数 | O10: 修了者数 | R10: 履修者数 | U10: 修了者数 | X10: 履修者数 | AA10: 修了者数 | AD10: 履修者数 | AG10: 修了者数 | AJ10: 履修者数 | AM10: 修了者数
F11: 合計 | G11: 男性 | H11: 女性 | I11: 合計 | J11: 男性 | K11: 女性 | L11: 合計 | M11: 男性 | N11: 女性 | O11: 合計 | P11: 男性 | Q11: 女性 | R11: 合計 | S11: 男性 | T11: 女性 | U11: 合計 | V11: 男性 | W11: 女性 | X11: 合計 | Y11: 男性 | Z11: 女性 | AA11: 合計 | AB11: 男性 | AC11: 女性 | AD11: 合計 | AE11: 男性 | AF11: 女性 | AG11: 合計 | AH11: 男性 | AI11: 女性 | AJ11: 合計 | AK11: 男性 | AL11: 女性 | AM11: 合計 | AN11: 男性 | AO11: 女性
B12: 機械工学科 | C12: 41 | D12: 40 | E12: 200 | F12: 41 | G12: 37 | H12: 4 | I12: =J12+K12 -> 0 | J12: 0 | K12: 0 | L12: =M12+N12 -> 0 | O12: =P12+Q12 -> 0 | R12: =S12+T12 -> 0 | U12: =V12+W12 -> 0 | X12: =Y12+Z12 -> 0 | AA12: =AB12+AC12 -> 0 | AD12: =AE12+AF12 -> 0 | AG12: =AH12+AI12 -> 0 | AJ12: =AK12+AL12 -> 0 | AM12: =AN12+AO12 -> 0 | AP12: =F12+L12+R12+X12+AD12+AJ12 -> 41 | AQ12: =AP12/E12 -> 0.205
B13: 電気工学科 | C13: 41 | D13: 40 | E13: 200 | F13: 41 | G13: 36 | H13: 5 | I13: =J13+K13 -> 0 | J13: 0 | K13: 0 | L13: =M13+N13 -> 0 | O13: =P13+Q13 -> 0 | R13: =S13+T13 -> 0 | U13: =V13+W13 -> 0 | X13: =Y13+Z13 -> 0 | AA13: =AB13+AC13 -> 0 | AD13: =AE13+AF13 -> 0 | AG13: =AH13+AI13 -> 0 | AJ13: =AK13+AL13 -> 0 | AM13: =AN13+AO13 -> 0 | AP13: =F13+L13+R13+X13+AD13+AJ13 -> 41 | AQ13: =AP13/E13 -> 0.205
B14: 制御情報工学科 | C14: 42 | D14: 40 | E14: 200 | F14: 42 | G14: 29 | H14: 13 | I14: =J14+K14 -> 0 | J14: 0 | K14: 0 | L14: =M14+N14 -> 0 | O14: =P14+Q14 -> 0 | R14: =S14+T14 -> 0 | U14: =V14+W14 -> 0 | X14: =Y14+Z14 -> 0 | AA14: =AB14+AC14 -> 0 | AD14: =AE14+AF14 -> 0 | AG14: =AH14+AI14 -> 0 | AJ14: =AK14+AL14 -> 0 | AM14: =AN14+AO14 -> 0 | AP14: =F14+L14+R14+X14+AD14+AJ14 -> 42 | AQ14: =AP14/E14 -> 0.21
B15: 物質工学科 | C15: 42 | D15: 40 | E15: 200 | F15: 42 | G15: 20 | H15: 22 | I15: =J15+K15 -> 0 | J15: 0 | K15: 0 | L15: =M15+N15 -> 0 | O15: =P15+Q15 -> 0 | R15: =S15+T15 -> 0 | U15: =V15+W15 -> 0 | X15: =Y15+Z15 -> 0 | AA15: =AB15+AC15 -> 0 | AD15: =AE15+AF15 -> 0 | AG15: =AH15+AI15 -> 0 | AJ15: =AK15+AL15 -> 0 | AM15: =AN15+AO15 -> 0 | AP15: =F15+L15+R15+X15+AD15+AJ15 -> 42 | AQ15: =AP15/E15 -> 0.21
B16: 経営情報学科 | C16: 43 | D16: 40 | E16: 200 | F16: 43 | G16: 20 | H16: 23 | I16: =J16+K16 -> 0 | J16: 0 | K16: 0 | L16: =M16+N16 -> 0 | O16: =P16+Q16 -> 0 | R16: =S16+T16 -> 0 | U16: =V16+W16 -> 0 | X16: =Y16+Z16 -> 0 | AA16: =AB16+AC16 -> 0 | AD16: =AE16+AF16 -> 0 | AG16: =AH16+AI16 -> 0 | AJ16: =AK16+AL16 -> 0 | AM16: =AN16+AO16 -> 0 | AP16: =F16+L16+R16+X16+AD16+AJ16 -> 43 | AQ16: =AP16/E16 -> 0.215
F17: =G17+H17 -> 0 | I17: =J17+K17 -> 0 | L17: =M17+N17 -> 0 | O17: =P17+Q17 -> 0 | R17: =S17+T17 -> 0 | U17: =V17+W17 -> 0 | X17: =Y17+Z17 -> 0 | AA17: =AB17+AC17 -> 0 | AD17: =AE17+AF17 -> 0 | AG17: =AH17+AI17 -> 0 | AJ17: =AK17+AL17 -> 0 | AM17: =AN17+AO17 -> 0 | AP17: =F17+L17+R17+X17+AD17+AJ17 -> 0 | AQ17: =AP17/E17 -> #DIV/0!
F18: =G18+H18 -> 0 | I18: =J18+K18 -> 0 | L18: =M18+N18 -> 0 | O18: =P18+Q18 -> 0 | R18: =S18+T18 -> 0 | U18: =V18+W18 -> 0 | X18: =Y18+Z18 -> 0 | AA18: =AB18+AC18 -> 0 | AD18: =AE18+AF18 -> 0 | AG18: =AH18+AI18 -> 0 | AJ18: =AK18+AL18 -> 0 | AM18: =AN18+AO18 -> 0 | AP18: =F18+L18+R18+X18+AD18+AJ18 -> 0 | AQ18: =AP18/E18 -> #DIV/0!
F19: =G19+H19 -> 0 | I19: =J19+K19 -> 0 | L19: =M19+N19 -> 0 | O19: =P19+Q19 -> 0 | R19: =S19+T19 -> 0 | U19: =V19+W19 -> 0 | X19: =Y19+Z19 -> 0 | AA19: =AB19+AC19 -> 0 | AD19: =AE19+AF19 -> 0 | AG19: =AH19+AI19 -> 0 | AJ19: =AK19+AL19 -> 0 | AM19: =AN19+AO19 -> 0 | AP19: =F19+L19+R19+X19+AD19+AJ19 -> 0 | AQ19: =AP19/E19 -> #DIV/0!
F20: =G20+H20 -> 0 | I20: =J20+K20 -> 0 | L20: =M20+N20 -> 0 | O20: =P20+Q20 -> 0 | R20: =S20+T20 -> 0 | U20: =V20+W20 -> 0 | X20: =Y20+Z20 -> 0 | AA20: =AB20+AC20 -> 0 | AD20: =AE20+AF20 -> 0 | AG20: =AH20+AI20 -> 0 | AJ20: =AK20+AL20 -> 0 | AM20: =AN20+AO20 -> 0 | AP20: =F20+L20+R20+X20+AD20+AJ20 -> 0 | AQ20: =AP20/E20 -> #DIV/0!
F21: =G21+H21 -> 0 | I21: =J21+K21 -> 0 | L21: =M21+N21 -> 0 | O21: =P21+Q21 -> 0 | R21: =S21+T21 -> 0 | U21: =V21+W21 -> 0 | X21: =Y21+Z21 -> 0 | AA21: =AB21+AC21 -> 0 | AD21: =AE21+AF21 -> 0 | AG21: =AH21+AI21 -> 0 | AJ21: =AK21+AL21 -> 0 | AM21: =AN21+AO21 -> 0 | AP21: =F21+L21+R21+X21+AD21+AJ21 -> 0 | AQ21: =AP21/E21 -> #DIV/0!
F22: =G22+H22 -> 0 | I22: =J22+K22 -> 0 | L22: =M22+N22 -> 0 | O22: =P22+Q22 -> 0 | R22: =S22+T22 -> 0 | U22: =V22+W22 -> 0 | X22: =Y22+Z22 -> 0 | AA22: =AB22+AC22 -> 0 | AD22: =AE22+AF22 -> 0 | AG22: =AH22+AI22 -> 0 | AJ22: =AK22+AL22 -> 0 | AM22: =AN22+AO22 -> 0 | AP22: =F22+L22+R22+X22+AD22+AJ22 -> 0 | AQ22: =AP22/E22 -> #DIV/0!
F23: =G23+H23 -> 0 | I23: =J23+K23 -> 0 | L23: =M23+N23 -> 0 | O23: =P23+Q23 -> 0 | R23: =S23+T23 -> 0 | U23: =V23+W23 -> 0 | X23: =Y23+Z23 -> 0 | AA23: =AB23+AC23 -> 0 | AD23: =AE23+AF23 -> 0 | AG23: =AH23+AI23 -> 0 | AJ23: =AK23+AL23 -> 0 | AM23: =AN23+AO23 -> 0 | AP23: =F23+L23+R23+X23+AD23+AJ23 -> 0 | AQ23: =AP23/E23 -> #DIV/0!
F24: =G24+H24 -> 0 | I24: =J24+K24 -> 0 | L24: =M24+N24 -> 0 | O24: =P24+Q24 -> 0 | R24: =S24+T24 -> 0 | U24: =V24+W24 -> 0 | X24: =Y24+Z24 -> 0 | AA24: =AB24+AC24 -> 0 | AD24: =AE24+AF24 -> 0 | AG24: =AH24+AI24 -> 0 | AJ24: =AK24+AL24 -> 0 | AM24: =AN24+AO24 -> 0 | AP24: =F24+L24+R24+X24+AD24+AJ24 -> 0 | AQ24: =AP24/E24 -> #DIV/0!
F25: =G25+H25 -> 0 | I25: =J25+K25 -> 0 | L25: =M25+N25 -> 0 | O25: =P25+Q25 -> 0 | R25: =S25+T25 -> 0 | U25: =V25+W25 -> 0 | X25: =Y25+Z25 -> 0 | AA25: =AB25+AC25 -> 0 | AD25: =AE25+AF25 -> 0 | AG25: =AH25+AI25 -> 0 | AJ25: =AK25+AL25 -> 0 | AM25: =AN25+AO25 -> 0 | AP25: =F25+L25+R25+X25+AD25+AJ25 -> 0 | AQ25: =AP25/E25 -> #DIV/0!
F26: =G26+H26 -> 0 | I26: =J26+K26 -> 0 | L26: =M26+N26 -> 0 | O26: =P26+Q26 -> 0 | R26: =S26+T26 -> 0 | U26: =V26+W26 -> 0 | X26: =Y26+Z26 -> 0 | AA26: =AB26+AC26 -> 0 | AD26: =AE26+AF26 -> 0 | AG26: =AH26+AI26 -> 0 | AJ26: =AK26+AL26 -> 0 | AM26: =AN26+AO26 -> 0 | AP26: =F26+L26+R26+X26+AD26+AJ26 -> 0 | AQ26: =AP26/E26 -> #DIV/0!
F27: =G27+H27 -> 0 | I27: =J27+K27 -> 0 | L27: =M27+N27 -> 0 | O27: =P27+Q27 -> 0 | R27: =S27+T27 -> 0 | U27: =V27+W27 -> 0 | X27: =Y27+Z27 -> 0 | AA27: =AB27+AC27 -> 0 | AD27: =AE27+AF27 -> 0 | AG27: =AH27+AI27 -> 0 | AJ27: =AK27+AL27 -> 0 | AM27: =AN27+AO27 -> 0 | AP27: =F27+L27+R27+X27+AD27+AJ27 -> 0 | AQ27: =AP27/E27 -> #DIV/0!
F28: =G28+H28 -> 0 | I28: =J28+K28 -> 0 | L28: =M28+N28 -> 0 | O28: =P28+Q28 -> 0 | R28: =S28+T28 -> 0 | U28: =V28+W28 -> 0 | X28: =Y28+Z28 -> 0 | AA28: =AB28+AC28 -> 0 | AD28: =AE28+AF28 -> 0 | AG28: =AH28+AI28 -> 0 | AJ28: =AK28+AL28 -> 0 | AM28: =AN28+AO28 -> 0 | AP28: =F28+L28+R28+X28+AD28+AJ28 -> 0 | AQ28: =AP28/E28 -> #DIV/0!
... F31: =G31+H31 -> 0 | I31: =J31+K31 -> 0 | L31: =M31+N31 -> 0 | O31: =P31+Q31 -> 0 | R31: =S31+T31 -> 0 | U31: =V31+W31 -> 0 | X31: =Y31+Z31 -> 0 | AA31: =AB31+AC31 -> 0 | AD31: =AE31+AF31 -> 0 | AG31: =AH31+AI31 -> 0 | AJ31: =AK31+AL31 -> 0 | AM31: =AN31+AO31 -> 0 | AP31: =F31+L31+R31+X31+AD31+AJ31 -> 0 | AQ31: =AP31/E31 -> #DIV/0!
B32: 合 計 | C32: =SUM(C12:C31) -> 209 | D32: =SUM(D12:D31) -> 200 | E32: =SUM(E12:E31) -> 1000 | F32: =SUM(F12:F31) -> 209 | G32: =SUM(G12:G31) -> 142 | H32: =SUM(H12:H31) -> 67 | I32: =SUM(I12:I31) -> 0 | J32: =SUM(J12:J31) -> 0 | ... AP32: =SUM(AP12:AP31) -> 209 | AQ32: =AP32/E32 -> 0.209

Sheet 様式３ 教育の質・履修者数を向上させるための体制・計画
I1: 様式３
G2: 大学等名 | H2: ='様式１ー５ プログラムを構成する授業科目'!C2 -> 宇部工業高等専門学校
A4: 教育の質・履修者数を向上させるための体制・計画について
A6: ① | B6: 全学の教員数 | C6: (常勤） | E6: 70 | F6: 人 | G6: （非常勤） | H6: 16 | I6: 人
A8: ② | B8: プログラムの授業を教えている教員数 | H8: 21 | I8: 人
A10: ③ | B10: プログラムの運営責任者
B11: （責任者名） | C11: 山川 昌男 | G11: （役職名） | H11: 校長
A13: ④ | B13: プログラムを改善・進化させるための体制（委員会・組織等）
B14: 宇部工業高等専門学校教務委員会
B16: （責任者名） | C16: 仙波 伸也 | G16: （役職名） | H16: 校長補佐（教務主事）
A18: ⑤ | B18: プログラムを改善・進化させるための体制を定める規則名称
B19: 宇部工業高等専門学校教務委員会規則
A21: ⑥ | B21: 体制の目的
B22: 教育課程の編成や実施など、教務に関する事項を審議するために教務委員会が設置されている。教務委員会は本教育プログラムを含む事項の改善・進化に関する事項を取り扱う。
A34: ⑦ | B34: 具体的な構成員
B35: 校長補佐（教務主事） 電気工学科 教授 仙波伸也 校長補佐（学生主事） 制御情報工学科 教授 江原史朗 校長補佐（寮務主事） 経営情報学科 教授 松野成悟 教務主事補 物質工学科 教授 小倉 薫、物質工学科 教授 廣原志保、 一般科 教授 三浦 敬、一般科 准教授 中村成芳 機械工学科長 教授 後藤 実、電気工学科長 教授 春山和男、 制御情報工学科長 教授 久保田良輔、物質工学科長 教授 杉本憲司、 経営情報学科長 教授 岸川善紀 一般科科長（文系） 教授 池田 晶、一般科科長（理系） 教授 伊藤耕作 各学科から推薦された教員 機械工学科 助教 山﨑由勝、電気工学科 准教授 三澤秀明、 制御情報工学科 准教授 伊藤直樹、物質工学科 准教授 小林和香子、 経営情報学科 准教授 山根陽一 一般科の文系及び理系から推薦された教員（助手を除く） 一般科 准教授 末柗昌子、一般科 准教授 服部勝己 学生課長 原 建二 その他校長が必要と認めた者 専攻科長 経営情報学科 教授 田川晋也
A48: ⑧ | B48: 履修者数・履修率の向上に向けた計画 ※様式１の「履修必須の有無」で「計画がある」としている場合は詳細について記載すること
B49: 令和４年度実績 | C49: ='様式２ 履修者等数の実績'!AQ32 -> 0.209 | E49: 令和５年度予定 | F49: 0.4 | H49: 令和６年度予定 | I49: 0.6
B50: 令和７年度予定 | C50: 0.8 | E50: 令和８年度予定 | F50: 1 | H50: 収容定員（名） | I50: ='様式２ 履修者等数の実績'!E32 -> 1000
B51: 具体的な計画
B52: 本教育プログラムは必修科目のみで構成されており、全学生（※）が履修する。したがって、対象学年の履修率は100％であり、履修率の向上に向けた計画は不要である。 ※転入学、編入学、転科、再入学によって入学年より前の学年の授業科目を履修できない者は，対象外となる。
A65: ⑨ | B65: 学部・学科に関係なく希望する学生全員が受講可能となるような必要な体制・取組等
B66: 本教育プログラムは必修科目のみで構成されており、全学生が受講する。
A79: ⑩ | B79: できる限り多くの学生が履修できるような具体的な周知方法・取組
B80: 本教育プログラムは必修科目のみで構成されており、全学生が履修する。教育プログラムの内容はホームページで公開するとともに、教育プログラムの全学科共通科目である「ジェネリックスキルⅠ～Ⅳ」の対象授業内で周知する。
A93: ⑪ | B93: できる限り多くの学生が履修・修得できるようなサポート体制
B94: 本教育プログラムは必修科目のみで構成されており、全学生が履修する。全学生が修得できるようにするためのサポート体制は以下のとおりである。 １．学生の自学をサポートするために当該関連分野の参考書を図書館に充実させている。 ２．全教室にWi-Fi環境を整備し、学生がインターネットから必要な情報を素早く引き出せるようにしている。 ３．情報演習室を2室整備し、授業時間外に学生が自由に利用できるように開放している。
A107: ⑫ | B107: 授業時間内外で学習指導、質問を受け付ける具体的な仕組み
B108: 本校では以下のような仕組みで授業時間外での学習指導や質問に対応している。 １．全教員が週に２回、各30分以上のオフィスアワーを設け、授業時間外での学習指導や学生の質問に対応する体制を整えている。教員毎のオフィスアワーはMicrosoft Teamsを利用してクラス別に作ってあるTeam上で学生向けに公開している。 ２．学生がMicrosoft TeamsをPC、タブレット、スマートフォンなどで利用できるようにしており、オンライン上での学習指導や学生からの質問に対応できる環境を整備している。

Sheet 様式４　自己点検・評価
I1: 様式４
H2: 大学等名 | I2: ='様式１ー５ プログラムを構成する授業科目'!C2 -> 宇部工業高等専門学校
A3: 自己点検・評価について
A5: ① | B5: プログラムの自己点検・評価を行う体制（委員会・組織等）
B6: 宇部工業高等専門学校機関評価室
D8: （責任者名） | E8: 城戸秀樹 | G8: （役職名） | H8: 機関評価室長
A10: ② | B10: 自己点検・評価体制における意見等
B11: 自己点検・評価の視点 | E11: 自己点検・評価体制における意見・結果・改善に向けた取組等
B12: 学内からの視点
C13: プログラムの履修・修得状況 | E13: 本教育プログラムは必修科目のみで構成されており、入学した学生全員（定員200名）が履修（※）する。本教育プログラム構成科目の修得状況は進級認定会議及び卒業認定会議で確認する。 ※転入学、編入学、転科、再入学によって入学年より前の学年の授業科目を履修できない者は、対象外となる。
C14: 学修成果 | E14: 学年末の進級認定会議及び卒業認定会議において学生の履修・単位修得状況が把握され、クラス担任から学生に対して適切な指導を行っている。また、すべての開講科目は隔年で授業改善アンケートを実施して学修成果の確認を行っている。本教育プログラムの授業改善アンケートによると、学生自身の授業への取り組み状況は非常に積極的であり、授業への満足度も高い結果が得られている。アンケートの結果は、授業担当教員にフィードバックされ、翌年度以降の授業の改善に活用されている。
C15: 学生アンケート等を通じた学生の内容の理解度 | E15: 本教育プログラムの学習内容に関する理解度確認アンケートを第１学年から第４学年までの全学科共通科目「ジェネリックスキルⅠ～Ⅳ」の最終回で実施した。今年度初めての履修生となる１年生に実施したアンケ－ト結果では、学生の理解度が高いことが伺えた。
C16: 学生アンケート等を通じた後輩等他の学生への推奨度 | E16: 本教育プログラムの構成科目は、すべて必修科目となっており、後輩等他の学生への推奨する状況は生じない。また、本教育プログラムは開始間もないため、今後、学生向けに説明の機会を増やし、履修の参考となるよう情報を発信してく予定である。
C17: 全学的な履修者数、履修率向上に向けた計画の達成・進捗状況 | E17: 本教育プログラムは必修科目のみで構成されており、入学した学生全員（定員200名）が履修（※）する。 ※転入学、編入学、転科、再入学によって入学年より前の学年の授業科目を履修できない者は，対象外となる。
B18: 学外からの視点
C19: 教育プログラム修了者の進路、活躍状況、企業等の評価 | E19: 令和４年度末の時点で本教育プログラムの修了者はいないが、教育プログラム修了生の進路状況を継続的に調査・記録する予定である。
C20: 産業界からの視点を含めた教育プログラム内容・手法等への意見 | E20: 教育研究、管理運営、地域連携等に関する事項に関して学外有識者からの助言を求めるため、運営諮問会議を毎年度開催している。また、定期的な機関別認証評価など外部評価を受審している。 令和４年度の運営諮問会議では、本教育プログラムの内容について高い評価を受けており、今後の展開が期待されている。
B21: 数理・データサイエンス・ＡＩを「学ぶ楽しさ」「学ぶことの意義」を理解させること | E21: 本プログラムを構成する科目は、モデルカリキュラムのリテラシーレベルに準じた内容としながら、実社会で情報やAIがどのように活用されているか、先進的な事例に触れながら授業を行っている。また、学科共通科目だけではなく、各学科による専門に関連するデータを用いた演習・実習を含むことで、学生に数理・AI・データサイエンスを身近なものと感じさせ、「学ぶ楽しさ」や「学ぶことの意義」を理解させている。
B22: 内容・水準を維持・向上しつつ、より「分かりやすい」授業とすること | E22: 全開講科目において授業改善アンケートを実施しており、アンケートの結果を授業担当教員へフィードバックすることによって年度ごとに改善される体制としている。また、本教育プログラムの学習内容に関する理解度確認アンケートを別途実施する。その結果を振り返りながら学習コンテンツのアップデートを行い、「分かりやすい」授業に向けた改善を進める。
