Workbook

Sheet 様式１　プログラムを構成する授業科目
R1: 様式１－１ | T1: 「学部・学科によって、修了要件は相違する」場合は、本シートを複製の上＜様式１－〇＞と枝番号を付してください
B2: 大学等名 | C2: 専修大学
B3: プログラム名 | C3: Siデータサイエンス教育プログラム（基礎リテラシーレベル）
A5: プログラムを構成する授業科目について
A7: ① 対象となる学部・学科名称 | J7: ② 教育プログラムの修了要件 | K7: 学部・学科によって、修了要件は相違する
B9: 経済学部、法学部、人間科学部
A12: ③ 修了要件
B13: 「情報入門１」「情報入門２」の２科目４単位を取得すること。 | V13: 【プルダウンリスト】
V14: 令和４年度以前より、履修することが必須のプログラムとして実施
V15: 令和７年度までに履修必須とする計画
V16: 令和８年度以降に履修必須とする計画、又は未定
B20: 必要最低単位数 | C20: 4 | E20: 単位 | J20: 履修必須の有無 | K20: 令和８年度以降に履修必須とする計画、又は未定
A22: ④ 現在進行中の社会変化（第４次産業革命、Society 5.0、データ駆動型社会等）に深く寄与しているものであり、それが自らの生活と密接に結びついている」の内容を含む授業科目
B24: 授業科目 | F24: 単位数 | G24: 必須 | H24: 1-1 | I24: 1-6 | J24: 授業科目 | P24: 単位数 | Q24: 必須 | R24: 1-1 | S24: 1-6
B25: 情報入門１ | F25: 2 | G25: ○ | H25: ○ | I25: ○
A33: ⑤ 「社会で活用されているデータ」や「データの活用領域」は非常に広範囲であって、日常生活や社会の課題を解決する有用なツールになり得るもの」の内容を含む授業科目
B35: 授業科目 | F35: 単位数 | G35: 必須 | H35: 1-2 | I35: 1-3 | J35: 授業科目 | P35: 単位数 | Q35: 必須 | R35: 1-2 | S35: 1-3
B36: 情報入門１ | F36: 2 | G36: ○ | H36: ○ | I36: ○
A44: ⑥ 「様々なデータ利活用の現場におけるデータ利活用事例が示され、様々な適用領域（流通、製造、金融、サービス、インフラ、公共、ヘルスケア等）の知見と組み合わせることで価値を創出するもの」の内容を含む授業科目
B46: 授業科目 | F46: 単位数 | G46: 必須 | H46: 1-4 | I46: 1-5 | J46: 授業科目 | P46: 単位数 | Q46: 必須 | R46: 1-4 | S46: 1-5
B47: 情報入門１ | F47: 2 | G47: ○ | H47: ○ | I47: ○
A55: ⑦ 「活用に当たっての様々な留意事項（ELSI、個人情報、データ倫理、ＡＩ社会原則等）を考慮し、情報セキュリティや情報漏洩等、データを守る上での留意事項への理解をする」の内容を含む授業科目
B57: 授業科目 | F57: 単位数 | G57: 必須 | H57: 3-1 | I57: 3-2 | J57: 授業科目 | P57: 単位数 | Q57: 必須 | R57: 3-1 | S57: 3-2
B58: 情報入門１ | F58: 2 | G58: ○ | H58: ○ | I58: ○
A66: ⑧ 「実データ・実課題（学術データ等を含む）を用いた演習など、社会での実例を題材として、「データを読む、説明する、扱う」といった数理・データサイエンス・ＡＩの基本的な活用法に関するもの」の内容を含む授業科目
B68: 授業科目 | E68: 単位数 | F68: 必須 | G68: 2-1 | H68: 2-2 | I68: 2-3 | J68: 授業科目 | O68: 単位数 | P68: 必須 | Q68: 2-1 | R68: 2-2 | S68: 2-3
B69: 情報入門１ | E69: 2 | F69: ○ | G69: ○ | H69: ○ | I69: ○
B70: 情報入門２ | E70: 2 | F70: ○ | G70: ○ | H70: ○
A77: ⑨ 選択「４．オプション」の内容を含む授業科目
B78: 授業科目 | F78: 選択項目 | J78: 授業科目 | P78: 選択項目
A87: ⑩ プログラムを構成する授業の内容
B88: 授業に含まれている内容・要素 | D88: 講義内容
B89: （１）現在進行中の社会変化（第４次産業革命、Society 5.0、データ駆動型社会等）に深く寄与しているものであり、それが自らの生活と密接に結びついている | C89: 1-1 | D89: ・ビッグデータ、IoT、AI、ロボット「情報入門１」（4回目） ・データ量の増加、計算機の処理性能の向上、AI の⾮連続的進化「情報入門１」（4回目） ・複数技術を組み合わせたAIサービス「情報入門１」（4回目）
C90: 1-6 | D90: ・AI最新技術の活用例（深層生成モデル、敵対的生成ネットワーク、強化学習、転移学習など）「情報入門１」（5回目）
B91: （２）「社会で活用されているデータ」や「データの活用領域」は非常に広範囲であって、日常生活や社会の課題を解決する有用なツールになり得るもの | C91: 1-2 | D91: ・調査データ、実験データ、人の行動ログデータ、機械の稼働ログデータなど「情報入門１」（4回目） ・1次データ、2次データ、データのメタ化「情報入門１」（4回目） ・構造化データ、非構造化データ（文章、画像/動画、音声/音楽など）「情報入門１」（4回目） ・データのオープン化（オープンデータ）「情報入門１」（4回目）
C92: 1-3 | D92: ・データ・AI活用領域の広がり(生産、消費、文化活動など)「情報入門１」（4回目） ・研究開発、調達、製造、物流、販売、マーケティング、サービスなど「情報入門１」（4回目） ・仮説検証、知識発見、原因究明、計画策定、判断支援、活動代替、新規生成など「情報入門１」（4回目）
B93: （３）様々なデータ利活用の現場におけるデータ利活用事例が示され、様々な適用領域（流通、製造、金融、サービス、インフラ、公共、ヘルスケア等）の知見と組み合わせることで価値を創出するもの | C93: 1-4 | D93: ・データ解析：予測、グルーピング、パターン発見、最適化、シミュレーション・データ同化など「情報入門１」（4回目） ・データ可視化：複合グラフ、2軸グラフ、多次元の可視化、関係性の可視化、地図上の可視化、挙動・軌跡の可視化、リアルタイム可視化など「情報入門１」（4回目） ・非構造化データ処理：言語処理、画像/動画処理、音声/音楽処理など「情報入門１」（4回目） ・特化型AIと汎用AI、今のAIで出来ることと出来ないこと、AIとビッグデータ「情報入門１」（4回目）
C94: 1-5 | D94: ・データサイエンスのサイクル（課題抽出と定式化、データの取得・管理・加工、探索的データ解析、データ解析と推論、結果の共有・伝達、課題解決に向けた提案）「情報入門１」（5回目） ・流通、製造、金融、サービス、インフラ、公共、ヘルスケア等におけるデータ・AI利活用事例紹介「情報入門１」（5回目）
B95: （４）活用に当たっての様々な留意事項（ELSI、個人情報、データ倫理、ＡＩ社会原則等）を考慮し、情報セキュリティや情報漏洩等、データを守る上での留意事項への理解をする | C95: 3-1 | D95: ・ELSI（Ethical, Legal and Social Issues）「情報入門１」（5回目） ・個人情報保護、EU一般データ保護規則(GDPR)、忘れられる権利、オプトアウト「情報入門１」（5回目） ・データ倫理：データのねつ造、改ざん、盗用、プライバシー保護「情報入門１」（5回目） ・AI社会原則（公平性、説明責任、透明性、人間中心の判断）「情報入門１」（5回目） ・データバイアス、アルゴリズムバイアス「情報入門１」（5回目）
C96: 3-2 | D96: ・情報セキュリティ：機密性、完全性、可用性「情報入門１」（5回目） ・情報漏洩等によるセキュリティ事故の事例紹介「情報入門１」（1回目）
...

Sheet 様式１　プログラムを構成する授業科目　経営学部
R1: 様式１－２ | T1: 「学部・学科によって、修了要件は相違する」場合は、本シートを複製の上＜様式１－〇＞と枝番号を付してください
B2: 大学等名 | C2: 専修大学
B3: プログラム名 | C3: Siデータサイエンス教育プログラム（基礎リテラシーレベル）
A5: プログラムを構成する授業科目について
A7: ① 対象となる学部・学科名称 | J7: ② 教育プログラムの修了要件 | K7: 学部・学科によって、修了要件は相違する
B9: 経営学部
A12: ③ 修了要件
B13: 「情報システム入門」「情報処理入門」「情報リテラシ基礎演習」「統計入門」の４科目８単位を取得すること。 | V13: 【プルダウンリスト】
V14: 令和４年度以前より、履修することが必須のプログラムとして実施
V15: 令和７年度までに履修必須とする計画
V16: 令和８年度以降に履修必須とする計画、又は未定
B20: 必要最低単位数 | C20: 8 | E20: 単位 | J20: 履修必須の有無 | K20: 令和８年度以降に履修必須とする計画、又は未定
A22: ④ 現在進行中の社会変化（第４次産業革命、Society 5.0、データ駆動型社会等）に深く寄与しているものであり、それが自らの生活と密接に結びついている」の内容を含む授業科目
B24: 授業科目 | F24: 単位数 | G24: 必須 | H24: 1-1 | I24: 1-6 | J24: 授業科目 | P24: 単位数 | Q24: 必須 | R24: 1-1 | S24: 1-6
B25: 情報システム入門 | F25: 2 | G25: ○ | H25: ○ | I25: ○
B26: 情報処理入門 | F26: 2 | G26: ○ | H26: ○
A33: ⑤ 「社会で活用されているデータ」や「データの活用領域」は非常に広範囲であって、日常生活や社会の課題を解決する有用なツールになり得るもの」の内容を含む授業科目
B35: 授業科目 | F35: 単位数 | G35: 必須 | H35: 1-2 | I35: 1-3 | J35: 授業科目 | P35: 単位数 | Q35: 必須 | R35: 1-2 | S35: 1-3
B36: 情報システム入門 | F36: 2 | G36: ○ | H36: ○
B37: 情報処理入門 | F37: 2 | G37: ○ | H37: ○ | I37: ○
B38: 情報リテラシ基礎演習 | F38: 2 | G38: ○ | H38: ○ | I38: ○
A44: ⑥ 「様々なデータ利活用の現場におけるデータ利活用事例が示され、様々な適用領域（流通、製造、金融、サービス、インフラ、公共、ヘルスケア等）の知見と組み合わせることで価値を創出するもの」の内容を含む授業科目
B46: 授業科目 | F46: 単位数 | G46: 必須 | H46: 1-4 | I46: 1-5 | J46: 授業科目 | P46: 単位数 | Q46: 必須 | R46: 1-4 | S46: 1-5
B47: 情報システム入門 | F47: 2 | G47: ○ | H47: ○ | I47: ○
B48: 情報処理入門 | F48: 2 | G48: ○ | H48: ○ | I48: ○
A55: ⑦ 「活用に当たっての様々な留意事項（ELSI、個人情報、データ倫理、ＡＩ社会原則等）を考慮し、情報セキュリティや情報漏洩等、データを守る上での留意事項への理解をする」の内容を含む授業科目
B57: 授業科目 | F57: 単位数 | G57: 必須 | H57: 3-1 | I57: 3-2 | J57: 授業科目 | P57: 単位数 | Q57: 必須 | R57: 3-1 | S57: 3-2
B58: 情報システム入門 | F58: 2 | G58: ○ | H58: ○ | I58: ○
B59: 情報処理入門 | F59: 2 | G59: ○ | H59: ○ | I59: ○
B60: 情報リテラシ基礎演習 | F60: 2 | G60: ○ | H60: ○
A66: ⑧ 「実データ・実課題（学術データ等を含む）を用いた演習など、社会での実例を題材として、「データを読む、説明する、扱う」といった数理・データサイエンス・ＡＩの基本的な活用法に関するもの」の内容を含む授業科目
B68: 授業科目 | E68: 単位数 | F68: 必須 | G68: 2-1 | H68: 2-2 | I68: 2-3 | J68: 授業科目 | O68: 単位数 | P68: 必須 | Q68: 2-1 | R68: 2-2 | S68: 2-3
B69: 情報処理入門 | E69: 2 | F69: ○ | G69: ○ | H69: ○ | I69: ○
B70: 情報リテラシ基礎演習 | E70: 2 | F70: ○ | H70: ○
B71: 統計入門 | E71: 2 | F71: ○ | G71: ○ | H71: ○ | I71: ○
A77: ⑨ 選択「４．オプション」の内容を含む授業科目
B78: 授業科目 | F78: 選択項目 | J78: 授業科目 | P78: 選択項目
A87: ⑩ プログラムを構成する授業の内容
B88: 授業に含まれている内容・要素 | D88: 講義内容
B89: （１）現在進行中の社会変化（第４次産業革命、Society 5.0、データ駆動型社会等）に深く寄与しているものであり、それが自らの生活と密接に結びついている | C89: 1-1 | D89: ・ビッグデータ、IoT、AI、ロボット「情報システム入門」（1、2、3、4、14回目） ・データ量の増加、計算機の処理性能の向上、AI の⾮連続的進化「情報システム入門」（4回目） ・第4 次産業革命、 Society 5.0 、 データ駆動型社会「情報システム入門」（1、4、14回目） ・複数技術を組み合わせたAIサービス「情報システム入門」（1回目） ・人間の知的活動とAIの関係性「情報システム入門」（4、14回目） ・データを起点としたものの見方、人間の知的活動を起点としたものの見方「情報システム入門」（1回目）、「情報処理入門」（15回目）
...

Sheet 様式１　プログラムを構成する授業科目　商学部
R1: 様式１－３ | T1: 「学部・学科によって、修了要件は相違する」場合は、本シートを複製の上＜様式１－〇＞と枝番号を付してください
B2: 大学等名 | C2: 専修大学
B3: プログラム名 | C3: Siデータサイエンス教育プログラム（基礎リテラシーレベル）
A5: プログラムを構成する授業科目について
A7: ① 対象となる学部・学科名称 | J7: ② 教育プログラムの修了要件 | K7: 学部・学科によって、修了要件は相違する
B9: 商学部
A12: ③ 修了要件
B13: 「情報基礎Ⅰ」「情報基礎Ⅱ」の２科目４単位を取得すること。 | V13: 【プルダウンリスト】
V14: 令和４年度以前より、履修することが必須のプログラムとして実施
V15: 令和７年度までに履修必須とする計画
V16: 令和８年度以降に履修必須とする計画、又は未定
B20: 必要最低単位数 | C20: 4 | E20: 単位 | J20: 履修必須の有無 | K20: 令和８年度以降に履修必須とする計画、又は未定
A22: ④ 現在進行中の社会変化（第４次産業革命、Society 5.0、データ駆動型社会等）に深く寄与しているものであり、それが自らの生活と密接に結びついている」の内容を含む授業科目
B24: 授業科目 | F24: 単位数 | G24: 必須 | H24: 1-1 | I24: 1-6 | J24: 授業科目 | P24: 単位数 | Q24: 必須 | R24: 1-1 | S24: 1-6
B25: 情報基礎Ⅰ | F25: 2 | G25: ○ | H25: ○ | I25: ○
A33: ⑤ 「社会で活用されているデータ」や「データの活用領域」は非常に広範囲であって、日常生活や社会の課題を解決する有用なツールになり得るもの」の内容を含む授業科目
B35: 授業科目 | F35: 単位数 | G35: 必須 | H35: 1-2 | I35: 1-3 | J35: 授業科目 | P35: 単位数 | Q35: 必須 | R35: 1-2 | S35: 1-3
B36: 情報基礎Ⅰ | F36: 2 | G36: ○ | H36: ○ | I36: ○
A44: ⑥ 「様々なデータ利活用の現場におけるデータ利活用事例が示され、様々な適用領域（流通、製造、金融、サービス、インフラ、公共、ヘルスケア等）の知見と組み合わせることで価値を創出するもの」の内容を含む授業科目
B46: 授業科目 | F46: 単位数 | G46: 必須 | H46: 1-4 | I46: 1-5 | J46: 授業科目 | P46: 単位数 | Q46: 必須 | R46: 1-4 | S46: 1-5
B47: 情報基礎Ⅰ | F47: 2 | G47: ○ | H47: ○ | I47: ○
A55: ⑦ 「活用に当たっての様々な留意事項（ELSI、個人情報、データ倫理、ＡＩ社会原則等）を考慮し、情報セキュリティや情報漏洩等、データを守る上での留意事項への理解をする」の内容を含む授業科目
B57: 授業科目 | F57: 単位数 | G57: 必須 | H57: 3-1 | I57: 3-2 | J57: 授業科目 | P57: 単位数 | Q57: 必須 | R57: 3-1 | S57: 3-2
B58: 情報基礎Ⅰ | F58: 2 | G58: ○ | H58: ○ | I58: ○
A66: ⑧ 「実データ・実課題（学術データ等を含む）を用いた演習など、社会での実例を題材として、「データを読む、説明する、扱う」といった数理・データサイエンス・ＡＩの基本的な活用法に関するもの」の内容を含む授業科目
B68: 授業科目 | E68: 単位数 | F68: 必須 | G68: 2-1 | H68: 2-2 | I68: 2-3 | J68: 授業科目 | O68: 単位数 | P68: 必須 | Q68: 2-1 | R68: 2-2 | S68: 2-3
B69: 情報基礎Ⅰ | E69: 2 | F69: ○ | G69: ○ | H69: ○ | I69: ○
B70: 情報基礎Ⅱ | E70: 2 | F70: ○ | G70: ○ | H70: ○
A77: ⑨ 選択「４．オプション」の内容を含む授業科目
B78: 授業科目 | F78: 選択項目 | J78: 授業科目 | P78: 選択項目
A87: ⑩ プログラムを構成する授業の内容
B88: 授業に含まれている内容・要素 | D88: 講義内容
B89: （１）現在進行中の社会変化（第４次産業革命、Society 5.0、データ駆動型社会等）に深く寄与しているものであり、それが自らの生活と密接に結びついている | C89: 1-1 | D89: ・ビッグデータ、IoT、AI、ロボット「情報基礎Ⅰ」（4回目） ・データ量の増加、計算機の処理性能の向上、AI の⾮連続的進化「情報基礎Ⅰ」（4回目） ・複数技術を組み合わせたAIサービス「情報基礎Ⅰ」（4回目）
C90: 1-6 | D90: ・AI最新技術の活用例（深層生成モデル、敵対的生成ネットワーク、強化学習、転移学習など）「情報基礎Ⅰ」（5回目）
B91: （２）「社会で活用されているデータ」や「データの活用領域」は非常に広範囲であって、日常生活や社会の課題を解決する有用なツールになり得るもの | C91: 1-2 | D91: ・調査データ、実験データ、人の行動ログデータ、機械の稼働ログデータなど「情報基礎Ⅰ」（4回目） ・1次データ、2次データ、データのメタ化「情報基礎Ⅰ」（4回目） ・構造化データ、非構造化データ（文章、画像/動画、音声/音楽など）「情報基礎Ⅰ」（4回目） ・データのオープン化（オープンデータ）「情報基礎Ⅰ」（4回目）
C92: 1-3 | D92: ・データ・AI活用領域の広がり(生産、消費、文化活動など)「情報基礎Ⅰ」（4回目） ・研究開発、調達、製造、物流、販売、マーケティング、サービスなど「情報基礎Ⅰ」（4回目） ・仮説検証、知識発見、原因究明、計画策定、判断支援、活動代替、新規生成など「情報基礎Ⅰ」（4回目）
B93: （３）様々なデータ利活用の現場におけるデータ利活用事例が示され、様々な適用領域（流通、製造、金融、サービス、インフラ、公共、ヘルスケア等）の知見と組み合わせることで価値を創出するもの | C93: 1-4 | D93: ・データ解析：予測、グルーピング、パターン発見、最適化、シミュレーション・データ同化など「情報基礎Ⅰ」（4回目） ・データ可視化：複合グラフ、2軸グラフ、多次元の可視化、関係性の可視化、地図上の可視化、挙動・軌跡の可視化、リアルタイム可視化など「情報基礎Ⅰ」（4回目） ・非構造化データ処理：言語処理、画像/動画処理、音声/音楽処理など「情報基礎Ⅰ」（4回目） ・特化型AIと汎用AI、今のAIで出来ることと出来ないこと、AIとビッグデータ「情報基礎Ⅰ」（4回目）
C94: 1-5 | D94: ・データサイエンスのサイクル（課題抽出と定式化、データの取得・管理・加工、探索的データ解析、データ解析と推論、結果の共有・伝達、課題解決に向けた提案）「情報基礎Ⅰ」（5回目） ・流通、製造、金融、サービス、インフラ、公共、ヘルスケア等におけるデータ・AI利活用事例紹介「情報基礎Ⅰ」（5回目）
B95: （４）活用に当たっての様々な留意事項（ELSI、個人情報、データ倫理、ＡＩ社会原則等）を考慮し、情報セキュリティや情報漏洩等、データを守る上での留意事項への理解をする | C95: 3-1 | D95: ・ELSI（Ethical, Legal and Social Issues）「情報基礎Ⅰ」（5回目） ・個人情報保護、EU一般データ保護規則(GDPR)、忘れられる権利、オプトアウト「情報基礎Ⅰ」（5回目） ・データ倫理：データのねつ造、改ざん、盗用、プライバシー保護「情報基礎Ⅰ」（5回目） ・AI社会原則（公平性、説明責任、透明性、人間中心の判断）「情報基礎Ⅰ」（5回目） ・データバイアス、アルゴリズムバイアス「情報基礎Ⅰ」（5回目）
C96: 3-2 | D96: ・情報セキュリティ：機密性、完全性、可用性「情報基礎Ⅰ」（5回目） ・情報漏洩等によるセキュリティ事故の事例紹介「情報基礎Ⅰ」（1回目）
...

Sheet 様式１　プログラムを構成する授業科目　文学部
R1: 様式１－４ | T1: 「学部・学科によって、修了要件は相違する」場合は、本シートを複製の上＜様式１－〇＞と枝番号を付してください
B2: 大学等名 | C2: 専修大学
B3: プログラム名 | C3: Siデータサイエンス教育プログラム（基礎リテラシーレベル）
A5: プログラムを構成する授業科目について
A7: ① 対象となる学部・学科名称 | J7: ② 教育プログラムの修了要件 | K7: 学部・学科によって、修了要件は相違する
B9: 文学部
A12: ③ 修了要件
B13: ＜日本文学文化学科・英語英米文学科・哲学科・歴史学科・環境地理学科＞ 「情報入門１」「情報入門２」の２科目４単位を取得すること。 ＜ジャーナリズム学科＞ 必修科目３科目６単位及び次の条件を満たす選択必修科目４単位を含む合計１０単位を修得すること。 【必修】 「情報表現実習（基礎）」「パブリックメディア論」「情報表現実習（応用）」の３科目６単位 【選択必修】 「スポーツ医科学情報」「現代社会とスポーツ」の２科目の中から１科目（２単位）かつ 「心理情報とメンタルマネジメント」「ライフステージと健康情報」「コンディショニングのための情報分析」の３科目の中から１科目（２単位） | V13: 【プルダウンリスト】
V14: 令和４年度以前より、履修することが必須のプログラムとして実施
V15: 令和７年度までに履修必須とする計画
V16: 令和８年度以降に履修必須とする計画、又は未定
B20: 必要最低単位数 | C20: 4 | E20: 単位 | J20: 履修必須の有無 | K20: 令和８年度以降に履修必須とする計画、又は未定
A22: ④ 現在進行中の社会変化（第４次産業革命、Society 5.0、データ駆動型社会等）に深く寄与しているものであり、それが自らの生活と密接に結びついている」の内容を含む授業科目
B24: 授業科目 | F24: 単位数 | G24: 必須 | H24: 1-1 | I24: 1-6 | J24: 授業科目 | P24: 単位数 | Q24: 必須 | R24: 1-1 | S24: 1-6
B25: 情報入門１ | F25: 2 | H25: ○ | I25: ○
B26: 情報表現実習（基礎） | F26: 2 | H26: ○ | I26: ○
A33: ⑤ 「社会で活用されているデータ」や「データの活用領域」は非常に広範囲であって、日常生活や社会の課題を解決する有用なツールになり得るもの」の内容を含む授業科目
B35: 授業科目 | F35: 単位数 | G35: 必須 | H35: 1-2 | I35: 1-3 | J35: 授業科目 | P35: 単位数 | Q35: 必須 | R35: 1-2 | S35: 1-3
B36: 情報入門１ | F36: 2 | H36: ○ | I36: ○
B37: スポーツ医科学情報 | F37: 2 | H37: ○ | I37: ○
B38: 現代社会とスポーツ | F38: 2 | H38: ○ | I38: ○
A44: ⑥ 「様々なデータ利活用の現場におけるデータ利活用事例が示され、様々な適用領域（流通、製造、金融、サービス、インフラ、公共、ヘルスケア等）の知見と組み合わせることで価値を創出するもの」の内容を含む授業科目
B46: 授業科目 | F46: 単位数 | G46: 必須 | H46: 1-4 | I46: 1-5 | J46: 授業科目 | P46: 単位数 | Q46: 必須 | R46: 1-4 | S46: 1-5
B47: 情報入門１ | F47: 2 | H47: ○ | I47: ○
B48: 心理情報とメンタルマネジメント | F48: 2 | H48: ○ | I48: ○
B49: ライフステージと健康情報 | F49: 2 | H49: ○ | I49: ○
B50: コンディショニングのための情報分析 | F50: 2 | H50: ○ | I50: ○
A55: ⑦ 「活用に当たっての様々な留意事項（ELSI、個人情報、データ倫理、ＡＩ社会原則等）を考慮し、情報セキュリティや情報漏洩等、データを守る上での留意事項への理解をする」の内容を含む授業科目
B57: 授業科目 | F57: 単位数 | G57: 必須 | H57: 3-1 | I57: 3-2 | J57: 授業科目 | P57: 単位数 | Q57: 必須 | R57: 3-1 | S57: 3-2
B58: 情報入門１ | F58: 2 | H58: ○ | I58: ○
B59: パブリックメディア論 | F59: 2 | H59: ○ | I59: ○
A66: ⑧ 「実データ・実課題（学術データ等を含む）を用いた演習など、社会での実例を題材として、「データを読む、説明する、扱う」といった数理・データサイエンス・ＡＩの基本的な活用法に関するもの」の内容を含む授業科目
B68: 授業科目 | E68: 単位数 | F68: 必須 | G68: 2-1 | H68: 2-2 | I68: 2-3 | J68: 授業科目 | O68: 単位数 | P68: 必須 | Q68: 2-1 | R68: 2-2 | S68: 2-3
B69: 情報入門１ | E69: 2 | G69: ○ | H69: ○ | I69: ○
B70: 情報入門２ | E70: 2 | G70: ○ | H70: ○
B71: 情報表現実習（応用） | E71: 2 | I71: ○
B72: スポーツ医科学情報 | E72: 2 | G72: ○ | H72: ○
B73: 現代社会とスポーツ | E73: 2 | G73: ○ | H73: ○
A77: ⑨ 選択「４．オプション」の内容を含む授業科目
B78: 授業科目 | F78: 選択項目 | J78: 授業科目 | P78: 選択項目
...

Sheet 様式１　プログラムを構成する授業科目　ネットワーク情報学部
R1: 様式１－５ | T1: 「学部・学科によって、修了要件は相違する」場合は、本シートを複製の上＜様式１－〇＞と枝番号を付してください
B2: 大学等名 | C2: 専修大学
B3: プログラム名 | C3: Siデータサイエンス教育プログラム（基礎リテラシーレベル）
A5: プログラムを構成する授業科目について
A7: ① 対象となる学部・学科名称 | J7: ② 教育プログラムの修了要件 | K7: 学部・学科によって、修了要件は相違する
B9: ネットワーク情報学部
A12: ③ 修了要件
B13: 「ネットワーク情報総論１」「 情報分析基礎」「情報分析演習」の３科目６単位を取得すること。 | V13: 【プルダウンリスト】
V14: 令和４年度以前より、履修することが必須のプログラムとして実施
V15: 令和７年度までに履修必須とする計画
V16: 令和８年度以降に履修必須とする計画、又は未定
B20: 必要最低単位数 | C20: 6 | E20: 単位 | J20: 履修必須の有無 | K20: 令和４年度以前より、履修することが必須のプログラムとして実施
A22: ④ 現在進行中の社会変化（第４次産業革命、Society 5.0、データ駆動型社会等）に深く寄与しているものであり、それが自らの生活と密接に結びついている」の内容を含む授業科目
B24: 授業科目 | F24: 単位数 | G24: 必須 | H24: 1-1 | I24: 1-6 | J24: 授業科目 | P24: 単位数 | Q24: 必須 | R24: 1-1 | S24: 1-6
B25: ネットワーク情報総論１ | F25: 2 | G25: ○ | H25: ○ | I25: ○
A33: ⑤ 「社会で活用されているデータ」や「データの活用領域」は非常に広範囲であって、日常生活や社会の課題を解決する有用なツールになり得るもの」の内容を含む授業科目
B35: 授業科目 | F35: 単位数 | G35: 必須 | H35: 1-2 | I35: 1-3 | J35: 授業科目 | P35: 単位数 | Q35: 必須 | R35: 1-2 | S35: 1-3
B36: ネットワーク情報総論１ | F36: 2 | G36: ○ | H36: ○ | I36: ○
A44: ⑥ 「様々なデータ利活用の現場におけるデータ利活用事例が示され、様々な適用領域（流通、製造、金融、サービス、インフラ、公共、ヘルスケア等）の知見と組み合わせることで価値を創出するもの」の内容を含む授業科目
B46: 授業科目 | F46: 単位数 | G46: 必須 | H46: 1-4 | I46: 1-5 | J46: 授業科目 | P46: 単位数 | Q46: 必須 | R46: 1-4 | S46: 1-5
B47: ネットワーク情報総論１ | F47: 2 | G47: ○ | H47: ○ | I47: ○
A55: ⑦ 「活用に当たっての様々な留意事項（ELSI、個人情報、データ倫理、ＡＩ社会原則等）を考慮し、情報セキュリティや情報漏洩等、データを守る上での留意事項への理解をする」の内容を含む授業科目
B57: 授業科目 | F57: 単位数 | G57: 必須 | H57: 3-1 | I57: 3-2 | J57: 授業科目 | P57: 単位数 | Q57: 必須 | R57: 3-1 | S57: 3-2
B58: ネットワーク情報総論１ | F58: 2 | G58: ○ | H58: ○ | I58: ○
A66: ⑧ 「実データ・実課題（学術データ等を含む）を用いた演習など、社会での実例を題材として、「データを読む、説明する、扱う」といった数理・データサイエンス・ＡＩの基本的な活用法に関するもの」の内容を含む授業科目
B68: 授業科目 | E68: 単位数 | F68: 必須 | G68: 2-1 | H68: 2-2 | I68: 2-3 | J68: 授業科目 | O68: 単位数 | P68: 必須 | Q68: 2-1 | R68: 2-2 | S68: 2-3
B69: 情報分析基礎 | E69: 2 | F69: ○ | G69: ○ | H69: ○ | I69: ○
B70: 情報分析演習 | E70: 2 | F70: ○ | G70: ○ | H70: ○ | I70: ○
A77: ⑨ 選択「４．オプション」の内容を含む授業科目
B78: 授業科目 | F78: 選択項目 | J78: 授業科目 | P78: 選択項目
A87: ⑩ プログラムを構成する授業の内容
B88: 授業に含まれている内容・要素 | D88: 講義内容
B89: （１）現在進行中の社会変化（第４次産業革命、Society 5.0、データ駆動型社会等）に深く寄与しているものであり、それが自らの生活と密接に結びついている | C89: 1-1 | D89: ・ビッグデータ、IoT、AI、ロボット「ネットワーク情報総論１」（３・４・１０回目） ・データ量の増加、計算機の処理性能の向上、AI の⾮連続的進化「ネットワーク情報総論１」（３・４・１０回目） ・第4 次産業革命、 Society 5.0 、 データ駆動型社会「ネットワーク情報総論１」（３・４・１０回目） ・複数技術を組み合わせたAIサービス「ネットワーク情報総論１」（３・４・１０回目）
C90: 1-6 | D90: ・AI最新技術の活用例（深層生成モデル、敵対的生成ネットワーク、強化学習、転移学習など）「ネットワーク情報総論１」（３・４・１０回目）
B91: （２）「社会で活用されているデータ」や「データの活用領域」は非常に広範囲であって、日常生活や社会の課題を解決する有用なツールになり得るもの | C91: 1-2 | D91: ・調査データ、実験データ、人の行動ログデータ、機械の稼働ログデータなど「ネットワーク情報総論１」（５・６・７回目） ・1次データ、2次データ、データのメタ化「ネットワーク情報総論１」（５・６・７回目） ・構造化データ、非構造化データ（文章、画像/動画、音声/音楽など）「ネットワーク情報総論１」（５・６・７回目） ・データのオープン化（オープンデータ）「ネットワーク情報総論１」（６回目）
C92: 1-3 | D92: ・データ・AI活用領域の広がり(生産、消費、文化活動など)「ネットワーク情報総論１」（５・６・７回目） ・研究開発、調達、製造、物流、販売、マーケティング、サービスなど「ネットワーク情報総論１」（５・６・７回目） ・仮説検証、知識発見、原因究明、計画策定、判断支援、活動代替、新規生成など「ネットワーク情報総論１」（５・６・７回目）
B93: （３）様々なデータ利活用の現場におけるデータ利活用事例が示され、様々な適用領域（流通、製造、金融、サービス、インフラ、公共、ヘルスケア等）の知見と組み合わせることで価値を創出するもの | C93: 1-4 | D93: ・データ解析：予測、グルーピング、パターン発見、最適化、シミュレーション・データ同化など「ネットワーク情報総論１」（５・７回目） ・データ可視化：複合グラフ、2軸グラフ、多次元の可視化、関係性の可視化、地図上の可視化、挙動・軌跡の可視化、リアルタイム可視化など「ネットワーク情報総論１」（５・７回目） ・非構造化データ処理：言語処理、画像/動画処理、音声/音楽処理など「ネットワーク情報総論１」（５・７回目） ・特化型AIと汎用AI、今のAIで出来ることと出来ないこと、AIとビッグデータ「ネットワーク情報総論１」（５・７回目）
C94: 1-5 | D94: ・データサイエンスのサイクル（課題抽出と定式化、データの取得・管理・加工、探索的データ解析、データ解析と推論、結果の共有・伝達、課題解決に向けた提案）「ネットワーク情報総論１」（５・７回目） ・流通、製造、金融、サービス、インフラ、公共、ヘルスケア等におけるデータ・AI利活用事例紹介「ネットワーク情報総論１」（５・７回目）
B95: （４）活用に当たっての様々な留意事項（ELSI、個人情報、データ倫理、ＡＩ社会原則等）を考慮し、情報セキュリティや情報漏洩等、データを守る上での留意事項への理解をする | C95: 3-1 | D95: ・ELSI（Ethical, Legal and Social Issues）「ネットワーク情報総論１」（８回目） ・個人情報保護、EU一般データ保護規則(GDPR)、忘れられる権利、オプトアウト「ネットワーク情報総論１」（８回目） ・データ倫理：データのねつ造、改ざん、盗用、プライバシー保護「ネットワーク情報総論１」（８回目） ・AI社会原則（公平性、説明責任、透明性、人間中心の判断）「ネットワーク情報総論１」（８回目） ・データバイアス、アルゴリズムバイアス「ネットワーク情報総論１」（８回目）
C96: 3-2 | D96: ・情報セキュリティ：機密性、完全性、可用性「ネットワーク情報総論１」（８回目） ・匿名加工情報、暗号化、パスワード、悪意ある情報搾取「ネットワーク情報総論１」（８回目） ・情報漏洩等によるセキュリティ事故の事例紹介「ネットワーク情報総論１」（８回目）
...

Sheet 様式１プログラムを構成する授業科目　国際コミュニケーション学部
R1: 様式１－６ | T1: 「学部・学科によって、修了要件は相違する」場合は、本シートを複製の上＜様式１－〇＞と枝番号を付してください
B2: 大学等名 | C2: 専修大学
B3: プログラム名 | C3: Siデータサイエンス教育プログラム（基礎リテラシーレベル）
A5: プログラムを構成する授業科目について
A7: ① 対象となる学部・学科名称 | J7: ② 教育プログラムの修了要件 | K7: 学部・学科によって、修了要件は相違する
B9: 国際コミュニケーション学部
A12: ③ 修了要件
B13: ＜日本語学科＞ 「日本語情報処理１」「日本語情報処理２」の２科目４単位を取得すること。 ＜異文化コミュニケーション学科＞ 「情報入門１」「情報入門２」の２科目４単位を取得すること。 | V13: 【プルダウンリスト】
V14: 令和４年度以前より、履修することが必須のプログラムとして実施
V15: 令和７年度までに履修必須とする計画
V16: 令和８年度以降に履修必須とする計画、又は未定
B20: 必要最低単位数 | C20: 4 | E20: 単位 | J20: 履修必須の有無 | K20: 令和８年度以降に履修必須とする計画、又は未定
A22: ④ 現在進行中の社会変化（第４次産業革命、Society 5.0、データ駆動型社会等）に深く寄与しているものであり、それが自らの生活と密接に結びついている」の内容を含む授業科目
B24: 授業科目 | F24: 単位数 | G24: 必須 | H24: 1-1 | I24: 1-6 | J24: 授業科目 | P24: 単位数 | Q24: 必須 | R24: 1-1 | S24: 1-6
B25: 日本語情報処理１ | F25: 2 | H25: ○ | I25: ○
B26: 日本語情報処理２ | F26: 2 | H26: ○
B27: 情報入門１ | F27: 2 | H27: ○ | I27: ○
A33: ⑤ 「社会で活用されているデータ」や「データの活用領域」は非常に広範囲であって、日常生活や社会の課題を解決する有用なツールになり得るもの」の内容を含む授業科目
B35: 授業科目 | F35: 単位数 | G35: 必須 | H35: 1-2 | I35: 1-3 | J35: 授業科目 | P35: 単位数 | Q35: 必須 | R35: 1-2 | S35: 1-3
B36: 日本語情報処理１ | F36: 2 | H36: ○ | I36: ○
B37: 日本語情報処理２ | F37: 2 | H37: ○
B38: 情報入門１ | F38: 2 | H38: ○ | I38: ○
A44: ⑥ 「様々なデータ利活用の現場におけるデータ利活用事例が示され、様々な適用領域（流通、製造、金融、サービス、インフラ、公共、ヘルスケア等）の知見と組み合わせることで価値を創出するもの」の内容を含む授業科目
B46: 授業科目 | F46: 単位数 | G46: 必須 | H46: 1-4 | I46: 1-5 | J46: 授業科目 | P46: 単位数 | Q46: 必須 | R46: 1-4 | S46: 1-5
B47: 日本語情報処理１ | F47: 2 | H47: ○ | I47: ○
B48: 情報入門１ | F48: 2 | H48: ○ | I48: ○
A55: ⑦ 「活用に当たっての様々な留意事項（ELSI、個人情報、データ倫理、ＡＩ社会原則等）を考慮し、情報セキュリティや情報漏洩等、データを守る上での留意事項への理解をする」の内容を含む授業科目
B57: 授業科目 | F57: 単位数 | G57: 必須 | H57: 3-1 | I57: 3-2 | J57: 授業科目 | P57: 単位数 | Q57: 必須 | R57: 3-1 | S57: 3-2
B58: 日本語情報処理１ | F58: 2 | H58: ○ | I58: ○
B59: 日本語情報処理２ | F59: 2 | H59: ○
B60: 情報入門１ | F60: 2 | H60: ○ | I60: ○
A66: ⑧ 「実データ・実課題（学術データ等を含む）を用いた演習など、社会での実例を題材として、「データを読む、説明する、扱う」といった数理・データサイエンス・ＡＩの基本的な活用法に関するもの」の内容を含む授業科目
B68: 授業科目 | E68: 単位数 | F68: 必須 | G68: 2-1 | H68: 2-2 | I68: 2-3 | J68: 授業科目 | O68: 単位数 | P68: 必須 | Q68: 2-1 | R68: 2-2 | S68: 2-3
B69: 日本語情報処理１ | E69: 2 | G69: ○ | I69: ○
B70: 日本語情報処理２ | E70: 2 | G70: ○ | H70: ○ | I70: ○
B71: 情報入門１ | E71: 2 | G71: ○ | H71: ○ | I71: ○
B72: 情報入門２ | E72: 2 | G72: ○ | H72: ○
A77: ⑨ 選択「４．オプション」の内容を含む授業科目
B78: 授業科目 | F78: 選択項目 | J78: 授業科目 | P78: 選択項目
A87: ⑩ プログラムを構成する授業の内容
...

Sheet 様式２ 履修者等数の実績
AQ1: 様式２
AL2: 大学等名 | AM2: ='様式１ プログラムを構成する授業科目'!C2 -> 専修大学
A3: プログラムの履修者数等の実績について
A5: ①プログラム開設年度 | C5: 令和４ | E5: 年度
A7: ②履修者・修了者の実績
B9: 学部・学科名称 | C9: 学生数 | D9: 入学 定員 | E9: 収容 定員 | F9: 令和4年度 | L9: 令和3年度 | R9: 令和2年度 | X9: 令和元年度 | AD9: 平成30年度 | AJ9: 平成29年度 | AP9: 履修者数 合計 | AQ9: 履修率
F10: 履修者数 | I10: 修了者数 | L10: 履修者数 | O10: 修了者数 | R10: 履修者数 | U10: 修了者数 | X10: 履修者数 | AA10: 修了者数 | AD10: 履修者数 | AG10: 修了者数 | AJ10: 履修者数 | AM10: 修了者数
F11: 合計 | G11: 男性 | H11: 女性 | I11: 合計 | J11: 男性 | K11: 女性 | L11: 合計 | M11: 男性 | N11: 女性 | O11: 合計 | P11: 男性 | Q11: 女性 | R11: 合計 | S11: 男性 | T11: 女性 | U11: 合計 | V11: 男性 | W11: 女性 | X11: 合計 | Y11: 男性 | Z11: 女性 | AA11: 合計 | AB11: 男性 | AC11: 女性 | AD11: 合計 | AE11: 男性 | AF11: 女性 | AG11: 合計 | AH11: 男性 | AI11: 女性 | AJ11: 合計 | AK11: 男性 | AL11: 女性 | AM11: 合計 | AN11: 男性 | AO11: 女性
B12: 経済学部 | C12: 3135 | D12: 751 | E12: 2948 | F12: 329 | I12: 264 | L12: =M12+N12 -> 0 | O12: =P12+Q12 -> 0 | R12: =S12+T12 -> 0 | U12: =V12+W12 -> 0 | X12: =Y12+Z12 -> 0 | AA12: =AB12+AC12 -> 0 | AD12: =AE12+AF12 -> 0 | AG12: =AH12+AI12 -> 0 | AJ12: =AK12+AL12 -> 0 | AM12: =AN12+AO12 -> 0 | AP12: =F12+L12+R12+X12+AD12+AJ12 -> 329 | AQ12: =AP12/E12 -> 0.11160109
B13: 法学部 | C13: 3016 | D13: 697 | E13: 2806 | F13: 529 | I13: 425 | L13: =M13+N13 -> 0 | O13: =P13+Q13 -> 0 | R13: =S13+T13 -> 0 | U13: =V13+W13 -> 0 | X13: =Y13+Z13 -> 0 | AA13: =AB13+AC13 -> 0 | AD13: =AE13+AF13 -> 0 | AG13: =AH13+AI13 -> 0 | AJ13: =AK13+AL13 -> 0 | AM13: =AN13+AO13 -> 0 | AP13: =F13+L13+R13+X13+AD13+AJ13 -> 529 | AQ13: =AP13/E13 -> 0.18852459
B14: 経営学部 | C14: 2399 | D14: 553 | E14: 2212 | F14: 606 | I14: 432 | L14: =M14+N14 -> 0 | O14: =P14+Q14 -> 0 | R14: =S14+T14 -> 0 | U14: =V14+W14 -> 0 | X14: =Y14+Z14 -> 0 | AA14: =AB14+AC14 -> 0 | AD14: =AE14+AF14 -> 0 | AG14: =AH14+AI14 -> 0 | AJ14: =AK14+AL14 -> 0 | AM14: =AN14+AO14 -> 0 | AP14: =F14+L14+R14+X14+AD14+AJ14 -> 606 | AQ14: =AP14/E14 -> 0.27396022
B15: 商学部 | C15: 2791 | D15: 648 | E15: 2619 | F15: 681 | I15: 636 | L15: =M15+N15 -> 0 | O15: =P15+Q15 -> 0 | R15: =S15+T15 -> 0 | U15: =V15+W15 -> 0 | X15: =Y15+Z15 -> 0 | AA15: =AB15+AC15 -> 0 | AD15: =AE15+AF15 -> 0 | AG15: =AH15+AI15 -> 0 | AJ15: =AK15+AL15 -> 0 | AM15: =AN15+AO15 -> 0 | AP15: =F15+L15+R15+X15+AD15+AJ15 -> 681 | AQ15: =AP15/E15 -> 0.26002291
B16: 文学部 | C16: 2910 | D16: 671 | E16: 2718 | F16: 282 | I16: 122 | L16: =M16+N16 -> 0 | O16: =P16+Q16 -> 0 | R16: =S16+T16 -> 0 | U16: =V16+W16 -> 0 | X16: =Y16+Z16 -> 0 | AA16: =AB16+AC16 -> 0 | AD16: =AE16+AF16 -> 0 | AG16: =AH16+AI16 -> 0 | AJ16: =AK16+AL16 -> 0 | AM16: =AN16+AO16 -> 0 | AP16: =F16+L16+R16+X16+AD16+AJ16 -> 282 | AQ16: =AP16/E16 -> 0.10375276
B17: ネットワーク情報学部 | C17: 989 | D17: 235 | E17: 940 | F17: 247 | I17: 199 | L17: =M17+N17 -> 0 | O17: =P17+Q17 -> 0 | R17: =S17+T17 -> 0 | U17: =V17+W17 -> 0 | X17: =Y17+Z17 -> 0 | AA17: =AB17+AC17 -> 0 | AD17: =AE17+AF17 -> 0 | AG17: =AH17+AI17 -> 0 | AJ17: =AK17+AL17 -> 0 | AM17: =AN17+AO17 -> 0 | AP17: =F17+L17+R17+X17+AD17+AJ17 -> 247 | AQ17: =AP17/E17 -> 0.26276596
B18: 人間科学部 | C18: 936 | D18: 224 | E18: 866 | F18: 142 | I18: 125 | L18: =M18+N18 -> 0 | O18: =P18+Q18 -> 0 | R18: =S18+T18 -> 0 | U18: =V18+W18 -> 0 | X18: =Y18+Z18 -> 0 | AA18: =AB18+AC18 -> 0 | AD18: =AE18+AF18 -> 0 | AG18: =AH18+AI18 -> 0 | AJ18: =AK18+AL18 -> 0 | AM18: =AN18+AO18 -> 0 | AP18: =F18+L18+R18+X18+AD18+AJ18 -> 142 | AQ18: =AP18/E18 -> 0.16397229
B19: 国際コミュニケーション学部 | C19: 689 | D19: 221 | E19: 663 | F19: 160 | I19: 145 | L19: =M19+N19 -> 0 | O19: =P19+Q19 -> 0 | R19: =S19+T19 -> 0 | U19: =V19+W19 -> 0 | X19: =Y19+Z19 -> 0 | AA19: =AB19+AC19 -> 0 | AD19: =AE19+AF19 -> 0 | AG19: =AH19+AI19 -> 0 | AJ19: =AK19+AL19 -> 0 | AM19: =AN19+AO19 -> 0 | AP19: =F19+L19+R19+X19+AD19+AJ19 -> 160 | AQ19: =AP19/E19 -> 0.2413273
F20: =G20+H20 -> 0 | I20: =J20+K20 -> 0 | L20: =M20+N20 -> 0 | O20: =P20+Q20 -> 0 | R20: =S20+T20 -> 0 | U20: =V20+W20 -> 0 | X20: =Y20+Z20 -> 0 | AA20: =AB20+AC20 -> 0 | AD20: =AE20+AF20 -> 0 | AG20: =AH20+AI20 -> 0 | AJ20: =AK20+AL20 -> 0 | AM20: =AN20+AO20 -> 0 | AP20: =F20+L20+R20+X20+AD20+AJ20 -> 0 | AQ20: =AP20/E20 -> #DIV/0!
F21: =G21+H21 -> 0 | I21: =J21+K21 -> 0 | L21: =M21+N21 -> 0 | O21: =P21+Q21 -> 0 | R21: =S21+T21 -> 0 | U21: =V21+W21 -> 0 | X21: =Y21+Z21 -> 0 | AA21: =AB21+AC21 -> 0 | AD21: =AE21+AF21 -> 0 | AG21: =AH21+AI21 -> 0 | AJ21: =AK21+AL21 -> 0 | AM21: =AN21+AO21 -> 0 | AP21: =F21+L21+R21+X21+AD21+AJ21 -> 0 | AQ21: =AP21/E21 -> #DIV/0!
F22: =G22+H22 -> 0 | I22: =J22+K22 -> 0 | L22: =M22+N22 -> 0 | O22: =P22+Q22 -> 0 | R22: =S22+T22 -> 0 | U22: =V22+W22 -> 0 | X22: =Y22+Z22 -> 0 | AA22: =AB22+AC22 -> 0 | AD22: =AE22+AF22 -> 0 | AG22: =AH22+AI22 -> 0 | AJ22: =AK22+AL22 -> 0 | AM22: =AN22+AO22 -> 0 | AP22: =F22+L22+R22+X22+AD22+AJ22 -> 0 | AQ22: =AP22/E22 -> #DIV/0!
F23: =G23+H23 -> 0 | I23: =J23+K23 -> 0 | L23: =M23+N23 -> 0 | O23: =P23+Q23 -> 0 | R23: =S23+T23 -> 0 | U23: =V23+W23 -> 0 | X23: =Y23+Z23 -> 0 | AA23: =AB23+AC23 -> 0 | AD23: =AE23+AF23 -> 0 | AG23: =AH23+AI23 -> 0 | AJ23: =AK23+AL23 -> 0 | AM23: =AN23+AO23 -> 0 | AP23: =F23+L23+R23+X23+AD23+AJ23 -> 0 | AQ23: =AP23/E23 -> #DIV/0!
F24: =G24+H24 -> 0 | I24: =J24+K24 -> 0 | L24: =M24+N24 -> 0 | O24: =P24+Q24 -> 0 | R24: =S24+T24 -> 0 | U24: =V24+W24 -> 0 | X24: =Y24+Z24 -> 0 | AA24: =AB24+AC24 -> 0 | AD24: =AE24+AF24 -> 0 | AG24: =AH24+AI24 -> 0 | AJ24: =AK24+AL24 -> 0 | AM24: =AN24+AO24 -> 0 | AP24: =F24+L24+R24+X24+AD24+AJ24 -> 0 | AQ24: =AP24/E24 -> #DIV/0!
F25: =G25+H25 -> 0 | I25: =J25+K25 -> 0 | L25: =M25+N25 -> 0 | O25: =P25+Q25 -> 0 | R25: =S25+T25 -> 0 | U25: =V25+W25 -> 0 | X25: =Y25+Z25 -> 0 | AA25: =AB25+AC25 -> 0 | AD25: =AE25+AF25 -> 0 | AG25: =AH25+AI25 -> 0 | AJ25: =AK25+AL25 -> 0 | AM25: =AN25+AO25 -> 0 | AP25: =F25+L25+R25+X25+AD25+AJ25 -> 0 | AQ25: =AP25/E25 -> #DIV/0!
F26: =G26+H26 -> 0 | I26: =J26+K26 -> 0 | L26: =M26+N26 -> 0 | O26: =P26+Q26 -> 0 | R26: =S26+T26 -> 0 | U26: =V26+W26 -> 0 | X26: =Y26+Z26 -> 0 | AA26: =AB26+AC26 -> 0 | AD26: =AE26+AF26 -> 0 | AG26: =AH26+AI26 -> 0 | AJ26: =AK26+AL26 -> 0 | AM26: =AN26+AO26 -> 0 | AP26: =F26+L26+R26+X26+AD26+AJ26 -> 0 | AQ26: =AP26/E26 -> #DIV/0!
F27: =G27+H27 -> 0 | I27: =J27+K27 -> 0 | L27: =M27+N27 -> 0 | O27: =P27+Q27 -> 0 | R27: =S27+T27 -> 0 | U27: =V27+W27 -> 0 | X27: =Y27+Z27 -> 0 | AA27: =AB27+AC27 -> 0 | AD27: =AE27+AF27 -> 0 | AG27: =AH27+AI27 -> 0 | AJ27: =AK27+AL27 -> 0 | AM27: =AN27+AO27 -> 0 | AP27: =F27+L27+R27+X27+AD27+AJ27 -> 0 | AQ27: =AP27/E27 -> #DIV/0!
F28: =G28+H28 -> 0 | I28: =J28+K28 -> 0 | L28: =M28+N28 -> 0 | O28: =P28+Q28 -> 0 | R28: =S28+T28 -> 0 | U28: =V28+W28 -> 0 | X28: =Y28+Z28 -> 0 | AA28: =AB28+AC28 -> 0 | AD28: =AE28+AF28 -> 0 | AG28: =AH28+AI28 -> 0 | AJ28: =AK28+AL28 -> 0 | AM28: =AN28+AO28 -> 0 | AP28: =F28+L28+R28+X28+AD28+AJ28 -> 0 | AQ28: =AP28/E28 -> #DIV/0!
F29: =G29+H29 -> 0 | I29: =J29+K29 -> 0 | L29: =M29+N29 -> 0 | O29: =P29+Q29 -> 0 | R29: =S29+T29 -> 0 | U29: =V29+W29 -> 0 | X29: =Y29+Z29 -> 0 | AA29: =AB29+AC29 -> 0 | AD29: =AE29+AF29 -> 0 | AG29: =AH29+AI29 -> 0 | AJ29: =AK29+AL29 -> 0 | AM29: =AN29+AO29 -> 0 | AP29: =F29+L29+R29+X29+AD29+AJ29 -> 0 | AQ29: =AP29/E29 -> #DIV/0!
F30: =G30+H30 -> 0 | I30: =J30+K30 -> 0 | L30: =M30+N30 -> 0 | O30: =P30+Q30 -> 0 | R30: =S30+T30 -> 0 | U30: =V30+W30 -> 0 | X30: =Y30+Z30 -> 0 | AA30: =AB30+AC30 -> 0 | AD30: =AE30+AF30 -> 0 | AG30: =AH30+AI30 -> 0 | AJ30: =AK30+AL30 -> 0 | AM30: =AN30+AO30 -> 0 | AP30: =F30+L30+R30+X30+AD30+AJ30 -> 0 | AQ30: =AP30/E30 -> #DIV/0!
F31: =G31+H31 -> 0 | I31: =J31+K31 -> 0 | L31: =M31+N31 -> 0 | O31: =P31+Q31 -> 0 | R31: =S31+T31 -> 0 | U31: =V31+W31 -> 0 | X31: =Y31+Z31 -> 0 | AA31: =AB31+AC31 -> 0 | AD31: =AE31+AF31 -> 0 | AG31: =AH31+AI31 -> 0 | AJ31: =AK31+AL31 -> 0 | AM31: =AN31+AO31 -> 0 | AP31: =F31+L31+R31+X31+AD31+AJ31 -> 0 | AQ31: =AP31/E31 -> #DIV/0!
B32: 合 計 | C32: =SUM(C12:C31) -> 16865 | D32: =SUM(D12:D31) -> 4000 | E32: =SUM(E12:E31) -> 15772 | F32: =SUM(F12:F31) -> 2976 | G32: =SUM(G12:G31) -> 0 | H32: =SUM(H12:H31) -> 0 | I32: =SUM(I12:I31) -> 2348 | J32: =SUM(J12:J31) -> 0 | ... AP32: =SUM(AP12:AP31) -> 2976 | AQ32: =AP32/E32 -> 0.18868882

Sheet 様式３ 教育の質・履修者数を向上させるための体制・計画
I1: 様式３
G2: 大学等名 | H2: ='様式１ プログラムを構成する授業科目'!C2 -> 専修大学
A4: 教育の質・履修者数を向上させるための体制・計画について
A6: ① | B6: 全学の教員数 | C6: (常勤） | E6: 442 | F6: 人 | G6: （非常勤） | H6: 720 | I6: 人
A8: ② | B8: プログラムの授業を教えている教員数 | H8: 46 | I8: 人
A10: ③ | B10: プログラムの運営責任者
B11: （責任者名） | C11: 松永 賢次 | G11: （役職名） | H11: ネットワーク情報学部教授
A13: ④ | B13: プログラムを改善・進化させるための体制（委員会・組織等）
B14: 専修大学数理・データサイエンス・ＡＩ教育運営委員会
B16: （責任者名） | C16: 松永 賢次 | G16: （役職名） | H16: ネットワーク情報学部教授
A18: ⑤ | B18: プログラムを改善・進化させるための体制を定める規則名称
B19: 専修大学数理・データサイエンス・ＡＩ教育運営委員会規程
A21: ⑥ | B21: 体制の目的
B22: 数理・データサイエンス・ＡＩ教育の円滑な運営を図るために必要な連絡調整を行い、本学における数理・データサイエンス・ＡＩ教育の推進及び質向上を図ることを目的として、令和４年４月１日に「専修大学数理・データサイエンス・ＡＩ教育運営委員会」を設置した。 本委員会では本学の数理・データサイエンス・AI教育分野の授業科目ならびに教育プログラムの点検、評価、改善・充実とその支援に取り組んでいる。
A34: ⑦ | B34: 具体的な構成員
B35: ネットワーク情報学部 教授 松永 賢次 （委員長・情報科学センター長） 商学部 教授 岩尾 詠一郎 （情報科学センター教育企画室長） 経済学部 准教授 小川 健 法学部 教授 水崎 高浩 経営学部 教授 西山 貴弘 経営学部 准教授 宇佐美 嘉弘 商学部 教授 高萩 栄一郎 文学部 教授 福冨 忠和 人間科学部 教授 金井 雅之 国際コミュニケーション学部 教授 丸山 岳彦 教務部教務課 課長 遠藤 清 情報システム部情報システム課 掛長 天坂 里緒子
A48: ⑧ | B48: 履修者数・履修率の向上に向けた計画 ※様式１の「履修必須の有無」で「計画がある」としている場合は詳細について記載すること
B49: 令和４年度実績 | C49: ='様式２ 履修者等数の実績'!AQ32 -> 0.18868882 | E49: 令和５年度予定 | F49: 0.38 | H49: 令和６年度予定 | I49: 0.57
B50: 令和７年度予定 | C50: 0.76 | E50: 令和８年度予定 | F50: 0.85 | H50: 収容定員（名） | I50: ='様式２ 履修者等数の実績'!E32 -> 15772
B51: 具体的な計画
B52: 上記の目標を実現するために、以下の取組みを実施する計画である。 ●令和５年度の計画 １ 「情報入門１・２」の展開増等の対応 令和４年度開講の「情報入門 １」を調査したところ、 履修希望者が特定の曜日・時限に集中していたため、２割程度が希望する曜日・時限で履修できなかったことが判明した。そのため、令和５年度は、令和４年度の実績（学生の履修状況）に基づき、「情報入門１」「情報入門２」の展開増等で履修率の改善を図る。 ２ 文学部ジャーナリズム学科の令和５年度カリキュラム改正 多くの学科が「情報入門１」「情報入門２」の２科目４単位の修得で基礎リテラシーレベルの修了を認定する一方、文学部ジャーナリズム学科の令和４年度入学者は、「情報入門１」「情報入門２」を履修できないカリキュラムとなっていた。そのため、基礎リテラシーレベル修了には配当年次が２年次以上の２科目を含む５科目10単位の修得が求められていたことから、同学科における履修者数・履修率の向上を図るため令和５年度以降入学者を対象に、「情報入門１」「情報入門２」を履修できるようカリキュラム改正を行うとともに、修了要件をこの２科目の修得に変更する。これに伴い、令和４年度の文学部ジャーナリズム学科の修了要件は、令和５年度入学者からは適用しない。 ●令和６年度以降の計画 令和５年度の実績や外部評価の結果に基づき、令和６年度以降の改善策を検討する。
A65: ⑨ | B65: 学部・学科に関係なく希望する学生全員が受講可能となるような必要な体制・取組等
B66: Siデータサイエンス教育プログラム（基礎リテラシーレベル）の開講科目は各学部で異なるものの、ネットワーク情報学部および国際コミュニケーション学部日本語学科においては開講科目の全てを必修科目としている。 経営学部においては全ての開講科目（４科目）のうち、３科目を必修科目に設定しており、残る１科目は選択必修科目に位置付けられているものの、当該科目は履修を希望する全ての学生が履修できるように対応している。 文学部ジャーナリズム学科においては、⑧に記載のとおり、令和５年度にカリキュラム改正を行うことによって、他学科と比べて著しく高い修了要件となっていた状況の見直しを図る。 一方、これらを除く全ての学部・学科においては、基礎的なデータ分析の手法や統計学について、「情報入門１・２（情報基礎Ⅰ・Ⅱ）」を履修することとなるが、⑧に記載のとおり、履修を希望する全ての学生が履修可能となるように、令和５年度は「情報入門１」「情報入門２」の展開増等を計画している。
A79: ⑩ | B79: できる限り多くの学生が履修できるような具体的な周知方法・取組
B80: Siデータサイエンス教育プログラム（基礎リテラシーレベル）の履修率向上を目的として、令和４年度入学者に対しては、Siデータサイエンス教育プログラム専用のホームページの公開や、ニュース専修による紹介、さらには令和４年４月のオリエンテーションガイダンスにおけるリーフレットの配布を通じて、令和４年度入学者に向けて様々な周知を行った。それに加えて、専修大学長と専修大学数理・データサイエンス・AI教育運営委員会委員長との対談動画を用意し、この動画をSiデータサイエンス教育プログラム専用のホームページで紹介するなどの広報活動を展開した。 令和５年度は、引き続きSiデータサイエンス教育プログラム専用のホームページにおいて本プログラムの周知を図るとともに、オリエンテーションガイダンスの際、「学修ガイドブック」を活用したガイダンス説明などを計画している。
A93: ⑪ | B93: できる限り多くの学生が履修・修得できるようなサポート体制
B94: Siデータサイエンス教育プログラム（基礎リテラシーレベル）では、学生の興味・関心にあわせたオンデマンド教材８本(１本：15～20分程度)を用意することにより、学生の理解力向上につなげることができた。令和５年度は、昨年度制作した既存動画８本の改訂に加えて、新規動画２本の制作を行う計画である。 また、⑩に記載のとおり、専修大学長と専修大学数理・データサイエンス・AI教育運営委員会委員長との対談動画をSiデータサイエンス教育プログラム専用のホームページで紹介するなど、学生がこの動画を通じて数理・データサイエンス・AI教育を受講することの意義を理解できるように努めている。
A107: ⑫ | B107: 授業時間内外で学習指導、質問を受け付ける具体的な仕組み
B108: 電子メールや授業支援システム(LMS)であるin CampusやGoogle Classroomを通じて、履修者はいつでも担当教員から質問することができ、また返信されるスキームを構築している。それに加えて、オフィスアワー制度の導入により、専任教員が質問対応や履修上の相談に対応できる体制も整備している。 さらに、学内の情報環境の利用に関するサポートを情報科学センターが担っており、授業時間外に資格試験を受験することに対する支援として、PCスキルアップ講座、MOS資格試験対策講座、ＩＴパスポート対策講座、情報セキュリティマネジメント試験対策講座などの各種講座を実施している。

Sheet 様式４　自己点検・評価
I1: 様式４
H2: 大学等名 | I2: ='様式１ プログラムを構成する授業科目'!C2 -> 専修大学
A3: 自己点検・評価について
A5: ① | B5: プログラムの自己点検・評価を行う体制（委員会・組織等）
B6: 専修大学数理・データサイエンス・ＡＩ教育関係自己点検・評価実施委員会
D8: （責任者名） | E8: 松永 賢次 | G8: （役職名） | H8: ネットワーク情報学部教授
A10: ② | B10: 自己点検・評価体制における意見等
B11: 自己点検・評価の視点 | E11: 自己点検・評価体制における意見・結果・改善に向けた取組等
B12: 学内からの視点
C13: プログラムの履修・修得状況 | E13: 教務部教務課において、Siデータサイエンス教育プログラム（基礎リテラシーレベル）の履修・修得状況を分析し、その結果を数理・データサイエンス・AI教育運営委員会にて情報共有することにより、学生の履修率の向上などの検討を図っている。
C14: 学修成果 | E14: 数理・データサイエンス・AI教育運営委員会において、令和４年10月24日（月）から11月27日（日）までの間、大規模な学生アンケート調査を実施し、学生の学修成果を測定した。アンケート対象者は、本プログラムを受講する令和４年度入学者（２年次にも開講科目がある文学部ジャーナリズム学科については調査から除外。）とした。対象者2,834名のうち、1,148名が回答しており、回答率は40.5%であった。学生の学修成果を測定するに際しては、①【意欲】②【理解度】③【成長実感】④【推奨度】⑤【希望】の５つの観点から把握・測定し、本委員会にてSiデータサイエンス教育プログラム（基礎リテラシーレベル）の評価・改善を行っている。
C15: 学生アンケート等を通じた学生の内容の理解度 | E15: 上述の学生アンケート調査において、学生の【理解度】を確認するために設定した、設問２「データ・AIによって、社会および日常生活が大きく変化していることを理解できた。」、設問３「『数理・データサイエンス・AI』が、今後の社会における『読み・書き・そろばん』に相当することを理解できた。」、設問４「今のAIで出来ることと、出来ないことを理解できた。」、設問５「AIを活用した新しいビジネスやサービスは複数の技術が組み合わされて実現していることを理解できた。」、設問７「個人情報保護法やＥＵ一般データ保護規則（ＧＤＰＲ）など、データを取り巻く国際的な動向を理解できた。」、設問８「データ・AIを利活用する際に求められるモラルや倫理、データ駆動型社会におけるリスク、個人のデータを守るために留意すべき事項を理解できた。」については、設問７を除いて、肯定回答率が50％を超える結果となった。 その一方で、肯定回答率が46.4％に沈んだ設問７については、新入生には理解が難しい授業内容であることが判明した。この点については、次年度以降の課題であると認識している。
C16: 学生アンケート等を通じた後輩等他の学生への推奨度 | E16: 上述の学生アンケート調査において、学生の【推奨度】を確認するために設定した、設問10「このSiデータサイエンス教育プログラムを、後輩や友人などのほかの学生に勧めたい。」については、肯定回答率が62.5％となり、本プログラムを高く評価していることが確認できた。
C17: 全学的な履修者数、履修率向上に向けた計画の達成・進捗状況 | E17: 数理・データサイエンス・AI教育運営委員会において、全学的な観点からSiデータサイエンス教育プログラム（基礎リテラシーレベル）の実施状況についての確認を継続的に行っている。本委員会では令和４年度実績に基づき、令和５年度の履修者数・履修率の向上に向けた計画を立案している。令和５年度は、「情報入門１」「情報入門２」の展開増等、文学部ジャーナリズム学科のカリキュラム改正（学生が「情報入門１」「情報入門２」を履修できるように改正）を主に計画している。
B18: 学外からの視点
C19: 教育プログラム修了者の進路、活躍状況、企業等の評価 | E19: Siデータサイエンス教育プログラム（基礎リテラシーレベル）については令和４年度に開講したことから、本プログラム第１期生の卒業は令和７年度からとなる。したがって、現状では本申請のプログラム修了者の進路調査や活躍状況の調査、企業からの評価は受けていない。今後は、数理・データサイエンス・AI教育運営委員会を中心としてキャリアセンター事務部と調整を図りながら、教育プログラム修了者の進路や活躍状況などを追跡できるように整備を進めていく計画である。
C20: 産業界からの視点を含めた教育プログラム内容・手法等への意見 | E20: 産業界で活躍中の外部評価委員と年１回、「外部評価」の機会を設けている。令和４年度は、Siデータサイエンス教育プログラム（基礎リテラシーレベル）の教育内容を中心にオンラインで実施し、外部評価委員からは概ね肯定的な意見をいただいた。 その一方で、外部評価委員からは本プログラムが内包する課題も複数指摘されたことから、これらの課題については数理・データサイエンス・AI教育運営委員会を通じて、改善していく計画である。
B21: 数理・データサイエンス・ＡＩを「学ぶ楽しさ」「学ぶことの意義」を理解させること | E21: 上述の学生アンケート調査において、設問12では、本プログラムにおける学生の評価を確認することを企図して、「Siデータサイエンス教育プログラムを受講して良かったと思う点を記入してください。」を設定した。本設問は、任意項目であったものの、482名の有効回答数を得ることができた。 学生からフィードバックされた回答については、テキストマイニングを活用して共起キーワードを分析した結果、「できる」「知る」「学ぶ」「身につける」といった学生の成長実感が、AIやデータを含む多様なキーワードと結びついていることが看取できた。この学生の成長実感は、数理・データサイエンス・ＡＩを「学ぶ楽しさ」を直接的ないしは間接的に証明しているものと考える。なお、学生の【意欲】を確認するために設定した、設問１「Siデータサイエンス教育プログラムに意欲的に参加することができた。」については、肯定回答率の割合が、67.1％となり、７割近くの学生が本プログラムに意欲的に参加していることが確認できた。 また、専修大学長と専修大学数理・データサイエンス・AI教育運営委員会委員長との対談動画をSiデータサイエンス教育プログラム専用のホームページで紹介するなど、この動画を通じてより多くの学生に数理・データサイエンス・AI教育を受講することの意義を伝えている。
B22: 内容・水準を維持・向上しつつ、より「分かりやすい」授業とすること | E22: Siデータサイエンス教育プログラム（基礎リテラシーレベル）では、学生の興味・関心にあわせたオンデマンド教材８本(１本：15～20分程度)を用意することにより、教育内容・水準を維持しつつ、学生にとってわかりやすい授業を展開することができた。数理・データサイエンス・AI教育運営委員会では、本委員会委員より、オンデマンド教材を活用した授業が学生に好評であったことが報告されている。 一方、上述の学生アンケート調査において、「Siデータサイエンス教育プログラムをより良くするために工夫できることがあれば記入してください。」を設問１３に設定した。本設問は、任意項目であったものの、124名の有効回答数を得ることができた。学生からフィードバックされた回答については一部の学生からの声ではあるものの、本プログラムの授業内容が「伝わりにくい」「難しい」といったキーワードが抽出されたため、今後は、より分かりやすい授業内容に改善していく必要があると考える。
