Workbook

Sheet 様式１－1　プログラムを構成する授業科目
R1: 様式１－１ | T1: 「学部・学科によって、修了要件は相違する」場合は、本シートを複製の上＜様式１－〇＞と枝番号を付してください
B2: 大学等名 | C2: 岡山商科大学
B3: プログラム名 | C3: データサイエンス・リテラシー教育プログラム
A5: プログラムを構成する授業科目について
A7: ① 対象となる学部・学科名称 | J7: ② 教育プログラムの修了要件 | K7: 学部・学科によって、修了要件は相違する
B9: 経済学部、経営学部
A12: ③ 修了要件
B13: プログラムを構成する「必修科目（下記１、２）」の4単位、「グループA科目群（下記３～５）」から2単位以上、「グループB科目群（下記６～１５）」から8単位以上を取得すること。 必修科目：１．データ分析、２．法と情報 グループA科目群：３．情報と職業、４．情報技術論Ⅱ、５．情報社会と情報倫理 グループB科目群：６．データサイエンス入門Ⅰ、７．データサイエンス入門Ⅱ、８．経済統計論Ⅰ、９．経済統計論Ⅱ、１０．経営統計学Ⅰ、１１．経営統計学Ⅱ、１２．市場調査論、１３．教育におけるICT活用、１４．情報システム技術、１５．応用情報処理Ⅰ | V13: 【プルダウンリスト】
V14: 令和４年度以前より、履修することが必須のプログラムとして実施
V15: 令和７年度までに履修必須とする計画
V16: 令和８年度以降に履修必須とする計画、又は未定
B20: 必要最低単位数 | C20: 14 | E20: 単位 | J20: 履修必須の有無 | K20: 令和８年度以降に履修必須とする計画、又は未定
A22: ④ 現在進行中の社会変化（第４次産業革命、Society 5.0、データ駆動型社会等）に深く寄与しているものであり、それが自らの生活と密接に結びついている」の内容を含む授業科目
B24: 授業科目 | F24: 単位数 | G24: 必須 | H24: 1-1 | I24: 1-6 | J24: 授業科目 | P24: 単位数 | Q24: 必須 | R24: 1-1 | S24: 1-6
B25: 法と情報 | F25: 2 | G25: ○ | H25: ○ | I25: ○
B26: 情報と職業 | F26: 2 | H26: ○ | I26: ○
B27: 情報技術論Ⅱ | F27: 2 | H27: ○ | I27: ○
B28: 情報社会と情報倫理 | F28: 2 | H28: ○ | I28: ○
A33: ⑤ 「社会で活用されているデータ」や「データの活用領域」は非常に広範囲であって、日常生活や社会の課題を解決する有用なツールになり得るもの」の内容を含む授業科目
B35: 授業科目 | F35: 単位数 | G35: 必須 | H35: 1-2 | I35: 1-3 | J35: 授業科目 | P35: 単位数 | Q35: 必須 | R35: 1-2 | S35: 1-3
B36: 法と情報 | F36: 2 | G36: ○ | H36: ○ | I36: ○
B37: 情報と職業 | F37: 2 | H37: ○ | I37: ○
B38: 情報技術論Ⅱ | F38: 2 | H38: ○ | I38: ○
B39: 情報社会と情報倫理 | F39: 2 | H39: ○ | I39: ○
A44: ⑥ 「様々なデータ利活用の現場におけるデータ利活用事例が示され、様々な適用領域（流通、製造、金融、サービス、インフラ、公共、ヘルスケア等）の知見と組み合わせることで価値を創出するもの」の内容を含む授業科目
B46: 授業科目 | F46: 単位数 | G46: 必須 | H46: 1-4 | I46: 1-5 | J46: 授業科目 | P46: 単位数 | Q46: 必須 | R46: 1-4 | S46: 1-5
B47: 法と情報 | F47: 2 | G47: ○ | H47: ○ | I47: ○
B48: 情報と職業 | F48: 2 | H48: ○ | I48: ○
B49: 情報技術論Ⅱ | F49: 2 | H49: ○ | I49: ○
B50: 情報社会と情報倫理 | F50: 2 | H50: ○ | I50: ○
A55: ⑦ 「活用に当たっての様々な留意事項（ELSI、個人情報、データ倫理、ＡＩ社会原則等）を考慮し、情報セキュリティや情報漏洩等、データを守る上での留意事項への理解をする」の内容を含む授業科目
B57: 授業科目 | F57: 単位数 | G57: 必須 | H57: 3-1 | I57: 3-2 | J57: 授業科目 | P57: 単位数 | Q57: 必須 | R57: 3-1 | S57: 3-2
B58: 法と情報 | F58: 2 | G58: ○ | H58: ○ | I58: ○
B59: 情報と職業 | F59: 2 | H59: ○ | I59: ○
B60: 情報技術論Ⅱ | F60: 2 | H60: ○ | I60: ○
B61: 情報社会と情報倫理 | F61: 2 | H61: ○ | I61: ○
A66: ⑧ 「実データ・実課題（学術データ等を含む）を用いた演習など、社会での実例を題材として、「データを読む、説明する、扱う」といった数理・データサイエンス・ＡＩの基本的な活用法に関するもの」の内容を含む授業科目
B68: 授業科目 | E68: 単位数 | F68: 必須 | G68: 2-1 | H68: 2-2 | I68: 2-3 | J68: 授業科目 | O68: 単位数 | P68: 必須 | Q68: 2-1 | R68: 2-2 | S68: 2-3
B69: データ分析 | E69: 2 | F69: ○ | G69: ○ | H69: ○ | I69: ○ | J69: 市場調査論 | O69: 2 | Q69: ○ | R69: ○ | S69: ○
B70: データサイエンス入門Ⅰ | E70: 2 | G70: ○ | H70: ○ | I70: ○ | J70: 教育におけるICT活用 | O70: 2 | Q70: ○ | R70: ○ | S70: ○
...

Sheet 様式１－２　プログラムを構成する授業科目
R1: 様式１－２ | T1: 「学部・学科によって、修了要件は相違する」場合は、本シートを複製の上＜様式１－〇＞と枝番号を付してください
B2: 大学等名 | C2: 岡山商科大学
B3: プログラム名 | C3: データサイエンス・リテラシー教育プログラム
A5: プログラムを構成する授業科目について
A7: ① 対象となる学部・学科名称 | J7: ② 教育プログラムの修了要件 | K7: 学部・学科によって、修了要件は相違する
B9: 法学部
A12: ③ 修了要件
B13: プログラムを構成する「必修科目（下記１、２）」の4単位、「グループA科目群（下記３～５）」から2単位以上、「グループB科目群（下記６～１３）」から8単位以上を取得すること。 必修科目：１．データ分析、２．法と情報 グループA科目群：３．情報と職業、４．情報技術論Ⅱ、５．情報社会と情報倫理 グループB科目群：６．データサイエンス入門Ⅰ、７．データサイエンス入門Ⅱ、８．経済統計論Ⅰ、９．経済統計論Ⅱ、１０．経営統計学Ⅰ、１１．経営統計学Ⅱ、１２．市場調査論、１３．教育におけるICT活用 | V13: 【プルダウンリスト】
V14: 令和４年度以前より、履修することが必須のプログラムとして実施
V15: 令和７年度までに履修必須とする計画
V16: 令和８年度以降に履修必須とする計画、又は未定
B20: 必要最低単位数 | C20: 14 | E20: 単位 | J20: 履修必須の有無 | K20: 令和８年度以降に履修必須とする計画、又は未定
A22: ④ 現在進行中の社会変化（第４次産業革命、Society 5.0、データ駆動型社会等）に深く寄与しているものであり、それが自らの生活と密接に結びついている」の内容を含む授業科目
B24: 授業科目 | F24: 単位数 | G24: 必須 | H24: 1-1 | I24: 1-6 | J24: 授業科目 | P24: 単位数 | Q24: 必須 | R24: 1-1 | S24: 1-6
B25: 法と情報 | F25: 2 | G25: ○ | H25: ○ | I25: ○
B26: 情報と職業 | F26: 2 | H26: ○ | I26: ○
B27: 情報技術論Ⅱ | F27: 2 | H27: ○ | I27: ○
B28: 情報社会と情報倫理 | F28: 2 | H28: ○ | I28: ○
A33: ⑤ 「社会で活用されているデータ」や「データの活用領域」は非常に広範囲であって、日常生活や社会の課題を解決する有用なツールになり得るもの」の内容を含む授業科目
B35: 授業科目 | F35: 単位数 | G35: 必須 | H35: 1-2 | I35: 1-3 | J35: 授業科目 | P35: 単位数 | Q35: 必須 | R35: 1-2 | S35: 1-3
B36: 法と情報 | F36: 2 | G36: ○ | H36: ○ | I36: ○
B37: 情報と職業 | F37: 2 | H37: ○ | I37: ○
B38: 情報技術論Ⅱ | F38: 2 | H38: ○ | I38: ○
B39: 情報社会と情報倫理 | F39: 2 | H39: ○ | I39: ○
A44: ⑥ 「様々なデータ利活用の現場におけるデータ利活用事例が示され、様々な適用領域（流通、製造、金融、サービス、インフラ、公共、ヘルスケア等）の知見と組み合わせることで価値を創出するもの」の内容を含む授業科目
B46: 授業科目 | F46: 単位数 | G46: 必須 | H46: 1-4 | I46: 1-5 | J46: 授業科目 | P46: 単位数 | Q46: 必須 | R46: 1-4 | S46: 1-5
B47: 法と情報 | F47: 2 | G47: ○ | H47: ○ | I47: ○
B48: 情報と職業 | F48: 2 | H48: ○ | I48: ○
B49: 情報技術論Ⅱ | F49: 2 | H49: ○ | I49: ○
B50: 情報社会と情報倫理 | F50: 2 | H50: ○ | I50: ○
A55: ⑦ 「活用に当たっての様々な留意事項（ELSI、個人情報、データ倫理、ＡＩ社会原則等）を考慮し、情報セキュリティや情報漏洩等、データを守る上での留意事項への理解をする」の内容を含む授業科目
B57: 授業科目 | F57: 単位数 | G57: 必須 | H57: 3-1 | I57: 3-2 | J57: 授業科目 | P57: 単位数 | Q57: 必須 | R57: 3-1 | S57: 3-2
B58: 法と情報 | F58: 2 | G58: ○ | H58: ○ | I58: ○
B59: 情報と職業 | F59: 2 | H59: ○ | I59: ○
B60: 情報技術論Ⅱ | F60: 2 | H60: ○ | I60: ○
B61: 情報社会と情報倫理 | F61: 2 | H61: ○ | I61: ○
A66: ⑧ 「実データ・実課題（学術データ等を含む）を用いた演習など、社会での実例を題材として、「データを読む、説明する、扱う」といった数理・データサイエンス・ＡＩの基本的な活用法に関するもの」の内容を含む授業科目
B68: 授業科目 | E68: 単位数 | F68: 必須 | G68: 2-1 | H68: 2-2 | I68: 2-3 | J68: 授業科目 | O68: 単位数 | P68: 必須 | Q68: 2-1 | R68: 2-2 | S68: 2-3
B69: データ分析 | E69: 2 | F69: ○ | G69: ○ | H69: ○ | I69: ○ | J69: 市場調査論 | O69: 2 | Q69: ○ | R69: ○ | S69: ○
B70: データサイエンス入門Ⅰ | E70: 2 | G70: ○ | H70: ○ | I70: ○ | J70: 教育におけるICT活用 | O70: 2 | Q70: ○ | R70: ○ | S70: ○
...

Sheet 様式２ 履修者等数の実績
AQ1: 様式２
AL2: 大学等名 | AM2: ='様式１－1 プログラムを構成する授業科目'!C2 -> 岡山商科大学
A3: プログラムの履修者数等の実績について
A5: ①プログラム開設年度 | C5: 令和3 | E5: 年度
A7: ②履修者・修了者の実績
B9: 学部・学科名称 | C9: 学生数 | D9: 入学 定員 | E9: 収容 定員 | F9: 令和4年度 | L9: 令和3年度 | R9: 令和2年度 | X9: 令和元年度 | AD9: 平成30年度 | AJ9: 平成29年度 | AP9: 履修者数 合計 | AQ9: 履修率
F10: 履修者数 | I10: 修了者数 | L10: 履修者数 | O10: 修了者数 | R10: 履修者数 | U10: 修了者数 | X10: 履修者数 | AA10: 修了者数 | AD10: 履修者数 | AG10: 修了者数 | AJ10: 履修者数 | AM10: 修了者数
F11: 合計 | G11: 男性 | H11: 女性 | I11: 合計 | J11: 男性 | K11: 女性 | L11: 合計 | M11: 男性 | N11: 女性 | O11: 合計 | P11: 男性 | Q11: 女性 | R11: 合計 | S11: 男性 | T11: 女性 | U11: 合計 | V11: 男性 | W11: 女性 | X11: 合計 | Y11: 男性 | Z11: 女性 | AA11: 合計 | AB11: 男性 | AC11: 女性 | AD11: 合計 | AE11: 男性 | AF11: 女性 | AG11: 合計 | AH11: 男性 | AI11: 女性 | AJ11: 合計 | AK11: 男性 | AL11: 女性 | AM11: 合計 | AN11: 男性 | AO11: 女性
B12: 法学部 | C12: 344 | D12: 85 | E12: 320 | F12: =G12+H12 -> 2 | G12: 2 | H12: 0 | I12: =J12+K12 -> 0 | J12: 0 | K12: 0 | L12: =M12+N12 -> 0 | M12: 0 | N12: 0 | O12: =P12+Q12 -> 0 | P12: 0 | Q12: 0 | R12: =S12+T12 -> 0 | U12: =V12+W12 -> 0 | X12: =Y12+Z12 -> 0 | AA12: =AB12+AC12 -> 0 | AD12: =AE12+AF12 -> 0 | AG12: =AH12+AI12 -> 0 | AJ12: =AK12+AL12 -> 0 | AM12: =AN12+AO12 -> 0 | AP12: =F12+L12+R12+X12+AD12+AJ12 -> 2 | AQ12: =AP12/E12 -> 0.00625
B13: 経済学部 | C13: 351 | D13: 80 | E13: 360 | F13: =G13+H13 -> 10 | G13: 5 | H13: 5 | I13: =J13+K13 -> 0 | J13: 0 | K13: 0 | L13: =M13+N13 -> 1 | M13: 1 | N13: 0 | O13: =P13+Q13 -> 0 | P13: 0 | Q13: 0 | R13: =S13+T13 -> 0 | U13: =V13+W13 -> 0 | X13: =Y13+Z13 -> 0 | AA13: =AB13+AC13 -> 0 | AD13: =AE13+AF13 -> 0 | AG13: =AH13+AI13 -> 0 | AJ13: =AK13+AL13 -> 0 | AM13: =AN13+AO13 -> 0 | AP13: =F13+L13+R13+X13+AD13+AJ13 -> 11 | AQ13: =AP13/E13 -> 0.030555556
B14: 経営学部 | C14: 1135 | D14: 250 | E14: 1040 | F14: =G14+H14 -> 10 | G14: 9 | H14: 1 | I14: =J14+K14 -> 2 | J14: 1 | K14: 1 | L14: =M14+N14 -> 2 | M14: 1 | N14: 1 | O14: =P14+Q14 -> 0 | P14: 0 | Q14: 0 | R14: =S14+T14 -> 0 | U14: =V14+W14 -> 0 | X14: =Y14+Z14 -> 0 | AA14: =AB14+AC14 -> 0 | AD14: =AE14+AF14 -> 0 | AG14: =AH14+AI14 -> 0 | AJ14: =AK14+AL14 -> 0 | AM14: =AN14+AO14 -> 0 | AP14: =F14+L14+R14+X14+AD14+AJ14 -> 12 | AQ14: =AP14/E14 -> 0.011538462
F15: =G15+H15 -> 0 | I15: =J15+K15 -> 0 | L15: =M15+N15 -> 0 | O15: =P15+Q15 -> 0 | R15: =S15+T15 -> 0 | U15: =V15+W15 -> 0 | X15: =Y15+Z15 -> 0 | AA15: =AB15+AC15 -> 0 | AD15: =AE15+AF15 -> 0 | AG15: =AH15+AI15 -> 0 | AJ15: =AK15+AL15 -> 0 | AM15: =AN15+AO15 -> 0 | AP15: =F15+L15+R15+X15+AD15+AJ15 -> 0 | AQ15: =AP15/E15 -> #DIV/0!
F16: =G16+H16 -> 0 | I16: =J16+K16 -> 0 | L16: =M16+N16 -> 0 | O16: =P16+Q16 -> 0 | R16: =S16+T16 -> 0 | U16: =V16+W16 -> 0 | X16: =Y16+Z16 -> 0 | AA16: =AB16+AC16 -> 0 | AD16: =AE16+AF16 -> 0 | AG16: =AH16+AI16 -> 0 | AJ16: =AK16+AL16 -> 0 | AM16: =AN16+AO16 -> 0 | AP16: =F16+L16+R16+X16+AD16+AJ16 -> 0 | AQ16: =AP16/E16 -> #DIV/0!
F17: =G17+H17 -> 0 | I17: =J17+K17 -> 0 | L17: =M17+N17 -> 0 | O17: =P17+Q17 -> 0 | R17: =S17+T17 -> 0 | U17: =V17+W17 -> 0 | X17: =Y17+Z17 -> 0 | AA17: =AB17+AC17 -> 0 | AD17: =AE17+AF17 -> 0 | AG17: =AH17+AI17 -> 0 | AJ17: =AK17+AL17 -> 0 | AM17: =AN17+AO17 -> 0 | AP17: =F17+L17+R17+X17+AD17+AJ17 -> 0 | AQ17: =AP17/E17 -> #DIV/0!
F18: =G18+H18 -> 0 | I18: =J18+K18 -> 0 | L18: =M18+N18 -> 0 | O18: =P18+Q18 -> 0 | R18: =S18+T18 -> 0 | U18: =V18+W18 -> 0 | X18: =Y18+Z18 -> 0 | AA18: =AB18+AC18 -> 0 | AD18: =AE18+AF18 -> 0 | AG18: =AH18+AI18 -> 0 | AJ18: =AK18+AL18 -> 0 | AM18: =AN18+AO18 -> 0 | AP18: =F18+L18+R18+X18+AD18+AJ18 -> 0 | AQ18: =AP18/E18 -> #DIV/0!
F19: =G19+H19 -> 0 | I19: =J19+K19 -> 0 | L19: =M19+N19 -> 0 | O19: =P19+Q19 -> 0 | R19: =S19+T19 -> 0 | U19: =V19+W19 -> 0 | X19: =Y19+Z19 -> 0 | AA19: =AB19+AC19 -> 0 | AD19: =AE19+AF19 -> 0 | AG19: =AH19+AI19 -> 0 | AJ19: =AK19+AL19 -> 0 | AM19: =AN19+AO19 -> 0 | AP19: =F19+L19+R19+X19+AD19+AJ19 -> 0 | AQ19: =AP19/E19 -> #DIV/0!
F20: =G20+H20 -> 0 | I20: =J20+K20 -> 0 | L20: =M20+N20 -> 0 | O20: =P20+Q20 -> 0 | R20: =S20+T20 -> 0 | U20: =V20+W20 -> 0 | X20: =Y20+Z20 -> 0 | AA20: =AB20+AC20 -> 0 | AD20: =AE20+AF20 -> 0 | AG20: =AH20+AI20 -> 0 | AJ20: =AK20+AL20 -> 0 | AM20: =AN20+AO20 -> 0 | AP20: =F20+L20+R20+X20+AD20+AJ20 -> 0 | AQ20: =AP20/E20 -> #DIV/0!
F21: =G21+H21 -> 0 | I21: =J21+K21 -> 0 | L21: =M21+N21 -> 0 | O21: =P21+Q21 -> 0 | R21: =S21+T21 -> 0 | U21: =V21+W21 -> 0 | X21: =Y21+Z21 -> 0 | AA21: =AB21+AC21 -> 0 | AD21: =AE21+AF21 -> 0 | AG21: =AH21+AI21 -> 0 | AJ21: =AK21+AL21 -> 0 | AM21: =AN21+AO21 -> 0 | AP21: =F21+L21+R21+X21+AD21+AJ21 -> 0 | AQ21: =AP21/E21 -> #DIV/0!
F22: =G22+H22 -> 0 | I22: =J22+K22 -> 0 | L22: =M22+N22 -> 0 | O22: =P22+Q22 -> 0 | R22: =S22+T22 -> 0 | U22: =V22+W22 -> 0 | X22: =Y22+Z22 -> 0 | AA22: =AB22+AC22 -> 0 | AD22: =AE22+AF22 -> 0 | AG22: =AH22+AI22 -> 0 | AJ22: =AK22+AL22 -> 0 | AM22: =AN22+AO22 -> 0 | AP22: =F22+L22+R22+X22+AD22+AJ22 -> 0 | AQ22: =AP22/E22 -> #DIV/0!
F23: =G23+H23 -> 0 | I23: =J23+K23 -> 0 | L23: =M23+N23 -> 0 | O23: =P23+Q23 -> 0 | R23: =S23+T23 -> 0 | U23: =V23+W23 -> 0 | X23: =Y23+Z23 -> 0 | AA23: =AB23+AC23 -> 0 | AD23: =AE23+AF23 -> 0 | AG23: =AH23+AI23 -> 0 | AJ23: =AK23+AL23 -> 0 | AM23: =AN23+AO23 -> 0 | AP23: =F23+L23+R23+X23+AD23+AJ23 -> 0 | AQ23: =AP23/E23 -> #DIV/0!
F24: =G24+H24 -> 0 | I24: =J24+K24 -> 0 | L24: =M24+N24 -> 0 | O24: =P24+Q24 -> 0 | R24: =S24+T24 -> 0 | U24: =V24+W24 -> 0 | X24: =Y24+Z24 -> 0 | AA24: =AB24+AC24 -> 0 | AD24: =AE24+AF24 -> 0 | AG24: =AH24+AI24 -> 0 | AJ24: =AK24+AL24 -> 0 | AM24: =AN24+AO24 -> 0 | AP24: =F24+L24+R24+X24+AD24+AJ24 -> 0 | AQ24: =AP24/E24 -> #DIV/0!
F25: =G25+H25 -> 0 | I25: =J25+K25 -> 0 | L25: =M25+N25 -> 0 | O25: =P25+Q25 -> 0 | R25: =S25+T25 -> 0 | U25: =V25+W25 -> 0 | X25: =Y25+Z25 -> 0 | AA25: =AB25+AC25 -> 0 | AD25: =AE25+AF25 -> 0 | AG25: =AH25+AI25 -> 0 | AJ25: =AK25+AL25 -> 0 | AM25: =AN25+AO25 -> 0 | AP25: =F25+L25+R25+X25+AD25+AJ25 -> 0 | AQ25: =AP25/E25 -> #DIV/0!
F26: =G26+H26 -> 0 | I26: =J26+K26 -> 0 | L26: =M26+N26 -> 0 | O26: =P26+Q26 -> 0 | R26: =S26+T26 -> 0 | U26: =V26+W26 -> 0 | X26: =Y26+Z26 -> 0 | AA26: =AB26+AC26 -> 0 | AD26: =AE26+AF26 -> 0 | AG26: =AH26+AI26 -> 0 | AJ26: =AK26+AL26 -> 0 | AM26: =AN26+AO26 -> 0 | AP26: =F26+L26+R26+X26+AD26+AJ26 -> 0 | AQ26: =AP26/E26 -> #DIV/0!
... F31: =G31+H31 -> 0 | I31: =J31+K31 -> 0 | L31: =M31+N31 -> 0 | O31: =P31+Q31 -> 0 | R31: =S31+T31 -> 0 | U31: =V31+W31 -> 0 | X31: =Y31+Z31 -> 0 | AA31: =AB31+AC31 -> 0 | AD31: =AE31+AF31 -> 0 | AG31: =AH31+AI31 -> 0 | AJ31: =AK31+AL31 -> 0 | AM31: =AN31+AO31 -> 0 | AP31: =F31+L31+R31+X31+AD31+AJ31 -> 0 | AQ31: =AP31/E31 -> #DIV/0!
B32: 合 計 | C32: =SUM(C12:C31) -> 1830 | D32: =SUM(D12:D31) -> 415 | E32: =SUM(E12:E31) -> 1720 | F32: =SUM(F12:F31) -> 22 | G32: =SUM(G12:G31) -> 16 | H32: =SUM(H12:H31) -> 6 | I32: =SUM(I12:I31) -> 2 | J32: =SUM(J12:J31) -> 1 | ... AP32: =SUM(AP12:AP31) -> 25 | AQ32: =AP32/E32 -> 0.014534884

Sheet 様式３ 教育の質・履修者数を向上させるための体制・計画
I1: 様式３
G2: 大学等名 | H2: ='様式１－1 プログラムを構成する授業科目'!C2 -> 岡山商科大学
A4: 教育の質・履修者数を向上させるための体制・計画について
A6: ① | B6: 全学の教員数 | C6: (常勤） | E6: 81 | F6: 人 | G6: （非常勤） | H6: 18 | I6: 人
A8: ② | B8: プログラムの授業を教えている教員数 | H8: 9 | I8: 人
A10: ③ | B10: プログラムの運営責任者
B11: （責任者名） | C11: 田中 康秀 | G11: （役職名） | H11: 副学長
A13: ④ | B13: プログラムを改善・進化させるための体制（委員会・組織等）
B14: 全学共通プログラム修了判定委員会
B16: （責任者名） | C16: 田中 康秀 | G16: （役職名） | H16: 副学長
A18: ⑤ | B18: プログラムを改善・進化させるための体制を定める規則名称
B19: 岡山商科大学全学共通プログラム修了判定委員会内規
A21: ⑥ | B21: 体制の目的
B22: 「数理・データサイエンス・AI」を活用できる基礎的な能力（リテラシー）の育成をめざし、この分野を活かせる人材を養成する目的で設置した「データサイエンス・リテラシー（DSL)教育プログラム」は、本学における全学共通プログラムの1つであり、そのプログラムの運営全般に関しては全学共通プログラム修了判定委員会が所掌している。それ故に、本プログラムの修了者判定、プログラムの評価や改善の取り組みなどはこの委員会において行っている。また、本委員会でなされた評価や改善の内容は、学長を委員長とする自己点検・評価委員会に諮られ、全学的に周知徹底を図っている。 全学共通プログラム修了判定委員会では、次の各号に定める事項の審議を目的とする。 (1) 全学共通プログラムの登録学生の承認 (2) 全学共通プログラムの修了判定及び修了証書授与候補者の選考 (3) 全学共通プログラムの点検・評価及び改正等 (4) その他委員長が必要と認める事項
A34: ⑦ | B34: 具体的な構成員
B35: 経済学部 教授・副学長 田中康秀 （委員長） 経営学部 教授・教務部長 蒲和重 法学部 教授 伊藤治彦 経済学部 教授 佐井至道 経営学部 教授 川本和則 経営学部 教授 三好宏
A48: ⑧ | B48: 履修者数・履修率の向上に向けた計画 ※様式１の「履修必須の有無」で「計画がある」としている場合は詳細について記載すること
B49: 令和４年度実績 | C49: ='様式２ 履修者等数の実績'!AQ32 -> 0.014534884 | E49: 令和５年度予定 | F49: 0.06 | H49: 令和６年度予定 | I49: 0.1
B50: 令和７年度予定 | C50: 0.14 | E50: 令和８年度予定 | F50: 0.18 | H50: 収容定員（名） | I50: ='様式２ 履修者等数の実績'!E32 -> 1720
B51: 具体的な計画
B52: 「データサイエンス・リテラシー（DSL)教育プログラム」については、その設立当初から少なくとも毎年度4回全学の学生向けに説明会を開催してプログラムの趣旨を伝えている。また、2022(令和4)年度より、プログラムの必修科目の1つである「データ分析」については全学生が履修修得しなければならない必修科目(一般教育科目）として設定している。 プログラムを構成する科目の中には、本プログラムを立ち上げて以降、全学生の半数程度が履修登録を行っているものもある（例えば、「情報と職業」や「情報社会と情報倫理」）。 しかしながら、修了証書を授与できる本プログラム（DSL教育プログラム）への参加者数はまだ少数であり、本プログラムの目的を全学的に実現するために、2023(令和5)年度以降、プログラム説明会に加えて各授業科目を通じて参加者を募り、本プログラムの履修者を増やす方策を強化する計画である。また、経済学部では一部のコース選択者に対して本プログラムへの参加を強く推奨する予定で、新たな履修者として毎年度80名程度が見込まれることから、2026(令和8)年度時点の履修者は収容定員の18%に達すると予想できる。
A65: ⑨ | B65: 学部・学科に関係なく希望する学生全員が受講可能となるような必要な体制・取組等
B66: 「データサイエンス・リテラシー（DSL)教育プログラム」は当初から全学共通プログラムの1つとして設置したものであり、それ故に、学部・学科に関係なく希望する学生全員が受講できる体制となっている。本プログラムを構成する科目については、プログラム立ち上げ前には一部の学部の学生しか履修できないものもあったが、ほとんどの科目については全学部の学生が受講できるように履修対象を変更した。今後もその方針で取り組む予定である。
A79: ⑩ | B79: できる限り多くの学生が履修できるような具体的な周知方法・取組
B80: 既に記述したように、「データサイエンス・リテラシー（DSL)教育プログラム」については、年間を通じて4回、全学の学生向けに説明会を開催してプログラムの趣旨を伝えている。 また、新入生オリエンテーションを通じて新入生に周知させるとともに、プログラムを構成する諸科目の授業内や、本学ホームページなどを通じて学生が本プログラムの情報を受け取りやすい環境を整えている。
A93: ⑪ | B93: できる限り多くの学生が履修・修得できるようなサポート体制
B94: 本プログラムの運営を担当する「全学共通プログラム修了判定委員会」はその下部組織として運営部会を置いており、本学の4学科から選出された各1名の運営委員が配置されており、また当部会には各学科の教務関係を所掌する教学委員も加わっており、本プログラムに対する学生からの履修相談など全般的な相談に対応する体制を整えている。 また、教養演習や基礎演習、研究演習でのゼミナール担当教員も、プログラムへの参加に関わる相談や履修指導などを行っている。
A107: ⑫ | B107: 授業時間内外で学習指導、質問を受け付ける具体的な仕組み
B108: 本プログラムの履修に関する学習指導や質問などは以下のような方法で可能としており、学生の履修相談等にきめ細かい対応ができる体制としている。 ・各授業科目の担当教員 ・全学共通プログラム修了判定委員会運営部会の運営委員 ・教養演習や基礎演習、研究演習のゼミナール担当教員 これらの相談は対面のみならず、WebClass(LMS)でも可能となるように整備している。

Sheet 様式４　自己点検・評価
I1: 様式４
H2: 大学等名 | I2: ='様式１－1 プログラムを構成する授業科目'!C2 -> 岡山商科大学
A3: 自己点検・評価について
A5: ① | B5: プログラムの自己点検・評価を行う体制（委員会・組織等）
B6: 自己点検・評価委員会、全学共通プログラム修了判定委員会
D8: （責任者名） | E8: 井尻 昭夫、 田中 康秀 | G8: （役職名） | H8: 学長、 副学長
A10: ② | B10: 自己点検・評価体制における意見等
B11: 自己点検・評価の視点 | E11: 自己点検・評価体制における意見・結果・改善に向けた取組等
B12: 学内からの視点
C13: プログラムの履修・修得状況 | E13: 全学部学生向けに設けている「データサイエンス・リテラシー（DSL)教育プログラム」は2021年度後期からスタートしたが、その履修カリキュラムは、必修科目及び選択必修科目から成り、後者はさらにグループA科目群とグループB科目群から構成しており、それらの科目における履修者等のデータを毎年度点検・評価しながら、必要に応じて科目の改善を行っている。
C14: 学修成果 | E14: 本学では、すべての開講科目について履修者全員に対して授業評価アンケートを行っている。質問項目は「知識・技能の習得方法について順をおって教えてくれた」などの選択形式20項目と、「良い点」、「悪い点」などの自由回答形式3項目からなる。本プログラムの特徴を測るために、通常の集計・分析とは別に、回答内容は本プログラムとそれ以外の科目について比較可能な形式でも集計される。また一部の科目では、独自にもアンケート調査を行っている。それらの結果は本プログラムのワーキンググループや、全学共通プログラム修了判定委員会等で報告され、本プログラムの評価・改善に活用している。
C15: 学生アンケート等を通じた学生の内容の理解度 | E15: 本学では、すべての開講科目について履修者全員に対して授業評価アンケートを行っている。多くの項目については、1.全く違う～5.全くその通りである、の5段階の回答形式となっている。2022年度の本プログラムの科目の結果では、「勉強に集中できたか」の平均が4.63、「教員が予習・復習を促したか」の平均が4.50で全科目の平均を上回っており、学生が十分努力したことが読み取れる。一方で「難易度は適切だったか」の平均が4.09、「学生が理解しているかどうかに注意が払われていたか」の平均が4.27で、高い値ではあるものの全科目の平均を下回っていた。特にパソコンを使用する科目については理解度を継続的に測る必要があると考えられる。
C16: 学生アンケート等を通じた後輩等他の学生への推奨度 | E16: 本プログラムの科目について、授業評価アンケートの「総合的に判断してこの授業に満足しているか」という設問の回答の平均は4.28となっており、満足している学生が多数を占めていることが分かる。また自由回答の集計では、良い点を挙げたものが176件、悪い点を挙げたものが71件で、肯定的な評価が多いことが分かる。さらに良い点の回答で使われているの単語を抽出したところ「分かる」「説明」「丁寧」などが上位にランキングされていた。これらの結果については本プログラムのホームページに掲載するとともに、年4回開催する説明会でも学生に伝えるなどして活用している。
C17: 全学的な履修者数、履修率向上に向けた計画の達成・進捗状況 | E17: 本プログラムにおける必須科目の1つである「データ分析」については、2022年度からプログラムへの参加の有無に関わらず、本学学生全員が受講するように改め、また、卒業要件の1つとすることによって、全学生がデータサイエンスの入門編を修得した上で卒業するように制度設計を行い、使用する教科書についても授業担当者間で内容を吟味して執筆している。 また、グループAの科目群における「情報と職業」、「情報社会と情報倫理」も2022年度は前年度の履修者数に比較してほぼ倍増し、同一学年の学生数の約半数が履修している。 今後は、DSL教育プログラム自体への参加者数を増加させることによって、各科目群の履修者数、履修率向上を図る。
B18: 学外からの視点
C19: 教育プログラム修了者の進路、活躍状況、企業等の評価 | E19: 本プログラムを立ち上げて1年半しか経過しておらず、2022年度末でのプログラム修了者は2名となっている。彼らはいずれも留学生であり、帰国して就職活動を行っている。 従って、受け入れ企業等からの評価については現在情報はないが、今後修了者が増えることによって、彼らの活躍状況や受け入れ企業等からの評価に関わるデータを収集できると考えている。もっとも、次の項目に示すように、現時点でも本プログラムに対して外部から期待されている。
C20: 産業界からの視点を含めた教育プログラム内容・手法等への意見 | E20: 本学では卒業生の就職先企業を対象としたアンケート調査を毎年度実施している。2022年度の158社から回答を得たアンケート調査では、「データ活用やITにかかる能力・スキルの育成をさらに充実してほしい」と回答した企業は20.9%で、前回調査の30.4%から減少した。データサイエンスの必要性は高まっていると推測されるため、本学のデータサイエンス教育は以前より充実した、と評価されていると考えられる。 また本学附属の研究所の後援会役員会を毎年度開催して産業界の方から意見をいただいている。2023年2月に開催された役員会では、本学のデータサイエンス教育に対して肯定的な評価をいただくとともに、一層の充実を要望する意見をいただいた。
B21: 数理・データサイエンス・ＡＩを「学ぶ楽しさ」「学ぶことの意義」を理解させること | E21: 本プログラムの各授業科目では、社会におけるデータやAIの実用例を挙げてデータ分析に興味を持たせるとともに、解析の数理のみならず、データを視覚化することや、データが社会科学的にどのように分析・解析できるかについて実践的に学修させることで、「学ぶ楽しさ」を理解させる内容としている。 さらに、数理・データサイエンス・AIを扱う場合の法的問題や倫理的問題、今後の社会像を踏まえた職業での役割などを理解させることで、「学ぶことの意義」を伝えるような内容としている。 本プログラムの授業科目については、担当教員同士がお互い意見交換できる場を設けることや、授業評価アンケート等を活用して、その内容の改善に役立てている。
B22: 内容・水準を維持・向上しつつ、より「分かりやすい」授業とすること | E22: 各授業科目では、課題を課しそのフィードバックコメントを行うなど双方向型の授業とすること、また、授業内容についても数量的表現だけではなく図を用いたり、様々な実例を利用したりするなど、「分かりやすい」授業となるように心がけている。 さらに、各授業科目の授業評価アンケート等で示される個別意見やコメントを毎学期IR実施委員会で精査して全学教職員会議で公表するとともに、学外の各種団体に委員をお願いしている教育研究評議会（本学の外部評価委員会）や本学附属の社会総合研究所後援会役員会などでの意見を踏まえて、学生にとって「分かりやすい」授業となるように授業の内容・実施方法等の見直しを検討している。
