Workbook

Sheet 様式１−１　プログラムを構成する授業科目
R1: 様式１－１ | T1: 「学部・学科によって、修了要件は相違する」場合は、本シートを複製の上＜様式１－〇＞と枝番号を付してください
B2: 大学等名 | C2: 岩手県立大学盛岡短期大学部
B3: プログラム名 | C3: 文理融合データサイエンス教育プログラム
A5: プログラムを構成する授業科目について
A7: ① 対象となる学部・学科名称 | J7: ② 教育プログラムの修了要件 | K7: 学部・学科によって、修了要件は相違する
B9: 生活科学科
A12: ③ 修了要件
B13: 生活デザイン専攻においては、本プログラムを構成する「情報科学概論」（２単位）と「情報処理演習（１単位）」を取得すること。 食物栄養学専攻においては、本プログラムを構成する「情報科学概論」（２単位）と「栄養情報処理実習（１単位）」を取得すること。 | V13: 【プルダウンリスト】
V14: 令和４年度以前より、履修することが必須のプログラムとして実施
V15: 令和７年度までに履修必須とする計画
V16: 令和８年度以降に履修必須とする計画、又は未定
B20: 必要最低単位数 | C20: 3 | E20: 単位 | J20: 履修必須の有無 | K20: 令和８年度以降に履修必須とする計画、又は未定
A22: ④ 現在進行中の社会変化（第４次産業革命、Society 5.0、データ駆動型社会等）に深く寄与しているものであり、それが自らの生活と密接に結びついている」の内容を含む授業科目
B24: 授業科目 | F24: 単位数 | G24: 必須 | H24: 1-1 | I24: 1-6 | J24: 授業科目 | P24: 単位数 | Q24: 必須 | R24: 1-1 | S24: 1-6
B25: 情報科学概論 | F25: 2 | G25: ○ | H25: ○ | I25: ○
B26: 栄養情報処理実習 | F26: 1 | H26: ○ | I26: ○
A33: ⑤ 「社会で活用されているデータ」や「データの活用領域」は非常に広範囲であって、日常生活や社会の課題を解決する有用なツールになり得るもの」の内容を含む授業科目
B35: 授業科目 | F35: 単位数 | G35: 必須 | H35: 1-2 | I35: 1-3 | J35: 授業科目 | P35: 単位数 | Q35: 必須 | R35: 1-2 | S35: 1-3
B36: 情報科学概論 | F36: 2 | G36: ○ | H36: ○ | I36: ○
A44: ⑥ 「様々なデータ利活用の現場におけるデータ利活用事例が示され、様々な適用領域（流通、製造、金融、サービス、インフラ、公共、ヘルスケア等）の知見と組み合わせることで価値を創出するもの」の内容を含む授業科目
B46: 授業科目 | F46: 単位数 | G46: 必須 | H46: 1-4 | I46: 1-5 | J46: 授業科目 | P46: 単位数 | Q46: 必須 | R46: 1-4 | S46: 1-5
B47: 情報科学概論 | F47: 2 | G47: ○ | H47: ○ | I47: ○
B48: 情報処理演習 | F48: 1 | H48: ○ | I48: ○
A55: ⑦ 「活用に当たっての様々な留意事項（ELSI、個人情報、データ倫理、ＡＩ社会原則等）を考慮し、情報セキュリティや情報漏洩等、データを守る上での留意事項への理解をする」の内容を含む授業科目
B57: 授業科目 | F57: 単位数 | G57: 必須 | H57: 3-1 | I57: 3-2 | J57: 授業科目 | P57: 単位数 | Q57: 必須 | R57: 3-1 | S57: 3-2
B58: 情報科学概論 | F58: 2 | G58: ○ | H58: ○ | I58: ○
B59: 栄養情報処理実習 | F59: 1 | H59: ○ | I59: ○
A66: ⑧ 「実データ・実課題（学術データ等を含む）を用いた演習など、社会での実例を題材として、「データを読む、説明する、扱う」といった数理・データサイエンス・ＡＩの基本的な活用法に関するもの」の内容を含む授業科目
B68: 授業科目 | E68: 単位数 | F68: 必須 | G68: 2-1 | H68: 2-2 | I68: 2-3 | J68: 授業科目 | O68: 単位数 | P68: 必須 | Q68: 2-1 | R68: 2-2 | S68: 2-3
B69: 情報科学概論 | E69: 2 | F69: ○ | G69: ○ | H69: ○ | I69: ○
B70: 情報処理演習 | E70: 1 | G70: ○ | H70: ○ | I70: ○
B71: 栄養情報処理実習 | E71: 1 | G71: ○ | H71: ○ | I71: ○
A77: ⑨ 選択「４．オプション」の内容を含む授業科目
B78: 授業科目 | F78: 選択項目 | J78: 授業科目 | P78: 選択項目
A87: ⑩ プログラムを構成する授業の内容
B88: 授業に含まれている内容・要素 | D88: 講義内容
B89: （１）現在進行中の社会変化（第４次産業革命、Society 5.0、データ駆動型社会等）に深く寄与しているものであり、それが自らの生活と密接に結びついている | C89: 1-1 | D89: ・第4次産業革命、Society 5.0、データ駆動型社会 「情報科学概論」（第１回、第２回） ・ビッグデータ、IoT、AI、ロボット 「栄養情報処理実習」（第１回）
C90: 1-6 | D90: ・AI等を活用した新しいビジネスモデル(シェアリングエコノミー、商品のレコメンデーションなど) 「情報科学概論」（第１回、第２回） ・AI最新技術の活用例(深層生成モデル、敵対的生成ネットワーク、強化学習、転移学習など) 「栄養情報処理実習」（第１回）
B91: （２）「社会で活用されているデータ」や「データの活用領域」は非常に広範囲であって、日常生活や社会の課題を解決する有用なツールになり得るもの | C91: 1-2 | D91: ・調査データ、実験データ、人の行動ログデータ、機械の稼働ログデータなど 「情報科学概論」（第３回～第５回） ・1次データ、2次データ、データのメタ化 「情報科学概論」（第３回～第５回）
C92: 1-3 | D92: ・データ・AI活用領域の広がり(生産、消費、文化活動など) 「情報科学概論」（第３回～第５回）
...

Sheet 様式１−２　プログラムを構成する授業科目
R1: 様式１－２ | T1: 「学部・学科によって、修了要件は相違する」場合は、本シートを複製の上＜様式１－〇＞と枝番号を付してください
B2: 大学等名 | C2: 岩手県立大学盛岡短期大学部
B3: プログラム名 | C3: 文理融合データサイエンス教育プログラム
A5: プログラムを構成する授業科目について
A7: ① 対象となる学部・学科名称 | J7: ② 教育プログラムの修了要件 | K7: 学部・学科によって、修了要件は相違する
B9: 国際文化学科
A12: ③ 修了要件
B13: 本プログラムを構成する「情報処理入門」（２単位）に加えて、「情報処理演習Ａ（２単位）」と「情報処理演習Ｂ（２単位）」から１科目以上取得すること。 | V13: 【プルダウンリスト】
V14: 令和４年度以前より、履修することが必須のプログラムとして実施
V15: 令和７年度までに履修必須とする計画
V16: 令和８年度以降に履修必須とする計画、又は未定
B20: 必要最低単位数 | C20: 4 | E20: 単位 | J20: 履修必須の有無 | K20: 令和８年度以降に履修必須とする計画、又は未定
A22: ④ 現在進行中の社会変化（第４次産業革命、Society 5.0、データ駆動型社会等）に深く寄与しているものであり、それが自らの生活と密接に結びついている」の内容を含む授業科目
B24: 授業科目 | F24: 単位数 | G24: 必須 | H24: 1-1 | I24: 1-6 | J24: 授業科目 | P24: 単位数 | Q24: 必須 | R24: 1-1 | S24: 1-6
B25: 情報処理入門 | F25: 2 | G25: ○ | H25: ○ | I25: ○
A33: ⑤ 「社会で活用されているデータ」や「データの活用領域」は非常に広範囲であって、日常生活や社会の課題を解決する有用なツールになり得るもの」の内容を含む授業科目
B35: 授業科目 | F35: 単位数 | G35: 必須 | H35: 1-2 | I35: 1-3 | J35: 授業科目 | P35: 単位数 | Q35: 必須 | R35: 1-2 | S35: 1-3
B36: 情報処理入門 | F36: 2 | G36: ○ | H36: ○ | I36: ○
A44: ⑥ 「様々なデータ利活用の現場におけるデータ利活用事例が示され、様々な適用領域（流通、製造、金融、サービス、インフラ、公共、ヘルスケア等）の知見と組み合わせることで価値を創出するもの」の内容を含む授業科目
B46: 授業科目 | F46: 単位数 | G46: 必須 | H46: 1-4 | I46: 1-5 | J46: 授業科目 | P46: 単位数 | Q46: 必須 | R46: 1-4 | S46: 1-5
B47: 情報処理入門 | F47: 2 | G47: ○ | H47: ○ | I47: ○
A55: ⑦ 「活用に当たっての様々な留意事項（ELSI、個人情報、データ倫理、ＡＩ社会原則等）を考慮し、情報セキュリティや情報漏洩等、データを守る上での留意事項への理解をする」の内容を含む授業科目
B57: 授業科目 | F57: 単位数 | G57: 必須 | H57: 3-1 | I57: 3-2 | J57: 授業科目 | P57: 単位数 | Q57: 必須 | R57: 3-1 | S57: 3-2
B58: 情報処理入門 | F58: 2 | G58: ○ | H58: ○ | I58: ○
B59: 情報処理演習Ｂ | F59: 2 | H59: ○ | I59: ○
A66: ⑧ 「実データ・実課題（学術データ等を含む）を用いた演習など、社会での実例を題材として、「データを読む、説明する、扱う」といった数理・データサイエンス・ＡＩの基本的な活用法に関するもの」の内容を含む授業科目
B68: 授業科目 | E68: 単位数 | F68: 必須 | G68: 2-1 | H68: 2-2 | I68: 2-3 | J68: 授業科目 | O68: 単位数 | P68: 必須 | Q68: 2-1 | R68: 2-2 | S68: 2-3
B69: 情報処理入門 | E69: 2 | F69: ○ | G69: ○ | H69: ○ | I69: ○
B70: 情報処理演習Ａ | E70: 2 | G70: ○ | H70: ○ | I70: ○
B71: 情報処理演習Ｂ | E71: 2 | G71: ○ | H71: ○ | I71: ○
A77: ⑨ 選択「４．オプション」の内容を含む授業科目
B78: 授業科目 | F78: 選択項目 | J78: 授業科目 | P78: 選択項目
A87: ⑩ プログラムを構成する授業の内容
B88: 授業に含まれている内容・要素 | D88: 講義内容
B89: （１）現在進行中の社会変化（第４次産業革命、Society 5.0、データ駆動型社会等）に深く寄与しているものであり、それが自らの生活と密接に結びついている | C89: 1-1 | D89: ・ビッグデータ、IoT、AI、ロボット 「情報処理入門」（第１回） ・データ量の増加、計算機の処理性能の向上、AIの非連続的進化 「情報処理入門」（第１回） ・第4次産業革命、Society 5.0、データ駆動型社会 「情報処理入門」（第１回）
C90: 1-6 | D90: ・AI等を活用した新しいビジネスモデル(シェアリングエコノミー、商品のレコメンデーションなど) 「情報処理入門」（第１回）
B91: （２）「社会で活用されているデータ」や「データの活用領域」は非常に広範囲であって、日常生活や社会の課題を解決する有用なツールになり得るもの | C91: 1-2 | D91: ・調査データ、実験データ、人の行動ログデータ、機械の稼働ログデータなど 「情報処理入門」（第４回）
C92: 1-3 | D92: ・データ・AI活用領域の広がり(生産、消費、文化活動など) 「情報処理入門」（第４回） ・研究開発、調達、製造、物流、販売、マーケティング、サービスなど 「情報処理入門」（第４回）
B93: （３）様々なデータ利活用の現場におけるデータ利活用事例が示され、様々な適用領域（流通、製造、金融、サービス、インフラ、公共、ヘルスケア等）の知見と組み合わせることで価値を創出するもの | C93: 1-4 | D93: ・データ解析:予測、グルーピング、パターン発見、最適化、シミュレーション・データ同化など 「情報処理入門」（第13回） ・データ可視化:複合グラフ、2軸グラフ、多次元の可視化、関係性の可視化、地図上の可視化、挙動・軌跡の可視化、リアルタイム可視化など 「情報処理入門」（第13回） ・非構造化データ処理:言語処理、画像/動画処理、音声/音楽処理など 「情報処理入門」（第13回） ・特化型AIと汎用AI、今のAIで出来ることと出来ないこと、AIとビッグデータ 「情報処理入門」（第13回）
C94: 1-5 | D94: ・流通、製造、金融、サービス、インフラ、公共、ヘルスケア等におけるデータ・AI利活用事例紹介 「情報処理入門」（第13回）
...

Sheet 様式２ 履修者等数の実績
AQ1: 様式２
AL2: 大学等名 | AM2: ='様式１−１ プログラムを構成する授業科目'!C2 -> 岩手県立大学盛岡短期大学部
A3: プログラムの履修者数等の実績について
A5: ①プログラム開設年度 | C5: 令和４ | E5: 年度
A7: ②履修者・修了者の実績
B9: 学部・学科名称 | C9: 学生数 | D9: 入学 定員 | E9: 収容 定員 | F9: 令和4年度 | L9: 令和3年度 | R9: 令和2年度 | X9: 令和元年度 | AD9: 平成30年度 | AJ9: 平成29年度 | AP9: 履修者数 合計 | AQ9: 履修率
F10: 履修者数 | I10: 修了者数 | L10: 履修者数 | O10: 修了者数 | R10: 履修者数 | U10: 修了者数 | X10: 履修者数 | AA10: 修了者数 | AD10: 履修者数 | AG10: 修了者数 | AJ10: 履修者数 | AM10: 修了者数
F11: 合計 | G11: 男性 | H11: 女性 | I11: 合計 | J11: 男性 | K11: 女性 | L11: 合計 | M11: 男性 | N11: 女性 | O11: 合計 | P11: 男性 | Q11: 女性 | R11: 合計 | S11: 男性 | T11: 女性 | U11: 合計 | V11: 男性 | W11: 女性 | X11: 合計 | Y11: 男性 | Z11: 女性 | AA11: 合計 | AB11: 男性 | AC11: 女性 | AD11: 合計 | AE11: 男性 | AF11: 女性 | AG11: 合計 | AH11: 男性 | AI11: 女性 | AJ11: 合計 | AK11: 男性 | AL11: 女性 | AM11: 合計 | AN11: 男性 | AO11: 女性
B12: 生活科学科 | C12: 108 | D12: 50 | E12: 100 | F12: 53 | I12: 26 | L12: =M12+N12 -> 0 | O12: =P12+Q12 -> 0 | R12: =S12+T12 -> 0 | U12: =V12+W12 -> 0 | X12: =Y12+Z12 -> 0 | AA12: =AB12+AC12 -> 0 | AD12: =AE12+AF12 -> 0 | AG12: =AH12+AI12 -> 0 | AJ12: =AK12+AL12 -> 0 | AM12: =AN12+AO12 -> 0 | AP12: =F12+L12+R12+X12+AD12+AJ12 -> 53 | AQ12: =AP12/E12 -> 0.53
B13: 国際文化学科 | C13: 122 | D13: 50 | E13: 100 | F13: 37 | I13: 33 | L13: =M13+N13 -> 0 | O13: =P13+Q13 -> 0 | R13: =S13+T13 -> 0 | U13: =V13+W13 -> 0 | X13: =Y13+Z13 -> 0 | AA13: =AB13+AC13 -> 0 | AD13: =AE13+AF13 -> 0 | AG13: =AH13+AI13 -> 0 | AJ13: =AK13+AL13 -> 0 | AM13: =AN13+AO13 -> 0 | AP13: =F13+L13+R13+X13+AD13+AJ13 -> 37 | AQ13: =AP13/E13 -> 0.37
F14: =G14+H14 -> 0 | I14: =J14+K14 -> 0 | L14: =M14+N14 -> 0 | O14: =P14+Q14 -> 0 | R14: =S14+T14 -> 0 | U14: =V14+W14 -> 0 | X14: =Y14+Z14 -> 0 | AA14: =AB14+AC14 -> 0 | AD14: =AE14+AF14 -> 0 | AG14: =AH14+AI14 -> 0 | AJ14: =AK14+AL14 -> 0 | AM14: =AN14+AO14 -> 0 | AP14: =F14+L14+R14+X14+AD14+AJ14 -> 0 | AQ14: =AP14/E14 -> #DIV/0!
F15: =G15+H15 -> 0 | I15: =J15+K15 -> 0 | L15: =M15+N15 -> 0 | O15: =P15+Q15 -> 0 | R15: =S15+T15 -> 0 | U15: =V15+W15 -> 0 | X15: =Y15+Z15 -> 0 | AA15: =AB15+AC15 -> 0 | AD15: =AE15+AF15 -> 0 | AG15: =AH15+AI15 -> 0 | AJ15: =AK15+AL15 -> 0 | AM15: =AN15+AO15 -> 0 | AP15: =F15+L15+R15+X15+AD15+AJ15 -> 0 | AQ15: =AP15/E15 -> #DIV/0!
F16: =G16+H16 -> 0 | I16: =J16+K16 -> 0 | L16: =M16+N16 -> 0 | O16: =P16+Q16 -> 0 | R16: =S16+T16 -> 0 | U16: =V16+W16 -> 0 | X16: =Y16+Z16 -> 0 | AA16: =AB16+AC16 -> 0 | AD16: =AE16+AF16 -> 0 | AG16: =AH16+AI16 -> 0 | AJ16: =AK16+AL16 -> 0 | AM16: =AN16+AO16 -> 0 | AP16: =F16+L16+R16+X16+AD16+AJ16 -> 0 | AQ16: =AP16/E16 -> #DIV/0!
F17: =G17+H17 -> 0 | I17: =J17+K17 -> 0 | L17: =M17+N17 -> 0 | O17: =P17+Q17 -> 0 | R17: =S17+T17 -> 0 | U17: =V17+W17 -> 0 | X17: =Y17+Z17 -> 0 | AA17: =AB17+AC17 -> 0 | AD17: =AE17+AF17 -> 0 | AG17: =AH17+AI17 -> 0 | AJ17: =AK17+AL17 -> 0 | AM17: =AN17+AO17 -> 0 | AP17: =F17+L17+R17+X17+AD17+AJ17 -> 0 | AQ17: =AP17/E17 -> #DIV/0!
F18: =G18+H18 -> 0 | I18: =J18+K18 -> 0 | L18: =M18+N18 -> 0 | O18: =P18+Q18 -> 0 | R18: =S18+T18 -> 0 | U18: =V18+W18 -> 0 | X18: =Y18+Z18 -> 0 | AA18: =AB18+AC18 -> 0 | AD18: =AE18+AF18 -> 0 | AG18: =AH18+AI18 -> 0 | AJ18: =AK18+AL18 -> 0 | AM18: =AN18+AO18 -> 0 | AP18: =F18+L18+R18+X18+AD18+AJ18 -> 0 | AQ18: =AP18/E18 -> #DIV/0!
F19: =G19+H19 -> 0 | I19: =J19+K19 -> 0 | L19: =M19+N19 -> 0 | O19: =P19+Q19 -> 0 | R19: =S19+T19 -> 0 | U19: =V19+W19 -> 0 | X19: =Y19+Z19 -> 0 | AA19: =AB19+AC19 -> 0 | AD19: =AE19+AF19 -> 0 | AG19: =AH19+AI19 -> 0 | AJ19: =AK19+AL19 -> 0 | AM19: =AN19+AO19 -> 0 | AP19: =F19+L19+R19+X19+AD19+AJ19 -> 0 | AQ19: =AP19/E19 -> #DIV/0!
F20: =G20+H20 -> 0 | I20: =J20+K20 -> 0 | L20: =M20+N20 -> 0 | O20: =P20+Q20 -> 0 | R20: =S20+T20 -> 0 | U20: =V20+W20 -> 0 | X20: =Y20+Z20 -> 0 | AA20: =AB20+AC20 -> 0 | AD20: =AE20+AF20 -> 0 | AG20: =AH20+AI20 -> 0 | AJ20: =AK20+AL20 -> 0 | AM20: =AN20+AO20 -> 0 | AP20: =F20+L20+R20+X20+AD20+AJ20 -> 0 | AQ20: =AP20/E20 -> #DIV/0!
F21: =G21+H21 -> 0 | I21: =J21+K21 -> 0 | L21: =M21+N21 -> 0 | O21: =P21+Q21 -> 0 | R21: =S21+T21 -> 0 | U21: =V21+W21 -> 0 | X21: =Y21+Z21 -> 0 | AA21: =AB21+AC21 -> 0 | AD21: =AE21+AF21 -> 0 | AG21: =AH21+AI21 -> 0 | AJ21: =AK21+AL21 -> 0 | AM21: =AN21+AO21 -> 0 | AP21: =F21+L21+R21+X21+AD21+AJ21 -> 0 | AQ21: =AP21/E21 -> #DIV/0!
F22: =G22+H22 -> 0 | I22: =J22+K22 -> 0 | L22: =M22+N22 -> 0 | O22: =P22+Q22 -> 0 | R22: =S22+T22 -> 0 | U22: =V22+W22 -> 0 | X22: =Y22+Z22 -> 0 | AA22: =AB22+AC22 -> 0 | AD22: =AE22+AF22 -> 0 | AG22: =AH22+AI22 -> 0 | AJ22: =AK22+AL22 -> 0 | AM22: =AN22+AO22 -> 0 | AP22: =F22+L22+R22+X22+AD22+AJ22 -> 0 | AQ22: =AP22/E22 -> #DIV/0!
F23: =G23+H23 -> 0 | I23: =J23+K23 -> 0 | L23: =M23+N23 -> 0 | O23: =P23+Q23 -> 0 | R23: =S23+T23 -> 0 | U23: =V23+W23 -> 0 | X23: =Y23+Z23 -> 0 | AA23: =AB23+AC23 -> 0 | AD23: =AE23+AF23 -> 0 | AG23: =AH23+AI23 -> 0 | AJ23: =AK23+AL23 -> 0 | AM23: =AN23+AO23 -> 0 | AP23: =F23+L23+R23+X23+AD23+AJ23 -> 0 | AQ23: =AP23/E23 -> #DIV/0!
F24: =G24+H24 -> 0 | I24: =J24+K24 -> 0 | L24: =M24+N24 -> 0 | O24: =P24+Q24 -> 0 | R24: =S24+T24 -> 0 | U24: =V24+W24 -> 0 | X24: =Y24+Z24 -> 0 | AA24: =AB24+AC24 -> 0 | AD24: =AE24+AF24 -> 0 | AG24: =AH24+AI24 -> 0 | AJ24: =AK24+AL24 -> 0 | AM24: =AN24+AO24 -> 0 | AP24: =F24+L24+R24+X24+AD24+AJ24 -> 0 | AQ24: =AP24/E24 -> #DIV/0!
F25: =G25+H25 -> 0 | I25: =J25+K25 -> 0 | L25: =M25+N25 -> 0 | O25: =P25+Q25 -> 0 | R25: =S25+T25 -> 0 | U25: =V25+W25 -> 0 | X25: =Y25+Z25 -> 0 | AA25: =AB25+AC25 -> 0 | AD25: =AE25+AF25 -> 0 | AG25: =AH25+AI25 -> 0 | AJ25: =AK25+AL25 -> 0 | AM25: =AN25+AO25 -> 0 | AP25: =F25+L25+R25+X25+AD25+AJ25 -> 0 | AQ25: =AP25/E25 -> #DIV/0!
... F30: =G30+H30 -> 0 | I30: =J30+K30 -> 0 | L30: =M30+N30 -> 0 | O30: =P30+Q30 -> 0 | R30: =S30+T30 -> 0 | U30: =V30+W30 -> 0 | X30: =Y30+Z30 -> 0 | AA30: =AB30+AC30 -> 0 | AD30: =AE30+AF30 -> 0 | AG30: =AH30+AI30 -> 0 | AJ30: =AK30+AL30 -> 0 | AM30: =AN30+AO30 -> 0 | AP30: =F30+L30+R30+X30+AD30+AJ30 -> 0 | AQ30: =AP30/E30 -> #DIV/0!
B31: 合 計 | C31: =SUM(C12:C30) -> 230 | D31: =SUM(D12:D30) -> 100 | E31: =SUM(E12:E30) -> 200 | F31: =SUM(F12:F30) -> 90 | G31: =SUM(G12:G30) -> 0 | H31: =SUM(H12:H30) -> 0 | I31: =SUM(I12:I30) -> 59 | J31: =SUM(J12:J30) -> 0 | ... AP31: =SUM(AP12:AP30) -> 90 | AQ31: =AP31/E31 -> 0.45

Sheet 様式３ 教育の質・履修者数を向上させるための体制・計画
I1: 様式３
G2: 大学等名 | H2: ='様式１−１ プログラムを構成する授業科目'!C2 -> 岩手県立大学盛岡短期大学部
A4: 教育の質・履修者数を向上させるための体制・計画について
A6: ① | B6: 全学の教員数 | C6: (常勤） | E6: 25 | F6: 人 | G6: （非常勤） | H6: 41 | I6: 人
A8: ② | B8: プログラムの授業を教えている教員数 | H8: 6 | I8: 人
A10: ③ | B10: プログラムの運営責任者
B11: （責任者名） | C11: 猪股俊光 | G11: （役職名） | H11: 教育支援本部長
A13: ④ | B13: プログラムを改善・進化させるための体制（委員会・組織等）
B14: 学務調整会議、高等教育推進センター高等教育企画部
B16: （責任者名） | C16: 猪股俊光 | G16: （役職名） | H16: 教育支援本部長
A18: ⑤ | B18: プログラムを改善・進化させるための体制を定める規則名称
B19: 公立大学法人岩手県立大学学務調整会議設置要綱
A21: ⑥ | B21: 体制の目的
B22: 学務調整会議は、全学部（盛岡短期大学部他、四年生学部も含む）並びに各センター（高等教育推進センター、教職教育センター）の教務責任者からなり、全学の教育課程の推進に関する事項の協議及び連絡調整のための組織である。その中では、全学科目の担当者・時間割の調整、授業アンケートの実施などを行っている。 また、高等教育推進センター高等教育企画部では「教育の質保証のための検証及び支援に関すること」「全学に共通する新たな教育課題等への対応に関すること」「ファカルティ・ディベロップメントに関すること」を所掌している。全学共通の教育プログラムについては、高等教育推進センター高等教育企画部で企画・立案し、学部調整会議を通じて実施した授業アンケートの結果をもとに、高等教育推進センター高等教育企画部にて改善を図っている。
A34: ⑦ | B34: 具体的な構成員
B35: 学務調整会議 委員長 猪股俊光 盛岡短期大学部教務委員長 大澤朋子、宮古短期大学部教務委員長 昇高茂樹 高等教育企画部副部長 渡部芳栄、教育支援本部 工藤真由美 看護学部教務委員長 内海香子、社会福祉学部教務委員長 鈴木力雄 ソフトウェア情報学部教務委員長 新井義和、総合政策学部教務委員長 Tee Kian Heng 高等教育推進センター教務委員長 高橋英也、教職教育センター 福島朋子 看護学研究科教務委員長 高橋有里、社会福祉学研究科教務委員長 佐藤哲郎 ソフトウェア情報学研究科教務委員長 高田豊雄、総合政策研究科教務委員長 倉原宗孝 高等教育推進センター高等教育企画部 部長 猪股俊光 副部長 渡部芳栄 准教授 天野哲彦 准教授 高瀬和実
A48: ⑧ | B48: 履修者数・履修率の向上に向けた計画 ※様式１の「履修必須の有無」で「計画がある」としている場合は詳細について記載すること
B49: 令和４年度実績 | C49: ='様式２ 履修者等数の実績'!AQ31 -> 0.45 | E49: 令和５年度予定 | F49: 0.87 | H49: 令和６年度予定 | I49: 1
B50: 令和７年度予定 | C50: 1 | E50: 令和８年度予定 | F50: 1 | H50: 収容定員（名） | I50: ='様式２ 履修者等数の実績'!E31 -> 200
B51: 具体的な計画
B52: 生活科学科のうち生活デザイン専攻の学生については、本プログラムを構成する「情報科学概論」と「情報処理演習」はともに１年次の必修科目であることから令和４年度の新入生26人全員が履修し、26人が本プログラムを修了した。同学科生活科学食物栄養専攻の学生については、１年次の「情報科学概論」は新入生28人中27人が履修し、２年次（令和５年度）に「栄養情報処理演習」を選択科目として履修することで本プログラムを修了する。そのため、生活科学科の本プログラム修了生は令和４年度26人よりも令和５年度は約53人へと増加することが見込まれる。これにより、生活科学科の本プログラムの履修率は、令和４年度53％、令和５年度約100％と年々向上する予定である。 国際文化学科の学生の場合、本プログラムを構成する「情報処理入門」、「情報処理演習Ａ」、「情報処理演習Ｂ」はともに１年次の科目であることから令和４年度の時点で37人が本プログラムを履修した。来年度も同程度の履修者が見込まれることから、履修率は令和４年度37％、令和５年度約75％と年々向上する予定である。
A65: ⑨ | B65: 学部・学科に関係なく希望する学生全員が受講可能となるような必要な体制・取組等
B66: 本プログラムを構成する各学科の科目については、時間割の調整をして、同一時限に他科目との重複開講を避けることで、希望する学生全員が受講できるようにしている。具体的には、必修科目として開講している生活科学科「情報科学概論、情報処理実習」と国際文化学科「情報処理入門」に加えて、選択科目である生活科学科「栄養情報処理実習」、国際文化学科「情報処理実習Ａ、情報処理実習Ｂ」はいずれも希望する学生が履修できるよう時間割や使用する教室を調整している。
A79: ⑩ | B79: できる限り多くの学生が履修できるような具体的な周知方法・取組
B80: 本学の学生が学科に関係なく本プログラムを履修することを、次の媒体を通じながら学内外に周知することで、本学志願者や入学者らの本プログラムへの認知度が高まるよう努めた。 ・本学Webページでの本プログラムの紹介 ・「入学案内」（受験生向けのパンフレット）での本プログラムの紹介 ・本学の広報誌（Arch 第83号）での本プログラムの紹介 とくに、入学予定者（入試合格者）には、BYODの導入の案内とともにノートＰＣを活用した本プログラムが開始されることを伝えた。 さらに、入学後の新入生ガイダンスにおいて、本プログラムを説明するとともに、「履修の手引き」のなかで本プログラムの目的・対象科目・修了要件などを記載している。
A93: ⑪ | B93: できる限り多くの学生が履修・修得できるようなサポート体制
B94: 本プログラムの履修者が必要な単位を修得できるように、入学時オリエンテーションの期間中には、本プログラムを履修するために必要なアプリケーションソフトウェアを学生個人が所有しているノートＰＣへインストールするためのガイダンスを短期大学部生全員を対象に開催している。さらに、前期の授業開始前までに、学内のＬＭＳの利用方法のガイダンスも行い、本プログラムの履修に必要な学内情報システムの利用法について全入学生に周知している。
A107: ⑫ | B107: 授業時間内外で学習指導、質問を受け付ける具体的な仕組み
B108: 各科目の担当者は、同一キャンパスに設置されている４年生大学の常勤教員（ソフトウェア情報学部等所属）であり、ＬＭＳ（WebClass）を活用して、講義資料の配付や課題の提出、質問の受付・回答が行えるようにしている。また、学生個人所有のノートＰＣを利用した科目では各クラスに２名のＴＡ（主にソフトウェア情報学研究科の学生など）を配置し、授業内容についての個別指導に対応している。 さらに、数理分野の質問は、短期大学部生が利用できる数学相談室（統計や微分積分などに対応）でも受け付けている。 そして、令和５年度からは、全学部の学生を対象として、データサイエンス・ＡＩや ＩＣＴ操作法に関する相談も受け付けられるよう体制を整えていく予定としている。

Sheet 様式４　自己点検・評価
I1: 様式４
H2: 大学等名 | I2: ='様式１−１ プログラムを構成する授業科目'!C2 -> 岩手県立大学盛岡短期大学部
A3: 自己点検・評価について
A5: ① | B5: プログラムの自己点検・評価を行う体制（委員会・組織等）
B6: 学務調整委員会、高等教育推進センター高等教育企画部
D8: （責任者名） | E8: 猪股俊光 | G8: （役職名） | H8: 教育支援本部長
A10: ② | B10: 自己点検・評価体制における意見等
B11: 自己点検・評価の視点 | E11: 自己点検・評価体制における意見・結果・改善に向けた取組等
B12: 学内からの視点
C13: プログラムの履修・修得状況 | E13: 本プログラムを構成する各科目では、全学部共通の学務システムによって履修・修得状況を、授業支援システムによって受講者毎の課題提出状況を、それぞれ把握することができる。 生活科学科生活デザイン専攻においては、新入生26名が履修し、全員がプログラムを修了している。生活科学科食物栄養学専攻においては、プログラムを構成する科目のうち、１年次開講科目については、新入生全員が履修・取得している。プログラムを構成するもう1つの科目は2年次開講科目であるため、まだプログラムの修了者はいない。 国際文化学科においては、37名が履修し、内33名が単位を修得、プログラムを修了している（新入生の約90%）。
C14: 学修成果 | E14: 生活科学科、国際文化学科ともに、授業における評価方法が、課題の達成度、内容の理解に基づいている。また授業アンケートにおける「得たものが多かったですか」「到達目標は達成てきましたか」の項目を分析することにより、学生自身による理解度の自己評価を把握することができる。これらを統合的に分析することにより、学修成果の把握を行う。 また、これらの結果を担当教員を中心に教員間で共有し、検証することで、本教育プログラムの評価・改善を行う。
C15: 学生アンケート等を通じた学生の内容の理解度 | E15: 本教育プログラムを構成する授業科目について、授業アンケートを実施している。授業アンケートにおける「得たものが多かったですか」「到達目標は達成できましたか」という項目を分析することにより、学生の内容の理解度を把握する。 令和４年度においては「得たもの」について、6段階中上位2段階が、生活科学科では83%、国際文化学科については65%を占めている。また「到達目標」については、生活科学科では74%、国際文化学科については55%を占めている。このような情報を担当教員を中心にフィードバックすることで、学生の理解度を把握するとともに、理解度向上への改善につなげる。
C16: 学生アンケート等を通じた後輩等他の学生への推奨度 | E16: 各科目について授業アンケートには「得たものが多かったですか」「到達目標は達成できましたか」に加え、「真剣な態度で参加できましたか」も含まれている。令和4年度においては、6段階中上位2段階が生活科学科で75%、国際文化学科で67%を占めている。これらの結果を、本教育プログラムを構成する授業科目に含まれる必須科目において、学生に伝えることで、授業の履修を推奨する。また個人情報にも配慮したうえで学生の意見を公開するほか、学ぶ内容の活用機会などを必修科目において紹介することで、推奨を強化する。
C17: 全学的な履修者数、履修率向上に向けた計画の達成・進捗状況 | E17: 生活科学科生活デザイン専攻の場合、令和４年度の履修率は52％であり、令和５年度は100％に向上することが見込まれる。生活科学科食物栄養専攻の場合、令和４年度に「情報科学概論」を１年生全員が履修しており、令和５年度に「栄養情報処理実習（選択）」の履修予定者は前年度実績より２年生全員が見込めることから、令和５年度の履修率は50％、令和６年度の履修率は100％となる予定である。 国際文化学科の場合、令和４年度の履修率は37％であり、令和５年度も同程度の修了者が見込まれ、令和５年度の履修率は約70％と向上する予定である。その後も履修率の向上に努めていく。
B18: 学外からの視点
C19: 教育プログラム修了者の進路、活躍状況、企業等の評価 | E19: 本短期大学部の卒業生の就職先は、金融・保険業、サービス業、製造業・建設業、専門職（栄養士）、卸・小売業など、多業種にわたっており、卒業生には、AIをはじめとする最新技術を活用し、新たな価値やあらたな社会を創造することが求められている。本プログラムの修了生が卒業する令和６年度以降からは、企業等へのアンケートなどをもとに本プログラムの改善に努める予定である。
C20: 産業界からの視点を含めた教育プログラム内容・手法等への意見 | E20: 岩手県内の高等教育機関や地方公共団体、経済・産業団体からなる「いわて高等教育地域連携プラットフォーム」による、「高等教育人材の教育及び県内定着促進に関するアンケート調査によれば、岩手県内の430事業所のうち、約７割の事業所大学等高等教育機関に求める教育プログラムとして「数理・データサイエンス・ＡＩ・ＩＴ教育」をあげている。また、本学の設立団体が示した「いわて県民計画（2019〜2028）」では、AIをはじめとする第４次産業革命技術を活用し、新たな社会を創造し、岩手県の未来をけん引する人材の育成が求められている。 このような社会的な要請に応えるべく、本プログラムの改善に努めていく。
B21: 数理・データサイエンス・ＡＩを「学ぶ楽しさ」「学ぶことの意義」を理解させること | E21: リコメンデーションシステムや経路探索など、学生が日頃接することが多いと考えられる事例を中心に、それらに関連する数理・データサイエンス・AIを紹介し、自分たちの生活との関連性を意識させている。また、映画などのコンテンツで紹介された事例をあげるとともに、企業などが展開している内容を紹介することで、将来をイメージさせている。さらにネットストーカーやフェイクニュース、個人情報流出など、自らも被害者にも加害者にもなりうる負の事例も紹介し、データリテラシーの重要性についても講義している。これらを通し、数理・データサイエンス・AIを学ぶことの楽しさや意義の理解を深めている。
B22: 内容・水準を維持・向上しつつ、より「分かりやすい」授業とすること | E22: 授業アンケートでは、演習科目において難易度が高いと回答する傾向が見られる。これは実際のソフトウェア操作に係る点が大きい。この点に対し、独自に補足資料を用意するとともに、それらを学生がアクセスしやすい形で公開している。また実際に教員が作業内容を見せることで、わかりやすさの向上を図る。今後はそのような手順を動画などで用意することや、教育アシスタントを重点的に配置すること、ペアワークを取り入れるなどし、履修者間での教えあう形を推進するなどを通して、「わかりやすさ」の維持向上を進める。
