Workbook

Sheet 様式１－１　プログラムを構成する授業科目
R1: 様式１-１ | T1: 「学部・学科によって、修了要件は相違する」場合は、本シートを複製の上＜様式１－〇＞と枝番号を付してください
B2: 大学等名 | C2: 常磐大学
B3: プログラム名 | C3: 常磐大学数理・データサイエンス・AI教育プログラム
A5: プログラムを構成する授業科目について
A7: ① 対象となる学部・学科名称 | J7: ② 教育プログラムの修了要件 | K7: 学部・学科によって、修了要件は相違する
B9: 人間科学部、総合政策学部
A12: ③ 修了要件
B13: 本プログラムを構成する『情報の処理I』（全学基本科目・必修）を2単位、『統計の基礎』（全学基本科目・必修）を2単位、計4単位を取得すること。 | V13: 【プルダウンリスト】
V14: 令和４年度以前より、履修することが必須のプログラムとして実施
V15: 令和７年度までに履修必須とする計画
V16: 令和８年度以降に履修必須とする計画、又は未定
B20: 必要最低単位数 | C20: 4 | E20: 単位 | J20: 履修必須の有無 | K20: 令和７年度までに履修必須とする計画
A22: ④ 現在進行中の社会変化(「情報の処理I」第４次産業革命、Society 5.0、データ駆動型社会等）に深く寄与しているものであり、それが自らの生活と密接に結びついている」の内容を含む授業科目
B24: 授業科目 | F24: 単位数 | G24: 必須 | H24: 1-1 | I24: 1-6 | J24: 授業科目 | P24: 単位数 | Q24: 必須 | R24: 1-1 | S24: 1-6
B25: 情報の処理I | F25: 2 | G25: ○ | H25: ○ | I25: ○
A33: ⑤ 「社会で活用されているデータ」や「データの活用領域」は非常に広範囲であって、日常生活や社会の課題を解決する有用なツールになり得るもの」の内容を含む授業科目
B35: 授業科目 | F35: 単位数 | G35: 必須 | H35: 1-2 | I35: 1-3 | J35: 授業科目 | P35: 単位数 | Q35: 必須 | R35: 1-2 | S35: 1-3
B36: 情報の処理I | F36: 2 | G36: ○ | H36: ○ | I36: ○
A44: ⑥ 「様々なデータ利活用の現場におけるデータ利活用事例が示され、様々な適用領域（流通、製造、金融、サービス、インフラ、公共、ヘルスケア等）の知見と組み合わせることで価値を創出するもの」の内容を含む授業科目
B46: 授業科目 | F46: 単位数 | G46: 必須 | H46: 1-4 | I46: 1-5 | J46: 授業科目 | P46: 単位数 | Q46: 必須 | R46: 1-4 | S46: 1-5
B47: 情報の処理I | F47: 2 | G47: ○ | H47: ○ | I47: ○
A55: ⑦ 「活用に当たっての様々な留意事項（ELSI、個人情報、データ倫理、ＡＩ社会原則等）を考慮し、情報セキュリティや情報漏洩等、データを守る上での留意事項への理解をする」の内容を含む授業科目
B57: 授業科目 | F57: 単位数 | G57: 必須 | H57: 3-1 | I57: 3-2 | J57: 授業科目 | P57: 単位数 | Q57: 必須 | R57: 3-1 | S57: 3-2
B58: 情報の処理I | F58: 2 | G58: ○ | H58: ○ | I58: ○
A66: ⑧ 「実データ・実課題（学術データ等を含む）を用いた演習など、社会での実例を題材として、「データを読む、説明する、扱う」といった数理・データサイエンス・ＡＩの基本的な活用法に関するもの」の内容を含む授業科目
B68: 授業科目 | E68: 単位数 | F68: 必須 | G68: 2-1 | H68: 2-2 | I68: 2-3 | J68: 授業科目 | O68: 単位数 | P68: 必須 | Q68: 2-1 | R68: 2-2 | S68: 2-3
B69: 情報の処理I | E69: 2 | F69: ○ | G69: ○ | H69: ○ | I69: ○
B70: 統計の基礎 | E70: 2 | F70: ○ | G70: ○ | H70: ○ | I70: ○
A77: ⑨ 選択「４．オプション」の内容を含む授業科目
B78: 授業科目 | F78: 選択項目 | J78: 授業科目 | P78: 選択項目
A87: ⑩ プログラムを構成する授業の内容
B88: 授業に含まれている内容・要素 | D88: 講義内容
B89: （１）現在進行中の社会変化(「情報の処理I」第４次産業革命、Society 5.0、データ駆動型社会等）に深く寄与しているものであり、それが自らの生活と密接に結びついている | C89: 1-1 | D89: ・ビッグデータ、IoT、AI、ロボット(「情報の処理I」第4回） ・データ量の増加、計算機の処理性能の向上、AIの非連続的進化(「情報の処理I」第4回） ・第4次産業革命、Society5.0、データ駆動型社会(「情報の処理I」第4回） ・複数技術を組み合わせたAIサービス(「情報の処理I」第4回）
C90: 1-6 | D90: ・AI等を活用した新しいビジネスモデル(「情報の処理I」第5回） ・AI最新技術の活用例(「情報の処理I」第5回）
B91: （２）「社会で活用されているデータ」や「データの活用領域」は非常に広範囲であって、日常生活や社会の課題を解決する有用なツールになり得るもの | C91: 1-2 | D91: ・調査データ、実験データ、人の行動ログデータ、機械の稼働ログデータなど(「情報の処理I」第4回） ・1次データ、2次データ、データのメタ化(「情報の処理I」第4回） ・データのオープン化(「情報の処理I」第4回）
C92: 1-3 | D92: ・データ・AI活用領域の広がり(「情報の処理I」第4回） ・研究開発、調達、製造、物流、販売、マーケティング、サービスなど(「情報の処理I」第4回）
B93: （３）様々なデータ利活用の現場におけるデータ利活用事例が示され、様々な適用領域（流通、製造、金融、サービス、インフラ、公共、ヘルスケア等）の知見と組み合わせることで価値を創出するもの | C93: 1-4 | D93: ・特化型AIと汎用AI、今のAIで出来ることと出来ないこと、AIとビッグデータ(「情報の処理I」第5回）
C94: 1-5 | D94: ・流通、製造、金融、サービス、インフラ、公共、ヘルスケア等におけるデータ・AI利活用事例紹介(「情報の処理I」第5回）
B95: （４）活用に当たっての様々な留意事項（ELSI、個人情報、データ倫理、ＡＩ社会原則等）を考慮し、情報セキュリティや情報漏洩等、データを守る上での留意事項への理解をする | C95: 3-1 | D95: ・個人情報保護、EU一般データ保護規則(GDPR)、忘れられる権利、オプトアウト(「情報の処理I」第3回) ・データ倫理：データのねつ造、改ざん、盗用、プライバシー保護(「情報の処理I」第3回) ・AI社会原則(「情報の処理I」第3回)
C96: 3-2 | D96: ・情報セキュリティ：機密性、完全性、可用性(「情報の処理I」第3回) ・匿名加工情報、暗号化、パスワード、悪意ある情報搾取(「情報の処理I」第3回) ・情報漏洩等によるセキュリティ事故の事例紹介(「情報の処理I」第3回)
...

Sheet 様式１－２　プログラムを構成する授業科目
R1: 様式１-２ | T1: 「学部・学科によって、修了要件は相違する」場合は、本シートを複製の上＜様式１－〇＞と枝番号を付してください
B2: 大学等名 | C2: 常磐大学
B3: プログラム名 | C3: 常磐大学数理・データサイエンス・AI教育プログラム
A5: プログラムを構成する授業科目について
A7: ① 対象となる学部・学科名称 | J7: ② 教育プログラムの修了要件 | K7: 学部・学科によって、修了要件は相違する
B9: 看護学部
A12: ③ 修了要件
B13: 本プログラムを構成する『情報の処理』（全学基本科目・必修）を2単位、『統計の基礎』（全学基本科目・必修）を2単位、計4単位を取得すること。 | V13: 【プルダウンリスト】
V14: 令和４年度以前より、履修することが必須のプログラムとして実施
V15: 令和７年度までに履修必須とする計画
V16: 令和８年度以降に履修必須とする計画、又は未定
B20: 必要最低単位数 | C20: 4 | E20: 単位 | J20: 履修必須の有無 | K20: 令和７年度までに履修必須とする計画
A22: ④ 現在進行中の社会変化(「情報の処理」第４次産業革命、Society 5.0、データ駆動型社会等）に深く寄与しているものであり、それが自らの生活と密接に結びついている」の内容を含む授業科目
B24: 授業科目 | F24: 単位数 | G24: 必須 | H24: 1-1 | I24: 1-6 | J24: 授業科目 | P24: 単位数 | Q24: 必須 | R24: 1-1 | S24: 1-6
B25: 情報の処理 | F25: 2 | G25: ○ | H25: ○ | I25: ○
A33: ⑤ 「社会で活用されているデータ」や「データの活用領域」は非常に広範囲であって、日常生活や社会の課題を解決する有用なツールになり得るもの」の内容を含む授業科目
B35: 授業科目 | F35: 単位数 | G35: 必須 | H35: 1-2 | I35: 1-3 | J35: 授業科目 | P35: 単位数 | Q35: 必須 | R35: 1-2 | S35: 1-3
B36: 情報の処理 | F36: 2 | G36: ○ | H36: ○ | I36: ○
A44: ⑥ 「様々なデータ利活用の現場におけるデータ利活用事例が示され、様々な適用領域（流通、製造、金融、サービス、インフラ、公共、ヘルスケア等）の知見と組み合わせることで価値を創出するもの」の内容を含む授業科目
B46: 授業科目 | F46: 単位数 | G46: 必須 | H46: 1-4 | I46: 1-5 | J46: 授業科目 | P46: 単位数 | Q46: 必須 | R46: 1-4 | S46: 1-5
B47: 情報の処理 | F47: 2 | G47: ○ | H47: ○ | I47: ○
A55: ⑦ 「活用に当たっての様々な留意事項（ELSI、個人情報、データ倫理、ＡＩ社会原則等）を考慮し、情報セキュリティや情報漏洩等、データを守る上での留意事項への理解をする」の内容を含む授業科目
B57: 授業科目 | F57: 単位数 | G57: 必須 | H57: 3-1 | I57: 3-2 | J57: 授業科目 | P57: 単位数 | Q57: 必須 | R57: 3-1 | S57: 3-2
B58: 情報の処理 | F58: 2 | G58: ○ | H58: ○ | I58: ○
A66: ⑧ 「実データ・実課題（学術データ等を含む）を用いた演習など、社会での実例を題材として、「データを読む、説明する、扱う」といった数理・データサイエンス・ＡＩの基本的な活用法に関するもの」の内容を含む授業科目
B68: 授業科目 | E68: 単位数 | F68: 必須 | G68: 2-1 | H68: 2-2 | I68: 2-3 | J68: 授業科目 | O68: 単位数 | P68: 必須 | Q68: 2-1 | R68: 2-2 | S68: 2-3
B69: 情報の処理 | E69: 2 | F69: ○ | G69: ○ | H69: ○ | I69: ○
B70: 統計の基礎 | E70: 2 | F70: ○ | G70: ○ | H70: ○ | I70: ○
A77: ⑨ 選択「４．オプション」の内容を含む授業科目
B78: 授業科目 | F78: 選択項目 | J78: 授業科目 | P78: 選択項目
A87: ⑩ プログラムを構成する授業の内容
B88: 授業に含まれている内容・要素 | D88: 講義内容
B89: （１）現在進行中の社会変化(「情報の処理」第４次産業革命、Society 5.0、データ駆動型社会等）に深く寄与しているものであり、それが自らの生活と密接に結びついている | C89: 1-1 | D89: ・ビッグデータ、IoT、AI、ロボット(「情報の処理」第4回） ・データ量の増加、計算機の処理性能の向上、AIの非連続的進化(「情報の処理」第4回） ・第4次産業革命、Society5.0、データ駆動型社会(「情報の処理」第4回） ・複数技術を組み合わせたAIサービス(「情報の処理」第4回）
C90: 1-6 | D90: ・AI等を活用した新しいビジネスモデル(「情報の処理」第5回） ・AI最新技術の活用例(「情報の処理」第5回）
B91: （２）「社会で活用されているデータ」や「データの活用領域」は非常に広範囲であって、日常生活や社会の課題を解決する有用なツールになり得るもの | C91: 1-2 | D91: ・調査データ、実験データ、人の行動ログデータ、機械の稼働ログデータなど(「情報の処理」第4回） ・1次データ、2次データ、データのメタ化(「情報の処理」第4回） ・データのオープン化(「情報の処理」第4回）
C92: 1-3 | D92: ・データ・AI活用領域の広がり(「情報の処理」第4回） ・研究開発、調達、製造、物流、販売、マーケティング、サービスなど(「情報の処理」第4回）
B93: （３）様々なデータ利活用の現場におけるデータ利活用事例が示され、様々な適用領域（流通、製造、金融、サービス、インフラ、公共、ヘルスケア等）の知見と組み合わせることで価値を創出するもの | C93: 1-4 | D93: ・特化型AIと汎用AI、今のAIで出来ることと出来ないこと、AIとビッグデータ(「情報の処理」第5回）
C94: 1-5 | D94: ・流通、製造、金融、サービス、インフラ、公共、ヘルスケア等におけるデータ・AI利活用事例紹介(「情報の処理」第5回）
B95: （４）活用に当たっての様々な留意事項（ELSI、個人情報、データ倫理、ＡＩ社会原則等）を考慮し、情報セキュリティや情報漏洩等、データを守る上での留意事項への理解をする | C95: 3-1 | D95: ・個人情報保護、EU一般データ保護規則(GDPR)、忘れられる権利、オプトアウト(「情報の処理」第3回) ・データ倫理：データのねつ造、改ざん、盗用、プライバシー保護(「情報の処理」第3回) ・AI社会原則(「情報の処理」第3回)
C96: 3-2 | D96: ・情報セキュリティ：機密性、完全性、可用性(「情報の処理」第3回) ・匿名加工情報、暗号化、パスワード、悪意ある情報搾取(「情報の処理」第3回) ・情報漏洩等によるセキュリティ事故の事例紹介(「情報の処理」第3回)
...

Sheet 様式２ 履修者等数の実績
AQ1: 様式２
AL2: 大学等名 | AM2: ='様式１－２ プログラムを構成する授業科目'!C2 -> 常磐大学
A3: プログラムの履修者数等の実績について
A5: ①プログラム開設年度 | C5: 令和4 | E5: 年度
A7: ②履修者・修了者の実績
B9: 学部・学科名称 | C9: 学生数 | D9: 入学 定員 | E9: 収容 定員 | F9: 令和4年度 | L9: 令和3年度 | R9: 令和2年度 | X9: 令和元年度 | AD9: 平成30年度 | AJ9: 平成29年度 | AP9: 履修者数 合計 | AQ9: 履修率
F10: 履修者数 | I10: 修了者数 | L10: 履修者数 | O10: 修了者数 | R10: 履修者数 | U10: 修了者数 | X10: 履修者数 | AA10: 修了者数 | AD10: 履修者数 | AG10: 修了者数 | AJ10: 履修者数 | AM10: 修了者数
F11: 合計 | G11: 男性 | H11: 女性 | I11: 合計 | J11: 男性 | K11: 女性 | L11: 合計 | M11: 男性 | N11: 女性 | O11: 合計 | P11: 男性 | Q11: 女性 | R11: 合計 | S11: 男性 | T11: 女性 | U11: 合計 | V11: 男性 | W11: 女性 | X11: 合計 | Y11: 男性 | Z11: 女性 | AA11: 合計 | AB11: 男性 | AC11: 女性 | AD11: 合計 | AE11: 男性 | AF11: 女性 | AG11: 合計 | AH11: 男性 | AI11: 女性 | AJ11: 合計 | AK11: 男性 | AL11: 女性 | AM11: 合計 | AN11: 男性 | AO11: 女性
B12: 人間科学部 | C12: 1713 | D12: 396 | E12: 1584 | F12: =G12+H12 -> 422 | G12: 164 | H12: 258 | I12: =J12+K12 -> 366 | J12: 125 | K12: 241 | L12: =M12+N12 -> 0 | O12: =P12+Q12 -> 0 | R12: =S12+T12 -> 0 | U12: =V12+W12 -> 0 | X12: =Y12+Z12 -> 0 | AA12: =AB12+AC12 -> 0 | AD12: =AE12+AF12 -> 0 | AG12: =AH12+AI12 -> 0 | AJ12: =AK12+AL12 -> 0 | AM12: =AN12+AO12 -> 0 | AP12: =F12+L12+R12+X12+AD12+AJ12 -> 422 | AQ12: =AP12/E12 -> 0.26641414
B13: 総合政策学部 | C13: 1084 | D13: 245 | E13: 980 | F13: =G13+H13 -> 285 | G13: 204 | H13: 81 | I13: =J13+K13 -> 251 | J13: 177 | K13: 74 | L13: =M13+N13 -> 0 | O13: =P13+Q13 -> 0 | R13: =S13+T13 -> 0 | U13: =V13+W13 -> 0 | X13: =Y13+Z13 -> 0 | AA13: =AB13+AC13 -> 0 | AD13: =AE13+AF13 -> 0 | AG13: =AH13+AI13 -> 0 | AJ13: =AK13+AL13 -> 0 | AM13: =AN13+AO13 -> 0 | AP13: =F13+L13+R13+X13+AD13+AJ13 -> 285 | AQ13: =AP13/E13 -> 0.29081633
B14: 看護学部 | C14: 340 | D14: 80 | E14: 320 | F14: =G14+H14 -> 81 | G14: 13 | H14: 68 | I14: =J14+K14 -> 64 | J14: 10 | K14: 54 | L14: =M14+N14 -> 0 | O14: =P14+Q14 -> 0 | R14: =S14+T14 -> 0 | U14: =V14+W14 -> 0 | X14: =Y14+Z14 -> 0 | AA14: =AB14+AC14 -> 0 | AD14: =AE14+AF14 -> 0 | AG14: =AH14+AI14 -> 0 | AJ14: =AK14+AL14 -> 0 | AM14: =AN14+AO14 -> 0 | AP14: =F14+L14+R14+X14+AD14+AJ14 -> 81 | AQ14: =AP14/E14 -> 0.253125
F15: =G15+H15 -> 0 | I15: =J15+K15 -> 0 | L15: =M15+N15 -> 0 | O15: =P15+Q15 -> 0 | R15: =S15+T15 -> 0 | U15: =V15+W15 -> 0 | X15: =Y15+Z15 -> 0 | AA15: =AB15+AC15 -> 0 | AD15: =AE15+AF15 -> 0 | AG15: =AH15+AI15 -> 0 | AJ15: =AK15+AL15 -> 0 | AM15: =AN15+AO15 -> 0 | AP15: =F15+L15+R15+X15+AD15+AJ15 -> 0 | AQ15: 0
F16: =G16+H16 -> 0 | I16: =J16+K16 -> 0 | L16: =M16+N16 -> 0 | O16: =P16+Q16 -> 0 | R16: =S16+T16 -> 0 | U16: =V16+W16 -> 0 | X16: =Y16+Z16 -> 0 | AA16: =AB16+AC16 -> 0 | AD16: =AE16+AF16 -> 0 | AG16: =AH16+AI16 -> 0 | AJ16: =AK16+AL16 -> 0 | AM16: =AN16+AO16 -> 0 | AP16: =F16+L16+R16+X16+AD16+AJ16 -> 0 | AQ16: 0
F17: =G17+H17 -> 0 | I17: =J17+K17 -> 0 | L17: =M17+N17 -> 0 | O17: =P17+Q17 -> 0 | R17: =S17+T17 -> 0 | U17: =V17+W17 -> 0 | X17: =Y17+Z17 -> 0 | AA17: =AB17+AC17 -> 0 | AD17: =AE17+AF17 -> 0 | AG17: =AH17+AI17 -> 0 | AJ17: =AK17+AL17 -> 0 | AM17: =AN17+AO17 -> 0 | AP17: =F17+L17+R17+X17+AD17+AJ17 -> 0 | AQ17: 0
F18: =G18+H18 -> 0 | I18: =J18+K18 -> 0 | L18: =M18+N18 -> 0 | O18: =P18+Q18 -> 0 | R18: =S18+T18 -> 0 | U18: =V18+W18 -> 0 | X18: =Y18+Z18 -> 0 | AA18: =AB18+AC18 -> 0 | AD18: =AE18+AF18 -> 0 | AG18: =AH18+AI18 -> 0 | AJ18: =AK18+AL18 -> 0 | AM18: =AN18+AO18 -> 0 | AP18: =F18+L18+R18+X18+AD18+AJ18 -> 0 | AQ18: 0
F19: =G19+H19 -> 0 | I19: =J19+K19 -> 0 | L19: =M19+N19 -> 0 | O19: =P19+Q19 -> 0 | R19: =S19+T19 -> 0 | U19: =V19+W19 -> 0 | X19: =Y19+Z19 -> 0 | AA19: =AB19+AC19 -> 0 | AD19: =AE19+AF19 -> 0 | AG19: =AH19+AI19 -> 0 | AJ19: =AK19+AL19 -> 0 | AM19: =AN19+AO19 -> 0 | AP19: =F19+L19+R19+X19+AD19+AJ19 -> 0 | AQ19: 0
F20: =G20+H20 -> 0 | I20: =J20+K20 -> 0 | L20: =M20+N20 -> 0 | O20: =P20+Q20 -> 0 | R20: =S20+T20 -> 0 | U20: =V20+W20 -> 0 | X20: =Y20+Z20 -> 0 | AA20: =AB20+AC20 -> 0 | AD20: =AE20+AF20 -> 0 | AG20: =AH20+AI20 -> 0 | AJ20: =AK20+AL20 -> 0 | AM20: =AN20+AO20 -> 0 | AP20: =F20+L20+R20+X20+AD20+AJ20 -> 0 | AQ20: 0
F21: =G21+H21 -> 0 | I21: =J21+K21 -> 0 | L21: =M21+N21 -> 0 | O21: =P21+Q21 -> 0 | R21: =S21+T21 -> 0 | U21: =V21+W21 -> 0 | X21: =Y21+Z21 -> 0 | AA21: =AB21+AC21 -> 0 | AD21: =AE21+AF21 -> 0 | AG21: =AH21+AI21 -> 0 | AJ21: =AK21+AL21 -> 0 | AM21: =AN21+AO21 -> 0 | AP21: =F21+L21+R21+X21+AD21+AJ21 -> 0 | AQ21: 0
F22: =G22+H22 -> 0 | I22: =J22+K22 -> 0 | L22: =M22+N22 -> 0 | O22: =P22+Q22 -> 0 | R22: =S22+T22 -> 0 | U22: =V22+W22 -> 0 | X22: =Y22+Z22 -> 0 | AA22: =AB22+AC22 -> 0 | AD22: =AE22+AF22 -> 0 | AG22: =AH22+AI22 -> 0 | AJ22: =AK22+AL22 -> 0 | AM22: =AN22+AO22 -> 0 | AP22: =F22+L22+R22+X22+AD22+AJ22 -> 0 | AQ22: 0
F23: =G23+H23 -> 0 | I23: =J23+K23 -> 0 | L23: =M23+N23 -> 0 | O23: =P23+Q23 -> 0 | R23: =S23+T23 -> 0 | U23: =V23+W23 -> 0 | X23: =Y23+Z23 -> 0 | AA23: =AB23+AC23 -> 0 | AD23: =AE23+AF23 -> 0 | AG23: =AH23+AI23 -> 0 | AJ23: =AK23+AL23 -> 0 | AM23: =AN23+AO23 -> 0 | AP23: =F23+L23+R23+X23+AD23+AJ23 -> 0 | AQ23: 0
F24: =G24+H24 -> 0 | I24: =J24+K24 -> 0 | L24: =M24+N24 -> 0 | O24: =P24+Q24 -> 0 | R24: =S24+T24 -> 0 | U24: =V24+W24 -> 0 | X24: =Y24+Z24 -> 0 | AA24: =AB24+AC24 -> 0 | AD24: =AE24+AF24 -> 0 | AG24: =AH24+AI24 -> 0 | AJ24: =AK24+AL24 -> 0 | AM24: =AN24+AO24 -> 0 | AP24: =F24+L24+R24+X24+AD24+AJ24 -> 0 | AQ24: 0
F25: =G25+H25 -> 0 | I25: =J25+K25 -> 0 | L25: =M25+N25 -> 0 | O25: =P25+Q25 -> 0 | R25: =S25+T25 -> 0 | U25: =V25+W25 -> 0 | X25: =Y25+Z25 -> 0 | AA25: =AB25+AC25 -> 0 | AD25: =AE25+AF25 -> 0 | AG25: =AH25+AI25 -> 0 | AJ25: =AK25+AL25 -> 0 | AM25: =AN25+AO25 -> 0 | AP25: =F25+L25+R25+X25+AD25+AJ25 -> 0 | AQ25: 0
F26: =G26+H26 -> 0 | I26: =J26+K26 -> 0 | L26: =M26+N26 -> 0 | O26: =P26+Q26 -> 0 | R26: =S26+T26 -> 0 | U26: =V26+W26 -> 0 | X26: =Y26+Z26 -> 0 | AA26: =AB26+AC26 -> 0 | AD26: =AE26+AF26 -> 0 | AG26: =AH26+AI26 -> 0 | AJ26: =AK26+AL26 -> 0 | AM26: =AN26+AO26 -> 0 | AP26: =F26+L26+R26+X26+AD26+AJ26 -> 0 | AQ26: 0
... F31: =G31+H31 -> 0 | I31: =J31+K31 -> 0 | L31: =M31+N31 -> 0 | O31: =P31+Q31 -> 0 | R31: =S31+T31 -> 0 | U31: =V31+W31 -> 0 | X31: =Y31+Z31 -> 0 | AA31: =AB31+AC31 -> 0 | AD31: =AE31+AF31 -> 0 | AG31: =AH31+AI31 -> 0 | AJ31: =AK31+AL31 -> 0 | AM31: =AN31+AO31 -> 0 | AP31: =F31+L31+R31+X31+AD31+AJ31 -> 0 | AQ31: 0
B32: 合 計 | C32: =SUM(C12:C31) -> 3137 | D32: =SUM(D12:D31) -> 721 | E32: =SUM(E12:E31) -> 2884 | F32: =SUM(F12:F31) -> 788 | G32: =SUM(G12:G31) -> 381 | H32: =SUM(H12:H31) -> 407 | I32: =SUM(I12:I31) -> 681 | J32: =SUM(J12:J31) -> 312 | ... AP32: =SUM(AP12:AP31) -> 788 | AQ32: =AP32/E32 -> 0.27323162

Sheet 様式３ 教育の質・履修者数を向上させるための体制・計画
I1: 様式３
G2: 大学等名 | H2: ='様式１－２ プログラムを構成する授業科目'!C2 -> 常磐大学
A4: 教育の質・履修者数を向上させるための体制・計画について
A6: ① | B6: 全学の教員数 | C6: (常勤） | E6: 129 | F6: 人 | G6: （非常勤） | H6: 85 | I6: 人
A8: ② | B8: プログラムの授業を教えている教員数 | H8: 10 | I8: 人
A10: ③ | B10: プログラムの運営責任者
B11: （責任者名） | C11: 河野敬一 | G11: （役職名） | H11: 総合講座委員会委員長
A13: ④ | B13: プログラムを改善・進化させるための体制（委員会・組織等）
B14: 総合講座委員会
B16: （責任者名） | C16: 河野敬一 | G16: （役職名） | H16: 総合講座委員会委員長
A18: ⑤ | B18: プログラムを改善・進化させるための体制を定める規則名称
B19: 総合講座委員会規程，全学自己点検・評価規程，全学情報教育委員会規程
A21: ⑥ | B21: 体制の目的
B22: 総合講座委員会は、常磐大学における全学共通教育を実施する責任組織として、全学共通教育に関する授業科目の開設および廃止に関すること、全学共通教育に関する教育課程および教育指導に関することについて、企画・運営および審議を行う。 また、総合講座委員会の中に、全学共通教育の科目群のひとつである全学基本科目運営会議を設け、情報教育に関して、全学情報教育委員会と連携して教育を円滑に実施することを目的とし、コンピュータスキルおよび統計手法を学生が修得するよう審議し、総合講座委員会において改善の提議等を行う。
A34: ⑦ | B34: 具体的な構成員
B35: 人間科学部 教授 河野敬一 （総合講座委員会委員長、総合講座自己点検・評価実施委員会委員長） 人間科学部 教授 森 弘一 （総合講座委員会副委員長） 総合政策学部 准教授 町 英朋 （総合講座委員会全学基本科目運営会議長、全学情報教育委員会委員長、情報教育の授業運営に関するWG長） 人間科学部 教授 北根 精美（情報教育の授業運営に関するWG） 総合政策学部 教授 塩 雅之（情報教育の授業運営に関するWG） 人間科学部 専任講師 寺島 哲平（総合講座全学基本科目運営会議委員、全学情報教育委員会委員、情報教育の授業運営に関するWG） 人間科学部 助教 栗原 和弘（総合講座全学基本科目運営会議委員、『統計の基礎』担当教員） 常磐短期大学 助教 笹原 康孝 （全学情報教育委員会委員、情報教育の授業運営に関するWG）
A48: ⑧ | B48: 履修者数・履修率の向上に向けた計画 ※様式１の「履修必須の有無」で「計画がある」としている場合は詳細について記載すること
B49: 令和４年度実績 | C49: ='様式２ 履修者等数の実績'!AQ32 -> 0.27323162 | E49: 令和５年度予定 | F49: 0.5 | H49: 令和６年度予定 | I49: 0.75
B50: 令和７年度予定 | C50: 1 | E50: 令和８年度予定 | F50: 1 | H50: 収容定員（名） | I50: ='様式２ 履修者等数の実績'!E32 -> 2884
B51: 具体的な計画
B52: 本学の「数理・データサイエンス・AI教育プログラム（リテラシーレベル）」は、本学の全学基本科目に配置されている科目『情報の処理I』と『統計の基礎』が取得要件となっている。この2科目は必修科目（卒業要件）であり、入学者全員が履修するため、履修者数は入学者数となる。
A65: ⑨ | B65: 学部・学科に関係なく希望する学生全員が受講可能となるような必要な体制・取組等
B66: ⑧に記載のとおり、本プログラム対象の2科目は必修科目であるため、学位が授与された学生については100％の履修率となる。当該2科目の配当年次は1年次であり、入学初年次に履修を終えることが望ましい。なお、単位未修得となった場合は翌年度に再履修することを原則としているが、履修上の指導によっては卒業時までのいずれかの学年で履修することとなる。
A79: ⑩ | B79: できる限り多くの学生が履修できるような具体的な周知方法・取組
B80: ⑧に記載のとおり、本プログラムの対象科目は必修科目であるため、学生は年度当初の履修登録において当該科目を必ず履修するよう履修ガイダンス等で指導されることになる。また、当該科目のシラバスはWeb上に公開されており、「授業の概要」「学修の到達目標」「授業計画」「成績の評価方法・基準」など具体的な項目について学生が自ら確認できるようになっており、本プログラムと対象科目との位置づけが理解できるようになっている。
A93: ⑪ | B93: できる限り多くの学生が履修・修得できるようなサポート体制
B94: ⑧に記載のとおり、本プログラムの対象科目は必修科目であるため、全員初年次に履修することになる。履修登録については、クラス編成を履修登録システムで管理しているため、履修登録のミスはシステムでエラーとなる。所管である学生支援センターと学事センターとクラス編成担当教員とで連携を密に行い、全ての新入生と再履修学生が履修登録を完了し、授業を受けられるような体制をとっている。
A107: ⑫ | B107: 授業時間内外で学習指導、質問を受け付ける具体的な仕組み
B108: 本プログラムの対象科目を担当する教員のうち、専任教員についてはオフィスアワーを設定しており、授業内容の質問等について対面による相談体制が用意されている（本プログラム当該科目担当教員のみならず、本学の全専任教員がオフィスアワーを設定することになっている）。また、専任教員および非常勤講師は連絡先としてメールアドレス等を学生に伝えており（eラーニングシステムの授業コースに掲載）、対面に依らないオンラインにおける相談についても対応する体制になっている。

Sheet 様式４　自己点検・評価
I1: 様式４
H2: 大学等名 | I2: ='様式１－２ プログラムを構成する授業科目'!C2 -> 常磐大学
A3: 自己点検・評価について
A5: ① | B5: プログラムの自己点検・評価を行う体制（委員会・組織等）
B6: 総合講座自己点検・評価実施委員会
D8: （責任者名） | E8: 河野敬一 | G8: （役職名） | H8: 総合講座自己点検・評価実施委員会委員長
A10: ② | B10: 自己点検・評価体制における意見等
B11: 自己点検・評価の視点 | E11: 自己点検・評価体制における意見・結果・改善に向けた取組等
B12: 学内からの視点
C13: プログラムの履修・修得状況 | E13: 総合講座自己点検・評価実施委員会より全学基本科目運営会議宛てに履修・成績状況の確認依頼が行われる（データの送付有り）。全学基本科目運営会議において、『情報の処理I』『情報の処理』『統計の基礎』の各クラスごとの成績評価の状況（評定値：Ｓ･Ａ･Ｂ･Ｃ･Ｄ・Ｆ･Ｘの分布等）を把握し、科目担当教員との情報共有を図っている。『情報の処理I』『情報の処理』については、全学情報教育委員会が設置する「情報教育の授業運営に関するWG」とも情報共有を行い、必要に応じて次年度の授業内容の改善を講じている。
C14: 学修成果 | E14: 『情報の処理I』『情報の処理』は対面授業であるが、eラーニングシステム上に教材が用意され授業運営されている。学生はコース内の課題について提出状況などを自身で把握することが出来るようになっている。本プログラムに関する授業回に関する小テスト等も随時行われ、担当教員および学生が学修成果をそれぞれ確認できるようになっている。 学修成果の内容については、「情報教育の授業運営に関するWG」で情報共有を図り、授業内容の妥当性などの検証を行っている。また、上記の履修・修得状況のデータと併せて、本プログラムの効果についても検証を行っている。
C15: 学生アンケート等を通じた学生の内容の理解度 | E15: 本学では本プログラムの対象科目を含めほとんどの授業科目で学生による授業アンケートを行っており、アンケートの結果は「常磐大学ファカルティデベロップメント委員会」より各科目担当教員へ送付されている。このアンケートにより、学生の理解度などを科目担当教員はそれぞれ把握できるようになっている。本プログラムの対象科目についても、科目担当教員間あるいは全学基本科目運営会議などを通して情報共有を行っている。
C16: 学生アンケート等を通じた後輩等他の学生への推奨度 | E16: 本プログラムの対象科目は1年次の必修科目であるため、学生による授業評価アンケートの実施後に後輩等他の学生へ履修を推奨するような取り組みは特に行われてはいない。
C17: 全学的な履修者数、履修率向上に向けた計画の達成・進捗状況 | E17: 上記に記載のとおり、本プログラムの対象科目は1年次必修科目であるため、新入生の履修率は100％である。1年次に修得できなかった学生に対しては、原則として2年次に再履修するよう履修指導が行われており、在学期間の早期に本プログラムの修了要件を満たすように本プログラムは運用されている。
B18: 学外からの視点
C19: 教育プログラム修了者の進路、活躍状況、企業等の評価 | E19: 主な就職先である企業等に対して毎年実施している「卒業生に関するアンケート」において、本教育プログラムを修了した卒業生の採用状況や企業評価、採用意欲等を把握する仕組みを設ける予定である。これらの情報を総合講座自己点検・評価実施委員会で点検・評価し、プログラム改善の取り組みを進めていく。
C20: 産業界からの視点を含めた教育プログラム内容・手法等への意見 | E20: 主な就職先である企業等に対して毎年実施している「卒業生に関するアンケート」において、本教育プログラムに対する評価・意見等を収集するとともに、本教育プログラムの改善に活用する予定である。また、2023年度より設置する「常磐大学・常磐短期大学の教育研究活動に関する懇談会」において、教育プログラムの内容･方法や教育プログラムに関する点検・評価の取り組みについて、学外諸機関の関係者や有識者の意見を求め、改善に結びつける仕組みを整えている。
B21: 数理・データサイエンス・ＡＩを「学ぶ楽しさ」「学ぶことの意義」を理解させること | E21: ビッグデータやIoT、AIの利活用などの内容については、身近な事例を多く取りあげ、理工系の難しい話という印象を持たせることなく自分たちの生活に密接に関わっているという視点で理解につながるよう授業展開を工夫している。
B22: 内容・水準を維持・向上しつつ、より「分かりやすい」授業とすること | E22: 授業進行中において、全学情報教育委員会のもとに設置している「情報教育の授業運営に関するWG」を中心に、教室内の学生の様子について意見交換を行っている。また、授業終了後においては、学生による授業評価アンケート結果を基に授業内容や方法の改善を継続的に図っている。
