Workbook

Sheet 様式１　プログラムを構成する授業科目
R1: 様式１
B2: 大学等名 | C2: 広島経済大学
B3: プログラム名 | C3: データサイエンス教育プログラム
A5: プログラムを構成する授業科目について
A7: ① 対象となる学部・学科名称 | J7: ② 教育プログラムの修了要件 | K7: 学部・学科によって、修了要件は相違しない
B9: 経
A12: ③ 修了要件
B13: 「AIリテラシー入門」 （共通科目群 基礎教養科目）2単位を取得すること。
B20: 必要最低単位数 | C20: 2 | E20: 単位 | J20: 履修必須の有無 | K20: 令和８年度以降に履修必須とする計画、又は未定
A22: ④ 現在進行中の社会変化（第４次産業革命、Society 5.0、データ駆動型社会等）に深く寄与しているものであり、それが自らの生活と密接に結びついている」の内容を含む授業科目
B24: 授業科目 | F24: 単位数 | G24: 必須 | H24: 1-1 | I24: 1-6 | J24: 授業科目 | P24: 単位数 | Q24: 必須 | R24: 1-1 | S24: 1-6
B25: AIリテラシー入門 | F25: 2 | G25: ○ | H25: ○ | I25: ○
A33: ⑤ 「社会で活用されているデータ」や「データの活用領域」は非常に広範囲であって、日常生活や社会の課題を解決する有用なツールになり得るもの」の内容を含む授業科目
B35: 授業科目 | F35: 単位数 | G35: 必須 | H35: 1-2 | I35: 1-3 | J35: 授業科目 | P35: 単位数 | Q35: 必須 | R35: 1-2 | S35: 1-3
B36: AIリテラシー入門 | F36: 2 | G36: ○ | H36: ○ | I36: ○
A44: ⑥ 「様々なデータ利活用の現場におけるデータ利活用事例が示され、様々な適用領域（流通、製造、金融、サービス、インフラ、公共、ヘルスケア等）の知見と組み合わせることで価値を創出するもの」の内容を含む授業科目
B46: 授業科目 | F46: 単位数 | G46: 必須 | H46: 1-4 | I46: 1-5 | J46: 授業科目 | P46: 単位数 | Q46: 必須 | R46: 1-4 | S46: 1-5
B47: AIリテラシー入門 | F47: 2 | G47: ○ | H47: ○ | I47: ○
A55: ⑦ 「活用に当たっての様々な留意事項（ELSI、個人情報、データ倫理、ＡＩ社会原則等）を考慮し、情報セキュリティや情報漏洩等、データを守る上での留意事項への理解をする」の内容を含む授業科目
B57: 授業科目 | F57: 単位数 | G57: 必須 | H57: 3-1 | I57: 3-2 | J57: 授業科目 | P57: 単位数 | Q57: 必須 | R57: 3-1 | S57: 3-2
B58: AIリテラシー入門 | F58: 2 | G58: ○ | H58: ○ | I58: ○
A66: ⑧ 「実データ・実課題（学術データ等を含む）を用いた演習など、社会での実例を題材として、「データを読む、説明する、扱う」といった数理・データサイエンス・ＡＩの基本的な活用法に関するもの」の内容を含む授業科目
B68: 授業科目 | E68: 単位数 | F68: 必須 | G68: 2-1 | H68: 2-2 | I68: 2-3 | J68: 授業科目 | O68: 単位数 | P68: 必須 | Q68: 2-1 | R68: 2-2 | S68: 2-3
B69: AIリテラシー入門 | E69: 2 | F69: ○ | G69: ○ | H69: ○ | I69: ○
A77: ⑨ 選択「４．オプション」の内容を含む授業科目
B78: 授業科目 | F78: 選択項目 | J78: 授業科目 | P78: 選択項目
B79: AIリテラシー入門 | F79: 4‐2アルゴリズム基礎
B80: AIリテラシー入門 | F80: 4‐4時系列データ解析
B81: AIリテラシー入門 | F81: 4‐5テキスト解析
B82: AIリテラシー入門 | F82: 4‐6画像解析
A87: ⑩ プログラムを構成する授業の内容
B88: 授業に含まれている内容・要素 | D88: 講義内容
B89: （１）現在進行中の社会変化（第４次産業革命、Society 5.0、データ駆動型社会等）に深く寄与しているものであり、それが自らの生活と密接に結びついている | C89: 1-1 | D89: ・変化の激しい現代社会においてなぜAIが必要とされるのか（ビッグデータ、IoT、AI、ロボット、第4次産業革命、Society 5.0、データ駆動型社会、データを起点としたものの見方、人間の知的活動を起点としたものの見方） 「AIリテラシー入門」 （第１回）
C90: 1-6 | D90: ・データや人工知能の活用（AI等を活用した新しいビジネスモデル、AI最新技術の活用例） 「AIリテラシー入門」（ 第４回） ・人工知能の活用②：人間に勝利する人工知能（AI等を活用した新しいビジネスモデル、AI最新技術の活用例） 「AIリテラシー入門」 （第12回） ・人工知能の活用③：人間の言葉を理解する人工知能（AI等を活用した新しいビジネスモデル、AI最新技術の活用例） 「AIリテラシー入門」 （第13回） ・人工知能の活用④：人間を楽しませる人工知能（AI等を活用した新しいビジネスモデル、AI最新技術の活用例） 「AIリテラシー入門」 （第14回） ・人工知能の活用⑤：人工知能で未来はどこまで予測できるのか（AI等を活用した新しいビジネスモデル、AI最新技術の活用例） 「AIリテラシー入門」 （第15回）
B91: （２）「社会で活用されているデータ」や「データの活用領域」は非常に広範囲であって、日常生活や社会の課題を解決する有用なツールになり得るもの | C91: 1-2 | D91: ・社会で活用されるデータの種類（調査・実験・ログデータ、1次・2次データ、データのメタ化、構造化・非構造化データ、データ作成、データのオープン化） 「AIリテラシー入門」 （第２回） ・データの活用②：収集したデータを用いて予測する（調査・実験データ、1次・2次データ） 「AIリテラシー入門」 （第７回） ・データの活用④：確率で表されたデータをきちんと読む（調査データ、1次・2次データ） 「AIリテラシー入門」 （第９回） ・データの活用⑤：相関関係の背後にある因果関係をさぐる（調査データ、1次・2次データ） 「AIリテラシー入門」 （第10回）
C92: 1-3 | D92: ・データや人工知能の活用（データ・AI活用領域の広がり、仮説検証、知識発見、原因究明） 「AIリテラシー入門」 （第４回） ・データの活用②：収集したデータを用いて予測する（仮説検証、原因究明） 「AIリテラシー入門」 （第７回） ・人工知能の活用①：自ら学ぶ人工知能の仕組み（データ・AI活用領域の広がり） 「AIリテラシー入門」 （第11回）
B93: （３）様々なデータ利活用の現場におけるデータ利活用事例が示され、様々な適用領域（流通、製造、金融、サービス、インフラ、公共、ヘルスケア等）の知見と組み合わせることで価値を創出するもの | C93: 1-4 | D93: ・人工知能ではデータがどのように処理されているのか（データ解析、データ可視化） 「AIリテラシー入門」 （第３回） ・人工知能の活用①：自ら学ぶ人工知能の仕組み（データ解析、特化型AIと汎用AI、今のAIで出来ることと出来ないこと、AIとビッグデータ） 「AIリテラシー入門」 （第11回） ・人工知能の活用②：人間に勝利する人工知能（データ解析、特化型AIと汎用AI、今のAIで出来ることと出来ないこと、AIとビッグデータ） 「AIリテラシー入門」 （第12回） ・人工知能の活用③：人間の言葉を理解する人工知能（非構造化データ処理） 「AIリテラシー入門」 （第13回） ・人工知能の活用④：人間を楽しませる人工知能（非構造化データ処理、認識技術、ルールベース、自動化技術） 「AIリテラシー入門」 （第14回）
C94: 1-5 | D94: ・データや人工知能の活用（データサイエンスのサイクル、流通業界・製造業界・インフラ・公共におけるデータ・AI利活用事例紹介） 「AIリテラシー入門」 （第４回） ・人工知能の活用②：人間に勝利する人工知能（流通、製造、金融、サービス、インフラ、公共、ヘルスケア等におけるデータ・AI利活用事例紹介） 「AIリテラシー入門」 （第12回） ・人工知能の活用③：人間の言葉を理解する人工知能（流通、製造、金融、サービス、インフラ、公共、ヘルスケア等におけるデータ・AI利活用事例紹介） 「AIリテラシー入門」 （第13回） ・人工知能の活用④：人間を楽しませる人工知能（流通、製造、金融、サービス、インフラ、公共、ヘルスケア等におけるデータ・AI利活用事例紹介） 「AIリテラシー入門」 （第14回） ・人工知能の活用⑤：人工知能で未来はどこまで予測できるのか（流通、製造、金融、サービス、インフラ、公共、ヘルスケア等におけるデータ・AI利活用事例紹介） 「AIリテラシー入門」 （第15回）
B95: （４）活用に当たっての様々な留意事項（ELSI、個人情報、データ倫理、ＡＩ社会原則等）を考慮し、情報セキュリティや情報漏洩等、データを守る上での留意事項への理解をする | C95: 3-1 | D95: ・データや人工知能を扱う注意点ならびにセキュリティ（ELSI、個人情報保護、EU一般データ保護規則、忘れられる権利、オプトアウト、データ倫理：データのねつ造、改ざん、盗用、プライバシー保護、AI社会原則、データバイアス、データ・AI活用における負の事例紹介） 「AIリテラシー入門」 （第５回） ・データの活用④：確率で表されたデータをきちんと読む（データバイアス、アルゴリズムバイアス） 「AIリテラシー入門」 （第９回） ・データの活用⑤：相関関係の背後にある因果関係をさぐる（データの改ざん、データバイアス、データ・AI活用における負の事例紹介） 「AIリテラシー入門」 （第10回）
C96: 3-2 | D96: ・データや人工知能を扱う注意点ならびにセキュリティ（情報セキュリティ、匿名加工情報、暗号化、パスワード、悪意ある情報搾取、セキュリティ事故の事例紹介） 「AIリテラシー入門」 （第５回）
...

Sheet 様式２ 履修者等数の実績
AQ1: 様式２
AL2: 大学等名 | AM2: ='様式１ プログラムを構成する授業科目'!C2 -> 広島経済大学
A3: プログラムの履修者数等の実績について
A5: ①プログラム開設年度 | C5: 令和４ | E5: 年度
A7: ②履修者・修了者の実績
B9: 学部・学科名称 | C9: 学生数 | D9: 入学 定員 | E9: 収容 定員 | F9: 令和4年度 | L9: 令和3年度 | R9: 令和2年度 | X9: 令和元年度 | AD9: 平成30年度 | AJ9: 平成29年度 | AP9: 履修者数 合計 | AQ9: 履修率
F10: 履修者数 | I10: 修了者数 | L10: 履修者数 | O10: 修了者数 | R10: 履修者数 | U10: 修了者数 | X10: 履修者数 | AA10: 修了者数 | AD10: 履修者数 | AG10: 修了者数 | AJ10: 履修者数 | AM10: 修了者数
F11: 合計 | G11: 男性 | H11: 女性 | I11: 合計 | J11: 男性 | K11: 女性 | L11: 合計 | M11: 男性 | N11: 女性 | O11: 合計 | P11: 男性 | Q11: 女性 | R11: 合計 | S11: 男性 | T11: 女性 | U11: 合計 | V11: 男性 | W11: 女性 | X11: 合計 | Y11: 男性 | Z11: 女性 | AA11: 合計 | AB11: 男性 | AC11: 女性 | AD11: 合計 | AE11: 男性 | AF11: 女性 | AG11: 合計 | AH11: 男性 | AI11: 女性 | AJ11: 合計 | AK11: 男性 | AL11: 女性 | AM11: 合計 | AN11: 男性 | AO11: 女性
B12: 経済学部 経済学科 | C12: 1241 | D12: 330 | E12: 1320 | F12: 49 | I12: 36 | L12: =M12+N12 -> 0 | O12: =P12+Q12 -> 0 | R12: =S12+T12 -> 0 | U12: =V12+W12 -> 0 | X12: =Y12+Z12 -> 0 | AA12: =AB12+AC12 -> 0 | AD12: =AE12+AF12 -> 0 | AG12: =AH12+AI12 -> 0 | AJ12: =AK12+AL12 -> 0 | AM12: =AN12+AO12 -> 0 | AP12: =F12+L12+R12+X12+AD12+AJ12 -> 49 | AQ12: =AP12/E12 -> 0.037121212
B13: 経済学部 経営学科 | C13: 33 | F13: =G13+H13 -> 0 | I13: =J13+K13 -> 0 | L13: =M13+N13 -> 0 | O13: =P13+Q13 -> 0 | R13: =S13+T13 -> 0 | U13: =V13+W13 -> 0 | X13: =Y13+Z13 -> 0 | AA13: =AB13+AC13 -> 0 | AD13: =AE13+AF13 -> 0 | AG13: =AH13+AI13 -> 0 | AJ13: =AK13+AL13 -> 0 | AM13: =AN13+AO13 -> 0 | AP13: =F13+L13+R13+X13+AD13+AJ13 -> 0 | AQ13: =AP13/E13 -> #DIV/0!
B14: 経済学部 ビジネス情報学科 | C14: 11 | F14: =G14+H14 -> 0 | I14: =J14+K14 -> 0 | L14: =M14+N14 -> 0 | O14: =P14+Q14 -> 0 | R14: =S14+T14 -> 0 | U14: =V14+W14 -> 0 | X14: =Y14+Z14 -> 0 | AA14: =AB14+AC14 -> 0 | AD14: =AE14+AF14 -> 0 | AG14: =AH14+AI14 -> 0 | AJ14: =AK14+AL14 -> 0 | AM14: =AN14+AO14 -> 0 | AP14: =F14+L14+R14+X14+AD14+AJ14 -> 0 | AQ14: =AP14/E14 -> #DIV/0!
B15: 経済学部 メディアビジネス学科 | C15: 11 | F15: =G15+H15 -> 0 | I15: =J15+K15 -> 0 | L15: =M15+N15 -> 0 | O15: =P15+Q15 -> 0 | R15: =S15+T15 -> 0 | U15: =V15+W15 -> 0 | X15: =Y15+Z15 -> 0 | AA15: =AB15+AC15 -> 0 | AD15: =AE15+AF15 -> 0 | AG15: =AH15+AI15 -> 0 | AJ15: =AK15+AL15 -> 0 | AM15: =AN15+AO15 -> 0 | AP15: =F15+L15+R15+X15+AD15+AJ15 -> 0 | AQ15: =AP15/E15 -> #DIV/0!
B16: 経済学部 スポーツ経営学科 | C16: 3 | F16: =G16+H16 -> 0 | I16: =J16+K16 -> 0 | L16: =M16+N16 -> 0 | O16: =P16+Q16 -> 0 | R16: =S16+T16 -> 0 | U16: =V16+W16 -> 0 | X16: =Y16+Z16 -> 0 | AA16: =AB16+AC16 -> 0 | AD16: =AE16+AF16 -> 0 | AG16: =AH16+AI16 -> 0 | AJ16: =AK16+AL16 -> 0 | AM16: =AN16+AO16 -> 0 | AP16: =F16+L16+R16+X16+AD16+AJ16 -> 0 | AQ16: =AP16/E16 -> #DIV/0!
B17: 経営学部 経営学科 | C17: 1191 | D17: 310 | E17: 1240 | F17: 27 | I17: 16 | L17: =M17+N17 -> 0 | O17: =P17+Q17 -> 0 | R17: =S17+T17 -> 0 | U17: =V17+W17 -> 0 | X17: =Y17+Z17 -> 0 | AA17: =AB17+AC17 -> 0 | AD17: =AE17+AF17 -> 0 | AG17: =AH17+AI17 -> 0 | AJ17: =AK17+AL17 -> 0 | AM17: =AN17+AO17 -> 0 | AP17: =F17+L17+R17+X17+AD17+AJ17 -> 27 | AQ17: =AP17/E17 -> 0.021774194
B18: 経営学部 スポーツ経営学科 | C18: 264 | D18: 70 | E18: 280 | F18: 8 | I18: 4 | L18: =M18+N18 -> 0 | O18: =P18+Q18 -> 0 | R18: =S18+T18 -> 0 | U18: =V18+W18 -> 0 | X18: =Y18+Z18 -> 0 | AA18: =AB18+AC18 -> 0 | AD18: =AE18+AF18 -> 0 | AG18: =AH18+AI18 -> 0 | AJ18: =AK18+AL18 -> 0 | AM18: =AN18+AO18 -> 0 | AP18: =F18+L18+R18+X18+AD18+AJ18 -> 8 | AQ18: =AP18/E18 -> 0.028571429
B19: メディアビジネス学部 ビジネス情報学科 | C19: 266 | D19: 80 | E19: 320 | F19: 42 | I19: 34 | L19: =M19+N19 -> 0 | O19: =P19+Q19 -> 0 | R19: =S19+T19 -> 0 | U19: =V19+W19 -> 0 | X19: =Y19+Z19 -> 0 | AA19: =AB19+AC19 -> 0 | AD19: =AE19+AF19 -> 0 | AG19: =AH19+AI19 -> 0 | AJ19: =AK19+AL19 -> 0 | AM19: =AN19+AO19 -> 0 | AP19: =F19+L19+R19+X19+AD19+AJ19 -> 42 | AQ19: =AP19/E19 -> 0.13125
B20: メディアビジネス学部 メディアビジネス学科 | C20: 233 | D20: 60 | E20: 240 | F20: 5 | I20: 4 | L20: =M20+N20 -> 0 | O20: =P20+Q20 -> 0 | R20: =S20+T20 -> 0 | U20: =V20+W20 -> 0 | X20: =Y20+Z20 -> 0 | AA20: =AB20+AC20 -> 0 | AD20: =AE20+AF20 -> 0 | AG20: =AH20+AI20 -> 0 | AJ20: =AK20+AL20 -> 0 | AM20: =AN20+AO20 -> 0 | AP20: =F20+L20+R20+X20+AD20+AJ20 -> 5 | AQ20: =AP20/E20 -> 0.020833333
F21: =G21+H21 -> 0 | I21: =J21+K21 -> 0 | L21: =M21+N21 -> 0 | O21: =P21+Q21 -> 0 | R21: =S21+T21 -> 0 | U21: =V21+W21 -> 0 | X21: =Y21+Z21 -> 0 | AA21: =AB21+AC21 -> 0 | AD21: =AE21+AF21 -> 0 | AG21: =AH21+AI21 -> 0 | AJ21: =AK21+AL21 -> 0 | AM21: =AN21+AO21 -> 0 | AP21: =F21+L21+R21+X21+AD21+AJ21 -> 0 | AQ21: =AP21/E21 -> #DIV/0!
F22: =G22+H22 -> 0 | I22: =J22+K22 -> 0 | L22: =M22+N22 -> 0 | O22: =P22+Q22 -> 0 | R22: =S22+T22 -> 0 | U22: =V22+W22 -> 0 | X22: =Y22+Z22 -> 0 | AA22: =AB22+AC22 -> 0 | AD22: =AE22+AF22 -> 0 | AG22: =AH22+AI22 -> 0 | AJ22: =AK22+AL22 -> 0 | AM22: =AN22+AO22 -> 0 | AP22: =F22+L22+R22+X22+AD22+AJ22 -> 0 | AQ22: =AP22/E22 -> #DIV/0!
F23: =G23+H23 -> 0 | I23: =J23+K23 -> 0 | L23: =M23+N23 -> 0 | O23: =P23+Q23 -> 0 | R23: =S23+T23 -> 0 | U23: =V23+W23 -> 0 | X23: =Y23+Z23 -> 0 | AA23: =AB23+AC23 -> 0 | AD23: =AE23+AF23 -> 0 | AG23: =AH23+AI23 -> 0 | AJ23: =AK23+AL23 -> 0 | AM23: =AN23+AO23 -> 0 | AP23: =F23+L23+R23+X23+AD23+AJ23 -> 0 | AQ23: =AP23/E23 -> #DIV/0!
F24: =G24+H24 -> 0 | I24: =J24+K24 -> 0 | L24: =M24+N24 -> 0 | O24: =P24+Q24 -> 0 | R24: =S24+T24 -> 0 | U24: =V24+W24 -> 0 | X24: =Y24+Z24 -> 0 | AA24: =AB24+AC24 -> 0 | AD24: =AE24+AF24 -> 0 | AG24: =AH24+AI24 -> 0 | AJ24: =AK24+AL24 -> 0 | AM24: =AN24+AO24 -> 0 | AP24: =F24+L24+R24+X24+AD24+AJ24 -> 0 | AQ24: =AP24/E24 -> #DIV/0!
F25: =G25+H25 -> 0 | I25: =J25+K25 -> 0 | L25: =M25+N25 -> 0 | O25: =P25+Q25 -> 0 | R25: =S25+T25 -> 0 | U25: =V25+W25 -> 0 | X25: =Y25+Z25 -> 0 | AA25: =AB25+AC25 -> 0 | AD25: =AE25+AF25 -> 0 | AG25: =AH25+AI25 -> 0 | AJ25: =AK25+AL25 -> 0 | AM25: =AN25+AO25 -> 0 | AP25: =F25+L25+R25+X25+AD25+AJ25 -> 0 | AQ25: =AP25/E25 -> #DIV/0!
F26: =G26+H26 -> 0 | I26: =J26+K26 -> 0 | L26: =M26+N26 -> 0 | O26: =P26+Q26 -> 0 | R26: =S26+T26 -> 0 | U26: =V26+W26 -> 0 | X26: =Y26+Z26 -> 0 | AA26: =AB26+AC26 -> 0 | AD26: =AE26+AF26 -> 0 | AG26: =AH26+AI26 -> 0 | AJ26: =AK26+AL26 -> 0 | AM26: =AN26+AO26 -> 0 | AP26: =F26+L26+R26+X26+AD26+AJ26 -> 0 | AQ26: =AP26/E26 -> #DIV/0!
F27: =G27+H27 -> 0 | I27: =J27+K27 -> 0 | L27: =M27+N27 -> 0 | O27: =P27+Q27 -> 0 | R27: =S27+T27 -> 0 | U27: =V27+W27 -> 0 | X27: =Y27+Z27 -> 0 | AA27: =AB27+AC27 -> 0 | AD27: =AE27+AF27 -> 0 | AG27: =AH27+AI27 -> 0 | AJ27: =AK27+AL27 -> 0 | AM27: =AN27+AO27 -> 0 | AP27: =F27+L27+R27+X27+AD27+AJ27 -> 0 | AQ27: =AP27/E27 -> #DIV/0!
F28: =G28+H28 -> 0 | I28: =J28+K28 -> 0 | L28: =M28+N28 -> 0 | O28: =P28+Q28 -> 0 | R28: =S28+T28 -> 0 | U28: =V28+W28 -> 0 | X28: =Y28+Z28 -> 0 | AA28: =AB28+AC28 -> 0 | AD28: =AE28+AF28 -> 0 | AG28: =AH28+AI28 -> 0 | AJ28: =AK28+AL28 -> 0 | AM28: =AN28+AO28 -> 0 | AP28: =F28+L28+R28+X28+AD28+AJ28 -> 0 | AQ28: =AP28/E28 -> #DIV/0!
F29: =G29+H29 -> 0 | I29: =J29+K29 -> 0 | L29: =M29+N29 -> 0 | O29: =P29+Q29 -> 0 | R29: =S29+T29 -> 0 | U29: =V29+W29 -> 0 | X29: =Y29+Z29 -> 0 | AA29: =AB29+AC29 -> 0 | AD29: =AE29+AF29 -> 0 | AG29: =AH29+AI29 -> 0 | AJ29: =AK29+AL29 -> 0 | AM29: =AN29+AO29 -> 0 | AP29: =F29+L29+R29+X29+AD29+AJ29 -> 0 | AQ29: =AP29/E29 -> #DIV/0!
F30: =G30+H30 -> 0 | I30: =J30+K30 -> 0 | L30: =M30+N30 -> 0 | O30: =P30+Q30 -> 0 | R30: =S30+T30 -> 0 | U30: =V30+W30 -> 0 | X30: =Y30+Z30 -> 0 | AA30: =AB30+AC30 -> 0 | AD30: =AE30+AF30 -> 0 | AG30: =AH30+AI30 -> 0 | AJ30: =AK30+AL30 -> 0 | AM30: =AN30+AO30 -> 0 | AP30: =F30+L30+R30+X30+AD30+AJ30 -> 0 | AQ30: =AP30/E30 -> #DIV/0!
F31: =G31+H31 -> 0 | I31: =J31+K31 -> 0 | L31: =M31+N31 -> 0 | O31: =P31+Q31 -> 0 | R31: =S31+T31 -> 0 | U31: =V31+W31 -> 0 | X31: =Y31+Z31 -> 0 | AA31: =AB31+AC31 -> 0 | AD31: =AE31+AF31 -> 0 | AG31: =AH31+AI31 -> 0 | AJ31: =AK31+AL31 -> 0 | AM31: =AN31+AO31 -> 0 | AP31: =F31+L31+R31+X31+AD31+AJ31 -> 0 | AQ31: =AP31/E31 -> #DIV/0!
B32: 合 計 | C32: =SUM(C12:C31) -> 3253 | D32: =SUM(D12:D31) -> 850 | E32: =SUM(E12:E31) -> 3400 | F32: =SUM(F12:F31) -> 131 | G32: =SUM(G12:G31) -> 0 | H32: =SUM(H12:H31) -> 0 | I32: =SUM(I12:I31) -> 94 | J32: =SUM(J12:J31) -> 0 | ... AP32: =SUM(AP12:AP31) -> 131 | AQ32: =AP32/E32 -> 0.038529412

Sheet 様式３ 教育の質・履修者数を向上させるための体制・計画
I1: 様式３
G2: 大学等名 | H2: ='様式１ プログラムを構成する授業科目'!C2 -> 広島経済大学
A4: 教育の質・履修者数を向上させるための体制・計画について
A6: ① | B6: 全学の教員数 | C6: (常勤） | E6: 103 | F6: 人 | G6: （非常勤） | H6: 109 | I6: 人
A8: ② | B8: プログラムの授業を教えている教員数 | H8: 3 | I8: 人
A10: ③ | B10: プログラムの運営責任者
B11: （責任者名） | C11: 北野 尚人 | G11: （役職名） | H11: メディアビジネス学部学部長・教授
A13: ④ | B13: プログラムを改善・進化させるための体制（委員会・組織等）
B14: データサイエンス教育プログラム推進ワーキンググループ
B16: （責任者名） | C16: 丹羽 啓一 | G16: （役職名） | H16: メディアビジネス学部ビジネス情報学科主任・教授
A18: ⑤ | B18: プログラムを改善・進化させるための体制を定める規則名称
B19: 数理・データサイエンス・ＡＩ教育に関するガイドライン
A21: ⑥ | B21: 体制の目的
B22: 広島経済大学に在籍するすべての学生がリテラシーレベルの数理・データサイエンス・AI教育を学ぶことのできる環境を整備し、身につけた数理・データサイエンス・AIに関する能力（知識とスキル）を、学生が卒業後の個々の実務現場で発揮できることを目指し、学部・学科、部署間の枠を超えて、全学的な取り組みを行うことを目的として組織されたワーキンググループとする。 ワーキンググルーブは主に教育プログラムの企画・立案、改善・進化を担当し、プログラムを構成する科目の設置を管轄する教養教育部会と科目担当教員が所属するメディアビジネス学部、学務センター教務課が中心となって、目的の達成を目指す。 自己点検評価は、既存組織である自己点検・評価委員会が担当する。それぞれの役割分担が明確であり、PDCAサイクルを機能させる組織体制となっている。
A34: ⑦ | B34: 具体的な構成員
B35: データサイエンス教育プログラム推進ワーキンググループ 2023年度メンバー ・メディアビジネス学部学部長・教授 北野 尚人 ・メディアビジネス学部ビジネス情報学科主任・教授 丹羽 啓一 ・プログラム構成科目担当教員 教養教育部・准教授 青谷 章弘 ・学務センター教務課課長 栗田 宰子
A48: ⑧ | B48: 履修者数・履修率の向上に向けた計画 ※様式１の「履修必須の有無」で「計画がある」としている場合は詳細について記載すること
B49: 令和４年度実績 | C49: ='様式２ 履修者等数の実績'!AQ32 -> 0.038529412 | E49: 令和５年度予定 | F49: 0.1 | H49: 令和６年度予定 | I49: 0.19
B50: 令和７年度予定 | C50: 0.3 | E50: 令和８年度予定 | F50: 0.51 | H50: 収容定員（名） | I50: ='様式２ 履修者等数の実績'!E32 -> 3400
B51: 具体的な計画
B52: 令和３（2021）年度 ワーキンググループを設置、条件を満たす科目内容の検討を開始する 令和４（2022）年度 新規科目設置・開講（後期２単位）・履修者実績131名 令和５（2023）年度 履修者目標200名・全学履修必修化に向けた検討を開始する 令和６（2024）年度 履修者目標300名・オンデマンド授業一部導入を検討する 令和７（2025）年度 履修者目標400名・オンデマンド授業導入、ハイブリット型での開講を目指す 令和８（2026）年度 令和８(2026)年度新入生(850名)から履修必修化スタート予定
A65: ⑨ | B65: 学部・学科に関係なく希望する学生全員が受講可能となるような必要な体制・取組等
B66: 全学部対象の共通科目の基礎教養科目群に設置し、全学生が受講できるカリキュラムとしている。時間割についても、可能な限り１年次の必修科目と重複しないよう調整し、多くの学生が受講可能な時間に配置している。予定する教室の定員を上回る履修希望があった場合は、教室を変更して希望者全員が受講できるよう対応する。さらに多くの履修希望が合った場合は、オンデマンド授業の前倒し実施など臨機応変に対応する予定である。
A79: ⑩ | B79: できる限り多くの学生が履修できるような具体的な周知方法・取組
B80: 令和４(2022)年度は、新規科目（後期科目）として、入学後のガイダンスおよび前期・後期各履修ガイダンスで紹介することで履修を促し、前期ガイダンス終了後に84名、後期ガイダンス終了後には47名が履修登録し、初年度の最終的な履修登録者は131名となった。授業の様子は本学ホームページＴｏｐｉｃｓで紹介し、学内外への周知を図った。 （https://www.hue.ac.jp/news/topics/b0b5mu000000k882.html） 令和５(2023)年度は、プログラムの目的、授業内容、今年度の様子などの詳細も紹介動画に加え、在校生には履修ガイダンスで、新入生には入学後のガイダンスで周知した。前期履修登録時点で、昨年度の履修者数を超える142名が登録している。
A93: ⑪ | B93: できる限り多くの学生が履修・修得できるようなサポート体制
B94: 多くの学生が履修できるように、特に低学年配当の必修科目と出来るだけ重複しない時間帯にこの科目を設置している。本学では、令和３(2021)年度入学生から順次、ノートパソコン必携化を行っており、従来の席数が限られた情報処理教室の利用ではなく、一般教室での開講が可能となったことによっても、より多くの学生が履修できる環境が整った。 また、 各授業回でアンケート、小テスト等を実施し履修生の理解度を確認して、翌回の授業でフォーロアップすることで、より多くの履修者が単位修得に向けて理解が深まるよう工夫している。
A107: ⑫ | B107: 授業時間内外で学習指導、質問を受け付ける具体的な仕組み
B108: 本学のLearning Management SystemのQ&A機能や学内mailを使用した質問の受付とそのSystemを活用した回答の提示を行うことが出来る。文章での回答が難しい場合は、Microsoft Teamsを活用した回答機会を設けたり、授業の前後に回答を説明する時間を設ける予定である。 また、教員は週に１回は必ず研究室に在室している時間（オフィスアワー）を設けて学生にも時間を公開しているため、その時間に質問等に対応することも可能である。 さらに、本学では、教育・学習支援センターラーニングサポートコーナーに情報スチューデントアシスタント（SA）を配置しており、申し込みによって学習相談を受けることができる。SAでは対応が難しい内容は、担当教員につなぐ体制も整えている。

Sheet 様式４　自己点検・評価
I1: 様式４
H2: 大学等名 | I2: ='様式１ プログラムを構成する授業科目'!C2 -> 広島経済大学
A3: 自己点検・評価について
A5: ① | B5: プログラムの自己点検・評価を行う体制（委員会・組織等）
B6: 自己点検・評価委員会
D8: （責任者名） | E8: 石田 優子 | G8: （役職名） | H8: 学長 ・ 自己点検・評価委員会委員長
A10: ② | B10: 自己点検・評価体制における意見等
B11: 自己点検・評価の視点 | E11: 自己点検・評価体制における意見・結果・改善に向けた取組等
B12: 学内からの視点
C13: プログラムの履修・修得状況 | E13: 本プログラムを構成する「AIリテラシー入門」の開講初年度の履修生は、予定（120名）を上回る131名となった。また、全学部全学科からの履修者を得てのスタートとなった。新入生向け履修ガイダンス及び在校生向けに学期毎に行う履修ガイダンスなどでの周知が功を奏したと判断できる。 修得状況については、131名の履修者に対して単位修得者が94名となり、目標の8割に届いていない。教授方法、授業の難易度についての検討が必要であると考えられる。
C14: 学修成果 | E14: 学修成果について、全授業終了後の学内定期試験の結果を分析することの他、受講後の理解度アンケート (演習問題を含む) の回答、全学的に行われている授業アンケートの回答などのデータを分析することで、各講ならびに授業全体としての受講生の理解度について把握している。 また、この授業を受けたことによって興味をもつに至った授業内容を把握するとともに、上位学年になった時にさらに深く学んでみたい内容の把握に努めている。 収集したデータの分析と今後の授業内容の検討に関しては、授業担当者だけでなくデータサイエンス教育プログラム推進ワーキンググループでも行っており、自己点検・評価委員会での評価と合わせて、改善につなげていく必要がある。
C15: 学生アンケート等を通じた学生の内容の理解度 | E15: 受講前アンケートの結果から各講の授業内容に関する受講生の前知識を把握し、授業内容と難易度の調整に活用している。受講後の理解度アンケートの結果からは、各講の授業内容において受講生が得意な項目、不得意な項目を把握し、特に不得意な項目に関しては、わかりやすい補助教材を準備するなど授業の理解度の向上に努めている。 また、全学的に行われている授業アンケートの結果からは、学生の授業への参加度合いによって分類されたデータを分析することで、授業に積極的に参加していないと思われる学生の割合を把握するとともにそのような学生に対しても魅力的な授業にできるよう、内容の検討につなげていく必要がある。
C16: 学生アンケート等を通じた後輩等他の学生への推奨度 | E16: 最終講に実施した受講後の理解度アンケート (演習問題を含む) において友人・後輩に本授業の履修を推奨するかどうかを問うことで、その度合いを把握している。初年度は76．3％が推奨するという肯定的な回答であった。 また、教育・学習支援センターに配置している情報スチューデントアシスタント（SA）のもとに、学習相談に訪れた学生に対して本授業の履修を推奨する取り組みを実施している。今後も本授業の推奨度を高めるためには、より魅力的な授業を行うことが前提となるため、SAを通じた授業に対する学生の生の声やニーズも捉えながら本プログラムのブラッシュアップを図っていく必要がある。
C17: 全学的な履修者数、履修率向上に向けた計画の達成・進捗状況 | E17: 本プログラムを構成する「AIリテラシー入門」の履修者数や履修率の向上に向けて、まず学期毎に実施している履修ガイダンスにおいて本授業のことを特別に取り上げ、プログラム設置、科目設置の目的である「デジタル時代に必要な数理・データサイエンス・AIの基礎などの必要な力をすべての国民が育み、あらゆる分野で人材が活躍する環境を構築する」ことを説明し、履修を促す取り組みを行っている。初年度は目標履修者数を上回る履修登録があった。 さらに、２年目に向けて、本授業の授業内容や授業風景等の取材記事を本学のホームページNews & Topicsに掲載し、本授業の認知度を高めることで履修者数の増加を促した。 また、今年度からは、令和8（2026)年の履修必修化に向けて検討を始める。
B18: 学外からの視点
C19: 教育プログラム修了者の進路、活躍状況、企業等の評価 | E19: プログラムを修了した卒業生の進路は、卒業時にキャリアセンターに提出する最終進路報告書によって確認することができる。 また、卒業生の就職先企業（卒業3年目の卒業生を対象）に対して、キャリアセンターと教育・学習支援センターが毎年協同で行っている「企業アンケート」の活用やキャリアセンターに来訪のあった企業の採用担当者にヒアリングをするなどして、本プログラムと本プログラムの受講生の活躍状況、評価を確認する予定である。
C20: 産業界からの視点を含めた教育プログラム内容・手法等への意見 | E20: 本プログラムの受講生の就職先となっている企業や本学の正課科目である「インターンシップ」に協力して頂いている企業・団体に対して本プログラムに関するアンケート調査を行い、産業界におけるニーズの把握に努めるとともに本プログラムに対する企業からの要望なども併せて意見聴取することで本プログラムの改善・進化に役立てる予定である。
B21: 数理・データサイエンス・ＡＩを「学ぶ楽しさ」「学ぶことの意義」を理解させること | E21: 大学で行われている基礎研究を紹介するだけでなく、映像資料や画像資料を用いて企業の適用事例を紹介することでデータサイエンスやAIが受講生の身近なものとして認識できるようにするとともに、データサイエンスやAIのことを学ぶことが将来においてどのように役立つかを理解できるよう工夫している。 また、データサイエンスやAIの手法に触れて楽しむ目的で授業内に演習時間を設けて、実際に計算を行ったりプログラムを動かしてみることで能動的に学ぶ仕組みも取り入れている。
B22: 内容・水準を維持・向上しつつ、より「分かりやすい」授業とすること | E22: 本授業の担当者間による打ち合わせを頻繁に行うことで、受講生の傾向を把握し、授業内容や授業難易度を適切に設定しようとしている。 「より分かりやすく」の観点から、企業の実データをもとにした分析・ワークや直近の話題が反映されたデータなどを取り入れ学生が興味を持つ内容も盛り込むことも検討している。 また、今後、各学部からの意見、要望なども取り入れ、本学の特色を活かした授業内容とすることも検討していきたい。 各種アンケートの結果を、データサイエンス教育プログラム推進ワーキンググループにて分析し、学生にとってより分かりやすく、興味の深まる授業となるよう内容や実施方法を改善・進化させていくことが重要である。
