Workbook

Sheet 様式１-1　プログラムを構成する授業科目
R1: 様式１-１ | T1: 「学部・学科によって、修了要件は相違する」場合は、本シートを複製の上＜様式１－〇＞と枝番号を付してください
B2: 大学等名 | C2: 弓削商船高等専門学校
B3: プログラム名 | C3: 数理・データサイエンス・AI教育プログラム
A5: プログラムを構成する授業科目について
A7: ① 対象となる学部・学科名称 | J7: ② 教育プログラムの修了要件 | K7: 学部・学科によって、修了要件は相違する
B9: 商船学科
A12: ③ 修了要件
B13: プログラムを構成する「情報処理１」「情報処理２」を修得していること。 | V13: 【プルダウンリスト】
V14: 令和４年度以前より、履修することが必須のプログラムとして実施
V15: 令和７年度までに履修必須とする計画
V16: 令和８年度以降に履修必須とする計画、又は未定
B20: 必要最低単位数 | C20: 3 | E20: 単位 | J20: 履修必須の有無 | K20: 令和４年度以前より、履修することが必須のプログラムとして実施
A22: ④ 現在進行中の社会変化（第４次産業革命、Society 5.0、データ駆動型社会等）に深く寄与しているものであり、それが自らの生活と密接に結びついている」の内容を含む授業科目
B24: 授業科目 | F24: 単位数 | G24: 必須 | H24: 1-1 | I24: 1-6 | J24: 授業科目 | P24: 単位数 | Q24: 必須 | R24: 1-1 | S24: 1-6
B25: 情報処理2 | F25: 1 | G25: ○ | H25: ○ | I25: ○
A33: ⑤ 「社会で活用されているデータ」や「データの活用領域」は非常に広範囲であって、日常生活や社会の課題を解決する有用なツールになり得るもの」の内容を含む授業科目
B35: 授業科目 | F35: 単位数 | G35: 必須 | H35: 1-2 | I35: 1-3 | J35: 授業科目 | P35: 単位数 | Q35: 必須 | R35: 1-2 | S35: 1-3
B36: 情報処理1 | F36: 2 | G36: ○ | H36: ○ | I36: ○
A44: ⑥ 「様々なデータ利活用の現場におけるデータ利活用事例が示され、様々な適用領域（流通、製造、金融、サービス、インフラ、公共、ヘルスケア等）の知見と組み合わせることで価値を創出するもの」の内容を含む授業科目
B46: 授業科目 | F46: 単位数 | G46: 必須 | H46: 1-4 | I46: 1-5 | J46: 授業科目 | P46: 単位数 | Q46: 必須 | R46: 1-4 | S46: 1-5
B47: 情報処理2 | F47: 1 | G47: ○ | H47: ○ | I47: ○
A55: ⑦ 「活用に当たっての様々な留意事項（ELSI、個人情報、データ倫理、ＡＩ社会原則等）を考慮し、情報セキュリティや情報漏洩等、データを守る上での留意事項への理解をする」の内容を含む授業科目
B57: 授業科目 | F57: 単位数 | G57: 必須 | H57: 3-1 | I57: 3-2 | J57: 授業科目 | P57: 単位数 | Q57: 必須 | R57: 3-1 | S57: 3-2
B58: 情報処理1 | F58: 2 | G58: ○ | H58: ○ | I58: ○
A66: ⑧ 「実データ・実課題（学術データ等を含む）を用いた演習など、社会での実例を題材として、「データを読む、説明する、扱う」といった数理・データサイエンス・ＡＩの基本的な活用法に関するもの」の内容を含む授業科目
B68: 授業科目 | E68: 単位数 | F68: 必須 | G68: 2-1 | H68: 2-2 | I68: 2-3 | J68: 授業科目 | O68: 単位数 | P68: 必須 | Q68: 2-1 | R68: 2-2 | S68: 2-3
B69: 情報処理2 | E69: 1 | F69: ○ | G69: ○ | H69: ○ | I69: ○
A77: ⑨ 選択「４．オプション」の内容を含む授業科目
B78: 授業科目 | F78: 選択項目 | J78: 授業科目 | P78: 選択項目
A87: ⑩ プログラムを構成する授業の内容
B88: 授業に含まれている内容・要素 | D88: 講義内容
B89: （１）現在進行中の社会変化（第４次産業革命、Society 5.0、データ駆動型社会等）に深く寄与しているものであり、それが自らの生活と密接に結びついている | C89: 1-1 | D89: ビッグデータ、IoT、AI「情報処理2」(2ndQ 11週)
C90: 1-6 | D90: AI最新技術の活用例「情報処理2」(2ndQ 11週)
B91: （２）「社会で活用されているデータ」や「データの活用領域」は非常に広範囲であって、日常生活や社会の課題を解決する有用なツールになり得るもの | C91: 1-2 | D91: 調査データ、実験データ、人の行動ログデータ、機械の稼働ログデータなど「情報処理1」(3rdQ 5週,6週)
C92: 1-3 | D92: 研究開発、調達、製造、物流、販売、マーケティング、サービスなど「情報処理1」(3rdQ 5週,6週)
B93: （３）様々なデータ利活用の現場におけるデータ利活用事例が示され、様々な適用領域（流通、製造、金融、サービス、インフラ、公共、ヘルスケア等）の知見と組み合わせることで価値を創出するもの | C93: 1-4 | D93: 特化型AIと汎用AI、今のAIで出来ることと出来ないこと、AIとビッグデータ「情報処理2」(2ndQ 11週)
C94: 1-5 | D94: 流通、製造、金融、サービス、インフラ、公共、ヘルスケア等におけるデータ・AI利活用事例紹介「情報処理2」(2ndQ 11週)
B95: （４）活用に当たっての様々な留意事項（ELSI、個人情報、データ倫理、ＡＩ社会原則等）を考慮し、情報セキュリティや情報漏洩等、データを守る上での留意事項への理解をする | C95: 3-1 | D95: データ倫理：データのねつ造、改ざん、盗用、プライバシー保護「情報処理1」(3rdQ 1週,2週)
C96: 3-2 | D96: 情報セキュリティ：機密性、完全性、可用性「情報処理1」(3rdQ 1週,2週)
B97: （５）実データ・実課題（学術データ等を含む）を用いた演習など、社会での実例を題材として、「データを読む、説明する、扱う」といった数理・データサイエンス・ＡＩの基本的な活用法に関するもの | C97: 2-1 | D97: データの分布(ヒストグラム)と代表値（平均値、中央値、最頻値）「情報処理2」(2ndQ 12週)
...

Sheet 様式１-2　プログラムを構成する授業科目
R1: 様式１-２ | T1: 「学部・学科によって、修了要件は相違する」場合は、本シートを複製の上＜様式１－〇＞と枝番号を付してください
B2: 大学等名 | C2: 弓削商船高等専門学校
B3: プログラム名 | C3: 数理・データサイエンス・AI教育プログラム
A5: プログラムを構成する授業科目について
A7: ① 対象となる学部・学科名称 | J7: ② 教育プログラムの修了要件 | K7: 学部・学科によって、修了要件は相違する
B9: 電子機械工学科
A12: ③ 修了要件
B13: プログラムを構成する「情報処理１」「情報処理２」を修得していること。 | V13: 【プルダウンリスト】
V14: 令和４年度以前より、履修することが必須のプログラムとして実施
V15: 令和７年度までに履修必須とする計画
V16: 令和８年度以降に履修必須とする計画、又は未定
B20: 必要最低単位数 | C20: 4 | E20: 単位 | J20: 履修必須の有無 | K20: 令和４年度以前より、履修することが必須のプログラムとして実施
A22: ④ 現在進行中の社会変化（第４次産業革命、Society 5.0、データ駆動型社会等）に深く寄与しているものであり、それが自らの生活と密接に結びついている」の内容を含む授業科目
B24: 授業科目 | F24: 単位数 | G24: 必須 | H24: 1-1 | I24: 1-6 | J24: 授業科目 | P24: 単位数 | Q24: 必須 | R24: 1-1 | S24: 1-6
B25: 情報処理1 | F25: 2 | G25: ○ | H25: ○ | I25: ○
A33: ⑤ 「社会で活用されているデータ」や「データの活用領域」は非常に広範囲であって、日常生活や社会の課題を解決する有用なツールになり得るもの」の内容を含む授業科目
B35: 授業科目 | F35: 単位数 | G35: 必須 | H35: 1-2 | I35: 1-3 | J35: 授業科目 | P35: 単位数 | Q35: 必須 | R35: 1-2 | S35: 1-3
B36: 情報処理1 | F36: 2 | G36: ○ | H36: ○ | I36: ○
A44: ⑥ 「様々なデータ利活用の現場におけるデータ利活用事例が示され、様々な適用領域（流通、製造、金融、サービス、インフラ、公共、ヘルスケア等）の知見と組み合わせることで価値を創出するもの」の内容を含む授業科目
B46: 授業科目 | F46: 単位数 | G46: 必須 | H46: 1-4 | I46: 1-5 | J46: 授業科目 | P46: 単位数 | Q46: 必須 | R46: 1-4 | S46: 1-5
B47: 情報処理1 | F47: 2 | G47: ○ | H47: ○ | I47: ○
A55: ⑦ 「活用に当たっての様々な留意事項（ELSI、個人情報、データ倫理、ＡＩ社会原則等）を考慮し、情報セキュリティや情報漏洩等、データを守る上での留意事項への理解をする」の内容を含む授業科目
B57: 授業科目 | F57: 単位数 | G57: 必須 | H57: 3-1 | I57: 3-2 | J57: 授業科目 | P57: 単位数 | Q57: 必須 | R57: 3-1 | S57: 3-2
B58: 情報処理1 | F58: 2 | G58: ○ | H58: ○ | I58: ○
A66: ⑧ 「実データ・実課題（学術データ等を含む）を用いた演習など、社会での実例を題材として、「データを読む、説明する、扱う」といった数理・データサイエンス・ＡＩの基本的な活用法に関するもの」の内容を含む授業科目
B68: 授業科目 | E68: 単位数 | F68: 必須 | G68: 2-1 | H68: 2-2 | I68: 2-3 | J68: 授業科目 | O68: 単位数 | P68: 必須 | Q68: 2-1 | R68: 2-2 | S68: 2-3
B69: 情報処理2 | E69: 2 | F69: ○ | G69: ○ | H69: ○ | I69: ○
A77: ⑨ 選択「４．オプション」の内容を含む授業科目
B78: 授業科目 | F78: 選択項目 | J78: 授業科目 | P78: 選択項目
A87: ⑩ プログラムを構成する授業の内容
B88: 授業に含まれている内容・要素 | D88: 講義内容
B89: （１）現在進行中の社会変化（第４次産業革命、Society 5.0、データ駆動型社会等）に深く寄与しているものであり、それが自らの生活と密接に結びついている | C89: 1-1 | D89: ビッグデータ、IoT、AI「情報処理1」(1stQ 2週)
C90: 1-6 | D90: AI等を活用した新しいビジネスモデル、AI最新技術の活用例「情報処理1」(3rdQ 7週)
B91: （２）「社会で活用されているデータ」や「データの活用領域」は非常に広範囲であって、日常生活や社会の課題を解決する有用なツールになり得るもの | C91: 1-2 | D91: データのメタ化、データのオープン化「情報処理1」(2ndQ 9週)
C92: 1-3 | D92: データ・AI活用領域の広がり「情報処理1」(2ndQ 10週)
B93: （３）様々なデータ利活用の現場におけるデータ利活用事例が示され、様々な適用領域（流通、製造、金融、サービス、インフラ、公共、ヘルスケア等）の知見と組み合わせることで価値を創出するもの | C93: 1-4 | D93: データ解析、データ可視化、非構造化データ処理、AIとビッグデータ、認識技術「情報処理1」(3rdQ 1週)
C94: 1-5 | D94: データサイエンスのサイクル、データ・AI利活用事例紹介「情報処理1」(3rdQ 2週)
B95: （４）活用に当たっての様々な留意事項（ELSI、個人情報、データ倫理、ＡＩ社会原則等）を考慮し、情報セキュリティや情報漏洩等、データを守る上での留意事項への理解をする | C95: 3-1 | D95: AI社会原則「情報処理1」(4thQ 15週)
C96: 3-2 | D96: 情報セキュリティ、情報漏洩等によるセキュリティ事故の事例紹介「情報処理1」(4thQ 14週)
B97: （５）実データ・実課題（学術データ等を含む）を用いた演習など、社会での実例を題材として、「データを読む、説明する、扱う」といった数理・データサイエンス・ＡＩの基本的な活用法に関するもの | C97: 2-1 | D97: データの種類（量的変数、質的変数）「情報処理2」(1stQ 5週)
...

Sheet 様式１-3　プログラムを構成する授業科目 
R1: 様式１-３ | T1: 「学部・学科によって、修了要件は相違する」場合は、本シートを複製の上＜様式１－〇＞と枝番号を付してください
B2: 大学等名 | C2: 弓削商船高等専門学校
B3: プログラム名 | C3: 数理・データサイエンス・AI教育プログラム
A5: プログラムを構成する授業科目について
A7: ① 対象となる学部・学科名称 | J7: ② 教育プログラムの修了要件 | K7: 学部・学科によって、修了要件は相違する
B9: 情報工学科
A12: ③ 修了要件
B13: プログラムを構成する「基礎情報工学」「情報工学実験１」を修得していること。 | V13: 【プルダウンリスト】
V14: 令和４年度以前より、履修することが必須のプログラムとして実施
V15: 令和７年度までに履修必須とする計画
V16: 令和８年度以降に履修必須とする計画、又は未定
B20: 必要最低単位数 | C20: 6 | E20: 単位 | J20: 履修必須の有無 | K20: 令和４年度以前より、履修することが必須のプログラムとして実施
A22: ④ 現在進行中の社会変化（第４次産業革命、Society 5.0、データ駆動型社会等）に深く寄与しているものであり、それが自らの生活と密接に結びついている」の内容を含む授業科目
B24: 授業科目 | F24: 単位数 | G24: 必須 | H24: 1-1 | I24: 1-6 | J24: 授業科目 | P24: 単位数 | Q24: 必須 | R24: 1-1 | S24: 1-6
B25: 基礎情報工学 | F25: 2 | G25: ○ | H25: ○ | I25: ○
A33: ⑤ 「社会で活用されているデータ」や「データの活用領域」は非常に広範囲であって、日常生活や社会の課題を解決する有用なツールになり得るもの」の内容を含む授業科目
B35: 授業科目 | F35: 単位数 | G35: 必須 | H35: 1-2 | I35: 1-3 | J35: 授業科目 | P35: 単位数 | Q35: 必須 | R35: 1-2 | S35: 1-3
B36: 基礎情報工学 | F36: 2 | G36: ○ | H36: ○ | I36: ○
A44: ⑥ 「様々なデータ利活用の現場におけるデータ利活用事例が示され、様々な適用領域（流通、製造、金融、サービス、インフラ、公共、ヘルスケア等）の知見と組み合わせることで価値を創出するもの」の内容を含む授業科目
B46: 授業科目 | F46: 単位数 | G46: 必須 | H46: 1-4 | I46: 1-5 | J46: 授業科目 | P46: 単位数 | Q46: 必須 | R46: 1-4 | S46: 1-5
B47: 基礎情報工学 | F47: 2 | G47: ○ | H47: ○ | I47: ○
A55: ⑦ 「活用に当たっての様々な留意事項（ELSI、個人情報、データ倫理、ＡＩ社会原則等）を考慮し、情報セキュリティや情報漏洩等、データを守る上での留意事項への理解をする」の内容を含む授業科目
B57: 授業科目 | F57: 単位数 | G57: 必須 | H57: 3-1 | I57: 3-2 | J57: 授業科目 | P57: 単位数 | Q57: 必須 | R57: 3-1 | S57: 3-2
B58: 基礎情報工学 | F58: 2 | G58: ○ | H58: ○ | I58: ○
A66: ⑧ 「実データ・実課題（学術データ等を含む）を用いた演習など、社会での実例を題材として、「データを読む、説明する、扱う」といった数理・データサイエンス・ＡＩの基本的な活用法に関するもの」の内容を含む授業科目
B68: 授業科目 | E68: 単位数 | F68: 必須 | G68: 2-1 | H68: 2-2 | I68: 2-3 | J68: 授業科目 | O68: 単位数 | P68: 必須 | Q68: 2-1 | R68: 2-2 | S68: 2-3
B69: 情報工学実験1 | E69: 4 | F69: ○ | G69: ○ | H69: ○ | I69: ○
A77: ⑨ 選択「４．オプション」の内容を含む授業科目
B78: 授業科目 | F78: 選択項目 | J78: 授業科目 | P78: 選択項目
A87: ⑩ プログラムを構成する授業の内容
B88: 授業に含まれている内容・要素 | D88: 講義内容
B89: （１）現在進行中の社会変化（第４次産業革命、Society 5.0、データ駆動型社会等）に深く寄与しているものであり、それが自らの生活と密接に結びついている | C89: 1-1 | D89: データを起点としたものの見方、人間の知的活動を起点としたものの見方「基礎情報工学」(1st 2週)
C90: 1-6 | D90: AI最新技術の活用例（深層生成モデル、敵対的生成ネットワーク、強化学習、転移学習など）「基礎情報工学」(1st 2週)
B91: （２）「社会で活用されているデータ」や「データの活用領域」は非常に広範囲であって、日常生活や社会の課題を解決する有用なツールになり得るもの | C91: 1-2 | D91: 調査データ、実験データ、人の行動ログデータ、機械の稼働ログデータなど「基礎情報工学」(1st 2週)
C92: 1-3 | D92: 仮説検証、知識発見、原因究明、計画策定、判断支援、活動代替、新規生成など「基礎情報工学」(1st 2週)
B93: （３）様々なデータ利活用の現場におけるデータ利活用事例が示され、様々な適用領域（流通、製造、金融、サービス、インフラ、公共、ヘルスケア等）の知見と組み合わせることで価値を創出するもの | C93: 1-4 | D93: データ解析：予測、グルーピング、パターン発見、最適化、シミュレーション・データ同化など「基礎情報工学」(1st 2週)
C94: 1-5 | D94: データサイエンスのサイクル「基礎情報工学」(1st 2週)
B95: （４）活用に当たっての様々な留意事項（ELSI、個人情報、データ倫理、ＡＩ社会原則等）を考慮し、情報セキュリティや情報漏洩等、データを守る上での留意事項への理解をする | C95: 3-1 | D95: データ倫理：データのねつ造、改ざん、盗用、プライバシー保護「基礎情報工学」(4thQ 10週)
C96: 3-2 | D96: 情報セキュリティ：機密性、完全性、可用性「基礎情報工学」(4thQ 10週)
B97: （５）実データ・実課題（学術データ等を含む）を用いた演習など、社会での実例を題材として、「データを読む、説明する、扱う」といった数理・データサイエンス・ＡＩの基本的な活用法に関するもの | C97: 2-1 | D97: データの分布(ヒストグラム)と代表値（平均値、中央値、最頻値）「情報工学実験1」(2ndQ 13週,14週)
...

Sheet 様式２ 履修者等数の実績
AQ1: 様式２
AL2: 大学等名 | AM2: ='様式１-1 プログラムを構成する授業科目'!C2 -> 弓削商船高等専門学校
A3: プログラムの履修者数等の実績について
A5: ①プログラム開設年度 | C5: 令和３ | E5: 年度
A7: ②履修者・修了者の実績
B9: 学部・学科名称 | C9: 学生数 | D9: 入学 定員 | E9: 収容 定員 | F9: 令和4年度 | L9: 令和3年度 | R9: 令和2年度 | X9: 令和元年度 | AD9: 平成30年度 | AJ9: 平成29年度 | AP9: 履修者数 合計 | AQ9: 履修率
F10: 履修者数 | I10: 修了者数 | L10: 履修者数 | O10: 修了者数 | R10: 履修者数 | U10: 修了者数 | X10: 履修者数 | AA10: 修了者数 | AD10: 履修者数 | AG10: 修了者数 | AJ10: 履修者数 | AM10: 修了者数
F11: 合計 | G11: 男性 | H11: 女性 | I11: 合計 | J11: 男性 | K11: 女性 | L11: 合計 | M11: 男性 | N11: 女性 | O11: 合計 | P11: 男性 | Q11: 女性 | R11: 合計 | S11: 男性 | T11: 女性 | U11: 合計 | V11: 男性 | W11: 女性 | X11: 合計 | Y11: 男性 | Z11: 女性 | AA11: 合計 | AB11: 男性 | AC11: 女性 | AD11: 合計 | AE11: 男性 | AF11: 女性 | AG11: 合計 | AH11: 男性 | AI11: 女性 | AJ11: 合計 | AK11: 男性 | AL11: 女性 | AM11: 合計 | AN11: 男性 | AO11: 女性
B12: 商船学科 | C12: 227 | D12: 40 | E12: 240 | F12: =G12+H12 -> 89 | G12: 77 | H12: 12 | I12: =J12+K12 -> 43 | J12: 37 | K12: 6 | L12: =M12+N12 -> 44 | M12: 38 | N12: 6 | O12: =P12+Q12 -> 0 | P12: 0 | Q12: 0 | R12: =S12+T12 -> 0 | S12: 0 | T12: 0 | U12: =V12+W12 -> 0 | V12: 0 | W12: 0 | X12: =Y12+Z12 -> 0 | Y12: 0 | Z12: 0 | AA12: =AB12+AC12 -> 0 | AB12: 0 | AC12: 0 | AD12: =AE12+AF12 -> 0 | AE12: 0 | AF12: 0 | AG12: =AH12+AI12 -> 0 | AH12: 0 | AI12: 0 | AJ12: =AK12+AL12 -> 0 | AK12: 0 | AL12: 0 | AM12: =AN12+AO12 -> 0 | AN12: 0 | AO12: 0 | AP12: =F12+L12+R12+X12+AD12+AJ12 -> 133 | AQ12: =AP12/E12 -> 0.55416667
B13: 電子機械工学科 | C13: 213 | D13: 40 | E13: 200 | F13: =G13+H13 -> 43 | G13: 38 | H13: 5 | I13: =J13+K13 -> 0 | J13: 0 | K13: 0 | L13: =M13+N13 -> 0 | M13: 0 | N13: 0 | O13: =P13+Q13 -> 0 | P13: 0 | Q13: 0 | R13: =S13+T13 -> 0 | S13: 0 | T13: 0 | U13: =V13+W13 -> 0 | V13: 0 | W13: 0 | X13: =Y13+Z13 -> 0 | Y13: 0 | Z13: 0 | AA13: =AB13+AC13 -> 0 | AB13: 0 | AC13: 0 | AD13: =AE13+AF13 -> 0 | AE13: 0 | AF13: 0 | AG13: =AH13+AI13 -> 0 | AH13: 0 | AI13: 0 | AJ13: =AK13+AL13 -> 0 | AK13: 0 | AL13: 0 | AM13: =AN13+AO13 -> 0 | AN13: 0 | AO13: 0 | AP13: =F13+L13+R13+X13+AD13+AJ13 -> 43 | AQ13: =AP13/E13 -> 0.215
B14: 情報工学科 | C14: 195 | D14: 40 | E14: 200 | F14: =G14+H14 -> 40 | G14: 19 | H14: 21 | I14: =J14+K14 -> 40 | J14: 19 | K14: 21 | L14: =M14+N14 -> 44 | M14: 28 | N14: 16 | O14: =P14+Q14 -> 44 | P14: 28 | Q14: 16 | R14: =S14+T14 -> 0 | S14: 0 | T14: 0 | U14: =V14+W14 -> 0 | V14: 0 | W14: 0 | X14: =Y14+Z14 -> 0 | Y14: 0 | Z14: 0 | AA14: =AB14+AC14 -> 0 | AB14: 0 | AC14: 0 | AD14: =AE14+AF14 -> 0 | AE14: 0 | AF14: 0 | AG14: =AH14+AI14 -> 0 | AH14: 0 | AI14: 0 | AJ14: =AK14+AL14 -> 0 | AK14: 0 | AL14: 0 | AM14: =AN14+AO14 -> 0 | AN14: 0 | AO14: 0 | AP14: =F14+L14+R14+X14+AD14+AJ14 -> 84 | AQ14: =AP14/E14 -> 0.42
F15: =G15+H15 -> 0 | I15: =J15+K15 -> 0 | L15: =M15+N15 -> 0 | O15: =P15+Q15 -> 0 | R15: =S15+T15 -> 0 | U15: =V15+W15 -> 0 | X15: =Y15+Z15 -> 0 | AA15: =AB15+AC15 -> 0 | AD15: =AE15+AF15 -> 0 | AG15: =AH15+AI15 -> 0 | AJ15: =AK15+AL15 -> 0 | AM15: =AN15+AO15 -> 0 | AP15: =F15+L15+R15+X15+AD15+AJ15 -> 0 | AQ15: =AP15/E15 -> #DIV/0!
F16: =G16+H16 -> 0 | I16: =J16+K16 -> 0 | L16: =M16+N16 -> 0 | O16: =P16+Q16 -> 0 | R16: =S16+T16 -> 0 | U16: =V16+W16 -> 0 | X16: =Y16+Z16 -> 0 | AA16: =AB16+AC16 -> 0 | AD16: =AE16+AF16 -> 0 | AG16: =AH16+AI16 -> 0 | AJ16: =AK16+AL16 -> 0 | AM16: =AN16+AO16 -> 0 | AP16: =F16+L16+R16+X16+AD16+AJ16 -> 0 | AQ16: =AP16/E16 -> #DIV/0!
F17: =G17+H17 -> 0 | I17: =J17+K17 -> 0 | L17: =M17+N17 -> 0 | O17: =P17+Q17 -> 0 | R17: =S17+T17 -> 0 | U17: =V17+W17 -> 0 | X17: =Y17+Z17 -> 0 | AA17: =AB17+AC17 -> 0 | AD17: =AE17+AF17 -> 0 | AG17: =AH17+AI17 -> 0 | AJ17: =AK17+AL17 -> 0 | AM17: =AN17+AO17 -> 0 | AP17: =F17+L17+R17+X17+AD17+AJ17 -> 0 | AQ17: =AP17/E17 -> #DIV/0!
F18: =G18+H18 -> 0 | I18: =J18+K18 -> 0 | L18: =M18+N18 -> 0 | O18: =P18+Q18 -> 0 | R18: =S18+T18 -> 0 | U18: =V18+W18 -> 0 | X18: =Y18+Z18 -> 0 | AA18: =AB18+AC18 -> 0 | AD18: =AE18+AF18 -> 0 | AG18: =AH18+AI18 -> 0 | AJ18: =AK18+AL18 -> 0 | AM18: =AN18+AO18 -> 0 | AP18: =F18+L18+R18+X18+AD18+AJ18 -> 0 | AQ18: =AP18/E18 -> #DIV/0!
F19: =G19+H19 -> 0 | I19: =J19+K19 -> 0 | L19: =M19+N19 -> 0 | O19: =P19+Q19 -> 0 | R19: =S19+T19 -> 0 | U19: =V19+W19 -> 0 | X19: =Y19+Z19 -> 0 | AA19: =AB19+AC19 -> 0 | AD19: =AE19+AF19 -> 0 | AG19: =AH19+AI19 -> 0 | AJ19: =AK19+AL19 -> 0 | AM19: =AN19+AO19 -> 0 | AP19: =F19+L19+R19+X19+AD19+AJ19 -> 0 | AQ19: =AP19/E19 -> #DIV/0!
F20: =G20+H20 -> 0 | I20: =J20+K20 -> 0 | L20: =M20+N20 -> 0 | O20: =P20+Q20 -> 0 | R20: =S20+T20 -> 0 | U20: =V20+W20 -> 0 | X20: =Y20+Z20 -> 0 | AA20: =AB20+AC20 -> 0 | AD20: =AE20+AF20 -> 0 | AG20: =AH20+AI20 -> 0 | AJ20: =AK20+AL20 -> 0 | AM20: =AN20+AO20 -> 0 | AP20: =F20+L20+R20+X20+AD20+AJ20 -> 0 | AQ20: =AP20/E20 -> #DIV/0!
F21: =G21+H21 -> 0 | I21: =J21+K21 -> 0 | L21: =M21+N21 -> 0 | O21: =P21+Q21 -> 0 | R21: =S21+T21 -> 0 | U21: =V21+W21 -> 0 | X21: =Y21+Z21 -> 0 | AA21: =AB21+AC21 -> 0 | AD21: =AE21+AF21 -> 0 | AG21: =AH21+AI21 -> 0 | AJ21: =AK21+AL21 -> 0 | AM21: =AN21+AO21 -> 0 | AP21: =F21+L21+R21+X21+AD21+AJ21 -> 0 | AQ21: =AP21/E21 -> #DIV/0!
F22: =G22+H22 -> 0 | I22: =J22+K22 -> 0 | L22: =M22+N22 -> 0 | O22: =P22+Q22 -> 0 | R22: =S22+T22 -> 0 | U22: =V22+W22 -> 0 | X22: =Y22+Z22 -> 0 | AA22: =AB22+AC22 -> 0 | AD22: =AE22+AF22 -> 0 | AG22: =AH22+AI22 -> 0 | AJ22: =AK22+AL22 -> 0 | AM22: =AN22+AO22 -> 0 | AP22: =F22+L22+R22+X22+AD22+AJ22 -> 0 | AQ22: =AP22/E22 -> #DIV/0!
F23: =G23+H23 -> 0 | I23: =J23+K23 -> 0 | L23: =M23+N23 -> 0 | O23: =P23+Q23 -> 0 | R23: =S23+T23 -> 0 | U23: =V23+W23 -> 0 | X23: =Y23+Z23 -> 0 | AA23: =AB23+AC23 -> 0 | AD23: =AE23+AF23 -> 0 | AG23: =AH23+AI23 -> 0 | AJ23: =AK23+AL23 -> 0 | AM23: =AN23+AO23 -> 0 | AP23: =F23+L23+R23+X23+AD23+AJ23 -> 0 | AQ23: =AP23/E23 -> #DIV/0!
F24: =G24+H24 -> 0 | I24: =J24+K24 -> 0 | L24: =M24+N24 -> 0 | O24: =P24+Q24 -> 0 | R24: =S24+T24 -> 0 | U24: =V24+W24 -> 0 | X24: =Y24+Z24 -> 0 | AA24: =AB24+AC24 -> 0 | AD24: =AE24+AF24 -> 0 | AG24: =AH24+AI24 -> 0 | AJ24: =AK24+AL24 -> 0 | AM24: =AN24+AO24 -> 0 | AP24: =F24+L24+R24+X24+AD24+AJ24 -> 0 | AQ24: =AP24/E24 -> #DIV/0!
F25: =G25+H25 -> 0 | I25: =J25+K25 -> 0 | L25: =M25+N25 -> 0 | O25: =P25+Q25 -> 0 | R25: =S25+T25 -> 0 | U25: =V25+W25 -> 0 | X25: =Y25+Z25 -> 0 | AA25: =AB25+AC25 -> 0 | AD25: =AE25+AF25 -> 0 | AG25: =AH25+AI25 -> 0 | AJ25: =AK25+AL25 -> 0 | AM25: =AN25+AO25 -> 0 | AP25: =F25+L25+R25+X25+AD25+AJ25 -> 0 | AQ25: =AP25/E25 -> #DIV/0!
F26: =G26+H26 -> 0 | I26: =J26+K26 -> 0 | L26: =M26+N26 -> 0 | O26: =P26+Q26 -> 0 | R26: =S26+T26 -> 0 | U26: =V26+W26 -> 0 | X26: =Y26+Z26 -> 0 | AA26: =AB26+AC26 -> 0 | AD26: =AE26+AF26 -> 0 | AG26: =AH26+AI26 -> 0 | AJ26: =AK26+AL26 -> 0 | AM26: =AN26+AO26 -> 0 | AP26: =F26+L26+R26+X26+AD26+AJ26 -> 0 | AQ26: =AP26/E26 -> #DIV/0!
... F31: =G31+H31 -> 0 | I31: =J31+K31 -> 0 | L31: =M31+N31 -> 0 | O31: =P31+Q31 -> 0 | R31: =S31+T31 -> 0 | U31: =V31+W31 -> 0 | X31: =Y31+Z31 -> 0 | AA31: =AB31+AC31 -> 0 | AD31: =AE31+AF31 -> 0 | AG31: =AH31+AI31 -> 0 | AJ31: =AK31+AL31 -> 0 | AM31: =AN31+AO31 -> 0 | AP31: =F31+L31+R31+X31+AD31+AJ31 -> 0 | AQ31: =AP31/E31 -> #DIV/0!
B32: 合 計 | C32: =SUM(C12:C31) -> 635 | D32: =SUM(D12:D31) -> 120 | E32: =SUM(E12:E31) -> 640 | F32: =SUM(F12:F31) -> 172 | G32: =SUM(G12:G31) -> 134 | H32: =SUM(H12:H31) -> 38 | I32: =SUM(I12:I31) -> 83 | J32: =SUM(J12:J31) -> 56 | ... AP32: =SUM(AP12:AP31) -> 260 | AQ32: =AP32/E32 -> 0.40625

Sheet 様式３ 教育の質・履修者数を向上させるための体制・計画
I1: 様式３
G2: 大学等名 | H2: ='様式１-1 プログラムを構成する授業科目'!C2 -> 弓削商船高等専門学校
A4: 教育の質・履修者数を向上させるための体制・計画について
A6: ① | B6: 全学の教員数 | C6: (常勤） | E6: 48 | F6: 人 | G6: （非常勤） | H6: 32 | I6: 人
A8: ② | B8: プログラムの授業を教えている教員数 | H8: 5 | I8: 人
A10: ③ | B10: プログラムの運営責任者
B11: （責任者名） | C11: 石田 邦光 | G11: （役職名） | H11: 校長
A13: ④ | B13: プログラムを改善・進化させるための体制（委員会・組織等）
B14: 教務委員会
B16: （責任者名） | C16: 藤本 隆士 | G16: （役職名） | H16: 教務主事
A18: ⑤ | B18: プログラムを改善・進化させるための体制を定める規則名称
B19: 弓削商船高等専門学校教務委員会規則
A21: ⑥ | B21: 体制の目的
B22: この委員会は、弓削商船高等専門学校において、教育計画の立案に関する事項を審議する。
A34: ⑦ | B34: 具体的な構成員
B35: 教務主事 藤本 隆士 商船学科長 二村 彰 電子機械工学科長 長井 弘志 情報工学科長 徳田 誠 総合教育科長 久保 康幸 教務主事補 佐久間 一行、政家 利彦、日下 佳春 学生課長 成田 悦子
A48: ⑧ | B48: 履修者数・履修率の向上に向けた計画 ※様式１の「履修必須の有無」で「計画がある」としている場合は詳細について記載すること
B49: 令和４年度実績 | C49: ='様式２ 履修者等数の実績'!AQ32 -> 0.40625 | E49: 令和５年度予定 | F49: 0.59 | H49: 令和６年度予定 | I49: 0.78
B50: 令和７年度予定 | C50: 0.97 | E50: 令和８年度予定 | F50: 1 | H50: 収容定員（名） | I50: ='様式２ 履修者等数の実績'!E32 -> 640
B51: 具体的な計画
B52: 目標を実現するために、講義時間外の指導を含め学生の該当講義の履修単位取得を積極的に補助する。教務委員会として、その科目担当教員を補助する。必修科目の修得で可能となるため、全学生が取得できることを目的とする。
A65: ⑨ | B65: 学部・学科に関係なく希望する学生全員が受講可能となるような必要な体制・取組等
B66: 全学科において必修科目としており、学生全員が受講可能である。
A79: ⑩ | B79: できる限り多くの学生が履修できるような具体的な周知方法・取組
B80: 全学生が必修科目で履修する。
A93: ⑪ | B93: できる限り多くの学生が履修・修得できるようなサポート体制
B94: 講義時間外の指導を含め、学生の該当講義の履修単位取得を積極的に補助する。
A107: ⑫ | B107: 授業時間内外で学習指導、質問を受け付ける具体的な仕組み
B108: オフィスアワーを設けて学生の要望に応じて対応する。また、teamsやmoodleを活用した遠隔での指導を行う。

Sheet 様式４　自己点検・評価
I1: 様式４
H2: 大学等名 | I2: ='様式１-1 プログラムを構成する授業科目'!C2 -> 弓削商船高等専門学校
A3: 自己点検・評価について
A5: ① | B5: プログラムの自己点検・評価を行う体制（委員会・組織等）
B6: 自己点検評価委員会
D8: （責任者名） | E8: 石田 邦光 | G8: （役職名） | H8: 校長
A10: ② | B10: 自己点検・評価体制における意見等
B11: 自己点検・評価の視点 | E11: 自己点検・評価体制における意見・結果・改善に向けた取組等
B12: 学内からの視点
C13: プログラムの履修・修得状況 | E13: 本教育プログラムは、各学科の必修科目で構成されているため、学生全員が履修する。 2022年度の該当科目については途中退学者を除き、ほぼ全員が修得した。
C14: 学修成果 | E14: プログラムを構成する科目について、成績評価の平均点は良好であった。特に情報工学科においては、平均点が８０点以上あり、成果を上げている。また、授業評価アンケートを行っており、「学習内容を理解し興味をもった」のアンケート項目を分析することで学生の理解度を把握しているが、ほとんどの科目が４以上（５段階）であり、よく理解できていると言える。
C15: 学生アンケート等を通じた学生の内容の理解度 | E15: 授業評価アンケートを行っており、「学習内容を理解し興味をもった」のアンケート項目を分析することで学生の理解度を把握しているが、ほとんどの科目が４以上（５段階）であり、よく理解できていると言える。
C16: 学生アンケート等を通じた後輩等他の学生への推奨度 | E16: 本教育プログラムは必修科目で構成されている。そのため、本校に入学するすべての学生が教育プログラムの履修者であるため、履修を促すための特別な推奨を行っていない。ただし、授業評価アンケートを通じて、授業における学生の興味関心の確認は必ず行っている。
C17: 全学的な履修者数、履修率向上に向けた計画の達成・進捗状況 | E17: 本教育プログラムは必修科目で構成されている。そのため、本校に入学するすべての学生が教育プログラムの履修者であるため、履修率１００％である。今後、新たな教育課程を編成するときも、数理・データサイエンス・ＡＩ教育は重要であるという認識のもと、教育プログラムを修得するために必修科目で構成する計画である。
B18: 学外からの視点
C19: 教育プログラム修了者の進路、活躍状況、企業等の評価 | E19: 令和５年３月末時点で教育プログラム修了者の卒業者はいない。
C20: 産業界からの視点を含めた教育プログラム内容・手法等への意見 | E20: 卒業生や企業へのアンケートは行っている。令和4年時点では卒業生がいないため不明である。
B21: 数理・データサイエンス・ＡＩを「学ぶ楽しさ」「学ぶことの意義」を理解させること | E21: 本教育プログラムに関わる科目において、代表的な事例を紹介しつつ、その利便性を講義したり、社会におけるデータ・ＡＩ利活用・社会で起きている変化を講義するなど、「学ぶ楽しさ」「学ぶことの意義」を理解するよう取り組んでいる。
B22: 内容・水準を維持・向上しつつ、より「分かりやすい」授業とすること | E22: 授業評価アンケートを行い、学生からの意見を取り入れ、教務委員会において分析することで、より「分かりやすい」授業とするような体制を取っている。
