Workbook

Sheet 様式１-１　プログラムを構成する授業科目
R1: 様式１-１ | T1: 「学部・学科によって、修了要件は相違する」場合は、本シートを複製の上＜様式１－〇＞と枝番号を付してください
B2: 大学等名 | C2: 愛知学院大学
B3: プログラム名 | C3: 愛知学院大学データサイエンス教育プログラム
A5: プログラムを構成する授業科目について
A7: ① 対象となる学部・学科名称 | J7: ② 教育プログラムの修了要件 | K7: 学部・学科によって、修了要件は相違する
B9: 文学部、法学部、心身科学部、心理学部
A12: ③ 修了要件
B13: プログラム構成科目である「情報科学Ⅰ・Ⅱ」及び「教養セミナーⅢ・Ⅳ」（教養教育科目・教育基幹科目）の4科目6単位を取得すること。 | V13: 【プルダウンリスト】
V14: 令和４年度以前より、履修することが必須のプログラムとして実施
V15: 令和７年度までに履修必須とする計画
V16: 令和８年度以降に履修必須とする計画、又は未定
B20: 必要最低単位数 | C20: 6 | E20: 単位 | J20: 履修必須の有無 | K20: 令和８年度以降に履修必須とする計画、又は未定
A22: ④ 現在進行中の社会変化（第４次産業革命、Society 5.0、データ駆動型社会等）に深く寄与しているものであり、それが自らの生活と密接に結びついている」の内容を含む授業科目
B24: 授業科目 | F24: 単位数 | G24: 必須 | H24: 1-1 | I24: 1-6 | J24: 授業科目 | P24: 単位数 | Q24: 必須 | R24: 1-1 | S24: 1-6
B25: 情報科学Ⅰ | F25: 2 | G25: ○ | H25: ○
B26: 情報科学Ⅱ | F26: 2 | G26: ○ | I26: ○
A33: ⑤ 「社会で活用されているデータ」や「データの活用領域」は非常に広範囲であって、日常生活や社会の課題を解決する有用なツールになり得るもの」の内容を含む授業科目
B35: 授業科目 | F35: 単位数 | G35: 必須 | H35: 1-2 | I35: 1-3 | J35: 授業科目 | P35: 単位数 | Q35: 必須 | R35: 1-2 | S35: 1-3
B36: 情報科学Ⅰ | F36: 2 | G36: ○ | H36: ○ | I36: ○
A44: ⑥ 「様々なデータ利活用の現場におけるデータ利活用事例が示され、様々な適用領域（流通、製造、金融、サービス、インフラ、公共、ヘルスケア等）の知見と組み合わせることで価値を創出するもの」の内容を含む授業科目
B46: 授業科目 | F46: 単位数 | G46: 必須 | H46: 1-4 | I46: 1-5 | J46: 授業科目 | P46: 単位数 | Q46: 必須 | R46: 1-4 | S46: 1-5
B47: 情報科学Ⅱ | F47: 2 | G47: ○ | H47: ○ | I47: ○
A55: ⑦ 「活用に当たっての様々な留意事項（ELSI、個人情報、データ倫理、ＡＩ社会原則等）を考慮し、情報セキュリティや情報漏洩等、データを守る上での留意事項への理解をする」の内容を含む授業科目
B57: 授業科目 | F57: 単位数 | G57: 必須 | H57: 3-1 | I57: 3-2 | J57: 授業科目 | P57: 単位数 | Q57: 必須 | R57: 3-1 | S57: 3-2
B58: 教養セミナーⅣ | F58: 1 | G58: ○ | H58: ○ | I58: ○
A66: ⑧ 「実データ・実課題（学術データ等を含む）を用いた演習など、社会での実例を題材として、「データを読む、説明する、扱う」といった数理・データサイエンス・ＡＩの基本的な活用法に関するもの」の内容を含む授業科目
B68: 授業科目 | E68: 単位数 | F68: 必須 | G68: 2-1 | H68: 2-2 | I68: 2-3 | J68: 授業科目 | O68: 単位数 | P68: 必須 | Q68: 2-1 | R68: 2-2 | S68: 2-3
B69: 教養セミナーⅢ | E69: 1 | F69: ○ | G69: ○ | H69: ○ | I69: ○
A77: ⑨ 選択「４．オプション」の内容を含む授業科目
B78: 授業科目 | F78: 選択項目 | J78: 授業科目 | P78: 選択項目
A87: ⑩ プログラムを構成する授業の内容
B88: 授業に含まれている内容・要素 | D88: 講義内容
B89: （１）現在進行中の社会変化（第４次産業革命、Society 5.0、データ駆動型社会等）に深く寄与しているものであり、それが自らの生活と密接に結びついている | C89: 1-1 | D89: ・ビッグデータ、第4次産業革命、データ駆動型社会「情報科学Ⅰ」（6回目） ・ビッグデータ、AI、第4次産業革命「情報科学Ⅰ」（2-4回目） ・ビッグデータ、計算機の処理性能の向上「情報科学Ⅰ」（1回目） ・ビッグデータ「情報科学Ⅰ」（2回目） ・人間の知的活動とAIの関係性「情報科学Ⅰ」（1回目）
C90: 1-6 | D90: ・AI等を活用した新しいビジネスモデル「情報科学Ⅱ」（2回目） ・AI最新技術の活用例「情報科学Ⅱ」（4回目） ・AI等を活用した新しいビジネスモデル「情報科学Ⅰ」（12回目） ・AI最新技術の活用例（強化学習）「情報科学Ⅱ」（2回目） ・AI等を活用した新しいビジネスモデル「情報科学Ⅱ」（1回目） ・AI最新技術の活用例（強化学習）「情報科学Ⅱ」（2回目）
B91: （２）「社会で活用されているデータ」や「データの活用領域」は非常に広範囲であって、日常生活や社会の課題を解決する有用なツールになり得るもの | C91: 1-2 | D91: ・構造化データ「情報科学Ⅰ」（1回目） ・データのメタ化「情報科学Ⅰ」（2回目） ・調査データ、人の行動ログデータ、機械の稼働ログデータ、構造化データ、非構造化データ「情報科学Ⅰ」（7回目） ・構造化データ、非構造化データ「情報科学Ⅰ」（7回目） ・調査データ、実験データ、構造化データ、非構造化データ「情報科学Ⅰ」（1回目）
C92: 1-3 | D92: ・データ・AI活用領域の広がり（生産、消費、文化活動など）、仮説検証「情報科学Ⅰ」（7回目） ・データ・AI活用領域の広がり「情報科学Ⅰ」（13回目） ・データ・AI活用領域の広がり（生産、消費、文化活動など）、仮説検証、知識発見、原因究明「情報科学Ⅰ」（2回目） ・データ・AI活用領域の広がり「情報科学Ⅰ」（5回目） ・データ・AI活用領域の広がり（生産、消費、文化活動など）「情報科学Ⅰ」（3回目）
B93: （３）様々なデータ利活用の現場におけるデータ利活用事例が示され、様々な適用領域（流通、製造、金融、サービス、インフラ、公共、ヘルスケア等）の知見と組み合わせることで価値を創出するもの | C93: 1-4 | D93: ・データ解析：予測、グルーピング、パターン発見、データ可視化、非構造化データ処理、今のAIで出来ることと出来ないこと「情報科学Ⅱ」（1回目） ・データ可視化「情報科学Ⅱ」（2回目） ・データ解析、データ可視化「情報科学Ⅰ」（6、10回目） ・データ解析：予測、グルーピング、パターン発見、データ可視化：複合グラフ、2軸グラフ「情報科学Ⅱ」（1回目） ・データ解析：最適化「情報科学Ⅱ」（7、8回目） ・データ可視化：複合グラフ、2軸グラフ「情報科学Ⅱ」（9回目）
C94: 1-5 | D94: ・データサイエンスのサイクル（データ解析と推論）、流通、製造、金融、サービス、インフラ、公共、ヘルスケア等におけるデータ・AI利活用事例紹介「情報科学Ⅱ」（1回目） ・データサイエンスのサイクル（課題抽出と定式化）「情報科学Ⅱ」（7、8回目） ・データサイエンスのサイクル「情報科学Ⅱ」（2回目） ・流通、製造、金融、サービス、インフラ、公共、ヘルスケア等におけるデータ・AI利活用事例紹介「情報科学Ⅱ」（1回目） ・データサイエンスのサイクル（データの取得・管理・加工）「情報科学Ⅱ」（3回目）
B95: （４）活用に当たっての様々な留意事項（ELSI、個人情報、データ倫理、ＡＩ社会原則等）を考慮し、情報セキュリティや情報漏洩等、データを守る上での留意事項への理解をする | C95: 3-1 | D95: ・データ倫理：データのねつ造、改ざん、盗用、プライバシー保護「教養セミナーⅣ」（1回目）
C96: 3-2 | D96: ・情報セキュリティ：機密性、完全性、可用性「教養セミナーⅣ」（1回目）
...

Sheet 様式１-２　プログラムを構成する授業科目
R1: 様式１-２ | T1: 「学部・学科によって、修了要件は相違する」場合は、本シートを複製の上＜様式１－〇＞と枝番号を付してください
B2: 大学等名 | C2: 愛知学院大学
B3: プログラム名 | C3: 愛知学院大学データサイエンス教育プログラム
A5: プログラムを構成する授業科目について
A7: ① 対象となる学部・学科名称 | J7: ② 教育プログラムの修了要件 | K7: 学部・学科によって、修了要件は相違する
B9: 商学部
A12: ③ 修了要件
B13: プログラム構成科目である「情報リテラシーA」「情報リテラシーB」「情報社会論」「データ分析Ⅰ」「情報セキュリティ」（専門教育科目）の5科目10単位を取得すること。 | V13: 【プルダウンリスト】
V14: 令和４年度以前より、履修することが必須のプログラムとして実施
V15: 令和７年度までに履修必須とする計画
V16: 令和８年度以降に履修必須とする計画、又は未定
B20: 必要最低単位数 | C20: 10 | E20: 単位 | J20: 履修必須の有無 | K20: 令和８年度以降に履修必須とする計画、又は未定
A22: ④ 現在進行中の社会変化（第４次産業革命、Society 5.0、データ駆動型社会等）に深く寄与しているものであり、それが自らの生活と密接に結びついている」の内容を含む授業科目
B24: 授業科目 | F24: 単位数 | G24: 必須 | H24: 1-1 | I24: 1-6 | J24: 授業科目 | P24: 単位数 | Q24: 必須 | R24: 1-1 | S24: 1-6
B25: 情報社会論 | F25: 2 | G25: ○ | H25: ○ | I25: ○
A33: ⑤ 「社会で活用されているデータ」や「データの活用領域」は非常に広範囲であって、日常生活や社会の課題を解決する有用なツールになり得るもの」の内容を含む授業科目
B35: 授業科目 | F35: 単位数 | G35: 必須 | H35: 1-2 | I35: 1-3 | J35: 授業科目 | P35: 単位数 | Q35: 必須 | R35: 1-2 | S35: 1-3
B36: 情報社会論 | F36: 2 | G36: ○ | H36: ○ | I36: ○
A44: ⑥ 「様々なデータ利活用の現場におけるデータ利活用事例が示され、様々な適用領域（流通、製造、金融、サービス、インフラ、公共、ヘルスケア等）の知見と組み合わせることで価値を創出するもの」の内容を含む授業科目
B46: 授業科目 | F46: 単位数 | G46: 必須 | H46: 1-4 | I46: 1-5 | J46: 授業科目 | P46: 単位数 | Q46: 必須 | R46: 1-4 | S46: 1-5
B47: データ分析Ⅰ | F47: 2 | G47: ○ | H47: ○
B48: 情報社会論 | F48: 2 | G48: ○ | I48: ○
A55: ⑦ 「活用に当たっての様々な留意事項（ELSI、個人情報、データ倫理、ＡＩ社会原則等）を考慮し、情報セキュリティや情報漏洩等、データを守る上での留意事項への理解をする」の内容を含む授業科目
B57: 授業科目 | F57: 単位数 | G57: 必須 | H57: 3-1 | I57: 3-2 | J57: 授業科目 | P57: 単位数 | Q57: 必須 | R57: 3-1 | S57: 3-2
B58: 情報リテラシーA | F58: 2 | G58: ○ | H58: ○ | I58: ○
B59: 情報セキュリティ | F59: 2 | G59: ○ | H59: ○ | I59: ○
A66: ⑧ 「実データ・実課題（学術データ等を含む）を用いた演習など、社会での実例を題材として、「データを読む、説明する、扱う」といった数理・データサイエンス・ＡＩの基本的な活用法に関するもの」の内容を含む授業科目
B68: 授業科目 | E68: 単位数 | F68: 必須 | G68: 2-1 | H68: 2-2 | I68: 2-3 | J68: 授業科目 | O68: 単位数 | P68: 必須 | Q68: 2-1 | R68: 2-2 | S68: 2-3
B69: データ分析Ⅰ | E69: 2 | F69: ○ | G69: ○ | H69: ○ | I69: ○
B70: 情報リテラシーB | E70: 2 | F70: ○ | H70: ○ | I70: ○
A77: ⑨ 選択「４．オプション」の内容を含む授業科目
B78: 授業科目 | F78: 選択項目 | J78: 授業科目 | P78: 選択項目
A87: ⑩ プログラムを構成する授業の内容
B88: 授業に含まれている内容・要素 | D88: 講義内容
B89: （１）現在進行中の社会変化（第４次産業革命、Society 5.0、データ駆動型社会等）に深く寄与しているものであり、それが自らの生活と密接に結びついている | C89: 1-1 | D89: ・ビッグデータ、AI「情報社会論」（5回目） ・IoT「情報社会論」（12回目）
C90: 1-6 | D90: ・AI最新技術の活用例「情報社会論」（5回目） ・AI等を活用した新しいビジネスモデル「情報社会論」（12回目）
B91: （２）「社会で活用されているデータ」や「データの活用領域」は非常に広範囲であって、日常生活や社会の課題を解決する有用なツールになり得るもの | C91: 1-2 | D91: ・調査データ、実験データ「情報社会論」（5回目） ・人の行動ログデータ 「情報社会論」（9回目）
C92: 1-3 | D92: ・データ・AI活用領域の広がり「情報社会論」（5、9回目）
B93: （３）様々なデータ利活用の現場におけるデータ利活用事例が示され、様々な適用領域（流通、製造、金融、サービス、インフラ、公共、ヘルスケア等）の知見と組み合わせることで価値を創出するもの | C93: 1-4 | D93: ・データ可視化：地図上の可視化「データ分析Ⅰ」（13回目） ・データ解析：パターン発見「データ分析Ⅰ」（14回目） ・データ解析：予測「データ分析Ⅰ」（11-14回目） ・データ解析：予測 「データ分析Ⅰ」（11回目）
C94: 1-5 | D94: ・流通、製造、金融、サービス、インフラ、公共、ヘルスケア等におけるデータ・AI利活用事例紹介「情報社会論」（5、12回目）
...

Sheet 様式１-３　プログラムを構成する授業科目
R1: 様式１-３ | T1: 「学部・学科によって、修了要件は相違する」場合は、本シートを複製の上＜様式１－〇＞と枝番号を付してください
B2: 大学等名 | C2: 愛知学院大学
B3: プログラム名 | C3: 愛知学院大学データサイエンス教育プログラム
A5: プログラムを構成する授業科目について
A7: ① 対象となる学部・学科名称 | J7: ② 教育プログラムの修了要件 | K7: 学部・学科によって、修了要件は相違する
B9: 経営学部
A12: ③ 修了要件
B13: プログラム構成科目である「情報リテラシーⅠ」「情報リテラシーⅡ」「経営と情報Ⅰ」「経営と情報Ⅱ」「経営統計Ⅰ」「経営統計Ⅱ」（専門教育科目）の6科目10単位を取得すること。 | V13: 【プルダウンリスト】
V14: 令和４年度以前より、履修することが必須のプログラムとして実施
V15: 令和７年度までに履修必須とする計画
V16: 令和８年度以降に履修必須とする計画、又は未定
B20: 必要最低単位数 | C20: 10 | E20: 単位 | J20: 履修必須の有無 | K20: 令和８年度以降に履修必須とする計画、又は未定
A22: ④ 現在進行中の社会変化（第４次産業革命、Society 5.0、データ駆動型社会等）に深く寄与しているものであり、それが自らの生活と密接に結びついている」の内容を含む授業科目
B24: 授業科目 | F24: 単位数 | G24: 必須 | H24: 1-1 | I24: 1-6 | J24: 授業科目 | P24: 単位数 | Q24: 必須 | R24: 1-1 | S24: 1-6
B25: 経営と情報Ⅱ | F25: 2 | G25: ○ | H25: ○ | I25: ○
A33: ⑤ 「社会で活用されているデータ」や「データの活用領域」は非常に広範囲であって、日常生活や社会の課題を解決する有用なツールになり得るもの」の内容を含む授業科目
B35: 授業科目 | F35: 単位数 | G35: 必須 | H35: 1-2 | I35: 1-3 | J35: 授業科目 | P35: 単位数 | Q35: 必須 | R35: 1-2 | S35: 1-3
B36: 経営と情報Ⅰ | F36: 2 | G36: ○ | H36: ○ | I36: ○
B37: 経営と情報Ⅱ | F37: 2 | G37: ○ | I37: ○
A44: ⑥ 「様々なデータ利活用の現場におけるデータ利活用事例が示され、様々な適用領域（流通、製造、金融、サービス、インフラ、公共、ヘルスケア等）の知見と組み合わせることで価値を創出するもの」の内容を含む授業科目
B46: 授業科目 | F46: 単位数 | G46: 必須 | H46: 1-4 | I46: 1-5 | J46: 授業科目 | P46: 単位数 | Q46: 必須 | R46: 1-4 | S46: 1-5
B47: 経営と情報Ⅰ | F47: 2 | G47: ○ | H47: ○ | I47: ○
B48: 経営と情報Ⅱ | F48: 2 | G48: ○ | H48: ○
B49: 経営統計Ⅰ | F49: 2 | G49: ○ | H49: ○ | I49: ○
B50: 経営統計Ⅱ | F50: 2 | G50: ○ | I50: ○
A55: ⑦ 「活用に当たっての様々な留意事項（ELSI、個人情報、データ倫理、ＡＩ社会原則等）を考慮し、情報セキュリティや情報漏洩等、データを守る上での留意事項への理解をする」の内容を含む授業科目
B57: 授業科目 | F57: 単位数 | G57: 必須 | H57: 3-1 | I57: 3-2 | J57: 授業科目 | P57: 単位数 | Q57: 必須 | R57: 3-1 | S57: 3-2
B58: 経営と情報Ⅰ | F58: 2 | G58: ○ | H58: ○ | I58: ○
A66: ⑧ 「実データ・実課題（学術データ等を含む）を用いた演習など、社会での実例を題材として、「データを読む、説明する、扱う」といった数理・データサイエンス・ＡＩの基本的な活用法に関するもの」の内容を含む授業科目
B68: 授業科目 | E68: 単位数 | F68: 必須 | G68: 2-1 | H68: 2-2 | I68: 2-3 | J68: 授業科目 | O68: 単位数 | P68: 必須 | Q68: 2-1 | R68: 2-2 | S68: 2-3
B69: 経営統計Ⅰ | E69: 2 | F69: ○ | G69: ○ | H69: ○ | I69: ○
B70: 経営統計Ⅱ | E70: 2 | F70: ○ | G70: ○ | I70: ○
B71: 情報リテラシーⅠ | E71: 1 | F71: ○ | H71: ○ | I71: ○
B72: 情報リテラシーⅡ | E72: 1 | F72: ○ | H72: ○ | I72: ○
A77: ⑨ 選択「４．オプション」の内容を含む授業科目
B78: 授業科目 | F78: 選択項目 | J78: 授業科目 | P78: 選択項目
A87: ⑩ プログラムを構成する授業の内容
B88: 授業に含まれている内容・要素 | D88: 講義内容
B89: （１）現在進行中の社会変化（第４次産業革命、Society 5.0、データ駆動型社会等）に深く寄与しているものであり、それが自らの生活と密接に結びついている | C89: 1-1 | D89: ・第4次産業革命、Society5.0「経営と情報Ⅱ」（14回目）
C90: 1-6 | D90: ・AI等を活用した新しいビジネスモデル「経営と情報Ⅱ」（10回目）
...

Sheet 様式１-４　プログラムを構成する授業科目
R1: 様式１-４ | T1: 「学部・学科によって、修了要件は相違する」場合は、本シートを複製の上＜様式１－〇＞と枝番号を付してください
B2: 大学等名 | C2: 愛知学院大学
B3: プログラム名 | C3: 愛知学院大学データサイエンス教育プログラム
A5: プログラムを構成する授業科目について
A7: ① 対象となる学部・学科名称 | J7: ② 教育プログラムの修了要件 | K7: 学部・学科によって、修了要件は相違する
B9: 経済学部
A12: ③ 修了要件
B13: プログラム構成科目である「情報リテラシーA」「情報リテラシーB」「経済情報論A」（専門教育科目）の3科目6単位を取得すること。 | V13: 【プルダウンリスト】
V14: 令和４年度以前より、履修することが必須のプログラムとして実施
V15: 令和７年度までに履修必須とする計画
V16: 令和８年度以降に履修必須とする計画、又は未定
B20: 必要最低単位数 | C20: 6 | E20: 単位 | J20: 履修必須の有無 | K20: 令和８年度以降に履修必須とする計画、又は未定
A22: ④ 現在進行中の社会変化（第４次産業革命、Society 5.0、データ駆動型社会等）に深く寄与しているものであり、それが自らの生活と密接に結びついている」の内容を含む授業科目
B24: 授業科目 | F24: 単位数 | G24: 必須 | H24: 1-1 | I24: 1-6 | J24: 授業科目 | P24: 単位数 | Q24: 必須 | R24: 1-1 | S24: 1-6
B25: 経済情報論A | F25: 2 | G25: ○ | H25: ○ | I25: ○
A33: ⑤ 「社会で活用されているデータ」や「データの活用領域」は非常に広範囲であって、日常生活や社会の課題を解決する有用なツールになり得るもの」の内容を含む授業科目
B35: 授業科目 | F35: 単位数 | G35: 必須 | H35: 1-2 | I35: 1-3 | J35: 授業科目 | P35: 単位数 | Q35: 必須 | R35: 1-2 | S35: 1-3
B36: 情報リテラシーB | F36: 2 | G36: ○ | H36: ○ | I36: ○
A44: ⑥ 「様々なデータ利活用の現場におけるデータ利活用事例が示され、様々な適用領域（流通、製造、金融、サービス、インフラ、公共、ヘルスケア等）の知見と組み合わせることで価値を創出するもの」の内容を含む授業科目
B46: 授業科目 | F46: 単位数 | G46: 必須 | H46: 1-4 | I46: 1-5 | J46: 授業科目 | P46: 単位数 | Q46: 必須 | R46: 1-4 | S46: 1-5
B47: 情報リテラシーB | F47: 2 | G47: ○ | H47: ○ | I47: ○
A55: ⑦ 「活用に当たっての様々な留意事項（ELSI、個人情報、データ倫理、ＡＩ社会原則等）を考慮し、情報セキュリティや情報漏洩等、データを守る上での留意事項への理解をする」の内容を含む授業科目
B57: 授業科目 | F57: 単位数 | G57: 必須 | H57: 3-1 | I57: 3-2 | J57: 授業科目 | P57: 単位数 | Q57: 必須 | R57: 3-1 | S57: 3-2
B58: 情報リテラシーA | F58: 2 | G58: ○ | H58: ○ | I58: ○
A66: ⑧ 「実データ・実課題（学術データ等を含む）を用いた演習など、社会での実例を題材として、「データを読む、説明する、扱う」といった数理・データサイエンス・ＡＩの基本的な活用法に関するもの」の内容を含む授業科目
B68: 授業科目 | E68: 単位数 | F68: 必須 | G68: 2-1 | H68: 2-2 | I68: 2-3 | J68: 授業科目 | O68: 単位数 | P68: 必須 | Q68: 2-1 | R68: 2-2 | S68: 2-3
B69: 情報リテラシーB | E69: 2 | F69: ○ | G69: ○ | H69: ○ | I69: ○
A77: ⑨ 選択「４．オプション」の内容を含む授業科目
B78: 授業科目 | F78: 選択項目 | J78: 授業科目 | P78: 選択項目
A87: ⑩ プログラムを構成する授業の内容
B88: 授業に含まれている内容・要素 | D88: 講義内容
B89: （１）現在進行中の社会変化（第４次産業革命、Society 5.0、データ駆動型社会等）に深く寄与しているものであり、それが自らの生活と密接に結びついている | C89: 1-1 | D89: ・ビッグデータ、IoT、AI「経済情報論A」（2-4、9、11、13回目）
C90: 1-6 | D90: ・AI最新技術の活用例「経済情報論A」（9、10、12回目）
B91: （２）「社会で活用されているデータ」や「データの活用領域」は非常に広範囲であって、日常生活や社会の課題を解決する有用なツールになり得るもの | C91: 1-2 | D91: ・調査データ、人の行動ログデータ「情報リテラシーB」（1回目）
C92: 1-3 | D92: ・データ・AI活用領域の広がり（生産、消費、文化活動など）「情報リテラシーB」（1回目）
B93: （３）様々なデータ利活用の現場におけるデータ利活用事例が示され、様々な適用領域（流通、製造、金融、サービス、インフラ、公共、ヘルスケア等）の知見と組み合わせることで価値を創出するもの | C93: 1-4 | D93: ・データ可視化：複合グラフ「情報リテラシーB」（12回目）
C94: 1-5 | D94: ・データサイエンスのサイクル（データの取得・管理・加工）「情報リテラシーB」（13、14回目）
B95: （４）活用に当たっての様々な留意事項（ELSI、個人情報、データ倫理、ＡＩ社会原則等）を考慮し、情報セキュリティや情報漏洩等、データを守る上での留意事項への理解をする | C95: 3-1 | D95: ・データ倫理：盗用、プライバシー保護、忘れられる権利、オプトアウト、データバイアス、アルゴリズムバイアス「情報リテラシーA」（4-7、9、10、12回目）
C96: 3-2 | D96: ・暗号化、パスワード、情報漏洩等によるセキュリティ事故の事例紹介「情報リテラシーA」（3、13回目）
B97: （５）実データ・実課題（学術データ等を含む）を用いた演習など、社会での実例を題材として、「データを読む、説明する、扱う」といった数理・データサイエンス・ＡＩの基本的な活用法に関するもの | C97: 2-1 | D97: ・母集団と標本抽出、クロス集計表「情報リテラシーB」（13、14回目）
...

Sheet 様式１-５　プログラムを構成する授業科目
R1: 様式１-５ | T1: 「学部・学科によって、修了要件は相違する」場合は、本シートを複製の上＜様式１－〇＞と枝番号を付してください
B2: 大学等名 | C2: 愛知学院大学
B3: プログラム名 | C3: 愛知学院大学データサイエンス教育プログラム
A5: プログラムを構成する授業科目について
A7: ① 対象となる学部・学科名称 | J7: ② 教育プログラムの修了要件 | K7: 学部・学科によって、修了要件は相違する
B9: 総合政策学部
A12: ③ 修了要件
B13: プログラム構成科目である「情報リテラシーⅡ」及び「データ分析Ⅰ」（専門教育科目）の2科目4単位を取得すること。 | V13: 【プルダウンリスト】
V14: 令和４年度以前より、履修することが必須のプログラムとして実施
V15: 令和７年度までに履修必須とする計画
V16: 令和８年度以降に履修必須とする計画、又は未定
B20: 必要最低単位数 | C20: 4 | E20: 単位 | J20: 履修必須の有無 | K20: 令和４年度以前より、履修することが必須のプログラムとして実施
A22: ④ 現在進行中の社会変化（第４次産業革命、Society 5.0、データ駆動型社会等）に深く寄与しているものであり、それが自らの生活と密接に結びついている」の内容を含む授業科目
B24: 授業科目 | F24: 単位数 | G24: 必須 | H24: 1-1 | I24: 1-6 | J24: 授業科目 | P24: 単位数 | Q24: 必須 | R24: 1-1 | S24: 1-6
B25: 情報リテラシーⅡ | F25: 2 | G25: ○ | H25: ○ | I25: ○
A33: ⑤ 「社会で活用されているデータ」や「データの活用領域」は非常に広範囲であって、日常生活や社会の課題を解決する有用なツールになり得るもの」の内容を含む授業科目
B35: 授業科目 | F35: 単位数 | G35: 必須 | H35: 1-2 | I35: 1-3 | J35: 授業科目 | P35: 単位数 | Q35: 必須 | R35: 1-2 | S35: 1-3
B36: 情報リテラシーⅡ | F36: 2 | G36: ○ | H36: ○ | I36: ○
A44: ⑥ 「様々なデータ利活用の現場におけるデータ利活用事例が示され、様々な適用領域（流通、製造、金融、サービス、インフラ、公共、ヘルスケア等）の知見と組み合わせることで価値を創出するもの」の内容を含む授業科目
B46: 授業科目 | F46: 単位数 | G46: 必須 | H46: 1-4 | I46: 1-5 | J46: 授業科目 | P46: 単位数 | Q46: 必須 | R46: 1-4 | S46: 1-5
B47: 情報リテラシーⅡ | F47: 2 | G47: ○ | H47: ○ | I47: ○
A55: ⑦ 「活用に当たっての様々な留意事項（ELSI、個人情報、データ倫理、ＡＩ社会原則等）を考慮し、情報セキュリティや情報漏洩等、データを守る上での留意事項への理解をする」の内容を含む授業科目
B57: 授業科目 | F57: 単位数 | G57: 必須 | H57: 3-1 | I57: 3-2 | J57: 授業科目 | P57: 単位数 | Q57: 必須 | R57: 3-1 | S57: 3-2
B58: 情報リテラシーⅡ | F58: 2 | G58: ○ | H58: ○ | I58: ○
A66: ⑧ 「実データ・実課題（学術データ等を含む）を用いた演習など、社会での実例を題材として、「データを読む、説明する、扱う」といった数理・データサイエンス・ＡＩの基本的な活用法に関するもの」の内容を含む授業科目
B68: 授業科目 | E68: 単位数 | F68: 必須 | G68: 2-1 | H68: 2-2 | I68: 2-3 | J68: 授業科目 | O68: 単位数 | P68: 必須 | Q68: 2-1 | R68: 2-2 | S68: 2-3
B69: データ分析Ⅰ | E69: 2 | F69: ○ | G69: ○ | H69: ○ | I69: ○
A77: ⑨ 選択「４．オプション」の内容を含む授業科目
B78: 授業科目 | F78: 選択項目 | J78: 授業科目 | P78: 選択項目
A87: ⑩ プログラムを構成する授業の内容
B88: 授業に含まれている内容・要素 | D88: 講義内容
B89: （１）現在進行中の社会変化（第４次産業革命、Society 5.0、データ駆動型社会等）に深く寄与しているものであり、それが自らの生活と密接に結びついている | C89: 1-1 | D89: ・人間の知的活動とAIの関係性 「情報リテラシーII」（4、9、10回目）
C90: 1-6 | D90: ・AI等を活用した新しいビジネスモデル、AI最新技術の活用例「情報リテラシーII」（13、14回目）
B91: （２）「社会で活用されているデータ」や「データの活用領域」は非常に広範囲であって、日常生活や社会の課題を解決する有用なツールになり得るもの | C91: 1-2 | D91: ・調査データ 「情報リテラシーII」（9回目）
C92: 1-3 | D92: ・データ・AI活用領域の広がり（生産、消費、文化活動など）、研究開発「情報リテラシーII」（6回目）
B93: （３）様々なデータ利活用の現場におけるデータ利活用事例が示され、様々な適用領域（流通、製造、金融、サービス、インフラ、公共、ヘルスケア等）の知見と組み合わせることで価値を創出するもの | C93: 1-4 | D93: ・今のAIで出来ることと出来ないこと、自動化技術「情報リテラシーII」（5回目） ・特化型AIと汎用AI 「情報リテラシーII」（6回目）
C94: 1-5 | D94: ・データサイエンスのサイクル（課題解決に向けた提案）、流通、製造、金融、サービス、インフラ、公共、ヘルスケア等におけるデータ・AI利活用事例紹介 「情報リテラシーII」（13回目）
B95: （４）活用に当たっての様々な留意事項（ELSI、個人情報、データ倫理、ＡＩ社会原則等）を考慮し、情報セキュリティや情報漏洩等、データを守る上での留意事項への理解をする | C95: 3-1 | D95: ・プライバシー保護、個人情報保護、AI社会原則、AIサービスの責任論 「情報リテラシーII」（10、14回目）
C96: 3-2 | D96: ・情報セキュリティ：機密性、完全性、可用性「情報リテラシーII」（10回目）
B97: （５）実データ・実課題（学術データ等を含む）を用いた演習など、社会での実例を題材として、「データを読む、説明する、扱う」といった数理・データサイエンス・ＡＩの基本的な活用法に関するもの | C97: 2-1 | D97: ・データの種類「データ分析I」（6-8回目） ・データの分布（ヒストグラム）と代表値「データ分析I」（11、12回目） ・クロス集計表「データ分析I」（13回目）
...

Sheet 様式１-６　プログラムを構成する授業科目
R1: 様式１-６ | T1: 「学部・学科によって、修了要件は相違する」場合は、本シートを複製の上＜様式１－〇＞と枝番号を付してください
B2: 大学等名 | C2: 愛知学院大学
B3: プログラム名 | C3: 愛知学院大学データサイエンス教育プログラム
A5: プログラムを構成する授業科目について
A7: ① 対象となる学部・学科名称 | J7: ② 教育プログラムの修了要件 | K7: 学部・学科によって、修了要件は相違する
B9: 歯学部
A12: ③ 修了要件
B13: プログラム構成科目である「情報の科学」「社会と歯学Ⅰ」「社会と歯学Ⅱ」「社会と歯学Ⅲ」「実習：社会と歯学」（専門教育科目）の5科目7単位を取得すること。 | V13: 【プルダウンリスト】
V14: 令和４年度以前より、履修することが必須のプログラムとして実施
V15: 令和７年度までに履修必須とする計画
V16: 令和８年度以降に履修必須とする計画、又は未定
B20: 必要最低単位数 | C20: 7 | E20: 単位 | J20: 履修必須の有無 | K20: 令和４年度以前より、履修することが必須のプログラムとして実施
A22: ④ 現在進行中の社会変化（第４次産業革命、Society 5.0、データ駆動型社会等）に深く寄与しているものであり、それが自らの生活と密接に結びついている」の内容を含む授業科目
B24: 授業科目 | F24: 単位数 | G24: 必須 | H24: 1-1 | I24: 1-6 | J24: 授業科目 | P24: 単位数 | Q24: 必須 | R24: 1-1 | S24: 1-6
B25: 情報の科学 | F25: 1 | G25: ○ | H25: ○ | I25: ○
A33: ⑤ 「社会で活用されているデータ」や「データの活用領域」は非常に広範囲であって、日常生活や社会の課題を解決する有用なツールになり得るもの」の内容を含む授業科目
B35: 授業科目 | F35: 単位数 | G35: 必須 | H35: 1-2 | I35: 1-3 | J35: 授業科目 | P35: 単位数 | Q35: 必須 | R35: 1-2 | S35: 1-3
B36: 情報の科学 | F36: 1 | G36: ○ | H36: ○ | I36: ○
B37: 社会と歯学Ⅰ | F37: 1 | G37: ○ | H37: ○
B38: 社会と歯学Ⅱ | F38: 2 | G38: ○ | H38: ○
B39: 社会と歯学Ⅲ | F39: 1 | G39: ○ | H39: ○
A44: ⑥ 「様々なデータ利活用の現場におけるデータ利活用事例が示され、様々な適用領域（流通、製造、金融、サービス、インフラ、公共、ヘルスケア等）の知見と組み合わせることで価値を創出するもの」の内容を含む授業科目
B46: 授業科目 | F46: 単位数 | G46: 必須 | H46: 1-4 | I46: 1-5 | J46: 授業科目 | P46: 単位数 | Q46: 必須 | R46: 1-4 | S46: 1-5
B47: 情報の科学 | F47: 1 | G47: ○ | H47: ○ | I47: ○
A55: ⑦ 「活用に当たっての様々な留意事項（ELSI、個人情報、データ倫理、ＡＩ社会原則等）を考慮し、情報セキュリティや情報漏洩等、データを守る上での留意事項への理解をする」の内容を含む授業科目
B57: 授業科目 | F57: 単位数 | G57: 必須 | H57: 3-1 | I57: 3-2 | J57: 授業科目 | P57: 単位数 | Q57: 必須 | R57: 3-1 | S57: 3-2
B58: 情報の科学 | F58: 1 | G58: ○ | H58: ○ | I58: ○
B59: 社会と歯学Ⅲ | F59: 1 | G59: ○ | H59: ○ | I59: ○
A66: ⑧ 「実データ・実課題（学術データ等を含む）を用いた演習など、社会での実例を題材として、「データを読む、説明する、扱う」といった数理・データサイエンス・ＡＩの基本的な活用法に関するもの」の内容を含む授業科目
B68: 授業科目 | E68: 単位数 | F68: 必須 | G68: 2-1 | H68: 2-2 | I68: 2-3 | J68: 授業科目 | O68: 単位数 | P68: 必須 | Q68: 2-1 | R68: 2-2 | S68: 2-3
B69: 情報の科学 | E69: 1 | F69: ○ | G69: ○ | H69: ○ | I69: ○
B70: 実習：社会と歯学 | E70: 2 | F70: ○ | G70: ○ | I70: ○
B71: 社会と歯学Ⅰ | E71: 1 | F71: ○ | G71: ○
B72: 社会と歯学Ⅱ | E72: 2 | F72: ○ | G72: ○ | H72: ○
A77: ⑨ 選択「４．オプション」の内容を含む授業科目
B78: 授業科目 | F78: 選択項目 | J78: 授業科目 | P78: 選択項目
A87: ⑩ プログラムを構成する授業の内容
B88: 授業に含まれている内容・要素 | D88: 講義内容
B89: （１）現在進行中の社会変化（第４次産業革命、Society 5.0、データ駆動型社会等）に深く寄与しているものであり、それが自らの生活と密接に結びついている | C89: 1-1 | D89: ・複数技術を組み合わせたAIサービス「情報の科学」（1回目）
C90: 1-6 | D90: ・AI最新技術の活用例「情報の科学」（1回目）
...

Sheet 様式１-7　プログラムを構成する授業科目
R1: 様式１-７ | T1: 「学部・学科によって、修了要件は相違する」場合は、本シートを複製の上＜様式１－〇＞と枝番号を付してください
B2: 大学等名 | C2: 愛知学院大学
B3: プログラム名 | C3: 愛知学院大学データサイエンス教育プログラム
A5: プログラムを構成する授業科目について
A7: ① 対象となる学部・学科名称 | J7: ② 教育プログラムの修了要件 | K7: 学部・学科によって、修了要件は相違する
B9: 薬学部
A12: ③ 修了要件
B13: プログラム構成科目である「情報処理演習」「製剤工学」「医薬品情報学」「基礎薬学演習Ⅰ」（専門教育科目）の4科目4単位を取得すること。 | V13: 【プルダウンリスト】
V14: 令和４年度以前より、履修することが必須のプログラムとして実施
V15: 令和７年度までに履修必須とする計画
V16: 令和８年度以降に履修必須とする計画、又は未定
B20: 必要最低単位数 | C20: 4 | E20: 単位 | J20: 履修必須の有無 | K20: 令和４年度以前より、履修することが必須のプログラムとして実施
A22: ④ 現在進行中の社会変化（第４次産業革命、Society 5.0、データ駆動型社会等）に深く寄与しているものであり、それが自らの生活と密接に結びついている」の内容を含む授業科目
B24: 授業科目 | F24: 単位数 | G24: 必須 | H24: 1-1 | I24: 1-6 | J24: 授業科目 | P24: 単位数 | Q24: 必須 | R24: 1-1 | S24: 1-6
B25: 情報処理演習 | F25: 1 | G25: ○ | H25: ○
B26: 製剤工学 | F26: 1 | G26: ○ | I26: ○
A33: ⑤ 「社会で活用されているデータ」や「データの活用領域」は非常に広範囲であって、日常生活や社会の課題を解決する有用なツールになり得るもの」の内容を含む授業科目
B35: 授業科目 | F35: 単位数 | G35: 必須 | H35: 1-2 | I35: 1-3 | J35: 授業科目 | P35: 単位数 | Q35: 必須 | R35: 1-2 | S35: 1-3
B36: 情報処理演習 | F36: 1 | G36: ○ | H36: ○ | I36: ○
B37: 製剤工学 | F37: 1 | G37: ○ | I37: ○
A44: ⑥ 「様々なデータ利活用の現場におけるデータ利活用事例が示され、様々な適用領域（流通、製造、金融、サービス、インフラ、公共、ヘルスケア等）の知見と組み合わせることで価値を創出するもの」の内容を含む授業科目
B46: 授業科目 | F46: 単位数 | G46: 必須 | H46: 1-4 | I46: 1-5 | J46: 授業科目 | P46: 単位数 | Q46: 必須 | R46: 1-4 | S46: 1-5
B47: 情報処理演習 | F47: 1 | G47: ○ | I47: ○
B48: 製剤工学 | F48: 1 | G48: ○ | H48: ○ | I48: ○
B49: 医薬品情報学 | F49: 1 | G49: ○ | H49: ○
A55: ⑦ 「活用に当たっての様々な留意事項（ELSI、個人情報、データ倫理、ＡＩ社会原則等）を考慮し、情報セキュリティや情報漏洩等、データを守る上での留意事項への理解をする」の内容を含む授業科目
B57: 授業科目 | F57: 単位数 | G57: 必須 | H57: 3-1 | I57: 3-2 | J57: 授業科目 | P57: 単位数 | Q57: 必須 | R57: 3-1 | S57: 3-2
B58: 基礎薬学演習Ⅰ | F58: 1 | G58: ○ | H58: ○ | I58: ○
B59: 製剤工学 | F59: 1 | G59: ○ | H59: ○ | I59: ○
A66: ⑧ 「実データ・実課題（学術データ等を含む）を用いた演習など、社会での実例を題材として、「データを読む、説明する、扱う」といった数理・データサイエンス・ＡＩの基本的な活用法に関するもの」の内容を含む授業科目
B68: 授業科目 | E68: 単位数 | F68: 必須 | G68: 2-1 | H68: 2-2 | I68: 2-3 | J68: 授業科目 | O68: 単位数 | P68: 必須 | Q68: 2-1 | R68: 2-2 | S68: 2-3
B69: 医薬品情報学 | E69: 1 | F69: ○ | G69: ○ | H69: ○ | I69: ○
B70: 基礎薬学演習Ⅰ | E70: 1 | F70: ○ | H70: ○ | I70: ○
B71: 情報処理演習 | E71: 1 | F71: ○ | H71: ○ | I71: ○
B72: 製剤工学 | E72: 1 | F72: ○ | H72: ○ | I72: ○
A77: ⑨ 選択「４．オプション」の内容を含む授業科目
B78: 授業科目 | F78: 選択項目 | J78: 授業科目 | P78: 選択項目
A87: ⑩ プログラムを構成する授業の内容
B88: 授業に含まれている内容・要素 | D88: 講義内容
B89: （１）現在進行中の社会変化（第４次産業革命、Society 5.0、データ駆動型社会等）に深く寄与しているものであり、それが自らの生活と密接に結びついている | C89: 1-1 | D89: ・ビッグデータ、AI「情報処理演習」（1回目） ・ビッグデータ、AI、Society 5.0、データ駆動型社会、データ爆発、AIの非連続的進化、人間の知的活動とAI の関係性「情報処理演習」（7回目）
...

Sheet 様式２ 履修者等数の実績
AQ1: 様式２
AL2: 大学等名 | AM2: ='様式１-１ プログラムを構成する授業科目'!C2 -> 愛知学院大学
A3: プログラムの履修者数等の実績について
A5: ①プログラム開設年度 | C5: 令和4 | E5: 年度
A7: ②履修者・修了者の実績
B9: 学部・学科名称 | C9: 学生数 | D9: 入学 定員 | E9: 収容 定員 | F9: 令和4年度 | L9: 令和3年度 | R9: 令和2年度 | X9: 令和元年度 | AD9: 平成30年度 | AJ9: 平成29年度 | AP9: 履修者数 合計 | AQ9: 履修率
F10: 履修者数 | I10: 修了者数 | L10: 履修者数 | O10: 修了者数 | R10: 履修者数 | U10: 修了者数 | X10: 履修者数 | AA10: 修了者数 | AD10: 履修者数 | AG10: 修了者数 | AJ10: 履修者数 | AM10: 修了者数
F11: 合計 | G11: 男性 | H11: 女性 | I11: 合計 | J11: 男性 | K11: 女性 | L11: 合計 | M11: 男性 | N11: 女性 | O11: 合計 | P11: 男性 | Q11: 女性 | R11: 合計 | S11: 男性 | T11: 女性 | U11: 合計 | V11: 男性 | W11: 女性 | X11: 合計 | Y11: 男性 | Z11: 女性 | AA11: 合計 | AB11: 男性 | AC11: 女性 | AD11: 合計 | AE11: 男性 | AF11: 女性 | AG11: 合計 | AH11: 男性 | AI11: 女性 | AJ11: 合計 | AK11: 男性 | AL11: 女性 | AM11: 合計 | AN11: 男性 | AO11: 女性
B12: 文学部 | C12: 2187 | D12: 530 | E12: 2145 | F12: 326 | I12: =J12+K12 -> 0 | L12: =M12+N12 -> 0 | O12: =P12+Q12 -> 0 | R12: =S12+T12 -> 0 | U12: =V12+W12 -> 0 | X12: =Y12+Z12 -> 0 | AA12: =AB12+AC12 -> 0 | AD12: =AE12+AF12 -> 0 | AG12: =AH12+AI12 -> 0 | AJ12: =AK12+AL12 -> 0 | AM12: =AN12+AO12 -> 0 | AP12: =F12+L12+R12+X12+AD12+AJ12 -> 326 | AQ12: =AP12/E12 -> 0.15198135
B13: 商学部 | C13: 1029 | D13: 250 | E13: 1005 | F13: 216 | I13: =J13+K13 -> 0 | L13: =M13+N13 -> 0 | O13: =P13+Q13 -> 0 | R13: =S13+T13 -> 0 | U13: =V13+W13 -> 0 | X13: =Y13+Z13 -> 0 | AA13: =AB13+AC13 -> 0 | AD13: =AE13+AF13 -> 0 | AG13: =AH13+AI13 -> 0 | AJ13: =AK13+AL13 -> 0 | AM13: =AN13+AO13 -> 0 | AP13: =F13+L13+R13+X13+AD13+AJ13 -> 216 | AQ13: =AP13/E13 -> 0.21492537
B14: 経営学部 | C14: 1235 | D14: 290 | E14: 1165 | F14: 302 | I14: =J14+K14 -> 0 | L14: =M14+N14 -> 0 | O14: =P14+Q14 -> 0 | R14: =S14+T14 -> 0 | U14: =V14+W14 -> 0 | X14: =Y14+Z14 -> 0 | AA14: =AB14+AC14 -> 0 | AD14: =AE14+AF14 -> 0 | AG14: =AH14+AI14 -> 0 | AJ14: =AK14+AL14 -> 0 | AM14: =AN14+AO14 -> 0 | AP14: =F14+L14+R14+X14+AD14+AJ14 -> 302 | AQ14: =AP14/E14 -> 0.25922747
B15: 経済学部 | C15: 1075 | D15: 250 | E15: 1005 | F15: 264 | I15: =J15+K15 -> 0 | L15: =M15+N15 -> 0 | O15: =P15+Q15 -> 0 | R15: =S15+T15 -> 0 | U15: =V15+W15 -> 0 | X15: =Y15+Z15 -> 0 | AA15: =AB15+AC15 -> 0 | AD15: =AE15+AF15 -> 0 | AG15: =AH15+AI15 -> 0 | AJ15: =AK15+AL15 -> 0 | AM15: =AN15+AO15 -> 0 | AP15: =F15+L15+R15+X15+AD15+AJ15 -> 264 | AQ15: =AP15/E15 -> 0.26268657
B16: 法学部 | C16: 1253 | D16: 295 | E16: 1190 | F16: 71 | I16: =J16+K16 -> 0 | L16: =M16+N16 -> 0 | O16: =P16+Q16 -> 0 | R16: =S16+T16 -> 0 | U16: =V16+W16 -> 0 | X16: =Y16+Z16 -> 0 | AA16: =AB16+AC16 -> 0 | AD16: =AE16+AF16 -> 0 | AG16: =AH16+AI16 -> 0 | AJ16: =AK16+AL16 -> 0 | AM16: =AN16+AO16 -> 0 | AP16: =F16+L16+R16+X16+AD16+AJ16 -> 71 | AQ16: =AP16/E16 -> 0.059663866
B17: 総合政策学部 | C17: 873 | D17: 210 | E17: 845 | F17: 219 | I17: =J17+K17 -> 0 | L17: =M17+N17 -> 0 | O17: =P17+Q17 -> 0 | R17: =S17+T17 -> 0 | U17: =V17+W17 -> 0 | X17: =Y17+Z17 -> 0 | AA17: =AB17+AC17 -> 0 | AD17: =AE17+AF17 -> 0 | AG17: =AH17+AI17 -> 0 | AJ17: =AK17+AL17 -> 0 | AM17: =AN17+AO17 -> 0 | AP17: =F17+L17+R17+X17+AD17+AJ17 -> 219 | AQ17: =AP17/E17 -> 0.2591716
B18: 心身科学部 | C18: 1532 | D18: 260 | E18: 1470 | F18: 235 | I18: =J18+K18 -> 0 | L18: =M18+N18 -> 0 | O18: =P18+Q18 -> 0 | R18: =S18+T18 -> 0 | U18: =V18+W18 -> 0 | X18: =Y18+Z18 -> 0 | AA18: =AB18+AC18 -> 0 | AD18: =AE18+AF18 -> 0 | AG18: =AH18+AI18 -> 0 | AJ18: =AK18+AL18 -> 0 | AM18: =AN18+AO18 -> 0 | AP18: =F18+L18+R18+X18+AD18+AJ18 -> 235 | AQ18: =AP18/E18 -> 0.15986395
B19: 心理学部 | C19: 180 | D19: 160 | E19: 160 | F19: 112 | I19: =J19+K19 -> 0 | L19: =M19+N19 -> 0 | O19: =P19+Q19 -> 0 | R19: =S19+T19 -> 0 | U19: =V19+W19 -> 0 | X19: =Y19+Z19 -> 0 | AA19: =AB19+AC19 -> 0 | AD19: =AE19+AF19 -> 0 | AG19: =AH19+AI19 -> 0 | AJ19: =AK19+AL19 -> 0 | AM19: =AN19+AO19 -> 0 | AP19: =F19+L19+R19+X19+AD19+AJ19 -> 112 | AQ19: =AP19/E19 -> 0.7
B20: 歯学部 | C20: 724 | D20: 125 | E20: 750 | F20: 89 | I20: =J20+K20 -> 0 | L20: =M20+N20 -> 0 | O20: =P20+Q20 -> 0 | R20: =S20+T20 -> 0 | U20: =V20+W20 -> 0 | X20: =Y20+Z20 -> 0 | AA20: =AB20+AC20 -> 0 | AD20: =AE20+AF20 -> 0 | AG20: =AH20+AI20 -> 0 | AJ20: =AK20+AL20 -> 0 | AM20: =AN20+AO20 -> 0 | AP20: =F20+L20+R20+X20+AD20+AJ20 -> 89 | AQ20: =AP20/E20 -> 0.11866667
B21: 薬学部 | C21: 874 | D21: 145 | E21: 870 | F21: 166 | I21: =J21+K21 -> 0 | L21: =M21+N21 -> 0 | O21: =P21+Q21 -> 0 | R21: =S21+T21 -> 0 | U21: =V21+W21 -> 0 | X21: =Y21+Z21 -> 0 | AA21: =AB21+AC21 -> 0 | AD21: =AE21+AF21 -> 0 | AG21: =AH21+AI21 -> 0 | AJ21: =AK21+AL21 -> 0 | AM21: =AN21+AO21 -> 0 | AP21: =F21+L21+R21+X21+AD21+AJ21 -> 166 | AQ21: =AP21/E21 -> 0.1908046
F22: =G22+H22 -> 0 | I22: =J22+K22 -> 0 | L22: =M22+N22 -> 0 | O22: =P22+Q22 -> 0 | R22: =S22+T22 -> 0 | U22: =V22+W22 -> 0 | X22: =Y22+Z22 -> 0 | AA22: =AB22+AC22 -> 0 | AD22: =AE22+AF22 -> 0 | AG22: =AH22+AI22 -> 0 | AJ22: =AK22+AL22 -> 0 | AM22: =AN22+AO22 -> 0 | AP22: =F22+L22+R22+X22+AD22+AJ22 -> 0 | AQ22: =AP22/E22 -> #DIV/0!
F23: =G23+H23 -> 0 | I23: =J23+K23 -> 0 | L23: =M23+N23 -> 0 | O23: =P23+Q23 -> 0 | R23: =S23+T23 -> 0 | U23: =V23+W23 -> 0 | X23: =Y23+Z23 -> 0 | AA23: =AB23+AC23 -> 0 | AD23: =AE23+AF23 -> 0 | AG23: =AH23+AI23 -> 0 | AJ23: =AK23+AL23 -> 0 | AM23: =AN23+AO23 -> 0 | AP23: =F23+L23+R23+X23+AD23+AJ23 -> 0 | AQ23: =AP23/E23 -> #DIV/0!
F24: =G24+H24 -> 0 | I24: =J24+K24 -> 0 | L24: =M24+N24 -> 0 | O24: =P24+Q24 -> 0 | R24: =S24+T24 -> 0 | U24: =V24+W24 -> 0 | X24: =Y24+Z24 -> 0 | AA24: =AB24+AC24 -> 0 | AD24: =AE24+AF24 -> 0 | AG24: =AH24+AI24 -> 0 | AJ24: =AK24+AL24 -> 0 | AM24: =AN24+AO24 -> 0 | AP24: =F24+L24+R24+X24+AD24+AJ24 -> 0 | AQ24: =AP24/E24 -> #DIV/0!
F25: =G25+H25 -> 0 | I25: =J25+K25 -> 0 | L25: =M25+N25 -> 0 | O25: =P25+Q25 -> 0 | R25: =S25+T25 -> 0 | U25: =V25+W25 -> 0 | X25: =Y25+Z25 -> 0 | AA25: =AB25+AC25 -> 0 | AD25: =AE25+AF25 -> 0 | AG25: =AH25+AI25 -> 0 | AJ25: =AK25+AL25 -> 0 | AM25: =AN25+AO25 -> 0 | AP25: =F25+L25+R25+X25+AD25+AJ25 -> 0 | AQ25: =AP25/E25 -> #DIV/0!
F26: =G26+H26 -> 0 | I26: =J26+K26 -> 0 | L26: =M26+N26 -> 0 | O26: =P26+Q26 -> 0 | R26: =S26+T26 -> 0 | U26: =V26+W26 -> 0 | X26: =Y26+Z26 -> 0 | AA26: =AB26+AC26 -> 0 | AD26: =AE26+AF26 -> 0 | AG26: =AH26+AI26 -> 0 | AJ26: =AK26+AL26 -> 0 | AM26: =AN26+AO26 -> 0 | AP26: =F26+L26+R26+X26+AD26+AJ26 -> 0 | AQ26: =AP26/E26 -> #DIV/0!
F27: =G27+H27 -> 0 | I27: =J27+K27 -> 0 | L27: =M27+N27 -> 0 | O27: =P27+Q27 -> 0 | R27: =S27+T27 -> 0 | U27: =V27+W27 -> 0 | X27: =Y27+Z27 -> 0 | AA27: =AB27+AC27 -> 0 | AD27: =AE27+AF27 -> 0 | AG27: =AH27+AI27 -> 0 | AJ27: =AK27+AL27 -> 0 | AM27: =AN27+AO27 -> 0 | AP27: =F27+L27+R27+X27+AD27+AJ27 -> 0 | AQ27: =AP27/E27 -> #DIV/0!
F28: =G28+H28 -> 0 | I28: =J28+K28 -> 0 | L28: =M28+N28 -> 0 | O28: =P28+Q28 -> 0 | R28: =S28+T28 -> 0 | U28: =V28+W28 -> 0 | X28: =Y28+Z28 -> 0 | AA28: =AB28+AC28 -> 0 | AD28: =AE28+AF28 -> 0 | AG28: =AH28+AI28 -> 0 | AJ28: =AK28+AL28 -> 0 | AM28: =AN28+AO28 -> 0 | AP28: =F28+L28+R28+X28+AD28+AJ28 -> 0 | AQ28: =AP28/E28 -> #DIV/0!
F29: =G29+H29 -> 0 | I29: =J29+K29 -> 0 | L29: =M29+N29 -> 0 | O29: =P29+Q29 -> 0 | R29: =S29+T29 -> 0 | U29: =V29+W29 -> 0 | X29: =Y29+Z29 -> 0 | AA29: =AB29+AC29 -> 0 | AD29: =AE29+AF29 -> 0 | AG29: =AH29+AI29 -> 0 | AJ29: =AK29+AL29 -> 0 | AM29: =AN29+AO29 -> 0 | AP29: =F29+L29+R29+X29+AD29+AJ29 -> 0 | AQ29: =AP29/E29 -> #DIV/0!
F30: =G30+H30 -> 0 | I30: =J30+K30 -> 0 | L30: =M30+N30 -> 0 | O30: =P30+Q30 -> 0 | R30: =S30+T30 -> 0 | U30: =V30+W30 -> 0 | X30: =Y30+Z30 -> 0 | AA30: =AB30+AC30 -> 0 | AD30: =AE30+AF30 -> 0 | AG30: =AH30+AI30 -> 0 | AJ30: =AK30+AL30 -> 0 | AM30: =AN30+AO30 -> 0 | AP30: =F30+L30+R30+X30+AD30+AJ30 -> 0 | AQ30: =AP30/E30 -> #DIV/0!
F31: =G31+H31 -> 0 | I31: =J31+K31 -> 0 | L31: =M31+N31 -> 0 | O31: =P31+Q31 -> 0 | R31: =S31+T31 -> 0 | U31: =V31+W31 -> 0 | X31: =Y31+Z31 -> 0 | AA31: =AB31+AC31 -> 0 | AD31: =AE31+AF31 -> 0 | AG31: =AH31+AI31 -> 0 | AJ31: =AK31+AL31 -> 0 | AM31: =AN31+AO31 -> 0 | AP31: =F31+L31+R31+X31+AD31+AJ31 -> 0 | AQ31: =AP31/E31 -> #DIV/0!
B32: 合 計 | C32: =SUM(C12:C31) -> 10962 | D32: =SUM(D12:D31) -> 2515 | E32: =SUM(E12:E31) -> 10605 | F32: =SUM(F12:F31) -> 2000 | G32: =SUM(G12:G31) -> 0 | H32: =SUM(H12:H31) -> 0 | I32: =SUM(I12:I31) -> 0 | J32: =SUM(J12:J31) -> 0 | ... AP32: =SUM(AP12:AP31) -> 2000 | AQ32: =AP32/E32 -> 0.18859029

Sheet 様式３ 教育の質・履修者数を向上させるための体制・計画
I1: 様式３
G2: 大学等名 | H2: ='様式１-１ プログラムを構成する授業科目'!C2 -> 愛知学院大学
A4: 教育の質・履修者数を向上させるための体制・計画について
A6: ① | B6: 全学の教員数 | C6: (常勤） | E6: 465 | F6: 人 | G6: （非常勤） | H6: 1367 | I6: 人
A8: ② | B8: プログラムの授業を教えている教員数 | H8: 51 | I8: 人
A10: ③ | B10: プログラムの運営責任者
B11: （責任者名） | C11: 内藤 勲 | G11: （役職名） | H11: 教務部長
A13: ④ | B13: プログラムを改善・進化させるための体制（委員会・組織等）
B14: 愛知学院大学データサイエンス教育プログラム委員会
B16: （責任者名） | C16: 内藤 勲 | G16: （役職名） | H16: 教務部長
A18: ⑤ | B18: プログラムを改善・進化させるための体制を定める規則名称
B19: 愛知学院大学データサイエンス教育プログラム委員会規程
A21: ⑥ | B21: 体制の目的
B22: 「数理・データサイエンス・A I教育プログラム認定制度」に基づく認定プログラムの立案、実施、改善を継続的に行うため、愛知学院大学データサイエンス教育プログラム委員会を置く。 委員会は、具体的に、 (１)プログラムの立案、実施に関すること。 (２)プログラムの改善に関すること。 (３)プログラムの自己点検・評価に関すること。 (４)数理・データサイエンス・A I教育の全学的な普及、整備に関すること等について審議し、審議結果を学長及び各学部教授会に報告する。
A34: ⑦ | B34: 具体的な構成員
B35: （１）委員長： 教務部長 内藤勲教授（経営学部） （２）文学部 石川弓子准教授 商学部 吉田聡教授 経営学部 千葉賢准教授 経済学部 渡邉隆俊教授 法学部 山野嘉朗教授 総合政策学部 中村悦大教授 心身科学部 渡邉智之教授 心理学部 谷伊織准教授 歯学部 河合達志教授 薬学部 山本浩充教授 教養部 山下秀康准教授 （３）教務部事務部長 橋本秀晃 （４）教務部教務課長 花井久美子 （５）教養部長 佐々木真教授（教養部）・大学教学改革推進企画室事務長 加藤雅人
A48: ⑧ | B48: 履修者数・履修率の向上に向けた計画 ※様式１の「履修必須の有無」で「計画がある」としている場合は詳細について記載すること
B49: 令和４年度実績 | C49: ='様式２ 履修者等数の実績'!AQ32 -> 0.18859029 | E49: 令和５年度予定 | F49: 0.28 | H49: 令和６年度予定 | I49: 0.37
B50: 令和７年度予定 | C50: 0.44 | E50: 令和８年度予定 | F50: 0.51 | H50: 収容定員（名） | I50: ='様式２ 履修者等数の実績'!E32 -> 10605
B51: 具体的な計画
B52: （１）各年度の履修者数の目標値（履修率） 令和５年度 2927名(28％） 令和６年度 3887名（37％） 令和７年度 4699名（44％） 令和８年度 5361名（51％） （２）目標達成に向けた具体的な方策 ※総合政策学部・歯学部・薬学部においては、プログラム対応科目が必修科目であるため、全学生が履修し、年度進行に伴い、当プログラムの履修率は100％になる。 （総合政策学部は令和7年度、歯学部・薬学部は令和9年度） 【令和5年度以降】 ・プログラムについて、学生へ配付している履修要項やポータルサイトでの案内を行い周知し、更に学期毎のオリエンテーションや履修指導において必要な履修科目や就職活動等におけるメリットを周知することにより、履修率の向上を目指す。 ・前年度までの履修実績をモニタリングし、希望者や目標値の実現状況を確認し、次年度の取り組みを検討する。 ・履修中の学生のモチベーションを維持・向上すべく、授業内での質疑応答のほか、オフィスアワーやメール等で相談・指導等体制を整えていく。
A68: ⑨ | B68: 学部・学科に関係なく希望する学生全員が受講可能となるような必要な体制・取組等
B69: 1．文学部・法学部・心身科学部・心理学部においては、教養教育科目の一環として開講している「情報科学Ⅰ・Ⅱ」は1年次、「教養セミナーⅢ・Ⅳ」は2年次開講であり、希望する学生の履修計画に応じて履修出来る体制となっている。また、教室のPCの台数の関係上、受講者数制限があるが、異なる曜日・時限に同名の科目が複数開講されているため、ある程度の数の学生が受講することが可能な体制が整っている。 2．商学部・経営学部・経済学部・総合政策学部・歯学部・薬学部においては、自学部における専門科目をプログラム対応科目としているため、スムーズな履修登録が可能である。 3．総合政策学部・歯学部・薬学部においては、必修の専門科目をプログラム対応科目としているため全学生の受講が可能となっている。
A82: ⑩ | B82: できる限り多くの学生が履修できるような具体的な周知方法・取組
B83: ・学生に対し、履修要項等の履修関係資料だけではなく、オリエンテーションや必修科目内で本プログラム認定制度について説明・周知するとともに、ポータルサイトでのメッセージ機能を用いて周知を行い、履修を促す。 また、大学ホームページのプログラム専用ページにおいて周知するとともに、広報誌や本学専用アプリなどの媒体を通じたプログラム紹介を行い、多くの学生が情報を受け取りやすいように配慮している。 ・具体的授業内容について、シラバスを通じて全学生に公開・周知し、興味を引くように努めている。 ・今後は修了者による学生の声を取り上げて学修成果を発信する。
A96: ⑪ | B96: できる限り多くの学生が履修・修得できるようなサポート体制
B97: ・必修科目等との重複開講を防ぐなど、時間割の工夫により、多くの学生が受講できるように対応する。 ・文学部・法学部・心身科学部・心理学部以外の学部においては、自学部における専門科目をプログラム対応科目としているため、スムーズな履修登録が可能である。 また、総合政策学部・歯学部・薬学部においては、必修の専門科目をプログラム対応科目としているため全学生の受講が可能となっている。 ・学生からの学修上の相談や質問について、担当教員がTeamsやメール、オフィスアワーを通して受け付けることが可能で、多くの学生が修得できるよう支援を行っている。 ・教員もプログラム内容について理解を深め、学生に周知するとともに、学生から相談があれば応じられるようにし、必要に応じて、科目担当者等とも連携し相談に応じられるようにする。
A110: ⑫ | B110: 授業時間内外で学習指導、質問を受け付ける具体的な仕組み
B111: ・Teamsのチャット利用、教員のメールアドレスやオフィスアワーをシラバスや授業を通して学生に伝え、授業時間外でも授業担当者が学生からの質問や指導上の連絡を受け付け、対応する仕組みを整備済である。 必要に応じて、担当教員間で質問等の教育情報を共有して、教育改善に結びつける。 ・PC教室(自習室)の開放を行い、学生がいつでも教材コンテンツにアクセスできるよう授業時間外の自学自習を促す。

Sheet 様式４　自己点検・評価
I1: 様式４
H2: 大学等名 | I2: ='様式１-１ プログラムを構成する授業科目'!C2 -> 愛知学院大学
A3: 自己点検・評価について
A5: ① | B5: プログラムの自己点検・評価を行う体制（委員会・組織等）
B6: 愛知学院大学データサイエンス教育プログラム委員会
D8: （責任者名） | E8: 内藤 勲 | G8: （役職名） | H8: 教務部長
A10: ② | B10: 自己点検・評価体制における意見等
B11: 自己点検・評価の視点 | E11: 自己点検・評価体制における意見・結果・改善に向けた取組等
B12: 学内からの視点
C13: プログラムの履修・修得状況 | E13: 総合政策学部、歯学部、薬学部は、本プログラムを必修科目のみで構成している。必修科目と選択科目で構成している商学部、経済学部と選択科目のみで構成している文学部、経営学部、法学部、心身科学部、心理学部では、教務課と連携して本プログラムの履修・修得状況のデータを共有している。なお、経営学部では、必修科目でないものの大半の学生の履修が確認されている。経営学部と心理学部では授業担当者が、受講者ごとの科目履修状況や課題への回答状況をTeamsやWebCampusを通じて把握できる環境となっている。以上のとおり、本プログラム構成科目を必修科目としている学部とそうでない学部に二分されるが、後者であっても、教務課との連携やネット環境の利用によりその履修・修得状況の把握に努めている。
C14: 学修成果 | E14: 本プログラムを構成する全科目が学部提供科目で構成される商学部・経営学部・経済学部・総合政策学部・歯学部・薬学部の各学部では試験・課題等の成果・成績の経年的な比較や単位修得状況および講義担当者からのフィードバックをもとに学生の理解度や学修成果を把握できる。また、共通の教養教育科目により構成する文学部・法学部・心身科学部・心理学部も、教務課より提供された成績、授業アンケートデータおよび個別学生との面談機会のある学部では直接の面談結果により、学生の理解度や学修成果を把握できる。いずれの学部もその結果をデーターサイエンス教育プログラム委員会へ報告・共有し、教育プログラムの評価・改善を行う。
C15: 学生アンケート等を通じた学生の内容の理解度 | E15: セメスター毎に全学的に実施している「授業アンケート」において、対象分野への関心の高まりや知識・技能向上への役立ちといった項目を通じ、学生の理解度について分析し、その分析結果をもとにして学習内容に対する学生の理解度を推測している。
C16: 学生アンケート等を通じた後輩等他の学生への推奨度 | E16: セメスター毎に全学的に実施している「授業アンケート」の回答結果に基づいて、後輩等他の学生への推奨度について推測している。このアンケートでは、「学問分野への関心」、「知識・技能などの向上」および「受講の満足度」を定量的に把握できる。これに加えて、「自由記述」欄の回答で受講生の具体的な意見を把握できる。定量的な分析だけでなく、この自由記述回答における肯定的な意見を踏まえて、推奨度を評価できる。これらの推奨度に関する分析結果をオリエンテーション等で学生に示し、未受講の学生への講義推奨に活用する。
C17: 全学的な履修者数、履修率向上に向けた計画の達成・進捗状況 | E17: 総合政策学部、歯学部、薬学部では本プログラムを必修科目で構成している。特に、総合政策学部では再履修クラスを設けるなど、単位修得率の向上に向けた取り組みが行われている。必修科目と選択科目で構成している商学部・経済学部と選択科目のみで構成している文学部、経営学部、法学部、心身科学部、心理学部では、オリエンテーションや学習支援室、ホームページ等において、数理・データサイエンス・AI教育の内容についてガイダンスが行われ、より多くの学生が履修選択するように取り組んでいる。なお、商学部では、本年度オリエンテーションでの周知が行われていなかったが、次年度以降、オリエンテーションや講義内で周知し、履修者数を推進する取り組みを実施する予定である。
B18: 学外からの視点
C19: 教育プログラム修了者の進路、活躍状況、企業等の評価 | E19: 現在、すべての学部において本プログラム修了者が卒業していないため、進路、活躍状況および企業等の評価については、把握できていない。しかしながら、現在、各学部がその把握のための具体的な検討を行っている。 例えば、一部学部において、本学キャリアセンター就職課と連携した卒業生の採用状況の実態調査、同窓会を通じた在学生と卒業生の交流機会を利用したヒアリング、外部団体・協会による卒業生に対する就職実態調査、本学の近隣関係企業との交流を通じたヒアリング、卒業生調査による卒業生の進路先や活躍状況の把握等、多様な手法によって、調査結果等に基づいた点検・評価を予定している。
C20: 産業界からの視点を含めた教育プログラム内容・手法等への意見 | E20: 上記項目と同様、現在、本プログラム修了者が卒業していないため、実態を把握できていないが、既に各学部では具体的な検討を行っている。例えば、一部学部において、インターンシップの依頼がある企業、産学官連携講座の協力企業など、キャリアセンターと社会連携センターを通じて意見を収集すること、共同研究等提携企業および本学のシンポジウム等に参加している企業に対してアンケートを実施し、教育プログラムの手法について意見を収集すること、関連するシンポジウム等に参加している企業との意見交換を通じて、本学の取り組みの紹介と教育方法の知見を収集してプログラムの改善を行うこと等、多様な分析手法によって点検・評価を予定している。
B21: 数理・データサイエンス・ＡＩを「学ぶ楽しさ」「学ぶことの意義」を理解させること | E21: 「学ぶ楽しさ」「学ぶことの意義」を理解させるために、各学部や講義の特色に応じ、以下の取り組みを行っている。 ①実務経験のある教員が、開発現場やビジネスで必要となる技術や知識を紹介する。 ②時事やトレンドなどをもとにAIの活用を紹介し、好奇心を喚起する。 ③学生アンケート等を活用し、興味関心の高いトピックを選定する。 ④身近なデータサイエンスやAIに関する技術などを紹介し、学ぶ意義を高める。 ⑤産業界の視点や意見をフィードバックする。 ⑥将来の学びに備え、カリキュラム全体を周知する。 ⑦学生が解決できない問題をフォローし、全員のプログラムの完成を目指す。 ⑧目に見えて達成感を味わえる授業構成とする。
B22: 内容・水準を維持・向上しつつ、より「分かりやすい」授業とすること | E22: 「分かりやすさ」の観点から、講義内容・方法の見直しを定期的に実施している。具体的には、各学部や講義の特色に応じて、以下の取り組みを行っている。 ①学生アンケートや提携企業、卒業生からの意見を参考にした改善を行う。 ②授業内で理解度を確認するための演習やワークを実施する。 ③授業における課題や改善方法について、FD活動を通して教員間で共有、実践する。 ④Teamsなどを活用し、問題を随時解消する。 ⑤学習支援室を利用し、学生への相談体制を整備する。 ⑥授業の各段階にて、学生が前進していることを自覚できる講義構成とする。 ⑦身近な事例を交えて説明し、学生の興味関心を高める。 ⑧科目間連携を高め、次の科目の理解度を高める。
