Workbook

Sheet 様式１-1 外国語学部　プログラムを構成する授業科目
R1: 様式１ー１ | T1: 「学部・学科によって、修了要件は相違する」場合は、本シートを複製の上＜様式１－〇＞と枝番号を付してください
B2: 大学等名 | C2: 文京学院大学
B3: プログラム名 | C3: 文京学院大学データサイエンス ・リテラシープログラム
A5: プログラムを構成する授業科目について
A7: ① 対象となる学部・学科名称 | J7: ② 教育プログラムの修了要件 | K7: 学部・学科によって、修了要件は相違する
B9: 外国語学部・英語コミュニケーション学科
A12: ③ 修了要件
B13: プログラムを構成する「大学特別科目」から２単位以上、「情報処理」から2単位以上、合計4単位以上を取得すること。 大学特別科目：１．データサイエンス入門（1年次/必修/2単位） 情報処理：２．情報処理演習a（1年次/必修/1単位）、２．情報処理演習b（1年次/必修/1単位） なお、データサイエンス入門は、2023年度から全学部対面式で共通内容の授業を行う（2022年度は4学部のうち3学部で共通内容を実施済み）。 | V13: 【プルダウンリスト】
V14: 令和４年度以前より、履修することが必須のプログラムとして実施
V15: 令和７年度までに履修必須とする計画
V16: 令和８年度以降に履修必須とする計画、又は未定
B20: 必要最低単位数 | C20: 4 | E20: 単位 | J20: 履修必須の有無 | K20: 令和７年度までに履修必須とする計画
A22: ④ 現在進行中の社会変化（第４次産業革命、Society 5.0、データ駆動型社会等）に深く寄与しているものであり、それが自らの生活と密接に結びついている」の内容を含む授業科目
B24: 授業科目 | F24: 単位数 | G24: 必須 | H24: 1-1 | I24: 1-6 | J24: 授業科目 | P24: 単位数 | Q24: 必須 | R24: 1-1 | S24: 1-6
B25: データサイエンス入門 | F25: 2 | G25: ○ | H25: ○ | I25: ○
A33: ⑤ 「社会で活用されているデータ」や「データの活用領域」は非常に広範囲であって、日常生活や社会の課題を解決する有用なツールになり得るもの」の内容を含む授業科目
B35: 授業科目 | F35: 単位数 | G35: 必須 | H35: 1-2 | I35: 1-3 | J35: 授業科目 | P35: 単位数 | Q35: 必須 | R35: 1-2 | S35: 1-3
B36: データサイエンス入門 | F36: 2 | G36: ○ | H36: ○ | I36: ○
A44: ⑥ 「様々なデータ利活用の現場におけるデータ利活用事例が示され、様々な適用領域（流通、製造、金融、サービス、インフラ、公共、ヘルスケア等）の知見と組み合わせることで価値を創出するもの」の内容を含む授業科目
B46: 授業科目 | F46: 単位数 | G46: 必須 | H46: 1-4 | I46: 1-5 | J46: 授業科目 | P46: 単位数 | Q46: 必須 | R46: 1-4 | S46: 1-5
B47: データサイエンス入門 | F47: 2 | G47: ○ | H47: ○ | I47: ○
A55: ⑦ 「活用に当たっての様々な留意事項（ELSI、個人情報、データ倫理、ＡＩ社会原則等）を考慮し、情報セキュリティや情報漏洩等、データを守る上での留意事項への理解をする」の内容を含む授業科目
B57: 授業科目 | F57: 単位数 | G57: 必須 | H57: 3-1 | I57: 3-2 | J57: 授業科目 | P57: 単位数 | Q57: 必須 | R57: 3-1 | S57: 3-2
B58: データサイエンス入門 | F58: 2 | G58: ○ | H58: ○ | I58: ○
B59: 情報処理演習a | F59: 1 | G59: ○ | H59: ○ | I59: ○
A66: ⑧ 「実データ・実課題（学術データ等を含む）を用いた演習など、社会での実例を題材として、「データを読む、説明する、扱う」といった数理・データサイエンス・ＡＩの基本的な活用法に関するもの」の内容を含む授業科目
B68: 授業科目 | E68: 単位数 | F68: 必須 | G68: 2-1 | H68: 2-2 | I68: 2-3 | J68: 授業科目 | O68: 単位数 | P68: 必須 | Q68: 2-1 | R68: 2-2 | S68: 2-3
B69: 情報処理演習b | E69: 1 | F69: ○ | G69: ○ | H69: ○ | I69: ○
A77: ⑨ 選択「４．オプション」の内容を含む授業科目
B78: 授業科目 | F78: 選択項目 | J78: 授業科目 | P78: 選択項目
A87: ⑩ プログラムを構成する授業の内容
B88: 授業に含まれている内容・要素 | D88: 講義内容
B89: （１）現在進行中の社会変化（第４次産業革命、Society 5.0、データ駆動型社会等）に深く寄与しているものであり、それが自らの生活と密接に結びついている | C89: 1-1 | D89: 社会で起きている変化 ・現代社会におけるデータサイエンスの役割と重要性（ビッグデータ、データ駆動型社会、IoT、AI）「データサイエンス入門」（1回目）
C90: 1-6 | D90: データ・AI利活用の最新動向 ・現代社会におけるデータサイエンスの役割と重要性（AI炊飯器からのレコメンデーション、自動消火ガスコンロ）「データサイエンス入門」（1回目） ・データサイエンス入門おけるAIの基礎（ニューラルネットワーク、強化学習）「データサイエンス入門」（14回目）
B91: （２）「社会で活用されているデータ」や「データの活用領域」は非常に広範囲であって、日常生活や社会の課題を解決する有用なツールになり得るもの | C91: 1-2 | D91: 社会で活用されているデータ ・現代社会におけるデータサイエンスの役割と重要性（非構造化データ、機械の稼働ログデータ）「データサイエンス入門」（1回目） ・データのタイプと特徴(調査データ、データ作成)「データサイエンス入門」（2回目） ・データの収集と整形（データのオープン化）「データサイエンス入門」（3回目）
C92: 1-3 | D92: データ・AIの活用領域 ・現代社会におけるデータサイエンスの役割と重要性（データ・AI活用領域の広がり）「データサイエンス入門」（1回目） ・データのタイプと特徴（調達、マーケティング、サービス）「データサイエンス入門」（2回目） ・データの収集と整形（計画策定）「データサイエンス入門」（3回目） ・データサイエンス入門おけるAIの基礎（データ・AI活用領域の広がり、知識発見）「データサイエンス入門」（14回目）
B93: （３）様々なデータ利活用の現場におけるデータ利活用事例が示され、様々な適用領域（流通、製造、金融、サービス、インフラ、公共、ヘルスケア等）の知見と組み合わせることで価値を創出するもの | C93: 1-4 | D93: データ・AI利活用のための技術 ・現代社会におけるデータサイエンスの役割と重要性(ルールベース、自動化技術)「データサイエンス入門」（1回目） ・データ可視化やデータ解析（クラスター分析、主成分分析、回帰分析、ニューラルネットワーク等）の活用「データサイエンス入や門」（7回目、8回目、10回目、15回目）
C94: 1-5 | D94: データ・AI利活用の現場 ・現代社会におけるデータサイエンスの役割と重要性（データサイエンスのサイクル）「データサイエンス入門」（1回目） ・流通、サービス、ヘルスケアのデータ・AI活用事例「データサイエンス入門」（7回目、8回目、10回目、15回目）
B95: （４）活用に当たっての様々な留意事項（ELSI、個人情報、データ倫理、ＡＩ社会原則等）を考慮し、情報セキュリティや情報漏洩等、データを守る上での留意事項への理解をする | C95: 3-1 | D95: データ・AI利活用における留意事項 ・データの倫理（個人情報保護、データの倫理、データバイアス）「データサイエンス入門」（13回目） ・情報倫理と自己防衛(個人情報保護、プライバシー保護)「情報処理演習a」（4回目）
C96: 3-2 | D96: データを守る上での留意事項 ・データの倫理（匿名加工情報、悪意ある情報搾取）「データサイエンス入門」（13回目） ・情報倫理と自己防衛（情報セキュリティー、パスワード）「情報処理演習a」（4回目）
...

Sheet 様式１-2 経営学部　プログラムを構成する授業科目
R1: 様式１ー２ | T1: 「学部・学科によって、修了要件は相違する」場合は、本シートを複製の上＜様式１－〇＞と枝番号を付してください
B2: 大学等名 | C2: 文京学院大学
B3: プログラム名 | C3: 文京学院大学データサイエンス ・リテラシープログラム
A5: プログラムを構成する授業科目について
A7: ① 対象となる学部・学科名称 | J7: ② 教育プログラムの修了要件 | K7: 学部・学科によって、修了要件は相違する
B9: 経営学部・経営コミュニケーション学科、経営学部・マーケティング・デザイン学科
A12: ③ 修了要件
B13: プログラムを構成する「大学特別科目」から２単位以上、「学部共通科目」から2単位以上、合計4単位以上を取得すること。 大学特別科目：１．データサイエンス入門（1年次/必修/2単位） 学部共通科目：２．統計学a（1年次/選択/2単位） なお、データサイエンス入門は、2023年度から全学部対面式で共通内容の授業を行う（2022年度は4学部のうち3学部で共通内容を実施済み）。 | V13: 【プルダウンリスト】
V14: 令和４年度以前より、履修することが必須のプログラムとして実施
V15: 令和７年度までに履修必須とする計画
V16: 令和８年度以降に履修必須とする計画、又は未定
B20: 必要最低単位数 | C20: 4 | E20: 単位 | J20: 履修必須の有無 | K20: 令和７年度までに履修必須とする計画
A22: ④ 現在進行中の社会変化（第４次産業革命、Society 5.0、データ駆動型社会等）に深く寄与しているものであり、それが自らの生活と密接に結びついている」の内容を含む授業科目
B24: 授業科目 | F24: 単位数 | G24: 必須 | H24: 1-1 | I24: 1-6 | J24: 授業科目 | P24: 単位数 | Q24: 必須 | R24: 1-1 | S24: 1-6
B25: データサイエンス入門 | F25: 2 | G25: ○ | H25: ○ | I25: ○
A33: ⑤ 「社会で活用されているデータ」や「データの活用領域」は非常に広範囲であって、日常生活や社会の課題を解決する有用なツールになり得るもの」の内容を含む授業科目
B35: 授業科目 | F35: 単位数 | G35: 必須 | H35: 1-2 | I35: 1-3 | J35: 授業科目 | P35: 単位数 | Q35: 必須 | R35: 1-2 | S35: 1-3
B36: データサイエンス入門 | F36: 2 | G36: ○ | H36: ○ | I36: ○
A44: ⑥ 「様々なデータ利活用の現場におけるデータ利活用事例が示され、様々な適用領域（流通、製造、金融、サービス、インフラ、公共、ヘルスケア等）の知見と組み合わせることで価値を創出するもの」の内容を含む授業科目
B46: 授業科目 | F46: 単位数 | G46: 必須 | H46: 1-4 | I46: 1-5 | J46: 授業科目 | P46: 単位数 | Q46: 必須 | R46: 1-4 | S46: 1-5
B47: データサイエンス入門 | F47: 2 | G47: ○ | H47: ○ | I47: ○
A55: ⑦ 「活用に当たっての様々な留意事項（ELSI、個人情報、データ倫理、ＡＩ社会原則等）を考慮し、情報セキュリティや情報漏洩等、データを守る上での留意事項への理解をする」の内容を含む授業科目
B57: 授業科目 | F57: 単位数 | G57: 必須 | H57: 3-1 | I57: 3-2 | J57: 授業科目 | P57: 単位数 | Q57: 必須 | R57: 3-1 | S57: 3-2
B58: データサイエンス入門 | F58: 2 | G58: ○ | H58: ○ | I58: ○
A66: ⑧ 「実データ・実課題（学術データ等を含む）を用いた演習など、社会での実例を題材として、「データを読む、説明する、扱う」といった数理・データサイエンス・ＡＩの基本的な活用法に関するもの」の内容を含む授業科目
B68: 授業科目 | E68: 単位数 | F68: 必須 | G68: 2-1 | H68: 2-2 | I68: 2-3 | J68: 授業科目 | O68: 単位数 | P68: 必須 | Q68: 2-1 | R68: 2-2 | S68: 2-3
B69: 統計学a | E69: 2 | F69: ○ | G69: ○ | H69: ○ | I69: ○
A77: ⑨ 選択「４．オプション」の内容を含む授業科目
B78: 授業科目 | F78: 選択項目 | J78: 授業科目 | P78: 選択項目
A87: ⑩ プログラムを構成する授業の内容
B88: 授業に含まれている内容・要素 | D88: 講義内容
B89: （１）現在進行中の社会変化（第４次産業革命、Society 5.0、データ駆動型社会等）に深く寄与しているものであり、それが自らの生活と密接に結びついている | C89: 1-1 | D89: 社会で起きている変化 ・現代社会におけるデータサイエンスの役割と重要性（ビッグデータ、データ駆動型社会、IoT、AI）「データサイエンス入門」（1回目）
C90: 1-6 | D90: データ・AI利活用の最新動向 ・現代社会におけるデータサイエンスの役割と重要性（AI炊飯器からのレコメンデーション、自動消火ガスコンロ）「データサイエンス入門」（1回目） ・データサイエンス入門おけるAIの基礎（ニューラルネットワーク、強化学習）「データサイエンス入門」（14回目）
B91: （２）「社会で活用されているデータ」や「データの活用領域」は非常に広範囲であって、日常生活や社会の課題を解決する有用なツールになり得るもの | C91: 1-2 | D91: 社会で活用されているデータ ・現代社会におけるデータサイエンスの役割と重要性（非構造化データ、機械の稼働ログデータ）「データサイエンス入門」（1回目） ・データのタイプと特徴(調査データ、データ作成)「データサイエンス入門」（2回目） ・データの収集と整形（データのオープン化）「データサイエンス入門」（3回目）
C92: 1-3 | D92: データ・AIの活用領域 ・現代社会におけるデータサイエンスの役割と重要性（データ・AI活用領域の広がり）「データサイエンス入門」（1回目） ・データのタイプと特徴（調達、マーケティング、サービス）「データサイエンス入門」（2回目） ・データの収集と整形（計画策定）「データサイエンス入門」（3回目） ・データサイエンス入門おけるAIの基礎（データ・AI活用領域の広がり、知識発見）「データサイエンス入門」（14回目）
B93: （３）様々なデータ利活用の現場におけるデータ利活用事例が示され、様々な適用領域（流通、製造、金融、サービス、インフラ、公共、ヘルスケア等）の知見と組み合わせることで価値を創出するもの | C93: 1-4 | D93: データ・AI利活用のための技術 ・現代社会におけるデータサイエンスの役割と重要性(ルールベース、自動化技術)「データサイエンス入門」（1回目） ・データ可視化やデータ解析（クラスター分析、主成分分析、回帰分析、ニューラルネットワーク等）の活用「データサイエンス入や門」（7回目、8回目、10回目、15回目）
C94: 1-5 | D94: データ・AI利活用の現場 ・現代社会におけるデータサイエンスの役割と重要性（データサイエンスのサイクル）「データサイエンス入門」（1回目） ・流通、サービス、ヘルスケアのデータ・AI活用事例「データサイエンス入門」（7回目、8回目、10回目、15回目）
B95: （４）活用に当たっての様々な留意事項（ELSI、個人情報、データ倫理、ＡＩ社会原則等）を考慮し、情報セキュリティや情報漏洩等、データを守る上での留意事項への理解をする | C95: 3-1 | D95: データ・AI利活用における留意事項 ・データの倫理（個人情報保護、データの倫理、データバイアス）「データサイエンス入門」（13回目）
C96: 3-2 | D96: データを守る上での留意事項 ・データの倫理（匿名加工情報、悪意ある情報搾取）「データサイエンス入門」（13回目）
B97: （５）実データ・実課題（学術データ等を含む）を用いた演習など、社会での実例を題材として、「データを読む、説明する、扱う」といった数理・データサイエンス・ＡＩの基本的な活用法に関するもの | C97: 2-1 | D97: データを読む・データを説明する（データの種類、データの分布、代表値の性質の違い、データのばらつき、相関と因果、母集団と標本抽出、クロス集計表、統計情報の正しい理解） ・データの性質（質的なデータと量的なデータ）、基礎統計量とExcelを利用したその計算「統計学a」（4回） ・１変数の分析：質的なデータの場合「統計学a」（5回） ・１変数の分析：量的なデータの場合「統計学a」（6回）
...

Sheet 様式１-3 保健医療技術部　プログラムを構成する授業科目 
R1: 様式１ー３ | T1: 「学部・学科によって、修了要件は相違する」場合は、本シートを複製の上＜様式１－〇＞と枝番号を付してください
B2: 大学等名 | C2: 文京学院大学
B3: プログラム名 | C3: 文京学院大学データサイエンス ・リテラシープログラム
A5: プログラムを構成する授業科目について
A7: ① 対象となる学部・学科名称 | J7: ② 教育プログラムの修了要件 | K7: 学部・学科によって、修了要件は相違する
B9: 保健医療技術学部・理学療法学科、保健医療技術学部・作業療法学科、保健医療技術学部・臨床検査学科、保健医療技術学部・看護学科
A12: ③ 修了要件
B13: プログラムを構成する「大学特別科目」から２単位以上、「学科別の科目」から1単位以上、合計3単位以上を取得すること。 大学特別科目：１．データサイエンス入門（1年次/必修/2単位） 学科別の科目：２．統計学（看護学科1年次/必修/2単位）、３．統計学（理学療法学科及び作業療法学科2年次/必修/2単位）、４．医療情報処理演習Ⅱ（臨床検査学科4年次/必修/1単位） なお、データサイエンス入門は、2023年度から全学部対面式で共通内容の授業を行う（2022年度は4学部のうち3学部で共通内容を実施済み）。 | V13: 【プルダウンリスト】
V14: 令和４年度以前より、履修することが必須のプログラムとして実施
V15: 令和７年度までに履修必須とする計画
V16: 令和８年度以降に履修必須とする計画、又は未定
B20: 必要最低単位数 | C20: 3 | E20: 単位 | J20: 履修必須の有無 | K20: 令和７年度までに履修必須とする計画
A22: ④ 現在進行中の社会変化（第４次産業革命、Society 5.0、データ駆動型社会等）に深く寄与しているものであり、それが自らの生活と密接に結びついている」の内容を含む授業科目
B24: 授業科目 | F24: 単位数 | G24: 必須 | H24: 1-1 | I24: 1-6 | J24: 授業科目 | P24: 単位数 | Q24: 必須 | R24: 1-1 | S24: 1-6
B25: データサイエンス入門 | F25: 2 | G25: ○ | H25: ○ | I25: ○
A33: ⑤ 「社会で活用されているデータ」や「データの活用領域」は非常に広範囲であって、日常生活や社会の課題を解決する有用なツールになり得るもの」の内容を含む授業科目
B35: 授業科目 | F35: 単位数 | G35: 必須 | H35: 1-2 | I35: 1-3 | J35: 授業科目 | P35: 単位数 | Q35: 必須 | R35: 1-2 | S35: 1-3
B36: データサイエンス入門 | F36: 2 | G36: ○ | H36: ○ | I36: ○
A44: ⑥ 「様々なデータ利活用の現場におけるデータ利活用事例が示され、様々な適用領域（流通、製造、金融、サービス、インフラ、公共、ヘルスケア等）の知見と組み合わせることで価値を創出するもの」の内容を含む授業科目
B46: 授業科目 | F46: 単位数 | G46: 必須 | H46: 1-4 | I46: 1-5 | J46: 授業科目 | P46: 単位数 | Q46: 必須 | R46: 1-4 | S46: 1-5
B47: データサイエンス入門 | F47: 2 | G47: ○ | H47: ○ | I47: ○
B48: 医療情報処理演習Ⅱ（臨床検査学科） | F48: 1 | H48: ○ | I48: ○
A55: ⑦ 「活用に当たっての様々な留意事項（ELSI、個人情報、データ倫理、ＡＩ社会原則等）を考慮し、情報セキュリティや情報漏洩等、データを守る上での留意事項への理解をする」の内容を含む授業科目
B57: 授業科目 | F57: 単位数 | G57: 必須 | H57: 3-1 | I57: 3-2 | J57: 授業科目 | P57: 単位数 | Q57: 必須 | R57: 3-1 | S57: 3-2
B58: データサイエンス入門 | F58: 2 | G58: ○ | H58: ○ | I58: ○
A66: ⑧ 「実データ・実課題（学術データ等を含む）を用いた演習など、社会での実例を題材として、「データを読む、説明する、扱う」といった数理・データサイエンス・ＡＩの基本的な活用法に関するもの」の内容を含む授業科目
B68: 授業科目 | E68: 単位数 | F68: 必須 | G68: 2-1 | H68: 2-2 | I68: 2-3 | J68: 授業科目 | O68: 単位数 | P68: 必須 | Q68: 2-1 | R68: 2-2 | S68: 2-3
B69: 統計学（看護学科1年次） | E69: 2 | G69: ○ | H69: ○ | I69: ○
B70: 統計学（理学療法学科2年次） | E70: 2 | G70: ○ | H70: ○ | I70: ○
B71: 統計学（作業療法学科2年次） | E71: 2 | G71: ○ | H71: ○ | I71: ○
B72: 医療情報処理演習Ⅱ（臨床検査学科４年次） | E72: 1 | G72: ○ | H72: ○ | I72: ○
A77: ⑨ 選択「４．オプション」の内容を含む授業科目
B78: 授業科目 | F78: 選択項目 | J78: 授業科目 | P78: 選択項目
A87: ⑩ プログラムを構成する授業の内容
B88: 授業に含まれている内容・要素 | D88: 講義内容
B89: （１）現在進行中の社会変化（第４次産業革命、Society 5.0、データ駆動型社会等）に深く寄与しているものであり、それが自らの生活と密接に結びついている | C89: 1-1 | D89: 社会で起きている変化 ・現代社会におけるデータサイエンスの役割と重要性（ビッグデータ、データ駆動型社会、IoT、AI）「データサイエンス入門」（1回目）
C90: 1-6 | D90: データ・AI利活用の最新動向 ・現代社会におけるデータサイエンスの役割と重要性（AI炊飯器からのレコメンデーション、自動消火ガスコンロ）「データサイエンス入門」（1回目） ・データサイエンス入門おけるAIの基礎（ニューラルネットワーク、強化学習）「データサイエンス入門」（14回目）
B91: （２）「社会で活用されているデータ」や「データの活用領域」は非常に広範囲であって、日常生活や社会の課題を解決する有用なツールになり得るもの | C91: 1-2 | D91: 社会で活用されているデータ ・現代社会におけるデータサイエンスの役割と重要性（非構造化データ、機械の稼働ログデータ）「データサイエンス入門」（1回目） ・データのタイプと特徴(調査データ、データ作成)「データサイエンス入門」（2回目） ・データの収集と整形（データのオープン化）「データサイエンス入門」（3回目）
C92: 1-3 | D92: データ・AIの活用領域 ・現代社会におけるデータサイエンスの役割と重要性（データ・AI活用領域の広がり）「データサイエンス入門」（1回目） ・データのタイプと特徴（調達、マーケティング、サービス）「データサイエンス入門」（2回目） ・データの収集と整形（計画策定）「データサイエンス入門」（3回目） ・データサイエンス入門おけるAIの基礎（データ・AI活用領域の広がり、知識発見）「データサイエンス入門」（14回目）
B93: （３）様々なデータ利活用の現場におけるデータ利活用事例が示され、様々な適用領域（流通、製造、金融、サービス、インフラ、公共、ヘルスケア等）の知見と組み合わせることで価値を創出するもの | C93: 1-4 | D93: データ・AI利活用のための技術（データ解析、データ可視化） ・現代社会におけるデータサイエンスの役割と重要性「データサイエンス入門」（1回目） ・クラスター分析、主成分分析、回帰分析、ニューラルネットワーク等の活用「データサイエンス入門」（7回目、8回目、10回目、15回目） ・クラスター分析、主成分分析、回帰分析等の活用「医療情報処理演習Ⅱ（臨床検査学科）」（8回目から12回目）
...

Sheet 様式１-４ 人間学部　プログラムを構成する授業科目
R1: 様式１ー４ | T1: 「学部・学科によって、修了要件は相違する」場合は、本シートを複製の上＜様式１－〇＞と枝番号を付してください
B2: 大学等名 | C2: 文京学院大学
B3: プログラム名 | C3: 文京学院大学データサイエンス ・リテラシープログラム
A5: プログラムを構成する授業科目について
A7: ① 対象となる学部・学科名称 | J7: ② 教育プログラムの修了要件 | K7: 学部・学科によって、修了要件は相違する
B9: 人間学部・児童発達学科、人間学部・心理学科、人間学部・コミュニケーション社会学科、人間学部・人間福祉学科
A12: ③ 修了要件
B13: プログラムを構成する「大学特別科目」から２単位以上、「学科別の科目」から1単位以上、合計3単位以上を取得すること。 大学特別科目：１．データサイエンス入門（1年次/必修/2単位） 学科別の科目：２．心理学統計法Ⅰ（心理学科1年次/必修/2単位）、３．社会統計学Ⅰ（コミュニケーション社会学科年次/必修/2単位）、４．情報処理演習Ⅰ（人間福祉学科1年次/必修/2単位）、５．情報メディア演習（児童発達学科1年次/選択/2単位）、６．情報機器の操作（児童発達学科2年次/選択/2単位）、７．算数（児童発達学科1年次/選択/2単位） なお、データサイエンス入門は、2023年度から全学部対面式で共通内容の授業を行う（2022年度は4学部のうち3学部で共通内容を実施済み）。 | V13: 【プルダウンリスト】
V14: 令和４年度以前より、履修することが必須のプログラムとして実施
V15: 令和７年度までに履修必須とする計画
V16: 令和８年度以降に履修必須とする計画、又は未定
B20: 必要最低単位数 | C20: 4 | E20: 単位 | J20: 履修必須の有無 | K20: 令和７年度までに履修必須とする計画
A22: ④ 現在進行中の社会変化（第４次産業革命、Society 5.0、データ駆動型社会等）に深く寄与しているものであり、それが自らの生活と密接に結びついている」の内容を含む授業科目
B24: 授業科目 | F24: 単位数 | G24: 必須 | H24: 1-1 | I24: 1-6 | J24: 授業科目 | P24: 単位数 | Q24: 必須 | R24: 1-1 | S24: 1-6
B25: データサイエンス入門 | F25: 2 | G25: ○ | H25: ○ | I25: ○
A33: ⑤ 「社会で活用されているデータ」や「データの活用領域」は非常に広範囲であって、日常生活や社会の課題を解決する有用なツールになり得るもの」の内容を含む授業科目
B35: 授業科目 | F35: 単位数 | G35: 必須 | H35: 1-2 | I35: 1-3 | J35: 授業科目 | P35: 単位数 | Q35: 必須 | R35: 1-2 | S35: 1-3
B36: データサイエンス入門 | F36: 2 | G36: ○ | H36: ○ | I36: ○
A44: ⑥ 「様々なデータ利活用の現場におけるデータ利活用事例が示され、様々な適用領域（流通、製造、金融、サービス、インフラ、公共、ヘルスケア等）の知見と組み合わせることで価値を創出するもの」の内容を含む授業科目
B46: 授業科目 | F46: 単位数 | G46: 必須 | H46: 1-4 | I46: 1-5 | J46: 授業科目 | P46: 単位数 | Q46: 必須 | R46: 1-4 | S46: 1-5
B47: データサイエンス入門 | F47: 2 | G47: ○ | H47: ○ | I47: ○
A55: ⑦ 「活用に当たっての様々な留意事項（ELSI、個人情報、データ倫理、ＡＩ社会原則等）を考慮し、情報セキュリティや情報漏洩等、データを守る上での留意事項への理解をする」の内容を含む授業科目
B57: 授業科目 | F57: 単位数 | G57: 必須 | H57: 3-1 | I57: 3-2 | J57: 授業科目 | P57: 単位数 | Q57: 必須 | R57: 3-1 | S57: 3-2
B58: データサイエンス入門 | F58: 2 | G58: ○ | H58: ○ | I58: ○
A66: ⑧ 「実データ・実課題（学術データ等を含む）を用いた演習など、社会での実例を題材として、「データを読む、説明する、扱う」といった数理・データサイエンス・ＡＩの基本的な活用法に関するもの」の内容を含む授業科目
B68: 授業科目 | E68: 単位数 | F68: 必須 | G68: 2-1 | H68: 2-2 | I68: 2-3 | J68: 授業科目 | O68: 単位数 | P68: 必須 | Q68: 2-1 | R68: 2-2 | S68: 2-3
B69: 心理学統計法Ⅰ（心理学科1年次） | E69: 2 | G69: ○ | H69: ○ | I69: ○
B70: 社会統計学Ⅰ（コミュニケーション社会学科2年次） | E70: 2 | G70: ○ | H70: ○ | I70: ○
B71: 情報処理演習Ⅰ（人間福祉学科1年次） | E71: 2 | G71: ○ | H71: ○ | I71: ○
B72: 情報メディア演習（児童発達学科1年次） | E72: 2 | G72: ○ | H72: ○ | I72: ○
B73: 情報機器の操作（児童発達学科2年次） | E73: 2 | G73: ○ | H73: ○ | I73: ○
B74: 算数（児童発達学科2年次） | E74: 2 | G74: ○ | H74: ○ | I74: ○
A77: ⑨ 選択「４．オプション」の内容を含む授業科目
B78: 授業科目 | F78: 選択項目 | J78: 授業科目 | P78: 選択項目
A87: ⑩ プログラムを構成する授業の内容
B88: 授業に含まれている内容・要素 | D88: 講義内容
B89: （１）現在進行中の社会変化（第４次産業革命、Society 5.0、データ駆動型社会等）に深く寄与しているものであり、それが自らの生活と密接に結びついている | C89: 1-1 | D89: 社会で起きている変化 ・現代社会におけるデータサイエンスの役割と重要性（ビッグデータ、データ駆動型社会、IoT、AI）「データサイエンス入門」（1回目）
C90: 1-6 | D90: データ・AI利活用の最新動向 ・現代社会におけるデータサイエンスの役割と重要性（AI炊飯器からのレコメンデーション、自動消火ガスコンロ）「データサイエンス入門」（1回目） ・データサイエンス入門おけるAIの基礎（ニューラルネットワーク、強化学習）「データサイエンス入門」（14回目）
B91: （２）「社会で活用されているデータ」や「データの活用領域」は非常に広範囲であって、日常生活や社会の課題を解決する有用なツールになり得るもの | C91: 1-2 | D91: 社会で活用されているデータ ・現代社会におけるデータサイエンスの役割と重要性（非構造化データ、機械の稼働ログデータ）「データサイエンス入門」（1回目） ・データのタイプと特徴(調査データ、データ作成)「データサイエンス入門」（2回目） ・データの収集と整形（データのオープン化）「データサイエンス入門」（3回目）
C92: 1-3 | D92: データ・AIの活用領域 ・現代社会におけるデータサイエンスの役割と重要性（データ・AI活用領域の広がり）「データサイエンス入門」（1回目） ・データのタイプと特徴（調達、マーケティング、サービス）「データサイエンス入門」（2回目） ・データの収集と整形（計画策定）「データサイエンス入門」（3回目） ・データサイエンス入門おけるAIの基礎（データ・AI活用領域の広がり、知識発見）「データサイエンス入門」（14回目）
...

Sheet 様式２ 履修者等数の実績
AQ1: 様式２
AL2: 大学等名 | AM2: ='様式１-2 経営学部 プログラムを構成する授業科目'!C2 -> 文京学院大学
A3: プログラムの履修者数等の実績について
A5: ①プログラム開設年度 | C5: 2022 | E5: 年度
A7: ②履修者・修了者の実績
B9: 学部・学科名称 | C9: 学生数 | D9: 入学 定員 | E9: 収容 定員 | F9: 令和4年度 | L9: 令和3年度 | R9: 令和2年度 | X9: 令和元年度 | AD9: 平成30年度 | AJ9: 平成29年度 | AP9: 履修者数 合計 | AQ9: 履修率
F10: 履修者数 | I10: 修了者数 | L10: 履修者数 | O10: 修了者数 | R10: 履修者数 | U10: 修了者数 | X10: 履修者数 | AA10: 修了者数 | AD10: 履修者数 | AG10: 修了者数 | AJ10: 履修者数 | AM10: 修了者数
F11: 合計 | G11: 男性 | H11: 女性 | I11: 合計 | J11: 男性 | K11: 女性 | L11: 合計 | M11: 男性 | N11: 女性 | O11: 合計 | P11: 男性 | Q11: 女性 | R11: 合計 | S11: 男性 | T11: 女性 | U11: 合計 | V11: 男性 | W11: 女性 | X11: 合計 | Y11: 男性 | Z11: 女性 | AA11: 合計 | AB11: 男性 | AC11: 女性 | AD11: 合計 | AE11: 男性 | AF11: 女性 | AG11: 合計 | AH11: 男性 | AI11: 女性 | AJ11: 合計 | AK11: 男性 | AL11: 女性 | AM11: 合計 | AN11: 男性 | AO11: 女性
B12: 外国語学部英語コミュニケーション学科 | C12: 926 | D12: 260 | E12: 1040 | F12: =G12+H12 -> 395 | G12: 146 | H12: 249 | I12: =J12+K12 -> 8 | J12: 4 | K12: 4 | L12: =M12+N12 -> 0 | O12: =P12+Q12 -> 0 | R12: =S12+T12 -> 0 | U12: =V12+W12 -> 0 | X12: =Y12+Z12 -> 0 | AA12: =AB12+AC12 -> 0 | AD12: =AE12+AF12 -> 0 | AG12: =AH12+AI12 -> 0 | AJ12: =AK12+AL12 -> 0 | AM12: =AN12+AO12 -> 0 | AP12: =F12+L12+R12+X12+AD12+AJ12 -> 395 | AQ12: =AP12/E12 -> 0.37980769
B13: 経営学部経営学科 | C13: 1040 | D13: 260 | E13: 1040 | F13: =G13+H13 -> 19 | G13: 10 | H13: 9 | I13: =J13+K13 -> 0 | J13: 0 | K13: 0 | L13: =M13+N13 -> 0 | O13: =P13+Q13 -> 0 | R13: =S13+T13 -> 0 | U13: =V13+W13 -> 0 | X13: =Y13+Z13 -> 0 | AA13: =AB13+AC13 -> 0 | AD13: =AE13+AF13 -> 0 | AG13: =AH13+AI13 -> 0 | AJ13: =AK13+AL13 -> 0 | AM13: =AN13+AO13 -> 0 | AP13: =F13+L13+R13+X13+AD13+AJ13 -> 19 | AQ13: =AP13/E13 -> 0.018269231
B14: 人間学部コミュニケーション社会学科 | C14: 279 | D14: 60 | E14: 240 | F14: =G14+H14 -> 75 | G14: 47 | H14: 28 | I14: =J14+K14 -> 0 | J14: 0 | K14: 0 | L14: =M14+N14 -> 0 | O14: =P14+Q14 -> 0 | R14: =S14+T14 -> 0 | U14: =V14+W14 -> 0 | X14: =Y14+Z14 -> 0 | AA14: =AB14+AC14 -> 0 | AD14: =AE14+AF14 -> 0 | AG14: =AH14+AI14 -> 0 | AJ14: =AK14+AL14 -> 0 | AM14: =AN14+AO14 -> 0 | AP14: =F14+L14+R14+X14+AD14+AJ14 -> 75 | AQ14: =AP14/E14 -> 0.3125
B15: 人間学部児童発達学科 | C15: 407 | D15: 130 | E15: 520 | F15: =G15+H15 -> 250 | G15: 81 | H15: 169 | I15: =J15+K15 -> 0 | J15: 0 | K15: 0 | L15: =M15+N15 -> 0 | O15: =P15+Q15 -> 0 | R15: =S15+T15 -> 0 | U15: =V15+W15 -> 0 | X15: =Y15+Z15 -> 0 | AA15: =AB15+AC15 -> 0 | AD15: =AE15+AF15 -> 0 | AG15: =AH15+AI15 -> 0 | AJ15: =AK15+AL15 -> 0 | AM15: =AN15+AO15 -> 0 | AP15: =F15+L15+R15+X15+AD15+AJ15 -> 250 | AQ15: =AP15/E15 -> 0.48076923
B16: 人間学部人間福祉学科 | C16: 368 | D16: 110 | E16: 440 | F16: =G16+H16 -> 75 | G16: 40 | H16: 35 | I16: =J16+K16 -> 0 | J16: 0 | K16: 0 | L16: =M16+N16 -> 0 | O16: =P16+Q16 -> 0 | R16: =S16+T16 -> 0 | U16: =V16+W16 -> 0 | X16: =Y16+Z16 -> 0 | AA16: =AB16+AC16 -> 0 | AD16: =AE16+AF16 -> 0 | AG16: =AH16+AI16 -> 0 | AJ16: =AK16+AL16 -> 0 | AM16: =AN16+AO16 -> 0 | AP16: =F16+L16+R16+X16+AD16+AJ16 -> 75 | AQ16: =AP16/E16 -> 0.17045455
B17: 人間学部心理学科 | C17: 450 | D17: 100 | E17: 400 | F17: =G17+H17 -> 136 | G17: 68 | H17: 68 | I17: =J17+K17 -> 2 | J17: 0 | K17: 2 | L17: =M17+N17 -> 0 | O17: =P17+Q17 -> 0 | R17: =S17+T17 -> 0 | U17: =V17+W17 -> 0 | X17: =Y17+Z17 -> 0 | AA17: =AB17+AC17 -> 0 | AD17: =AE17+AF17 -> 0 | AG17: =AH17+AI17 -> 0 | AJ17: =AK17+AL17 -> 0 | AM17: =AN17+AO17 -> 0 | AP17: =F17+L17+R17+X17+AD17+AJ17 -> 136 | AQ17: =AP17/E17 -> 0.34
B18: 保健医療技術学部理学療法学科 | C18: 317 | D18: 80 | E18: 320 | F18: =G18+H18 -> 70 | G18: 39 | H18: 31 | I18: =J18+K18 -> 0 | J18: 0 | K18: 0 | L18: =M18+N18 -> 0 | O18: =P18+Q18 -> 0 | R18: =S18+T18 -> 0 | U18: =V18+W18 -> 0 | X18: =Y18+Z18 -> 0 | AA18: =AB18+AC18 -> 0 | AD18: =AE18+AF18 -> 0 | AG18: =AH18+AI18 -> 0 | AJ18: =AK18+AL18 -> 0 | AM18: =AN18+AO18 -> 0 | AP18: =F18+L18+R18+X18+AD18+AJ18 -> 70 | AQ18: =AP18/E18 -> 0.21875
B19: 保健医療技術学部作業療法学科 | C19: 128 | D19: 40 | E19: 160 | F19: =G19+H19 -> 23 | G19: 4 | H19: 19 | I19: =J19+K19 -> 1 | J19: 0 | K19: 1 | L19: =M19+N19 -> 0 | O19: =P19+Q19 -> 0 | R19: =S19+T19 -> 0 | U19: =V19+W19 -> 0 | X19: =Y19+Z19 -> 0 | AA19: =AB19+AC19 -> 0 | AD19: =AE19+AF19 -> 0 | AG19: =AH19+AI19 -> 0 | AJ19: =AK19+AL19 -> 0 | AM19: =AN19+AO19 -> 0 | AP19: =F19+L19+R19+X19+AD19+AJ19 -> 23 | AQ19: =AP19/E19 -> 0.14375
B20: 保健医療技術学部臨床検査学科 | C20: 314 | D20: 80 | E20: 320 | F20: =G20+H20 -> 57 | G20: 17 | H20: 40 | I20: =J20+K20 -> 0 | J20: 0 | K20: 0 | L20: =M20+N20 -> 0 | O20: =P20+Q20 -> 0 | R20: =S20+T20 -> 0 | U20: =V20+W20 -> 0 | X20: =Y20+Z20 -> 0 | AA20: =AB20+AC20 -> 0 | AD20: =AE20+AF20 -> 0 | AG20: =AH20+AI20 -> 0 | AJ20: =AK20+AL20 -> 0 | AM20: =AN20+AO20 -> 0 | AP20: =F20+L20+R20+X20+AD20+AJ20 -> 57 | AQ20: =AP20/E20 -> 0.178125
B21: 保健医療技術学部看護学科 | C21: 424 | D21: 100 | E21: 400 | F21: =G21+H21 -> 104 | G21: 8 | H21: 96 | I21: =J21+K21 -> 2 | J21: 0 | K21: 2 | L21: =M21+N21 -> 0 | O21: =P21+Q21 -> 0 | R21: =S21+T21 -> 0 | U21: =V21+W21 -> 0 | X21: =Y21+Z21 -> 0 | AA21: =AB21+AC21 -> 0 | AD21: =AE21+AF21 -> 0 | AG21: =AH21+AI21 -> 0 | AJ21: =AK21+AL21 -> 0 | AM21: =AN21+AO21 -> 0 | AP21: =F21+L21+R21+X21+AD21+AJ21 -> 104 | AQ21: =AP21/E21 -> 0.26
F22: =G22+H22 -> 0 | I22: =J22+K22 -> 0 | L22: =M22+N22 -> 0 | O22: =P22+Q22 -> 0 | R22: =S22+T22 -> 0 | U22: =V22+W22 -> 0 | X22: =Y22+Z22 -> 0 | AA22: =AB22+AC22 -> 0 | AD22: =AE22+AF22 -> 0 | AG22: =AH22+AI22 -> 0 | AJ22: =AK22+AL22 -> 0 | AM22: =AN22+AO22 -> 0 | AP22: =F22+L22+R22+X22+AD22+AJ22 -> 0 | AQ22: =AP22/E22 -> #DIV/0!
F23: =G23+H23 -> 0 | I23: =J23+K23 -> 0 | L23: =M23+N23 -> 0 | O23: =P23+Q23 -> 0 | R23: =S23+T23 -> 0 | U23: =V23+W23 -> 0 | X23: =Y23+Z23 -> 0 | AA23: =AB23+AC23 -> 0 | AD23: =AE23+AF23 -> 0 | AG23: =AH23+AI23 -> 0 | AJ23: =AK23+AL23 -> 0 | AM23: =AN23+AO23 -> 0 | AP23: =F23+L23+R23+X23+AD23+AJ23 -> 0 | AQ23: =AP23/E23 -> #DIV/0!
F24: =G24+H24 -> 0 | I24: =J24+K24 -> 0 | L24: =M24+N24 -> 0 | O24: =P24+Q24 -> 0 | R24: =S24+T24 -> 0 | U24: =V24+W24 -> 0 | X24: =Y24+Z24 -> 0 | AA24: =AB24+AC24 -> 0 | AD24: =AE24+AF24 -> 0 | AG24: =AH24+AI24 -> 0 | AJ24: =AK24+AL24 -> 0 | AM24: =AN24+AO24 -> 0 | AP24: =F24+L24+R24+X24+AD24+AJ24 -> 0 | AQ24: =AP24/E24 -> #DIV/0!
F25: =G25+H25 -> 0 | I25: =J25+K25 -> 0 | L25: =M25+N25 -> 0 | O25: =P25+Q25 -> 0 | R25: =S25+T25 -> 0 | U25: =V25+W25 -> 0 | X25: =Y25+Z25 -> 0 | AA25: =AB25+AC25 -> 0 | AD25: =AE25+AF25 -> 0 | AG25: =AH25+AI25 -> 0 | AJ25: =AK25+AL25 -> 0 | AM25: =AN25+AO25 -> 0 | AP25: =F25+L25+R25+X25+AD25+AJ25 -> 0 | AQ25: =AP25/E25 -> #DIV/0!
F26: =G26+H26 -> 0 | I26: =J26+K26 -> 0 | L26: =M26+N26 -> 0 | O26: =P26+Q26 -> 0 | R26: =S26+T26 -> 0 | U26: =V26+W26 -> 0 | X26: =Y26+Z26 -> 0 | AA26: =AB26+AC26 -> 0 | AD26: =AE26+AF26 -> 0 | AG26: =AH26+AI26 -> 0 | AJ26: =AK26+AL26 -> 0 | AM26: =AN26+AO26 -> 0 | AP26: =F26+L26+R26+X26+AD26+AJ26 -> 0 | AQ26: =AP26/E26 -> #DIV/0!
F27: =G27+H27 -> 0 | I27: =J27+K27 -> 0 | L27: =M27+N27 -> 0 | O27: =P27+Q27 -> 0 | R27: =S27+T27 -> 0 | U27: =V27+W27 -> 0 | X27: =Y27+Z27 -> 0 | AA27: =AB27+AC27 -> 0 | AD27: =AE27+AF27 -> 0 | AG27: =AH27+AI27 -> 0 | AJ27: =AK27+AL27 -> 0 | AM27: =AN27+AO27 -> 0 | AP27: =F27+L27+R27+X27+AD27+AJ27 -> 0 | AQ27: =AP27/E27 -> #DIV/0!
F28: =G28+H28 -> 0 | I28: =J28+K28 -> 0 | L28: =M28+N28 -> 0 | O28: =P28+Q28 -> 0 | R28: =S28+T28 -> 0 | U28: =V28+W28 -> 0 | X28: =Y28+Z28 -> 0 | AA28: =AB28+AC28 -> 0 | AD28: =AE28+AF28 -> 0 | AG28: =AH28+AI28 -> 0 | AJ28: =AK28+AL28 -> 0 | AM28: =AN28+AO28 -> 0 | AP28: =F28+L28+R28+X28+AD28+AJ28 -> 0 | AQ28: =AP28/E28 -> #DIV/0!
F29: =G29+H29 -> 0 | I29: =J29+K29 -> 0 | L29: =M29+N29 -> 0 | O29: =P29+Q29 -> 0 | R29: =S29+T29 -> 0 | U29: =V29+W29 -> 0 | X29: =Y29+Z29 -> 0 | AA29: =AB29+AC29 -> 0 | AD29: =AE29+AF29 -> 0 | AG29: =AH29+AI29 -> 0 | AJ29: =AK29+AL29 -> 0 | AM29: =AN29+AO29 -> 0 | AP29: =F29+L29+R29+X29+AD29+AJ29 -> 0 | AQ29: =AP29/E29 -> #DIV/0!
F30: =G30+H30 -> 0 | I30: =J30+K30 -> 0 | L30: =M30+N30 -> 0 | O30: =P30+Q30 -> 0 | R30: =S30+T30 -> 0 | U30: =V30+W30 -> 0 | X30: =Y30+Z30 -> 0 | AA30: =AB30+AC30 -> 0 | AD30: =AE30+AF30 -> 0 | AG30: =AH30+AI30 -> 0 | AJ30: =AK30+AL30 -> 0 | AM30: =AN30+AO30 -> 0 | AP30: =F30+L30+R30+X30+AD30+AJ30 -> 0 | AQ30: =AP30/E30 -> #DIV/0!
F31: =G31+H31 -> 0 | I31: =J31+K31 -> 0 | L31: =M31+N31 -> 0 | O31: =P31+Q31 -> 0 | R31: =S31+T31 -> 0 | U31: =V31+W31 -> 0 | X31: =Y31+Z31 -> 0 | AA31: =AB31+AC31 -> 0 | AD31: =AE31+AF31 -> 0 | AG31: =AH31+AI31 -> 0 | AJ31: =AK31+AL31 -> 0 | AM31: =AN31+AO31 -> 0 | AP31: =F31+L31+R31+X31+AD31+AJ31 -> 0 | AQ31: =AP31/E31 -> #DIV/0!
B32: 合 計 | C32: =SUM(C12:C31) -> 4653 | D32: =SUM(D12:D31) -> 1220 | E32: =SUM(E12:E31) -> 4880 | F32: =SUM(F12:F31) -> 1204 | G32: =SUM(G12:G31) -> 460 | H32: =SUM(H12:H31) -> 744 | I32: =SUM(I12:I31) -> 13 | J32: =SUM(J12:J31) -> 4 | ... AP32: =SUM(AP12:AP31) -> 1204 | AQ32: =AP32/E32 -> 0.24672131

Sheet 様式３ 教育の質・履修者数を向上させるための体制・計画
I1: 様式３
G2: 大学等名 | H2: ='様式１-2 経営学部 プログラムを構成する授業科目'!C2 -> 文京学院大学
A4: 教育の質・履修者数を向上させるための体制・計画について
A6: ① | B6: 全学の教員数 | C6: (常勤） | E6: 181 | F6: 人 | G6: （非常勤） | H6: 431 | I6: 人
A8: ② | B8: プログラムの授業を教えている教員数 | H8: 13 | I8: 人
A10: ③ | B10: プログラムの運営責任者
B11: （責任者名） | C11: 福井 勉 | G11: （役職名） | H11: 学長
A13: ④ | B13: プログラムを改善・進化させるための体制（委員会・組織等）
B14: DX推進センター運営委員会
B16: （責任者名） | C16: 浜 正樹 | G16: （役職名） | H16: DX推進センター長
A18: ⑤ | B18: プログラムを改善・進化させるための体制を定める規則名称
B19: DX推進センター規程
A21: ⑥ | B21: 体制の目的
B22: 文京学院大学（以下「本学」という。）の教育・研究・業務運営の諸活動において、デ ジタルの活用を推進し業務を変革すること（デジタルトランスフォーメーション（以下、 「ＤＸ」という。）により、本学の機能強化、教育研究活動の高度化及び業務運営の効率 化を図ることを目的として、ＤＸ推進センター（以下「センター」という。）を設置している。 DX推進センターの業務分掌として、AI・データサイエンスプログラムの開発を含めており、そのカリキュラムを全学教務委員会へ提案している。 なお、将来的には、AI・データサイエンス教育の全学教養課程での位置付けを検討するため、全学教養課程委員会にそのカリキュラム運営業務を移管する予定である。
A34: ⑦ | B34: 具体的な構成員
B35: DX推進センター長・外国語学部教授：浜正樹 経営学部教授：藤田邦彦 外国語学部准教授：仲田知弘 人間学部：長野祐一郎准教授 保健医療技術学部：鈴木里砂准教授 学習支援センター長（本郷キャンパス）：笹田泰宏 学習支援センター長（ふじみ野キャンパス）：神藤隆将 学習支援センター長補佐：東城俊太郎 情報教育研究センターマネジャー：友田賢一郎 情報教育研究センターアシスタントマネジャー：鈴木勲 情報教育研究センターチーフ：和田健太郎
A48: ⑧ | B48: 履修者数・履修率の向上に向けた計画 ※様式１の「履修必須の有無」で「計画がある」としている場合は詳細について記載すること
B49: 令和４年度実績 | C49: ='様式２ 履修者等数の実績'!AQ32 -> 0.24672131 | E49: 令和５年度予定 | F49: 0.5 | H49: 令和６年度予定 | I49: 0.75
B50: 令和７年度予定 | C50: 1 | E50: 令和８年度予定 | F50: 1 | H50: 収容定員（名） | I50: ='様式２ 履修者等数の実績'!E32 -> 4880
B51: 具体的な計画
B52: 経営学部の1科目を除いて、本教育プログラムは必修科目のみの構成であり、卒業要件として全員履修することを前提としているため、本項目に関する特段の取り組みは行われていない。
A65: ⑨ | B65: 学部・学科に関係なく希望する学生全員が受講可能となるような必要な体制・取組等
B66: 経営学部の1科目を除いて、本教育プログラムは必修科目のみの構成であり、卒業要件として全員履修することを前提としているため、本項目に関する特段の取り組みは行われていない。 令和4年度に初開講（当時は選択科目）となった「データサイエンス入門」については、外国語学部の設置科目ではあるが、他学部履修可能で全学部からの履修を可能とした。
A79: ⑩ | B79: できる限り多くの学生が履修できるような具体的な周知方法・取組
B80: 経営学部の1科目を除いて、本教育プログラムは必修科目のみの構成であり、卒業要件として全員履修することを前提としているため、本項目に関する特段の取り組みは行われていない。
A93: ⑪ | B93: できる限り多くの学生が履修・修得できるようなサポート体制
B94: 経営学部の1科目を除いて、本教育プログラムは必修科目のみから構成され、卒業要件として全員履修することが前提としているため、本項目に関する特段の取り組みは行われていない。 修得率を向上させるためのサポート体制としては、必修科目では、授業時間内で質問機会を増やして、学生の理解度に合わせて進めている。選択科目では、LMSやTeamsを利用して学生はいつでも担当教員に個別に質問や相談が可能であり、担当教員により迅速に対応が行われている。
A107: ⑫ | B107: 授業時間内外で学習指導、質問を受け付ける具体的な仕組み
B108: 本教育プログラムは、すべてLMSを活用することになっている。必修科目では、授業時間内で質問機会を増やしている。選択科目では、学生は授業時間以外でも不明点等をLMSやTeamsを利用して個別に担当教員に質問や相談が可能であり、担当教員はそれに対して直接LMSやTeamsで回答、指導が行われている。

Sheet 様式４　自己点検・評価
I1: 様式４
H2: 大学等名 | I2: ='様式１-2 経営学部 プログラムを構成する授業科目'!C2 -> 文京学院大学
A3: 自己点検・評価について
A5: ① | B5: プログラムの自己点検・評価を行う体制（委員会・組織等）
B6: DX推進センター運営委員会
D8: （責任者名） | E8: 浜 正樹 | G8: （役職名） | H8: DX推進センター長
A10: ② | B10: 自己点検・評価体制における意見等
B11: 自己点検・評価の視点 | E11: 自己点検・評価体制における意見・結果・改善に向けた取組等
B12: 学内からの視点
C13: プログラムの履修・修得状況 | E13: 全学部教務グループにおいて、教育プログラムへ履修登録している学生数や履修状況の分析・把握が可能となっており、令和4年度は、プログラム修了に必須である「データサイエンス入門」については、外国語学部生を中心に2学部以上の学生が単位取得している。今後、2023年度に全学部共通「データサイエンス入門」の必修化およびオプション科目の履修可能人数を増やすことにより、教育プログラムを履修希望する学生全員がよりスムーズに単位修得できるように改善を継続的に進めていく。
C14: 学修成果 | E14: 必須科目「データサイエンス入門」においては、全履修者に対して授業前に指定テキストを事前に学習し、課題把握を促し、授業後には内容の振り返りをさせることで理解を深めている。その他の科目についても授業アンケート結果等を分析することにより、学修成果を把握できるようになっている。例えば、受講アンケートにおいて「あなたはこの科目で十分な力がついたと思うか？」という設問に対して受講者の70％以上が力がついたと回答している。このような分析結果をDX推進センター運営委員会で共有し、プログラムの評価を毎年度行い内容の改善を図る。
C15: 学生アンケート等を通じた学生の内容の理解度 | E15: 本学では半期の授業ごとに「学生による授業アンケート」を実施し、学生の理解度を確認できる仕組みがすでに整っている。さらに申請プログラムの必須科目「データサイエンス入門」においては、授業時間内に理解度を確認するレポートや宿題を毎回課しており、これらの結果や提出状況からも内容の理解度や進捗度が把握できるようにしている。令和4年度のアンケート分析結果から、「データサイエンス入門」について80％程度が授業全体について満足したと回答をしている。今後も同アンケートを利用して継続的に理解度を把握し、プログラム運営に反映するようにしていく。
C16: 学生アンケート等を通じた後輩等他の学生への推奨度 | E16: 他の学生への推奨度は、プログラム科目に必須である「学生による授業アンケート」において受講後にアンケートをとることで把握する体制となっている。令和4年度前期、後期の授業が終わった段階で、「この科目はあなたの今後の生活に役に立つと思うか」という問いに80%以上の学生が肯定的な回答をしている。今後も継続的に受講生に対するアンケートを続け、多くの学生に推奨されるように内容を点検・改善していく。
C17: 全学的な履修者数、履修率向上に向けた計画の達成・進捗状況 | E17: 令和4年度は、本申請の教育プログラムの初年度であり履修登録者数が1204名であった。令和5年度は、必須科目の「データサイエンス入門」を全学部必修化することで、履修者数および履修率の向上が見込まれる。令和5年度からは、オプション科目の選択肢も増やしながら、さらに履修者数を向上させる計画となっている。
B18: 学外からの視点
C19: 教育プログラム修了者の進路、活躍状況、企業等の評価 | E19: 本学ではデータサイエンス・AI教育プログラムは令和4年度開始であり、修了者の進路、活躍状況等の分析ができるデータはまだ出ていない。今後は大学で行っている卒業生向けのアンケートやキャリアセンターにおいて把握している進路等をプログラム修了者と結びつけて解析を行い、DX推進センター運営委員会において、その結果を検討し、教育プログラムの改善に役立てる予定としている。
C20: 産業界からの視点を含めた教育プログラム内容・手法等への意見 | E20: ・本学では、自立と共生という建学の精神に基づき、多様な価値観を認め受け入れ、お互いを尊重しあえる共生社会の実現に貢献する、自立した人間教育を大切にしており、この理念を活かすために、様々な学部・学科の専門教育までつながるプログラムを設置したことは評価できる。 ・身に付けるべき能力として挙げられている2点については、今後のデジタル社会を生き抜く力として必要であり、共通の入門科目の他、学部の特性に応じてオプション科目や応用基礎レベルのプログラムまで用意しており、体系的な教育プログラムと評価できる。 ・「データサイエンス入門」では基礎的な知識や社会での利活用の実態について学び、後半ではエクセルによるデータ分析の基礎を実習形式で身に付けることができるように計画されている。
B21: 数理・データサイエンス・ＡＩを「学ぶ楽しさ」「学ぶことの意義」を理解させること | E21: 本学では、数理・データサイエンス・ＡＩを「学ぶ楽しさ」「学ぶことの意義」を理解させるために、教科書や資料等で身近な生活の事例を図解で振り返り、データやデータサイエンスに興味を持つことから始めている。全学必修科目「データサイエンス入門」は、経営学部、外国語学部、人間学部、保健医療技術学部の大学1年生が履修する科目であり、データサイエンスに興味がない学生、または知らない学生も多い。そこで、データサイエンスは、将来の卒業研究や仕事等に役立つ事を示し、興味を持つようにデータサイエンスの楽しさと考え方のポイントを解説している。
B22: 内容・水準を維持・向上しつつ、より「分かりやすい」授業とすること | E22: 本学では、全学必修科目「データサイエンス入門」を大学1年生に導入することで、既存科目の統計学やExcelやSPSS等を用いたデータ分析演習をより「わかりやすい」授業へと繋げている。そして、本学は各学部ごとに定めたプログラムの科目を履修することで、各学部ごとのデータサイエンス・リテラシーの内容・水準を維持・向上が可能であると考えている。
