Workbook

Sheet 様式１-１プログラムを構成する授業科目（法学部）
R1: 様式１－１ | T1: 「学部・学科によって、修了要件は相違する」場合は、本シートを複製の上＜様式１－〇＞と枝番号を付してください
B2: 大学等名 | C2: 明治大学
B3: プログラム名 | C3: 数理データサイエンス人工知能リテラシーレベルプログラム
A5: プログラムを構成する授業科目について
A7: ① 対象となる学部・学科名称 | J7: ② 教育プログラムの修了要件 | K7: 学部・学科によって、修了要件は相違する
B9: 法学部
A12: ③ 修了要件
B13: 「データサイエンス・AIの社会利用」科目群（④・⑥・⑦）から２単位以上 「データサイエンス・人工知能演習」科目群（⑧）から２単位以上 「数理統計」科目群（⑤）から２単位以上 合計６単位以上を取得すること。 | V13: 【プルダウンリスト】
V14: 令和４年度以前より、履修することが必須のプログラムとして実施
V15: 令和７年度までに履修必須とする計画
V16: 令和８年度以降に履修必須とする計画、又は未定
B20: 必要最低単位数 | C20: 6 | E20: 単位 | J20: 履修必須の有無 | K20: 令和８年度以降に履修必須とする計画、又は未定
A22: ④ 現在進行中の社会変化（第４次産業革命、Society 5.0、データ駆動型社会等）に深く寄与しているものであり、それが自らの生活と密接に結びついている」の内容を含む授業科目
B24: 授業科目 | F24: 単位数 | G24: 必須 | H24: 1-1 | I24: 1-6 | J24: 授業科目 | P24: 単位数 | Q24: 必須 | R24: 1-1 | S24: 1-6
B25: データサイエンスAI概論 | F25: 2 | G25: ○ | H25: ○ | I25: ○
A33: ⑤ 「社会で活用されているデータ」や「データの活用領域」は非常に広範囲であって、日常生活や社会の課題を解決する有用なツールになり得るもの」の内容を含む授業科目
B35: 授業科目 | F35: 単位数 | G35: 必須 | H35: 1-2 | I35: 1-3 | J35: 授業科目 | P35: 単位数 | Q35: 必須 | R35: 1-2 | S35: 1-3
B36: 数理と社会Ⅰ | F36: 2 | H36: ○ | I36: ○
B37: 数理と社会Ⅱ | F37: 2 | H37: ○ | I37: ○
A44: ⑥ 「様々なデータ利活用の現場におけるデータ利活用事例が示され、様々な適用領域（流通、製造、金融、サービス、インフラ、公共、ヘルスケア等）の知見と組み合わせることで価値を創出するもの」の内容を含む授業科目
B46: 授業科目 | F46: 単位数 | G46: 必須 | H46: 1-4 | I46: 1-5 | J46: 授業科目 | P46: 単位数 | Q46: 必須 | R46: 1-4 | S46: 1-5
B47: データサイエンスAI概論 | F47: 2 | G47: ○ | H47: ○ | I47: ○
A55: ⑦ 「活用に当たっての様々な留意事項（ELSI、個人情報、データ倫理、ＡＩ社会原則等）を考慮し、情報セキュリティや情報漏洩等、データを守る上での留意事項への理解をする」の内容を含む授業科目
B57: 授業科目 | F57: 単位数 | G57: 必須 | H57: 3-1 | I57: 3-2 | J57: 授業科目 | P57: 単位数 | Q57: 必須 | R57: 3-1 | S57: 3-2
B58: データサイエンスAI概論 | F58: 2 | G58: ○ | H58: ○ | I58: ○
A66: ⑧ 「実データ・実課題（学術データ等を含む）を用いた演習など、社会での実例を題材として、「データを読む、説明する、扱う」といった数理・データサイエンス・ＡＩの基本的な活用法に関するもの」の内容を含む授業科目
B68: 授業科目 | E68: 単位数 | F68: 必須 | G68: 2-1 | H68: 2-2 | I68: 2-3 | J68: 授業科目 | O68: 単位数 | P68: 必須 | Q68: 2-1 | R68: 2-2 | S68: 2-3
B69: ICT統計解析Ⅰ | E69: 2 | G69: ○ | H69: ○ | I69: ○
B70: ICTデータベースＩ | E70: 2 | G70: ○ | H70: ○ | I70: ○
B71: デジタルコンテンツA | E71: 2 | G71: ○ | H71: ○ | I71: ○
B72: デジタルコンテンツB | E72: 2 | G72: ○ | H72: ○ | I72: ○
A77: ⑨ 選択「４．オプション」の内容を含む授業科目
B78: 授業科目 | F78: 選択項目 | J78: 授業科目 | P78: 選択項目
A87: ⑩ プログラムを構成する授業の内容
B88: 授業に含まれている内容・要素 | D88: 講義内容
B89: （１）現在進行中の社会変化（第４次産業革命、Society 5.0、データ駆動型社会等）に深く寄与しているものであり、それが自らの生活と密接に結びついている | C89: 1-1 | D89: 複数技術を組み合わせたAIサービス「データサイエンスAI概論」（第７回） ビッグデータ、IoT、AI、ロボット「データサイエンスAI概論」（第８回） 人間の知的活動とAIの関係性「データサイエンスAI概論」（第９回）
C90: 1-6 | D90: AI等を活用した新しいビジネスモデル「データサイエンスAI概論」（第６，９，１０回） AI最新技術の活用例（深層生成モデル、敵対的生成ネットワーク）「データサイエンスAI概論」（第１３回）
B91: （２）「社会で活用されているデータ」や「データの活用領域」は非常に広範囲であって、日常生活や社会の課題を解決する有用なツールになり得るもの | C91: 1-2 | D91: 調査データ、実験データ、人の行動ログデータ、機械の稼働ログデータなど「数理と社会Ⅰ」（第２～８回） データのオープン化「数理と社会Ⅱ」（第２，８回） 1次データ、2次データ、データのメタ化「数理と社会Ⅱ」（第４，６，１０回）
C92: 1-3 | D92: 研究開発、調達、製造、物流、販売、マーケティング、サービスなど「数理と社会Ⅰ」（第９，１０回） データ・AI活用領域の広がり「数理と社会Ⅰ」（第１１～１３回） 仮説検証、知識発見、原因究明、計画策定、判断支援、活動代替、新規生成など「数理と社会Ⅱ」（第８，１０，１２回）
B93: （３）様々なデータ利活用の現場におけるデータ利活用事例が示され、様々な適用領域（流通、製造、金融、サービス、インフラ、公共、ヘルスケア等）の知見と組み合わせることで価値を創出するもの | C93: 1-4 | D93: データ解析：予測、グルーピング、パターン発見、最適化、シミュレーション・データ同化など「データサイエンスAI概論」（第３，５，９回） 特化型AIと汎用AI、今のAIで出来ることと出来ないこと「データサイエンスAI概論」（第１０，１１，１３回）
...

Sheet 様式１-２（商学部）
R1: 様式１－２ | T1: 「学部・学科によって、修了要件は相違する」場合は、本シートを複製の上＜様式１－〇＞と枝番号を付してください
B2: 大学等名 | C2: 明治大学
B3: プログラム名 | C3: 数理データサイエンス人工知能リテラシーレベルプログラム
A5: プログラムを構成する授業科目について
A7: ① 対象となる学部・学科名称 | J7: ② 教育プログラムの修了要件 | K7: 学部・学科によって、修了要件は相違する
B9: 商学部
A12: ③ 修了要件
B13: 「データサイエンス・AIの社会利用」科目群（④・⑥・⑦）から２単位以上 「データサイエンス・人工知能演習」科目群（⑧）から２単位以上 「数理統計」科目群（⑤）から２単位以上 合計６単位以上を取得すること。 | V13: 【プルダウンリスト】
V14: 令和４年度以前より、履修することが必須のプログラムとして実施
V15: 令和７年度までに履修必須とする計画
V16: 令和８年度以降に履修必須とする計画、又は未定
B20: 必要最低単位数 | C20: 6 | E20: 単位 | J20: 履修必須の有無 | K20: 令和８年度以降に履修必須とする計画、又は未定
A22: ④ 現在進行中の社会変化（第４次産業革命、Society 5.0、データ駆動型社会等）に深く寄与しているものであり、それが自らの生活と密接に結びついている」の内容を含む授業科目
B24: 授業科目 | F24: 単位数 | G24: 必須 | H24: 1-1 | I24: 1-6 | J24: 授業科目 | P24: 単位数 | Q24: 必須 | R24: 1-1 | S24: 1-6
B25: データサイエンスAI概論 | F25: 2 | G25: ○ | H25: ○ | I25: ○
A33: ⑤ 「社会で活用されているデータ」や「データの活用領域」は非常に広範囲であって、日常生活や社会の課題を解決する有用なツールになり得るもの」の内容を含む授業科目
B35: 授業科目 | F35: 単位数 | G35: 必須 | H35: 1-2 | I35: 1-3 | J35: 授業科目 | P35: 単位数 | Q35: 必須 | R35: 1-2 | S35: 1-3
B36: 統計学A | F36: 2 | H36: ○ | I36: ○
B37: 統計学B | F37: 2 | H37: ○ | I37: ○
B38: 線型数学A | F38: 2 | H38: ○ | I38: ○
B39: 線型数学B | F39: 2 | H39: ○ | I39: ○
B40: 解析数学A | F40: 2 | H40: ○ | I40: ○
B41: 解析数学B | F41: 2 | H41: ○ | I41: ○
A44: ⑥ 「様々なデータ利活用の現場におけるデータ利活用事例が示され、様々な適用領域（流通、製造、金融、サービス、インフラ、公共、ヘルスケア等）の知見と組み合わせることで価値を創出するもの」の内容を含む授業科目
B46: 授業科目 | F46: 単位数 | G46: 必須 | H46: 1-4 | I46: 1-5 | J46: 授業科目 | P46: 単位数 | Q46: 必須 | R46: 1-4 | S46: 1-5
B47: データサイエンスAI概論 | F47: 2 | G47: ○ | H47: ○ | I47: ○
A55: ⑦ 「活用に当たっての様々な留意事項（ELSI、個人情報、データ倫理、ＡＩ社会原則等）を考慮し、情報セキュリティや情報漏洩等、データを守る上での留意事項への理解をする」の内容を含む授業科目
B57: 授業科目 | F57: 単位数 | G57: 必須 | H57: 3-1 | I57: 3-2 | J57: 授業科目 | P57: 単位数 | Q57: 必須 | R57: 3-1 | S57: 3-2
B58: データサイエンスAI概論 | F58: 2 | G58: ○ | H58: ○ | I58: ○
A66: ⑧ 「実データ・実課題（学術データ等を含む）を用いた演習など、社会での実例を題材として、「データを読む、説明する、扱う」といった数理・データサイエンス・ＡＩの基本的な活用法に関するもの」の内容を含む授業科目
B68: 授業科目 | E68: 単位数 | F68: 必須 | G68: 2-1 | H68: 2-2 | I68: 2-3 | J68: 授業科目 | O68: 単位数 | P68: 必須 | Q68: 2-1 | R68: 2-2 | S68: 2-3
B69: ICT統計解析Ⅰ | E69: 2 | G69: ○ | H69: ○ | I69: ○
B70: ICTアプリ開発Ⅰ | E70: 2 | G70: ○ | H70: ○ | I70: ○
B71: ICTデータベースＩ | E71: 2 | G71: ○ | H71: ○ | I71: ○
A77: ⑨ 選択「４．オプション」の内容を含む授業科目
B78: 授業科目 | F78: 選択項目 | J78: 授業科目 | P78: 選択項目
A87: ⑩ プログラムを構成する授業の内容
B88: 授業に含まれている内容・要素 | D88: 講義内容
B89: （１）現在進行中の社会変化（第４次産業革命、Society 5.0、データ駆動型社会等）に深く寄与しているものであり、それが自らの生活と密接に結びついている | C89: 1-1 | D89: 複数技術を組み合わせたAIサービス「データサイエンスAI概論」（第７回） ビッグデータ、IoT、AI、ロボット「データサイエンスAI概論」（第８回） 人間の知的活動とAIの関係性「データサイエンスAI概論」（第９回）
C90: 1-6 | D90: AI等を活用した新しいビジネスモデル「データサイエンスAI概論」（第６，９，１０回） AI最新技術の活用例（深層生成モデル、敵対的生成ネットワーク）「データサイエンスAI概論」（第１３回）
...

Sheet 様式１-３（政治経済学部）
R1: 様式１－３ | T1: 「学部・学科によって、修了要件は相違する」場合は、本シートを複製の上＜様式１－〇＞と枝番号を付してください
B2: 大学等名 | C2: 明治大学
B3: プログラム名 | C3: 数理データサイエンス人工知能リテラシーレベルプログラム
A5: プログラムを構成する授業科目について
A7: ① 対象となる学部・学科名称 | J7: ② 教育プログラムの修了要件 | K7: 学部・学科によって、修了要件は相違する
B9: 政治経済学部
A12: ③ 修了要件
B13: 「データサイエンス・AIの社会利用」科目群（④・⑥・⑦）から２単位以上 「データサイエンス・人工知能演習」科目群（⑧）から２単位以上 「数理統計」科目群（⑤）から４単位以上 合計８単位以上を取得すること。 | V13: 【プルダウンリスト】
V14: 令和４年度以前より、履修することが必須のプログラムとして実施
V15: 令和７年度までに履修必須とする計画
V16: 令和８年度以降に履修必須とする計画、又は未定
B20: 必要最低単位数 | C20: 8 | E20: 単位 | J20: 履修必須の有無 | K20: 令和８年度以降に履修必須とする計画、又は未定
A22: ④ 現在進行中の社会変化（第４次産業革命、Society 5.0、データ駆動型社会等）に深く寄与しているものであり、それが自らの生活と密接に結びついている」の内容を含む授業科目
B24: 授業科目 | F24: 単位数 | G24: 必須 | H24: 1-1 | I24: 1-6 | J24: 授業科目 | P24: 単位数 | Q24: 必須 | R24: 1-1 | S24: 1-6
B25: データサイエンスAI概論 | F25: 2 | G25: ○ | H25: ○ | I25: ○
A33: ⑤ 「社会で活用されているデータ」や「データの活用領域」は非常に広範囲であって、日常生活や社会の課題を解決する有用なツールになり得るもの」の内容を含む授業科目
B35: 授業科目 | F35: 単位数 | G35: 必須 | H35: 1-2 | I35: 1-3 | J35: 授業科目 | P35: 単位数 | Q35: 必須 | R35: 1-2 | S35: 1-3
B36: 統計学 | F36: 4 | G36: ○ | H36: ○ | I36: ○
A44: ⑥ 「様々なデータ利活用の現場におけるデータ利活用事例が示され、様々な適用領域（流通、製造、金融、サービス、インフラ、公共、ヘルスケア等）の知見と組み合わせることで価値を創出するもの」の内容を含む授業科目
B46: 授業科目 | F46: 単位数 | G46: 必須 | H46: 1-4 | I46: 1-5 | J46: 授業科目 | P46: 単位数 | Q46: 必須 | R46: 1-4 | S46: 1-5
B47: データサイエンスAI概論 | F47: 2 | G47: ○ | H47: ○ | I47: ○
A55: ⑦ 「活用に当たっての様々な留意事項（ELSI、個人情報、データ倫理、ＡＩ社会原則等）を考慮し、情報セキュリティや情報漏洩等、データを守る上での留意事項への理解をする」の内容を含む授業科目
B57: 授業科目 | F57: 単位数 | G57: 必須 | H57: 3-1 | I57: 3-2 | J57: 授業科目 | P57: 単位数 | Q57: 必須 | R57: 3-1 | S57: 3-2
B58: データサイエンスAI概論 | F58: 2 | G58: ○ | H58: ○ | I58: ○
A66: ⑧ 「実データ・実課題（学術データ等を含む）を用いた演習など、社会での実例を題材として、「データを読む、説明する、扱う」といった数理・データサイエンス・ＡＩの基本的な活用法に関するもの」の内容を含む授業科目
B68: 授業科目 | E68: 単位数 | F68: 必須 | G68: 2-1 | H68: 2-2 | I68: 2-3 | J68: 授業科目 | O68: 単位数 | P68: 必須 | Q68: 2-1 | R68: 2-2 | S68: 2-3
B69: ICT統計解析Ⅰ | E69: 2 | G69: ○ | H69: ○ | I69: ○
B70: ICTアプリ開発Ⅰ | E70: 2 | G70: ○ | H70: ○ | I70: ○
B71: ICTデータベースＩ | E71: 2 | G71: ○ | H71: ○ | I71: ○
A77: ⑨ 選択「４．オプション」の内容を含む授業科目
B78: 授業科目 | F78: 選択項目 | J78: 授業科目 | P78: 選択項目
A87: ⑩ プログラムを構成する授業の内容
B88: 授業に含まれている内容・要素 | D88: 講義内容
B89: （１）現在進行中の社会変化（第４次産業革命、Society 5.0、データ駆動型社会等）に深く寄与しているものであり、それが自らの生活と密接に結びついている | C89: 1-1 | D89: 複数技術を組み合わせたAIサービス「データサイエンスAI概論」（第７回） ビッグデータ、IoT、AI、ロボット「データサイエンスAI概論」（第８回） 人間の知的活動とAIの関係性「データサイエンスAI概論」（第９回）
C90: 1-6 | D90: AI等を活用した新しいビジネスモデル「データサイエンスAI概論」（第６，９，１０回） AI最新技術の活用例（深層生成モデル、敵対的生成ネットワーク）「データサイエンスAI概論」（第１３回）
B91: （２）「社会で活用されているデータ」や「データの活用領域」は非常に広範囲であって、日常生活や社会の課題を解決する有用なツールになり得るもの | C91: 1-2 | D91: データのオープン化「統計学」（第１回） 1次データ、2次データ、データのメタ化「統計学」（第２～５回） 調査データ、実験データ、人の行動ログデータ、機械の稼働ログデータなど「統計学」（第６～９回）
C92: 1-3 | D92: 研究開発、調達、製造、物流、販売、マーケティング、サービスなど「統計学」（第１１～１３回） 仮説検証、知識発見、原因究明、計画策定、判断支援、活動代替、新規生成など「統計学」（第１４～１７回） データ・AI活用領域の広がり「統計学」（第２５～２６回）
B93: （３）様々なデータ利活用の現場におけるデータ利活用事例が示され、様々な適用領域（流通、製造、金融、サービス、インフラ、公共、ヘルスケア等）の知見と組み合わせることで価値を創出するもの | C93: 1-4 | D93: データ解析：予測、グルーピング、パターン発見、最適化、シミュレーション・データ同化など「データサイエンスAI概論」（第３，５，９回） 特化型AIと汎用AI、今のAIで出来ることと出来ないこと「データサイエンスAI概論」（第１０，１１，１３回）
C94: 1-5 | D94: 流通、製造、金融、サービス、インフラ、公共、ヘルスケア等におけるデータ・AI利活用事例紹介「データサイエンスAI概論」（第１～１４回）
B95: （４）活用に当たっての様々な留意事項（ELSI、個人情報、データ倫理、ＡＩ社会原則等）を考慮し、情報セキュリティや情報漏洩等、データを守る上での留意事項への理解をする | C95: 3-1 | D95: ELSI，AIサービスの責任論「データサイエンスAI概論」（第１回） 個人情報保護、EU一般データ保護規則(GDPR)、忘れられる権利、オプトアウト，データ倫理：データのねつ造、改ざん、盗用、プライバシー保護「データサイエンスAI概論」（第２回）
...

Sheet 様式１-４（文学部）
R1: 様式１－４ | T1: 「学部・学科によって、修了要件は相違する」場合は、本シートを複製の上＜様式１－〇＞と枝番号を付してください
B2: 大学等名 | C2: 明治大学
B3: プログラム名 | C3: 数理データサイエンス人工知能リテラシーレベルプログラム
A5: プログラムを構成する授業科目について
A7: ① 対象となる学部・学科名称 | J7: ② 教育プログラムの修了要件 | K7: 学部・学科によって、修了要件は相違する
B9: 文学部
A12: ③ 修了要件
B13: 「データサイエンス・AIの社会利用」科目群（④・⑥・⑦）から２単位以上 「データサイエンス・人工知能演習」科目群（⑧）から２単位以上 「数理統計」科目群（⑤）から２単位以上 合計６単位以上を取得すること。 | V13: 【プルダウンリスト】
V14: 令和４年度以前より、履修することが必須のプログラムとして実施
V15: 令和７年度までに履修必須とする計画
V16: 令和８年度以降に履修必須とする計画、又は未定
B20: 必要最低単位数 | C20: 6 | E20: 単位 | J20: 履修必須の有無 | K20: 令和８年度以降に履修必須とする計画、又は未定
A22: ④ 現在進行中の社会変化（第４次産業革命、Society 5.0、データ駆動型社会等）に深く寄与しているものであり、それが自らの生活と密接に結びついている」の内容を含む授業科目
B24: 授業科目 | F24: 単位数 | G24: 必須 | H24: 1-1 | I24: 1-6 | J24: 授業科目 | P24: 単位数 | Q24: 必須 | R24: 1-1 | S24: 1-6
B25: データサイエンスAI概論 | F25: 2 | G25: ○ | H25: ○ | I25: ○
A33: ⑤ 「社会で活用されているデータ」や「データの活用領域」は非常に広範囲であって、日常生活や社会の課題を解決する有用なツールになり得るもの」の内容を含む授業科目
B35: 授業科目 | F35: 単位数 | G35: 必須 | H35: 1-2 | I35: 1-3 | J35: 授業科目 | P35: 単位数 | Q35: 必須 | R35: 1-2 | S35: 1-3
B36: 統計学 | F36: 2 | H36: ○ | I36: ○
B37: 心理社会調査研究法Ａ | F37: 2 | H37: ○ | I37: ○
B38: 地域統計学Ⅰ | F38: 2 | H38: ○ | I38: ○
A44: ⑥ 「様々なデータ利活用の現場におけるデータ利活用事例が示され、様々な適用領域（流通、製造、金融、サービス、インフラ、公共、ヘルスケア等）の知見と組み合わせることで価値を創出するもの」の内容を含む授業科目
B46: 授業科目 | F46: 単位数 | G46: 必須 | H46: 1-4 | I46: 1-5 | J46: 授業科目 | P46: 単位数 | Q46: 必須 | R46: 1-4 | S46: 1-5
B47: データサイエンスAI概論 | F47: 2 | G47: ○ | H47: ○ | I47: ○
A55: ⑦ 「活用に当たっての様々な留意事項（ELSI、個人情報、データ倫理、ＡＩ社会原則等）を考慮し、情報セキュリティや情報漏洩等、データを守る上での留意事項への理解をする」の内容を含む授業科目
B57: 授業科目 | F57: 単位数 | G57: 必須 | H57: 3-1 | I57: 3-2 | J57: 授業科目 | P57: 単位数 | Q57: 必須 | R57: 3-1 | S57: 3-2
B58: データサイエンスAI概論 | F58: 2 | G58: ○ | H58: ○ | I58: ○
A66: ⑧ 「実データ・実課題（学術データ等を含む）を用いた演習など、社会での実例を題材として、「データを読む、説明する、扱う」といった数理・データサイエンス・ＡＩの基本的な活用法に関するもの」の内容を含む授業科目
B68: 授業科目 | E68: 単位数 | F68: 必須 | G68: 2-1 | H68: 2-2 | I68: 2-3 | J68: 授業科目 | O68: 単位数 | P68: 必須 | Q68: 2-1 | R68: 2-2 | S68: 2-3
B69: ICT統計解析Ⅰ | E69: 2 | G69: ○ | H69: ○ | I69: ○
B70: ICTアプリ開発Ⅰ | E70: 2 | G70: ○ | H70: ○ | I70: ○
B71: ICTデータベースＩ | E71: 2 | G71: ○ | H71: ○ | I71: ○
A77: ⑨ 選択「４．オプション」の内容を含む授業科目
B78: 授業科目 | F78: 選択項目 | J78: 授業科目 | P78: 選択項目
A87: ⑩ プログラムを構成する授業の内容
B88: 授業に含まれている内容・要素 | D88: 講義内容
B89: （１）現在進行中の社会変化（第４次産業革命、Society 5.0、データ駆動型社会等）に深く寄与しているものであり、それが自らの生活と密接に結びついている | C89: 1-1 | D89: 複数技術を組み合わせたAIサービス「データサイエンスAI概論」（第７回） ビッグデータ、IoT、AI、ロボット「データサイエンスAI概論」（第８回） 人間の知的活動とAIの関係性「データサイエンスAI概論」（第９回）
C90: 1-6 | D90: AI等を活用した新しいビジネスモデル「データサイエンスAI概論」（第６，９，１０回） AI最新技術の活用例（深層生成モデル、敵対的生成ネットワーク）「データサイエンスAI概論」（第１３回）
B91: （２）「社会で活用されているデータ」や「データの活用領域」は非常に広範囲であって、日常生活や社会の課題を解決する有用なツールになり得るもの | C91: 1-2 | D91: 調査データ、実験データ、人の行動ログデータ、機械の稼働ログデータなど「統計学」（第３～６，８～１３回） 調査データ、実験データ、人の行動ログデータ、機械の稼働ログデータなど「心理社会調査研究法Ａ」（第２～４回） 調査データ、実験データ、人の行動ログデータ、機械の稼働ログデータなど「地域統計学Ⅰ」（第１～３回） 1次データ、2次データ、データのメタ化「地域統計学Ⅰ」（第４～９回）
C92: 1-3 | D92: データ・AI活用領域の広がり「統計学」（第３～６，８～１３回） 仮説検証、知識発見、原因究明、計画策定、判断支援、活動代替、新規生成など「心理社会調査研究法Ａ」（第５～１３回） 仮説検証、知識発見、原因究明、計画策定、判断支援、活動代替、新規生成など「地域統計学Ⅰ」（第７～９回） 研究開発、調達、製造、物流、販売、マーケティング、サービスなど「地域統計学Ⅰ」（第１０～1４回）
B93: （３）様々なデータ利活用の現場におけるデータ利活用事例が示され、様々な適用領域（流通、製造、金融、サービス、インフラ、公共、ヘルスケア等）の知見と組み合わせることで価値を創出するもの | C93: 1-4 | D93: データ解析：予測、グルーピング、パターン発見、最適化、シミュレーション・データ同化など「データサイエンスAI概論」（第３，５，９回） 特化型AIと汎用AI、今のAIで出来ることと出来ないこと「データサイエンスAI概論」（第１０，１１，１３回）
...

Sheet 様式１-５（理工学部）
R1: 様式１－５ | T1: 「学部・学科によって、修了要件は相違する」場合は、本シートを複製の上＜様式１－〇＞と枝番号を付してください
B2: 大学等名 | C2: 明治大学
B3: プログラム名 | C3: 数理データサイエンス人工知能リテラシーレベルプログラム
A5: プログラムを構成する授業科目について
A7: ① 対象となる学部・学科名称 | J7: ② 教育プログラムの修了要件 | K7: 学部・学科によって、修了要件は相違する
B9: 理工学部
A12: ③ 修了要件
B13: 「データサイエンス・AIの社会利用」科目群（④・⑥・⑦）から２単位以上 「データリテラシー実習」科目群（⑧）から２単位以上 「数理統計」科目群（⑤）から２単位以上 合計６単位以上を取得すること。 | V13: 【プルダウンリスト】
V14: 令和４年度以前より、履修することが必須のプログラムとして実施
V15: 令和７年度までに履修必須とする計画
V16: 令和８年度以降に履修必須とする計画、又は未定
B20: 必要最低単位数 | C20: 6 | E20: 単位 | J20: 履修必須の有無 | K20: 令和８年度以降に履修必須とする計画、又は未定
A22: ④ 現在進行中の社会変化（第４次産業革命、Society 5.0、データ駆動型社会等）に深く寄与しているものであり、それが自らの生活と密接に結びついている」の内容を含む授業科目
B24: 授業科目 | F24: 単位数 | G24: 必須 | H24: 1-1 | I24: 1-6 | J24: 授業科目 | P24: 単位数 | Q24: 必須 | R24: 1-1 | S24: 1-6
B25: データサイエンスAI概論 | F25: 2 | G25: ○ | H25: ○ | I25: ○
A33: ⑤ 「社会で活用されているデータ」や「データの活用領域」は非常に広範囲であって、日常生活や社会の課題を解決する有用なツールになり得るもの」の内容を含む授業科目
B35: 授業科目 | F35: 単位数 | G35: 必須 | H35: 1-2 | I35: 1-3 | J35: 授業科目 | P35: 単位数 | Q35: 必須 | R35: 1-2 | S35: 1-3
B36: 確率・統計 | F36: 2 | G36: ○ | H36: ○ | I36: ○
A44: ⑥ 「様々なデータ利活用の現場におけるデータ利活用事例が示され、様々な適用領域（流通、製造、金融、サービス、インフラ、公共、ヘルスケア等）の知見と組み合わせることで価値を創出するもの」の内容を含む授業科目
B46: 授業科目 | F46: 単位数 | G46: 必須 | H46: 1-4 | I46: 1-5 | J46: 授業科目 | P46: 単位数 | Q46: 必須 | R46: 1-4 | S46: 1-5
B47: データサイエンスAI概論 | F47: 2 | G47: ○ | H47: ○ | I47: ○
A55: ⑦ 「活用に当たっての様々な留意事項（ELSI、個人情報、データ倫理、ＡＩ社会原則等）を考慮し、情報セキュリティや情報漏洩等、データを守る上での留意事項への理解をする」の内容を含む授業科目
B57: 授業科目 | F57: 単位数 | G57: 必須 | H57: 3-1 | I57: 3-2 | J57: 授業科目 | P57: 単位数 | Q57: 必須 | R57: 3-1 | S57: 3-2
B58: データサイエンスAI概論 | F58: 2 | G58: ○ | H58: ○ | I58: ○
A66: ⑧ 「実データ・実課題（学術データ等を含む）を用いた演習など、社会での実例を題材として、「データを読む、説明する、扱う」といった数理・データサイエンス・ＡＩの基本的な活用法に関するもの」の内容を含む授業科目
B68: 授業科目 | E68: 単位数 | F68: 必須 | G68: 2-1 | H68: 2-2 | I68: 2-3 | J68: 授業科目 | O68: 単位数 | P68: 必須 | Q68: 2-1 | R68: 2-2 | S68: 2-3
B69: 情報処理実習１ | E69: 1 | G69: ○ | H69: ○ | I69: ○
B70: 情報処理実習２ | E70: 1 | G70: ○ | H70: ○ | I70: ○
B71: 基礎物理学実験１ | E71: 1 | G71: ○ | H71: ○ | I71: ○
B72: 基礎物理学実験２ | E72: 1 | G72: ○ | H72: ○ | I72: ○
B73: 基礎化学実験１ | E73: 1 | G73: ○ | H73: ○ | I73: ○
B74: 基礎化学実験２ | E74: 1 | G74: ○ | H74: ○ | I74: ○
A77: ⑨ 選択「４．オプション」の内容を含む授業科目
B78: 授業科目 | F78: 選択項目 | J78: 授業科目 | P78: 選択項目
A87: ⑩ プログラムを構成する授業の内容
B88: 授業に含まれている内容・要素 | D88: 講義内容
B89: （１）現在進行中の社会変化（第４次産業革命、Society 5.0、データ駆動型社会等）に深く寄与しているものであり、それが自らの生活と密接に結びついている | C89: 1-1 | D89: 複数技術を組み合わせたAIサービス「データサイエンスAI概論」（第７回） ビッグデータ、IoT、AI、ロボット「データサイエンスAI概論」（第８回） 人間の知的活動とAIの関係性「データサイエンスAI概論」（第９回）
C90: 1-6 | D90: AI等を活用した新しいビジネスモデル「データサイエンスAI概論」（第６，９，１０回） AI最新技術の活用例（深層生成モデル、敵対的生成ネットワーク）「データサイエンスAI概論」（第１３回）
B91: （２）「社会で活用されているデータ」や「データの活用領域」は非常に広範囲であって、日常生活や社会の課題を解決する有用なツールになり得るもの | C91: 1-2 | D91: 1次データ、2次データ、データのメタ化，構造化データ、非構造化データ「確率・統計」（第２～８回）
C92: 1-3 | D92: 仮説検証、知識発見、原因究明、計画策定、判断支援、活動代替、新規生成など「確率・統計」（第９～１３回）
...

Sheet 様式１-６（農学部）
R1: 様式１－６ | T1: 「学部・学科によって、修了要件は相違する」場合は、本シートを複製の上＜様式１－〇＞と枝番号を付してください
B2: 大学等名 | C2: 明治大学
B3: プログラム名 | C3: 数理データサイエンス人工知能リテラシーレベルプログラム
A5: プログラムを構成する授業科目について
A7: ① 対象となる学部・学科名称 | J7: ② 教育プログラムの修了要件 | K7: 学部・学科によって、修了要件は相違する
B9: 農学部
A12: ③ 修了要件
B13: 「データサイエンス・AIの社会利用」科目群（④・⑥・⑦）から２単位以上 「データサイエンス・人工知能演習」科目群（⑧）から２単位以上 「数理統計」科目群（⑤）から２単位以上 合計６単位以上を取得すること。 | V13: 【プルダウンリスト】
V14: 令和４年度以前より、履修することが必須のプログラムとして実施
V15: 令和７年度までに履修必須とする計画
V16: 令和８年度以降に履修必須とする計画、又は未定
B20: 必要最低単位数 | C20: 6 | E20: 単位 | J20: 履修必須の有無 | K20: 令和８年度以降に履修必須とする計画、又は未定
A22: ④ 現在進行中の社会変化（第４次産業革命、Society 5.0、データ駆動型社会等）に深く寄与しているものであり、それが自らの生活と密接に結びついている」の内容を含む授業科目
B24: 授業科目 | F24: 単位数 | G24: 必須 | H24: 1-1 | I24: 1-6 | J24: 授業科目 | P24: 単位数 | Q24: 必須 | R24: 1-1 | S24: 1-6
B25: データサイエンスAI概論 | F25: 2 | G25: ○ | H25: ○ | I25: ○
A33: ⑤ 「社会で活用されているデータ」や「データの活用領域」は非常に広範囲であって、日常生活や社会の課題を解決する有用なツールになり得るもの」の内容を含む授業科目
B35: 授業科目 | F35: 単位数 | G35: 必須 | H35: 1-2 | I35: 1-3 | J35: 授業科目 | P35: 単位数 | Q35: 必須 | R35: 1-2 | S35: 1-3
B36: 基礎生物統計学 | F36: 2 | H36: ○ | I36: ○
B37: 生物統計学 | F37: 2 | H37: ○ | I37: ○
B38: 応用生物統計学 | F38: 2 | H38: ○ | I38: ○
B39: 統計学入門 | F39: 2 | H39: ○ | I39: ○
B40: バイオインフォマティクス入門 | F40: 2 | H40: ○ | I40: ○
B41: バイオインフォマティクス | F41: 2 | H41: ○ | I41: ○
A44: ⑥ 「様々なデータ利活用の現場におけるデータ利活用事例が示され、様々な適用領域（流通、製造、金融、サービス、インフラ、公共、ヘルスケア等）の知見と組み合わせることで価値を創出するもの」の内容を含む授業科目
B46: 授業科目 | F46: 単位数 | G46: 必須 | H46: 1-4 | I46: 1-5 | J46: 授業科目 | P46: 単位数 | Q46: 必須 | R46: 1-4 | S46: 1-5
B47: データサイエンスAI概論 | F47: 2 | G47: ○ | H47: ○ | I47: ○
A55: ⑦ 「活用に当たっての様々な留意事項（ELSI、個人情報、データ倫理、ＡＩ社会原則等）を考慮し、情報セキュリティや情報漏洩等、データを守る上での留意事項への理解をする」の内容を含む授業科目
B57: 授業科目 | F57: 単位数 | G57: 必須 | H57: 3-1 | I57: 3-2 | J57: 授業科目 | P57: 単位数 | Q57: 必須 | R57: 3-1 | S57: 3-2
B58: データサイエンスAI概論 | F58: 2 | G58: ○ | H58: ○ | I58: ○
A66: ⑧ 「実データ・実課題（学術データ等を含む）を用いた演習など、社会での実例を題材として、「データを読む、説明する、扱う」といった数理・データサイエンス・ＡＩの基本的な活用法に関するもの」の内容を含む授業科目
B68: 授業科目 | E68: 単位数 | F68: 必須 | G68: 2-1 | H68: 2-2 | I68: 2-3 | J68: 授業科目 | O68: 単位数 | P68: 必須 | Q68: 2-1 | R68: 2-2 | S68: 2-3
B69: ICT統計解析Ⅰ | E69: 2 | G69: ○ | H69: ○ | I69: ○
B70: ICTアプリ開発Ⅰ | E70: 2 | G70: ○ | H70: ○ | I70: ○
B71: ICTデータベースＩ | E71: 2 | G71: ○ | H71: ○ | I71: ○
A77: ⑨ 選択「４．オプション」の内容を含む授業科目
B78: 授業科目 | F78: 選択項目 | J78: 授業科目 | P78: 選択項目
A87: ⑩ プログラムを構成する授業の内容
B88: 授業に含まれている内容・要素 | D88: 講義内容
B89: （１）現在進行中の社会変化（第４次産業革命、Society 5.0、データ駆動型社会等）に深く寄与しているものであり、それが自らの生活と密接に結びついている | C89: 1-1 | D89: 複数技術を組み合わせたAIサービス「データサイエンスAI概論」（第７回） ビッグデータ、IoT、AI、ロボット「データサイエンスAI概論」（第８回） 人間の知的活動とAIの関係性「データサイエンスAI概論」（第９回）
C90: 1-6 | D90: AI等を活用した新しいビジネスモデル「データサイエンスAI概論」（第６，９，１０回） AI最新技術の活用例（深層生成モデル、敵対的生成ネットワーク）「データサイエンスAI概論」（第１３回）
...

Sheet 様式１-７（経営学部）
R1: 様式１－７ | T1: 「学部・学科によって、修了要件は相違する」場合は、本シートを複製の上＜様式１－〇＞と枝番号を付してください
B2: 大学等名 | C2: 明治大学
B3: プログラム名 | C3: 数理データサイエンス人工知能リテラシーレベルプログラム
A5: プログラムを構成する授業科目について
A7: ① 対象となる学部・学科名称 | J7: ② 教育プログラムの修了要件 | K7: 学部・学科によって、修了要件は相違する
B9: 経営学部
A12: ③ 修了要件
B13: 「データサイエンス・AIの社会利用」科目群（④・⑥・⑦）から２単位以上 「データサイエンス・人工知能演習」科目群（⑧）から２単位以上 「数理統計」科目群（⑤）から２単位以上 合計６単位以上を取得すること。 | V13: 【プルダウンリスト】
V14: 令和４年度以前より、履修することが必須のプログラムとして実施
V15: 令和７年度までに履修必須とする計画
V16: 令和８年度以降に履修必須とする計画、又は未定
B20: 必要最低単位数 | C20: 6 | E20: 単位 | J20: 履修必須の有無 | K20: 令和８年度以降に履修必須とする計画、又は未定
A22: ④ 現在進行中の社会変化（第４次産業革命、Society 5.0、データ駆動型社会等）に深く寄与しているものであり、それが自らの生活と密接に結びついている」の内容を含む授業科目
B24: 授業科目 | F24: 単位数 | G24: 必須 | H24: 1-1 | I24: 1-6 | J24: 授業科目 | P24: 単位数 | Q24: 必須 | R24: 1-1 | S24: 1-6
B25: データサイエンスAI概論 | F25: 2 | G25: ○ | H25: ○ | I25: ○
A33: ⑤ 「社会で活用されているデータ」や「データの活用領域」は非常に広範囲であって、日常生活や社会の課題を解決する有用なツールになり得るもの」の内容を含む授業科目
B35: 授業科目 | F35: 単位数 | G35: 必須 | H35: 1-2 | I35: 1-3 | J35: 授業科目 | P35: 単位数 | Q35: 必須 | R35: 1-2 | S35: 1-3
B36: 統計学Ａ | F36: 2 | H36: ○ | I36: ○
B37: 統計学Ｂ | F37: 2 | H37: ○ | I37: ○
B38: 経営統計学Ａ | F38: 2 | H38: ○ | I38: ○
B39: 経営統計学Ｂ | F39: 2 | H39: ○ | I39: ○
A44: ⑥ 「様々なデータ利活用の現場におけるデータ利活用事例が示され、様々な適用領域（流通、製造、金融、サービス、インフラ、公共、ヘルスケア等）の知見と組み合わせることで価値を創出するもの」の内容を含む授業科目
B46: 授業科目 | F46: 単位数 | G46: 必須 | H46: 1-4 | I46: 1-5 | J46: 授業科目 | P46: 単位数 | Q46: 必須 | R46: 1-4 | S46: 1-5
B47: データサイエンスAI概論 | F47: 2 | G47: ○ | H47: ○ | I47: ○
A55: ⑦ 「活用に当たっての様々な留意事項（ELSI、個人情報、データ倫理、ＡＩ社会原則等）を考慮し、情報セキュリティや情報漏洩等、データを守る上での留意事項への理解をする」の内容を含む授業科目
B57: 授業科目 | F57: 単位数 | G57: 必須 | H57: 3-1 | I57: 3-2 | J57: 授業科目 | P57: 単位数 | Q57: 必須 | R57: 3-1 | S57: 3-2
B58: データサイエンスAI概論 | F58: 2 | G58: ○ | H58: ○ | I58: ○
A66: ⑧ 「実データ・実課題（学術データ等を含む）を用いた演習など、社会での実例を題材として、「データを読む、説明する、扱う」といった数理・データサイエンス・ＡＩの基本的な活用法に関するもの」の内容を含む授業科目
B68: 授業科目 | E68: 単位数 | F68: 必須 | G68: 2-1 | H68: 2-2 | I68: 2-3 | J68: 授業科目 | O68: 単位数 | P68: 必須 | Q68: 2-1 | R68: 2-2 | S68: 2-3
B69: ICT統計解析Ⅰ | E69: 2 | G69: ○ | H69: ○ | I69: ○
B70: ICTアプリ開発Ⅰ | E70: 2 | G70: ○ | H70: ○ | I70: ○
B71: ICTデータベースＩ | E71: 2 | G71: ○ | H71: ○ | I71: ○
A77: ⑨ 選択「４．オプション」の内容を含む授業科目
B78: 授業科目 | F78: 選択項目 | J78: 授業科目 | P78: 選択項目
A87: ⑩ プログラムを構成する授業の内容
B88: 授業に含まれている内容・要素 | D88: 講義内容
B89: （１）現在進行中の社会変化（第４次産業革命、Society 5.0、データ駆動型社会等）に深く寄与しているものであり、それが自らの生活と密接に結びついている | C89: 1-1 | D89: 複数技術を組み合わせたAIサービス「データサイエンスAI概論」（第７回） ビッグデータ、IoT、AI、ロボット「データサイエンスAI概論」（第８回） 人間の知的活動とAIの関係性「データサイエンスAI概論」（第９回）
C90: 1-6 | D90: AI等を活用した新しいビジネスモデル「データサイエンスAI概論」（第６，９，１０回） AI最新技術の活用例（深層生成モデル、敵対的生成ネットワーク）「データサイエンスAI概論」（第１３回）
B91: （２）「社会で活用されているデータ」や「データの活用領域」は非常に広範囲であって、日常生活や社会の課題を解決する有用なツールになり得るもの | C91: 1-2 | D91: 調査データ、実験データ「統計学A」（第３回）・「経営統計学A」（第３回） データ作成「統計学A」（第４回）・「経営統計学A」（第４回） 1次データ、2次データ、データのメタ化「統計学A」（第５，６回）・「経営統計学A」（第５，６回） 調査データ、実験データ、データ作成「統計学B」（第２，３回）・「経営統計学B」（第２，３回）
C92: 1-3 | D92: 仮説検証、知識発見、原因究明、計画策定、判断支援、活動代替、新規生成など「統計学A」（第９～１３回）・「経営統計学A」（第９～１３回） 仮説検証、知識発見、原因究明、計画策定、判断支援、活動代替、新規生成など「統計学A」（第５，６回）・「経営統計学A」（第５，６回） 研究開発、調達、製造、物流、販売、マーケティング、サービスなど「統計学B」（第２，３回）・「経営統計学B」（第２，３回） データ・AI活用領域の広がり「統計学B」（第４，５回）・「経営統計学B」（第４，５回） 仮説検証、知識発見、原因究明、計画策定、判断支援、活動代替、新規生成など「統計学B」（第６～１３回）・「経営統計学B」（第６～１３回）
...

Sheet 様式１-８（情報コミュニケーション学部）
R1: 様式１－８ | T1: 「学部・学科によって、修了要件は相違する」場合は、本シートを複製の上＜様式１－〇＞と枝番号を付してください
B2: 大学等名 | C2: 明治大学
B3: プログラム名 | C3: 数理データサイエンス人工知能リテラシーレベルプログラム
A5: プログラムを構成する授業科目について
A7: ① 対象となる学部・学科名称 | J7: ② 教育プログラムの修了要件 | K7: 学部・学科によって、修了要件は相違する
B9: 情報コミュニケーション学部
A12: ③ 修了要件
B13: 「データサイエンス・AIの社会利用」科目群（④・⑥・⑦）から２単位以上 「データサイエンス・人工知能演習」科目群（⑧）から２単位以上 「数理統計」科目群（⑤）から２単位以上 合計６単位以上を取得すること。 | V13: 【プルダウンリスト】
V14: 令和４年度以前より、履修することが必須のプログラムとして実施
V15: 令和７年度までに履修必須とする計画
V16: 令和８年度以降に履修必須とする計画、又は未定
B20: 必要最低単位数 | C20: 6 | E20: 単位 | J20: 履修必須の有無 | K20: 令和８年度以降に履修必須とする計画、又は未定
A22: ④ 現在進行中の社会変化（第４次産業革命、Society 5.0、データ駆動型社会等）に深く寄与しているものであり、それが自らの生活と密接に結びついている」の内容を含む授業科目
B24: 授業科目 | F24: 単位数 | G24: 必須 | H24: 1-1 | I24: 1-6 | J24: 授業科目 | P24: 単位数 | Q24: 必須 | R24: 1-1 | S24: 1-6
B25: データサイエンスAI概論 | F25: 2 | G25: ○ | H25: ○ | I25: ○
A33: ⑤ 「社会で活用されているデータ」や「データの活用領域」は非常に広範囲であって、日常生活や社会の課題を解決する有用なツールになり得るもの」の内容を含む授業科目
B35: 授業科目 | F35: 単位数 | G35: 必須 | H35: 1-2 | I35: 1-3 | J35: 授業科目 | P35: 単位数 | Q35: 必須 | R35: 1-2 | S35: 1-3
B36: 統計学Ａ | F36: 2 | H36: ○ | I36: ○
B37: 統計学Ｂ | F37: 2 | H37: ○ | I37: ○
B38: データ解析論Ⅰ | F38: 2 | H38: ○ | I38: ○
B39: 専門情報リテラシー（社会統計） | F39: 2 | H39: ○ | I39: ○
B40: 専門情報リテラシー（心理統計） | F40: 2 | H40: ○ | I40: ○
A44: ⑥ 「様々なデータ利活用の現場におけるデータ利活用事例が示され、様々な適用領域（流通、製造、金融、サービス、インフラ、公共、ヘルスケア等）の知見と組み合わせることで価値を創出するもの」の内容を含む授業科目
B46: 授業科目 | F46: 単位数 | G46: 必須 | H46: 1-4 | I46: 1-5 | J46: 授業科目 | P46: 単位数 | Q46: 必須 | R46: 1-4 | S46: 1-5
B47: データサイエンスAI概論 | F47: 2 | G47: ○ | H47: ○ | I47: ○
A55: ⑦ 「活用に当たっての様々な留意事項（ELSI、個人情報、データ倫理、ＡＩ社会原則等）を考慮し、情報セキュリティや情報漏洩等、データを守る上での留意事項への理解をする」の内容を含む授業科目
B57: 授業科目 | F57: 単位数 | G57: 必須 | H57: 3-1 | I57: 3-2 | J57: 授業科目 | P57: 単位数 | Q57: 必須 | R57: 3-1 | S57: 3-2
B58: データサイエンスAI概論 | F58: 2 | G58: ○ | H58: ○ | I58: ○
A66: ⑧ 「実データ・実課題（学術データ等を含む）を用いた演習など、社会での実例を題材として、「データを読む、説明する、扱う」といった数理・データサイエンス・ＡＩの基本的な活用法に関するもの」の内容を含む授業科目
B68: 授業科目 | E68: 単位数 | F68: 必須 | G68: 2-1 | H68: 2-2 | I68: 2-3 | J68: 授業科目 | O68: 単位数 | P68: 必須 | Q68: 2-1 | R68: 2-2 | S68: 2-3
B69: ICT統計解析Ⅰ | E69: 2 | G69: ○ | H69: ○ | I69: ○
B70: ICTアプリ開発Ⅰ | E70: 2 | G70: ○ | H70: ○ | I70: ○
B71: ICTデータベースＩ | E71: 2 | G71: ○ | H71: ○ | I71: ○
A77: ⑨ 選択「４．オプション」の内容を含む授業科目
B78: 授業科目 | F78: 選択項目 | J78: 授業科目 | P78: 選択項目
A87: ⑩ プログラムを構成する授業の内容
B88: 授業に含まれている内容・要素 | D88: 講義内容
B89: （１）現在進行中の社会変化（第４次産業革命、Society 5.0、データ駆動型社会等）に深く寄与しているものであり、それが自らの生活と密接に結びついている | C89: 1-1 | D89: 複数技術を組み合わせたAIサービス「データサイエンスAI概論」（第７回） ビッグデータ、IoT、AI、ロボット「データサイエンスAI概論」（第８回） 人間の知的活動とAIの関係性「データサイエンスAI概論」（第９回）
C90: 1-6 | D90: AI等を活用した新しいビジネスモデル「データサイエンスAI概論」（第６，９，１０回） AI最新技術の活用例（深層生成モデル、敵対的生成ネットワーク）「データサイエンスAI概論」（第１３回）
B91: （２）「社会で活用されているデータ」や「データの活用領域」は非常に広範囲であって、日常生活や社会の課題を解決する有用なツールになり得るもの | C91: 1-2 | D91: 調査データ、実験データ、人の行動ログデータ、機械の稼働ログデータなど「統計学A」（第１～８回） 1次データ、2次データ、データのメタ化「統計学B」（第１～４回） 1次データ、2次データ、データのメタ化「データ解析論Ⅰ」（第２～５回） データのオープン化「データ解析論Ⅰ」（第６，７回） 1次データ、2次データ、データのメタ化「専門情報リテラシー（社会統計）」（第２回） 調査データ、実験データ、人の行動ログデータ、機械の稼働ログデータなど「専門情報リテラシー（社会統計）」（第１～５回） 1次データ、2次データ、データのメタ化「専門情報リテラシー（社会統計）」（第６，７回） 調査データ、実験データ、人の行動ログデータ、機械の稼働ログデータなど「専門情報リテラシー（心理統計）」（第１～５回）
...

Sheet 様式１-９（国際日本学部）
R1: 様式１－９ | T1: 「学部・学科によって、修了要件は相違する」場合は、本シートを複製の上＜様式１－〇＞と枝番号を付してください
B2: 大学等名 | C2: 明治大学
B3: プログラム名 | C3: 数理データサイエンス人工知能リテラシーレベルプログラム
A5: プログラムを構成する授業科目について
A7: ① 対象となる学部・学科名称 | J7: ② 教育プログラムの修了要件 | K7: 学部・学科によって、修了要件は相違する
B9: 国際日本学部
A12: ③ 修了要件
B13: 「データサイエンス・AIの社会利用」科目群（④・⑥・⑦）から２単位以上 「データサイエンス・人工知能演習」科目群（⑧）から２単位以上 「数理統計」科目群（⑤）から２単位以上 合計６単位以上を取得すること。 | V13: 【プルダウンリスト】
V14: 令和４年度以前より、履修することが必須のプログラムとして実施
V15: 令和７年度までに履修必須とする計画
V16: 令和８年度以降に履修必須とする計画、又は未定
B20: 必要最低単位数 | C20: 6 | E20: 単位 | J20: 履修必須の有無 | K20: 令和８年度以降に履修必須とする計画、又は未定
A22: ④ 現在進行中の社会変化（第４次産業革命、Society 5.0、データ駆動型社会等）に深く寄与しているものであり、それが自らの生活と密接に結びついている」の内容を含む授業科目
B24: 授業科目 | F24: 単位数 | G24: 必須 | H24: 1-1 | I24: 1-6 | J24: 授業科目 | P24: 単位数 | Q24: 必須 | R24: 1-1 | S24: 1-6
B25: データサイエンスAI概論 | F25: 2 | G25: ○ | H25: ○ | I25: ○
A33: ⑤ 「社会で活用されているデータ」や「データの活用領域」は非常に広範囲であって、日常生活や社会の課題を解決する有用なツールになり得るもの」の内容を含む授業科目
B35: 授業科目 | F35: 単位数 | G35: 必須 | H35: 1-2 | I35: 1-3 | J35: 授業科目 | P35: 単位数 | Q35: 必須 | R35: 1-2 | S35: 1-3
B36: 統計学Ａ | F36: 2 | H36: ○ | I36: ○
B37: 統計学Ｂ | F37: 2 | H37: ○ | I37: ○
A44: ⑥ 「様々なデータ利活用の現場におけるデータ利活用事例が示され、様々な適用領域（流通、製造、金融、サービス、インフラ、公共、ヘルスケア等）の知見と組み合わせることで価値を創出するもの」の内容を含む授業科目
B46: 授業科目 | F46: 単位数 | G46: 必須 | H46: 1-4 | I46: 1-5 | J46: 授業科目 | P46: 単位数 | Q46: 必須 | R46: 1-4 | S46: 1-5
B47: データサイエンスAI概論 | F47: 2 | G47: ○ | H47: ○ | I47: ○
A55: ⑦ 「活用に当たっての様々な留意事項（ELSI、個人情報、データ倫理、ＡＩ社会原則等）を考慮し、情報セキュリティや情報漏洩等、データを守る上での留意事項への理解をする」の内容を含む授業科目
B57: 授業科目 | F57: 単位数 | G57: 必須 | H57: 3-1 | I57: 3-2 | J57: 授業科目 | P57: 単位数 | Q57: 必須 | R57: 3-1 | S57: 3-2
B58: データサイエンスAI概論 | F58: 2 | G58: ○ | H58: ○ | I58: ○
A66: ⑧ 「実データ・実課題（学術データ等を含む）を用いた演習など、社会での実例を題材として、「データを読む、説明する、扱う」といった数理・データサイエンス・ＡＩの基本的な活用法に関するもの」の内容を含む授業科目
B68: 授業科目 | E68: 単位数 | F68: 必須 | G68: 2-1 | H68: 2-2 | I68: 2-3 | J68: 授業科目 | O68: 単位数 | P68: 必須 | Q68: 2-1 | R68: 2-2 | S68: 2-3
B69: ICT統計解析Ⅰ | E69: 2 | G69: ○ | H69: ○ | I69: ○
B70: ICTアプリ開発Ⅰ | E70: 2 | G70: ○ | H70: ○ | I70: ○
B71: ICTデータベースＩ | E71: 2 | G71: ○ | H71: ○ | I71: ○
A77: ⑨ 選択「４．オプション」の内容を含む授業科目
B78: 授業科目 | F78: 選択項目 | J78: 授業科目 | P78: 選択項目
A87: ⑩ プログラムを構成する授業の内容
B88: 授業に含まれている内容・要素 | D88: 講義内容
B89: （１）現在進行中の社会変化（第４次産業革命、Society 5.0、データ駆動型社会等）に深く寄与しているものであり、それが自らの生活と密接に結びついている | C89: 1-1 | D89: 複数技術を組み合わせたAIサービス「データサイエンスAI概論」（第７回） ビッグデータ、IoT、AI、ロボット「データサイエンスAI概論」（第８回） 人間の知的活動とAIの関係性「データサイエンスAI概論」（第９回）
C90: 1-6 | D90: AI等を活用した新しいビジネスモデル「データサイエンスAI概論」（第６，９，１０回） AI最新技術の活用例（深層生成モデル、敵対的生成ネットワーク）「データサイエンスAI概論」（第１３回）
B91: （２）「社会で活用されているデータ」や「データの活用領域」は非常に広範囲であって、日常生活や社会の課題を解決する有用なツールになり得るもの | C91: 1-2 | D91: 調査データ、実験データ、人の行動ログデータ、機械の稼働ログデータなど「統計学A」（第１～４回） 1次データ、2次データ、データのメタ化「統計学A」（第７～１０回） データ作成「統計学B」（第２～６回）
C92: 1-3 | D92: 研究開発、調達、製造、物流、販売、マーケティング、サービス「統計学A」（第９，１０回） 仮説検証、知識発見、原因究明、計画策定、判断支援、活動代替、新規生成など「統計学A」（第１１～１４回） 仮説検証、知識発見、原因究明、計画策定、判断支援、活動代替、新規生成など「統計学B」（第７～１３回） 研究開発、調達、製造、物流、販売、マーケティング、サービス「統計学B」（第１４回）
B93: （３）様々なデータ利活用の現場におけるデータ利活用事例が示され、様々な適用領域（流通、製造、金融、サービス、インフラ、公共、ヘルスケア等）の知見と組み合わせることで価値を創出するもの | C93: 1-4 | D93: データ解析：予測、グルーピング、パターン発見、最適化、シミュレーション・データ同化など「データサイエンスAI概論」（第３，５，９回） 特化型AIと汎用AI、今のAIで出来ることと出来ないこと「データサイエンスAI概論」（第１０，１１，１３回）
C94: 1-5 | D94: 流通、製造、金融、サービス、インフラ、公共、ヘルスケア等におけるデータ・AI利活用事例紹介「データサイエンスAI概論」（第１～１４回）
...

Sheet 様式１-10（総合数理学部）
R1: 様式１－10 | T1: 「学部・学科によって、修了要件は相違する」場合は、本シートを複製の上＜様式１－〇＞と枝番号を付してください
B2: 大学等名 | C2: 明治大学
B3: プログラム名 | C3: 数理データサイエンス人工知能リテラシーレベルプログラム
A5: プログラムを構成する授業科目について
A7: ① 対象となる学部・学科名称 | J7: ② 教育プログラムの修了要件 | K7: 学部・学科によって、修了要件は相違する
B9: 総合数理学部
A12: ③ 修了要件
B13: 「データサイエンス・AIの社会利用」科目群（④・⑥・⑦）から２単位以上 「データサイエンス・人工知能演習」科目群（⑧）から２単位以上 「数理統計」科目群（⑤）から２単位以上 合計６単位以上を取得すること。 | V13: 【プルダウンリスト】
V14: 令和４年度以前より、履修することが必須のプログラムとして実施
V15: 令和７年度までに履修必須とする計画
V16: 令和８年度以降に履修必須とする計画、又は未定
B20: 必要最低単位数 | C20: 6 | E20: 単位 | J20: 履修必須の有無 | K20: 令和８年度以降に履修必須とする計画、又は未定
A22: ④ 現在進行中の社会変化（第４次産業革命、Society 5.0、データ駆動型社会等）に深く寄与しているものであり、それが自らの生活と密接に結びついている」の内容を含む授業科目
B24: 授業科目 | F24: 単位数 | G24: 必須 | H24: 1-1 | I24: 1-6 | J24: 授業科目 | P24: 単位数 | Q24: 必須 | R24: 1-1 | S24: 1-6
B25: データサイエンスAI概論 | F25: 2 | H25: ○ | I25: ○
B26: 先端メディアサイエンス特別講義 | F26: 2 | H26: ○ | I26: ○
A33: ⑤ 「社会で活用されているデータ」や「データの活用領域」は非常に広範囲であって、日常生活や社会の課題を解決する有用なツールになり得るもの」の内容を含む授業科目
B35: 授業科目 | F35: 単位数 | G35: 必須 | H35: 1-2 | I35: 1-3 | J35: 授業科目 | P35: 単位数 | Q35: 必須 | R35: 1-2 | S35: 1-3
B36: 統計学入門 | F36: 2 | H36: ○ | I36: ○
B37: 社会調査法 | F37: 2 | H37: ○ | I37: ○
A44: ⑥ 「様々なデータ利活用の現場におけるデータ利活用事例が示され、様々な適用領域（流通、製造、金融、サービス、インフラ、公共、ヘルスケア等）の知見と組み合わせることで価値を創出するもの」の内容を含む授業科目
B46: 授業科目 | F46: 単位数 | G46: 必須 | H46: 1-4 | I46: 1-5 | J46: 授業科目 | P46: 単位数 | Q46: 必須 | R46: 1-4 | S46: 1-5
B47: データサイエンスAI概論 | F47: 2 | H47: ○ | I47: ○
B48: 先端メディアサイエンス特別講義 | F48: 2 | H48: ○ | I48: ○
A55: ⑦ 「活用に当たっての様々な留意事項（ELSI、個人情報、データ倫理、ＡＩ社会原則等）を考慮し、情報セキュリティや情報漏洩等、データを守る上での留意事項への理解をする」の内容を含む授業科目
B57: 授業科目 | F57: 単位数 | G57: 必須 | H57: 3-1 | I57: 3-2 | J57: 授業科目 | P57: 単位数 | Q57: 必須 | R57: 3-1 | S57: 3-2
B58: データサイエンスAI概論 | F58: 2 | H58: ○ | I58: ○
B59: 先端メディアサイエンス特別講義 | F59: 2 | H59: ○ | I59: ○
A66: ⑧ 「実データ・実課題（学術データ等を含む）を用いた演習など、社会での実例を題材として、「データを読む、説明する、扱う」といった数理・データサイエンス・ＡＩの基本的な活用法に関するもの」の内容を含む授業科目
B68: 授業科目 | E68: 単位数 | F68: 必須 | G68: 2-1 | H68: 2-2 | I68: 2-3 | J68: 授業科目 | O68: 単位数 | P68: 必須 | Q68: 2-1 | R68: 2-2 | S68: 2-3
B69: プログラミング演習I | E69: 2又は4 | F69: ○ | G69: ○ | H69: ○ | I69: ○
A77: ⑨ 選択「４．オプション」の内容を含む授業科目
B78: 授業科目 | F78: 選択項目 | J78: 授業科目 | P78: 選択項目
A87: ⑩ プログラムを構成する授業の内容
B88: 授業に含まれている内容・要素 | D88: 講義内容
B89: （１）現在進行中の社会変化（第４次産業革命、Society 5.0、データ駆動型社会等）に深く寄与しているものであり、それが自らの生活と密接に結びついている | C89: 1-1 | D89: 複数技術を組み合わせたAIサービス「データサイエンスAI概論」（第７回） ビッグデータ、IoT、AI、ロボット「データサイエンスAI概論」（第８回） 人間の知的活動とAIの関係性「データサイエンスAI概論」（第９回） データを起点としたものの見方、人間の知的活動を起点としたものの見方「先端メディアサイエンス特別講義」（第４～７，１０～１４回）
C90: 1-6 | D90: AI等を活用した新しいビジネスモデル「データサイエンスAI概論」（第６，９，１０回） AI最新技術の活用例（深層生成モデル、敵対的生成ネットワーク）「データサイエンスAI概論」（第１３回） AI等を活用した新しいビジネスモデル「先端メディアサイエンス特別講義」（第２，５，７～１２回）
B91: （２）「社会で活用されているデータ」や「データの活用領域」は非常に広範囲であって、日常生活や社会の課題を解決する有用なツールになり得るもの | C91: 1-2 | D91: 調査データ、実験データ、人の行動ログデータ、機械の稼働ログデータなど「統計学入門」（第１～１０回） 調査データ、実験データ、人の行動ログデータ、機械の稼働ログデータなど「社会調査法」（第１～５回）
C92: 1-3 | D92: 仮説検証、知識発見、原因究明、計画策定、判断支援、活動代替、新規生成など「統計学入門」（第１１～１４回） 仮説検証、知識発見、原因究明、計画策定、判断支援、活動代替、新規生成など「社会調査法」（第６～１２回） 研究開発、調達、製造、物流、販売、マーケティング、サービス「社会調査法」（第１３，１４回）
B93: （３）様々なデータ利活用の現場におけるデータ利活用事例が示され、様々な適用領域（流通、製造、金融、サービス、インフラ、公共、ヘルスケア等）の知見と組み合わせることで価値を創出するもの | C93: 1-4 | D93: データ解析：予測、グルーピング、パターン発見、最適化、シミュレーション・データ同化など「データサイエンスAI概論」（第３，５，９回） 特化型AIと汎用AI、今のAIで出来ることと出来ないこと「データサイエンスAI概論」（第１０，１１，１３回） 特化型AIと汎用AI、今のAIで出来ることと出来ないこと「先端メディアサイエンス特別講義」（第９回）
...

Sheet 様式２ 履修者等数の実績
AQ1: 様式２
AL2: 大学等名 | AM2: ='様式１-１プログラムを構成する授業科目（法学部）'!C2 -> 明治大学
A3: プログラムの履修者数等の実績について
A5: ①プログラム開設年度 | C5: 令和4 | E5: 年度
A7: ②履修者・修了者の実績
B9: 学部・学科名称 | C9: 学生数 | D9: 入学 定員 | E9: 収容 定員 | F9: 令和4年度 | L9: 令和3年度 | R9: 令和2年度 | X9: 令和元年度 | AD9: 平成30年度 | AJ9: 平成29年度 | AP9: 履修者数 合計 | AQ9: 履修率
F10: 履修者数 | I10: 修了者数 | L10: 履修者数 | O10: 修了者数 | R10: 履修者数 | U10: 修了者数 | X10: 履修者数 | AA10: 修了者数 | AD10: 履修者数 | AG10: 修了者数 | AJ10: 履修者数 | AM10: 修了者数
F11: 合計 | G11: 男性 | H11: 女性 | I11: 合計 | J11: 男性 | K11: 女性 | L11: 合計 | M11: 男性 | N11: 女性 | O11: 合計 | P11: 男性 | Q11: 女性 | R11: 合計 | S11: 男性 | T11: 女性 | U11: 合計 | V11: 男性 | W11: 女性 | X11: 合計 | Y11: 男性 | Z11: 女性 | AA11: 合計 | AB11: 男性 | AC11: 女性 | AD11: 合計 | AE11: 男性 | AF11: 女性 | AG11: 合計 | AH11: 男性 | AI11: 女性 | AJ11: 合計 | AK11: 男性 | AL11: 女性 | AM11: 合計 | AN11: 男性 | AO11: 女性
B12: 法学部 | C12: 3717 | D12: 920 | E12: 3680 | F12: =G12+H12 -> 23 | G12: 18 | H12: 5 | I12: =J12+K12 -> 3 | J12: 1 | K12: 2 | L12: =M12+N12 -> 0 | O12: =P12+Q12 -> 0 | R12: =S12+T12 -> 0 | U12: =V12+W12 -> 0 | X12: =Y12+Z12 -> 0 | AA12: =AB12+AC12 -> 0 | AD12: =AE12+AF12 -> 0 | AG12: =AH12+AI12 -> 0 | AJ12: =AK12+AL12 -> 0 | AM12: =AN12+AO12 -> 0 | AP12: =F12+L12+R12+X12+AD12+AJ12 -> 23 | AQ12: =AP12/E12 -> 0.00625
B13: 商学部 | C13: 4575 | D13: 1150 | E13: 4600 | F13: =G13+H13 -> 18 | G13: 13 | H13: 5 | I13: =J13+K13 -> 6 | J13: 5 | K13: 1 | L13: =M13+N13 -> 0 | O13: =P13+Q13 -> 0 | R13: =S13+T13 -> 0 | U13: =V13+W13 -> 0 | X13: =Y13+Z13 -> 0 | AA13: =AB13+AC13 -> 0 | AD13: =AE13+AF13 -> 0 | AG13: =AH13+AI13 -> 0 | AJ13: =AK13+AL13 -> 0 | AM13: =AN13+AO13 -> 0 | AP13: =F13+L13+R13+X13+AD13+AJ13 -> 18 | AQ13: =AP13/E13 -> 0.0039130435
B14: 政治経済学部 | C14: 4645 | D14: 1150 | E14: 4600 | F14: =G14+H14 -> 64 | G14: 42 | H14: 22 | I14: =J14+K14 -> 13 | J14: 10 | K14: 3 | L14: =M14+N14 -> 0 | O14: =P14+Q14 -> 0 | R14: =S14+T14 -> 0 | U14: =V14+W14 -> 0 | X14: =Y14+Z14 -> 0 | AA14: =AB14+AC14 -> 0 | AD14: =AE14+AF14 -> 0 | AG14: =AH14+AI14 -> 0 | AJ14: =AK14+AL14 -> 0 | AM14: =AN14+AO14 -> 0 | AP14: =F14+L14+R14+X14+AD14+AJ14 -> 64 | AQ14: =AP14/E14 -> 0.013913043
B15: 文学部 | C15: 3893 | D15: 910 | E15: 3640 | F15: =G15+H15 -> 29 | G15: 14 | H15: 15 | I15: =J15+K15 -> 3 | J15: 2 | K15: 1 | L15: =M15+N15 -> 0 | O15: =P15+Q15 -> 0 | R15: =S15+T15 -> 0 | U15: =V15+W15 -> 0 | X15: =Y15+Z15 -> 0 | AA15: =AB15+AC15 -> 0 | AD15: =AE15+AF15 -> 0 | AG15: =AH15+AI15 -> 0 | AJ15: =AK15+AL15 -> 0 | AM15: =AN15+AO15 -> 0 | AP15: =F15+L15+R15+X15+AD15+AJ15 -> 29 | AQ15: =AP15/E15 -> 0.007967033
B16: 理工学部 | C16: 4178 | D16: 1065 | E16: 4260 | F16: =G16+H16 -> 49 | G16: 39 | H16: 10 | I16: =J16+K16 -> 21 | J16: 15 | K16: 6 | L16: =M16+N16 -> 0 | O16: =P16+Q16 -> 0 | R16: =S16+T16 -> 0 | U16: =V16+W16 -> 0 | X16: =Y16+Z16 -> 0 | AA16: =AB16+AC16 -> 0 | AD16: =AE16+AF16 -> 0 | AG16: =AH16+AI16 -> 0 | AJ16: =AK16+AL16 -> 0 | AM16: =AN16+AO16 -> 0 | AP16: =F16+L16+R16+X16+AD16+AJ16 -> 49 | AQ16: =AP16/E16 -> 0.011502347
B17: 農学部 | C17: 2419 | D17: 600 | E17: 2400 | F17: =G17+H17 -> 36 | G17: 21 | H17: 15 | I17: =J17+K17 -> 3 | J17: 1 | K17: 2 | L17: =M17+N17 -> 0 | O17: =P17+Q17 -> 0 | R17: =S17+T17 -> 0 | U17: =V17+W17 -> 0 | X17: =Y17+Z17 -> 0 | AA17: =AB17+AC17 -> 0 | AD17: =AE17+AF17 -> 0 | AG17: =AH17+AI17 -> 0 | AJ17: =AK17+AL17 -> 0 | AM17: =AN17+AO17 -> 0 | AP17: =F17+L17+R17+X17+AD17+AJ17 -> 36 | AQ17: =AP17/E17 -> 0.015
B18: 経営学部 | C18: 3018 | D18: 745 | E18: 2980 | F18: =G18+H18 -> 17 | G18: 9 | H18: 8 | I18: =J18+K18 -> 2 | J18: 1 | K18: 1 | L18: =M18+N18 -> 0 | O18: =P18+Q18 -> 0 | R18: =S18+T18 -> 0 | U18: =V18+W18 -> 0 | X18: =Y18+Z18 -> 0 | AA18: =AB18+AC18 -> 0 | AD18: =AE18+AF18 -> 0 | AG18: =AH18+AI18 -> 0 | AJ18: =AK18+AL18 -> 0 | AM18: =AN18+AO18 -> 0 | AP18: =F18+L18+R18+X18+AD18+AJ18 -> 17 | AQ18: =AP18/E18 -> 0.005704698
B19: 情報コミュニケーション学部 | C19: 2220 | D19: 520 | E19: 2080 | F19: =G19+H19 -> 26 | G19: 12 | H19: 14 | I19: =J19+K19 -> 14 | J19: 5 | K19: 9 | L19: =M19+N19 -> 0 | O19: =P19+Q19 -> 0 | R19: =S19+T19 -> 0 | U19: =V19+W19 -> 0 | X19: =Y19+Z19 -> 0 | AA19: =AB19+AC19 -> 0 | AD19: =AE19+AF19 -> 0 | AG19: =AH19+AI19 -> 0 | AJ19: =AK19+AL19 -> 0 | AM19: =AN19+AO19 -> 0 | AP19: =F19+L19+R19+X19+AD19+AJ19 -> 26 | AQ19: =AP19/E19 -> 0.0125
B20: 国際日本学部 | C20: 1625 | D20: 400 | E20: 1600 | F20: =G20+H20 -> 23 | G20: 12 | H20: 11 | I20: =J20+K20 -> 5 | J20: 2 | K20: 3 | L20: =M20+N20 -> 0 | O20: =P20+Q20 -> 0 | R20: =S20+T20 -> 0 | U20: =V20+W20 -> 0 | X20: =Y20+Z20 -> 0 | AA20: =AB20+AC20 -> 0 | AD20: =AE20+AF20 -> 0 | AG20: =AH20+AI20 -> 0 | AJ20: =AK20+AL20 -> 0 | AM20: =AN20+AO20 -> 0 | AP20: =F20+L20+R20+X20+AD20+AJ20 -> 23 | AQ20: =AP20/E20 -> 0.014375
B21: 総合数理学部 | C21: 1175 | D21: 300 | E21: 1200 | F21: =G21+H21 -> 63 | G21: 46 | H21: 17 | I21: =J21+K21 -> 63 | J21: 46 | K21: 17 | L21: =M21+N21 -> 0 | O21: =P21+Q21 -> 0 | R21: =S21+T21 -> 0 | U21: =V21+W21 -> 0 | X21: =Y21+Z21 -> 0 | AA21: =AB21+AC21 -> 0 | AD21: =AE21+AF21 -> 0 | AG21: =AH21+AI21 -> 0 | AJ21: =AK21+AL21 -> 0 | AM21: =AN21+AO21 -> 0 | AP21: =F21+L21+R21+X21+AD21+AJ21 -> 63 | AQ21: =AP21/E21 -> 0.0525
F22: =G22+H22 -> 0 | I22: =J22+K22 -> 0 | L22: =M22+N22 -> 0 | O22: =P22+Q22 -> 0 | R22: =S22+T22 -> 0 | U22: =V22+W22 -> 0 | X22: =Y22+Z22 -> 0 | AA22: =AB22+AC22 -> 0 | AD22: =AE22+AF22 -> 0 | AG22: =AH22+AI22 -> 0 | AJ22: =AK22+AL22 -> 0 | AM22: =AN22+AO22 -> 0 | AP22: =F22+L22+R22+X22+AD22+AJ22 -> 0 | AQ22: 0
F23: =G23+H23 -> 0 | I23: =J23+K23 -> 0 | L23: =M23+N23 -> 0 | O23: =P23+Q23 -> 0 | R23: =S23+T23 -> 0 | U23: =V23+W23 -> 0 | X23: =Y23+Z23 -> 0 | AA23: =AB23+AC23 -> 0 | AD23: =AE23+AF23 -> 0 | AG23: =AH23+AI23 -> 0 | AJ23: =AK23+AL23 -> 0 | AM23: =AN23+AO23 -> 0 | AP23: =F23+L23+R23+X23+AD23+AJ23 -> 0 | AQ23: 0
F24: =G24+H24 -> 0 | I24: =J24+K24 -> 0 | L24: =M24+N24 -> 0 | O24: =P24+Q24 -> 0 | R24: =S24+T24 -> 0 | U24: =V24+W24 -> 0 | X24: =Y24+Z24 -> 0 | AA24: =AB24+AC24 -> 0 | AD24: =AE24+AF24 -> 0 | AG24: =AH24+AI24 -> 0 | AJ24: =AK24+AL24 -> 0 | AM24: =AN24+AO24 -> 0 | AP24: =F24+L24+R24+X24+AD24+AJ24 -> 0 | AQ24: 0
F25: =G25+H25 -> 0 | I25: =J25+K25 -> 0 | L25: =M25+N25 -> 0 | O25: =P25+Q25 -> 0 | R25: =S25+T25 -> 0 | U25: =V25+W25 -> 0 | X25: =Y25+Z25 -> 0 | AA25: =AB25+AC25 -> 0 | AD25: =AE25+AF25 -> 0 | AG25: =AH25+AI25 -> 0 | AJ25: =AK25+AL25 -> 0 | AM25: =AN25+AO25 -> 0 | AP25: =F25+L25+R25+X25+AD25+AJ25 -> 0 | AQ25: 0
F26: =G26+H26 -> 0 | I26: =J26+K26 -> 0 | L26: =M26+N26 -> 0 | O26: =P26+Q26 -> 0 | R26: =S26+T26 -> 0 | U26: =V26+W26 -> 0 | X26: =Y26+Z26 -> 0 | AA26: =AB26+AC26 -> 0 | AD26: =AE26+AF26 -> 0 | AG26: =AH26+AI26 -> 0 | AJ26: =AK26+AL26 -> 0 | AM26: =AN26+AO26 -> 0 | AP26: =F26+L26+R26+X26+AD26+AJ26 -> 0 | AQ26: 0
F27: =G27+H27 -> 0 | I27: =J27+K27 -> 0 | L27: =M27+N27 -> 0 | O27: =P27+Q27 -> 0 | R27: =S27+T27 -> 0 | U27: =V27+W27 -> 0 | X27: =Y27+Z27 -> 0 | AA27: =AB27+AC27 -> 0 | AD27: =AE27+AF27 -> 0 | AG27: =AH27+AI27 -> 0 | AJ27: =AK27+AL27 -> 0 | AM27: =AN27+AO27 -> 0 | AP27: =F27+L27+R27+X27+AD27+AJ27 -> 0 | AQ27: 0
F28: =G28+H28 -> 0 | I28: =J28+K28 -> 0 | L28: =M28+N28 -> 0 | O28: =P28+Q28 -> 0 | R28: =S28+T28 -> 0 | U28: =V28+W28 -> 0 | X28: =Y28+Z28 -> 0 | AA28: =AB28+AC28 -> 0 | AD28: =AE28+AF28 -> 0 | AG28: =AH28+AI28 -> 0 | AJ28: =AK28+AL28 -> 0 | AM28: =AN28+AO28 -> 0 | AP28: =F28+L28+R28+X28+AD28+AJ28 -> 0 | AQ28: 0
F29: =G29+H29 -> 0 | I29: =J29+K29 -> 0 | L29: =M29+N29 -> 0 | O29: =P29+Q29 -> 0 | R29: =S29+T29 -> 0 | U29: =V29+W29 -> 0 | X29: =Y29+Z29 -> 0 | AA29: =AB29+AC29 -> 0 | AD29: =AE29+AF29 -> 0 | AG29: =AH29+AI29 -> 0 | AJ29: =AK29+AL29 -> 0 | AM29: =AN29+AO29 -> 0 | AP29: =F29+L29+R29+X29+AD29+AJ29 -> 0 | AQ29: 0
F30: =G30+H30 -> 0 | I30: =J30+K30 -> 0 | L30: =M30+N30 -> 0 | O30: =P30+Q30 -> 0 | R30: =S30+T30 -> 0 | U30: =V30+W30 -> 0 | X30: =Y30+Z30 -> 0 | AA30: =AB30+AC30 -> 0 | AD30: =AE30+AF30 -> 0 | AG30: =AH30+AI30 -> 0 | AJ30: =AK30+AL30 -> 0 | AM30: =AN30+AO30 -> 0 | AP30: =F30+L30+R30+X30+AD30+AJ30 -> 0 | AQ30: 0
F31: =G31+H31 -> 0 | I31: =J31+K31 -> 0 | L31: =M31+N31 -> 0 | O31: =P31+Q31 -> 0 | R31: =S31+T31 -> 0 | U31: =V31+W31 -> 0 | X31: =Y31+Z31 -> 0 | AA31: =AB31+AC31 -> 0 | AD31: =AE31+AF31 -> 0 | AG31: =AH31+AI31 -> 0 | AJ31: =AK31+AL31 -> 0 | AM31: =AN31+AO31 -> 0 | AP31: =F31+L31+R31+X31+AD31+AJ31 -> 0 | AQ31: 0
B32: 合 計 | C32: =SUM(C12:C31) -> 31465 | D32: =SUM(D12:D31) -> 7760 | E32: =SUM(E12:E31) -> 31040 | F32: =SUM(F12:F31) -> 348 | G32: =SUM(G12:G31) -> 226 | H32: =SUM(H12:H31) -> 122 | I32: =SUM(I12:I31) -> 133 | J32: =SUM(J12:J31) -> 88 | ... AP32: =SUM(AP12:AP31) -> 348 | AQ32: =AP32/E32 -> 0.01121134

Sheet 様式３ 教育の質・履修者数を向上させるための体制・計画
I1: 様式３
G2: 大学等名 | H2: ='様式１-１プログラムを構成する授業科目（法学部）'!C2 -> 明治大学
A4: 教育の質・履修者数を向上させるための体制・計画について
A6: ① | B6: 全学の教員数 | C6: (常勤） | E6: 1083 | F6: 人 | G6: （非常勤） | H6: 1782 | I6: 人
A8: ② | B8: プログラムの授業を教えている教員数 | H8: 75 | I8: 人
A10: ③ | B10: プログラムの運営責任者
B11: （責任者名） | C11: 千田亮吉 | G11: （役職名） | H11: 教務部長、副学長
A13: ④ | B13: プログラムを改善・進化させるための体制（委員会・組織等）
B14: 教育開発・支援センター運営委員会
B16: （責任者名） | C16: 千田亮吉 | G16: （役職名） | H16: 教育開発・支援センター長
A18: ⑤ | B18: プログラムを改善・進化させるための体制を定める規則名称
B19: 明治大学教育開発・支援センター規程
A21: ⑥ | B21: 体制の目的
B22: 本大学の教育理念及び教育目標を実現するため，全学的な教育支援体制に係る諸施策の立案及びその推進を図るとともに，組織的かつ継続的に教育内容及び教育技法の改善を行うことによって，効果的な教育活動の実践を支援・促進し，もって本大学の教育の発展に寄与することを目的とする。
A34: ⑦ | B34: 具体的な構成員
B35: センター長 教務部長 千田 亮吉 副センター長 副教務部長 阿原 一志 センター員 副教務部長 瀬倉 正克、副教務部長 武田 巧、副教務部長 石原 康利、副教務部長 加藤 久和 運営委員 法学部 神田 正行、商学部 前田 陽、政治経済学部 西村 弥、文学部 駒見 和夫、理工学部 松澤 淳、農学部 織田 哲司、経営学部 三上真寛、情報コミュニケーション学部 竹中 克久、国際日本学部 岸 磨貴子、総合数理学部 中村 和幸、大学院 石川 雅信、大学院 佐々木 貴規、専門職大学院 藤岡 資正、学長室専門員 高橋 一行、教務事務部長 前田 浩
A48: ⑧ | B48: 履修者数・履修率の向上に向けた計画 ※様式１の「履修必須の有無」で「計画がある」としている場合は詳細について記載すること
B49: 令和４年度実績 | C49: ='様式２ 履修者等数の実績'!AQ32 -> 0.01121134 | E49: 令和５年度予定 | F49: 0.03 | H49: 令和６年度予定 | I49: 0.06
B50: 令和７年度予定 | C50: 0.08 | E50: 令和８年度予定 | F50: 0.1 | H50: 収容定員（名） | I50: ='様式２ 履修者等数の実績'!E32 -> 31040
B51: 具体的な計画
B52: 目標を実現するために、令和３年度より、ティーチング・アシスタント配置による授業時間内外での学習指導、質問を受け付ける仕組みにより、学生のプログラム履修を促進している。また、令和４年度に本学が主催したシンポジウムにおける他大学の事例を基に、広報および改善を継続的に実施、全学的な履修率向上を推進に活かす。 全学部の「データサイエンス・ＡＩの社会利用」科目群にあたる「データサイエンスAI概論」について、令和６年度以降は春学期に加えて秋学期も開講することで、履修者数の倍増を目指す。
A65: ⑨ | B65: 学部・学科に関係なく希望する学生全員が受講可能となるような必要な体制・取組等
B66: 「データサイエンス・ＡＩの社会利用」科目群はリアルタイム配信でどこにいても履修が可能であり、 「データサイエンス・人工知能演習」科目群は対面型・フルオンラインクラスを選択可能とし、いずれも学部・所属キャンパスに関係なく履修可能としている。 また、Oh-o!Meijiシステム（LMS）アンケート機能により授業時間内外で質問可能とし、全学的な履修を支援・促進している。
A79: ⑩ | B79: できる限り多くの学生が履修できるような具体的な周知方法・取組
B80: 入学後のガイダンス、本学のWEBサイト上での周知、プレスリリースにより、学生が情報を受け取りやすい環境を整備している。
A93: ⑪ | B93: できる限り多くの学生が履修・修得できるようなサポート体制
B94: 「データサイエンス・ＡＩの社会利用」科目群はリアルタイム配信でどこにいても履修が可能、 「データサイエンス・人工知能演習」科目群は対面型・フルオンラインクラスを選択可能。 ※いずれも学部・所属キャンパスに関係なく履修可能
A107: ⑫ | B107: 授業時間内外で学習指導、質問を受け付ける具体的な仕組み
B108: Oh-o!Meijiシステム（LMS）アンケート機能により授業時間内外で質問可能。 「データサイエンス・ＡＩの社会利用」及び「データサイエンス・人工知能演習」科目群では全クラスにティーチング・アシスタントが配置され、きめ細やかな学修支援が可能。 統計解析・プログラミング等に使用する各ソフトウェアが導入されたパソコンを常時利用可。 ソフトウェア利用支援のスタッフが全てのキャンパスの自習室に常駐。

Sheet 様式４　自己点検・評価
I1: 様式４
H2: 大学等名 | I2: ='様式１-１プログラムを構成する授業科目（法学部）'!C2 -> 明治大学
A3: 自己点検・評価について
A5: ① | B5: プログラムの自己点検・評価を行う体制（委員会・組織等）
B6: 教育開発・支援センター運営委員会
D8: （責任者名） | E8: 千田亮吉 | G8: （役職名） | H8: 教育開発・支援センター長
A10: ② | B10: 自己点検・評価体制における意見等
B11: 自己点検・評価の視点 | E11: 自己点検・評価体制における意見・結果・改善に向けた取組等
B12: 学内からの視点
C13: プログラムの履修・修得状況 | E13: 履修データからプログラムの履修状況を把握し、各学部において判定シートを作成することで、受講者毎の修了要件単位取得状況を把握することができる。2022年度春学期は118名の修了が認定された。 修了者数は１％未満であり、修得率を向上させる体制が求められる。 目標を実現するために、2022年度中にシンポジウムを開催したため、他大学の事例を基に、広報および改善を継続的に実施、全学的な履修率向上を推進に活かす。また、2022年度は春学期にリアルタイム配信での開講だった「データサイエンスAI概論」講座を、2023年度には曜日時限の設定を外したオンデマンド型で開講することで履修できる学生を増やす。
C14: 学修成果 | E14: 教育開発・支援センターにおいて、修了必須科目受講者に対して「数理データサイエンス人工知能リテラシーレベルプログラムに関するアンケート」を実施し、「設問２：この科目を履修して，どのようなことが理解できるようになりましたか」の項目を分析することによって、テーマごとの学修成果を把握することができ、その結果を本教育プログラムの評価・改善に活用している。 「社会で起きている変化や活用されているデータ」「データ・AIを活用した新しいビジネス・サービス・技術」「データ・AIを利活用することで生まれる付加価値や最新動向（ビジネスモデル・テクノロジー）」「データ・AIを扱う上、またデータを守る上での留意事項」といったテーマをそれぞれ満遍なく理解できたとの回答があった。より幅広いテーマで学生が理解できるよう、引き続き精査する。
C15: 学生アンケート等を通じた学生の内容の理解度 | E15: 教育開発・支援センターにおいて、修了必須科目受講者に対して「数理データサイエンス人工知能リテラシーレベルプログラムに関するアンケート」を実施し、「設問３：データサイエンスAI概論」の授業内容を理解できましたか」の項目を分析することによって、学生の理解度を分析している。 「とても理解できた」と「少し理解できた」が合わせて95％に達した。さらなる理解度向上に向けて、講師からのアンケートにて意見のあった「初回授業で、人工知能概論として、現在のAIの技術がどの程度普及しているかを伝える」ことを、2023年度から行う。
C16: 学生アンケート等を通じた後輩等他の学生への推奨度 | E16: 教育開発・支援センターにおいて、修了必須科目受講者に対して「数理データサイエンス人工知能リテラシーレベルプログラムに関するアンケート」を実施し、「設問４：学生アンケート等を通じた後輩等他の学生への推奨度」の項目を分析することによって、後輩学生や他の学生への推奨について確認している。 「数理データサイエンス人工知能リテラシーレベルプログラムを他の学生にも勧めたい」は85％に達した。Oh-o!Meijiシステム（LMS）アンケート機能により授業時間内外で質問対応、ティーチング・アシスタントの配置できめ細やかな学修支援を行うことで、引き続き高い水準を目指す。
C17: 全学的な履修者数、履修率向上に向けた計画の達成・進捗状況 | E17: 本教育プログラムについては教育開発・支援センターにおいて、履修者数、履修率の向上にむけて、随時検討を行い、学生の履修を推進している。 入学後のガイダンス、本学のWEBサイト上での周知、プレスリリースにより、学生が情報を受け取りやすい環境を整備することで、高い水準を目指す。
B18: 学外からの視点
C19: 教育プログラム修了者の進路、活躍状況、企業等の評価 | E19: まだ修了者の卒業生が不在のため把握はできていないが、「データサイエンスＡＩ概論」の講師の中で、企業に所属している実務経験者にアンケートを実施し、受講生の授業態度（質問の量・質）、課題・リアクションペーパー等への入力内容から、受講生の質を聞いている。 受講生の質について、「とても評価できる」「少し評価できる」が合わせて100％となり、企業に所属する実務経験者からも評価されている。今後は修了者の進路を集計することで、本プログラム取得に係る影響を調査する。
C20: 産業界からの視点を含めた教育プログラム内容・手法等への意見 | E20: 「データサイエンスＡＩ概論」の講師の中で、企業に所属している実務経験者にアンケートを実施し、プログラム改善に係る意見を収集するとともに、教育開発・支援センターにおいてプログラムの改善に活用している。 理解度向上に向けて、「初回授業で、人工知能概論として、現在のAIの技術がどの程度普及しているかを伝える」ことを、2023年度から行う。 また、履修者数をもっと増やしても良いとの意見もあり、2022年度は春学期にリアルタイム配信での開講だった「データサイエンスAI概論」講座を、2023年度には曜日時限の設定を外したオンデマンド型で開講することで履修できる学生を増やす。
B21: 数理・データサイエンス・ＡＩを「学ぶ楽しさ」「学ぶことの意義」を理解させること | E21: 教育開発・支援センターにおいて、修了必須科目受講者に対して「数理データサイエンス人工知能リテラシーレベルプログラムに関するアンケート」を実施し、「設問５：「データサイエンスAI概論」を受講して、データサイエンスや人工知能への関心が高まったり、これを学ぶ意義が理解できましたか」の項目を分析している。 「大いに当てはまる」が85％、「やや当てはまる」15％で、全員が「学ぶ楽しさ」「学ぶことの意義」を理解したと回答した。
B22: 内容・水準を維持・向上しつつ、より「分かりやすい」授業とすること | E22: 教育開発・支援センターにおいて、修了必須科目についても「授業改善アンケート」を実施した。 難易度について「とても難しい」が10％、「少し難しい」が30％、「ちょうど良い」が60％との回答があり、難易度が高いと感じる学生が少し多かった。しかし授業の進むスピードは「ちょうど良い」が92％、資料の見やすさは「とても見やすい」「おおむね見やすい」が合わせて93％、満足度も「とても良い授業だと思う」「おおむね良い授業だと思う」が合わせて100％と高かった。難易度が少し高いものを理解しやすい形で運営できたことは、次年度以降も引き続き継続する。
