Workbook

Sheet 様式１　プログラムを構成する授業科目 
R1: 様式１ | T1: 「学部・学科によって、修了要件は相違する」場合は、本シートを複製の上＜様式１－〇＞と枝番号を付してください
B2: 大学等名 | C2: 流通科学大学
B3: プログラム名 | C3: 数理・データサイエンス・AI教育プログラム
A5: プログラムを構成する授業科目について
A7: ① 対象となる学部・学科名称 | J7: ② 教育プログラムの修了要件 | K7: 学部・学科によって、修了要件は相違しない
A12: ③ 修了要件
B13: 全学基礎科目・専門基礎「デジタル社会の基礎知識」2単位を取得すること。 | V13: 【プルダウンリスト】
V14: 令和４年度以前より、履修することが必須のプログラムとして実施
V15: 令和７年度までに履修必須とする計画
V16: 令和８年度以降に履修必須とする計画、又は未定
B20: 必要最低単位数 | C20: 2 | E20: 単位 | J20: 履修必須の有無 | K20: 令和８年度以降に履修必須とする計画、又は未定
A22: ④ 現在進行中の社会変化（第４次産業革命、Society 5.0、データ駆動型社会等）に深く寄与しているものであり、それが自らの生活と密接に結びついている」の内容を含む授業科目
B24: 授業科目 | F24: 単位数 | G24: 必須 | H24: 1-1 | I24: 1-6 | J24: 授業科目 | P24: 単位数 | Q24: 必須 | R24: 1-1 | S24: 1-6
B25: デジタル社会の基礎知識 | F25: 2 | G25: ○ | H25: ○ | I25: ○
A33: ⑤ 「社会で活用されているデータ」や「データの活用領域」は非常に広範囲であって、日常生活や社会の課題を解決する有用なツールになり得るもの」の内容を含む授業科目
B35: 授業科目 | F35: 単位数 | G35: 必須 | H35: 1-2 | I35: 1-3 | J35: 授業科目 | P35: 単位数 | Q35: 必須 | R35: 1-2 | S35: 1-3
B36: デジタル社会の基礎知識 | F36: 2 | G36: ○ | H36: ○ | I36: ○
A44: ⑥ 「様々なデータ利活用の現場におけるデータ利活用事例が示され、様々な適用領域（流通、製造、金融、サービス、インフラ、公共、ヘルスケア等）の知見と組み合わせることで価値を創出するもの」の内容を含む授業科目
B46: 授業科目 | F46: 単位数 | G46: 必須 | H46: 1-4 | I46: 1-5 | J46: 授業科目 | P46: 単位数 | Q46: 必須 | R46: 1-4 | S46: 1-5
B47: デジタル社会の基礎知識 | F47: 2 | G47: ○ | H47: ○ | I47: ○
A55: ⑦ 「活用に当たっての様々な留意事項（ELSI、個人情報、データ倫理、ＡＩ社会原則等）を考慮し、情報セキュリティや情報漏洩等、データを守る上での留意事項への理解をする」の内容を含む授業科目
B57: 授業科目 | F57: 単位数 | G57: 必須 | H57: 3-1 | I57: 3-2 | J57: 授業科目 | P57: 単位数 | Q57: 必須 | R57: 3-1 | S57: 3-2
B58: デジタル社会の基礎知識 | F58: 2 | G58: ○ | H58: ○ | I58: ○
A66: ⑧ 「実データ・実課題（学術データ等を含む）を用いた演習など、社会での実例を題材として、「データを読む、説明する、扱う」といった数理・データサイエンス・ＡＩの基本的な活用法に関するもの」の内容を含む授業科目
B68: 授業科目 | E68: 単位数 | F68: 必須 | G68: 2-1 | H68: 2-2 | I68: 2-3 | J68: 授業科目 | O68: 単位数 | P68: 必須 | Q68: 2-1 | R68: 2-2 | S68: 2-3
B69: デジタル社会の基礎知識 | E69: 2 | F69: ○ | G69: ○ | H69: ○ | I69: ○
A77: ⑨ 選択「４．オプション」の内容を含む授業科目
B78: 授業科目 | F78: 選択項目 | J78: 授業科目 | P78: 選択項目
A87: ⑩ プログラムを構成する授業の内容
B88: 授業に含まれている内容・要素 | D88: 講義内容
B89: （１）現在進行中の社会変化（第４次産業革命、Society 5.0、データ駆動型社会等）に深く寄与しているものであり、それが自らの生活と密接に結びついている | C89: 1-1 | D89: 1-1.社会で起きている変化 ・身近なコミュニケーションツール、仕事、商品サービスの変化 ・計算機の処理性能の向上と通信ネットワークの向上、データ量の増加 「デジタル社会の基礎知識」（第1回） ・第4次産業革命、Society5.0、データ駆動型社会とライフスタイルの変化 「デジタル社会の基礎知識」（第2回） ・IoTが活かされる場面、ビッグデータ 「デジタル社会の基礎知識」（第4回） ・社会の課題解決につながるAI、ロボット技術の活用 「デジタル社会の基礎知識」（第7回） ・データを起点としたものの見方 「デジタル社会の基礎知識」（第8回）
C90: 1-6 | D90: 1-6.データ・AI利活用の最新動向 AI等を活用した新しいビジネスモデル ・商品のレコメンデーション ・動画共有サイトでの推薦システム ・位置情報と気象情報を用いた物流 ・AIの学習（教師あり、ディープラーニング、強化学習） 「デジタル社会の基礎知識」（第6回）
B91: （２）「社会で活用されているデータ」や「データの活用領域」は非常に広範囲であって、日常生活や社会の課題を解決する有用なツールになり得るもの | C91: 1-2 | D91: 1-2. 社会で活用されているデータ ・意図しない発信データの収集、人の行動ログデータ ・モノが発信するデータの収集、機械の稼働ログデータ 「デジタル社会の基礎知識」（第3回） ・構造化データと非構造化データ（文章、画像/動画、音声/音楽） 「デジタル社会の基礎知識」（第4回） ・IoTとビッグデータ 「デジタル社会の基礎知識」（第4回） ・生活の中で目にするデータ活用（調査データ、観測データ、実験データ） 「デジタル社会の基礎知識」（第8回） ・オープンデータの利用 「デジタル社会の基礎知識」（第11回）
C92: 1-3 | D92: 1-3. データ・AIの活用領域 ・製造・販促活動・マーケティングでの画像認識技術の活用例 「デジタル社会の基礎知識」（第５回） ・小売、観光、サービス業でのダイナミックプライシング ・製造、販売、小売業の現場での画像認識技術 「デジタル社会の基礎知識」（第6回） ・位置情報と気象情報を用いた物流 ・人の意思決定と判断支援、仮説検証、計画策定 ・データ・AI活用領域の広がりを確かめる（日常生活でデータ・AIを活用している場面や身近な例を探索） ※レポート課題 「デジタル社会の基礎知識」（第7回）
B93: （３）様々なデータ利活用の現場におけるデータ利活用事例が示され、様々な適用領域（流通、製造、金融、サービス、インフラ、公共、ヘルスケア等）の知見と組み合わせることで価値を創出するもの | C93: 1-4 | D93: 1-4. データ・AI利活用のための技術 ・コンピュータプログラムとAIの違い ・特化型AIと汎用AI、身近なAIの活用例 ・機械学習、深層学習 ・強いAIと弱いAI（今のAIで出来ることと出来ないこと） ・製造、販売現場での画像認識技術 「デジタル社会の基礎知識」（第6回） ・スポーツでの挙動・軌跡の可視化などAI・データの活用例 「デジタル社会の基礎知識」（第5回） ・AIの浸透と社会の変化、AIとビッグデータ 「デジタル社会の基礎知識」（第7回） ・データの予測、シミュレーション（少子高齢化社会のデータから） 「デジタル社会の基礎知識」（第7回） ・データ解析の手法（ABC分析：データ解析、RFM分析：グルーピング、バスケット分析：パターン発見） 「デジタル社会の基礎知識」（第12回） ・適切なデータ表現（棒グラフ、折線グラフ、散布図による関係性の可視化、複合グラフ） 「デジタル社会の基礎知識」（第9回）
C94: 1-5 | D94: 1-5. データ・AI利活用の現場 ・商品のレコメンデーションの仕組み ・流通業における顧客サービス ・製造、販促活動・マーケティングでの画像認識技術の活用例 ※レポート課題 「デジタル社会の基礎知識」 （第５回） ・製造、販売、小売業の現場での画像認識技術 ・小売、観光業、サービス業でのダイナミックプライシング ・交通インフラ建設でのデータ活用 ・スポーツでの挙動のトラッキング ・医療・ヘルスケア分野でのAI・データの活用事例 ※レポート課題 「デジタル社会の基礎知識」 （第6回） ・AIが導き出した結果の共有と伝達、社会の課題抽出と課題解決に向けた提案 「デジタル社会の基礎知識」（第7回）（第15回）
B95: （４）活用に当たっての様々な留意事項（ELSI、個人情報、データ倫理、ＡＩ社会原則等）を考慮し、情報セキュリティや情報漏洩等、データを守る上での留意事項への理解をする | C95: 3-1 | D95: 3-1. データ・AI利活用における留意事項 個人情報と情報資産の保護 ・個人情報の第三者提供、オプトアウト ・個人情報保護法 ・データ倫理（プライバシー保護、ねつ造・改ざん・盗用のリスク） ・EU一般データ保護規則（GDPR）、十分性認定、忘れられる権利 「デジタル社会の基礎知識」 （第14回） AI社会で求められる倫理観 ・ELSI（Ethical,Legal and Social Issues） ・AI社会原則（Fairness公平性、Accountability説明責任、Transparency透明性、人間中心の判断） ・サンプリングバイアス、データバイアス、アルゴリズムバイアス、測定バイアス、確証バイアス、認知バイアス） ・AIサービスの責任論（自動運転、医療現場の例） ・データ・AI活用における負の事例紹介（ディープフェイクニュース、人材採用・翻訳ツールに見られる差別など） ※レポート課題 「デジタル社会の基礎知識」 （第15回）
C96: 3-2 | D96: 3-2. データを守る上での留意事項 情報資産のリスクと脅威 ・情報資産を脅かす脅威と情報セキュリティレベル ・情報漏洩等によるセキュリティ事故の事例紹介 ・情報セキュリティの3要素（機密性、完全性、可用性） ・データの守秘（強いパスワード、暗号化と復号） ・個人識別符号と個人関連情報 ・匿名加工情報と仮名加工情報 「デジタル社会の基礎知識」 （第14回）
B97: （５）実データ・実課題（学術データ等を含む）を用いた演習など、社会での実例を題材として、「データを読む、説明する、扱う」といった数理・データサイエンス・ＡＩの基本的な活用法に関するもの | C97: 2-1 | D97: 2-1. データを読む データ解析の手法 ・データの種類（量的変数と質的変数） ・代表値（平均値、中央値、最頻値）の性質の違い ・データの分布（度数とヒストグラム） ※スプレッドシートを用いた演習 「デジタル社会の基礎知識」（第8回） ・クロス集計表（属性クロス集計、設問間クロス集計） ・定量分析と定性分析、構造化データと非構造化データ ・テキストマイニング ※ニュース記事、商品レビューなど身近な題材を用いた演習 ・データのばらつき（分散と標準偏差、偏差値） ※スプレッドシートを用いた演習 「デジタル社会の基礎知識」（第10回） ・共分散と相関係数 ・相関と因果、疑似相関の例 ※スプレッドシートを用いた演習 「デジタル社会の基礎知識」（第12回） ・母集団と標本抽出（全数調査（国勢調査）と標本調査（アンケート調査、世論調査）の違い） ・単純無作為抽出、層別抽出、多段抽出の利用場面 「デジタル社会の基礎知識」（第13回） 統計情報の正しい理解 「デジタル社会の基礎知識」（第11回）
C98: 2-2 | D98: 2-2. データを説明する ・グラフの種類と使い分け ・適切なデータ表現（棒グラフ、折線グラフ、散布図による関係性の可視化、複合グラフ） ・不適切なグラフ表現の例（不必要な視覚的要素） ・データの可視化によって得られる新たな気づき、データの可視化事例の紹介（年代ごとのメディアの平均利用時間の推移、売上と天候・気温の関係性から） 「デジタル社会の基礎知識」（第9回）
...

Sheet 様式２ 履修者等数の実績
AQ1: 様式２
AL2: 大学等名 | AM2: ='様式１ プログラムを構成する授業科目 '!C2 -> 流通科学大学
A3: プログラムの履修者数等の実績について
A5: ①プログラム開設年度 | C5: 令和４年度 | E5: 年度
A7: ②履修者・修了者の実績
B9: 学部・学科名称 | C9: 学生数 | D9: 入学 定員 | E9: 収容 定員 | F9: 令和4年度 | L9: 令和3年度 | R9: 令和2年度 | X9: 令和元年度 | AD9: 平成30年度 | AJ9: 平成29年度 | AP9: 履修者数 合計 | AQ9: 履修率
F10: 履修者数 | I10: 修了者数 | L10: 履修者数 | O10: 修了者数 | R10: 履修者数 | U10: 修了者数 | X10: 履修者数 | AA10: 修了者数 | AD10: 履修者数 | AG10: 修了者数 | AJ10: 履修者数 | AM10: 修了者数
F11: 合計 | G11: 男性 | H11: 女性 | I11: 合計 | J11: 男性 | K11: 女性 | L11: 合計 | M11: 男性 | N11: 女性 | O11: 合計 | P11: 男性 | Q11: 女性 | R11: 合計 | S11: 男性 | T11: 女性 | U11: 合計 | V11: 男性 | W11: 女性 | X11: 合計 | Y11: 男性 | Z11: 女性 | AA11: 合計 | AB11: 男性 | AC11: 女性 | AD11: 合計 | AE11: 男性 | AF11: 女性 | AG11: 合計 | AH11: 男性 | AI11: 女性 | AJ11: 合計 | AK11: 男性 | AL11: 女性 | AM11: 合計 | AN11: 男性 | AO11: 女性
B12: 商学部 | C12: 1900 | D12: 450 | E12: 1800 | F12: 299 | G12: 232 | H12: 67 | I12: =J12+K12 -> 205 | J12: 152 | K12: 53 | L12: =M12+N12 -> 0 | O12: =P12+Q12 -> 0 | R12: =S12+T12 -> 0 | U12: =V12+W12 -> 0 | X12: =Y12+Z12 -> 0 | AA12: =AB12+AC12 -> 0 | AD12: =AE12+AF12 -> 0 | AG12: =AH12+AI12 -> 0 | AJ12: =AK12+AL12 -> 0 | AM12: =AN12+AO12 -> 0 | AP12: =F12+L12+R12+X12+AD12+AJ12 -> 299 | AQ12: =AP12/E12 -> 0.16611111
B13: 経済学部 | C13: 887 | D13: 200 | E13: 800 | F13: 163 | G13: 138 | H13: 25 | I13: =J13+K13 -> 137 | J13: 112 | K13: 25 | L13: =M13+N13 -> 0 | O13: =P13+Q13 -> 0 | R13: =S13+T13 -> 0 | U13: =V13+W13 -> 0 | X13: =Y13+Z13 -> 0 | AA13: =AB13+AC13 -> 0 | AD13: =AE13+AF13 -> 0 | AG13: =AH13+AI13 -> 0 | AJ13: =AK13+AL13 -> 0 | AM13: =AN13+AO13 -> 0 | AP13: =F13+L13+R13+X13+AD13+AJ13 -> 163 | AQ13: =AP13/E13 -> 0.20375
B14: 人間社会学部 | C14: 1049 | D14: 250 | E14: 1000 | F14: 167 | G14: 105 | H14: 62 | I14: =J14+K14 -> 142 | J14: 87 | K14: 55 | L14: =M14+N14 -> 0 | O14: =P14+Q14 -> 0 | R14: =S14+T14 -> 0 | U14: =V14+W14 -> 0 | X14: =Y14+Z14 -> 0 | AA14: =AB14+AC14 -> 0 | AD14: =AE14+AF14 -> 0 | AG14: =AH14+AI14 -> 0 | AJ14: =AK14+AL14 -> 0 | AM14: =AN14+AO14 -> 0 | AP14: =F14+L14+R14+X14+AD14+AJ14 -> 167 | AQ14: =AP14/E14 -> 0.167
F15: =G15+H15 -> 0 | I15: =J15+K15 -> 0 | L15: =M15+N15 -> 0 | O15: =P15+Q15 -> 0 | R15: =S15+T15 -> 0 | U15: =V15+W15 -> 0 | X15: =Y15+Z15 -> 0 | AA15: =AB15+AC15 -> 0 | AD15: =AE15+AF15 -> 0 | AG15: =AH15+AI15 -> 0 | AJ15: =AK15+AL15 -> 0 | AM15: =AN15+AO15 -> 0 | AP15: =F15+L15+R15+X15+AD15+AJ15 -> 0 | AQ15: =AP15/E15 -> #DIV/0!
F16: =G16+H16 -> 0 | I16: =J16+K16 -> 0 | L16: =M16+N16 -> 0 | O16: =P16+Q16 -> 0 | R16: =S16+T16 -> 0 | U16: =V16+W16 -> 0 | X16: =Y16+Z16 -> 0 | AA16: =AB16+AC16 -> 0 | AD16: =AE16+AF16 -> 0 | AG16: =AH16+AI16 -> 0 | AJ16: =AK16+AL16 -> 0 | AM16: =AN16+AO16 -> 0 | AP16: =F16+L16+R16+X16+AD16+AJ16 -> 0 | AQ16: =AP16/E16 -> #DIV/0!
F17: =G17+H17 -> 0 | I17: =J17+K17 -> 0 | L17: =M17+N17 -> 0 | O17: =P17+Q17 -> 0 | R17: =S17+T17 -> 0 | U17: =V17+W17 -> 0 | X17: =Y17+Z17 -> 0 | AA17: =AB17+AC17 -> 0 | AD17: =AE17+AF17 -> 0 | AG17: =AH17+AI17 -> 0 | AJ17: =AK17+AL17 -> 0 | AM17: =AN17+AO17 -> 0 | AP17: =F17+L17+R17+X17+AD17+AJ17 -> 0 | AQ17: =AP17/E17 -> #DIV/0!
F18: =G18+H18 -> 0 | I18: =J18+K18 -> 0 | L18: =M18+N18 -> 0 | O18: =P18+Q18 -> 0 | R18: =S18+T18 -> 0 | U18: =V18+W18 -> 0 | X18: =Y18+Z18 -> 0 | AA18: =AB18+AC18 -> 0 | AD18: =AE18+AF18 -> 0 | AG18: =AH18+AI18 -> 0 | AJ18: =AK18+AL18 -> 0 | AM18: =AN18+AO18 -> 0 | AP18: =F18+L18+R18+X18+AD18+AJ18 -> 0 | AQ18: =AP18/E18 -> #DIV/0!
F19: =G19+H19 -> 0 | I19: =J19+K19 -> 0 | L19: =M19+N19 -> 0 | O19: =P19+Q19 -> 0 | R19: =S19+T19 -> 0 | U19: =V19+W19 -> 0 | X19: =Y19+Z19 -> 0 | AA19: =AB19+AC19 -> 0 | AD19: =AE19+AF19 -> 0 | AG19: =AH19+AI19 -> 0 | AJ19: =AK19+AL19 -> 0 | AM19: =AN19+AO19 -> 0 | AP19: =F19+L19+R19+X19+AD19+AJ19 -> 0 | AQ19: =AP19/E19 -> #DIV/0!
F20: =G20+H20 -> 0 | I20: =J20+K20 -> 0 | L20: =M20+N20 -> 0 | O20: =P20+Q20 -> 0 | R20: =S20+T20 -> 0 | U20: =V20+W20 -> 0 | X20: =Y20+Z20 -> 0 | AA20: =AB20+AC20 -> 0 | AD20: =AE20+AF20 -> 0 | AG20: =AH20+AI20 -> 0 | AJ20: =AK20+AL20 -> 0 | AM20: =AN20+AO20 -> 0 | AP20: =F20+L20+R20+X20+AD20+AJ20 -> 0 | AQ20: =AP20/E20 -> #DIV/0!
F21: =G21+H21 -> 0 | I21: =J21+K21 -> 0 | L21: =M21+N21 -> 0 | O21: =P21+Q21 -> 0 | R21: =S21+T21 -> 0 | U21: =V21+W21 -> 0 | X21: =Y21+Z21 -> 0 | AA21: =AB21+AC21 -> 0 | AD21: =AE21+AF21 -> 0 | AG21: =AH21+AI21 -> 0 | AJ21: =AK21+AL21 -> 0 | AM21: =AN21+AO21 -> 0 | AP21: =F21+L21+R21+X21+AD21+AJ21 -> 0 | AQ21: =AP21/E21 -> #DIV/0!
F22: =G22+H22 -> 0 | I22: =J22+K22 -> 0 | L22: =M22+N22 -> 0 | O22: =P22+Q22 -> 0 | R22: =S22+T22 -> 0 | U22: =V22+W22 -> 0 | X22: =Y22+Z22 -> 0 | AA22: =AB22+AC22 -> 0 | AD22: =AE22+AF22 -> 0 | AG22: =AH22+AI22 -> 0 | AJ22: =AK22+AL22 -> 0 | AM22: =AN22+AO22 -> 0 | AP22: =F22+L22+R22+X22+AD22+AJ22 -> 0 | AQ22: =AP22/E22 -> #DIV/0!
F23: =G23+H23 -> 0 | I23: =J23+K23 -> 0 | L23: =M23+N23 -> 0 | O23: =P23+Q23 -> 0 | R23: =S23+T23 -> 0 | U23: =V23+W23 -> 0 | X23: =Y23+Z23 -> 0 | AA23: =AB23+AC23 -> 0 | AD23: =AE23+AF23 -> 0 | AG23: =AH23+AI23 -> 0 | AJ23: =AK23+AL23 -> 0 | AM23: =AN23+AO23 -> 0 | AP23: =F23+L23+R23+X23+AD23+AJ23 -> 0 | AQ23: =AP23/E23 -> #DIV/0!
F24: =G24+H24 -> 0 | I24: =J24+K24 -> 0 | L24: =M24+N24 -> 0 | O24: =P24+Q24 -> 0 | R24: =S24+T24 -> 0 | U24: =V24+W24 -> 0 | X24: =Y24+Z24 -> 0 | AA24: =AB24+AC24 -> 0 | AD24: =AE24+AF24 -> 0 | AG24: =AH24+AI24 -> 0 | AJ24: =AK24+AL24 -> 0 | AM24: =AN24+AO24 -> 0 | AP24: =F24+L24+R24+X24+AD24+AJ24 -> 0 | AQ24: =AP24/E24 -> #DIV/0!
F25: =G25+H25 -> 0 | I25: =J25+K25 -> 0 | L25: =M25+N25 -> 0 | O25: =P25+Q25 -> 0 | R25: =S25+T25 -> 0 | U25: =V25+W25 -> 0 | X25: =Y25+Z25 -> 0 | AA25: =AB25+AC25 -> 0 | AD25: =AE25+AF25 -> 0 | AG25: =AH25+AI25 -> 0 | AJ25: =AK25+AL25 -> 0 | AM25: =AN25+AO25 -> 0 | AP25: =F25+L25+R25+X25+AD25+AJ25 -> 0 | AQ25: =AP25/E25 -> #DIV/0!
F26: =G26+H26 -> 0 | I26: =J26+K26 -> 0 | L26: =M26+N26 -> 0 | O26: =P26+Q26 -> 0 | R26: =S26+T26 -> 0 | U26: =V26+W26 -> 0 | X26: =Y26+Z26 -> 0 | AA26: =AB26+AC26 -> 0 | AD26: =AE26+AF26 -> 0 | AG26: =AH26+AI26 -> 0 | AJ26: =AK26+AL26 -> 0 | AM26: =AN26+AO26 -> 0 | AP26: =F26+L26+R26+X26+AD26+AJ26 -> 0 | AQ26: =AP26/E26 -> #DIV/0!
... F31: =G31+H31 -> 0 | I31: =J31+K31 -> 0 | L31: =M31+N31 -> 0 | O31: =P31+Q31 -> 0 | R31: =S31+T31 -> 0 | U31: =V31+W31 -> 0 | X31: =Y31+Z31 -> 0 | AA31: =AB31+AC31 -> 0 | AD31: =AE31+AF31 -> 0 | AG31: =AH31+AI31 -> 0 | AJ31: =AK31+AL31 -> 0 | AM31: =AN31+AO31 -> 0 | AP31: =F31+L31+R31+X31+AD31+AJ31 -> 0 | AQ31: =AP31/E31 -> #DIV/0!
B32: 合 計 | C32: =SUM(C12:C31) -> 3836 | D32: =SUM(D12:D31) -> 900 | E32: =SUM(E12:E31) -> 3600 | F32: =SUM(F12:F31) -> 629 | G32: =SUM(G12:G31) -> 475 | H32: =SUM(H12:H31) -> 154 | I32: =SUM(I12:I31) -> 484 | J32: =SUM(J12:J31) -> 351 | ... AP32: =SUM(AP12:AP31) -> 629 | AQ32: =AP32/E32 -> 0.17472222

Sheet 様式３ 教育の質・履修者数を向上させるための体制・計画
I1: 様式３
G2: 大学等名 | H2: ='様式１ プログラムを構成する授業科目 '!C2 -> 流通科学大学
A4: 教育の質・履修者数を向上させるための体制・計画について
A6: ① | B6: 全学の教員数 | C6: (常勤） | E6: 104 | F6: 人 | G6: （非常勤） | H6: 97 | I6: 人
A8: ② | B8: プログラムの授業を教えている教員数 | H8: 4 | I8: 人
A10: ③ | B10: プログラムの運営責任者 | H10: パソコンの基礎を入れると専任８、非常勤４
B11: （責任者名） | C11: 藤井啓吾 | G11: （役職名） | H11: 学長
A13: ④ | B13: プログラムを改善・進化させるための体制（委員会・組織等）
B14: 教務委員会／数理・データサイエンス・AI教育専門部会
B16: （責任者名） | C16: 福田司文 | G16: （役職名） | H16: 副学長 教務委員長
A18: ⑤ | B18: プログラムを改善・進化させるための体制を定める規則名称
B19: 流通科学大学教務委員会規程
A21: ⑥ | B21: 体制の目的
B22: 教務委員会下の数理・データサイエンス・AI教育専門部会により、本プログラムの履修者数・履修率の向上に向けた計画、学部・学科に関係なく希望する学生全員が受講可能となるような体制・取り組み、できる限り多くの学生が履修できるような具体的な周知方法・取り組み、サポート体制の構築、授業時間内外で学習指導、質問を受け付ける具体的な仕組みについて検討、改善を行う。また、本学の情報処理教育全般の改善、進化および自己点検を行う。
A33: ⑦ | B33: 具体的な構成員
B34: ・教務委員長（数理・データサイエンス・AI教育専門部会長 流通科学大学 副学長・商学部経営学科 教授 福田司文 ・高等教育推進センター長 流通科学大学 商学部 マーケティング学科 教授 南木睦彦 ・流通科学大学教務部長 柴田智英 ・その他、数理・データサイエンス・AI教育専門部会長が指名する者 流通科学大学商学部 商学部長 教授 持田信治 流通科学大学経済学部 経済情報学科 准教授 関 陽 流通科学大学商学部 マーケティング学科 特任講師 宇佐美美紀子 流通科学大学商学部 経営学科 講師 森口文博 流通科学大学商学部 経営学科 講師 保田 洋 流通科学大学経済学部 経済情報学科 准教授 吉川 満 流通科学大学教務部次長 近藤 敦 流通科学大学教務部係長 横山 靖弘 流通科学大学情報システム室担当 操野祐典
A47: ⑧ | B47: 履修者数・履修率の向上に向けた計画 ※様式１の「履修必須の有無」で「計画がある」としている場合は詳細について記載すること
B48: 令和４年度実績 | C48: ='様式２ 履修者等数の実績'!AQ32 -> 0.17472222 | E48: 令和５年度予定 | F48: 0.32 | H48: 令和６年度予定 | I48: 0.37
B49: 令和７年度予定 | C49: 0.51 | E49: 令和８年度予定 | F49: 0.58 | H49: 収容定員（名） | I49: ='様式２ 履修者等数の実績'!E32 -> 3600
B50: 具体的な計画
B51: 「デジタル社会の基礎知識」科目は全学共通科目全学基礎科目（専門基礎選択必修科目）として、1年次に配当し、合計8コマを同じ内容の科目として開講しており、1年生全員が受講できる体制を整えている。また、2～4年次においても履修可能なクラスを設けており、卒業までに広く履修の機会を提供している。
A64: ⑨ | B64: 学部・学科に関係なく希望する学生全員が受講可能となるような必要な体制・取組等
B65: 「デジタル社会の基礎知識」科目は全学共通科目全学基礎科目（専門基礎選択必修科目）として、所属学部・学科に関係なく履修することができる科目である。また、合計8コマ、同内容の科目として開講し、学生が履修すべき曜日時限を指定することにより、適正人数での受講ができるように工夫を施している。
A77: ⑩ | B77: できる限り多くの学生が履修できるような具体的な周知方法・取組
B78: 毎年、全学生に配布している履修の手引きにおいて、「デジタル社会の基礎知識」のプログラムについて掲載している。また、学年別に実施している教務ガイダンスの中で、本プログラムについて説明し、履修を促している。適宜、授業内においても本プログラムについて紹介、説明することで、学生がプログラムの趣旨、内容を理解し、履修するような周知を行っている。 その他、履修要項、時間割表。履修管理システム等を用いて、履修に必要な情報が確認できるようにしていることに加え、大学のHPでも本プログラムの趣旨や内容を発信している（https://www.umds.ac.jp/facility/data-science/）。
A90: ⑪ | B90: できる限り多くの学生が履修・修得できるようなサポート体制
B91: 専任の指導教員を配置して、学生の履修や修学についての相談を受け付けている。また教務部において、履修登録のサポートを行っている。 学内ポータルサイトや、学修支援システムの使用方法、ネットワーク設定等のサポートを行い、円滑に学修をすすめられる体制を整えている。 学内にメディアセンターおよびコンピューター演習室合わせて約４６０台の常設PCを完備しており、予習・復習・レポート作成が可能となっており、オンデマンド講義の視聴も可能である。 また、図書館において関連分野の学生向け書籍を整備し、プログラミング体験コーナーを設けるなど、学生の興味・関心を高める取り組みを行い、修得をサポートしている。
A104: ⑫ | B104: 授業時間内外で学習指導、質問を受け付ける具体的な仕組み
B105: 授業時間内に質問を受け付けるほか、オフィスアワーを設け、受講生が直接教員の研究室を訪ねて指導が受けられるようにしている。また、いつでも担当教員にメールで相談することが可能である。

Sheet 様式４　自己点検・評価
I1: 様式４
H2: 大学等名 | I2: ='様式１ プログラムを構成する授業科目 '!C2 -> 流通科学大学
A3: 自己点検・評価について
A5: ① | B5: プログラムの自己点検・評価を行う体制（委員会・組織等）
B6: 教育審議会／教務委員会／数理・データサイエンス・AI専門部会
D8: （責任者名） | E8: 藤井啓吾 | G8: （役職名） | H8: 学長、教育審議会議長
A10: ② | B10: 自己点検・評価体制における意見等
B11: 自己点検・評価の視点 | E11: 自己点検・評価体制における意見・結果・改善に向けた取組等
B12: 学内からの視点
C13: プログラムの履修・修得状況 | E13: 本教育プログラム開始初年度である2022年度の「デジタル社会の基礎知識」の履修者は６２９名であり、このうち修了した学生は４８４名であった。履修者の学部別の内訳は、商学部２９９名、経済学部１６３名、人間社会学部１６７名であった。対象としたすべての学部の学生から本教育プログラムの履修があったことがわかり、概ね成果が上げられた。また、学内ポータルサイトおよびマイクロソフト社Office365のTeams、Formsやクリッカーｒｅｓｐｏｎ等を活用し、履修者の課題提出状況は取りまとめられている。さらに、履修者の授業への出席状況は学内の教務システムにて管理され、教員にその状況は共有されている。修得状況に課題のある学生に対しては、教員のオフィスアワーを活用してフォローできる体制を構築している。
C14: 学修成果 | E14: 学修成果の把握に関しては、授業時の課題提出物および学生による授業改善アンケートにより学生の理解度を把握することができ、授業内容や授業方法の改善を図っている。また、本教育プログラムを終了した学生がその後どのような科目を履修して、どのような成績を修めたか、卒業後にどのような進路に進んだかなどを経時的に調査し、幅広い視点で改善していく予定である。
C15: 学生アンケート等を通じた学生の内容の理解度 | E15: 毎年、「授業改善アンケート」を年2回（7月、2月）実施しており、学生の理解度について確認している。具体的には、「あなたは講義概要（シラバス）記載の目標に到達したと思いますか？」という項目に対して「そう思う」「どちらかといえばそう思う」「どちらともいえない」「どちらかといえばそう思わない」「そう思わない」の5段階評価により、学生がそれぞれの科目の到達目標に対してどの程度達成できたと考えているのか確認している。 また、授業時においても、「授業改善アンケート」とは別に、初回授業と最終回授業でアンケートを実施し、5段階評価で確認している。具体的には、本プログラムの受講前後で、データリテラシーに関する意識がどのように変化したかを確認した。質問は合計10問で、1問は変化がなかったが、9問については受講前後で平均点が高まる結果となった。特に、「この授業によって、分析したデータを自分なりにまとめる力が身についたと思う」「この授業によって、まとめたデータを用いて、誰かに説明したり説得する力が身についたと思う 」という分析し、まとめることに対する平均点がそれぞれ0.77ポイント、0.59ポイント受講前後で大きく向上した。また、「この授業によって、なぜ大学が本授業の履修を勧めているのか、友人・知人等に説明することができる」という本プログラム開講の趣旨に関する質問についても、0.68ポイント受講前後で大きく向上する結果となり、学生にも本プログラム開講の趣旨が伝わったことが確認できた。
C16: 学生アンケート等を通じた後輩等他の学生への推奨度 | E16: 授業改善アンケートに「この科目を他の学生に薦めたいと思いますか」という設問を作り、科目ごとに学生の回答状況を分析している。科目担当教員にフィードバックされ、授業内容および指導方法の改善に活かされている。なお、本学では大学全体の授業評価アンケートの集計結果を科目区分ごとに整理して大学ホームページで公表しており、教育の質保証に関して、社会に対する説明責任を遂行するよう努めている。
C17: 全学的な履修者数、履修率向上に向けた計画の達成・進捗状況 | E17: 全学的な履修者数、履修率向上に向けた取り組みとしては、「デジタル社会の基礎知識」科目は全学共通科目全学基礎科目（専門基礎選択必修科目）として、1年次に配当し、合計8コマを同じ内容の科目として開講し、1年次生全員が受講できる体制を整えている。学生が履修すべき曜日時限を指定することにより、適正人数での受講ができるように工夫を施している。 今後、履修証明のデジタルバッジを発行することで、さらなる履修率の向上が期待できる。今後も、教務委員会数理・DS・AI教育専門部会の運営により、専門領域に特化したカリキュラム検討ワーキンググループを定期的に開催し、学生にとって魅力的な教育プログラムを構成するために、日進月歩の技術革新に対応した数理・データサイエンス・AI関連教育の充実を図っていく。
B18: 学外からの視点
C19: 教育プログラム修了者の進路、活躍状況、企業等の評価 | E19: 令和4年度から開講した科目であるため、修了者の進路、活躍状況、企業の評価は調査されていない。今後、就職部や同窓会組織と連携し、卒業生調査を行うことを予定している。また、個別企業へのヒアリング等を行い、意見聴取することも予定している。
C20: 産業界からの視点を含めた教育プログラム内容・手法等への意見 | E20: 本学の外部評議員や情報系の就職先企業等にヒアリングを行い、企業の求める人材像に近づけるようプログラムの改善を継続して行う。
B21: 数理・データサイエンス・ＡＩを「学ぶ楽しさ」「学ぶことの意義」を理解させること | E21: 課題発見・課題解決に必要な情報を見定め、適切な手段を用いて収集・調査、整理することができる情報収集力、収集した個々の情報を多角的に分析し、現状を正確に把握することができる情報分析力。 これらの収集・分析力を基に、現象や事実のなかに隠れている問題点やその要因を発見し、解決すべき課題を設定することができる課題発見力を養う。加えて、さまざまな条件・制約を考慮して、解決策を吟味・選択肢、課題の解決に向けた道筋や段取りを明らかにした上で、具体化することができる構想力を養い、論理的思考力を持つことを目指す。 本教育プログラムを通して、情報が社会にどのような変化をもたらしてきたのかを振り返り、IoTとビッグデータとの関わりと我々の生活への影響、AIがもたらすライフスタイルの変革を身近に捉え、今後の社会のあり方、社会の課題解決につながる活用方法について考える。 また、日常生活の中の疑問を統計の視点から見直すことで、データの基本的な扱い方を知り、新しい観点を養い、それらが日常生活や社会の課題解決の糸口になり得ること、新たな価値を創出できることを知る。 社会の変化とそれにともなうリスクや配慮事項を理解し、自身や周囲の安全を守るために必要な知識を学ぶこととする。
B22: 内容・水準を維持・向上しつつ、より「分かりやすい」授業とすること | E22: 本プログラムを担当する教員4名が分担して、数理・データサイエンス・ＡＩに関する知識・技能（リテラシーレベル）を盛り込んだ15回分のテキストを独自に作成している。4名の教員相互にテキストの内容・水準を検証したうえで、教科書として履修者全員に配布した。テキストは、学生にとって身近で分かりやすい事例やイラストを多く導入し、教員が兵庫県内に拠点を置く画像認識・AI・業務システム企業へ出向いて取材をおこない、資料提供を受けたものを取り入れるなど、学生の関心が高まる内容となるよう工夫した。 また、オンラインで視聴可能な動画教材として、本学商学部マーケティング学科教員による「流通・小売企業におけるAI活用の実例」、経済情報学科教員による「情報推薦システムの仕組み」、商学部経営学科教員による、兵庫県内に拠点を置く情報処理機器開発企業から資料提供を受けた「画像認識システムとその活用例」を作成した。授業時の課題提出物および学生による授業改善アンケート等から、学生の理解度を把握し、テキストおよび動画教材の見直し、講義の内容・実施方法の検討を行うこととしている。 本学では、全学的一斉授業公開制度を設けている。前・後期各セメスター内の約3週間を公開授業の推奨期間とし、教員相互に評価し合い授業改善を図っている。学生に親しみをもたせ、より分かりやすい授業となるよう、学内の連携を取り、企業等の協力を得ていく予定である。引き続き、FD活動を含めて、授業内容の水準の維持、向上に繋げていく。
