Workbook

Sheet 様式１-１　プログラムを構成する授業科目
R1: 様式１-１ | T1: 「学部・学科によって、修了要件は相違する」場合は、本シートを複製の上＜様式１－〇＞と枝番号を付してください
B2: 大学等名 | C2: 淑徳大学
B3: プログラム名 | C3: 数理・データサイエンス・AI教育プログラム
A5: プログラムを構成する授業科目について
A7: ① 対象となる学部・学科名称 | J7: ② 教育プログラムの修了要件 | K7: 学部・学科によって、修了要件は相違する
B9: 総合福祉学部：社会福祉学科・教育福祉学科・実践心理学科、コミュニティ政策学部：コミュニティ政策学科
A12: ③ 修了要件
B13: 以下のパターンから、プログラムを構成する科目の単位を修得すること。 「情報処理法」 + 「情報活用法」 + 「情報社会とデータサイエンス」 | V13: 【プルダウンリスト】
V14: 令和４年度以前より、履修することが必須のプログラムとして実施
V15: 令和７年度までに履修必須とする計画
V16: 令和８年度以降に履修必須とする計画、又は未定
B20: 必要最低単位数 | C20: 5 | E20: 単位 | J20: 履修必須の有無 | K20: 令和８年度以降に履修必須とする計画、又は未定
A22: ④ 現在進行中の社会変化（第４次産業革命、Society 5.0、データ駆動型社会等）に深く寄与しているものであり、それが自らの生活と密接に結びついている」の内容を含む授業科目
B24: 授業科目 | F24: 単位数 | G24: 必須 | H24: 1-1 | I24: 1-6 | J24: 授業科目 | P24: 単位数 | Q24: 必須 | R24: 1-1 | S24: 1-6
B25: 情報社会とデータサイエンス | F25: 1 | G25: ○ | H25: ○ | I25: ○
A33: ⑤ 「社会で活用されているデータ」や「データの活用領域」は非常に広範囲であって、日常生活や社会の課題を解決する有用なツールになり得るもの」の内容を含む授業科目
B35: 授業科目 | F35: 単位数 | G35: 必須 | H35: 1-2 | I35: 1-3 | J35: 授業科目 | P35: 単位数 | Q35: 必須 | R35: 1-2 | S35: 1-3
B36: 情報社会とデータサイエンス | F36: 1 | G36: ○ | H36: ○ | I36: ○
A44: ⑥ 「様々なデータ利活用の現場におけるデータ利活用事例が示され、様々な適用領域（流通、製造、金融、サービス、インフラ、公共、ヘルスケア等）の知見と組み合わせることで価値を創出するもの」の内容を含む授業科目
B46: 授業科目 | F46: 単位数 | G46: 必須 | H46: 1-4 | I46: 1-5 | J46: 授業科目 | P46: 単位数 | Q46: 必須 | R46: 1-4 | S46: 1-5
B47: 情報社会とデータサイエンス | F47: 1 | G47: ○ | H47: ○ | I47: ○
A55: ⑦ 「活用に当たっての様々な留意事項（ELSI、個人情報、データ倫理、ＡＩ社会原則等）を考慮し、情報セキュリティや情報漏洩等、データを守る上での留意事項への理解をする」の内容を含む授業科目
B57: 授業科目 | F57: 単位数 | G57: 必須 | H57: 3-1 | I57: 3-2 | J57: 授業科目 | P57: 単位数 | Q57: 必須 | R57: 3-1 | S57: 3-2
B58: 情報社会とデータサイエンス | F58: 1 | G58: ○ | H58: ○ | I58: ○
A66: ⑧ 「実データ・実課題（学術データ等を含む）を用いた演習など、社会での実例を題材として、「データを読む、説明する、扱う」といった数理・データサイエンス・ＡＩの基本的な活用法に関するもの」の内容を含む授業科目
B68: 授業科目 | E68: 単位数 | F68: 必須 | G68: 2-1 | H68: 2-2 | I68: 2-3 | J68: 授業科目 | O68: 単位数 | P68: 必須 | Q68: 2-1 | R68: 2-2 | S68: 2-3
B69: 情報処理法 | E69: 2 | F69: ○ | G69: ○ | H69: ○ | I69: ○
B70: 情報活用法 | E70: 2 | F70: ○ | G70: ○ | H70: ○ | I70: ○
A77: ⑨ 選択「４．オプション」の内容を含む授業科目
B78: 授業科目 | F78: 選択項目 | J78: 授業科目 | P78: 選択項目
A87: ⑩ プログラムを構成する授業の内容
B88: 授業に含まれている内容・要素 | D88: 講義内容
B89: （１）現在進行中の社会変化（第４次産業革命、Society 5.0、データ駆動型社会等）に深く寄与しているものであり、それが自らの生活と密接に結びついている | C89: 1-1 | D89: ・ビッグデータ、IoT、AI、ロボット「情報社会とデータサイエンス」（１回目、２回目） ・データ量の増加、計算機の処理性能の向上、AIの非連続的進化「情報社会とデータサイエンス」（１回目、2回目） ・第4次産業革命、Society 5.0、データ駆動型社会「情報社会とデータサイエンス」（１回目、２回目） ・複数技術を組み合わせたAIサービス「情報社会とデータサイエンス」（３回目） ・人間の知的活動とAIの関係性「情報社会とデータサイエンス」（１回目、２回目） ・データを起点としたものの見方、人間の知的活動を起点としたものの見方「情報社会とデータサイエンス」（１回目、２回目）
C90: 1-6 | D90: ・AI等を活用した新しいビジネスモデル「情報社会とデータサイエンス」（４回目） ・AI最新技術の活用例「情報社会とデータサイエンス」（５回目）
B91: （２）「社会で活用されているデータ」や「データの活用領域」は非常に広範囲であって、日常生活や社会の課題を解決する有用なツールになり得るもの | C91: 1-2 | D91: ・調査データ、実験データ、人の行動ログデータ、機械の稼働ログデータなど「情報社会とデータサイエンス」（２回目、７回目） ・1次データ、2次データ、データのメタ化「情報社会とデータサイエンス」（２回目、７回目） ・構造化データ、非構造化データ（文章、画像/動画、音声/音楽など）「情報社会とデータサイエンス」（２回目、７回目） ・データ作成（ビッグデータとアノテーション）「情報社会とデータサイエンス」（２回目、７回目） ・データのオープン化（オープンデータ）「情報社会とデータサイエンス」（２回目、７回目）
C92: 1-3 | D92: ・データ・AI活用領域の広がり(生産、消費、文化活動など)「情報社会とデータサイエンス」（３回目、４回目、５回目、６回目） ・研究開発、調達、製造、物流、販売、マーケティング、サービスなど「情報社会とデータサイエンス」（３回目、４回目、５回目、６回目） ・仮説検証、知識発見、原因究明、計画策定、判断支援、活動代替、新規生成など「情報社会とデータサイエンス」（２回目、５回目）
B93: （３）様々なデータ利活用の現場におけるデータ利活用事例が示され、様々な適用領域（流通、製造、金融、サービス、インフラ、公共、ヘルスケア等）の知見と組み合わせることで価値を創出するもの | C93: 1-4 | D93: ・データ解析：予測、グルーピング、パターン発見、最適化、シミュレーション・データ同化など「情報社会とデータサイエンス」（７回目） ・データ可視化：複合グラフ、2軸グラフ、多次元の可視化、関係性の可視化、地図上の可視化、挙動・軌跡の可視化、リアルタイム可視化など「情報社会とデータサイエンス」（７回目） ・非構造化データ処理：言語処理、画像/動画処理、音声/音楽処理など「情報社会とデータサイエンス」（７回目） ・特化型AIと汎用AI、今のAIで出来ることと出来ないこと、AIとビッグデータ「情報社会とデータサイエンス」（７回目） ・認識技術、ルールベース、自動化技術「情報社会とデータサイエンス」（７回目）
C94: 1-5 | D94: ・データサイエンスのサイクル（課題抽出と定式化、データの取得・管理・加工、 探索的データ解析、データ解析と推論、結果の共有・伝達、課題解決に向けた提案）「情報社会とデータサイエンス」（２回目、５回目） ・流通、製造、金融、サービス、インフラ、公共、ヘルスケア等におけるデータ・AI利活用事例紹介「情報社会とデータサイエンス」（６回目）
B95: （４）活用に当たっての様々な留意事項（ELSI、個人情報、データ倫理、ＡＩ社会原則等）を考慮し、情報セキュリティや情報漏洩等、データを守る上での留意事項への理解をする | C95: 3-1 | D95: ・ELSI（Ethical, Legal and Social Issues）「情報社会とデータサイエンス」（８回目） ・個人情報保護、EU一般データ保護規則(GDPR)、忘れられる権利、オプトアウト「情報社会とデータサイエンス」（８回目） ・データ倫理：データのねつ造、改ざん、盗用、プライバシー保護「情報社会とデータサイエンス」（８回目） ・AI社会原則（公平性、説明責任、透明性、人間中心の判断）「情報社会とデータサイエンス」（８回目） ・データバイアス、アルゴリズムバイアス「情報社会とデータサイエンス」（８回目） ・AIサービスの責任論「情報社会とデータサイエンス」（８回目） ・データ・AI活用における負の事例紹介「情報社会とデータサイエンス」（８回目）
C96: 3-2 | D96: ・情報セキュリティ：機密性、完全性、可用性「情報社会とデータサイエンス」（８回目） ・匿名加工情報、暗号化、パスワード、悪意ある情報搾取「情報社会とデータサイエンス」（８回目） ・情報漏洩等によるセキュリティ事故の事例紹介「情報社会とデータサイエンス」（８回目）
...

Sheet 様式１-２　プログラムを構成する授業科目
R1: 様式１-２ | T1: 「学部・学科によって、修了要件は相違する」場合は、本シートを複製の上＜様式１－〇＞と枝番号を付してください
B2: 大学等名 | C2: 淑徳大学
B3: プログラム名 | C3: 数理・データサイエンス・AI教育プログラム
A5: プログラムを構成する授業科目について
A7: ① 対象となる学部・学科名称 | J7: ② 教育プログラムの修了要件 | K7: 学部・学科によって、修了要件は相違する
B9: 看護栄養学部：看護学科・栄養学科
A12: ③ 修了要件
B13: 以下のパターンから、プログラムを構成する科目の単位を修得すること。 「情報処理法」 + 「情報活用法」 + 「情報社会とデータサイエンス」 | V13: 【プルダウンリスト】
V14: 令和４年度以前より、履修することが必須のプログラムとして実施
V15: 令和７年度までに履修必須とする計画
V16: 令和８年度以降に履修必須とする計画、又は未定
B20: 必要最低単位数 | C20: 3 | E20: 単位 | J20: 履修必須の有無 | K20: 令和８年度以降に履修必須とする計画、又は未定
A22: ④ 現在進行中の社会変化（第４次産業革命、Society 5.0、データ駆動型社会等）に深く寄与しているものであり、それが自らの生活と密接に結びついている」の内容を含む授業科目
B24: 授業科目 | F24: 単位数 | G24: 必須 | H24: 1-1 | I24: 1-6 | J24: 授業科目 | P24: 単位数 | Q24: 必須 | R24: 1-1 | S24: 1-6
B25: 情報社会とデータサイエンス | F25: 1 | G25: ○ | H25: ○ | I25: ○
A33: ⑤ 「社会で活用されているデータ」や「データの活用領域」は非常に広範囲であって、日常生活や社会の課題を解決する有用なツールになり得るもの」の内容を含む授業科目
B35: 授業科目 | F35: 単位数 | G35: 必須 | H35: 1-2 | I35: 1-3 | J35: 授業科目 | P35: 単位数 | Q35: 必須 | R35: 1-2 | S35: 1-3
B36: 情報社会とデータサイエンス | F36: 1 | G36: ○ | H36: ○ | I36: ○
A44: ⑥ 「様々なデータ利活用の現場におけるデータ利活用事例が示され、様々な適用領域（流通、製造、金融、サービス、インフラ、公共、ヘルスケア等）の知見と組み合わせることで価値を創出するもの」の内容を含む授業科目
B46: 授業科目 | F46: 単位数 | G46: 必須 | H46: 1-4 | I46: 1-5 | J46: 授業科目 | P46: 単位数 | Q46: 必須 | R46: 1-4 | S46: 1-5
B47: 情報社会とデータサイエンス | F47: 1 | G47: ○ | H47: ○ | I47: ○
A55: ⑦ 「活用に当たっての様々な留意事項（ELSI、個人情報、データ倫理、ＡＩ社会原則等）を考慮し、情報セキュリティや情報漏洩等、データを守る上での留意事項への理解をする」の内容を含む授業科目
B57: 授業科目 | F57: 単位数 | G57: 必須 | H57: 3-1 | I57: 3-2 | J57: 授業科目 | P57: 単位数 | Q57: 必須 | R57: 3-1 | S57: 3-2
B58: 情報社会とデータサイエンス | F58: 1 | G58: ○ | H58: ○ | I58: ○
A66: ⑧ 「実データ・実課題（学術データ等を含む）を用いた演習など、社会での実例を題材として、「データを読む、説明する、扱う」といった数理・データサイエンス・ＡＩの基本的な活用法に関するもの」の内容を含む授業科目
B68: 授業科目 | E68: 単位数 | F68: 必須 | G68: 2-1 | H68: 2-2 | I68: 2-3 | J68: 授業科目 | O68: 単位数 | P68: 必須 | Q68: 2-1 | R68: 2-2 | S68: 2-3
B69: 情報処理法 | E69: 1 | F69: ○ | G69: ○ | H69: ○ | I69: ○
B70: 情報活用法 | E70: 1 | F70: ○ | G70: ○ | H70: ○ | I70: ○
A77: ⑨ 選択「４．オプション」の内容を含む授業科目
B78: 授業科目 | F78: 選択項目 | J78: 授業科目 | P78: 選択項目
A87: ⑩ プログラムを構成する授業の内容
B88: 授業に含まれている内容・要素 | D88: 講義内容
B89: （１）現在進行中の社会変化（第４次産業革命、Society 5.0、データ駆動型社会等）に深く寄与しているものであり、それが自らの生活と密接に結びついている | C89: 1-1 | D89: ・ビッグデータ、IoT、AI、ロボット「情報社会とデータサイエンス」（１回目、２回目） ・データ量の増加、計算機の処理性能の向上、AIの非連続的進化「情報社会とデータサイエンス」（１回目、2回目） ・第4次産業革命、Society 5.0、データ駆動型社会「情報社会とデータサイエンス」（１回目、２回目） ・複数技術を組み合わせたAIサービス「情報社会とデータサイエンス」（３回目） ・人間の知的活動とAIの関係性「情報社会とデータサイエンス」（１回目、２回目） ・データを起点としたものの見方、人間の知的活動を起点としたものの見方「情報社会とデータサイエンス」（１回目、２回目）
C90: 1-6 | D90: ・AI等を活用した新しいビジネスモデル「情報社会とデータサイエンス」（４回目） ・AI最新技術の活用例「情報社会とデータサイエンス」（５回目）
B91: （２）「社会で活用されているデータ」や「データの活用領域」は非常に広範囲であって、日常生活や社会の課題を解決する有用なツールになり得るもの | C91: 1-2 | D91: ・調査データ、実験データ、人の行動ログデータ、機械の稼働ログデータなど「情報社会とデータサイエンス」（２回目、７回目） ・1次データ、2次データ、データのメタ化「情報社会とデータサイエンス」（２回目、７回目） ・構造化データ、非構造化データ（文章、画像/動画、音声/音楽など）「情報社会とデータサイエンス」（２回目、７回目） ・データ作成（ビッグデータとアノテーション）「情報社会とデータサイエンス」（２回目、７回目） ・データのオープン化（オープンデータ）「情報社会とデータサイエンス」（２回目、７回目）
C92: 1-3 | D92: ・データ・AI活用領域の広がり(生産、消費、文化活動など)「情報社会とデータサイエンス」（３回目、４回目、５回目、６回目） ・研究開発、調達、製造、物流、販売、マーケティング、サービスなど「情報社会とデータサイエンス」（３回目、４回目、５回目、６回目） ・仮説検証、知識発見、原因究明、計画策定、判断支援、活動代替、新規生成など「情報社会とデータサイエンス」（２回目、５回目）
B93: （３）様々なデータ利活用の現場におけるデータ利活用事例が示され、様々な適用領域（流通、製造、金融、サービス、インフラ、公共、ヘルスケア等）の知見と組み合わせることで価値を創出するもの | C93: 1-4 | D93: ・データ解析：予測、グルーピング、パターン発見、最適化、シミュレーション・データ同化など「情報社会とデータサイエンス」（７回目） ・データ可視化：複合グラフ、2軸グラフ、多次元の可視化、関係性の可視化、地図上の可視化、挙動・軌跡の可視化、リアルタイム可視化など「情報社会とデータサイエンス」（７回目） ・非構造化データ処理：言語処理、画像/動画処理、音声/音楽処理など「情報社会とデータサイエンス」（７回目） ・特化型AIと汎用AI、今のAIで出来ることと出来ないこと、AIとビッグデータ「情報社会とデータサイエンス」（７回目） ・認識技術、ルールベース、自動化技術「情報社会とデータサイエンス」（７回目）
C94: 1-5 | D94: ・データサイエンスのサイクル（課題抽出と定式化、データの取得・管理・加工、 探索的データ解析、データ解析と推論、結果の共有・伝達、課題解決に向けた提案）「情報社会とデータサイエンス」（２回目、５回目） ・流通、製造、金融、サービス、インフラ、公共、ヘルスケア等におけるデータ・AI利活用事例紹介「情報社会とデータサイエンス」（６回目）
B95: （４）活用に当たっての様々な留意事項（ELSI、個人情報、データ倫理、ＡＩ社会原則等）を考慮し、情報セキュリティや情報漏洩等、データを守る上での留意事項への理解をする | C95: 3-1 | D95: ・ELSI（Ethical, Legal and Social Issues）「情報社会とデータサイエンス」（８回目） ・個人情報保護、EU一般データ保護規則(GDPR)、忘れられる権利、オプトアウト「情報社会とデータサイエンス」（８回目） ・データ倫理：データのねつ造、改ざん、盗用、プライバシー保護「情報社会とデータサイエンス」（８回目） ・AI社会原則（公平性、説明責任、透明性、人間中心の判断）「情報社会とデータサイエンス」（８回目） ・データバイアス、アルゴリズムバイアス「情報社会とデータサイエンス」（８回目） ・AIサービスの責任論「情報社会とデータサイエンス」（８回目） ・データ・AI活用における負の事例紹介「情報社会とデータサイエンス」（８回目）
C96: 3-2 | D96: ・情報セキュリティ：機密性、完全性、可用性「情報社会とデータサイエンス」（８回目） ・匿名加工情報、暗号化、パスワード、悪意ある情報搾取「情報社会とデータサイエンス」（８回目） ・情報漏洩等によるセキュリティ事故の事例紹介「情報社会とデータサイエンス」（８回目）
...

Sheet 様式１-３　プログラムを構成する授業科目 
R1: 様式１-３ | T1: 「学部・学科によって、修了要件は相違する」場合は、本シートを複製の上＜様式１－〇＞と枝番号を付してください
B2: 大学等名 | C2: 淑徳大学
B3: プログラム名 | C3: 数理・データサイエンス・AI教育プログラム
A5: プログラムを構成する授業科目について
A7: ① 対象となる学部・学科名称 | J7: ② 教育プログラムの修了要件 | K7: 学部・学科によって、修了要件は相違する
B9: 経営学部：経営学科・観光経営学科、教育学部：こども教育学科
A12: ③ 修了要件
B13: 以下のパターンから、プログラムを構成する科目の単位を修得すること。 「情報基礎演習」 + 「情報応用演習」 + 「情報社会とデータサイエンス」 | V13: 【プルダウンリスト】
V14: 令和４年度以前より、履修することが必須のプログラムとして実施
V15: 令和７年度までに履修必須とする計画
V16: 令和８年度以降に履修必須とする計画、又は未定
B20: 必要最低単位数 | C20: 5 | E20: 単位 | J20: 履修必須の有無 | K20: 令和８年度以降に履修必須とする計画、又は未定
A22: ④ 現在進行中の社会変化（第４次産業革命、Society 5.0、データ駆動型社会等）に深く寄与しているものであり、それが自らの生活と密接に結びついている」の内容を含む授業科目
B24: 授業科目 | F24: 単位数 | G24: 必須 | H24: 1-1 | I24: 1-6 | J24: 授業科目 | P24: 単位数 | Q24: 必須 | R24: 1-1 | S24: 1-6
B25: 情報社会とデータサイエンス | F25: 1 | G25: ○ | H25: ○ | I25: ○
A33: ⑤ 「社会で活用されているデータ」や「データの活用領域」は非常に広範囲であって、日常生活や社会の課題を解決する有用なツールになり得るもの」の内容を含む授業科目
B35: 授業科目 | F35: 単位数 | G35: 必須 | H35: 1-2 | I35: 1-3 | J35: 授業科目 | P35: 単位数 | Q35: 必須 | R35: 1-2 | S35: 1-3
B36: 情報社会とデータサイエンス | F36: 1 | G36: ○ | H36: ○ | I36: ○
A44: ⑥ 「様々なデータ利活用の現場におけるデータ利活用事例が示され、様々な適用領域（流通、製造、金融、サービス、インフラ、公共、ヘルスケア等）の知見と組み合わせることで価値を創出するもの」の内容を含む授業科目
B46: 授業科目 | F46: 単位数 | G46: 必須 | H46: 1-4 | I46: 1-5 | J46: 授業科目 | P46: 単位数 | Q46: 必須 | R46: 1-4 | S46: 1-5
B47: 情報社会とデータサイエンス | F47: 1 | G47: ○ | H47: ○ | I47: ○
A55: ⑦ 「活用に当たっての様々な留意事項（ELSI、個人情報、データ倫理、ＡＩ社会原則等）を考慮し、情報セキュリティや情報漏洩等、データを守る上での留意事項への理解をする」の内容を含む授業科目
B57: 授業科目 | F57: 単位数 | G57: 必須 | H57: 3-1 | I57: 3-2 | J57: 授業科目 | P57: 単位数 | Q57: 必須 | R57: 3-1 | S57: 3-2
B58: 情報社会とデータサイエンス | F58: 1 | G58: ○ | H58: ○ | I58: ○
A66: ⑧ 「実データ・実課題（学術データ等を含む）を用いた演習など、社会での実例を題材として、「データを読む、説明する、扱う」といった数理・データサイエンス・ＡＩの基本的な活用法に関するもの」の内容を含む授業科目
B68: 授業科目 | E68: 単位数 | F68: 必須 | G68: 2-1 | H68: 2-2 | I68: 2-3 | J68: 授業科目 | O68: 単位数 | P68: 必須 | Q68: 2-1 | R68: 2-2 | S68: 2-3
B69: 情報基礎演習 | E69: 2 | F69: ○ | G69: ○ | H69: ○ | I69: ○
B70: 情報応用演習 | E70: 2 | F70: ○ | G70: ○ | H70: ○ | I70: ○
A77: ⑨ 選択「４．オプション」の内容を含む授業科目
B78: 授業科目 | F78: 選択項目 | J78: 授業科目 | P78: 選択項目
A87: ⑩ プログラムを構成する授業の内容
B88: 授業に含まれている内容・要素 | D88: 講義内容
B89: （１）現在進行中の社会変化（第４次産業革命、Society 5.0、データ駆動型社会等）に深く寄与しているものであり、それが自らの生活と密接に結びついている | C89: 1-1 | D89: ・ビッグデータ、IoT、AI、ロボット「情報社会とデータサイエンス」（１回目、２回目） ・データ量の増加、計算機の処理性能の向上、AIの非連続的進化「情報社会とデータサイエンス」（１回目、2回目） ・第4次産業革命、Society 5.0、データ駆動型社会「情報社会とデータサイエンス」（１回目、２回目） ・複数技術を組み合わせたAIサービス「情報社会とデータサイエンス」（３回目） ・人間の知的活動とAIの関係性「情報社会とデータサイエンス」（１回目、２回目） ・データを起点としたものの見方、人間の知的活動を起点としたものの見方「情報社会とデータサイエンス」（１回目、２回目）
C90: 1-6 | D90: ・AI等を活用した新しいビジネスモデル「情報社会とデータサイエンス」（４回目） ・AI最新技術の活用例「情報社会とデータサイエンス」（５回目）
B91: （２）「社会で活用されているデータ」や「データの活用領域」は非常に広範囲であって、日常生活や社会の課題を解決する有用なツールになり得るもの | C91: 1-2 | D91: ・調査データ、実験データ、人の行動ログデータ、機械の稼働ログデータなど「情報社会とデータサイエンス」（２回目、７回目） ・1次データ、2次データ、データのメタ化「情報社会とデータサイエンス」（２回目、７回目） ・構造化データ、非構造化データ（文章、画像/動画、音声/音楽など）「情報社会とデータサイエンス」（２回目、７回目） ・データ作成（ビッグデータとアノテーション）「情報社会とデータサイエンス」（２回目、７回目） ・データのオープン化（オープンデータ）「情報社会とデータサイエンス」（２回目、７回目）
C92: 1-3 | D92: ・データ・AI活用領域の広がり(生産、消費、文化活動など)「情報社会とデータサイエンス」（３回目、４回目、５回目、６回目） ・研究開発、調達、製造、物流、販売、マーケティング、サービスなど「情報社会とデータサイエンス」（３回目、４回目、５回目、６回目） ・仮説検証、知識発見、原因究明、計画策定、判断支援、活動代替、新規生成など「情報社会とデータサイエンス」（２回目、５回目）
B93: （３）様々なデータ利活用の現場におけるデータ利活用事例が示され、様々な適用領域（流通、製造、金融、サービス、インフラ、公共、ヘルスケア等）の知見と組み合わせることで価値を創出するもの | C93: 1-4 | D93: ・データ解析：予測、グルーピング、パターン発見、最適化、シミュレーション・データ同化など「情報社会とデータサイエンス」（７回目） ・データ可視化：複合グラフ、2軸グラフ、多次元の可視化、関係性の可視化、地図上の可視化、挙動・軌跡の可視化、リアルタイム可視化など「情報社会とデータサイエンス」（７回目） ・非構造化データ処理：言語処理、画像/動画処理、音声/音楽処理など「情報社会とデータサイエンス」（７回目） ・特化型AIと汎用AI、今のAIで出来ることと出来ないこと、AIとビッグデータ「情報社会とデータサイエンス」（７回目） ・認識技術、ルールベース、自動化技術「情報社会とデータサイエンス」（７回目）
C94: 1-5 | D94: ・データサイエンスのサイクル（課題抽出と定式化、データの取得・管理・加工、 探索的データ解析、データ解析と推論、結果の共有・伝達、課題解決に向けた提案）「情報社会とデータサイエンス」（２回目、５回目） ・流通、製造、金融、サービス、インフラ、公共、ヘルスケア等におけるデータ・AI利活用事例紹介「情報社会とデータサイエンス」（６回目）
B95: （４）活用に当たっての様々な留意事項（ELSI、個人情報、データ倫理、ＡＩ社会原則等）を考慮し、情報セキュリティや情報漏洩等、データを守る上での留意事項への理解をする | C95: 3-1 | D95: ・ELSI（Ethical, Legal and Social Issues）「情報社会とデータサイエンス」（８回目） ・個人情報保護、EU一般データ保護規則(GDPR)、忘れられる権利、オプトアウト「情報社会とデータサイエンス」（８回目） ・データ倫理：データのねつ造、改ざん、盗用、プライバシー保護「情報社会とデータサイエンス」（８回目） ・AI社会原則（公平性、説明責任、透明性、人間中心の判断）「情報社会とデータサイエンス」（８回目） ・データバイアス、アルゴリズムバイアス「情報社会とデータサイエンス」（８回目） ・AIサービスの責任論「情報社会とデータサイエンス」（８回目） ・データ・AI活用における負の事例紹介「情報社会とデータサイエンス」（８回目）
C96: 3-2 | D96: ・情報セキュリティ：機密性、完全性、可用性「情報社会とデータサイエンス」（８回目） ・匿名加工情報、暗号化、パスワード、悪意ある情報搾取「情報社会とデータサイエンス」（８回目） ・情報漏洩等によるセキュリティ事故の事例紹介「情報社会とデータサイエンス」（８回目）
...

Sheet 様式１-４　プログラムを構成する授業科目
R1: 様式１-４ | T1: 「学部・学科によって、修了要件は相違する」場合は、本シートを複製の上＜様式１－〇＞と枝番号を付してください
B2: 大学等名 | C2: 淑徳大学
B3: プログラム名 | C3: 数理・データサイエンス・AI教育プログラム
A5: プログラムを構成する授業科目について
A7: ① 対象となる学部・学科名称 | J7: ② 教育プログラムの修了要件 | K7: 学部・学科によって、修了要件は相違する
B9: 人文学部：歴史学科・表現学科
A12: ③ 修了要件
B13: 以下のパターンから、プログラムを構成する科目の単位を修得すること。 「情報処理法」 + 「情報管理法」 + 「情報社会とデータサイエンス」 | V13: 【プルダウンリスト】
V14: 令和４年度以前より、履修することが必須のプログラムとして実施
V15: 令和７年度までに履修必須とする計画
V16: 令和８年度以降に履修必須とする計画、又は未定
B20: 必要最低単位数 | C20: 3 | E20: 単位 | J20: 履修必須の有無 | K20: 令和８年度以降に履修必須とする計画、又は未定
A22: ④ 現在進行中の社会変化（第４次産業革命、Society 5.0、データ駆動型社会等）に深く寄与しているものであり、それが自らの生活と密接に結びついている」の内容を含む授業科目
B24: 授業科目 | F24: 単位数 | G24: 必須 | H24: 1-1 | I24: 1-6 | J24: 授業科目 | P24: 単位数 | Q24: 必須 | R24: 1-1 | S24: 1-6
B25: 情報社会とデータサイエンス | F25: 1 | G25: ○ | H25: ○ | I25: ○
A33: ⑤ 「社会で活用されているデータ」や「データの活用領域」は非常に広範囲であって、日常生活や社会の課題を解決する有用なツールになり得るもの」の内容を含む授業科目
B35: 授業科目 | F35: 単位数 | G35: 必須 | H35: 1-2 | I35: 1-3 | J35: 授業科目 | P35: 単位数 | Q35: 必須 | R35: 1-2 | S35: 1-3
B36: 情報社会とデータサイエンス | F36: 1 | G36: ○ | H36: ○ | I36: ○
A44: ⑥ 「様々なデータ利活用の現場におけるデータ利活用事例が示され、様々な適用領域（流通、製造、金融、サービス、インフラ、公共、ヘルスケア等）の知見と組み合わせることで価値を創出するもの」の内容を含む授業科目
B46: 授業科目 | F46: 単位数 | G46: 必須 | H46: 1-4 | I46: 1-5 | J46: 授業科目 | P46: 単位数 | Q46: 必須 | R46: 1-4 | S46: 1-5
B47: 情報社会とデータサイエンス | F47: 1 | G47: ○ | H47: ○ | I47: ○
A55: ⑦ 「活用に当たっての様々な留意事項（ELSI、個人情報、データ倫理、ＡＩ社会原則等）を考慮し、情報セキュリティや情報漏洩等、データを守る上での留意事項への理解をする」の内容を含む授業科目
B57: 授業科目 | F57: 単位数 | G57: 必須 | H57: 3-1 | I57: 3-2 | J57: 授業科目 | P57: 単位数 | Q57: 必須 | R57: 3-1 | S57: 3-2
B58: 情報社会とデータサイエンス | F58: 1 | G58: ○ | H58: ○ | I58: ○
A66: ⑧ 「実データ・実課題（学術データ等を含む）を用いた演習など、社会での実例を題材として、「データを読む、説明する、扱う」といった数理・データサイエンス・ＡＩの基本的な活用法に関するもの」の内容を含む授業科目
B68: 授業科目 | E68: 単位数 | F68: 必須 | G68: 2-1 | H68: 2-2 | I68: 2-3 | J68: 授業科目 | O68: 単位数 | P68: 必須 | Q68: 2-1 | R68: 2-2 | S68: 2-3
B69: 情報処理法 | E69: 1 | F69: ○ | G69: ○ | H69: ○ | I69: ○
B70: 情報管理法 | E70: 1 | F70: ○ | G70: ○ | H70: ○ | I70: ○
A77: ⑨ 選択「４．オプション」の内容を含む授業科目
B78: 授業科目 | F78: 選択項目 | J78: 授業科目 | P78: 選択項目
A87: ⑩ プログラムを構成する授業の内容
B88: 授業に含まれている内容・要素 | D88: 講義内容
B89: （１）現在進行中の社会変化（第４次産業革命、Society 5.0、データ駆動型社会等）に深く寄与しているものであり、それが自らの生活と密接に結びついている | C89: 1-1 | D89: ・ビッグデータ、IoT、AI、ロボット「情報社会とデータサイエンス」（１回目、２回目） ・データ量の増加、計算機の処理性能の向上、AIの非連続的進化「情報社会とデータサイエンス」（１回目、2回目） ・第4次産業革命、Society 5.0、データ駆動型社会「情報社会とデータサイエンス」（１回目、２回目） ・複数技術を組み合わせたAIサービス「情報社会とデータサイエンス」（３回目） ・人間の知的活動とAIの関係性「情報社会とデータサイエンス」（１回目、２回目） ・データを起点としたものの見方、人間の知的活動を起点としたものの見方「情報社会とデータサイエンス」（１回目、２回目）
C90: 1-6 | D90: ・AI等を活用した新しいビジネスモデル「情報社会とデータサイエンス」（４回目） ・AI最新技術の活用例「情報社会とデータサイエンス」（５回目）
B91: （２）「社会で活用されているデータ」や「データの活用領域」は非常に広範囲であって、日常生活や社会の課題を解決する有用なツールになり得るもの | C91: 1-2 | D91: ・調査データ、実験データ、人の行動ログデータ、機械の稼働ログデータなど「情報社会とデータサイエンス」（２回目、７回目） ・1次データ、2次データ、データのメタ化「情報社会とデータサイエンス」（２回目、７回目） ・構造化データ、非構造化データ（文章、画像/動画、音声/音楽など）「情報社会とデータサイエンス」（２回目、７回目） ・データ作成（ビッグデータとアノテーション）「情報社会とデータサイエンス」（２回目、７回目） ・データのオープン化（オープンデータ）「情報社会とデータサイエンス」（２回目、７回目）
C92: 1-3 | D92: ・データ・AI活用領域の広がり(生産、消費、文化活動など)「情報社会とデータサイエンス」（３回目、４回目、５回目、６回目） ・研究開発、調達、製造、物流、販売、マーケティング、サービスなど「情報社会とデータサイエンス」（３回目、４回目、５回目、６回目） ・仮説検証、知識発見、原因究明、計画策定、判断支援、活動代替、新規生成など「情報社会とデータサイエンス」（２回目、５回目）
B93: （３）様々なデータ利活用の現場におけるデータ利活用事例が示され、様々な適用領域（流通、製造、金融、サービス、インフラ、公共、ヘルスケア等）の知見と組み合わせることで価値を創出するもの | C93: 1-4 | D93: ・データ解析：予測、グルーピング、パターン発見、最適化、シミュレーション・データ同化など「情報社会とデータサイエンス」（７回目） ・データ可視化：複合グラフ、2軸グラフ、多次元の可視化、関係性の可視化、地図上の可視化、挙動・軌跡の可視化、リアルタイム可視化など「情報社会とデータサイエンス」（７回目） ・非構造化データ処理：言語処理、画像/動画処理、音声/音楽処理など「情報社会とデータサイエンス」（７回目） ・特化型AIと汎用AI、今のAIで出来ることと出来ないこと、AIとビッグデータ「情報社会とデータサイエンス」（７回目） ・認識技術、ルールベース、自動化技術「情報社会とデータサイエンス」（７回目）
C94: 1-5 | D94: ・データサイエンスのサイクル（課題抽出と定式化、データの取得・管理・加工、 探索的データ解析、データ解析と推論、結果の共有・伝達、課題解決に向けた提案）「情報社会とデータサイエンス」（２回目、５回目） ・流通、製造、金融、サービス、インフラ、公共、ヘルスケア等におけるデータ・AI利活用事例紹介「情報社会とデータサイエンス」（６回目）
B95: （４）活用に当たっての様々な留意事項（ELSI、個人情報、データ倫理、ＡＩ社会原則等）を考慮し、情報セキュリティや情報漏洩等、データを守る上での留意事項への理解をする | C95: 3-1 | D95: ・ELSI（Ethical, Legal and Social Issues）「情報社会とデータサイエンス」（８回目） ・個人情報保護、EU一般データ保護規則(GDPR)、忘れられる権利、オプトアウト「情報社会とデータサイエンス」（８回目） ・データ倫理：データのねつ造、改ざん、盗用、プライバシー保護「情報社会とデータサイエンス」（８回目） ・AI社会原則（公平性、説明責任、透明性、人間中心の判断）「情報社会とデータサイエンス」（８回目） ・データバイアス、アルゴリズムバイアス「情報社会とデータサイエンス」（８回目） ・AIサービスの責任論「情報社会とデータサイエンス」（８回目） ・データ・AI活用における負の事例紹介「情報社会とデータサイエンス」（８回目）
C96: 3-2 | D96: ・情報セキュリティ：機密性、完全性、可用性「情報社会とデータサイエンス」（８回目） ・匿名加工情報、暗号化、パスワード、悪意ある情報搾取「情報社会とデータサイエンス」（８回目） ・情報漏洩等によるセキュリティ事故の事例紹介「情報社会とデータサイエンス」（８回目）
...

Sheet 様式２ 履修者等数の実績
AQ1: 様式２
AL2: 大学等名 | AM2: ='様式１-４ プログラムを構成する授業科目'!C2 -> 淑徳大学
A3: プログラムの履修者数等の実績について
A5: ①プログラム開設年度 | C5: 令和4 | E5: 年度
A7: ②履修者・修了者の実績
B9: 学部・学科名称 | C9: 学生数 | D9: 入学 定員 | E9: 収容 定員 | F9: 令和4年度 | L9: 令和3年度 | R9: 令和2年度 | X9: 令和元年度 | AD9: 平成30年度 | AJ9: 平成29年度 | AP9: 履修者数 合計 | AQ9: 履修率
F10: 履修者数 | I10: 修了者数 | L10: 履修者数 | O10: 修了者数 | R10: 履修者数 | U10: 修了者数 | X10: 履修者数 | AA10: 修了者数 | AD10: 履修者数 | AG10: 修了者数 | AJ10: 履修者数 | AM10: 修了者数
F11: 合計 | G11: 男性 | H11: 女性 | I11: 合計 | J11: 男性 | K11: 女性 | L11: 合計 | M11: 男性 | N11: 女性 | O11: 合計 | P11: 男性 | Q11: 女性 | R11: 合計 | S11: 男性 | T11: 女性 | U11: 合計 | V11: 男性 | W11: 女性 | X11: 合計 | Y11: 男性 | Z11: 女性 | AA11: 合計 | AB11: 男性 | AC11: 女性 | AD11: 合計 | AE11: 男性 | AF11: 女性 | AG11: 合計 | AH11: 男性 | AI11: 女性 | AJ11: 合計 | AK11: 男性 | AL11: 女性 | AM11: 合計 | AN11: 男性 | AO11: 女性
B12: 総合福祉学部 | C12: 1791 | D12: 450 | E12: 1800 | F12: 182 | G12: 66 | H12: 116 | I12: 160 | J12: 53 | K12: 107 | L12: =M12+N12 -> 0 | O12: =P12+Q12 -> 0 | R12: =S12+T12 -> 0 | U12: =V12+W12 -> 0 | X12: =Y12+Z12 -> 0 | AA12: =AB12+AC12 -> 0 | AD12: =AE12+AF12 -> 0 | AG12: =AH12+AI12 -> 0 | AJ12: =AK12+AL12 -> 0 | AM12: =AN12+AO12 -> 0 | AP12: =F12+L12+R12+X12+AD12+AJ12 -> 182 | AQ12: =AP12/E12 -> 0.10111111
B13: コミュニティ政策学部 | C13: 405 | D13: 95 | E13: 380 | F13: =G13+H13 -> 0 | G13: 0 | H13: 0 | I13: =J13+K13 -> 0 | J13: 0 | K13: 0 | L13: =M13+N13 -> 0 | O13: =P13+Q13 -> 0 | R13: =S13+T13 -> 0 | U13: =V13+W13 -> 0 | X13: =Y13+Z13 -> 0 | AA13: =AB13+AC13 -> 0 | AD13: =AE13+AF13 -> 0 | AG13: =AH13+AI13 -> 0 | AJ13: =AK13+AL13 -> 0 | AM13: =AN13+AO13 -> 0 | AP13: =F13+L13+R13+X13+AD13+AJ13 -> 0 | AQ13: =AP13/E13 -> 0
B14: 看護栄養学部 | C14: 721 | D14: 180 | E14: 720 | F14: =G14+H14 -> 0 | G14: 0 | H14: 0 | I14: =J14+K14 -> 0 | J14: 0 | K14: 0 | L14: =M14+N14 -> 0 | O14: =P14+Q14 -> 0 | R14: =S14+T14 -> 0 | U14: =V14+W14 -> 0 | X14: =Y14+Z14 -> 0 | AA14: =AB14+AC14 -> 0 | AD14: =AE14+AF14 -> 0 | AG14: =AH14+AI14 -> 0 | AJ14: =AK14+AL14 -> 0 | AM14: =AN14+AO14 -> 0 | AP14: =F14+L14+R14+X14+AD14+AJ14 -> 0 | AQ14: =AP14/E14 -> 0
B15: 経営学部 | C15: 758 | D15: 200 | E15: 800 | F15: 16 | G15: 8 | H15: 8 | I15: 16 | J15: 8 | K15: 8 | L15: =M15+N15 -> 0 | O15: =P15+Q15 -> 0 | R15: =S15+T15 -> 0 | U15: =V15+W15 -> 0 | X15: =Y15+Z15 -> 0 | AA15: =AB15+AC15 -> 0 | AD15: =AE15+AF15 -> 0 | AG15: =AH15+AI15 -> 0 | AJ15: =AK15+AL15 -> 0 | AM15: =AN15+AO15 -> 0 | AP15: =F15+L15+R15+X15+AD15+AJ15 -> 16 | AQ15: =AP15/E15 -> 0.02
B16: 教育学部 | C16: 508 | D16: 150 | E16: 500 | F16: 4 | G16: 3 | H16: 1 | I16: 4 | J16: 3 | K16: 1 | L16: =M16+N16 -> 0 | O16: =P16+Q16 -> 0 | R16: =S16+T16 -> 0 | U16: =V16+W16 -> 0 | X16: =Y16+Z16 -> 0 | AA16: =AB16+AC16 -> 0 | AD16: =AE16+AF16 -> 0 | AG16: =AH16+AI16 -> 0 | AJ16: =AK16+AL16 -> 0 | AM16: =AN16+AO16 -> 0 | AP16: =F16+L16+R16+X16+AD16+AJ16 -> 4 | AQ16: =AP16/E16 -> 0.008
B17: 人文学部 | C17: 603 | D17: 145 | E17: 580 | F17: 30 | G17: 21 | H17: 9 | I17: 28 | J17: 20 | K17: 8 | L17: =M17+N17 -> 0 | O17: =P17+Q17 -> 0 | R17: =S17+T17 -> 0 | U17: =V17+W17 -> 0 | X17: =Y17+Z17 -> 0 | AA17: =AB17+AC17 -> 0 | AD17: =AE17+AF17 -> 0 | AG17: =AH17+AI17 -> 0 | AJ17: =AK17+AL17 -> 0 | AM17: =AN17+AO17 -> 0 | AP17: =F17+L17+R17+X17+AD17+AJ17 -> 30 | AQ17: =AP17/E17 -> 0.051724138
F18: =G18+H18 -> 0 | I18: =J18+K18 -> 0 | L18: =M18+N18 -> 0 | O18: =P18+Q18 -> 0 | R18: =S18+T18 -> 0 | U18: =V18+W18 -> 0 | X18: =Y18+Z18 -> 0 | AA18: =AB18+AC18 -> 0 | AD18: =AE18+AF18 -> 0 | AG18: =AH18+AI18 -> 0 | AJ18: =AK18+AL18 -> 0 | AM18: =AN18+AO18 -> 0 | AP18: =F18+L18+R18+X18+AD18+AJ18 -> 0 | AQ18: =AP18/E18 -> #DIV/0!
F19: =G19+H19 -> 0 | I19: =J19+K19 -> 0 | L19: =M19+N19 -> 0 | O19: =P19+Q19 -> 0 | R19: =S19+T19 -> 0 | U19: =V19+W19 -> 0 | X19: =Y19+Z19 -> 0 | AA19: =AB19+AC19 -> 0 | AD19: =AE19+AF19 -> 0 | AG19: =AH19+AI19 -> 0 | AJ19: =AK19+AL19 -> 0 | AM19: =AN19+AO19 -> 0 | AP19: =F19+L19+R19+X19+AD19+AJ19 -> 0 | AQ19: =AP19/E19 -> #DIV/0!
F20: =G20+H20 -> 0 | I20: =J20+K20 -> 0 | L20: =M20+N20 -> 0 | O20: =P20+Q20 -> 0 | R20: =S20+T20 -> 0 | U20: =V20+W20 -> 0 | X20: =Y20+Z20 -> 0 | AA20: =AB20+AC20 -> 0 | AD20: =AE20+AF20 -> 0 | AG20: =AH20+AI20 -> 0 | AJ20: =AK20+AL20 -> 0 | AM20: =AN20+AO20 -> 0 | AP20: =F20+L20+R20+X20+AD20+AJ20 -> 0 | AQ20: =AP20/E20 -> #DIV/0!
F21: =G21+H21 -> 0 | I21: =J21+K21 -> 0 | L21: =M21+N21 -> 0 | O21: =P21+Q21 -> 0 | R21: =S21+T21 -> 0 | U21: =V21+W21 -> 0 | X21: =Y21+Z21 -> 0 | AA21: =AB21+AC21 -> 0 | AD21: =AE21+AF21 -> 0 | AG21: =AH21+AI21 -> 0 | AJ21: =AK21+AL21 -> 0 | AM21: =AN21+AO21 -> 0 | AP21: =F21+L21+R21+X21+AD21+AJ21 -> 0 | AQ21: =AP21/E21 -> #DIV/0!
F22: =G22+H22 -> 0 | I22: =J22+K22 -> 0 | L22: =M22+N22 -> 0 | O22: =P22+Q22 -> 0 | R22: =S22+T22 -> 0 | U22: =V22+W22 -> 0 | X22: =Y22+Z22 -> 0 | AA22: =AB22+AC22 -> 0 | AD22: =AE22+AF22 -> 0 | AG22: =AH22+AI22 -> 0 | AJ22: =AK22+AL22 -> 0 | AM22: =AN22+AO22 -> 0 | AP22: =F22+L22+R22+X22+AD22+AJ22 -> 0 | AQ22: =AP22/E22 -> #DIV/0!
F23: =G23+H23 -> 0 | I23: =J23+K23 -> 0 | L23: =M23+N23 -> 0 | O23: =P23+Q23 -> 0 | R23: =S23+T23 -> 0 | U23: =V23+W23 -> 0 | X23: =Y23+Z23 -> 0 | AA23: =AB23+AC23 -> 0 | AD23: =AE23+AF23 -> 0 | AG23: =AH23+AI23 -> 0 | AJ23: =AK23+AL23 -> 0 | AM23: =AN23+AO23 -> 0 | AP23: =F23+L23+R23+X23+AD23+AJ23 -> 0 | AQ23: =AP23/E23 -> #DIV/0!
F24: =G24+H24 -> 0 | I24: =J24+K24 -> 0 | L24: =M24+N24 -> 0 | O24: =P24+Q24 -> 0 | R24: =S24+T24 -> 0 | U24: =V24+W24 -> 0 | X24: =Y24+Z24 -> 0 | AA24: =AB24+AC24 -> 0 | AD24: =AE24+AF24 -> 0 | AG24: =AH24+AI24 -> 0 | AJ24: =AK24+AL24 -> 0 | AM24: =AN24+AO24 -> 0 | AP24: =F24+L24+R24+X24+AD24+AJ24 -> 0 | AQ24: =AP24/E24 -> #DIV/0!
F25: =G25+H25 -> 0 | I25: =J25+K25 -> 0 | L25: =M25+N25 -> 0 | O25: =P25+Q25 -> 0 | R25: =S25+T25 -> 0 | U25: =V25+W25 -> 0 | X25: =Y25+Z25 -> 0 | AA25: =AB25+AC25 -> 0 | AD25: =AE25+AF25 -> 0 | AG25: =AH25+AI25 -> 0 | AJ25: =AK25+AL25 -> 0 | AM25: =AN25+AO25 -> 0 | AP25: =F25+L25+R25+X25+AD25+AJ25 -> 0 | AQ25: =AP25/E25 -> #DIV/0!
F26: =G26+H26 -> 0 | I26: =J26+K26 -> 0 | L26: =M26+N26 -> 0 | O26: =P26+Q26 -> 0 | R26: =S26+T26 -> 0 | U26: =V26+W26 -> 0 | X26: =Y26+Z26 -> 0 | AA26: =AB26+AC26 -> 0 | AD26: =AE26+AF26 -> 0 | AG26: =AH26+AI26 -> 0 | AJ26: =AK26+AL26 -> 0 | AM26: =AN26+AO26 -> 0 | AP26: =F26+L26+R26+X26+AD26+AJ26 -> 0 | AQ26: =AP26/E26 -> #DIV/0!
F27: =G27+H27 -> 0 | I27: =J27+K27 -> 0 | L27: =M27+N27 -> 0 | O27: =P27+Q27 -> 0 | R27: =S27+T27 -> 0 | U27: =V27+W27 -> 0 | X27: =Y27+Z27 -> 0 | AA27: =AB27+AC27 -> 0 | AD27: =AE27+AF27 -> 0 | AG27: =AH27+AI27 -> 0 | AJ27: =AK27+AL27 -> 0 | AM27: =AN27+AO27 -> 0 | AP27: =F27+L27+R27+X27+AD27+AJ27 -> 0 | AQ27: =AP27/E27 -> #DIV/0!
F28: =G28+H28 -> 0 | I28: =J28+K28 -> 0 | L28: =M28+N28 -> 0 | O28: =P28+Q28 -> 0 | R28: =S28+T28 -> 0 | U28: =V28+W28 -> 0 | X28: =Y28+Z28 -> 0 | AA28: =AB28+AC28 -> 0 | AD28: =AE28+AF28 -> 0 | AG28: =AH28+AI28 -> 0 | AJ28: =AK28+AL28 -> 0 | AM28: =AN28+AO28 -> 0 | AP28: =F28+L28+R28+X28+AD28+AJ28 -> 0 | AQ28: =AP28/E28 -> #DIV/0!
F29: =G29+H29 -> 0 | I29: =J29+K29 -> 0 | L29: =M29+N29 -> 0 | O29: =P29+Q29 -> 0 | R29: =S29+T29 -> 0 | U29: =V29+W29 -> 0 | X29: =Y29+Z29 -> 0 | AA29: =AB29+AC29 -> 0 | AD29: =AE29+AF29 -> 0 | AG29: =AH29+AI29 -> 0 | AJ29: =AK29+AL29 -> 0 | AM29: =AN29+AO29 -> 0 | AP29: =F29+L29+R29+X29+AD29+AJ29 -> 0 | AQ29: =AP29/E29 -> #DIV/0!
... F31: =G31+H31 -> 0 | I31: =J31+K31 -> 0 | L31: =M31+N31 -> 0 | O31: =P31+Q31 -> 0 | R31: =S31+T31 -> 0 | U31: =V31+W31 -> 0 | X31: =Y31+Z31 -> 0 | AA31: =AB31+AC31 -> 0 | AD31: =AE31+AF31 -> 0 | AG31: =AH31+AI31 -> 0 | AJ31: =AK31+AL31 -> 0 | AM31: =AN31+AO31 -> 0 | AP31: =F31+L31+R31+X31+AD31+AJ31 -> 0 | AQ31: =AP31/E31 -> #DIV/0!
B32: 合 計 | C32: =SUM(C12:C31) -> 4786 | D32: =SUM(D12:D31) -> 1220 | E32: =SUM(E12:E31) -> 4780 | F32: =SUM(F12:F31) -> 232 | G32: =SUM(G12:G31) -> 98 | H32: =SUM(H12:H31) -> 134 | I32: =SUM(I12:I31) -> 208 | J32: =SUM(J12:J31) -> 84 | ... AP32: =SUM(AP12:AP31) -> 232 | AQ32: =AP32/E32 -> 0.048535565

Sheet 様式３ 教育の質・履修者数を向上させるための体制・計画
I1: 様式３
G2: 大学等名 | H2: ='様式１-４ プログラムを構成する授業科目'!C2 -> 淑徳大学
A4: 教育の質・履修者数を向上させるための体制・計画について
A6: ① | B6: 全学の教員数 | C6: (常勤） | E6: 160 | F6: 人 | G6: （非常勤） | H6: 290 | I6: 人
A8: ② | B8: プログラムの授業を教えている教員数 | H8: 18 | I8: 人
A10: ③ | B10: プログラムの運営責任者
B11: （責任者名） | C11: 下山 昭夫 | G11: （役職名） | H11: 高等教育研究開発センター長
A13: ④ | B13: プログラムを改善・進化させるための体制（委員会・組織等）
B14: 淑徳大学高等教育研究開発センター数理・データサイエンス・AI教育部門
B16: （責任者名） | C16: 松山恵美子 | G16: （役職名） | H16: 数理・データサイエンス・AI教育部門長
A18: ⑤ | B18: プログラムを改善・進化させるための体制を定める規則名称
B19: 淑徳大学高等教育研究開発センター規程
A21: ⑥ | B21: 体制の目的
B22: 大学の教育研究の改革・改善に関する事項を取扱い、大学の教育の発展・向上に資することを目的とした淑徳大学高等教育研究開発センター内に、数理・データサイエンス・AI教育部門を令和4年度に設置をした。この部門は、全学共通の数理・データサイエンス・AI教育プログラムの開発及び運営を行うことを目的とし、全ての学部から選出された情報教育あるいは関連分野の科目を担当をする教員及び各キャンパスの教学担当の職員で構成され、教職協働で数理・データサイエンス・AI教育の推進及び向上に取り組んでいる。またプログラムを円滑に運営するため定期的に部門会議を行い、各学部での課題の共有化と解決などプログラムのブラッシュアップに取り組んでいる。
A34: ⑦ | B34: 具体的な構成員
B35: データサイエンス運営部門長・総合福祉学部教授 松山 恵美子 コミュニティ政策学部 教授 野田陽子 看護栄養学部 准教授 阿曽菜美 経営学部 教授 齊藤鉄也 人文学部 助教 吉森丹衣子 千葉キャンパス学事部 課長補佐 佐々木敏人 千葉第二キャンパス事務部 事務員 中村 匠 埼玉キャンパス学事部 課長補佐 岩上達一郎 東京キャンパス学事部 課長 竹内好映
A48: ⑧ | B48: 履修者数・履修率の向上に向けた計画 ※様式１の「履修必須の有無」で「計画がある」としている場合は詳細について記載すること
B49: 令和４年度実績 | C49: ='様式２ 履修者等数の実績'!AQ32 -> 0.048535565 | E49: 令和５年度予定 | F49: 0.2 | H49: 令和６年度予定 | I49: 0.3
B50: 令和７年度予定 | C50: 0.4 | E50: 令和８年度予定 | F50: 0.5 | H50: 収容定員（名） | I50: ='様式２ 履修者等数の実績'!E32 -> 4780
B51: 具体的な計画
B52: 令和4年度は新入生に対し、オリエンテーションでの案内を実施した。特に教職課程の学生に対しては、履修指導などでプログラムの該当科目を履修するよう指導を実施している。 令和5年度からは全学共通基礎教育科目を見直し、新入生オリエンテーションで学生への周知を実施するほか、数理・データサイエンス・AI教育を大学として進めることを記載したホームページを設置し学内外に広く公表している。本数理・データサイエンス・AI教育プログラムは必修科目2科目と選択科目１科目で構成されている。そのため選択科目である「情報社会とデータサイエンス」については、全学部の履修モデル45モデルのうち、23モデル（開講科目の関係上、履修ができない学科が存在したため）に含め、積極的に履修することを促進している。 数理・データサイエンス・AI教育推進については令和5年度から5か年の中期事業計画にKPIとして設定し、大学全体で①数理・データサイエンス・ＡＩ教育認定プログラム修了生 卒業生の50％以上、②・教職課程履修者の履修率100％を掲げている。
A65: ⑨ | B65: 学部・学科に関係なく希望する学生全員が受講可能となるような必要な体制・取組等
B66: 令和5年度から基盤教育を全学で一新し、数理・データサイエンス・AI教育は全ての学科で共通のプログラムとし、時間割などの配慮を実施、希望する学生は履修できるよう取り組んでいる。 必修科目は全ての学生が履修するが、選択科目は資格科目の履修を優先せざるを得ない一部学科があるため、授業の収録を行い、オンデマンド教材による履修の整備を進めている。
A79: ⑩ | B79: できる限り多くの学生が履修できるような具体的な周知方法・取組
B80: 数理・データサイエンス・AI教育部門で共通の説明資料を作成し、入学後の新入生オリエンテーションで全学部の学生に向けた周知を行っている。また、個別の履修指導などでは数理・データサイエンス・AI教育の科目を配置した履修モデルを活用しながら履修指導を行っている。 また、令和5年度には大学ホームページに数理・データサイエンス・AI教育プログラムのページを設け、新入生へのオリエンテーションや、プログラム対象となる上級生には教学システムによるメッセージ配信で数理・データサイエンス・AI教育の周知をしている。
A93: ⑪ | B93: できる限り多くの学生が履修・修得できるようなサポート体制
B94: 数理・データサイエンス・AI教育の理解を深めるうえで、各キャンパスで下記の取組みを行っている。 ・情報スキルアップのため、夏休み/春休みのMOS資格講座を実施。 情報スキルアップに関する教育は、基礎的なスキルレベルは「情報リテラシー」「データリテラシー」の授業科目で対応している。それ以上の内容に関しては、マイクロソフト社の認定資格であるMOS（Microsoft Office Specialist）資格の講習会及び資格取得を通じて、学生のスキルレベル向上に取り組んでいる。 ・定期的な情報交換を実施する仕組み 情報の授業を担当する兼任講師と情報担当専任教員、担当職員により毎学期に2～3回程度の定期的な情報交換を実施している。 ・オープンバッジの導入によるプログラム履修の推進 本学の設定した数理・データサイエンス・AI教育プログラムを履修し、対象科目すべての単位を修得した学生には、デジタル証明書であるオープンバッジの発行を予定している。
A107: ⑫ | B107: 授業時間内外で学習指導、質問を受け付ける具体的な仕組み
B108: 本教育プログラムの対象科目履修クラスに、授業内における質問等に対応する役割としてのコーディネーター、または学生アシスタント・TAを配置する体制を整備し、授業時間内において課題に対する質問を受け付ける体制を整えている。また、千葉キャンパスでは情報教室のすぐ近くに専門員が常駐し、授業時間外でも学生の課題や質問に対応している。

Sheet 様式４　自己点検・評価
I1: 様式４
H2: 大学等名 | I2: ='様式１-４ プログラムを構成する授業科目'!C2 -> 淑徳大学
A3: 自己点検・評価について
A5: ① | B5: プログラムの自己点検・評価を行う体制（委員会・組織等）
B6: 高等教育研究開発センター
D8: （責任者名） | E8: 下山昭夫 | G8: （役職名） | H8: 高等教育研究開発センター長
A10: ② | B10: 自己点検・評価体制における意見等
B11: 自己点検・評価の視点 | E11: 自己点検・評価体制における意見・結果・改善に向けた取組等
B12: 学内からの視点
C13: プログラムの履修・修得状況 | E13: 【プログラムの履修状況】 令和4年度より大学全体で数理・データサイエンス・AI教育を開講し、全ての学部学科でカリキュラム改正及び学則改正を行い必要な科目を配置した。履修情報は高等教育研究開発センターの事務担当がデータを収集し、選択科目である2022年度の「情報社会とデータサイエンス」については233名、必修科目の単位を取得し、数理・データサイエンス・AI教育プログラムを修了したのは202名であった。 【プログラムの習得状況】 単位取得状況について、「情報社会とデータサイエンス」の受講者のうち合格者の割合は・・90.9％、「情報処理法」・・92.3％、「情報基礎演習」・・95.3％、「情報管理法」・・98.0％、「情報活用法」・・87.7％、「情報応用演習」・・92.7％であり、概ね適切な成績評価と単位認定が行われたと判断できる。 【改善に向けた取組】 履修状況は教職課程の学生が多く、教職課程での数理・データサイエンス・AI教育の必要性について指導した結果であると考えられる。今後、オープンバッジなどの導入や数理・データサイエンス・AI教育の必要性などをオリエンテーションを通じて、履修者数を増やす取り組みと行う。また単位の修得状況については、高等教育研究開発センターが中心となり、成績分布などの一覧を通じて、検証及び改善を行う。
C14: 学修成果 | E14: プログラムに関連する科目全てにおいて、到達目標を明記し、全てのシラバスについて第三者がシラバスチェックを行い、共通のプログラムとなるように取り組んでいる。また受講者を対象に授業アンケートを実施し。分析結果を大学レベル・教育課程レベル・担当教員にフィードバックし、今後の授業運営に反映している。 また11月に高等教育研究開発センターが行う学修行動等に関する調査では、入学した時点と比べての能力や知識の変化についての設問を設定し、「データや情報を収集・分析し、表現する力が増えた」によって、プログラムの学修成果を間接的に図っている。また、データサイエンスの関連科目における授業アンケートの結果（理解度や到達度など）や、授業における実態など、定量的、定性的双方の観点で、高等教育研究開発センターにおける委員会（データサイエンス運営担当者会議）などで共有及び検討し、次年度以降のプログラム運営の改善策を策定して、実行に向けて準備を進めている。
C15: 学生アンケート等を通じた学生の内容の理解度 | E15: 数理・データサイエンス・AI教育の対象科目全てに授業アンケートを行い、授業アンケート設問3「あなたは、シラバスに書かれた授業の目的、内容、評価方法等を理解していましたか」の結果として、理解できている、概ね理解できていると回答したのは、それぞれの講義の受講者のうち、「情報社会とデータサイエンス」・・84.0％、「情報処理法」・・93.3％、「情報基礎演習」・・97.5％、「情報管理法」・・95.8％、「情報活用法」・・93.2％、「情報応用演習」・・95.0％であり、学生のほとんどが授業内容について理解できている。
C16: 学生アンケート等を通じた後輩等他の学生への推奨度 | E16: 授業アンケートの授業の成果について設定した設問「あなたは、この授業を受講して、満足していますか」についてそれぞれ受講者のうち、「情報社会とデータサイエンス」・・67.0％、「情報処理法」・・96.5％、「情報基礎演習」・・96.8％、「情報管理法」・・98.4％、「情報活用法」・・88.6％、「情報応用演習」・・96.8％という高い数字が出ており、今後、他学生へ波及することが見込まれている。また、令和5年度に向けて実施された新入生オリエンテーションにて学生、教員向けにプログラムに関する周知をするなど、履修率向上の施策を実施している。
C17: 全学的な履修者数、履修率向上に向けた計画の達成・進捗状況 | E17: 全学的な履修者数・履修率の向上に向けた計画については、これまでの履修状況や単位取得状況、授業アンケートの結果などを考慮し、高等教育研究開発センター（データサイエンス運営担当者会議）を中心に、各学部の状況を踏まえつつ全学的な観点で履修者数、履修率向上に向けた改善計画を立案し推進している。また、次年度よりプログラム修了者にはオープンバッジ（デジタル証明書）を授与することで、データサイエンスに関する学修成果を示すことが可能となり、就職活動などでの活用が見込まれる。 また進捗状況については令和5年度以降は高等教育研究開発センターだけではなく、中期事業計画のKPIとして設定しているため、大学の内部質保証推進委員会などでも進捗状況の確認を実施予定である。
B18: 学外からの視点
C19: 教育プログラム修了者の進路、活躍状況、企業等の評価 | E19: 本プログラムは令和4年度より開始されたものであり、修了者の進路や活躍状況の把握・活用については、今後の課題となっている。本学は卒業生対象調査を卒業1年後に実施しており、本教育プログラムを修了した卒業生の進路先や活躍状況の把握をすることを想定している。また高等教育研究開発センターや学長室が民間企業、公務員団体に対して定期的に半構造インタビューを実施しているため、本教育プログラムを修了した卒業生における採用状況や卒業生の知識や能力評価を把握する仕組みを設ける予定である。
C20: 産業界からの視点を含めた教育プログラム内容・手法等への意見 | E20: 産業界からの視点として、数理・データサイエンス・AI教育等に知見のある外部有識者2名と及び大学の数理・データサイエンス・AI教育部門の教職員で自己点検・評価を実施し、科目の内容・手法に関する以下の意見をいただいた。 ・科目のシラバスに学生が追いついておらず、講義の進行に影響が出た。 ・講義を受けた学生には、メール、PowerPoint、Excel等の基本動作を扱えない学生が見受けられた。 ・Zoom、動画を撮影する課題に対する抵抗感は見られなかった。 ・ファイルの保存場所の概念やダブルクリック等、パソコンの基礎動作になれていない場面も見受けられた。 ・全体的に学生が受け身であり、質問等にも積極的ではない。 いただいた内容はシラバスの改善等に活用し、今後も産業界など学外有識者から定期的に教育内容および手法等について評価・意見交換し、プログラムの改善等に活用していく予定である。
B21: 数理・データサイエンス・ＡＩを「学ぶ楽しさ」「学ぶことの意義」を理解させること | E21: プログラムの対象科目の1つである「情報社会とデータサイエンス」では、イントロダクションとしてSociety5.0と個人情報に関する内容の講義を実施し、文系学生の理数系科目に対する苦手意識を考慮した講義を展開している。「学ぶことの楽しさ」については、授業アンケート設問16「あなたは、この授業を受講して、満足していますか」にて、「情報社会とデータサイエンス」・・67.0％、「情報処理法」・・96.5％、「情報基礎演習」・・96.8％、「情報管理法」・・98.4％、「情報活用法」・・88.6％、「情報応用演習」・・96.8％という高い数字がでており、受講生に「数理・データサイエンス・AIを『学ぶ楽しさ』『学ぶことの意義』の理解」は十分に得られていると判断できる。
B22: 内容・水準を維持・向上しつつ、より「分かりやすい」授業とすること | E22: 本プログラムはまだ開始されたばかりであり、内容・水準の維持・向上に関する改善等は数理・データサイエンス・AI教育部門にて検討を予定している。具体的には、プログラムを進行していく中で問題となる点を数理・データサイエンス・AI教育部門にて収集しながら、科目内容や教育手法の検討・改善につなげて仕組みを構築している。 また数理・データサイエンス・AI教育部門に配属された専任の教員が全ての数理・データサイエンス・AI教育プログラムのコーディネートを行い、一定の質の維持・向上を行う。 また、講義を担当している外部企業の有識者による講義に関する評価を受けることで、外部の視点を取り入れかつ継続的に授業内容を維持・向上させていきたい。
