Workbook

Sheet 様式１　プログラムを構成する授業科目
R1: 様式１ | T1: 「学部・学科によって、修了要件は相違する」場合は、本シートを複製の上＜様式１－〇＞と枝番号を付してください
B2: 大学等名 | C2: 甲南大学
B3: プログラム名 | C3: KONAN 数理・データサイエンス・AI教育プログラム
A5: プログラムを構成する授業科目について
A7: ① 対象となる学部・学科名称 | J7: ② 教育プログラムの修了要件 | K7: 学部・学科によって、修了要件は相違しない
A12: ③ 修了要件
B13: 「AI・データサイエンス入門」の単位（2単位）を修得すること。 「AI・データサイエンス入門」では、次の4つの基礎的なリテラシー能力を修得することを科目における到達目標とし、授業回ごとに課される合計15回の課題の成績に基づき単位を認定する。 • AI・データサイエンスの歴史および現状に関する基本的な理解 • 最先端のAI・データサイエンス技術の実例を通じた今後の展望の理解 • 表計算ソフトを活用した基礎的な統計処理によるデータの可視化方法の習得 • 情報セキュリティに関する基礎的な知識の習得と，データの収集と適正な管理のための知識の習得 | V13: 【プルダウンリスト】
V14: 令和４年度以前より、履修することが必須のプログラムとして実施
V15: 令和７年度までに履修必須とする計画
V16: 令和８年度以降に履修必須とする計画、又は未定
B20: 必要最低単位数 | C20: 2 | E20: 単位 | J20: 履修必須の有無 | K20: 令和８年度以降に履修必須とする計画、又は未定
A22: ④ 現在進行中の社会変化（第４次産業革命、Society 5.0、データ駆動型社会等）に深く寄与しているものであり、それが自らの生活と密接に結びついている」の内容を含む授業科目
B24: 授業科目 | F24: 単位数 | G24: 必須 | H24: 1-1 | I24: 1-6 | J24: 授業科目 | P24: 単位数 | Q24: 必須 | R24: 1-1 | S24: 1-6
B25: AI・データサイエンス入門 | F25: 2 | G25: ○ | H25: ○ | I25: ○
A33: ⑤ 「社会で活用されているデータ」や「データの活用領域」は非常に広範囲であって、日常生活や社会の課題を解決する有用なツールになり得るもの」の内容を含む授業科目
B35: 授業科目 | F35: 単位数 | G35: 必須 | H35: 1-2 | I35: 1-3 | J35: 授業科目 | P35: 単位数 | Q35: 必須 | R35: 1-2 | S35: 1-3
B36: AI・データサイエンス入門 | F36: 2 | G36: ○ | H36: ○ | I36: ○
A44: ⑥ 「様々なデータ利活用の現場におけるデータ利活用事例が示され、様々な適用領域（流通、製造、金融、サービス、インフラ、公共、ヘルスケア等）の知見と組み合わせることで価値を創出するもの」の内容を含む授業科目
B46: 授業科目 | F46: 単位数 | G46: 必須 | H46: 1-4 | I46: 1-5 | J46: 授業科目 | P46: 単位数 | Q46: 必須 | R46: 1-4 | S46: 1-5
B47: AI・データサイエンス入門 | F47: 2 | G47: ○ | H47: ○ | I47: ○
A55: ⑦ 「活用に当たっての様々な留意事項（ELSI、個人情報、データ倫理、ＡＩ社会原則等）を考慮し、情報セキュリティや情報漏洩等、データを守る上での留意事項への理解をする」の内容を含む授業科目
B57: 授業科目 | F57: 単位数 | G57: 必須 | H57: 3-1 | I57: 3-2 | J57: 授業科目 | P57: 単位数 | Q57: 必須 | R57: 3-1 | S57: 3-2
B58: AI・データサイエンス入門 | F58: 2 | G58: ○ | H58: ○ | I58: ○
A66: ⑧ 「実データ・実課題（学術データ等を含む）を用いた演習など、社会での実例を題材として、「データを読む、説明する、扱う」といった数理・データサイエンス・ＡＩの基本的な活用法に関するもの」の内容を含む授業科目
B68: 授業科目 | E68: 単位数 | F68: 必須 | G68: 2-1 | H68: 2-2 | I68: 2-3 | J68: 授業科目 | O68: 単位数 | P68: 必須 | Q68: 2-1 | R68: 2-2 | S68: 2-3
B69: AI・データサイエンス入門 | E69: 2 | F69: ○ | G69: ○ | H69: ○ | I69: ○
A77: ⑨ 選択「４．オプション」の内容を含む授業科目
B78: 授業科目 | F78: 選択項目 | J78: 授業科目 | P78: 選択項目
B79: AI・データサイエンス入門 | F79: 4‐3データ構造とプログラミング基礎
B80: AI・データサイエンス入門 | F80: 4‐8データ活用実践（教師あり学習）
A87: ⑩ プログラムを構成する授業の内容
B88: 授業に含まれている内容・要素 | D88: 講義内容
B89: （１）現在進行中の社会変化（第４次産業革命、Society 5.0、データ駆動型社会等）に深く寄与しているものであり、それが自らの生活と密接に結びついている | C89: 1-1 | D89: ビッグデータ、第4次産業革命、Society5.0、人間の知的活動とAI「AI・データサイエンス入門」（第1回）
C90: 1-6 | D90: AI等を活用したビジネスモデル（シェアリングエコノミーなど）、AI最新技術の活用例（敵対的生成ネットワークなど）「AI・データサイエンス入門」（第3回）
B91: （２）「社会で活用されているデータ」や「データの活用領域」は非常に広範囲であって、日常生活や社会の課題を解決する有用なツールになり得るもの | C91: 1-2 | D91: 調査データ、ログデータ、観測データ、構造化・非構造化データ「AI・データサイエンス入門」（第1回）
C92: 1-3 | D92: 研究開発、マーケティング、販売、サービスなどでのデータ・AI活用、仮説検証、知識発見「AI・データサイエンス入門」（第2回）
B93: （３）様々なデータ利活用の現場におけるデータ利活用事例が示され、様々な適用領域（流通、製造、金融、サービス、インフラ、公共、ヘルスケア等）の知見と組み合わせることで価値を創出するもの | C93: 1-4 | D93: データ解析、非構造化データ処理「AI・データサイエンス入門」(第2回）
C94: 1-5 | D94: データ分析による意思決定、データサイエンスのサイクル、「AI・データサイエンス入門」（第3回）
B95: （４）活用に当たっての様々な留意事項（ELSI、個人情報、データ倫理、ＡＩ社会原則等）を考慮し、情報セキュリティや情報漏洩等、データを守る上での留意事項への理解をする | C95: 3-1 | D95: ELSI（Ethical,Legal and Social Issues)、個人情報保護、EU一般データ保護規則（GDPR) 忘れられる権利、オプトアウト権 人間中心の判断 AIサービスの責任論「AI・データサイエンス入門」（第9回） データ倫理：データ捏造、改ざん、盗用、AI社会原則（公平性、説明責任、透明性）、データバイアス、アルゴリズムバイアス、データ・AI活用における負の事例紹介「AI・データサイエンス入門」（第10回）
C96: 3-2 | D96: 情報セキュリティ 機密性、完全性、可用性、匿名加工情報、暗号化、パスワード、悪意ある情報搾取（フィッシングなど）、情報漏洩等によるセキュリティ事故の事例紹介「データサイエンス入門」（第11回）
...

Sheet 様式２ 履修者等数の実績
AQ1: 様式２
AL2: 大学等名 | AM2: ='様式１ プログラムを構成する授業科目'!C2 -> 甲南大学
A3: プログラムの履修者数等の実績について
A5: ①プログラム開設年度 | C5: 令和４ | E5: 年度
A7: ②履修者・修了者の実績
B9: 学部・学科名称 | C9: 学生数 | D9: 入学 定員 | E9: 収容 定員 | F9: 令和4年度 | L9: 令和3年度 | R9: 令和2年度 | X9: 令和元年度 | AD9: 平成30年度 | AJ9: 平成29年度 | AP9: 履修者数 合計 | AQ9: 履修率
F10: 履修者数 | I10: 修了者数 | L10: 履修者数 | O10: 修了者数 | R10: 履修者数 | U10: 修了者数 | X10: 履修者数 | AA10: 修了者数 | AD10: 履修者数 | AG10: 修了者数 | AJ10: 履修者数 | AM10: 修了者数
F11: 合計 | G11: 男性 | H11: 女性 | I11: 合計 | J11: 男性 | K11: 女性 | L11: 合計 | M11: 男性 | N11: 女性 | O11: 合計 | P11: 男性 | Q11: 女性 | R11: 合計 | S11: 男性 | T11: 女性 | U11: 合計 | V11: 男性 | W11: 女性 | X11: 合計 | Y11: 男性 | Z11: 女性 | AA11: 合計 | AB11: 男性 | AC11: 女性 | AD11: 合計 | AE11: 男性 | AF11: 女性 | AG11: 合計 | AH11: 男性 | AI11: 女性 | AJ11: 合計 | AK11: 男性 | AL11: 女性 | AM11: 合計 | AN11: 男性 | AO11: 女性
B12: 文学部 | C12: 1812 | D12: 405 | E12: 1620 | F12: =G12+H12 -> 46 | G12: 12 | H12: 34 | I12: =J12+K12 -> 39 | J12: 9 | K12: 30 | L12: =M12+N12 -> 0 | O12: =P12+Q12 -> 0 | R12: =S12+T12 -> 0 | U12: =V12+W12 -> 0 | X12: =Y12+Z12 -> 0 | AA12: =AB12+AC12 -> 0 | AD12: =AE12+AF12 -> 0 | AG12: =AH12+AI12 -> 0 | AJ12: =AK12+AL12 -> 0 | AM12: =AN12+AO12 -> 0 | AP12: =F12+L12+R12+X12+AD12+AJ12 -> 46 | AQ12: =AP12/E12 -> 0.028395062
B13: 理工学部 | C13: 675 | D13: 155 | E13: 620 | F13: =G13+H13 -> 73 | G13: 51 | H13: 22 | I13: =J13+K13 -> 59 | J13: 39 | K13: 20 | L13: =M13+N13 -> 0 | O13: =P13+Q13 -> 0 | R13: =S13+T13 -> 0 | U13: =V13+W13 -> 0 | X13: =Y13+Z13 -> 0 | AA13: =AB13+AC13 -> 0 | AD13: =AE13+AF13 -> 0 | AG13: =AH13+AI13 -> 0 | AJ13: =AK13+AL13 -> 0 | AM13: =AN13+AO13 -> 0 | AP13: =F13+L13+R13+X13+AD13+AJ13 -> 73 | AQ13: =AP13/E13 -> 0.11774194
B14: 経済学部 | C14: 1560 | D14: 345 | E14: 1380 | F14: =G14+H14 -> 61 | G14: 48 | H14: 13 | I14: =J14+K14 -> 41 | J14: 30 | K14: 11 | L14: =M14+N14 -> 0 | O14: =P14+Q14 -> 0 | R14: =S14+T14 -> 0 | U14: =V14+W14 -> 0 | X14: =Y14+Z14 -> 0 | AA14: =AB14+AC14 -> 0 | AD14: =AE14+AF14 -> 0 | AG14: =AH14+AI14 -> 0 | AJ14: =AK14+AL14 -> 0 | AM14: =AN14+AO14 -> 0 | AP14: =F14+L14+R14+X14+AD14+AJ14 -> 61 | AQ14: =AP14/E14 -> 0.044202899
B15: 法学部 | C15: 1532 | D15: 345 | E15: 1380 | F15: =G15+H15 -> 41 | G15: 31 | H15: 10 | I15: =J15+K15 -> 30 | J15: 23 | K15: 7 | L15: =M15+N15 -> 0 | O15: =P15+Q15 -> 0 | R15: =S15+T15 -> 0 | U15: =V15+W15 -> 0 | X15: =Y15+Z15 -> 0 | AA15: =AB15+AC15 -> 0 | AD15: =AE15+AF15 -> 0 | AG15: =AH15+AI15 -> 0 | AJ15: =AK15+AL15 -> 0 | AM15: =AN15+AO15 -> 0 | AP15: =F15+L15+R15+X15+AD15+AJ15 -> 41 | AQ15: =AP15/E15 -> 0.029710145
B16: 経営学部 | C16: 1563 | D16: 345 | E16: 1380 | F16: =G16+H16 -> 57 | G16: 35 | H16: 22 | I16: =J16+K16 -> 38 | J16: 22 | K16: 16 | L16: =M16+N16 -> 0 | O16: =P16+Q16 -> 0 | R16: =S16+T16 -> 0 | U16: =V16+W16 -> 0 | X16: =Y16+Z16 -> 0 | AA16: =AB16+AC16 -> 0 | AD16: =AE16+AF16 -> 0 | AG16: =AH16+AI16 -> 0 | AJ16: =AK16+AL16 -> 0 | AM16: =AN16+AO16 -> 0 | AP16: =F16+L16+R16+X16+AD16+AJ16 -> 57 | AQ16: =AP16/E16 -> 0.041304348
B17: 知能情報学部 | C17: 558 | D17: 120 | E17: 480 | F17: =G17+H17 -> 137 | G17: 115 | H17: 22 | I17: =J17+K17 -> 106 | J17: 88 | K17: 18 | L17: =M17+N17 -> 0 | O17: =P17+Q17 -> 0 | R17: =S17+T17 -> 0 | U17: =V17+W17 -> 0 | X17: =Y17+Z17 -> 0 | AA17: =AB17+AC17 -> 0 | AD17: =AE17+AF17 -> 0 | AG17: =AH17+AI17 -> 0 | AJ17: =AK17+AL17 -> 0 | AM17: =AN17+AO17 -> 0 | AP17: =F17+L17+R17+X17+AD17+AJ17 -> 137 | AQ17: =AP17/E17 -> 0.28541667
B18: マネジメント創造学部 | C18: 780 | D18: 180 | E18: 720 | F18: =G18+H18 -> 29 | G18: 16 | H18: 13 | I18: =J18+K18 -> 24 | J18: 12 | K18: 12 | L18: =M18+N18 -> 0 | O18: =P18+Q18 -> 0 | R18: =S18+T18 -> 0 | U18: =V18+W18 -> 0 | X18: =Y18+Z18 -> 0 | AA18: =AB18+AC18 -> 0 | AD18: =AE18+AF18 -> 0 | AG18: =AH18+AI18 -> 0 | AJ18: =AK18+AL18 -> 0 | AM18: =AN18+AO18 -> 0 | AP18: =F18+L18+R18+X18+AD18+AJ18 -> 29 | AQ18: =AP18/E18 -> 0.040277778
B19: フロンティアサイエンス学部 | C19: 187 | D19: 45 | E19: 180 | F19: =G19+H19 -> 1 | G19: 1 | H19: 0 | I19: =J19+K19 -> 1 | J19: 1 | K19: 0 | L19: =M19+N19 -> 0 | O19: =P19+Q19 -> 0 | R19: =S19+T19 -> 0 | U19: =V19+W19 -> 0 | X19: =Y19+Z19 -> 0 | AA19: =AB19+AC19 -> 0 | AD19: =AE19+AF19 -> 0 | AG19: =AH19+AI19 -> 0 | AJ19: =AK19+AL19 -> 0 | AM19: =AN19+AO19 -> 0 | AP19: =F19+L19+R19+X19+AD19+AJ19 -> 1 | AQ19: =AP19/E19 -> 0.0055555556
F20: =G20+H20 -> 0 | I20: =J20+K20 -> 0 | L20: =M20+N20 -> 0 | O20: =P20+Q20 -> 0 | R20: =S20+T20 -> 0 | U20: =V20+W20 -> 0 | X20: =Y20+Z20 -> 0 | AA20: =AB20+AC20 -> 0 | AD20: =AE20+AF20 -> 0 | AG20: =AH20+AI20 -> 0 | AJ20: =AK20+AL20 -> 0 | AM20: =AN20+AO20 -> 0 | AP20: =F20+L20+R20+X20+AD20+AJ20 -> 0 | AQ20: =AP20/E20 -> #DIV/0!
F21: =G21+H21 -> 0 | I21: =J21+K21 -> 0 | L21: =M21+N21 -> 0 | O21: =P21+Q21 -> 0 | R21: =S21+T21 -> 0 | U21: =V21+W21 -> 0 | X21: =Y21+Z21 -> 0 | AA21: =AB21+AC21 -> 0 | AD21: =AE21+AF21 -> 0 | AG21: =AH21+AI21 -> 0 | AJ21: =AK21+AL21 -> 0 | AM21: =AN21+AO21 -> 0 | AP21: =F21+L21+R21+X21+AD21+AJ21 -> 0 | AQ21: =AP21/E21 -> #DIV/0!
F22: =G22+H22 -> 0 | I22: =J22+K22 -> 0 | L22: =M22+N22 -> 0 | O22: =P22+Q22 -> 0 | R22: =S22+T22 -> 0 | U22: =V22+W22 -> 0 | X22: =Y22+Z22 -> 0 | AA22: =AB22+AC22 -> 0 | AD22: =AE22+AF22 -> 0 | AG22: =AH22+AI22 -> 0 | AJ22: =AK22+AL22 -> 0 | AM22: =AN22+AO22 -> 0 | AP22: =F22+L22+R22+X22+AD22+AJ22 -> 0 | AQ22: =AP22/E22 -> #DIV/0!
F23: =G23+H23 -> 0 | I23: =J23+K23 -> 0 | L23: =M23+N23 -> 0 | O23: =P23+Q23 -> 0 | R23: =S23+T23 -> 0 | U23: =V23+W23 -> 0 | X23: =Y23+Z23 -> 0 | AA23: =AB23+AC23 -> 0 | AD23: =AE23+AF23 -> 0 | AG23: =AH23+AI23 -> 0 | AJ23: =AK23+AL23 -> 0 | AM23: =AN23+AO23 -> 0 | AP23: =F23+L23+R23+X23+AD23+AJ23 -> 0 | AQ23: =AP23/E23 -> #DIV/0!
F24: =G24+H24 -> 0 | I24: =J24+K24 -> 0 | L24: =M24+N24 -> 0 | O24: =P24+Q24 -> 0 | R24: =S24+T24 -> 0 | U24: =V24+W24 -> 0 | X24: =Y24+Z24 -> 0 | AA24: =AB24+AC24 -> 0 | AD24: =AE24+AF24 -> 0 | AG24: =AH24+AI24 -> 0 | AJ24: =AK24+AL24 -> 0 | AM24: =AN24+AO24 -> 0 | AP24: =F24+L24+R24+X24+AD24+AJ24 -> 0 | AQ24: =AP24/E24 -> #DIV/0!
F25: =G25+H25 -> 0 | I25: =J25+K25 -> 0 | L25: =M25+N25 -> 0 | O25: =P25+Q25 -> 0 | R25: =S25+T25 -> 0 | U25: =V25+W25 -> 0 | X25: =Y25+Z25 -> 0 | AA25: =AB25+AC25 -> 0 | AD25: =AE25+AF25 -> 0 | AG25: =AH25+AI25 -> 0 | AJ25: =AK25+AL25 -> 0 | AM25: =AN25+AO25 -> 0 | AP25: =F25+L25+R25+X25+AD25+AJ25 -> 0 | AQ25: =AP25/E25 -> #DIV/0!
F26: =G26+H26 -> 0 | I26: =J26+K26 -> 0 | L26: =M26+N26 -> 0 | O26: =P26+Q26 -> 0 | R26: =S26+T26 -> 0 | U26: =V26+W26 -> 0 | X26: =Y26+Z26 -> 0 | AA26: =AB26+AC26 -> 0 | AD26: =AE26+AF26 -> 0 | AG26: =AH26+AI26 -> 0 | AJ26: =AK26+AL26 -> 0 | AM26: =AN26+AO26 -> 0 | AP26: =F26+L26+R26+X26+AD26+AJ26 -> 0 | AQ26: =AP26/E26 -> #DIV/0!
F27: =G27+H27 -> 0 | I27: =J27+K27 -> 0 | L27: =M27+N27 -> 0 | O27: =P27+Q27 -> 0 | R27: =S27+T27 -> 0 | U27: =V27+W27 -> 0 | X27: =Y27+Z27 -> 0 | AA27: =AB27+AC27 -> 0 | AD27: =AE27+AF27 -> 0 | AG27: =AH27+AI27 -> 0 | AJ27: =AK27+AL27 -> 0 | AM27: =AN27+AO27 -> 0 | AP27: =F27+L27+R27+X27+AD27+AJ27 -> 0 | AQ27: =AP27/E27 -> #DIV/0!
F28: =G28+H28 -> 0 | I28: =J28+K28 -> 0 | L28: =M28+N28 -> 0 | O28: =P28+Q28 -> 0 | R28: =S28+T28 -> 0 | U28: =V28+W28 -> 0 | X28: =Y28+Z28 -> 0 | AA28: =AB28+AC28 -> 0 | AD28: =AE28+AF28 -> 0 | AG28: =AH28+AI28 -> 0 | AJ28: =AK28+AL28 -> 0 | AM28: =AN28+AO28 -> 0 | AP28: =F28+L28+R28+X28+AD28+AJ28 -> 0 | AQ28: =AP28/E28 -> #DIV/0!
F29: =G29+H29 -> 0 | I29: =J29+K29 -> 0 | L29: =M29+N29 -> 0 | O29: =P29+Q29 -> 0 | R29: =S29+T29 -> 0 | U29: =V29+W29 -> 0 | X29: =Y29+Z29 -> 0 | AA29: =AB29+AC29 -> 0 | AD29: =AE29+AF29 -> 0 | AG29: =AH29+AI29 -> 0 | AJ29: =AK29+AL29 -> 0 | AM29: =AN29+AO29 -> 0 | AP29: =F29+L29+R29+X29+AD29+AJ29 -> 0 | AQ29: =AP29/E29 -> #DIV/0!
F30: =G30+H30 -> 0 | I30: =J30+K30 -> 0 | L30: =M30+N30 -> 0 | O30: =P30+Q30 -> 0 | R30: =S30+T30 -> 0 | U30: =V30+W30 -> 0 | X30: =Y30+Z30 -> 0 | AA30: =AB30+AC30 -> 0 | AD30: =AE30+AF30 -> 0 | AG30: =AH30+AI30 -> 0 | AJ30: =AK30+AL30 -> 0 | AM30: =AN30+AO30 -> 0 | AP30: =F30+L30+R30+X30+AD30+AJ30 -> 0 | AQ30: =AP30/E30 -> #DIV/0!
F31: =G31+H31 -> 0 | I31: =J31+K31 -> 0 | L31: =M31+N31 -> 0 | O31: =P31+Q31 -> 0 | R31: =S31+T31 -> 0 | U31: =V31+W31 -> 0 | X31: =Y31+Z31 -> 0 | AA31: =AB31+AC31 -> 0 | AD31: =AE31+AF31 -> 0 | AG31: =AH31+AI31 -> 0 | AJ31: =AK31+AL31 -> 0 | AM31: =AN31+AO31 -> 0 | AP31: =F31+L31+R31+X31+AD31+AJ31 -> 0 | AQ31: =AP31/E31 -> #DIV/0!
B32: 合 計 | C32: =SUM(C12:C31) -> 8667 | D32: =SUM(D12:D31) -> 1940 | E32: =SUM(E12:E31) -> 7760 | F32: =SUM(F12:F31) -> 445 | G32: =SUM(G12:G31) -> 309 | H32: =SUM(H12:H31) -> 136 | I32: =SUM(I12:I31) -> 338 | J32: =SUM(J12:J31) -> 224 | ... AP32: =SUM(AP12:AP31) -> 445 | AQ32: =AP32/E32 -> 0.057345361

Sheet 様式３ 教育の質・履修者数を向上させるための体制・計画
I1: 様式３
G2: 大学等名 | H2: ='様式１ プログラムを構成する授業科目'!C2 -> 甲南大学
A4: 教育の質・履修者数を向上させるための体制・計画について
A6: ① | B6: 全学の教員数 | C6: (常勤） | E6: 266 | F6: 人 | G6: （非常勤） | H6: 610 | I6: 人
A8: ② | B8: プログラムの授業を教えている教員数 | H8: 3 | I8: 人
A10: ③ | B10: プログラムの運営責任者
B11: （責任者名） | C11: 高 龍秀 | G11: （役職名） | H11: 全学共通教育センター所長・学長補佐
A13: ④ | B13: プログラムを改善・進化させるための体制（委員会・組織等）
B14: 全学共通教育センター 組織別内部質保証委員会
B16: （責任者名） | C16: 高 龍秀 | G16: （役職名） | H16: 全学共通教育センター所長・学長補佐
A18: ⑤ | B18: プログラムを改善・進化させるための体制を定める規則名称
B19: 甲南大学内部質保証規程・個別内部質保証委員会に関する内規
A21: ⑥ | B21: 体制の目的
B22: 「全学共通教育センター 組織別内部質保証委員会」は、本大学の方針に基づく全学共通教育センターの目的・目標の実現に向けて活動し、絶えず自主・自律的な自己点検・評価活動を行い、組織及び活動の改善・向上に取組むことを目的としている。 本プログラムを構成する授業科目（以下、「本プログラム科目」）が全学共通教育センター開講科目であることから、授業担当者による授業運営におけるPDCAサイクルを確認・検証し、改善に向けたフィードバックを行うことで本プログラムの改善・進化を推進していく。
A34: ⑦ | B34: 具体的な構成員
B35: 委員長：高龍秀（全学共通教育センター所長・教授、学長補佐） 鵤木千加子（全学共通教育センター副所長・教授）、 上記の他、 伊東浩司(教授)、伊庭緑(教授)、梅本剛正(教授)、桂豊(教授)、金泰虎(教授)、久保はるか(教授)、胡金定(教授)、定金浩一(教授)、曽我部晋哉(教授)、谷守正寛(教授)、中村典子(教授)、西川耕平(教授)、野村和宏(教授)、鳩貝耕一(教授)、古田清和(教授)、MACHThomas(教授)、水澤克子(教授)、山崎俊輔(教授)、吉川歩(教授)、吉本忠弘(教授)、石井康一(准教授)、WANGMarian(准教授)、KIRKStanleyA(准教授)、小西幸男(准教授)、篠田有史(准教授)、千葉美保子(准教授)、野村幸宏(准教授)、山本貴揚(准教授)、吉田桂子(准教授)、武田佳久(特任教授)、長谷川雄彦(特任教授)、宮川貴美子(特任教授)、岡村こず恵(特任准教授)、西浦太郎(特任准教授)、山本シャーリ(特任講師)
A48: ⑧ | B48: 履修者数・履修率の向上に向けた計画 ※様式１の「履修必須の有無」で「計画がある」としている場合は詳細について記載すること
B49: 令和４年度実績 | C49: ='様式２ 履修者等数の実績'!AQ32 -> 0.057345361 | E49: 令和５年度予定 | F49: =+('様式２ 履修者等数の実績'!AP32+490)/'様式３ 教育の質・履修者数を向上させるための体制・計画'!$I$50 -> 0.12048969 | H49: 令和６年度予定 | I49: =+('様式２ 履修者等数の実績'!AP32+490*2)/'様式３ 教育の質・履修者数を向上させるための体制・計画'!$I$50 -> 0.18363402
B50: 令和７年度予定 | C50: =+('様式２ 履修者等数の実績'!AP32+490*3)/'様式３ 教育の質・履修者数を向上させるための体制・計画'!$I$50 -> 0.24677835 | E50: 令和８年度予定 | F50: =+('様式２ 履修者等数の実績'!AP32+490*3)/'様式３ 教育の質・履修者数を向上させるための体制・計画'!$I$50 -> 0.24677835 | H50: 収容定員（名） | I50: ='様式２ 履修者等数の実績'!E32 -> 7760
B51: 具体的な計画
B52: 本プログラム科目の開講初年度の履修者数は400名を目標としたところ、その約1.1倍の445名が履修登録をした。令和5年度以降はその1.1倍にあたる490名の履修を目標としたい。目標を実現するために、大学公式ホームページに立ち上げた「数理・データサイエンス・AI教育プログラム」のページや入学前に新入生特設サイトを通じてプログラムの紹介を積極的に行って入学予定者への訴求を行うとともに、入学後も学内広報（ポータルサイト（My KONAN）での周知、履修要項での記載、パンフレット等の配付）を積極的に実施することで、本プログラム科目の履修者数・履修者率を向上させる。なお、学則上初年次教育に位置付けられる科目となっているが、2年次以上の学生への告知を継続的に行うことで、更なる履修者数・履修者率の向上を目指す。
A65: ⑨ | B65: 学部・学科に関係なく希望する学生全員が受講可能となるような必要な体制・取組等
B66: 本プログラム科目はすべての学生が1年次より受講できるように配当年次を設定している。またオンデマンド形式での授業となっており、希望する学生が全員受講可能な体制を整えている。
A79: ⑩ | B79: できる限り多くの学生が履修できるような具体的な周知方法・取組
B80: ⑧に記載の通り、令和4年度には学生に対して本プログラム科目の履修を促す情報提供を実施することで、一定の効果を上げている。今後は大学公式ホームページに立ち上げた「数理・データサイエンス・AI教育プログラム」のページや新入生特設サイト等で本プログラム科目に関する記事を充実させていくことで、入学予定者へのさらなる訴求を行っていく。
A93: ⑪ | B93: できる限り多くの学生が履修・修得できるようなサポート体制
B94: 本プログラムの授業についてはオンデマンド形式となっており、動画資料、スライド資料、課題は本学の教育支援システムであるMy KONANに集約され、授業回毎に定められた期間内であれば何度も視聴することで理解を促す体制が整っている。
A107: ⑫ | B107: 授業時間内外で学習指導、質問を受け付ける具体的な仕組み
B108: 授業に対する理解の程度や感想、コメントを募集することで、履修学生の進捗度などを把握し必要に応じた対応ができるように措置している。また、本学の教育支援システムMy KONANの質問機能を用いて学生からの質問対応を行っている。

Sheet 様式４　自己点検・評価
I1: 様式４
H2: 大学等名 | I2: ='様式１ プログラムを構成する授業科目'!C2 -> 甲南大学
A3: 自己点検・評価について
A5: ① | B5: プログラムの自己点検・評価を行う体制（委員会・組織等）
B6: 全学教育推進機構 組織別内部質保証委員会
D8: （責任者名） | E8: 佐藤泰弘 | G8: （役職名） | H8: 全学教育推進機構長、副学長
A10: ② | B10: 自己点検・評価体制における意見等
B11: 自己点検・評価の視点 | E11: 自己点検・評価体制における意見・結果・改善に向けた取組等
B12: 学内からの視点
C13: プログラムの履修・修得状況 | E13: 本プログラムにおける学生の受講状況，そして受講後に収集したアンケートから，プログラムの履修・修得情報は次のようにまとめることができる．学習マネジメントシステム上での履修者は445名となり，このうち338名が合格し単位を取得した．合格となった学生の平均点は，78.8点となっており，成績の分布は秀：10%，優：28%，良：25%，可：14%，不可：24%となった．本授業では，指定された期間内に教材を閲覧し，出題された課題についても期限内の提出が求められる．学習マネジメントシステムからは，合格した学生の平均課題提出数14.6回（総課題数は15回）となっており，「可」以上の評定を受けた学生は，学習コースの内容について漏れなく十分に取り組んだものと考えられる．
C14: 学修成果 | E14: 前述の通り，出題した課題の採点状況から，合格した学生についてはほぼすべての授業回について，学習期間内に課題の提出が実現された．また，合格者の平均点は78.8点であり，課題の内容理解においても，十分な成果が得られているものと考えられる．授業後に実施したアンケート調査における「この授業を通じて，知識が深まった，能力が高まったと感じますか」という質問項目については，252名の回答中，73.4%の学生が「そう思う・どちらかといえばそう思う」のポジティブな回答となった．以上のことから，本授業で学習者が授業内容について学びを深め，その成果をきちんと身に付ける状況が実現できているものと考えられる．
C15: 学生アンケート等を通じた学生の内容の理解度 | E15: 授業後に学生に対して実施したアンケート調査では，「この授業に意欲的にとりくみましたか？」という質問に対して，252名の回答があり，75.0%の学生が「そう思う・どちらかといえばそう思う」のポジティブな回答となった．また，「授業を履修するにあたり、教員からの指示はよくわかりましたか？」という質問に対しては，253名が回答しており，75.9%の学生が「そう思う・どちらかといえばそう思う」のポジティブな回答となった．履修・習得状況にて紹介した成績の分布状況も鑑みると，本授業に真剣に取り組み，合格の評定を得た学生については，十分な理解が得られているものと考えられる．
C16: 学生アンケート等を通じた後輩等他の学生への推奨度 | E16: 学生へのアンケートで，『授業を履修して、「ＡＩ・データサイエンス入門」の履修を後輩学生に勧めたいですか？』と直接質問する項目を立てて調査を実施した．その結果，252名の回答があり，64.5%の学生が「勧めたい・どちらかといえば勧めたい」と回答した．他のアンケート項目で「課題の分量が多い・やや多い」と考えている学生が半数程度おり，これがやや低い推奨度につながっている可能性がある．一方，このような課題をこなした結果が「知識が深まった・能力が高まった」という前述のポジティブな回答につながっているとも考えられるため，学習成果は保ちつつ課題の分量や内容を見直し，授業の質と学生の満足度の適切なバランスを調整していく．
C17: 全学的な履修者数、履修率向上に向けた計画の達成・進捗状況 | E17: 初年度の実績として，当初400名の履修者を想定して準備を実施したが，最終的に445名の履修者を得ることができた．次年度より，履修者数・履修率の向上に向けた計画の中で立案された内容について，順次遂行し，履修者増・履修率の向上を図る．具体的には，入学前の段階での新入生特設サイトを通じたプログラムの紹介，入学後における学内広報を通じた周知，履修要項での記載，パンフレット等の配付）である．並行して2年次以上の学生への告知も継続的に実施する．
B18: 学外からの視点
C19: 教育プログラム修了者の進路、活躍状況、企業等の評価 | E19: 本教育プログラムは2022年度にスタートし，低年次の履修生が多いことから，修了者の進路，活躍状況，企業等での評価を得るまでには至っていないが，今後はキャリアセンターと連携し，分析を進めていきたい．
C20: 産業界からの視点を含めた教育プログラム内容・手法等への意見 | E20: （本プログラムの内容・手法等に関し，ジェネリックスキルを測定するPROGテストを開発する株式会社リアセック様よりいただいた意見は以下の通り） 文系学生も含めたすべての学生向けに提供される「AI・データサイエンス」の入門的学習プログラムとして，体系的かつ実践的な構成が組まれており，極めて効果的な授業であると評価されます．各自がそれぞれのスピードで，確認クイズを踏まえながら学習を進められることに加えて，随時質問できる環境を整えている点も，自己調整学習に対応した優れた授業運営と考えられます． 内容的には，第４回～第８回のエクセルを用いたデータハンドリングの実習の効果は高く，とりわけ，、第7・8回に布置された「活用編」の内容は，研究活動においても有効性が高く，データハンドリングスキルはもちろん，論理的思考力（特に非言語処理力）の育成にも効果的と思われます．続く，第9回～第11回でセキュリティについて学んだ後に，第12回以降でPythonを使ったプログラミングを学習する展開は，社会ニーズに合致しており実践的です．特に，scikit-learnライブラリーを使って機械学習まで経験させている点は，リテラシーレベルの学習としての完成度の高さを感じます． 一方で，第５回などで統計的検定の話題も触れられると，さらに，完成度が高まるように感じます．エクセル関数を使って，簡便に平均値の差や，独立性に関する検定を実践する回を組み込んでも良いかと思います．
B21: 数理・データサイエンス・ＡＩを「学ぶ楽しさ」「学ぶことの意義」を理解させること | E21: 本授業では，「学ぶ楽しさ」を，概念だけではなく実習による体験を通じて学生に提供する．また，「学ぶことの意義」を，机上の空論にとどまらず，身近な事例によるデータサイエンスの有用性を感じ取ることができる題材を通じて学生に提供する．このため，本授業では，教材や取り上げる内容について継続的に見直しを行い，可能な範囲で最新の話題やトレンドに沿った題材を取り入れ，学生からのアンケート結果も参考に内容に調整を加える．これにより，学生にとって身近な題材がデータサイエンスの視点を通してどのように捉えられるかを，体験的に学ぶことができる授業を目指す．
B22: 内容・水準を維持・向上しつつ、より「分かりやすい」授業とすること | E22: 授業後に実施したアンケートでは，「テキストおよび講義資料等は、授業を理解するために十分な分量・内容だったと思いますか？」の質問では，252名の回答があり，64.7%の学生が，「そう思う・どちらかといえばそう思う」と回答している．この結果を踏まえ，各授業回における課題の得点状況も鑑み，実習内容について継続的な見直しを実施する．また，学内外のFD活動やデータサイエンス教育を扱う学会誌などを通じた，入門者向けのデータサイエンス教育における教示方略や魅力的な題材に関する情報の入手と活用についても実施する．
