Workbook

Sheet 様式１ー１　プログラムを構成する授業科目
R1: 様式１-1 | T1: 「学部・学科によって、修了要件は相違する」場合は、本シートを複製の上＜様式１－〇＞と枝番号を付してください
B2: 大学等名 | C2: 福山平成大学
B3: プログラム名 | C3: 数理・データサイエンス・AI教育プログラム （リテラシーレベル）
A5: プログラムを構成する授業科目について
A7: ① 対象となる学部・学科名称 | J7: ② 教育プログラムの修了要件 | K7: 学部・学科によって、修了要件は相違する
B9: 経営学部経営学科
A12: ③ 修了要件
B13: 「数理・データサイエンス・AI教育プログラム（リテラシーレベル）」は、次の（１）及び（２）の要件を満たしていることを修了要件とする。なお、修了要件を満たした者を「数理・データサイエンス・AI教育プグラム（リテラシーレベル）」の修了者として大学が認定する。（１）一般教育科目である「データサイエンス入門」「情報リテラシーA」「情報リテラシーB」の単位及び学科専門科目である「ICT入門」の単位を取得していること。（２）一般教育科目である「人工知能概論」、「データサイエンス応用」、「プログラミング入門A」、「プログラミング入門B」、「データ科学のための数理統計」、「データリテラシー」のうち、いずれか１科目の単位を取得していること。 | V13: 【プルダウンリスト】
V14: 令和４年度以前より、履修することが必須のプログラムとして実施
V15: 令和７年度までに履修必須とする計画
V16: 令和８年度以降に履修必須とする計画、又は未定
B20: 必要最低単位数 | C20: 8 | E20: 単位 | J20: 履修必須の有無 | K20: 令和４年度以前より、履修することが必須のプログラムとして実施
A22: ④ 現在進行中の社会変化（第４次産業革命、Society 5.0、データ駆動型社会等）に深く寄与しているものであり、それが自らの生活と密接に結びついている」の内容を含む授業科目
B24: 授業科目 | F24: 単位数 | G24: 必須 | H24: 1-1 | I24: 1-6 | J24: 授業科目 | P24: 単位数 | Q24: 必須 | R24: 1-1 | S24: 1-6
B25: データサイエンス入門 | F25: 2 | G25: ○ | H25: ○ | I25: ○
B26: ICT入門 | F26: 2 | G26: ○ | H26: ○
A33: ⑤ 「社会で活用されているデータ」や「データの活用領域」は非常に広範囲であって、日常生活や社会の課題を解決する有用なツールになり得るもの」の内容を含む授業科目
B35: 授業科目 | F35: 単位数 | G35: 必須 | H35: 1-2 | I35: 1-3 | J35: 授業科目 | P35: 単位数 | Q35: 必須 | R35: 1-2 | S35: 1-3
B36: データサイエンス入門 | F36: 2 | G36: ○ | H36: ○ | I36: ○
B37: データリテラシ― | F37: 2 | H37: ○ | I37: ○
B38: ICT入門 | F38: 2 | G38: ○ | I38: ○
B39: データ科学のための数理統計 | F39: 2 | H39: ○ | I39: ○
A44: ⑥ 「様々なデータ利活用の現場におけるデータ利活用事例が示され、様々な適用領域（流通、製造、金融、サービス、インフラ、公共、ヘルスケア等）の知見と組み合わせることで価値を創出するもの」の内容を含む授業科目
B46: 授業科目 | F46: 単位数 | G46: 必須 | H46: 1-4 | I46: 1-5 | J46: 授業科目 | P46: 単位数 | Q46: 必須 | R46: 1-4 | S46: 1-5
B47: データサイエンス入門 | F47: 2 | G47: ○ | H47: ○ | I47: ○
B48: ICT入門 | F48: 2 | G48: ○ | I48: ○
A55: ⑦ 「活用に当たっての様々な留意事項（ELSI、個人情報、データ倫理、ＡＩ社会原則等）を考慮し、情報セキュリティや情報漏洩等、データを守る上での留意事項への理解をする」の内容を含む授業科目
B57: 授業科目 | F57: 単位数 | G57: 必須 | H57: 3-1 | I57: 3-2 | J57: 授業科目 | P57: 単位数 | Q57: 必須 | R57: 3-1 | S57: 3-2
B58: データサイエンス応用 | F58: 2 | H58: ○ | I58: ○ | J58: データ科学のための数理統計 | P58: 2 | R58: ○ | S58: ○
B59: 人工知能概論 | F59: 2 | H59: ○ | I59: ○
B60: 情報リテラシーA | F60: 1 | G60: ○ | H60: ○ | I60: ○
B61: プログラミング入門A | F61: 2 | H61: ○ | I61: ○
B62: プログラミング入門B | F62: 2 | H62: ○ | I62: ○
B63: データリテラシ― | F63: 2 | H63: ○ | I63: ○
B64: ICT入門 | F64: 2 | G64: ○ | H64: ○ | I64: ○
A66: ⑧ 「実データ・実課題（学術データ等を含む）を用いた演習など、社会での実例を題材として、「データを読む、説明する、扱う」といった数理・データサイエンス・ＡＩの基本的な活用法に関するもの」の内容を含む授業科目
B68: 授業科目 | E68: 単位数 | F68: 必須 | G68: 2-1 | H68: 2-2 | I68: 2-3 | J68: 授業科目 | O68: 単位数 | P68: 必須 | Q68: 2-1 | R68: 2-2 | S68: 2-3
B69: データサイエンス応用 | E69: 2 | G69: ○ | H69: ○ | I69: ○
B70: 人工知能概論 | E70: 2 | G70: ○ | H70: ○ | I70: ○
B71: 情報リテラシーB | E71: 1 | F71: ○ | G71: ○ | H71: ○ | I71: ○
...

Sheet 様式１ー２　プログラムを構成する授業科目
R1: 様式１-2 | T1: 「学部・学科によって、修了要件は相違する」場合は、本シートを複製の上＜様式１－〇＞と枝番号を付してください
B2: 大学等名 | C2: 福山平成大学
B3: プログラム名 | C3: 数理・データサイエンス・AI教育プログラム （リテラシーレベル）
A5: プログラムを構成する授業科目について
A7: ① 対象となる学部・学科名称 | J7: ② 教育プログラムの修了要件 | K7: 学部・学科によって、修了要件は相違する
B9: 福祉健康学部福祉学科 福祉健康学部こども学科 福祉健康学部健康スポーツ科学科
A12: ③ 修了要件
B13: 「数理・データサイエンス・AI教育プログラム（リテラシーレベル）」は、次の（１）及び（２）の要件を満たしていることを修了要件とする。なお、修了要件を満たした者を「数理・データサイエンス・AI教育プグラム（リテラシーレベル）」の修了者として大学が認定する。（１）一般教育科目である「データサイエンス入門」「情報リテラシーA」「情報リテラシーB」の単位及び福祉学科では学科専門科目である「社会福祉調査の基礎」、こども学科では学科専門科目である「ＩＣＴ活用の理論と実践」、健康スポーツ科学科では学科専門科目である「健康スポーツ情報処理演習」の単位を取得していること。（２）一般教育科目である「人工知能概論」、「データサイエンス応用」、「プログラミング入門A」、「プログラミング入門B」、「データ科学のための数理統計」、「データリテラシー」のうち、いずれか１科目の単位を取得していること。 | V13: 【プルダウンリスト】
V14: 令和４年度以前より、履修することが必須のプログラムとして実施
V15: 令和７年度までに履修必須とする計画
V16: 令和８年度以降に履修必須とする計画、又は未定
B20: 必要最低単位数 | C20: 8 | E20: 単位 | J20: 履修必須の有無 | K20: 令和４年度以前より、履修することが必須のプログラムとして実施
A22: ④ 現在進行中の社会変化（第４次産業革命、Society 5.0、データ駆動型社会等）に深く寄与しているものであり、それが自らの生活と密接に結びついている」の内容を含む授業科目
B24: 授業科目 | F24: 単位数 | G24: 必須 | H24: 1-1 | I24: 1-6 | J24: 授業科目 | P24: 単位数 | Q24: 必須 | R24: 1-1 | S24: 1-6
B25: データサイエンス入門 | F25: 2 | G25: ○ | H25: ○ | I25: ○
B26: ＩＣＴ活用の理論と実践 | F26: 2 | H26: ○ | I26: ○
A33: ⑤ 「社会で活用されているデータ」や「データの活用領域」は非常に広範囲であって、日常生活や社会の課題を解決する有用なツールになり得るもの」の内容を含む授業科目
B35: 授業科目 | F35: 単位数 | G35: 必須 | H35: 1-2 | I35: 1-3 | J35: 授業科目 | P35: 単位数 | Q35: 必須 | R35: 1-2 | S35: 1-3
B36: データサイエンス入門 | F36: 2 | G36: ○ | H36: ○ | I36: ○
B37: データリテラシ― | F37: 2 | H37: ○ | I37: ○
B38: データ科学のための数理統計 | F38: 2 | H38: ○ | I38: ○
A44: ⑥ 「様々なデータ利活用の現場におけるデータ利活用事例が示され、様々な適用領域（流通、製造、金融、サービス、インフラ、公共、ヘルスケア等）の知見と組み合わせることで価値を創出するもの」の内容を含む授業科目
B46: 授業科目 | F46: 単位数 | G46: 必須 | H46: 1-4 | I46: 1-5 | J46: 授業科目 | P46: 単位数 | Q46: 必須 | R46: 1-4 | S46: 1-5
B47: データサイエンス入門 | F47: 2 | G47: ○ | H47: ○ | I47: ○
B48: 社会福祉調査の基礎 | F48: 2 | H48: ○ | I48: ○
B49: ＩＣＴ活用の理論と実践 | F49: 2 | H49: ○ | I49: ○
A55: ⑦ 「活用に当たっての様々な留意事項（ELSI、個人情報、データ倫理、ＡＩ社会原則等）を考慮し、情報セキュリティや情報漏洩等、データを守る上での留意事項への理解をする」の内容を含む授業科目
B57: 授業科目 | F57: 単位数 | G57: 必須 | H57: 3-1 | I57: 3-2 | J57: 授業科目 | P57: 単位数 | Q57: 必須 | R57: 3-1 | S57: 3-2
B58: データサイエンス応用 | F58: 2 | H58: ○ | I58: ○ | J58: 社会福祉調査の基礎 | P58: 2 | R58: ○ | S58: ○
B59: 人工知能概論 | F59: 2 | H59: ○ | I59: ○ | J59: ＩＣＴ活用の理論と実践 | P59: 2 | R59: ○ | S59: ○
B60: 情報リテラシーA | F60: 1 | G60: ○ | H60: ○ | I60: ○
B61: プログラミング入門A | F61: 2 | H61: ○ | I61: ○
B62: プログラミング入門B | F62: 2 | H62: ○ | I62: ○
B63: データリテラシ― | F63: 2 | H63: ○ | I63: ○
B64: データ科学のための数理統計 | F64: 2 | H64: ○ | I64: ○
A66: ⑧ 「実データ・実課題（学術データ等を含む）を用いた演習など、社会での実例を題材として、「データを読む、説明する、扱う」といった数理・データサイエンス・ＡＩの基本的な活用法に関するもの」の内容を含む授業科目
B68: 授業科目 | E68: 単位数 | F68: 必須 | G68: 2-1 | H68: 2-2 | I68: 2-3 | J68: 授業科目 | O68: 単位数 | P68: 必須 | Q68: 2-1 | R68: 2-2 | S68: 2-3
B69: データサイエンス応用 | E69: 2 | G69: ○ | H69: ○ | I69: ○ | J69: 社会福祉調査の基礎 | O69: 2 | Q69: ○ | R69: ○ | S69: ○
B70: 人工知能概論 | E70: 2 | G70: ○ | H70: ○ | I70: ○ | J70: 健康スポーツ情報処理演習 | O70: 2 | Q70: ○ | R70: ○ | S70: ○
B71: 情報リテラシーB | E71: 1 | F71: ○ | G71: ○ | H71: ○ | I71: ○
...

Sheet 様式１ー３　プログラムを構成する授業科目
R1: 様式１-3 | T1: 「学部・学科によって、修了要件は相違する」場合は、本シートを複製の上＜様式１－〇＞と枝番号を付してください
B2: 大学等名 | C2: 福山平成大学
B3: プログラム名 | C3: 数理・データサイエンス・AI教育プログラム （リテラシーレベル）
A5: プログラムを構成する授業科目について
A7: ① 対象となる学部・学科名称 | J7: ② 教育プログラムの修了要件 | K7: 学部・学科によって、修了要件は相違する
B9: 看護学部看護学科
A12: ③ 修了要件
B13: 「数理・データサイエンス・AI教育プログラム（リテラシーレベル）」は、次の（１）及び（２）の要件を満たしていることを修了要件とする。なお、修了要件を満たした者を「数理・データサイエンス・AI教育プグラム（リテラシーレベル）」の修了者として大学が認定する。（１）一般教育科目である「データサイエンス入門」「情報リテラシーA」「情報リテラシーB」の単位及び学科専門科目である「保健統計論Ⅰ」と「保健統計論Ⅱ」の単位を取得していること。（２）一般教育科目である「人工知能概論」、「データサイエンス応用」、「プログラミング入門A」、「プログラミング入門B」、「データ科学のための数理統計」、「データリテラシー」のうち、いずれか１科目の単位を取得していること。 | V13: 【プルダウンリスト】
V14: 令和４年度以前より、履修することが必須のプログラムとして実施
V15: 令和７年度までに履修必須とする計画
V16: 令和８年度以降に履修必須とする計画、又は未定
B20: 必要最低単位数 | C20: 8 | E20: 単位 | J20: 履修必須の有無 | K20: 令和４年度以前より、履修することが必須のプログラムとして実施
A22: ④ 現在進行中の社会変化（第４次産業革命、Society 5.0、データ駆動型社会等）に深く寄与しているものであり、それが自らの生活と密接に結びついている」の内容を含む授業科目
B24: 授業科目 | F24: 単位数 | G24: 必須 | H24: 1-1 | I24: 1-6 | J24: 授業科目 | P24: 単位数 | Q24: 必須 | R24: 1-1 | S24: 1-6
B25: データサイエンス入門 | F25: 2 | G25: ○ | H25: ○ | I25: ○
B26: 保健統計論Ⅰ | F26: 1 | G26: ○ | H26: ○
A33: ⑤ 「社会で活用されているデータ」や「データの活用領域」は非常に広範囲であって、日常生活や社会の課題を解決する有用なツールになり得るもの」の内容を含む授業科目
B35: 授業科目 | F35: 単位数 | G35: 必須 | H35: 1-2 | I35: 1-3 | J35: 授業科目 | P35: 単位数 | Q35: 必須 | R35: 1-2 | S35: 1-3
B36: データサイエンス入門 | F36: 2 | G36: ○ | H36: ○ | I36: ○
B37: データリテラシ― | F37: 2 | H37: ○ | I37: ○
B38: データ科学のための数理統計 | F38: 2 | H38: ○ | I38: ○
B39: 保健統計論Ⅰ | F39: 1 | G39: ○ | H39: ○
A44: ⑥ 「様々なデータ利活用の現場におけるデータ利活用事例が示され、様々な適用領域（流通、製造、金融、サービス、インフラ、公共、ヘルスケア等）の知見と組み合わせることで価値を創出するもの」の内容を含む授業科目
B46: 授業科目 | F46: 単位数 | G46: 必須 | H46: 1-4 | I46: 1-5 | J46: 授業科目 | P46: 単位数 | Q46: 必須 | R46: 1-4 | S46: 1-5
B47: データサイエンス入門 | F47: 2 | G47: ○ | H47: ○ | I47: ○
A55: ⑦ 「活用に当たっての様々な留意事項（ELSI、個人情報、データ倫理、ＡＩ社会原則等）を考慮し、情報セキュリティや情報漏洩等、データを守る上での留意事項への理解をする」の内容を含む授業科目
B57: 授業科目 | F57: 単位数 | G57: 必須 | H57: 3-1 | I57: 3-2 | J57: 授業科目 | P57: 単位数 | Q57: 必須 | R57: 3-1 | S57: 3-2
B58: データサイエンス応用 | F58: 2 | H58: ○ | I58: ○
B59: 人工知能概論 | F59: 2 | H59: ○ | I59: ○
B60: 情報リテラシーA | F60: 1 | G60: ○ | H60: ○ | I60: ○
B61: プログラミング入門A | F61: 2 | H61: ○ | I61: ○
B62: プログラミング入門B | F62: 2 | H62: ○ | I62: ○
B63: データリテラシ― | F63: 2 | H63: ○ | I63: ○
B64: データ科学のための数理統計 | F64: 2 | H64: ○ | I64: ○
A66: ⑧ 「実データ・実課題（学術データ等を含む）を用いた演習など、社会での実例を題材として、「データを読む、説明する、扱う」といった数理・データサイエンス・ＡＩの基本的な活用法に関するもの」の内容を含む授業科目
B68: 授業科目 | E68: 単位数 | F68: 必須 | G68: 2-1 | H68: 2-2 | I68: 2-3 | J68: 授業科目 | O68: 単位数 | P68: 必須 | Q68: 2-1 | R68: 2-2 | S68: 2-3
B69: データサイエンス応用 | E69: 2 | G69: ○ | H69: ○ | I69: ○ | J69: 保健統計論Ⅰ | O69: 1 | P69: ○ | Q69: ○ | R69: ○ | S69: ○
B70: 人工知能概論 | E70: 2 | G70: ○ | H70: ○ | I70: ○ | J70: 保険統計論Ⅱ | O70: 1 | P70: ○ | Q70: ○ | R70: ○ | S70: ○
B71: 情報リテラシーB | E71: 1 | F71: ○ | G71: ○ | H71: ○ | I71: ○
B72: プログラミング入門A | E72: 2 | G72: ○ | H72: ○ | I72: ○
...

Sheet 様式２ 履修者等数の実績
AQ1: 様式２
AL2: 大学等名 | AM2: ='様式１ー１ プログラムを構成する授業科目'!C2 -> 福山平成大学
A3: プログラムの履修者数等の実績について
A5: ①プログラム開設年度 | C5: 令和４ | E5: 年度
A7: ②履修者・修了者の実績
B9: 学部・学科名称 | C9: 学生数 | D9: 入学 定員 | E9: 収容 定員 | F9: 令和4年度 | L9: 令和3年度 | R9: 令和2年度 | X9: 令和元年度 | AD9: 平成30年度 | AJ9: 平成29年度 | AP9: 履修者数 合計 | AQ9: 履修率
F10: 履修者数 | I10: 修了者数 | L10: 履修者数 | O10: 修了者数 | R10: 履修者数 | U10: 修了者数 | X10: 履修者数 | AA10: 修了者数 | AD10: 履修者数 | AG10: 修了者数 | AJ10: 履修者数 | AM10: 修了者数
F11: 合計 | G11: 男性 | H11: 女性 | I11: 合計 | J11: 男性 | K11: 女性 | L11: 合計 | M11: 男性 | N11: 女性 | O11: 合計 | P11: 男性 | Q11: 女性 | R11: 合計 | S11: 男性 | T11: 女性 | U11: 合計 | V11: 男性 | W11: 女性 | X11: 合計 | Y11: 男性 | Z11: 女性 | AA11: 合計 | AB11: 男性 | AC11: 女性 | AD11: 合計 | AE11: 男性 | AF11: 女性 | AG11: 合計 | AH11: 男性 | AI11: 女性 | AJ11: 合計 | AK11: 男性 | AL11: 女性 | AM11: 合計 | AN11: 男性 | AO11: 女性
B12: 経営学部 | C12: 179 | D12: 50 | E12: 200 | F12: =G12+H12 -> 36 | G12: 23 | H12: 13 | I12: =J12+K12 -> 0 | J12: 0 | K12: 0 | L12: =M12+N12 -> 0 | O12: =P12+Q12 -> 0 | R12: =S12+T12 -> 0 | U12: =V12+W12 -> 0 | X12: =Y12+Z12 -> 0 | AA12: =AB12+AC12 -> 0 | AD12: =AE12+AF12 -> 0 | AG12: =AH12+AI12 -> 0 | AJ12: =AK12+AL12 -> 0 | AM12: =AN12+AO12 -> 0 | AP12: =F12+L12+R12+X12+AD12+AJ12 -> 36 | AQ12: =AP12/E12 -> 0.18
B13: 福祉健康学部 | C13: 643 | D13: 210 | E13: 840 | F13: =G13+H13 -> 161 | G13: 92 | H13: 69 | I13: =J13+K13 -> 0 | J13: 0 | K13: 0 | L13: =M13+N13 -> 0 | O13: =P13+Q13 -> 0 | R13: =S13+T13 -> 0 | U13: =V13+W13 -> 0 | X13: =Y13+Z13 -> 0 | AA13: =AB13+AC13 -> 0 | AD13: =AE13+AF13 -> 0 | AG13: =AH13+AI13 -> 0 | AJ13: =AK13+AL13 -> 0 | AM13: =AN13+AO13 -> 0 | AP13: =F13+L13+R13+X13+AD13+AJ13 -> 161 | AQ13: =AP13/E13 -> 0.19166667
B14: 看護学部 | C14: 322 | D14: 80 | E14: 320 | F14: =G14+H14 -> 78 | G14: 9 | H14: 69 | I14: =J14+K14 -> 0 | J14: 0 | K14: 0 | L14: =M14+N14 -> 0 | O14: =P14+Q14 -> 0 | R14: =S14+T14 -> 0 | U14: =V14+W14 -> 0 | X14: =Y14+Z14 -> 0 | AA14: =AB14+AC14 -> 0 | AD14: =AE14+AF14 -> 0 | AG14: =AH14+AI14 -> 0 | AJ14: =AK14+AL14 -> 0 | AM14: =AN14+AO14 -> 0 | AP14: =F14+L14+R14+X14+AD14+AJ14 -> 78 | AQ14: =AP14/E14 -> 0.24375
F15: =G15+H15 -> 0 | I15: =J15+K15 -> 0 | L15: =M15+N15 -> 0 | O15: =P15+Q15 -> 0 | R15: =S15+T15 -> 0 | U15: =V15+W15 -> 0 | X15: =Y15+Z15 -> 0 | AA15: =AB15+AC15 -> 0 | AD15: =AE15+AF15 -> 0 | AG15: =AH15+AI15 -> 0 | AJ15: =AK15+AL15 -> 0 | AM15: =AN15+AO15 -> 0 | AP15: =F15+L15+R15+X15+AD15+AJ15 -> 0 | AQ15: =AP15/E15 -> #DIV/0!
F16: =G16+H16 -> 0 | I16: =J16+K16 -> 0 | L16: =M16+N16 -> 0 | O16: =P16+Q16 -> 0 | R16: =S16+T16 -> 0 | U16: =V16+W16 -> 0 | X16: =Y16+Z16 -> 0 | AA16: =AB16+AC16 -> 0 | AD16: =AE16+AF16 -> 0 | AG16: =AH16+AI16 -> 0 | AJ16: =AK16+AL16 -> 0 | AM16: =AN16+AO16 -> 0 | AP16: =F16+L16+R16+X16+AD16+AJ16 -> 0 | AQ16: =AP16/E16 -> #DIV/0!
F17: =G17+H17 -> 0 | I17: =J17+K17 -> 0 | L17: =M17+N17 -> 0 | O17: =P17+Q17 -> 0 | R17: =S17+T17 -> 0 | U17: =V17+W17 -> 0 | X17: =Y17+Z17 -> 0 | AA17: =AB17+AC17 -> 0 | AD17: =AE17+AF17 -> 0 | AG17: =AH17+AI17 -> 0 | AJ17: =AK17+AL17 -> 0 | AM17: =AN17+AO17 -> 0 | AP17: =F17+L17+R17+X17+AD17+AJ17 -> 0 | AQ17: =AP17/E17 -> #DIV/0!
F18: =G18+H18 -> 0 | I18: =J18+K18 -> 0 | L18: =M18+N18 -> 0 | O18: =P18+Q18 -> 0 | R18: =S18+T18 -> 0 | U18: =V18+W18 -> 0 | X18: =Y18+Z18 -> 0 | AA18: =AB18+AC18 -> 0 | AD18: =AE18+AF18 -> 0 | AG18: =AH18+AI18 -> 0 | AJ18: =AK18+AL18 -> 0 | AM18: =AN18+AO18 -> 0 | AP18: =F18+L18+R18+X18+AD18+AJ18 -> 0 | AQ18: =AP18/E18 -> #DIV/0!
F19: =G19+H19 -> 0 | I19: =J19+K19 -> 0 | L19: =M19+N19 -> 0 | O19: =P19+Q19 -> 0 | R19: =S19+T19 -> 0 | U19: =V19+W19 -> 0 | X19: =Y19+Z19 -> 0 | AA19: =AB19+AC19 -> 0 | AD19: =AE19+AF19 -> 0 | AG19: =AH19+AI19 -> 0 | AJ19: =AK19+AL19 -> 0 | AM19: =AN19+AO19 -> 0 | AP19: =F19+L19+R19+X19+AD19+AJ19 -> 0 | AQ19: =AP19/E19 -> #DIV/0!
F20: =G20+H20 -> 0 | I20: =J20+K20 -> 0 | L20: =M20+N20 -> 0 | O20: =P20+Q20 -> 0 | R20: =S20+T20 -> 0 | U20: =V20+W20 -> 0 | X20: =Y20+Z20 -> 0 | AA20: =AB20+AC20 -> 0 | AD20: =AE20+AF20 -> 0 | AG20: =AH20+AI20 -> 0 | AJ20: =AK20+AL20 -> 0 | AM20: =AN20+AO20 -> 0 | AP20: =F20+L20+R20+X20+AD20+AJ20 -> 0 | AQ20: =AP20/E20 -> #DIV/0!
F21: =G21+H21 -> 0 | I21: =J21+K21 -> 0 | L21: =M21+N21 -> 0 | O21: =P21+Q21 -> 0 | R21: =S21+T21 -> 0 | U21: =V21+W21 -> 0 | X21: =Y21+Z21 -> 0 | AA21: =AB21+AC21 -> 0 | AD21: =AE21+AF21 -> 0 | AG21: =AH21+AI21 -> 0 | AJ21: =AK21+AL21 -> 0 | AM21: =AN21+AO21 -> 0 | AP21: =F21+L21+R21+X21+AD21+AJ21 -> 0 | AQ21: =AP21/E21 -> #DIV/0!
F22: =G22+H22 -> 0 | I22: =J22+K22 -> 0 | L22: =M22+N22 -> 0 | O22: =P22+Q22 -> 0 | R22: =S22+T22 -> 0 | U22: =V22+W22 -> 0 | X22: =Y22+Z22 -> 0 | AA22: =AB22+AC22 -> 0 | AD22: =AE22+AF22 -> 0 | AG22: =AH22+AI22 -> 0 | AJ22: =AK22+AL22 -> 0 | AM22: =AN22+AO22 -> 0 | AP22: =F22+L22+R22+X22+AD22+AJ22 -> 0 | AQ22: =AP22/E22 -> #DIV/0!
F23: =G23+H23 -> 0 | I23: =J23+K23 -> 0 | L23: =M23+N23 -> 0 | O23: =P23+Q23 -> 0 | R23: =S23+T23 -> 0 | U23: =V23+W23 -> 0 | X23: =Y23+Z23 -> 0 | AA23: =AB23+AC23 -> 0 | AD23: =AE23+AF23 -> 0 | AG23: =AH23+AI23 -> 0 | AJ23: =AK23+AL23 -> 0 | AM23: =AN23+AO23 -> 0 | AP23: =F23+L23+R23+X23+AD23+AJ23 -> 0 | AQ23: =AP23/E23 -> #DIV/0!
F24: =G24+H24 -> 0 | I24: =J24+K24 -> 0 | L24: =M24+N24 -> 0 | O24: =P24+Q24 -> 0 | R24: =S24+T24 -> 0 | U24: =V24+W24 -> 0 | X24: =Y24+Z24 -> 0 | AA24: =AB24+AC24 -> 0 | AD24: =AE24+AF24 -> 0 | AG24: =AH24+AI24 -> 0 | AJ24: =AK24+AL24 -> 0 | AM24: =AN24+AO24 -> 0 | AP24: =F24+L24+R24+X24+AD24+AJ24 -> 0 | AQ24: =AP24/E24 -> #DIV/0!
F25: =G25+H25 -> 0 | I25: =J25+K25 -> 0 | L25: =M25+N25 -> 0 | O25: =P25+Q25 -> 0 | R25: =S25+T25 -> 0 | U25: =V25+W25 -> 0 | X25: =Y25+Z25 -> 0 | AA25: =AB25+AC25 -> 0 | AD25: =AE25+AF25 -> 0 | AG25: =AH25+AI25 -> 0 | AJ25: =AK25+AL25 -> 0 | AM25: =AN25+AO25 -> 0 | AP25: =F25+L25+R25+X25+AD25+AJ25 -> 0 | AQ25: =AP25/E25 -> #DIV/0!
F26: =G26+H26 -> 0 | I26: =J26+K26 -> 0 | L26: =M26+N26 -> 0 | O26: =P26+Q26 -> 0 | R26: =S26+T26 -> 0 | U26: =V26+W26 -> 0 | X26: =Y26+Z26 -> 0 | AA26: =AB26+AC26 -> 0 | AD26: =AE26+AF26 -> 0 | AG26: =AH26+AI26 -> 0 | AJ26: =AK26+AL26 -> 0 | AM26: =AN26+AO26 -> 0 | AP26: =F26+L26+R26+X26+AD26+AJ26 -> 0 | AQ26: =AP26/E26 -> #DIV/0!
... F31: =G31+H31 -> 0 | I31: =J31+K31 -> 0 | L31: =M31+N31 -> 0 | O31: =P31+Q31 -> 0 | R31: =S31+T31 -> 0 | U31: =V31+W31 -> 0 | X31: =Y31+Z31 -> 0 | AA31: =AB31+AC31 -> 0 | AD31: =AE31+AF31 -> 0 | AG31: =AH31+AI31 -> 0 | AJ31: =AK31+AL31 -> 0 | AM31: =AN31+AO31 -> 0 | AP31: =F31+L31+R31+X31+AD31+AJ31 -> 0 | AQ31: =AP31/E31 -> #DIV/0!
B32: 合 計 | C32: =SUM(C12:C31) -> 1144 | D32: =SUM(D12:D31) -> 340 | E32: =SUM(E12:E31) -> 1360 | F32: =SUM(F12:F31) -> 275 | G32: =SUM(G12:G31) -> 124 | H32: =SUM(H12:H31) -> 151 | I32: =SUM(I12:I31) -> 0 | J32: =SUM(J12:J31) -> 0 | ... AP32: =SUM(AP12:AP31) -> 275 | AQ32: =AP32/E32 -> 0.20220588

Sheet 様式３ 教育の質・履修者数を向上させるための体制・計画
I1: 様式３
G2: 大学等名 | H2: ='様式１ー１ プログラムを構成する授業科目'!C2 -> 福山平成大学
A4: 教育の質・履修者数を向上させるための体制・計画について
A6: ① | B6: 全学の教員数 | C6: (常勤） | E6: 84 | F6: 人 | G6: （非常勤） | H6: 79 | I6: 人
A8: ② | B8: プログラムの授業を教えている教員数 | H8: 8 | I8: 人
A10: ③ | B10: プログラムの運営責任者
B11: （責任者名） | C11: 川久保 和雄 | G11: （役職名） | H11: 大学教育センター長
A13: ④ | B13: プログラムを改善・進化させるための体制（委員会・組織等）
B14: 大学教育センター運営委員会、同センター数理・データサイエンス・AI教育部門
B16: （責任者名） | C16: 古賀 一博 | G16: （役職名） | H16: 運営委員会副委員長、数理・データサイエンス・AI教育部門長
A18: ⑤ | B18: プログラムを改善・進化させるための体制を定める規則名称
B19: 福山平成大学大学教育センター規則、数理・データサイエンス・AI教育部門運営細則
A21: ⑥ | B21: 体制の目的
B22: 大学教育センターは、福山平成大学教育システムおよび福山平成大学における共通教育に関する種々の業務を行う組織で、全学的な視点から大学教育に関する調査、 研究、 企画、 調整、 研修等を行うことにより大学全体の教育改革を主導している。その運営委員会は、本学の大学教育センターの運営全般の企画、審議を担う全学レベルの委員会であり、本学の 「数理・データサイエンス・AI教育プログラム」の改善・進化も担っている。また、大学教育センター内に数理・データサイエンス・AI教育部門が設置され、運営委員会の主導の下で同プログラムの改善・進化のための具体的な諸業務が遂行されている。
A34: ⑦ | B34: 具体的な構成員
B35: ○大学教育センター運営委員会 委員長(大学教育センター長) 川久保 和雄 運営委員 （運営委員会副委員長、大学教育センター数理・データサイエンス・AI教育部門長）古賀 一博 （大学教育センター初年次教育部門長・IR部門長）上村 崇 （大学教育センター学修支援部門長・情報基盤センター運営委員会委員長）佐藤 真司 （経営学部経営学科長）江口 圭一 （福祉健康学部福祉学科長）岡部 真智子 （福祉健康学部こども学科長）三藤 恭弘 （福祉健康学部スポーツ健康科学科長・学生委員長）石橋 勇 （看護学部看護学科長）岡 和子 （大学教育センター）尾崎 誠 （教務委員長）中原 大介
B45: （就職委員長）入澤 雅典 （事務局長・学務部長）吉留 義史 ○数理・データサイエンス・AI教育部門 部門長 古賀 一博 部門委員 （数理・データサイエンス・AI教育科目担当教員）川久保 和雄 （数理・データサイエンス・AI教育科目担当教員）青木 麟太郎 （数理・データサイエンス・AI教育科目担当教員）細川 光浩 （数理・データサイエンス・AI教育科目担当教員）福井 正康 （数理・データサイエンス・AI教育科目担当教員、経営学部経営学科）佐藤 真司 （数理・データサイエンス・AI教育科目担当教員）尾崎 誠 （教務委員長）中原 大介 （一般教育委員長）渡辺 清美 （福祉健康学部福祉学科）杉本 浩章 （福祉健康学部こども学科）田中 宏和 （福祉健康学部健康スポーツ科学科）河野 洋 （看護学部看護学科）平川 幹子 （事務局長・学務部長）吉留 義史 （教務課長）池本 大作
A48: ⑧ | B48: 履修者数・履修率の向上に向けた計画 ※様式１の「履修必須の有無」で「計画がある」としている場合は詳細について記載すること
B49: 令和４年度実績 | C49: ='様式２ 履修者等数の実績'!AQ32 -> 0.20220588 | E49: 令和５年度予定 | F49: 0.5 | H49: 令和６年度予定 | I49: 0.75
B50: 令和７年度予定 | C50: 1 | E50: 令和８年度予定 | F50: 1 | H50: 収容定員（名） | I50: ='様式２ 履修者等数の実績'!E32 -> 1360
B51: 具体的な計画
B52: 本プログラムの目標を達成するために、次の各事項を行っている。 １．本プログラムを構成する科目のうち「データサイエンス入門」「情報リテラシーA」「情報リテラシーB」を１年次の全学必修としている。また2年次以降についても選択必修として多数の発展的な応用科目を展開している。 ２．大学教育センターにおいて、全学生によるオンラインでの授業評価アンケートを実施し、授業担当教員による年２回の自己点検と学生へのフィードバック等により、教育の質向上を常に行っている。 ３．授業内容としては、１年次の「データサイエンス入門」「情報リテラシーA」「情報リテラシーB」を初学者であっても十分に内容を理解できるように設計している。 ４．令和４年度入学生より、本プログラムのカリキュラムを適用し、本プログラムを構成する教育内容の充実を図るとともに、２年次以降の学生に対しては本学における多様な学部の特性や資格免許への必要性等を鑑みたプログラム科目（専門教育科目）が準備されている。
A65: ⑨ | B65: 学部・学科に関係なく希望する学生全員が受講可能となるような必要な体制・取組等
B66: １．学部・学科に関係なく学生全員が受講可能なカリキュラムとなっている。 ２．令和４年度より大学教育センターに数理・データサイエンス・AI教育部門を新設し、運営委員会の主導の下で同部門が以下の具体的な業務を担っている。 １）学生全員の受講を前提としたカリキュラムならびにシラバスの点検と改善・充実を組織的・継続的に行っている。 ２）部門メンバーに全学部学科の教員が参画することにより、各学部学科の特性やニーズに応じつつも、全学生に共通の教育内容を検討し、その改善・進化を持続的に行っている。 ３．受講可能人数については、令和４年度からの入学者全員が本プログラムを履修する体制を整えている。100名を超えるような極端な大人数講義にならないよう、履修者を時間割ごとにクラス分けし、それに即した教室や担当教員の割り当てを行い、学生全員にプログラムで企図している教育水準を維持したカリキュラムを提供している。
A79: ⑩ | B79: できる限り多くの学生が履修できるような具体的な周知方法・取組
B80: １．本学のWEBサイトに専用のページを開設し、学生が情報を受け取りやすい環境を整備している。本プログラムのカリキュラム・ツリーを作成し、学生便覧上に掲載することにより、全学生が履修計画を立てやすいようにしている。本学は平成29年度から全入学者に通学におけるノートパソコン必携化を実施しているが、そのことと併せて、本学志願者に入学前からの本プログラムの学習準備を促している。 ２．本プログラムの修了証を発行する体制を整え、履修意欲の向上を図っている。 ３．学生に分かりやすいオンラインのシラバスを作成し、公開している。 ４．学生全員に迅速な通知ができるオンラインの掲示板システムを運用している。 ５．運営委員会において、全学科の学科長に本プログラムの内容を説明している。全学教授会等を通じて本プログラムの実施を説明し、教員間の相互理解を計り、教職員が学生に適切な履修指導を行えるようにしている。
A93: ⑪ | B93: できる限り多くの学生が履修・修得できるようなサポート体制
B94: １．学習の途中でICT機器の活用が必要となるが、学生がICT機器の活用について相談できる教職員常駐の情報基盤センターを常設している。それによりICT機器の活用を促進し、全学生が不安なく学修できるように支援できる体制を構築している。また、SA制度を活用して、初学者へ個別丁寧な履修支援を行なっている。 ２．教育の下支えとなる ICT機器・設備としては、平成29年度より全入学者にノートパソコンの必携化を実施しており、BYODの学習環境を達成していると共に、学内に余すところなく張り巡らされたWi-Fi環境を通じて、学生はいつでも持参したノートパソコン等をLMSや学内外のネットワークにアクセスできるようになっている。 ３．本学では、LMSを運用し、全学生がいつでも授業資料を閲覧できる環境を構築している。 ４．LMSと連動したオンデマンドのビデオ教材を積極的に作成し運用している。
A107: ⑫ | B107: 授業時間内外で学習指導、質問を受け付ける具体的な仕組み
B108: １．授業時間内外での学習指導や質問の受け付け等、学生の学修サポートを常設された情報基盤センターをはじめとする担当教職員が行っており、学内のLMSや授業内容に関する学習支援、履修支援を行っている。 ２．授業の履修は、全科目でLMSによっても管理されている。授業についての質問や相談は、授業時間外であっても、LMS上で行うことが可能である。LMS上でのコミュニケーションについては授業担当教員が行う他に、教員と学生間の情報共有やオンラインでのディスカッション等にも利用している。 ３．全学的に実施している授業評価アンケート調査についても、学生の質問や意見を受け付け、全ての教員からフィードバックを行う体制を整備している。

Sheet 様式４　自己点検・評価
I1: 様式４
H2: 大学等名 | I2: ='様式１ー１ プログラムを構成する授業科目'!C2 -> 福山平成大学
A3: 自己点検・評価について
A5: ① | B5: プログラムの自己点検・評価を行う体制（委員会・組織等）
B6: 大学教育センター運営委員会、同センター数理・データサイエンス・AI教育部門
D8: （責任者名） | E8: 古賀 一博 | G8: （役職名） | H8: 運営委員会副委員長、数理・データサイエンス・AI教育部門長
A10: ② | B10: 自己点検・評価体制における意見等
B11: 自己点検・評価の視点 | E11: 自己点検・評価体制における意見・結果・改善に向けた取組等
B12: 学内からの視点
C13: プログラムの履修・修得状況 | E13: 令和4年度の点検・評価の対象科目ごとの履修者数、修了者数、収容定員に対する履修率は次の通りである。 1. 情報リテラシーA（収容定員1360名）：【履修者数】275名 【修了者数】273名 【履修率】20％ 2. 情報リテラシーB（収容定員 同上）：【履修者数】275名 【修了者数】272名 【履修率】20％ 3. データサイエンス入門（収容定員 同上）：【履修者数】275名 【修了者数】271名 【履修率】20％ 4. ICT入門（収容定員200名）：【履修者数】36名 【修了者数】36名 【履修率】18％ 履修率に関しては大学収容定員を分母としており、プログラム開講から2年目となる令和5年度にはさらに上昇する見込みである。
C14: 学修成果 | E14: 開講1年目であるため、本学数理・データサイエンス・AI教育プログラムの最終的かつ総括的な学修成果は、現時点ではまだ確定しておらず、直接的には評価されていない。しかしながら、令和４年度段階の同プログラムにおいては、高い学生満足度が確認されると共に（下記学生授業評価アンケートによる）、令和4年度開設科目における修了者率は上記のように極めて高い。したがって、一定の学修成果が上がっているものと推認される。
C15: 学生アンケート等を通じた学生の内容の理解度 | E15: 本学FD推進委員会では授業評価アンケートを実施し、その結果を基に学生の学習動機や学修成果を把握し、FD活動に活用している。 令和4年度の授業評価アンケートでは、以下の項目について、「よくあてはまる」から「全くあてはまらない」までの5段階で回答を得た。 1. 学習到達目標や注意事項などの説明・指導の適切性 2. 教員の説明・指導のわかりやすさ 3. 授業の有意義さ 本プログラム科目に関する結果は、全科目でいずれの項目についても「よくあてはまる」「ややあてはまる」の合計が70％を上回った。よって、開設全科目で数理・データサイエンス・AI教育に関する適切な講義が実施され、学生の内容の理解度も高いことがわかる。
C16: 学生アンケート等を通じた後輩等他の学生への推奨度 | E16: 本学の数理・データサイエンス・AI教育プログラムに関して、履修者が他の学生にプログラムへの参加を推奨するようなことがあったかについては、それを立証する直接的なデータはなく、現時点では明らかでない。しかし、先述の授業評価アンケートの結果は、先輩学生がこれから履修をする学生や履修を検討している後輩学生に対して、当該プログラムへの参加を推奨する可能性を示唆するデータとしては、十分に活用し得るものであり、令和5年度以降の学生履修指導においても有効に活用したい。
C17: 全学的な履修者数、履修率向上に向けた計画の達成・進捗状況 | E17: 本学の数理・データサイエンス・AI教育プログラムに関しては、履修状況のデータから令和４年度（1年目）の取り組みは順調に行われていると言える。また、授業評価アンケートの結果から、1年目に実施された4つの科目の評価は概ね好評であり、本学での教育プログラムは「学生目線」からも順調に実施されていると判断できる。 さらに、本プログラムに関わっては、令和5年度より新たに一般教育科目で6科目が開講されるほか、経営学科を除く4学科においても学科専門科目が開講される。令和４年度から先行実施された4つの科目の結果を踏まえつつ、令和5年度以降、本プログラム全体の円滑で効果的な実施に鋭意取り組みたい。
B18: 学外からの視点
C19: 教育プログラム修了者の進路、活躍状況、企業等の評価 | E19: 本教育プログラムは令和４年度より開始され、まだ修了者が出ていないため、修了者の進路、活躍状況、企業等での評価を得るまでには至っていない。しかし、毎年、就職課および就職委員会において、全学生の就職・進路状況調査を実施しており、本プログラムを修了した卒業生の進路先、活躍状況の把握は可能である。今後はこれらの就職・進路状況調査を活用し、本プログラム修了者の進路や活躍状況、企業等の評価の分析に役立てたい。
C20: 産業界からの視点を含めた教育プログラム内容・手法等への意見 | E20: 本プログラムを統括する大学教育センターは、自己点検評価、学外の産業界有識者による点検、第三者評価を受審する体制をとっている。また、同センター内の数理・データサイエンス・AI教育部門では、当該分野の実務経験豊かな教員を部門メンバーとして参画させることにより、産業界からの視点に配慮した意見集約を可能としている。また、本プログラムを大学 WEB ページで周知することにより、企業等への幅広い認知を促進し、産業界からの視点を含めた意見を集約する体制を整えている。今後も、本プログラムの内容及び手法について幅広い意見を収集し、社会や時代にあったプログラムの改善を持続的に展開したい。
B21: 数理・データサイエンス・ＡＩを「学ぶ楽しさ」「学ぶことの意義」を理解させること | E21: ３学部５学科ある本学では、すべての学部・学科の学生が初年次の科目を履修した段階で、数理・データサイエンス・AI教育プログラム（リテラシーレベル）で学ぶべき内容・要素のすべてを一旦は網羅できるようになっている。更に、２年次以降では学部・学科の特性に合わせた内容の深化が図られ、専門分野での技術の活用についての具体例や手法等、学生の興味・関心に応じた内容を学ぶことができるようなプログラムになっている。授業後には、学生の満足度に関するアンケートを実施し授業評価を行っており、高い評価を得ている。
B22: 内容・水準を維持・向上しつつ、より「分かりやすい」授業とすること | E22: 令和４年度から本プログラムに関する内容を全学必修化し、教育内容の充実を図っている。ICTやデータサイエンス等の基礎はもとより、各学科の専門性に応じた基礎を、演習をしながら学ぶことができる内容としている。また、パソコンに不慣れな初年次はICT教室を活用し、基本操作の演習を行い、円滑に開始できるよう工夫している。加えて、SA制度を積極的に活用し、学生一人ひとりに寄り添ったきめ細かい履修支援を行なっている。さらに、授業後には学生による授業評価アンケートを実施し、結果に対して授業担当者がフィードバックを行い、より「分かりやすい」授業体制を整えている。
