Workbook

Sheet 様式１-1　プログラムを構成する授業科目
R1: 様式１-1 | T1: 「学部・学科によって、修了要件は相違する」場合は、本シートを複製の上＜様式１－〇＞と枝番号を付してください
B2: 大学等名 | C2: 立命館大学
B3: プログラム名 | C3: データサイエンス+Rプログラム（基礎）
A5: プログラムを構成する授業科目について
A7: ① 対象となる学部・学科名称 | J7: ② 教育プログラムの修了要件 | K7: 学部・学科によって、修了要件は相違する
B9: 法学部/産業社会学部/文学部/映像学部/経済学部/理工学部/生命科学部/薬学部/スポーツ健康科学部/食マネジメント学部/経営学部/政策科学部/総合心理学部
A12: ③ 修了要件
B13: プログラムを構成する科目のうち「情報技術と社会」を単位取得すること（令和4年度以降受講者対象） | V13: 【プルダウンリスト】
V14: 令和４年度以前より、履修することが必須のプログラムとして実施
V15: 令和７年度までに履修必須とする計画
V16: 令和８年度以降に履修必須とする計画、又は未定
B20: 必要最低単位数 | C20: 2 | E20: 単位 | J20: 履修必須の有無 | K20: 令和８年度以降に履修必須とする計画、又は未定
A22: ④ 現在進行中の社会変化（第４次産業革命、Society 5.0、データ駆動型社会等）に深く寄与しているものであり、それが自らの生活と密接に結びついている」の内容を含む授業科目
B24: 授業科目 | F24: 単位数 | G24: 必須 | H24: 1-1 | I24: 1-6 | J24: 授業科目 | P24: 単位数 | Q24: 必須 | R24: 1-1 | S24: 1-6
B25: 情報技術と社会 | F25: 2 | G25: ○ | H25: ○ | I25: ○
A33: ⑤ 「社会で活用されているデータ」や「データの活用領域」は非常に広範囲であって、日常生活や社会の課題を解決する有用なツールになり得るもの」の内容を含む授業科目
B35: 授業科目 | F35: 単位数 | G35: 必須 | H35: 1-2 | I35: 1-3 | J35: 授業科目 | P35: 単位数 | Q35: 必須 | R35: 1-2 | S35: 1-3
B36: 情報技術と社会 | F36: 2 | G36: ○ | H36: ○ | I36: ○
A44: ⑥ 「様々なデータ利活用の現場におけるデータ利活用事例が示され、様々な適用領域（流通、製造、金融、サービス、インフラ、公共、ヘルスケア等）の知見と組み合わせることで価値を創出するもの」の内容を含む授業科目
B46: 授業科目 | F46: 単位数 | G46: 必須 | H46: 1-4 | I46: 1-5 | J46: 授業科目 | P46: 単位数 | Q46: 必須 | R46: 1-4 | S46: 1-5
B47: 情報技術と社会 | F47: 2 | G47: ○ | H47: ○ | I47: ○
A55: ⑦ 「活用に当たっての様々な留意事項（ELSI、個人情報、データ倫理、ＡＩ社会原則等）を考慮し、情報セキュリティや情報漏洩等、データを守る上での留意事項への理解をする」の内容を含む授業科目
B57: 授業科目 | F57: 単位数 | G57: 必須 | H57: 3-1 | I57: 3-2 | J57: 授業科目 | P57: 単位数 | Q57: 必須 | R57: 3-1 | S57: 3-2
B58: 情報技術と社会 | F58: 2 | G58: ○ | H58: ○ | I58: ○
A66: ⑧ 「実データ・実課題（学術データ等を含む）を用いた演習など、社会での実例を題材として、「データを読む、説明する、扱う」といった数理・データサイエンス・ＡＩの基本的な活用法に関するもの」の内容を含む授業科目
B68: 授業科目 | E68: 単位数 | F68: 必須 | G68: 2-1 | H68: 2-2 | I68: 2-3 | J68: 授業科目 | O68: 単位数 | P68: 必須 | Q68: 2-1 | R68: 2-2 | S68: 2-3
B69: 情報技術と社会 | E69: 2 | F69: ○ | G69: ○ | H69: ○ | I69: ○
A77: ⑨ 選択「４．オプション」の内容を含む授業科目
B78: 授業科目 | F78: 選択項目 | J78: 授業科目 | P78: 選択項目
A87: ⑩ プログラムを構成する授業の内容
B88: 授業に含まれている内容・要素 | D88: 講義内容
B89: （１）現在進行中の社会変化（第４次産業革命、Society 5.0、データ駆動型社会等）に深く寄与しているものであり、それが自らの生活と密接に結びついている | C89: 1-1 | D89: ・第4次産業革命、Society5.0、データ駆動型社会「情報技術と社会」（第1,2,3回） ・ビッグデータ、IoT、AI、ロボット「情報技術と社会」（第5,7,8,12回）
C90: 1-6 | D90: ・AI等を活用した新しいビジネスモデル（シェアリングエコノミー、商品のレコメンデーションなど）「情報技術と社会」（第5,6,12回）
B91: （２）「社会で活用されているデータ」や「データの活用領域」は非常に広範囲であって、日常生活や社会の課題を解決する有用なツールになり得るもの | C91: 1-2 | D91: ・調査データ、実験データ、人の行動ログデータ、機械の稼働ログデータなど「情報技術と社会」（第12回） ・1次データ、2次データ、データのメタ化「情報技術と社会」（第12回）
C92: 1-3 | D92: ・データ・AI活用領域の広がり（生産、消費、文化活動など）「情報技術と社会」（第4,5,6回） ・研究開発、調達、製造、物流、販売、マーケティング、サービスなど「情報技術と社会」（第4,5,6,13回）
B93: （３）様々なデータ利活用の現場におけるデータ利活用事例が示され、様々な適用領域（流通、製造、金融、サービス、インフラ、公共、ヘルスケア等）の知見と組み合わせることで価値を創出するもの | C93: 1-4 | D93: ・特化型AIと汎用AI、今のAIに出来ることと出来ないこと、AIとビッグデータ「情報技術と社会」（第8,12回） ・データ解析：予測、グルーピング、パターン発見、最適化、シミュレーション、データ同化など「情報技術と社会」（第13回）
C94: 1-5 | D94: ・流通、製造、金融、サービス、インフラ、公共、ヘルスケア等におけるデータ・AI利活用事例紹介「情報技術と社会」（第4,6,12回）
B95: （４）活用に当たっての様々な留意事項（ELSI、個人情報、データ倫理、ＡＩ社会原則等）を考慮し、情報セキュリティや情報漏洩等、データを守る上での留意事項への理解をする | C95: 3-1 | D95: ・ELSI（Ethical,Legal and Social Issues）「情報技術と社会」（第9,11回） ・個人情報保護、EU一般データ保護規則（GDPR）、忘れられる権利、オプトアウト「情報技術と社会」（第9,11回） ・データ倫理：データの捏造、改ざん、盗用、プライバシー保護「情報技術と社会」（第9,11回）
C96: 3-2 | D96: ・情報セキュリティ：機密性、完全性、可用性「情報技術と社会」（第10回） ・匿名加工情報、暗号化、パスワード、悪意ある情報搾取「情報技術と社会」（第9,10回）
B97: （５）実データ・実課題（学術データ等を含む）を用いた演習など、社会での実例を題材として、「データを読む、説明する、扱う」といった数理・データサイエンス・ＡＩの基本的な活用法に関するもの | C97: 2-1 | D97: ・データの分布（ヒストグラム）と代表値（平均値、中央値、最頻値）「情報技術と社会」（第14回） ・代表値の性質の違い（実社会では平均値＝最頻値でないことが多い）「情報技術と社会」（第14回） ・データのばらつき（分散、標準偏差、偏差値）「情報技術と社会」（第14回） ・相関と因果（相関係数、疑似相関、交絡）「情報技術と社会」（第14回） ・統計情報の正しい理解（誇張表現に惑わされない）「情報技術と社会」（第14回）
...

Sheet 様式１-2　プログラムを構成する授業科目
R1: 様式１-2 | T1: 「学部・学科によって、修了要件は相違する」場合は、本シートを複製の上＜様式１－〇＞と枝番号を付してください
B2: 大学等名 | C2: 立命館大学
B3: プログラム名 | C3: データサイエンス+Rプログラム（基礎）
A5: プログラムを構成する授業科目について
A7: ① 対象となる学部・学科名称 | J7: ② 教育プログラムの修了要件 | K7: 学部・学科によって、修了要件は相違する
B9: 情報理工学部（情報理工学科 システムアーキテクトコース/セキュリティ・ネットワークコース/先端社会デザインコース/実世界情報コース/画像・音メディアコース/知能情報コース・情報システムグローバルコース）
A12: ③ 修了要件
B13: 【対象：情報理工学科 システムアーキテクトコース/セキュリティ・ネットワークコース/先端社会デザインコース/実世界情報コース/画像・音メディアコース/知能情報コース】 プログラムを構成する科目のうち「情報倫理と情報技術」1科目2単位を単位取得すること（令和4年度以降受講者対象） 【対象：情報理工学科 情報システムグローバルコース】 プログラムを構成する科目のうち「Introduction to Experimentation」及び「Professional Ethics」2科目4単位を単位取得すること（令和4年度以降受講者対象） | V13: 【プルダウンリスト】
V14: 令和４年度以前より、履修することが必須のプログラムとして実施
V15: 令和７年度までに履修必須とする計画
V16: 令和８年度以降に履修必須とする計画、又は未定
B20: 必要最低単位数 | C20: 2 | E20: 単位 | J20: 履修必須の有無 | K20: 令和８年度以降に履修必須とする計画、又は未定
A22: ④ 現在進行中の社会変化（第４次産業革命、Society 5.0、データ駆動型社会等）に深く寄与しているものであり、それが自らの生活と密接に結びついている」の内容を含む授業科目
B24: 授業科目 | F24: 単位数 | G24: 必須 | H24: 1-1 | I24: 1-6 | J24: 授業科目 | P24: 単位数 | Q24: 必須 | R24: 1-1 | S24: 1-6
B25: 情報倫理と情報技術 | F25: 2 | H25: ○ | I25: ○
B26: Introduction to Experimentation | F26: 2 | I26: ○
B27: Professional Ethics | F27: 2 | H27: ○
A33: ⑤ 「社会で活用されているデータ」や「データの活用領域」は非常に広範囲であって、日常生活や社会の課題を解決する有用なツールになり得るもの」の内容を含む授業科目
B35: 授業科目 | F35: 単位数 | G35: 必須 | H35: 1-2 | I35: 1-3 | J35: 授業科目 | P35: 単位数 | Q35: 必須 | R35: 1-2 | S35: 1-3
B36: 情報倫理と情報技術 | F36: 2 | H36: ○ | I36: ○
B37: Introduction to Experimentation | F37: 2 | H37: ○ | I37: ○
A44: ⑥ 「様々なデータ利活用の現場におけるデータ利活用事例が示され、様々な適用領域（流通、製造、金融、サービス、インフラ、公共、ヘルスケア等）の知見と組み合わせることで価値を創出するもの」の内容を含む授業科目
B46: 授業科目 | F46: 単位数 | G46: 必須 | H46: 1-4 | I46: 1-5 | J46: 授業科目 | P46: 単位数 | Q46: 必須 | R46: 1-4 | S46: 1-5
B47: 情報倫理と情報技術 | F47: 2 | H47: ○ | I47: ○
B48: Introduction to Experimentation | F48: 2 | H48: ○ | I48: ○
A55: ⑦ 「活用に当たっての様々な留意事項（ELSI、個人情報、データ倫理、ＡＩ社会原則等）を考慮し、情報セキュリティや情報漏洩等、データを守る上での留意事項への理解をする」の内容を含む授業科目
B57: 授業科目 | F57: 単位数 | G57: 必須 | H57: 3-1 | I57: 3-2 | J57: 授業科目 | P57: 単位数 | Q57: 必須 | R57: 3-1 | S57: 3-2
B58: 情報倫理と情報技術 | F58: 2 | H58: ○ | I58: ○
B59: Professional Ethics | F59: 2 | H59: ○ | I59: ○
A66: ⑧ 「実データ・実課題（学術データ等を含む）を用いた演習など、社会での実例を題材として、「データを読む、説明する、扱う」といった数理・データサイエンス・ＡＩの基本的な活用法に関するもの」の内容を含む授業科目
B68: 授業科目 | E68: 単位数 | F68: 必須 | G68: 2-1 | H68: 2-2 | I68: 2-3 | J68: 授業科目 | O68: 単位数 | P68: 必須 | Q68: 2-1 | R68: 2-2 | S68: 2-3
B69: 情報倫理と情報技術 | E69: 2 | G69: ○ | H69: ○ | I69: ○
B70: Introduction to Experimentation | E70: 2 | G70: ○ | H70: ○ | I70: ○
A77: ⑨ 選択「４．オプション」の内容を含む授業科目
B78: 授業科目 | F78: 選択項目 | J78: 授業科目 | P78: 選択項目
A87: ⑩ プログラムを構成する授業の内容
B88: 授業に含まれている内容・要素 | D88: 講義内容
B89: （１）現在進行中の社会変化（第４次産業革命、Society 5.0、データ駆動型社会等）に深く寄与しているものであり、それが自らの生活と密接に結びついている | C89: 1-1 | D89: ・ビッグデータ、IoT、AI、ロボット「情報倫理と情報技術」（第2,5回[K1]/第4,10回[K2]/第2,6回[K3]）「Professional Ethics」（第1回） ・複数技術を組み合わせたAIサービス「情報倫理と情報技術」（第7回[K1]/第3回[K2]/第4回[K3]) ・第4次産業革命、Society5.0、データ駆動型社会「Professional Ethics」（第1回）
C90: 1-6 | D90: ・AI等を活用した新しいビジネスモデル（シェアリングエコノミー、商品のレコメンデーションなど）「情報倫理と情報技術」（第7回[K1]/第3回[K2]/第4回[K3]） ・AI最新技術の活用例（深層作成モデル、敵対的生成ネットワーク、強化学習、転移学習など）「情報倫理と情報技術」（第7,8回[K1]/第3,7回[K2]/第4,5回[K3]）「Introduction to Experimentation」（第15回）
B91: （２）「社会で活用されているデータ」や「データの活用領域」は非常に広範囲であって、日常生活や社会の課題を解決する有用なツールになり得るもの | C91: 1-2 | D91: ・調査データ、実験データ、人の行動ログデータ、機械の稼働ログデータなど「情報倫理と情報技術」（第1,4回[K1]/第1,6回[K2]/第1,8回[K3]）「Introduction to Experimentation」（第4回） ・構造化データ、非構造化データ（文章、画像/動画、音声/音楽など）「情報倫理と情報技術」（第6回[K1]/第2回[K2]/第3回[K3]） ・1次データ、2次データ、データのメタ化「Introduction to Experimentation」（第4回）
...

Sheet 様式１-3　プログラムを構成する授業科目
R1: 様式１-3 | T1: 「学部・学科によって、修了要件は相違する」場合は、本シートを複製の上＜様式１－〇＞と枝番号を付してください
B2: 大学等名 | C2: 立命館大学
B3: プログラム名 | C3: データサイエンス+Rプログラム（基礎）
A5: プログラムを構成する授業科目について
A7: ① 対象となる学部・学科名称 | J7: ② 教育プログラムの修了要件 | K7: 学部・学科によって、修了要件は相違する
B9: 国際関係学部（国際関係学科/アメリカン大学・立命館大学国際連携学科）
A12: ③ 修了要件
B13: 【対象：国際関係学科】 プログラムを構成する科目のうち「情報技術と社会」または「IR18-AE114 Data Literacy for Research Design」のいずれか1科目2単位を単位取得すること（令和4年度以降受講者対象） 【対象：アメリカン大学・立命館大学国際連携学科】 プログラムを構成する科目のうち「IR18-AE114 Data Literacy for Research Design」1科目2単位を単位取得すること（令和4年度以降受講者対象） | V13: 【プルダウンリスト】
V14: 令和４年度以前より、履修することが必須のプログラムとして実施
V15: 令和７年度までに履修必須とする計画
V16: 令和８年度以降に履修必須とする計画、又は未定
B20: 必要最低単位数 | C20: 2 | E20: 単位 | J20: 履修必須の有無 | K20: 令和８年度以降に履修必須とする計画、又は未定
A22: ④ 現在進行中の社会変化（第４次産業革命、Society 5.0、データ駆動型社会等）に深く寄与しているものであり、それが自らの生活と密接に結びついている」の内容を含む授業科目
B24: 授業科目 | F24: 単位数 | G24: 必須 | H24: 1-1 | I24: 1-6 | J24: 授業科目 | P24: 単位数 | Q24: 必須 | R24: 1-1 | S24: 1-6
B25: IR18-AE114 Data Literacy for Research Design | F25: 2 | H25: ○ | I25: ○
B26: 情報技術と社会 | F26: 2 | H26: ○ | I26: ○
A33: ⑤ 「社会で活用されているデータ」や「データの活用領域」は非常に広範囲であって、日常生活や社会の課題を解決する有用なツールになり得るもの」の内容を含む授業科目
B35: 授業科目 | F35: 単位数 | G35: 必須 | H35: 1-2 | I35: 1-3 | J35: 授業科目 | P35: 単位数 | Q35: 必須 | R35: 1-2 | S35: 1-3
B36: IR18-AE114 Data Literacy for Research Design | F36: 2 | H36: ○ | I36: ○
B37: 情報技術と社会 | F37: 2 | H37: ○ | I37: ○
A44: ⑥ 「様々なデータ利活用の現場におけるデータ利活用事例が示され、様々な適用領域（流通、製造、金融、サービス、インフラ、公共、ヘルスケア等）の知見と組み合わせることで価値を創出するもの」の内容を含む授業科目
B46: 授業科目 | F46: 単位数 | G46: 必須 | H46: 1-4 | I46: 1-5 | J46: 授業科目 | P46: 単位数 | Q46: 必須 | R46: 1-4 | S46: 1-5
B47: IR18-AE114 Data Literacy for Research Design | F47: 2 | H47: ○ | I47: ○
B48: 情報技術と社会 | F48: 2 | H48: ○ | I48: ○
A55: ⑦ 「活用に当たっての様々な留意事項（ELSI、個人情報、データ倫理、ＡＩ社会原則等）を考慮し、情報セキュリティや情報漏洩等、データを守る上での留意事項への理解をする」の内容を含む授業科目
B57: 授業科目 | F57: 単位数 | G57: 必須 | H57: 3-1 | I57: 3-2 | J57: 授業科目 | P57: 単位数 | Q57: 必須 | R57: 3-1 | S57: 3-2
B58: IR18-AE114 Data Literacy for Research Design | F58: 2 | H58: ○ | I58: ○
B59: 情報技術と社会 | F59: 2 | H59: ○ | I59: ○
A66: ⑧ 「実データ・実課題（学術データ等を含む）を用いた演習など、社会での実例を題材として、「データを読む、説明する、扱う」といった数理・データサイエンス・ＡＩの基本的な活用法に関するもの」の内容を含む授業科目
B68: 授業科目 | E68: 単位数 | F68: 必須 | G68: 2-1 | H68: 2-2 | I68: 2-3 | J68: 授業科目 | O68: 単位数 | P68: 必須 | Q68: 2-1 | R68: 2-2 | S68: 2-3
B69: IR18-AE114 Data Literacy for Research Design | E69: 2 | G69: ○ | H69: ○ | I69: ○
B70: 情報技術と社会 | E70: 2 | G70: ○ | H70: ○ | I70: ○
A77: ⑨ 選択「４．オプション」の内容を含む授業科目
B78: 授業科目 | F78: 選択項目 | J78: 授業科目 | P78: 選択項目
B79: IR18-AE114 Data Literacy for Research Design | F79: 4-1統計および数理基礎
B80: IR18-AE114 Data Literacy for Research Design | F80: 4‐7データハンドリング
B81: IR18-AE114 Data Literacy for Research Design | F81: 4‐8データ活用実践（教師あり学習）
B82: IR18-AE114 Data Literacy for Research Design | F82: 4‐9データ活用実践（教師なし学習）
A87: ⑩ プログラムを構成する授業の内容
B88: 授業に含まれている内容・要素 | D88: 講義内容
...

Sheet 様式１-4　プログラムを構成する授業科目
R1: 様式１-4 | T1: 「学部・学科によって、修了要件は相違する」場合は、本シートを複製の上＜様式１－〇＞と枝番号を付してください
B2: 大学等名 | C2: 立命館大学
B3: プログラム名 | C3: データサイエンス+Rプログラム（基礎）
A5: プログラムを構成する授業科目について
A7: ① 対象となる学部・学科名称 | J7: ② 教育プログラムの修了要件 | K7: 学部・学科によって、修了要件は相違する
B9: グローバル教養学部（グローバル教養学科）
A12: ③ 修了要件
B13: プログラムを構成する科目のうち「Algorithm and Programming」及び「Social Change with AI」2科目8単位を単位取得すること（令和4年度以降受講者対象） | V13: 【プルダウンリスト】
V14: 令和４年度以前より、履修することが必須のプログラムとして実施
V15: 令和７年度までに履修必須とする計画
V16: 令和８年度以降に履修必須とする計画、又は未定
B20: 必要最低単位数 | C20: 8 | E20: 単位 | J20: 履修必須の有無 | K20: 令和８年度以降に履修必須とする計画、又は未定
A22: ④ 現在進行中の社会変化（第４次産業革命、Society 5.0、データ駆動型社会等）に深く寄与しているものであり、それが自らの生活と密接に結びついている」の内容を含む授業科目
B24: 授業科目 | F24: 単位数 | G24: 必須 | H24: 1-1 | I24: 1-6 | J24: 授業科目 | P24: 単位数 | Q24: 必須 | R24: 1-1 | S24: 1-6
B25: Social Change with AI | F25: 4 | G25: ○ | H25: ○ | I25: ○
A33: ⑤ 「社会で活用されているデータ」や「データの活用領域」は非常に広範囲であって、日常生活や社会の課題を解決する有用なツールになり得るもの」の内容を含む授業科目
B35: 授業科目 | F35: 単位数 | G35: 必須 | H35: 1-2 | I35: 1-3 | J35: 授業科目 | P35: 単位数 | Q35: 必須 | R35: 1-2 | S35: 1-3
B36: Social Change with AI | F36: 4 | G36: ○ | H36: ○ | I36: ○
A44: ⑥ 「様々なデータ利活用の現場におけるデータ利活用事例が示され、様々な適用領域（流通、製造、金融、サービス、インフラ、公共、ヘルスケア等）の知見と組み合わせることで価値を創出するもの」の内容を含む授業科目
B46: 授業科目 | F46: 単位数 | G46: 必須 | H46: 1-4 | I46: 1-5 | J46: 授業科目 | P46: 単位数 | Q46: 必須 | R46: 1-4 | S46: 1-5
B47: Social Change with AI | F47: 4 | G47: ○ | H47: ○ | I47: ○
A55: ⑦ 「活用に当たっての様々な留意事項（ELSI、個人情報、データ倫理、ＡＩ社会原則等）を考慮し、情報セキュリティや情報漏洩等、データを守る上での留意事項への理解をする」の内容を含む授業科目
B57: 授業科目 | F57: 単位数 | G57: 必須 | H57: 3-1 | I57: 3-2 | J57: 授業科目 | P57: 単位数 | Q57: 必須 | R57: 3-1 | S57: 3-2
B58: Social Change with AI | F58: 4 | G58: ○ | H58: ○ | I58: ○
A66: ⑧ 「実データ・実課題（学術データ等を含む）を用いた演習など、社会での実例を題材として、「データを読む、説明する、扱う」といった数理・データサイエンス・ＡＩの基本的な活用法に関するもの」の内容を含む授業科目
B68: 授業科目 | E68: 単位数 | F68: 必須 | G68: 2-1 | H68: 2-2 | I68: 2-3 | J68: 授業科目 | O68: 単位数 | P68: 必須 | Q68: 2-1 | R68: 2-2 | S68: 2-3
B69: Algorithm and Programming | E69: 4 | F69: ○ | G69: ○ | H69: ○ | I69: ○
B70: Social Change with AI | E70: 4 | F70: ○ | G70: ○ | H70: ○
A77: ⑨ 選択「４．オプション」の内容を含む授業科目
B78: 授業科目 | F78: 選択項目 | J78: 授業科目 | P78: 選択項目
B79: Algorithm and Programming | F79: 4‐2アルゴリズム基礎
B80: Algorithm and Programming | F80: 4‐3データ構造とプログラミング基礎
B81: Algorithm and Programming | F81: 4‐6画像解析
B82: Algorithm and Programming | F82: 4‐7データハンドリング
A87: ⑩ プログラムを構成する授業の内容
B88: 授業に含まれている内容・要素 | D88: 講義内容
B89: （１）現在進行中の社会変化（第４次産業革命、Society 5.0、データ駆動型社会等）に深く寄与しているものであり、それが自らの生活と密接に結びついている | C89: 1-1 | D89: ・ビッグデータ、IoT、AI、ロボット「Social Change with AI」（第1,2,3,4回） ・複数技術を組み合わせたAIサービス「Social Change with AI」（第2,3,4回） ・人間の知的活動とAIの関係性「Social Change with AI」（第2,3,4回）
C90: 1-6 | D90: ・AI等を活用した新しいビジネスモデル（シェアリングエコノミー、商品のレコメンデーションなど）「Social Change with AI」（第9,10,12,14回） ・AI最新技術の活用例（深層生成モデル、敵対的生成ネットワーク、強化学習、転移学習など）「Social Change with AI」（第9,10,12,14回）
B91: （２）「社会で活用されているデータ」や「データの活用領域」は非常に広範囲であって、日常生活や社会の課題を解決する有用なツールになり得るもの | C91: 1-2 | D91: ・調査データ、実験データ、人の行動ログデータ、機械の稼働ログデータなど「Social Change with AI」（第3,4,13回）
C92: 1-3 | D92: ・データ・AI活用領域の広がり（生産、消費、文化活動など）「Social Change with AI」（第9,10,13回） ・研究開発、調達、製造、物流、販売、マーケティング、サービスなど「Social Change with AI」（第9,10,13回） ・仮説検証、知識発見、原因究明、計画策定、判断支援、活動代替、新規生成など「Social Change with AI」（第9,10,13回）
...

Sheet 様式２ 履修者等数の実績
AQ1: 様式２
AL2: 大学等名 | AM2: ='様式１-1 プログラムを構成する授業科目'!C2 -> 立命館大学
A3: プログラムの履修者数等の実績について
A5: ①プログラム開設年度 | C5: 令和4 | E5: 年度
A7: ②履修者・修了者の実績
B9: 学部・学科名称 | C9: 学生数 | D9: 入学 定員 | E9: 収容 定員 | F9: 令和4年度 | L9: 令和3年度 | R9: 令和2年度 | X9: 令和元年度 | AD9: 平成30年度 | AJ9: 平成29年度 | AP9: 履修者数 合計 | AQ9: 履修率
F10: 履修者数 | I10: 修了者数 | L10: 履修者数 | O10: 修了者数 | R10: 履修者数 | U10: 修了者数 | X10: 履修者数 | AA10: 修了者数 | AD10: 履修者数 | AG10: 修了者数 | AJ10: 履修者数 | AM10: 修了者数
F11: 合計 | G11: 男性 | H11: 女性 | I11: 合計 | J11: 男性 | K11: 女性 | L11: 合計 | M11: 男性 | N11: 女性 | O11: 合計 | P11: 男性 | Q11: 女性 | R11: 合計 | S11: 男性 | T11: 女性 | U11: 合計 | V11: 男性 | W11: 女性 | X11: 合計 | Y11: 男性 | Z11: 女性 | AA11: 合計 | AB11: 男性 | AC11: 女性 | AD11: 合計 | AE11: 男性 | AF11: 女性 | AG11: 合計 | AH11: 男性 | AI11: 女性 | AJ11: 合計 | AK11: 男性 | AL11: 女性 | AM11: 合計 | AN11: 男性 | AO11: 女性
B12: 法学部 | C12: 3139 | D12: 720 | E12: 2880 | F12: =G12+H12 -> 77 | G12: 52 | H12: 25 | I12: =J12+K12 -> 64 | J12: 41 | K12: 23 | L12: =M12+N12 -> 0 | M12: 0 | N12: 0 | O12: =P12+Q12 -> 0 | P12: 0 | Q12: 0 | R12: =S12+T12 -> 0 | S12: 0 | T12: 0 | U12: =V12+W12 -> 0 | V12: 0 | W12: 0 | X12: =Y12+Z12 -> 0 | Y12: 0 | Z12: 0 | AA12: =AB12+AC12 -> 0 | AB12: 0 | AC12: 0 | AD12: =AE12+AF12 -> 0 | AE12: 0 | AF12: 0 | AG12: =AH12+AI12 -> 0 | AH12: 0 | AI12: 0 | AJ12: =AK12+AL12 -> 0 | AK12: 0 | AL12: 0 | AM12: =AN12+AO12 -> 0 | AN12: 0 | AO12: 0 | AP12: =F12+L12+R12+X12+AD12+AJ12 -> 77 | AQ12: =AP12/E12 -> 0.026736111
B13: 産業社会学部 | C13: 3316 | D13: 810 | E13: 3240 | F13: =G13+H13 -> 197 | G13: 134 | H13: 63 | I13: =J13+K13 -> 168 | J13: 112 | K13: 56 | L13: =M13+N13 -> 0 | M13: 0 | N13: 0 | O13: =P13+Q13 -> 0 | P13: 0 | Q13: 0 | R13: =S13+T13 -> 0 | S13: 0 | T13: 0 | U13: =V13+W13 -> 0 | V13: 0 | W13: 0 | X13: =Y13+Z13 -> 0 | Y13: 0 | Z13: 0 | AA13: =AB13+AC13 -> 0 | AB13: 0 | AC13: 0 | AD13: =AE13+AF13 -> 0 | AE13: 0 | AF13: 0 | AG13: =AH13+AI13 -> 0 | AH13: 0 | AI13: 0 | AJ13: =AK13+AL13 -> 0 | AK13: 0 | AL13: 0 | AM13: =AN13+AO13 -> 0 | AN13: 0 | AO13: 0 | AP13: =F13+L13+R13+X13+AD13+AJ13 -> 197 | AQ13: =AP13/E13 -> 0.060802469
B14: 国際関係学部 | C14: 1454 | D14: 360 | E14: 1440 | F14: =G14+H14 -> 49 | G14: 19 | H14: 30 | I14: =J14+K14 -> 44 | J14: 15 | K14: 29 | L14: =M14+N14 -> 0 | M14: 0 | N14: 0 | O14: =P14+Q14 -> 0 | P14: 0 | Q14: 0 | R14: =S14+T14 -> 0 | S14: 0 | T14: 0 | U14: =V14+W14 -> 0 | V14: 0 | W14: 0 | X14: =Y14+Z14 -> 0 | Y14: 0 | Z14: 0 | AA14: =AB14+AC14 -> 0 | AB14: 0 | AC14: 0 | AD14: =AE14+AF14 -> 0 | AE14: 0 | AF14: 0 | AG14: =AH14+AI14 -> 0 | AH14: 0 | AI14: 0 | AJ14: =AK14+AL14 -> 0 | AK14: 0 | AL14: 0 | AM14: =AN14+AO14 -> 0 | AN14: 0 | AO14: 0 | AP14: =F14+L14+R14+X14+AD14+AJ14 -> 49 | AQ14: =AP14/E14 -> 0.034027778
B15: 文学部 | C15: 4354 | D15: 1035 | E15: 4085 | F15: =G15+H15 -> 81 | G15: 52 | H15: 29 | I15: =J15+K15 -> 62 | J15: 39 | K15: 23 | L15: =M15+N15 -> 0 | M15: 0 | N15: 0 | O15: =P15+Q15 -> 0 | P15: 0 | Q15: 0 | R15: =S15+T15 -> 0 | S15: 0 | T15: 0 | U15: =V15+W15 -> 0 | V15: 0 | W15: 0 | X15: =Y15+Z15 -> 0 | Y15: 0 | Z15: 0 | AA15: =AB15+AC15 -> 0 | AB15: 0 | AC15: 0 | AD15: =AE15+AF15 -> 0 | AE15: 0 | AF15: 0 | AG15: =AH15+AI15 -> 0 | AH15: 0 | AI15: 0 | AJ15: =AK15+AL15 -> 0 | AK15: 0 | AL15: 0 | AM15: =AN15+AO15 -> 0 | AN15: 0 | AO15: 0 | AP15: =F15+L15+R15+X15+AD15+AJ15 -> 81 | AQ15: =AP15/E15 -> 0.019828641
B16: 映像学部 | C16: 685 | D16: 160 | E16: 640 | F16: =G16+H16 -> 5 | G16: 3 | H16: 2 | I16: =J16+K16 -> 2 | J16: 0 | K16: 2 | L16: =M16+N16 -> 0 | M16: 0 | N16: 0 | O16: =P16+Q16 -> 0 | P16: 0 | Q16: 0 | R16: =S16+T16 -> 0 | S16: 0 | T16: 0 | U16: =V16+W16 -> 0 | V16: 0 | W16: 0 | X16: =Y16+Z16 -> 0 | Y16: 0 | Z16: 0 | AA16: =AB16+AC16 -> 0 | AB16: 0 | AC16: 0 | AD16: =AE16+AF16 -> 0 | AE16: 0 | AF16: 0 | AG16: =AH16+AI16 -> 0 | AH16: 0 | AI16: 0 | AJ16: =AK16+AL16 -> 0 | AK16: 0 | AL16: 0 | AM16: =AN16+AO16 -> 0 | AN16: 0 | AO16: 0 | AP16: =F16+L16+R16+X16+AD16+AJ16 -> 5 | AQ16: =AP16/E16 -> 0.0078125
B17: 経済学部 | C17: 3242 | D17: 760 | E17: 3040 | F17: =G17+H17 -> 69 | G17: 60 | H17: 9 | I17: =J17+K17 -> 54 | J17: 46 | K17: 8 | L17: =M17+N17 -> 0 | M17: 0 | N17: 0 | O17: =P17+Q17 -> 0 | P17: 0 | Q17: 0 | R17: =S17+T17 -> 0 | S17: 0 | T17: 0 | U17: =V17+W17 -> 0 | V17: 0 | W17: 0 | X17: =Y17+Z17 -> 0 | Y17: 0 | Z17: 0 | AA17: =AB17+AC17 -> 0 | AB17: 0 | AC17: 0 | AD17: =AE17+AF17 -> 0 | AE17: 0 | AF17: 0 | AG17: =AH17+AI17 -> 0 | AH17: 0 | AI17: 0 | AJ17: =AK17+AL17 -> 0 | AK17: 0 | AL17: 0 | AM17: =AN17+AO17 -> 0 | AN17: 0 | AO17: 0 | AP17: =F17+L17+R17+X17+AD17+AJ17 -> 69 | AQ17: =AP17/E17 -> 0.022697368
B18: 理工学部 | C18: 4071 | D18: 959 | E18: 3928 | F18: =G18+H18 -> 258 | G18: 238 | H18: 20 | I18: =J18+K18 -> 222 | J18: 206 | K18: 16 | L18: =M18+N18 -> 0 | M18: 0 | N18: 0 | O18: =P18+Q18 -> 0 | P18: 0 | Q18: 0 | R18: =S18+T18 -> 0 | S18: 0 | T18: 0 | U18: =V18+W18 -> 0 | V18: 0 | W18: 0 | X18: =Y18+Z18 -> 0 | Y18: 0 | Z18: 0 | AA18: =AB18+AC18 -> 0 | AB18: 0 | AC18: 0 | AD18: =AE18+AF18 -> 0 | AE18: 0 | AF18: 0 | AG18: =AH18+AI18 -> 0 | AH18: 0 | AI18: 0 | AJ18: =AK18+AL18 -> 0 | AK18: 0 | AL18: 0 | AM18: =AN18+AO18 -> 0 | AN18: 0 | AO18: 0 | AP18: =F18+L18+R18+X18+AD18+AJ18 -> 258 | AQ18: =AP18/E18 -> 0.065682281
B19: 情報理工学部 | C19: 2019 | D19: 475 | E19: 1980 | F19: =G19+H19 -> 557 | G19: 471 | H19: 86 | I19: =J19+K19 -> 452 | J19: 383 | K19: 69 | L19: =M19+N19 -> 0 | M19: 0 | N19: 0 | O19: =P19+Q19 -> 0 | P19: 0 | Q19: 0 | R19: =S19+T19 -> 0 | S19: 0 | T19: 0 | U19: =V19+W19 -> 0 | V19: 0 | W19: 0 | X19: =Y19+Z19 -> 0 | Y19: 0 | Z19: 0 | AA19: =AB19+AC19 -> 0 | AB19: 0 | AC19: 0 | AD19: =AE19+AF19 -> 0 | AE19: 0 | AF19: 0 | AG19: =AH19+AI19 -> 0 | AH19: 0 | AI19: 0 | AJ19: =AK19+AL19 -> 0 | AK19: 0 | AL19: 0 | AM19: =AN19+AO19 -> 0 | AN19: 0 | AO19: 0 | AP19: =F19+L19+R19+X19+AD19+AJ19 -> 557 | AQ19: =AP19/E19 -> 0.28131313
B20: 生命科学部 | C20: 1277 | D20: 325 | E20: 1300 | F20: =G20+H20 -> 23 | G20: 19 | H20: 4 | I20: =J20+K20 -> 21 | J20: 17 | K20: 4 | L20: =M20+N20 -> 0 | M20: 0 | N20: 0 | O20: =P20+Q20 -> 0 | P20: 0 | Q20: 0 | R20: =S20+T20 -> 0 | S20: 0 | T20: 0 | U20: =V20+W20 -> 0 | V20: 0 | W20: 0 | X20: =Y20+Z20 -> 0 | Y20: 0 | Z20: 0 | AA20: =AB20+AC20 -> 0 | AB20: 0 | AC20: 0 | AD20: =AE20+AF20 -> 0 | AE20: 0 | AF20: 0 | AG20: =AH20+AI20 -> 0 | AH20: 0 | AI20: 0 | AJ20: =AK20+AL20 -> 0 | AK20: 0 | AL20: 0 | AM20: =AN20+AO20 -> 0 | AN20: 0 | AO20: 0 | AP20: =F20+L20+R20+X20+AD20+AJ20 -> 23 | AQ20: =AP20/E20 -> 0.017692308
B21: 薬学部 | C21: 816 | D21: 160 | E21: 840 | F21: =G21+H21 -> 0 | G21: 0 | H21: 0 | I21: =J21+K21 -> 0 | J21: 0 | K21: 0 | L21: =M21+N21 -> 0 | M21: 0 | N21: 0 | O21: =P21+Q21 -> 0 | P21: 0 | Q21: 0 | R21: =S21+T21 -> 0 | S21: 0 | T21: 0 | U21: =V21+W21 -> 0 | V21: 0 | W21: 0 | X21: =Y21+Z21 -> 0 | Y21: 0 | Z21: 0 | AA21: =AB21+AC21 -> 0 | AB21: 0 | AC21: 0 | AD21: =AE21+AF21 -> 0 | AE21: 0 | AF21: 0 | AG21: =AH21+AI21 -> 0 | AH21: 0 | AI21: 0 | AJ21: =AK21+AL21 -> 0 | AK21: 0 | AL21: 0 | AM21: =AN21+AO21 -> 0 | AN21: 0 | AO21: 0 | AP21: =F21+L21+R21+X21+AD21+AJ21 -> 0 | AQ21: =AP21/E21 -> 0
B22: スポーツ健康科学部 | C22: 1030 | D22: 235 | E22: 940 | F22: =G22+H22 -> 17 | G22: 12 | H22: 5 | I22: =J22+K22 -> 13 | J22: 9 | K22: 4 | L22: =M22+N22 -> 0 | M22: 0 | N22: 0 | O22: =P22+Q22 -> 0 | P22: 0 | Q22: 0 | R22: =S22+T22 -> 0 | S22: 0 | T22: 0 | U22: =V22+W22 -> 0 | V22: 0 | W22: 0 | X22: =Y22+Z22 -> 0 | Y22: 0 | Z22: 0 | AA22: =AB22+AC22 -> 0 | AB22: 0 | AC22: 0 | AD22: =AE22+AF22 -> 0 | AE22: 0 | AF22: 0 | AG22: =AH22+AI22 -> 0 | AH22: 0 | AI22: 0 | AJ22: =AK22+AL22 -> 0 | AK22: 0 | AL22: 0 | AM22: =AN22+AO22 -> 0 | AN22: 0 | AO22: 0 | AP22: =F22+L22+R22+X22+AD22+AJ22 -> 17 | AQ22: =AP22/E22 -> 0.018085106
B23: 食マネジメント学部 | C23: 1261 | D23: 320 | E23: 1280 | F23: =G23+H23 -> 12 | G23: 8 | H23: 4 | I23: =J23+K23 -> 10 | J23: 6 | K23: 4 | L23: =M23+N23 -> 0 | M23: 0 | N23: 0 | O23: =P23+Q23 -> 0 | P23: 0 | Q23: 0 | R23: =S23+T23 -> 0 | S23: 0 | T23: 0 | U23: =V23+W23 -> 0 | V23: 0 | W23: 0 | X23: =Y23+Z23 -> 0 | Y23: 0 | Z23: 0 | AA23: =AB23+AC23 -> 0 | AB23: 0 | AC23: 0 | AD23: =AE23+AF23 -> 0 | AE23: 0 | AF23: 0 | AG23: =AH23+AI23 -> 0 | AH23: 0 | AI23: 0 | AJ23: =AK23+AL23 -> 0 | AK23: 0 | AL23: 0 | AM23: =AN23+AO23 -> 0 | AN23: 0 | AO23: 0 | AP23: =F23+L23+R23+X23+AD23+AJ23 -> 12 | AQ23: =AP23/E23 -> 0.009375
... B27: グローバル教養学部 | C27: 278 | D27: 100 | E27: 400 | F27: =G27+H27 -> 69 | G27: 37 | H27: 32 | I27: =J27+K27 -> 1 | J27: 0 | K27: 1 | L27: =M27+N27 -> 0 | M27: 0 | N27: 0 | O27: =P27+Q27 -> 0 | P27: 0 | Q27: 0 | R27: =S27+T27 -> 0 | S27: 0 | T27: 0 | U27: =V27+W27 -> 0 | V27: 0 | W27: 0 | X27: =Y27+Z27 -> 0 | Y27: 0 | Z27: 0 | AA27: =AB27+AC27 -> 0 | AB27: 0 | AC27: 0 | AD27: =AE27+AF27 -> 0 | AE27: 0 | AF27: 0 | AG27: =AH27+AI27 -> 0 | AH27: 0 | AI27: 0 | AJ27: =AK27+AL27 -> 0 | AK27: 0 | AL27: 0 | AM27: =AN27+AO27 -> 0 | AN27: 0 | AO27: 0 | AP27: =F27+L27+R27+X27+AD27+AJ27 -> 69 | AQ27: =AP27/E27 -> 0.1725
F28: =G28+H28 -> 0 | I28: =J28+K28 -> 0 | L28: =M28+N28 -> 0 | O28: =P28+Q28 -> 0 | R28: =S28+T28 -> 0 | U28: =V28+W28 -> 0 | X28: =Y28+Z28 -> 0 | AA28: =AB28+AC28 -> 0 | AD28: =AE28+AF28 -> 0 | AG28: =AH28+AI28 -> 0 | AJ28: =AK28+AL28 -> 0 | AM28: =AN28+AO28 -> 0 | AP28: =F28+L28+R28+X28+AD28+AJ28 -> 0 | AQ28: =AP28/E28 -> #DIV/0!
F29: =G29+H29 -> 0 | I29: =J29+K29 -> 0 | L29: =M29+N29 -> 0 | O29: =P29+Q29 -> 0 | R29: =S29+T29 -> 0 | U29: =V29+W29 -> 0 | X29: =Y29+Z29 -> 0 | AA29: =AB29+AC29 -> 0 | AD29: =AE29+AF29 -> 0 | AG29: =AH29+AI29 -> 0 | AJ29: =AK29+AL29 -> 0 | AM29: =AN29+AO29 -> 0 | AP29: =F29+L29+R29+X29+AD29+AJ29 -> 0 | AQ29: =AP29/E29 -> #DIV/0!
F30: =G30+H30 -> 0 | I30: =J30+K30 -> 0 | L30: =M30+N30 -> 0 | O30: =P30+Q30 -> 0 | R30: =S30+T30 -> 0 | U30: =V30+W30 -> 0 | X30: =Y30+Z30 -> 0 | AA30: =AB30+AC30 -> 0 | AD30: =AE30+AF30 -> 0 | AG30: =AH30+AI30 -> 0 | AJ30: =AK30+AL30 -> 0 | AM30: =AN30+AO30 -> 0 | AP30: =F30+L30+R30+X30+AD30+AJ30 -> 0 | AQ30: =AP30/E30 -> #DIV/0!
F31: =G31+H31 -> 0 | I31: =J31+K31 -> 0 | L31: =M31+N31 -> 0 | O31: =P31+Q31 -> 0 | R31: =S31+T31 -> 0 | U31: =V31+W31 -> 0 | X31: =Y31+Z31 -> 0 | AA31: =AB31+AC31 -> 0 | AD31: =AE31+AF31 -> 0 | AG31: =AH31+AI31 -> 0 | AJ31: =AK31+AL31 -> 0 | AM31: =AN31+AO31 -> 0 | AP31: =F31+L31+R31+X31+AD31+AJ31 -> 0 | AQ31: =AP31/E31 -> #DIV/0!
B32: 合 計 | C32: =SUM(C12:C31) -> 33094 | D32: =SUM(D12:D31) -> 7904 | E32: =SUM(E12:E31) -> 31933 | F32: =SUM(F12:F31) -> 1713 | G32: =SUM(G12:G31) -> 1320 | H32: =SUM(H12:H31) -> 393 | I32: =SUM(I12:I31) -> 1371 | J32: =SUM(J12:J31) -> 1057 | ... AP32: =SUM(AP12:AP31) -> 1713 | AQ32: =AP32/E32 -> 0.053643566

Sheet 様式３ 教育の質・履修者数を向上させるための体制・計画
I1: 様式３
G2: 大学等名 | H2: ='様式１-1 プログラムを構成する授業科目'!C2 -> 立命館大学
A4: 教育の質・履修者数を向上させるための体制・計画について
A6: ① | B6: 全学の教員数 | C6: (常勤） | E6: 1395 | F6: 人 | G6: （非常勤） | H6: 1405 | I6: 人
A8: ② | B8: プログラムの授業を教えている教員数 | H8: 17 | I8: 人
A10: ③ | B10: プログラムの運営責任者
B11: （責任者名） | C11: 中本 大 | G11: （役職名） | H11: 教学部長
A13: ④ | B13: プログラムを改善・進化させるための体制（委員会・組織等）
B14: 教学委員会
B16: （責任者名） | C16: 中本 大 | G16: （役職名） | H16: 教学部長
A18: ⑤ | B18: プログラムを改善・進化させるための体制を定める規則名称
B19: 立命館大学教学委員会規程
A21: ⑥ | B21: 体制の目的
B22: 全16学部を擁する本学において数理・データサイエンス・AI教育を全ての学生へ提供することを目的としたデータサイエンス+Rプログラム（基礎）は教養科目と既存の学部独自科目を構成科目として展開しており、全学において一体化されたプログラム展開を行うために、「学部と研究科に共通する教学および教務事項」を審議事項とする教学委員会において、教育の質および履修者数向上に向けた取り組みなどを審議する。
A34: ⑦ | B34: 具体的な構成員
B35: ・教学部長 ・教学部副部長 ・教職教育センター長 ・教養教育センター長 ・言語教育センター長 ・教育・学修支援センター長 ・独立研究科副研究科長 ・国際部長 ・法学部副学部長 ・産業社会学部副学部長 ・国際関係学部副部長 ・文学部副学部長 ・映像学部副学部長 ・経済学部副学部長 ・理工学部副学部長 ・情報理工学部副学部長 ・生命科学部副学部長 ・薬学部副学部長 ・スポーツ健康科学部副学部長 ・食マネジメント学部副学部長 ・経営学部副学部長 ・政策科学部副学部長 ・総合心理学部副学部長 ・グローバル教養学部副学部長 ・教学部事務部長 ・教学部次長 ・学部または研究科の事務を掌る事務長および課長
A48: ⑧ | B48: 履修者数・履修率の向上に向けた計画 ※様式１の「履修必須の有無」で「計画がある」としている場合は詳細について記載すること
B49: 令和４年度実績 | C49: ='様式２ 履修者等数の実績'!AQ32 -> 0.053643566 | E49: 令和５年度予定 | F49: 0.1 | H49: 令和６年度予定 | I49: 0.16
B50: 令和７年度予定 | C50: 0.212 | E50: 令和８年度予定 | F50: 0.21 | H50: 収容定員（名） | I50: ='様式２ 履修者等数の実績'!E32 -> 31933
B51: 具体的な計画
B52: 履修者の増加に向け、令和5年度において、時間割調整を行い、学修要覧、ホームページでの広報を充実させるとともに、「データサイエンス+Rプログラム」の基礎と応用基礎の両方の修了要件を満たした学生に対してオープンバッチを授与することとしており、これら学習意欲向上に資する施策を通じ、履修者の拡大に努める。 令和6年度においては、「データサイエンス+Rプログラム（基礎）」の構成科目である教養科目の「情報技術と社会」を2クラス（秋学期：衣笠1クラス、OIC1クラス）増加させることによって履修者の拡大を目指す。
A65: ⑨ | B65: 学部・学科に関係なく希望する学生全員が受講可能となるような必要な体制・取組等
B66: 本学は文理全16の学部を擁しており、学部の専門性や数理・データサイエンス・AIに関するこれまでの学習履歴も様々である。本学においては、全学部一律の科目を設置する形ではなく、学部において特色ある教学の基に開講されている既存科目においても、モデルカリキュラムに記された内容に則した科目についてプログラム科目として位置づけ、学生全員が受講可能となる体制・取り組みとしている。
A79: ⑩ | B79: できる限り多くの学生が履修できるような具体的な周知方法・取組
B80: 各学部において配布される「学修要覧」へ記載し、全学生に対し、プログラムおよび修得の必要性について周知を行っている。また、本教育プログラムに関するホームページを公開し、数理・データサイエンス・AIに関する知識・技能を修得することの重要性および今後の社会における必要性について説明し、本学学生が自身の専門に関わらず広く受講および修得することが可能な教育プログラムとなっている点について周知を広く行っている。
A93: ⑪ | B93: できる限り多くの学生が履修・修得できるようなサポート体制
B94: 複数のキャンパスに跨って学部が存在する本学においては、キャンパス間移動を伴って受講することが困難なため、各キャンパスにおいて複数クラス開講するまたは、複数クラス開講が困難な場合においては、必修科目との重複などが生じない曜日時限に配置するなど、学生の受講機会の確保に注力し、多くの学生が履修できる環境の整備を行っている。 また、学習段階において適宜課題等を設定し、学生の理解度や進捗の把握を行うことにより、多くの学生が修得できるような体制を構築している。 加えて、各年度科目担当者間において情報共有を行うことにより、履修・修得できる環境の改善を行っている。
A107: ⑫ | B107: 授業時間内外で学習指導、質問を受け付ける具体的な仕組み
B108: 本学のLMSであるmanaba+Rを通じ、課題管理（出題、採点、フィードバック）を担当教員が逐次把握および対応するとともに、個別質疑応答が可能なフォームを設けることにより、学生および担当教員が任意のタイミングで学習指導および質問を受け付ける体制を構築している。また、授業内および終了後を利用して直接質問を受け付ける時間を確保している。

Sheet 様式４　自己点検・評価
I1: 様式４
H2: 大学等名 | I2: ='様式１-1 プログラムを構成する授業科目'!C2 -> 立命館大学
A3: 自己点検・評価について
A5: ① | B5: プログラムの自己点検・評価を行う体制（委員会・組織等）
B6: 教学委員会
D8: （責任者名） | E8: 中本 大 | G8: （役職名） | H8: 教学部長
A10: ② | B10: 自己点検・評価体制における意見等
B11: 自己点検・評価の視点 | E11: 自己点検・評価体制における意見・結果・改善に向けた取組等
B12: 学内からの視点
C13: プログラムの履修・修得状況 | E13: 履修率について5.4％と、目標にしていた8％には至らなかった。 次年度の履修目標を10％と定めており、数値目標達成のため、以下の取り組みを行う。 1.データサイエンス+Rプログラム履修促進のため、各学部学修要覧への組み込みならびにHPの改修を行い、プログラムの魅力を発信する。 2.学生の受講選択は配置曜日時限に大きく影響を受けるため、学生が受講選択しやすいよう時間割配置の工夫を行い、学生の受講機会の創出を図る。 3.令和6年度において13学部を対象とする「情報技術と社会」の開講クラス数を2クラス増とし、履修機会の拡充を図る。
C14: 学修成果 | E14: 本学では、全授業科目について履修学生を対象として授業内容の全容を把握して回答できる第13・14週において授業アンケートを実施しており、授業外学習時間や学習態度、理解度についてクラス単位で測定を行っている。 加えてデータサイエンス+Rプログラムでは、学生の詳細な学修実態を把握するため、全学において実施しているアンケートとは別に個別アンケートを実施しており、結果について担当教員へフィードバックするとともに、教学委員会にて審議することにより、教育改善に活用している。
C15: 学生アンケート等を通じた学生の内容の理解度 | E15: 前述の独自アンケートにおいて、授業内容の修得度ならびに難易度について集計を実施しており、その2つの視点より学生の理解度について把握することとしている。令和4年度での集計結果として、修得度においては、肯定的評価である「身についた」と「ある程度身についた」が76.2%となり、多くの受講生が授業内容について修得している状況が確認できる。また、難易度についても、「適切」が51.6%となり、学部の独自科目において専門的な要素が含まれているため、難易度が若干高くなっているが、おおよそ適切であると考えられる。なお、「難しい」が11.0％、「やや難しい」が31.8％、「やや簡単」が4.6％、「簡単」が1.0％となった。
C16: 学生アンケート等を通じた後輩等他の学生への推奨度 | E16: 独自アンケートにおいて、推奨度について、0（推奨しない）～10（大いに推奨）の11段階で集計を実施しており、平均値6.38、最頻値7と比較的高い推奨度であることが確認できる。 引き続きアンケートを通じた学生の推奨度把握を行い、授業改善を通じた推奨度の向上を図ることとする。また、未受講者への情報発信に用いることにより、履修率の向上に寄与することを目指したい。
C17: 全学的な履修者数、履修率向上に向けた計画の達成・進捗状況 | E17: 学部と研究科に共通する教学および教務事項を審議事項とする教学委員会を主とした自己点検・評価体制の基に、履修率向上に向けた計画を策定し、各学部においてその計画を実装する。 令和5年度に向けては、履修率の目標値をクリアするために、履修登録における広報活動を充実化させる。また、「データサイエンス＋Ｒプログラム（基礎・応用基礎）」の修了要件を満たした学生に対して、デジタル化されたサーティフィケートであるオープンバッチを授与することとしており、学生のモチベーションを高める。
B18: 学外からの視点
C19: 教育プログラム修了者の進路、活躍状況、企業等の評価 | E19: 「データサイエンス+Rプログラム（基礎）」は、令和4年度より取り組みを進めているものであり、さらには低回生向けに開講されている科目が大半を占めるため、令和4年度卒業回生となる学生が一部受講しているものの、全受講生に占める割合は僅かであり、進路ならびに活躍状況、企業の評価において、当該プログラムの直接的、間接的因果関係は考えにくい。 令和4年度において1または2回生時に当該プログラムを修了した学生が卒業該当年次となる4年後を目処に、進路ならびに活躍状況、企業等の評価について、改めて検証することとしたい。
C20: 産業界からの視点を含めた教育プログラム内容・手法等への意見 | E20: 本学では、令和4年度において、685社を対象に産業界等社会においてプログラムを通じて修得することが望ましい知識・技能を把握することを目的にアンケートを実施している。アンケートではプログラムの中で強化すべき点や新たに追加すべき知識・技能について確認を行っている。 アンケートの結果、122社より回答を得ることができ、概ね既存の授業内容（テーマ）に関する知識・技能の修得が期待されていることが確認できた。 企業からのプログラム内容に関する意見を収集することにより、実社会において求められる知識・技能が得られるよう教育プログラムの改善に役立てる。
B21: 数理・データサイエンス・ＡＩを「学ぶ楽しさ」「学ぶことの意義」を理解させること | E21: 本学は文理16学部を擁する総合大学であり、受講生の興味関心も様々であるが、原理など抽象的な学習内容とならないよう、実社会や日々の生活において活用されている例や課題を取り扱うとともに、情報社会において得られるデータを用いた内容を組み込むこととしている。このことによって、自身の専門分野に関わらず、「学ぶ楽しさ」や「学ぶことの意義」などについて理解できる内容となっている。
B22: 内容・水準を維持・向上しつつ、より「分かりやすい」授業とすること | E22: 前述の通り、本教育プログラムでは本学が全授業科目を対象に実施している「授業アンケート」に加え、独自にアンケートを実施しており、授業の難易度や理解度、学習時間など受講生の学修実態を調査し、分析結果について担当教員へのフィードバックならびに教学委員会において確認することによって、教育内容において質の保証および改善を行っている。 授業アンケートにおいて難易度については、「適切」が56.1％となっており、引き続き授業改善に取り組むことにより、当該数値についても向上するよう取り組むこととしたい。
