Workbook

Sheet 様式１　プログラムを構成する授業科目
R1: 様式１ | T1: 「学部・学科によって、修了要件は相違する」場合は、本シートを複製の上＜様式１－〇＞と枝番号を付してください
B2: 大学等名 | C2: 聖心女子大学
B3: プログラム名 | C3: AI・データサイエンス基礎
A5: プログラムを構成する授業科目について
A7: ① 対象となる学部・学科名称 | J7: ② 教育プログラムの修了要件 | K7: 学部・学科によって、修了要件は相違しない
B9: ｆｗんｓi
A12: ③ 修了要件
A13: 2 | B13: 「AI・データサイエンス基礎」２単位の修得をプログラム修了要件とする。 | V13: 【プルダウンリスト】
V14: 令和４年度以前より、履修することが必須のプログラムとして実施
V15: 令和７年度までに履修必須とする計画
V16: 令和８年度以降に履修必須とする計画、又は未定
B20: 必要最低単位数 | C20: 2 | E20: 単位 | J20: 履修必須の有無 | K20: 令和７年度までに履修必須とする計画
A22: ④ 現在進行中の社会変化（第４次産業革命、Society 5.0、データ駆動型社会等）に深く寄与しているものであり、それが自らの生活と密接に結びついている」の内容を含む授業科目
B24: 授業科目 | F24: 単位数 | G24: 必須 | H24: 1-1 | I24: 1-6 | J24: 授業科目 | P24: 単位数 | Q24: 必須 | R24: 1-1 | S24: 1-6
B25: AI・データサイエンス基礎 | F25: 2 | G25: ○ | H25: ○ | I25: ○
A33: ⑤ 「社会で活用されているデータ」や「データの活用領域」は非常に広範囲であって、日常生活や社会の課題を解決する有用なツールになり得るもの」の内容を含む授業科目
B35: 授業科目 | F35: 単位数 | G35: 必須 | H35: 1-2 | I35: 1-3 | J35: 授業科目 | P35: 単位数 | Q35: 必須 | R35: 1-2 | S35: 1-3
B36: AI・データサイエンス基礎 | F36: 2 | G36: ○ | H36: ○ | I36: ○
A44: ⑥ 「様々なデータ利活用の現場におけるデータ利活用事例が示され、様々な適用領域（流通、製造、金融、サービス、インフラ、公共、ヘルスケア等）の知見と組み合わせることで価値を創出するもの」の内容を含む授業科目
B46: 授業科目 | F46: 単位数 | G46: 必須 | H46: 1-4 | I46: 1-5 | J46: 授業科目 | P46: 単位数 | Q46: 必須 | R46: 1-4 | S46: 1-5
B47: AI・データサイエンス基礎 | F47: 2 | G47: ○ | H47: ○ | I47: ○
A55: ⑦ 「活用に当たっての様々な留意事項（ELSI、個人情報、データ倫理、ＡＩ社会原則等）を考慮し、情報セキュリティや情報漏洩等、データを守る上での留意事項への理解をする」の内容を含む授業科目
B57: 授業科目 | F57: 単位数 | G57: 必須 | H57: 3-1 | I57: 3-2 | J57: 授業科目 | P57: 単位数 | Q57: 必須 | R57: 3-1 | S57: 3-2
B58: AI・データサイエンス基礎 | F58: 2 | G58: ○ | H58: ○ | I58: ○
A66: ⑧ 「実データ・実課題（学術データ等を含む）を用いた演習など、社会での実例を題材として、「データを読む、説明する、扱う」といった数理・データサイエンス・ＡＩの基本的な活用法に関するもの」の内容を含む授業科目
B68: 授業科目 | E68: 単位数 | F68: 必須 | G68: 2-1 | H68: 2-2 | I68: 2-3 | J68: 授業科目 | O68: 単位数 | P68: 必須 | Q68: 2-1 | R68: 2-2 | S68: 2-3
B69: AI・データサイエンス基礎 | E69: 2 | F69: ○ | G69: ○ | H69: ○ | I69: ○
A77: ⑨ 選択「４．オプション」の内容を含む授業科目
B78: 授業科目 | F78: 選択項目 | J78: 授業科目 | P78: 選択項目
A87: ⑩ プログラムを構成する授業の内容
B88: 授業に含まれている内容・要素 | D88: 講義内容
B89: （１）現在進行中の社会変化（第４次産業革命、Society 5.0、データ駆動型社会等）に深く寄与しているものであり、それが自らの生活と密接に結びついている | C89: 1-1 | D89: ・「AI・データサイエンス基礎」第1回(ガイダンスならびにデータサイエンスの背景) はじめに、データサイエンスとは、データサイエンスが重要視される背景、データ活用を支援するデジタル技術のキーワード （学びのキーワード：データサイエンス、社会とデータサイエンスの身近な関わり、VUCA、コンピュータの発展、データ活用のコモディティ化、ビッグデータ、IoT、AI） ・「AI・データサイエンス基礎」第2回（日本社会の変化とデジタル社会の到来） 日本企業の国際競争力低下、市場の大きな変化、デジタル技術の発展、デジタル社会の提言 （学びのキーワード：大企業の国際競争力低下、スタートアップも十分育っていない、IMD世界競争力ランキング、日本の人口推移、ロングテール化、モノからコトへ、価値の源泉の変化、デジタルビジネス、デジタルトランスフォーメーション、第4次産業革命、Industrie4.0、データ駆動型社会、Society5.0）
C90: 1-6 | D90: ・「AI・データサイエンス基礎」第8回（データ・AIの利活用の最新動向） データ・AIを活用した新しいビジネス、データ・AIに関連した新技術、新ビジネスがなぜ小さな企業から生まれやすいのか （学びのキーワード：犯罪予測、農作業の意思決定支援、ダイナミックプライシング、個人信用評価、敵対的生成ネットワーク、強化学習、転移学習、経営資源取得の容易化、起業コストの低下、グローバル展開の容易化）
B91: （２）「社会で活用されているデータ」や「データの活用領域」は非常に広範囲であって、日常生活や社会の課題を解決する有用なツールになり得るもの | C91: 1-2 | D91: ・「AI・データサイエンス基礎」第3回（社会で活用されている様々なデータ） 社会で活用されているデータの実例、データの分類、データのオープン化 （学びのキーワード：統計データ、人の行動ログデータ、機械の稼働ログデータ、1次データ／2次データ、外部データ／内部データ、構造化／準構造化／非構造化データ、オープンデータ、SF Open Data、Crimespotting、Yelp）
C92: 1-3 | D92: ・「AI・データサイエンス基礎」第4回（AI（人工知能）の歴史と発展） AIの定義、AIの歴史、AI活用領域の広がり（生産、消費、文化活動など）、人間に近づくAI （学びのキーワード：AIの定義、推論・探索の時代、知識の時代、機械学習・ディープラーニングの時代、自動検品、商品仕分け、需要予測、危険運転の検知、ゲノム医療、診断支援、絵画を描くAI、作曲をするAI、小説を書くAI、入試に合格するAI）
B93: （３）様々なデータ利活用の現場におけるデータ利活用事例が示され、様々な適用領域（流通、製造、金融、サービス、インフラ、公共、ヘルスケア等）の知見と組み合わせることで価値を創出するもの | C93: 1-4 | D93: ・「AI・データサイエンス基礎」第5回（AIの強みと弱みならびに活用の課題） データ認識技術、AI技術、AIの課題、AIの難問、AIが社会にもたらす影響 （学びのキーワード：画像認識技術、文字認識技術、音声認識技術、顔認証技術、ルール・ベース、機械学習（教師あり学習、教師なし学習、強化学習）、ディープラーニング、未学習・過学習、フレーム問題、モラベックのパラドクス、シンボルグラウンディング問題、シンギュラリティ、AIは雇用を奪う、強いAIと弱いAI、AIの得意分野・不得意分野） ・「AI・データサイエンス基礎」第6回（データ活用におけるモデルと分析アプローチ） データの定義、データ活用のモデル、データ分析のアプローチ、データ分析においてより大きな価値を生む領域 （学びのキーワード：データの定義、DIKWモデル、SECIモデル、データ分析のプロセス、ロジックツリー、探索的データ解析、データの前処理、決定木、課題発見、解決策検討、多様な視点の重要性、試行錯誤の重要性）
C94: 1-5 | D94: ・「AI・データサイエンス基礎」第7回（データ・AIの利活用の現状） 製造業のデータ・AI活用、小売業のデータ・AI活用、サービス業のデータ・AI活用、公共・インフラ業のデータ・AI活用、データ・AI活用による新しいビジネス領域 （学びのキーワード：建設機械の挙動・状況把握、デジタル複合機のリモート管理、自動運転、スマートグラス、ID-POS、Amazon GO、ロボアドバイザリー、無担保融資、オンライン融資、スマートメーター、橋梁モニタリング、MaaS、シェアリングエコノミー、DtoC、スマートシティ）
B95: （４）活用に当たっての様々な留意事項（ELSI、個人情報、データ倫理、ＡＩ社会原則等）を考慮し、情報セキュリティや情報漏洩等、データを守る上での留意事項への理解をする | C95: 3-1 | D95: ・「AI・データサイエンス基礎」第12回（データ・AIを扱う上でのモラルと権利） 「ELSI」とは何か、データに関する不正行為、個人情報の保護、個人情報は誰が管理すべきか （学びのキーワード：データ・AIに関連する「ELSI」、インフォームド・コンセント、ねつ造・改ざん・盗用、ｐ値ハッキング、プライバシーの権利、個人情報保護法、オプトイン／オプトアウト、GDPR、忘れられる権利、個人情報管理主体（他者・自身）によるメリット・デメリット） ・「AI・データサイエンス基礎」第13回（データ・AIを扱う上でのバイアスの考慮） バイアスとは、データ収集におけるバイアス、データ・AIを扱う上でのバイアス、AIの正しい活用に向けて （学びのキーワード：GIGO、バイアスを最小化する、スナップショット調査、継続調査におけるバイアス、質問票によるバイアス、データバイアス、アルゴリズムバイアス、アルゴリズムバイアスの発生事例、AI活用のための原則、人間中心のAI社会原則）
C96: 3-2 | D96: ・「AI・データサイエンス基礎」第14回（データを守る情報セキュリティならびにまとめ） 情報セキュリティ、コンピュータウイルス、セキュリティ技術、まとめ：本講座におけるメッセージ （学びのキーワード：機密性・完全性・可用性、情報漏えい、不正のトライアングル、コンピュータウイルス、サイバー攻撃、サイバー攻撃への対応、情報セキュリティ脅威事例、暗号技術、認証技術）
B97: （５）実データ・実課題（学術データ等を含む）を用いた演習など、社会での実例を題材として、「データを読む、説明する、扱う」といった数理・データサイエンス・ＡＩの基本的な活用法に関するもの | C97: 2-1 | D97: ・「AI・データサイエンス基礎」第9回（データの種類と読み取り） データの種類、データの分布と代表値、データのばらつき、データのチェック （学びのキーワード：量的変数と質的変数、尺度、離散変数と連続変数、計算的代表値、位置的代表値、分散、標準偏差、偏差値、欠損、外れ値、異常値、データクレンジング） ・「AI・データサイエンス基礎」第10回（限られたデータからの読み取り） 相関と因果、母集団と抽出、統計情報の正しい理解 （学びのキーワード：相関関係、因果関係、疑似相関、アンスコムの例、全数調査、標本調査、単純無作為抽出法、層別抽出法、認知バイアス、印象操作）
...

Sheet 様式２ 履修者等数の実績
AQ1: 様式２
AL2: 大学等名 | AM2: ='様式１ プログラムを構成する授業科目'!C2 -> 聖心女子大学
A3: プログラムの履修者数等の実績について
A5: ①プログラム開設年度 | C5: 令和４ | E5: 年度
A7: ②履修者・修了者の実績
B9: 学部・学科名称 | C9: 学生数 | D9: 入学 定員 | E9: 収容 定員 | F9: 令和4年度 | L9: 令和3年度 | R9: 令和2年度 | X9: 令和元年度 | AD9: 平成30年度 | AJ9: 平成29年度 | AP9: 履修者数 合計 | AQ9: 履修率
F10: 履修者数 | I10: 修了者数 | L10: 履修者数 | O10: 修了者数 | R10: 履修者数 | U10: 修了者数 | X10: 履修者数 | AA10: 修了者数 | AD10: 履修者数 | AG10: 修了者数 | AJ10: 履修者数 | AM10: 修了者数
F11: 合計 | G11: 男性 | H11: 女性 | I11: 合計 | J11: 男性 | K11: 女性 | L11: 合計 | M11: 男性 | N11: 女性 | O11: 合計 | P11: 男性 | Q11: 女性 | R11: 合計 | S11: 男性 | T11: 女性 | U11: 合計 | V11: 男性 | W11: 女性 | X11: 合計 | Y11: 男性 | Z11: 女性 | AA11: 合計 | AB11: 男性 | AC11: 女性 | AD11: 合計 | AE11: 男性 | AF11: 女性 | AG11: 合計 | AH11: 男性 | AI11: 女性 | AJ11: 合計 | AK11: 男性 | AL11: 女性 | AM11: 合計 | AN11: 男性 | AO11: 女性
B12: 基礎課程 | C12: 588 | D12: 490 | E12: 490 | F12: =G12+H12 -> 574 | G12: 0 | H12: 574 | I12: =J12+K12 -> 562 | J12: 0 | K12: 562 | L12: =M12+N12 -> 0 | O12: =P12+Q12 -> 0 | R12: =S12+T12 -> 0 | U12: =V12+W12 -> 0 | X12: =Y12+Z12 -> 0 | AA12: =AB12+AC12 -> 0 | AD12: =AE12+AF12 -> 0 | AG12: =AH12+AI12 -> 0 | AJ12: =AK12+AL12 -> 0 | AM12: =AN12+AO12 -> 0 | AP12: =F12+L12+R12+X12+AD12+AJ12 -> 574 | AQ12: =AP12/E12 -> 1.1714286
B13: 英語文化コミュニケーション学科 | C13: 306 | E13: 288 | F13: =G13+H13 -> 2 | G13: 0 | H13: 2 | I13: =J13+K13 -> 2 | J13: 0 | K13: 2 | L13: =M13+N13 -> 0 | O13: =P13+Q13 -> 0 | R13: =S13+T13 -> 0 | U13: =V13+W13 -> 0 | X13: =Y13+Z13 -> 0 | AA13: =AB13+AC13 -> 0 | AD13: =AE13+AF13 -> 0 | AG13: =AH13+AI13 -> 0 | AJ13: =AK13+AL13 -> 0 | AM13: =AN13+AO13 -> 0 | AP13: =F13+L13+R13+X13+AD13+AJ13 -> 2 | AQ13: =AP13/E13 -> 0.0069444444
B14: 日本語日本文学科 | C14: 181 | E14: 153 | F14: =G14+H14 -> 2 | G14: 0 | H14: 2 | I14: =J14+K14 -> 2 | J14: 0 | K14: 2 | L14: =M14+N14 -> 0 | O14: =P14+Q14 -> 0 | R14: =S14+T14 -> 0 | U14: =V14+W14 -> 0 | X14: =Y14+Z14 -> 0 | AA14: =AB14+AC14 -> 0 | AD14: =AE14+AF14 -> 0 | AG14: =AH14+AI14 -> 0 | AJ14: =AK14+AL14 -> 0 | AM14: =AN14+AO14 -> 0 | AP14: =F14+L14+R14+X14+AD14+AJ14 -> 2 | AQ14: =AP14/E14 -> 0.013071895
B15: 史学科 | C15: 170 | E15: 171 | F15: =G15+H15 -> 0 | G15: 0 | I15: =J15+K15 -> 0 | J15: 0 | L15: =M15+N15 -> 0 | O15: =P15+Q15 -> 0 | R15: =S15+T15 -> 0 | U15: =V15+W15 -> 0 | X15: =Y15+Z15 -> 0 | AA15: =AB15+AC15 -> 0 | AD15: =AE15+AF15 -> 0 | AG15: =AH15+AI15 -> 0 | AJ15: =AK15+AL15 -> 0 | AM15: =AN15+AO15 -> 0 | AP15: =F15+L15+R15+X15+AD15+AJ15 -> 0 | AQ15: =AP15/E15 -> 0
B16: 人間関係学科 | C16: 209 | E16: 186 | F16: =G16+H16 -> 0 | G16: 0 | I16: =J16+K16 -> 0 | J16: 0 | L16: =M16+N16 -> 0 | O16: =P16+Q16 -> 0 | R16: =S16+T16 -> 0 | U16: =V16+W16 -> 0 | X16: =Y16+Z16 -> 0 | AA16: =AB16+AC16 -> 0 | AD16: =AE16+AF16 -> 0 | AG16: =AH16+AI16 -> 0 | AJ16: =AK16+AL16 -> 0 | AM16: =AN16+AO16 -> 0 | AP16: =F16+L16+R16+X16+AD16+AJ16 -> 0 | AQ16: =AP16/E16 -> 0
B17: 国際交流学科 | C17: 244 | E17: 201 | F17: =G17+H17 -> 0 | G17: 0 | I17: =J17+K17 -> 0 | J17: 0 | L17: =M17+N17 -> 0 | O17: =P17+Q17 -> 0 | R17: =S17+T17 -> 0 | U17: =V17+W17 -> 0 | X17: =Y17+Z17 -> 0 | AA17: =AB17+AC17 -> 0 | AD17: =AE17+AF17 -> 0 | AG17: =AH17+AI17 -> 0 | AJ17: =AK17+AL17 -> 0 | AM17: =AN17+AO17 -> 0 | AP17: =F17+L17+R17+X17+AD17+AJ17 -> 0 | AQ17: =AP17/E17 -> 0
B18: 哲学科 | C18: 145 | E18: 132 | F18: =G18+H18 -> 0 | G18: 0 | I18: =J18+K18 -> 0 | J18: 0 | L18: =M18+N18 -> 0 | O18: =P18+Q18 -> 0 | R18: =S18+T18 -> 0 | U18: =V18+W18 -> 0 | X18: =Y18+Z18 -> 0 | AA18: =AB18+AC18 -> 0 | AD18: =AE18+AF18 -> 0 | AG18: =AH18+AI18 -> 0 | AJ18: =AK18+AL18 -> 0 | AM18: =AN18+AO18 -> 0 | AP18: =F18+L18+R18+X18+AD18+AJ18 -> 0 | AQ18: =AP18/E18 -> 0
B19: 教育学科初等教育学専攻 | C19: 176 | E19: 150 | F19: =G19+H19 -> 0 | G19: 0 | I19: =J19+K19 -> 0 | J19: 0 | L19: =M19+N19 -> 0 | O19: =P19+Q19 -> 0 | R19: =S19+T19 -> 0 | U19: =V19+W19 -> 0 | X19: =Y19+Z19 -> 0 | AA19: =AB19+AC19 -> 0 | AD19: =AE19+AF19 -> 0 | AG19: =AH19+AI19 -> 0 | AJ19: =AK19+AL19 -> 0 | AM19: =AN19+AO19 -> 0 | AP19: =F19+L19+R19+X19+AD19+AJ19 -> 0 | AQ19: =AP19/E19 -> 0
B20: 教育学科教育学専攻 | C20: 108 | E20: 87 | F20: =G20+H20 -> 0 | G20: 0 | I20: =J20+K20 -> 0 | J20: 0 | L20: =M20+N20 -> 0 | O20: =P20+Q20 -> 0 | R20: =S20+T20 -> 0 | U20: =V20+W20 -> 0 | X20: =Y20+Z20 -> 0 | AA20: =AB20+AC20 -> 0 | AD20: =AE20+AF20 -> 0 | AG20: =AH20+AI20 -> 0 | AJ20: =AK20+AL20 -> 0 | AM20: =AN20+AO20 -> 0 | AP20: =F20+L20+R20+X20+AD20+AJ20 -> 0 | AQ20: =AP20/E20 -> 0
B21: 心理学科 | C21: 226 | E21: 192 | F21: =G21+H21 -> 0 | G21: 0 | I21: =J21+K21 -> 0 | J21: 0 | L21: =M21+N21 -> 0 | O21: =P21+Q21 -> 0 | R21: =S21+T21 -> 0 | U21: =V21+W21 -> 0 | X21: =Y21+Z21 -> 0 | AA21: =AB21+AC21 -> 0 | AD21: =AE21+AF21 -> 0 | AG21: =AH21+AI21 -> 0 | AJ21: =AK21+AL21 -> 0 | AM21: =AN21+AO21 -> 0 | AP21: =F21+L21+R21+X21+AD21+AJ21 -> 0 | AQ21: =AP21/E21 -> 0
F22: =G22+H22 -> 0 | I22: =J22+K22 -> 0 | L22: =M22+N22 -> 0 | O22: =P22+Q22 -> 0 | R22: =S22+T22 -> 0 | U22: =V22+W22 -> 0 | X22: =Y22+Z22 -> 0 | AA22: =AB22+AC22 -> 0 | AD22: =AE22+AF22 -> 0 | AG22: =AH22+AI22 -> 0 | AJ22: =AK22+AL22 -> 0 | AM22: =AN22+AO22 -> 0 | AP22: =F22+L22+R22+X22+AD22+AJ22 -> 0 | AQ22: =AP22/E22 -> #DIV/0!
F23: =G23+H23 -> 0 | I23: =J23+K23 -> 0 | L23: =M23+N23 -> 0 | O23: =P23+Q23 -> 0 | R23: =S23+T23 -> 0 | U23: =V23+W23 -> 0 | X23: =Y23+Z23 -> 0 | AA23: =AB23+AC23 -> 0 | AD23: =AE23+AF23 -> 0 | AG23: =AH23+AI23 -> 0 | AJ23: =AK23+AL23 -> 0 | AM23: =AN23+AO23 -> 0 | AP23: =F23+L23+R23+X23+AD23+AJ23 -> 0 | AQ23: =AP23/E23 -> #DIV/0!
F24: =G24+H24 -> 0 | I24: =J24+K24 -> 0 | L24: =M24+N24 -> 0 | O24: =P24+Q24 -> 0 | R24: =S24+T24 -> 0 | U24: =V24+W24 -> 0 | X24: =Y24+Z24 -> 0 | AA24: =AB24+AC24 -> 0 | AD24: =AE24+AF24 -> 0 | AG24: =AH24+AI24 -> 0 | AJ24: =AK24+AL24 -> 0 | AM24: =AN24+AO24 -> 0 | AP24: =F24+L24+R24+X24+AD24+AJ24 -> 0 | AQ24: =AP24/E24 -> #DIV/0!
F25: =G25+H25 -> 0 | I25: =J25+K25 -> 0 | L25: =M25+N25 -> 0 | O25: =P25+Q25 -> 0 | R25: =S25+T25 -> 0 | U25: =V25+W25 -> 0 | X25: =Y25+Z25 -> 0 | AA25: =AB25+AC25 -> 0 | AD25: =AE25+AF25 -> 0 | AG25: =AH25+AI25 -> 0 | AJ25: =AK25+AL25 -> 0 | AM25: =AN25+AO25 -> 0 | AP25: =F25+L25+R25+X25+AD25+AJ25 -> 0 | AQ25: =AP25/E25 -> #DIV/0!
F26: =G26+H26 -> 0 | I26: =J26+K26 -> 0 | L26: =M26+N26 -> 0 | O26: =P26+Q26 -> 0 | R26: =S26+T26 -> 0 | U26: =V26+W26 -> 0 | X26: =Y26+Z26 -> 0 | AA26: =AB26+AC26 -> 0 | AD26: =AE26+AF26 -> 0 | AG26: =AH26+AI26 -> 0 | AJ26: =AK26+AL26 -> 0 | AM26: =AN26+AO26 -> 0 | AP26: =F26+L26+R26+X26+AD26+AJ26 -> 0 | AQ26: =AP26/E26 -> #DIV/0!
F27: =G27+H27 -> 0 | I27: =J27+K27 -> 0 | L27: =M27+N27 -> 0 | O27: =P27+Q27 -> 0 | R27: =S27+T27 -> 0 | U27: =V27+W27 -> 0 | X27: =Y27+Z27 -> 0 | AA27: =AB27+AC27 -> 0 | AD27: =AE27+AF27 -> 0 | AG27: =AH27+AI27 -> 0 | AJ27: =AK27+AL27 -> 0 | AM27: =AN27+AO27 -> 0 | AP27: =F27+L27+R27+X27+AD27+AJ27 -> 0 | AQ27: =AP27/E27 -> #DIV/0!
F28: =G28+H28 -> 0 | I28: =J28+K28 -> 0 | L28: =M28+N28 -> 0 | O28: =P28+Q28 -> 0 | R28: =S28+T28 -> 0 | U28: =V28+W28 -> 0 | X28: =Y28+Z28 -> 0 | AA28: =AB28+AC28 -> 0 | AD28: =AE28+AF28 -> 0 | AG28: =AH28+AI28 -> 0 | AJ28: =AK28+AL28 -> 0 | AM28: =AN28+AO28 -> 0 | AP28: =F28+L28+R28+X28+AD28+AJ28 -> 0 | AQ28: =AP28/E28 -> #DIV/0!
F29: =G29+H29 -> 0 | I29: =J29+K29 -> 0 | L29: =M29+N29 -> 0 | O29: =P29+Q29 -> 0 | R29: =S29+T29 -> 0 | U29: =V29+W29 -> 0 | X29: =Y29+Z29 -> 0 | AA29: =AB29+AC29 -> 0 | AD29: =AE29+AF29 -> 0 | AG29: =AH29+AI29 -> 0 | AJ29: =AK29+AL29 -> 0 | AM29: =AN29+AO29 -> 0 | AP29: =F29+L29+R29+X29+AD29+AJ29 -> 0 | AQ29: =AP29/E29 -> #DIV/0!
F30: =G30+H30 -> 0 | I30: =J30+K30 -> 0 | L30: =M30+N30 -> 0 | O30: =P30+Q30 -> 0 | R30: =S30+T30 -> 0 | U30: =V30+W30 -> 0 | X30: =Y30+Z30 -> 0 | AA30: =AB30+AC30 -> 0 | AD30: =AE30+AF30 -> 0 | AG30: =AH30+AI30 -> 0 | AJ30: =AK30+AL30 -> 0 | AM30: =AN30+AO30 -> 0 | AP30: =F30+L30+R30+X30+AD30+AJ30 -> 0 | AQ30: =AP30/E30 -> #DIV/0!
F31: =G31+H31 -> 0 | I31: =J31+K31 -> 0 | L31: =M31+N31 -> 0 | O31: =P31+Q31 -> 0 | R31: =S31+T31 -> 0 | U31: =V31+W31 -> 0 | X31: =Y31+Z31 -> 0 | AA31: =AB31+AC31 -> 0 | AD31: =AE31+AF31 -> 0 | AG31: =AH31+AI31 -> 0 | AJ31: =AK31+AL31 -> 0 | AM31: =AN31+AO31 -> 0 | AP31: =F31+L31+R31+X31+AD31+AJ31 -> 0 | AQ31: =AP31/E31 -> #DIV/0!
B32: 合 計 | C32: =SUM(C12:C31) -> 2353 | D32: =SUM(D12:D31) -> 490 | E32: =SUM(E12:E31) -> 2050 | F32: =SUM(F12:F31) -> 578 | G32: =SUM(G12:G31) -> 0 | H32: =SUM(H12:H31) -> 578 | I32: =SUM(I12:I31) -> 566 | J32: =SUM(J12:J31) -> 0 | ... AP32: =SUM(AP12:AP31) -> 578 | AQ32: =AP32/E32 -> 0.28195122

Sheet 様式３ 教育の質・履修者数を向上させるための体制・計画
I1: 様式３
G2: 大学等名 | H2: ='様式１ プログラムを構成する授業科目'!C2 -> 聖心女子大学
A4: 教育の質・履修者数を向上させるための体制・計画について
A6: ① | B6: 全学の教員数 | C6: (常勤） | E6: 76 | F6: 人 | G6: （非常勤） | H6: 267 | I6: 人
A8: ② | B8: プログラムの授業を教えている教員数 | H8: 1 | I8: 人
A10: ③ | B10: プログラムの運営責任者
B11: （責任者名） | C11: 高祖 敏明 | G11: （役職名） | H11: 学長
A13: ④ | B13: プログラムを改善・進化させるための体制（委員会・組織等）
B14: 教務委員会
B16: （責任者名） | C16: 植田 誠治 | G16: （役職名） | H16: 副学長
A18: ⑤ | B18: プログラムを改善・進化させるための体制を定める規則名称
B19: 聖心女子大学教授会に基づく委員会規程
A21: ⑥ | B21: 体制の目的
B22: 聖心女子大学教授会に基づく委員会規程に基づき「教務委員会」を設定している。教務委員会では教育課程(カリキュラム）の編成及び履修に関する事項、教育課程実施の年間計画に関する事項、授業、定期試験及び授業時間割の編成に関する事項、成績評価及び単位認定に関する事項、教員の配置に関する事項などを所管している。特に、本件（AI・データサイエンス基礎）については、全学的リテラシー科目のカリキュラム編成、普及促進、情報リテラシー教育の質保証に向けた検討を行っている。
B34: 具体的な構成員
B35: （学務・大学院担当）副学長 教授 植田 誠治 英語文化コミュニケーション学科 教授 中川 僚子 日本語日本文学科 専任講師 清水 由貴子 史学科 准教授 齋藤 久美子 人間関係学科 専任講師 藤原 勇 国際交流学科 准教授 岡橋 純子 哲学科 専任講師 山田 庄太郎 教育学科 教授 高島 景子 心理学科 准教授 平部 正樹 事務局長 関 昭裕 広報・社会連携部次長 道正 伸久 教務課長 北村 早紀子
A48: ⑧ | B48: 履修者数・履修率の向上に向けた計画 ※様式１の「履修必須の有無」で「計画がある」としている場合は詳細について記載すること
B49: 令和４年度実績 | C49: ='様式２ 履修者等数の実績'!AQ32 -> 0.28195122 | E49: 令和５年度予定 | F49: 0.5 | H49: 令和６年度予定 | I49: 0.75
B50: 令和７年度予定 | C50: 1 | E50: 令和８年度予定 | F50: 1 | H50: 収容定員（名） | I50: ='様式２ 履修者等数の実績'!E32 -> 2050
B51: 具体的な計画
B52: 令和４年度よりSociety5.0時代に必要な「数理・データサイエンス・AI」に関する知識と技術を学び、それを活用する基礎的な能力を獲得することを目的に「AIデータサイエンス基礎」科目として１年次指定の準必修科目としての開講。前期に修得できなかった学生は、後期に再度履修し修得を図ることとしている。令和５年度より、必修科目に指定。漸次４年間で100％の履修を計画している。
A65: ⑨ | B65: 学部・学科に関係なく希望する学生全員が受講可能となるような必要な体制・取組等
B66: 「AIデータサイエンス基礎」科目として１年次指定の準必修科目としての開講。前期に修得できなかった学生は、後期に再度履修し修得を図ることとしている。令和５年度より、必修科目に指定。併せて、２～４年次生には学科に関係なく受講可能である旨を周知している。 特に、本教育プログラムの趣旨・目的については、新学期でのオリエンテーション期間中での説明と学内教学支援システムを利用しての配信により周知徹底を図っている。
A79: ⑩ | B79: できる限り多くの学生が履修できるような具体的な周知方法・取組
B80: 令和４年度より「AIデータサイエンス基礎」として１年次生指定の準必修科目としての開講、令和５年度より必修科目に指定。漸次４年間で１００％履修できる構造となっている。履修科目については「履修要覧」により、学生に周知している。 更に、本教育プログラムの趣旨・目的については学内教学支援システムにより配信するとともに、新入生オリエンテーション期間にガイダンスを実施している。 また、大学のウェブ上、教学支援システムを通して、本プログラムに関する情報を掲載するとともに、適宜情報発信している。
A93: ⑪ | B93: できる限り多くの学生が履修・修得できるようなサポート体制
B94: 令和４年度(開講初年度）において「「AIデータサイエンス基礎」科目履修者アンケートを参考にして、履修者へのサポート体制を検討、令和５年度に同科目を開講にあたっては、 ①Googleクラスルームを活用した双方向サポートの充実を図る ②学内のメディア学習支援センターでの、操作方法等支援を実施し、双方向性を確保する ③参考書等の学習教材を揃え、学習支援を強化する ④実践的、発展的な内容を扱うセミナーを開催し、学習の更なる深化を図るなどのバックアップ体制をとることとなった。 以上により、履修学生の質問、要望などにも対応できる体制とした。
A107: ⑫ | B107: 授業時間内外で学習指導、質問を受け付ける具体的な仕組み
B108: オフィスアワー制度を設けて、専任教員が各種質問に回答する体制が整備されている。 また、本学では情報教育の推進、情報メディアを活用した学習の支援、情報ネットワークシステム活用のための学習環境の向上を図ることを目的としてメディア学習支援センターを設置し、PCを使った実習や作品制作ができる演習室を備えている。メディア学習支援センターでは、機器操作方法等支援を実施し、双方向性を確保、参考書等の学習教材を揃え、学習支援の強化を図っている。

Sheet 様式４　自己点検・評価 
I1: 様式４
H2: 大学等名 | I2: ='様式１ プログラムを構成する授業科目'!C2 -> 聖心女子大学
A3: 自己点検・評価について
A5: ① | B5: プログラムの自己点検・評価を行う体制（委員会・組織等）
B6: 「AI・データサイエンス基礎」準備・実施ワーキンググループ
D8: （責任者名） | E8: 植田誠治 | G8: （役職名） | H8: 学務・大学院担当副学長
A10: ② | B10: 自己点検・評価体制における意見等
B11: 自己点検・評価の視点 | E11: 自己点検・評価体制における意見・結果・改善に向けた取組等
B12: 学内からの視点
C13: プログラムの履修・修得状況 | E13: ・令和４年度１年次対象の準必修科目として開講。前期は当初水曜日に開講を予定していたが、履修状況記録を確認したところ、木曜日に変更したほうが他科目との履修バランスが取れることが判明したため、急遽曜日変更を行い、１年次生にとって履修しやすい環境を整えた。しかしながら、授業後アンケートによる自己点検・評価の結果、曜日変更により一部混乱を生じさせたことや、提出期限がわかりにくいという声があったため、後期開講は、時間の統一と期限の明示化に取り組み改善した。 ・修得状況は、前期Aクラスの開講578名の履修に対して530名で、修得率は91.7%だった。前期に修得できなかった学生を対象として、後期にBクラスを開講し改善に取り組んだ。その結果、令和４年度に修得できたのは前期・後期の合計で566名となり、修得率は97.9%となった。
C14: 学修成果 | E14: 令和４年度前期の受講生に同プログラムの授業アンケートを実施したところ ①授業の満足度については満足＋やや満足＝70.8% ②データサイエンスという学問領域の関心度合いの変化については もともとの興味が更に深まった（10.6%)＋本講義をきっかけり興味・関心を持った(34.8%)＋本講義をきっかけに少し興味をもった(47.4%)=92.8%と関心度合いの高まり(変化）を知ることができた。 ③本講義が将来に活かせるものだったかとの質問には 大いに活かせる(45%)+少し活かせる（44.4）＝89.4% と有用性への気づきも確認できる。 以上のようなアンケ―ト結果を踏まえて、引き続き高い学修成果の創出に取り組む方針である。
C15: 学生アンケート等を通じた学生の内容の理解度 | E15: アンケートにおいて、あなた自身が身についたと思うことについて選択させたところ、データサイエンスの概念の理解は51.7%、データサイエンスの事例の理解は48.7%、データの扱い方は63.2%、データの分析手法は34.6%、機械学習を用いた実装方法は25.5%、機械学習を用いた分析方法は18.6%だった。機械学習（AI）に関しての理解度に課題があり、今後、最新の情報を共有していく形での改善を図ることとした。
C16: 学生アンケート等を通じた後輩等他の学生への推奨度 | E16: 当該科目は令和４年度に１年次生対象の準必修科目として新設し、令和５年度に１年次生の年次必修科目とした。そのため、当初は２～４年次生の履修は想定していなかったが、本学Webサイトに「AI・データサイエンス基礎」プログラムの新設を告知したところ上級生から自発的に「対象年次ではないが履修したい」との要望が複数よせられた。そのため、急遽、他学年にも開講することとしたことした経緯がある。以上により、学生の関心の高さを伺い知ることができる。
C17: 全学的な履修者数、履修率向上に向けた計画の達成・進捗状況 | E17: 令和４年度、１年次生対象の準必修科目として新規に開講。前期にAクラスを開講し、前期に修得できなかった学生を対象として後期にBクラスを開講することで、修得率の向上を目指した。その結果、当初90%を目標としていたが、結果的に修得率は97.9となり、目標を達成することができた。令和５年度より１年次生の年次指定科目として必修化されるため、漸次全学生修得率100%を達成する見込みである。
B18: 学外からの視点
C19: 教育プログラム修了者の進路、活躍状況、企業等の評価 | E19: 当該授業は令和４年度より、１年次生対象の準必修科目として新規に開講されたため、当該授業を履修、単位を修得して卒業した学生はいない。令和５年度より１年次生の年次指定科目として必修化している。そのため、令和８年度に最初の卒業生が生じることとなることなるので、当該科目を履修した学生の進路・就職状況等に変化（特徴）が見られる可能性がある。本学キャリアセンターと連携しつつ当プログラム修了者の進路等に注視し、自己点検・評価に生かしていく予定である。
C20: 産業界からの視点を含めた教育プログラム内容・手法等への意見 | E20: 外部のIT企業関係者より本プログラムの内容ならびに実施方法について意見を求めた。リテラシーレベルの修得に効果がある内容と、本学の履修スタイルに対応した手法であるとの評価を得られた。今後、時代の変化に合わせたコンテンツのアップデートが大切であるとのコメントをいただいた。
B21: 数理・データサイエンス・ＡＩを「学ぶ楽しさ」「学ぶことの意義」を理解させること | E21: アンケートにおいて、授業開始前は、51.6%の学生が、興味・関心はあるが、AI・データサイエンスについて学んでなく、14.7%は自分には関係ないと考えていた。また、聞いたことがない学生も30.5%いた。学んだことがある学生はわずか3.2%だった。しかしながら、授業を通して得るAI・データサイエンスの知識が将来に活かされると考えていた学生は、大いに活かせると思うが42.7%、少し活かせると思うが37.5%で合計80.2%であり、期待されている状態だった。修得後の調査の結果、大いに活かせると思うが45%に増加、少し活かせると思うも44.5%に増加し、合計89.4%に増加した。今後も数値向上のためのセミナーなどを企画して「学ぶことの意義」を向上させていく計画である。
B22: 内容・水準を維持・向上しつつ、より「分かりやすい」授業とすること | E22: 授業に関する質問対応や、アンケート調査より。「データを読む」「データを説明する」「データを扱う」ところでの演習操作に戸惑った学生が多かったことが明らかになった。そのため、相談できるスタッフを配置しサポートする体制を整えることで、わかりやすい授業に改善していく計画である。
