Workbook

Sheet 様式１-1　プログラムを構成する授業科目
R1: 様式１－１ | T1: 「学部・学科によって、修了要件は相違する」場合は、本シートを複製の上＜様式１－〇＞と枝番号を付してください
B2: 大学等名 | C2: 金沢学院大学
B3: プログラム名 | C3: 数理・データサイエンス・AI教育プログラム
A5: プログラムを構成する授業科目について
A7: ① 対象となる学部・学科名称 | J7: ② 教育プログラムの修了要件 | K7: 学部・学科によって、修了要件は相違する
B9: 文学部、芸術学部
A12: ③ 修了要件
B13: 数理データサイエンスAI教育プログラムを構成する科目のうち、「コンピュータ基礎演習II」（２単位）を取得すること。 | V13: 【プルダウンリスト】
V14: 令和４年度以前より、履修することが必須のプログラムとして実施
V15: 令和７年度までに履修必須とする計画
V16: 令和８年度以降に履修必須とする計画、又は未定
B20: 必要最低単位数 | C20: 2 | E20: 単位 | J20: 履修必須の有無 | K20: 令和４年度以前より、履修することが必須のプログラムとして実施
A22: ④ 現在進行中の社会変化（第４次産業革命、Society 5.0、データ駆動型社会等）に深く寄与しているものであり、それが自らの生活と密接に結びついている」の内容を含む授業科目
B24: 授業科目 | F24: 単位数 | G24: 必須 | H24: 1-1 | I24: 1-6 | J24: 授業科目 | P24: 単位数 | Q24: 必須 | R24: 1-1 | S24: 1-6
B25: コンピュータ基礎演習Ⅱ | F25: 2 | G25: ○ | H25: ○ | I25: ○
A33: ⑤ 「社会で活用されているデータ」や「データの活用領域」は非常に広範囲であって、日常生活や社会の課題を解決する有用なツールになり得るもの」の内容を含む授業科目
B35: 授業科目 | F35: 単位数 | G35: 必須 | H35: 1-2 | I35: 1-3 | J35: 授業科目 | P35: 単位数 | Q35: 必須 | R35: 1-2 | S35: 1-3
B36: コンピュータ基礎演習Ⅱ | F36: 2 | G36: ○ | H36: ○ | I36: ○
A44: ⑥ 「様々なデータ利活用の現場におけるデータ利活用事例が示され、様々な適用領域（流通、製造、金融、サービス、インフラ、公共、ヘルスケア等）の知見と組み合わせることで価値を創出するもの」の内容を含む授業科目
B46: 授業科目 | F46: 単位数 | G46: 必須 | H46: 1-4 | I46: 1-5 | J46: 授業科目 | P46: 単位数 | Q46: 必須 | R46: 1-4 | S46: 1-5
B47: コンピュータ基礎演習Ⅱ | F47: 2 | G47: ○ | H47: ○ | I47: ○
A55: ⑦ 「活用に当たっての様々な留意事項（ELSI、個人情報、データ倫理、ＡＩ社会原則等）を考慮し、情報セキュリティや情報漏洩等、データを守る上での留意事項への理解をする」の内容を含む授業科目
B57: 授業科目 | F57: 単位数 | G57: 必須 | H57: 3-1 | I57: 3-2 | J57: 授業科目 | P57: 単位数 | Q57: 必須 | R57: 3-1 | S57: 3-2
B58: コンピュータ基礎演習Ⅱ | F58: 2 | G58: ○ | H58: ○ | I58: ○
A66: ⑧ 「実データ・実課題（学術データ等を含む）を用いた演習など、社会での実例を題材として、「データを読む、説明する、扱う」といった数理・データサイエンス・ＡＩの基本的な活用法に関するもの」の内容を含む授業科目
B68: 授業科目 | E68: 単位数 | F68: 必須 | G68: 2-1 | H68: 2-2 | I68: 2-3 | J68: 授業科目 | O68: 単位数 | P68: 必須 | Q68: 2-1 | R68: 2-2 | S68: 2-3
B69: コンピュータ基礎演習Ⅱ | E69: 2 | F69: ○ | G69: ○ | H69: ○ | I69: ○
A77: ⑨ 選択「４．オプション」の内容を含む授業科目
B78: 授業科目 | F78: 選択項目 | J78: 授業科目 | P78: 選択項目
A87: ⑩ プログラムを構成する授業の内容
B88: 授業に含まれている内容・要素 | D88: 講義内容
B89: （１）現在進行中の社会変化（第４次産業革命、Society 5.0、データ駆動型社会等）に深く寄与しているものであり、それが自らの生活と密接に結びついている | C89: 1-1 | D89: ビッグデータ、IoT、AI、ロボット、第4次産業革命、Society 5.0、データ駆動型社会、複数技術を組み合わせたAIサービス、人間の知的活動とAIの関係性、データを起点としたものの見方について学ぶ 「コンピュータ基礎演習Ⅱ」（文学部 第２回）（芸術学部 第１回）  データサイエンスやAIとはどういう分野なのか、なぜ社会の関⼼を集めているのか  社会におけるデータ・AIの利活⽤例を幅広く学ぶことで、社会で起きている変化を知り、データサイエンスやAIを学ぶことの意義を理解することを⽬標とする  特にAIを活⽤した新しいビジネスやサービスは、複数の技術が組み合わさって実現していることに注⽬する
C90: 1-6 | D90: AI等を活用した新しいビジネスモデル(シェアリングエコノミー、商品のレコメンデーションなど)、AI最新技術の活用例（深層生成モデル、敵対的生成ネットワーク、強化学習、転移学習など）について学ぶ 「コンピュータ基礎演習Ⅱ」（文学部 第７回）（芸術学部 第６回）  データサイエンスの最先端ではどのような研究開発が行われているのか、いくつか先端的な技術を紹介する  データ・AI利活用における新技術と最新動向を知ることを目標とする
B91: （２）「社会で活用されているデータ」や「データの活用領域」は非常に広範囲であって、日常生活や社会の課題を解決する有用なツールになり得るもの | C91: 1-2 | D91: 構造化データ、非構造化データ（文章、画像/動画、音声/音楽など）、データのオープン化（オープンデータ）について学ぶ 「コンピュータ基礎演習Ⅱ」（文学部 第３回）（芸術学部 第２回）  どういうデータがデータサイエンスでは用いられるのか  代表的なデータをいくつか見ていくことで、どういうデータが集められ、どう活用されているかを知ることを目標とする
C92: 1-3 | D92: データ・AI活用領域の広がり(生産、消費、文化活動など)、研究開発、調達、製造、物流、販売、マーケティング、サービスなどについて学ぶ 「コンピュータ基礎演習Ⅱ」（文学部 第４回）（芸術学部 第３回）  データサイエンスやAIはどのように活用されているのか  いくつかの例を見ることで、さまざまな領域でデータ・AIが活用されていることを知ることを目標とする
B93: （３）様々なデータ利活用の現場におけるデータ利活用事例が示され、様々な適用領域（流通、製造、金融、サービス、インフラ、公共、ヘルスケア等）の知見と組み合わせることで価値を創出するもの | C93: 1-4 | D93: 非構造化データ処理：言語処理、画像/動画処理、音声/音楽処理などについて学ぶ 「コンピュータ基礎演習Ⅱ」（文学部 第５回）（芸術学部 第４回）  データサイエンスやAI利活用の現場ではどういう技術が用いられるのか  基本的なものを見ていくことで、データ・AIを活用するために使われている技術の概要を知ることを目標とする
C94: 1-5 | D94: データサイエンスのサイクル（課題抽出と定式化、データの取得・管理・加工、探索的データ解析、データ解析と推論、結果の共有・伝達、課題解決に向けた提案）、流通、製造、金融、サービス、インフラ、公共、ヘルスケア等におけるデータ・AI利活用事例について学ぶ 「コンピュータ基礎演習Ⅱ」（文学部 第６回）（芸術学部 第５回）  データサイエンティストの仕事の流れとは具体的にどのようなものなのか  データ・AIを活用することによって、どのような価値が生まれているかを知ることを目標とする
B95: （４）活用に当たっての様々な留意事項（ELSI、個人情報、データ倫理、ＡＩ社会原則等）を考慮し、情報セキュリティや情報漏洩等、データを守る上での留意事項への理解をする | C95: 3-1 | D95: ELSI（Ethical, Legal and Social Issues）、個人情報保護、EU一般データ保護規則(GDPR)、忘れられる権利、オプトアウト、データ倫理：データのねつ造、改ざん、盗用、プライバシー保護、AI社会原則（公平性、説明責任、透明性、人間中心の判断）、データバイアス、アルゴリズムバイアス、AIサービスの責任論、データ・AI活用における負の事例について学ぶ 「コンピュータ基礎演習Ⅱ」（文学部 第１１回）（芸術学部 第１０回）  データやAIは，強⼒な道具であるだけに，使い⽅を誤ると⼈間や社会に⼤きなダメージを与えるおそれがある  データやAIを使うにあたり最低限気をつけるべきことについて学ぶ
C96: 3-2 | D96: 情報セキュリティ：機密性、完全性、可用性、匿名加工情報、暗号化、パスワード、悪意ある情報搾取、情報漏洩等によるセキュリティ事故の事例について学ぶ 「コンピュータ基礎演習Ⅱ」（文学部 第１２回）（芸術学部 第１１回）  3-1の具体例として、データやAIにまつわる基本的な倫理，合意事項について学ぶ  そして、 データを守ること，およびそれが破られて起こった事例について学ぶ
B97: （５）実データ・実課題（学術データ等を含む）を用いた演習など、社会での実例を題材として、「データを読む、説明する、扱う」といった数理・データサイエンス・ＡＩの基本的な活用法に関するもの | C97: 2-1 | D97: データの種類（量的変数、質的変数）、データの分布(ヒストグラム)と代表値（平均値、中央値、最頻値）、代表値の性質の違い（実社会では平均値＝最頻値でないことが多い）、データのばらつき（分散、標準偏差、偏差値）、母集団と標本抽出（国勢調査、アンケート調査、全数調査、単純無作為抽出、層別抽出、多段抽出）、統計情報の正しい理解（誇張表現に惑わされない）について学ぶ 「コンピュータ基礎演習Ⅱ」（文学部 第８回）（芸術学部 第７回）  データを要約したり可視化したりする様々な手法について学ぶことで、事象の背景や意味合いを理解することを目標とする  これらの情報を読む上で注意すべきいくつかの点についても学ぶ  データを正しく読む上では、データがどのような背景から得られたものなのかを正しく理解することも重要であることを知る
...

Sheet 様式１-2　プログラムを構成する授業科目 
R1: 様式１－２ | T1: 「学部・学科によって、修了要件は相違する」場合は、本シートを複製の上＜様式１－〇＞と枝番号を付してください
B2: 大学等名 | C2: 金沢学院大学
B3: プログラム名 | C3: 数理・データサイエンス・AI教育プログラム
A5: プログラムを構成する授業科目について
A7: ① 対象となる学部・学科名称 | J7: ② 教育プログラムの修了要件 | K7: 学部・学科によって、修了要件は相違する
B9: スポーツ科学部、栄養学部
A12: ③ 修了要件
B13: 数理データサイエンスAI教育プログラムを構成する科目のうち、「コンピュータ基礎演習II」（２単位）を取得すること。 | V13: 【プルダウンリスト】
V14: 令和４年度以前より、履修することが必須のプログラムとして実施
V15: 令和７年度までに履修必須とする計画
V16: 令和８年度以降に履修必須とする計画、又は未定
B20: 必要最低単位数 | C20: 2 | E20: 単位 | J20: 履修必須の有無 | K20: 令和７年度までに履修必須とする計画
A22: ④ 現在進行中の社会変化（第４次産業革命、Society 5.0、データ駆動型社会等）に深く寄与しているものであり、それが自らの生活と密接に結びついている」の内容を含む授業科目
B24: 授業科目 | F24: 単位数 | G24: 必須 | H24: 1-1 | I24: 1-6 | J24: 授業科目 | P24: 単位数 | Q24: 必須 | R24: 1-1 | S24: 1-6
B25: コンピュータ基礎演習Ⅱ | F25: 2 | G25: ○ | H25: ○ | I25: ○
A33: ⑤ 「社会で活用されているデータ」や「データの活用領域」は非常に広範囲であって、日常生活や社会の課題を解決する有用なツールになり得るもの」の内容を含む授業科目
B35: 授業科目 | F35: 単位数 | G35: 必須 | H35: 1-2 | I35: 1-3 | J35: 授業科目 | P35: 単位数 | Q35: 必須 | R35: 1-2 | S35: 1-3
B36: コンピュータ基礎演習Ⅱ | F36: 2 | G36: ○ | H36: ○ | I36: ○
A44: ⑥ 「様々なデータ利活用の現場におけるデータ利活用事例が示され、様々な適用領域（流通、製造、金融、サービス、インフラ、公共、ヘルスケア等）の知見と組み合わせることで価値を創出するもの」の内容を含む授業科目
B46: 授業科目 | F46: 単位数 | G46: 必須 | H46: 1-4 | I46: 1-5 | J46: 授業科目 | P46: 単位数 | Q46: 必須 | R46: 1-4 | S46: 1-5
B47: コンピュータ基礎演習Ⅱ | F47: 2 | G47: ○ | H47: ○ | I47: ○
A55: ⑦ 「活用に当たっての様々な留意事項（ELSI、個人情報、データ倫理、ＡＩ社会原則等）を考慮し、情報セキュリティや情報漏洩等、データを守る上での留意事項への理解をする」の内容を含む授業科目
B57: 授業科目 | F57: 単位数 | G57: 必須 | H57: 3-1 | I57: 3-2 | J57: 授業科目 | P57: 単位数 | Q57: 必須 | R57: 3-1 | S57: 3-2
B58: コンピュータ基礎演習Ⅱ | F58: 2 | G58: ○ | H58: ○ | I58: ○
A66: ⑧ 「実データ・実課題（学術データ等を含む）を用いた演習など、社会での実例を題材として、「データを読む、説明する、扱う」といった数理・データサイエンス・ＡＩの基本的な活用法に関するもの」の内容を含む授業科目
B68: 授業科目 | E68: 単位数 | F68: 必須 | G68: 2-1 | H68: 2-2 | I68: 2-3 | J68: 授業科目 | O68: 単位数 | P68: 必須 | Q68: 2-1 | R68: 2-2 | S68: 2-3
B69: コンピュータ基礎演習Ⅱ | E69: 2 | F69: ○ | G69: ○ | H69: ○ | I69: ○
A77: ⑨ 選択「４．オプション」の内容を含む授業科目
B78: 授業科目 | F78: 選択項目 | J78: 授業科目 | P78: 選択項目
A87: ⑩ プログラムを構成する授業の内容
B88: 授業に含まれている内容・要素 | D88: 講義内容
B89: （１）現在進行中の社会変化（第４次産業革命、Society 5.0、データ駆動型社会等）に深く寄与しているものであり、それが自らの生活と密接に結びついている | C89: 1-1 | D89: ビッグデータ、IoT、AI、ロボット、第4次産業革命、Society 5.0、データ駆動型社会、複数技術を組み合わせたAIサービス、人間の知的活動とAIの関係性、データを起点としたものの見方について学ぶ 「コンピュータ基礎演習Ⅱ」（スポーツ科学部 第２回）（栄養学部 第１回）  データサイエンスやAIとはどういう分野なのか、なぜ社会の関⼼を集めているのか  社会におけるデータ・AIの利活⽤例を幅広く学ぶことで、社会で起きている変化を知り、データサイエンスやAIを学ぶことの意義を理解することを⽬標とする  特にAIを活⽤した新しいビジネスやサービスは、複数の技術が組み合わさって実現していることに注⽬する
C90: 1-6 | D90: AI等を活用した新しいビジネスモデル(シェアリングエコノミー、商品のレコメンデーションなど)、AI最新技術の活用例（深層生成モデル、敵対的生成ネットワーク、強化学習、転移学習など）について学ぶ 「コンピュータ基礎演習Ⅱ」（スポーツ科学部 第７回）（栄養学部 第１回・第１２回）  データサイエンスの最先端ではどのような研究開発が行われているのか、いくつか先端的な技術を紹介する  データ・AI利活用における新技術と最新動向を知ることを目標とする
B91: （２）「社会で活用されているデータ」や「データの活用領域」は非常に広範囲であって、日常生活や社会の課題を解決する有用なツールになり得るもの | C91: 1-2 | D91: 構造化データ、非構造化データ（文章、画像/動画、音声/音楽など）、データのオープン化（オープンデータ）について学ぶ 「コンピュータ基礎演習Ⅱ」（スポーツ科学部 第３回）（栄養学部 第３回・第８回） どういうデータがデータサイエンスでは用いられるのか  代表的なデータをいくつか見ていくことで、どういうデータが集められ、どう活用されているかを知ることを目標とする
C92: 1-3 | D92: データ・AI活用領域の広がり(生産、消費、文化活動など)、研究開発、調達、製造、物流、販売、マーケティング、サービスなどについて学ぶ 「コンピュータ基礎演習Ⅱ」（スポーツ科学部 第４回）（栄養学部 第２回・第９,１０回）  データサイエンスやAIはどのように活用されているのか  いくつかの例を見ることで、さまざまな領域でデータ・AIが活用されていることを知ることを目標とする
B93: （３）様々なデータ利活用の現場におけるデータ利活用事例が示され、様々な適用領域（流通、製造、金融、サービス、インフラ、公共、ヘルスケア等）の知見と組み合わせることで価値を創出するもの | C93: 1-4 | D93: 非構造化データ処理：言語処理、画像/動画処理、音声/音楽処理などについて学ぶ 「コンピュータ基礎演習Ⅱ」（スポーツ科学部 第５回）（栄養学部 第４回）  データサイエンスやAI利活用の現場ではどういう技術が用いられるのか  基本的なものを見ていくことで、データ・AIを活用するために使われている技術の概要を知ることを目標とする
C94: 1-5 | D94: データサイエンスのサイクル（課題抽出と定式化、データの取得・管理・加工、探索的データ解析、データ解析と推論、結果の共有・伝達、課題解決に向けた提案）、流通、製造、金融、サービス、インフラ、公共、ヘルスケア等におけるデータ・AI利活用事例について学ぶ 「コンピュータ基礎演習Ⅱ」（スポーツ科学部 第６回）（栄養学部 第１０回）  データサイエンティストの仕事の流れとは具体的にどのようなものなのか  データ・AIを活用することによって、どのような価値が生まれているかを知ることを目標とする
B95: （４）活用に当たっての様々な留意事項（ELSI、個人情報、データ倫理、ＡＩ社会原則等）を考慮し、情報セキュリティや情報漏洩等、データを守る上での留意事項への理解をする | C95: 3-1 | D95: ELSI（Ethical, Legal and Social Issues）、個人情報保護、EU一般データ保護規則(GDPR)、忘れられる権利、オプトアウト、データ倫理：データのねつ造、改ざん、盗用、プライバシー保護、AI社会原則（公平性、説明責任、透明性、人間中心の判断）、データバイアス、アルゴリズムバイアス、AIサービスの責任論、データ・AI活用における負の事例について学ぶ 「コンピュータ基礎演習Ⅱ」（スポーツ科学部 第１１回）（栄養学部 第１回）  データやAIは，強⼒な道具であるだけに，使い⽅を誤ると⼈間や社会に⼤きなダメージを与えるおそれがある  データやAIを使うにあたり最低限気をつけるべきことについて学ぶ
C96: 3-2 | D96: 情報セキュリティ：機密性、完全性、可用性、匿名加工情報、暗号化、パスワード、悪意ある情報搾取、情報漏洩等によるセキュリティ事故の事例について学ぶ 「コンピュータ基礎演習Ⅱ」（スポーツ科学部 第１２回）（栄養学部 第９回）  3-1の具体例として、データやAIにまつわる基本的な倫理，合意事項について学ぶ  そして、 データを守ること，およびそれが破られて起こった事例について学ぶ
B97: （５）実データ・実課題（学術データ等を含む）を用いた演習など、社会での実例を題材として、「データを読む、説明する、扱う」といった数理・データサイエンス・ＡＩの基本的な活用法に関するもの | C97: 2-1 | D97: データの種類（量的変数、質的変数）、データの分布(ヒストグラム)と代表値（平均値、中央値、最頻値）、代表値の性質の違い（実社会では平均値＝最頻値でないことが多い）、データのばらつき（分散、標準偏差、偏差値）、母集団と標本抽出（国勢調査、アンケート調査、全数調査、単純無作為抽出、層別抽出、多段抽出）、統計情報の正しい理解（誇張表現に惑わされない）について学ぶ 「コンピュータ基礎演習Ⅱ」（スポーツ科学部 第８回）（栄養学部 第６,７回・第１０,１１回）  データを要約したり可視化したりする様々な手法について学ぶことで、事象の背景や意味合いを理解することを目標とする  これらの情報を読む上で注意すべきいくつかの点についても学ぶ  データを正しく読む上では、データがどのような背景から得られたものなのかを正しく理解することも重要であることを知る
...

Sheet 様式１-３　プログラムを構成する授業科目
R1: 様式１－３ | T1: 「学部・学科によって、修了要件は相違する」場合は、本シートを複製の上＜様式１－〇＞と枝番号を付してください
B2: 大学等名 | C2: 金沢学院大学
B3: プログラム名 | C3: 数理・データサイエンス・AI教育プログラム
A5: プログラムを構成する授業科目について
A7: ① 対象となる学部・学科名称 | J7: ② 教育プログラムの修了要件 | K7: 学部・学科によって、修了要件は相違する
B9: 経済学部、経済情報学部
A12: ③ 修了要件
B13: 数理データサイエンスAI教育プログラムを構成する科目のうち、「コンピュータ基礎演習IIa」（１単位）および「コンピュータ基礎演習IIb」（１単位）を取得すること。 | V13: 【プルダウンリスト】
V14: 令和４年度以前より、履修することが必須のプログラムとして実施
V15: 令和７年度までに履修必須とする計画
V16: 令和８年度以降に履修必須とする計画、又は未定
B20: 必要最低単位数 | C20: 2 | E20: 単位 | J20: 履修必須の有無 | K20: 令和７年度までに履修必須とする計画
A22: ④ 現在進行中の社会変化（第４次産業革命、Society 5.0、データ駆動型社会等）に深く寄与しているものであり、それが自らの生活と密接に結びついている」の内容を含む授業科目
B24: 授業科目 | F24: 単位数 | G24: 必須 | H24: 1-1 | I24: 1-6 | J24: 授業科目 | P24: 単位数 | Q24: 必須 | R24: 1-1 | S24: 1-6
B25: コンピュータ基礎演習Ⅱａ | F25: 1 | G25: ○ | H25: ○ | I25: ○
A33: ⑤ 「社会で活用されているデータ」や「データの活用領域」は非常に広範囲であって、日常生活や社会の課題を解決する有用なツールになり得るもの」の内容を含む授業科目
B35: 授業科目 | F35: 単位数 | G35: 必須 | H35: 1-2 | I35: 1-3 | J35: 授業科目 | P35: 単位数 | Q35: 必須 | R35: 1-2 | S35: 1-3
B36: コンピュータ基礎演習Ⅱａ | F36: 1 | G36: ○ | H36: ○ | I36: ○
A44: ⑥ 「様々なデータ利活用の現場におけるデータ利活用事例が示され、様々な適用領域（流通、製造、金融、サービス、インフラ、公共、ヘルスケア等）の知見と組み合わせることで価値を創出するもの」の内容を含む授業科目
B46: 授業科目 | F46: 単位数 | G46: 必須 | H46: 1-4 | I46: 1-5 | J46: 授業科目 | P46: 単位数 | Q46: 必須 | R46: 1-4 | S46: 1-5
B47: コンピュータ基礎演習Ⅱａ | F47: 1 | G47: ○ | H47: ○ | I47: ○
A55: ⑦ 「活用に当たっての様々な留意事項（ELSI、個人情報、データ倫理、ＡＩ社会原則等）を考慮し、情報セキュリティや情報漏洩等、データを守る上での留意事項への理解をする」の内容を含む授業科目
B57: 授業科目 | F57: 単位数 | G57: 必須 | H57: 3-1 | I57: 3-2 | J57: 授業科目 | P57: 単位数 | Q57: 必須 | R57: 3-1 | S57: 3-2
B58: コンピュータ基礎演習Ⅱｂ | F58: 1 | G58: ○ | H58: ○ | I58: ○
A66: ⑧ 「実データ・実課題（学術データ等を含む）を用いた演習など、社会での実例を題材として、「データを読む、説明する、扱う」といった数理・データサイエンス・ＡＩの基本的な活用法に関するもの」の内容を含む授業科目
B68: 授業科目 | E68: 単位数 | F68: 必須 | G68: 2-1 | H68: 2-2 | I68: 2-3 | J68: 授業科目 | O68: 単位数 | P68: 必須 | Q68: 2-1 | R68: 2-2 | S68: 2-3
B69: コンピュータ基礎演習Ⅱａ | E69: 1 | F69: ○ | G69: ○
B70: コンピュータ基礎演習Ⅱｂ | E70: 1 | F70: ○ | H70: ○ | I70: ○
A77: ⑨ 選択「４．オプション」の内容を含む授業科目
B78: 授業科目 | F78: 選択項目 | J78: 授業科目 | P78: 選択項目
A87: ⑩ プログラムを構成する授業の内容
B88: 授業に含まれている内容・要素 | D88: 講義内容
B89: （１）現在進行中の社会変化（第４次産業革命、Society 5.0、データ駆動型社会等）に深く寄与しているものであり、それが自らの生活と密接に結びついている | C89: 1-1 | D89: ビッグデータ、IoT、AI、ロボット、第4次産業革命、Society 5.0、データ駆動型社会、複数技術を組み合わせたAIサービス、人間の知的活動とAIの関係性、データを起点としたものの見方について学ぶ 「コンピュータ基礎演習Ⅱａ」（第１回）  データサイエンスやAIとはどういう分野なのか、なぜ社会の関⼼を集めているのか  社会におけるデータ・AIの利活⽤例を幅広く学ぶことで、社会で起きている変化を知り、データサイエンスやAIを学ぶことの意義を理解することを⽬標とする  特にAIを活⽤した新しいビジネスやサービスは、複数の技術が組み合わさって実現していることに注⽬する
C90: 1-6 | D90: AI等を活用した新しいビジネスモデル(シェアリングエコノミー、商品のレコメンデーションなど)、AI最新技術の活用例（深層生成モデル、敵対的生成ネットワーク、強化学習、転移学習など）について学ぶ 「コンピュータ基礎演習Ⅱａ」（第６回）  データサイエンスの最先端ではどのような研究開発が行われているのか、いくつか先端的な技術を紹介する  データ・AI利活用における新技術と最新動向を知ることを目標とする
B91: （２）「社会で活用されているデータ」や「データの活用領域」は非常に広範囲であって、日常生活や社会の課題を解決する有用なツールになり得るもの | C91: 1-2 | D91: 構造化データ、非構造化データ（文章、画像/動画、音声/音楽など）、データのオープン化（オープンデータ）について学ぶ 「コンピュータ基礎演習Ⅱａ」（第２回） どういうデータがデータサイエンスでは用いられるのか  代表的なデータをいくつか見ていくことで、どういうデータが集められ、どう活用されているかを知ることを目標とする
C92: 1-3 | D92: データ・AI活用領域の広がり(生産、消費、文化活動など)、研究開発、調達、製造、物流、販売、マーケティング、サービスなどについて学ぶ 「コンピュータ基礎演習Ⅱａ」（第３回）  データサイエンスやAIはどのように活用されているのか  いくつかの例を見ることで、さまざまな領域でデータ・AIが活用されていることを知ることを目標とする
B93: （３）様々なデータ利活用の現場におけるデータ利活用事例が示され、様々な適用領域（流通、製造、金融、サービス、インフラ、公共、ヘルスケア等）の知見と組み合わせることで価値を創出するもの | C93: 1-4 | D93: 非構造化データ処理：言語処理、画像/動画処理、音声/音楽処理などについて学ぶ 「コンピュータ基礎演習Ⅱａ」（第４回）  データサイエンスやAI利活用の現場ではどういう技術が用いられるのか  基本的なものを見ていくことで、データ・AIを活用するために使われている技術の概要を知ることを目標とする
C94: 1-5 | D94: データサイエンスのサイクル（課題抽出と定式化、データの取得・管理・加工、探索的データ解析、データ解析と推論、結果の共有・伝達、課題解決に向けた提案）、流通、製造、金融、サービス、インフラ、公共、ヘルスケア等におけるデータ・AI利活用事例について学ぶ 「コンピュータ基礎演習Ⅱａ」（第５回）  データサイエンティストの仕事の流れとは具体的にどのようなものなのか  データ・AIを活用することによって、どのような価値が生まれているかを知ることを目標とする
B95: （４）活用に当たっての様々な留意事項（ELSI、個人情報、データ倫理、ＡＩ社会原則等）を考慮し、情報セキュリティや情報漏洩等、データを守る上での留意事項への理解をする | C95: 3-1 | D95: ELSI（Ethical, Legal and Social Issues）、個人情報保護、EU一般データ保護規則(GDPR)、忘れられる権利、オプトアウト、データ倫理：データのねつ造、改ざん、盗用、プライバシー保護、AI社会原則（公平性、説明責任、透明性、人間中心の判断）、データバイアス、アルゴリズムバイアス、AIサービスの責任論、データ・AI活用における負の事例について学ぶ 「コンピュータ基礎演習Ⅱｂ」（第３回）  データやAIは，強⼒な道具であるだけに，使い⽅を誤ると⼈間や社会に⼤きなダメージを与えるおそれがある  データやAIを使うにあたり最低限気をつけるべきことについて学ぶ
C96: 3-2 | D96: 情報セキュリティ：機密性、完全性、可用性、匿名加工情報、暗号化、パスワード、悪意ある情報搾取、情報漏洩等によるセキュリティ事故の事例について学ぶ 「コンピュータ基礎演習Ⅱｂ」（第４回）  3-1の具体例として、データやAIにまつわる基本的な倫理，合意事項について学ぶ  そして、 データを守ること，およびそれが破られて起こった事例について学ぶ
...

Sheet 様式１-４　プログラムを構成する授業科目
R1: 様式１－４ | T1: 「学部・学科によって、修了要件は相違する」場合は、本シートを複製の上＜様式１－〇＞と枝番号を付してください
B2: 大学等名 | C2: 金沢学院大学
B3: プログラム名 | C3: 数理データサイエンスAI教育プログラム
A5: プログラムを構成する授業科目について
A7: ① 対象となる学部・学科名称 | J7: ② 教育プログラムの修了要件 | K7: 学部・学科によって、修了要件は相違する
B9: 教育学部
A12: ③ 修了要件
B13: 数理データサイエンスAI教育プログラムを構成する科目のうち、「ICT活用教育概論」（２単位）を取得すること。 | V13: 【プルダウンリスト】
V14: 令和４年度以前より、履修することが必須のプログラムとして実施
V15: 令和７年度までに履修必須とする計画
V16: 令和８年度以降に履修必須とする計画、又は未定
B20: 必要最低単位数 | C20: 2 | E20: 単位 | J20: 履修必須の有無 | K20: 令和４年度以前より、履修することが必須のプログラムとして実施
A22: ④ 現在進行中の社会変化（第４次産業革命、Society 5.0、データ駆動型社会等）に深く寄与しているものであり、それが自らの生活と密接に結びついている」の内容を含む授業科目
B24: 授業科目 | F24: 単位数 | G24: 必須 | H24: 1-1 | I24: 1-6 | J24: 授業科目 | P24: 単位数 | Q24: 必須 | R24: 1-1 | S24: 1-6
B25: ICT活用教育概論 | F25: 2 | G25: ○ | H25: ○ | I25: ○
A33: ⑤ 「社会で活用されているデータ」や「データの活用領域」は非常に広範囲であって、日常生活や社会の課題を解決する有用なツールになり得るもの」の内容を含む授業科目
B35: 授業科目 | F35: 単位数 | G35: 必須 | H35: 1-2 | I35: 1-3 | J35: 授業科目 | P35: 単位数 | Q35: 必須 | R35: 1-2 | S35: 1-3
B36: ICT活用教育概論 | F36: 2 | G36: ○ | H36: ○ | I36: ○
A44: ⑥ 「様々なデータ利活用の現場におけるデータ利活用事例が示され、様々な適用領域（流通、製造、金融、サービス、インフラ、公共、ヘルスケア等）の知見と組み合わせることで価値を創出するもの」の内容を含む授業科目
B46: 授業科目 | F46: 単位数 | G46: 必須 | H46: 1-4 | I46: 1-5 | J46: 授業科目 | P46: 単位数 | Q46: 必須 | R46: 1-4 | S46: 1-5
B47: ICT活用教育概論 | F47: 2 | G47: ○ | H47: ○ | I47: ○
A55: ⑦ 「活用に当たっての様々な留意事項（ELSI、個人情報、データ倫理、ＡＩ社会原則等）を考慮し、情報セキュリティや情報漏洩等、データを守る上での留意事項への理解をする」の内容を含む授業科目
B57: 授業科目 | F57: 単位数 | G57: 必須 | H57: 3-1 | I57: 3-2 | J57: 授業科目 | P57: 単位数 | Q57: 必須 | R57: 3-1 | S57: 3-2
B58: ICT活用教育概論 | F58: 2 | G58: ○ | H58: ○ | I58: ○
A66: ⑧ 「実データ・実課題（学術データ等を含む）を用いた演習など、社会での実例を題材として、「データを読む、説明する、扱う」といった数理・データサイエンス・ＡＩの基本的な活用法に関するもの」の内容を含む授業科目
B68: 授業科目 | E68: 単位数 | F68: 必須 | G68: 2-1 | H68: 2-2 | I68: 2-3 | J68: 授業科目 | O68: 単位数 | P68: 必須 | Q68: 2-1 | R68: 2-2 | S68: 2-3
B69: ICT活用教育概論 | E69: 2 | F69: ○ | G69: ○ | H69: ○ | I69: ○
A77: ⑨ 選択「４．オプション」の内容を含む授業科目
B78: 授業科目 | F78: 選択項目 | J78: 授業科目 | P78: 選択項目
A87: ⑩ プログラムを構成する授業の内容
B88: 授業に含まれている内容・要素 | D88: 講義内容
B89: （１）現在進行中の社会変化（第４次産業革命、Society 5.0、データ駆動型社会等）に深く寄与しているものであり、それが自らの生活と密接に結びついている | C89: 1-1 | D89: ビッグデータ、IoT、AI、ロボット、第4次産業革命、Society 5.0、データ駆動型社会、複数技術を組み合わせたAIサービス、人間の知的活動とAIの関係性、データを起点としたものの見方について学ぶ 「ICT活用教育概論」（第１回）  データサイエンスやAIとはどういう分野なのか、なぜ社会の関⼼を集めているのか  社会におけるデータ・AIの利活⽤例を幅広く学ぶことで、社会で起きている変化を知り、データサイエンスやAIを学ぶことの意義を理解することを⽬標とする  特にAIを活⽤した新しいビジネスやサービスは、複数の技術が組み合わさって実現していることに注⽬する
C90: 1-6 | D90: AI等を活用した新しいビジネスモデル(シェアリングエコノミー、商品のレコメンデーションなど)、AI最新技術の活用例（深層生成モデル、敵対的生成ネットワーク、強化学習、転移学習など）について学ぶ 「ICT活用教育概論」（第６回）  データサイエンスの最先端ではどのような研究開発が行われているのか、いくつか先端的な技術を紹介する  データ・AI利活用における新技術と最新動向を知ることを目標とする
B91: （２）「社会で活用されているデータ」や「データの活用領域」は非常に広範囲であって、日常生活や社会の課題を解決する有用なツールになり得るもの | C91: 1-2 | D91: 構造化データ、非構造化データ（文章、画像/動画、音声/音楽など）、データのオープン化（オープンデータ）について学ぶ 「ICT活用教育概論」（第２回） どういうデータがデータサイエンスでは用いられるのか  代表的なデータをいくつか見ていくことで、どういうデータが集められ、どう活用されているかを知ることを目標とする
C92: 1-3 | D92: データ・AI活用領域の広がり(生産、消費、文化活動など)、研究開発、調達、製造、物流、販売、マーケティング、サービスなどについて学ぶ 「ICT活用教育概論」（第３回）  データサイエンスやAIはどのように活用されているのか  いくつかの例を見ることで、さまざまな領域でデータ・AIが活用されていることを知ることを目標とする
B93: （３）様々なデータ利活用の現場におけるデータ利活用事例が示され、様々な適用領域（流通、製造、金融、サービス、インフラ、公共、ヘルスケア等）の知見と組み合わせることで価値を創出するもの | C93: 1-4 | D93: 非構造化データ処理：言語処理、画像/動画処理、音声/音楽処理などについて学ぶ 「ICT活用教育概論」（第４回）  データサイエンスやAI利活用の現場ではどういう技術が用いられるのか  基本的なものを見ていくことで、データ・AIを活用するために使われている技術の概要を知ることを目標とする
C94: 1-5 | D94: データサイエンスのサイクル（課題抽出と定式化、データの取得・管理・加工、探索的データ解析、データ解析と推論、結果の共有・伝達、課題解決に向けた提案）、流通、製造、金融、サービス、インフラ、公共、ヘルスケア等におけるデータ・AI利活用事例について学ぶ 「ICT活用教育概論」（第５回）  データサイエンティストの仕事の流れとは具体的にどのようなものなのか  データ・AIを活用することによって、どのような価値が生まれているかを知ることを目標とする
B95: （４）活用に当たっての様々な留意事項（ELSI、個人情報、データ倫理、ＡＩ社会原則等）を考慮し、情報セキュリティや情報漏洩等、データを守る上での留意事項への理解をする | C95: 3-1 | D95: ELSI（Ethical, Legal and Social Issues）、個人情報保護、EU一般データ保護規則(GDPR)、忘れられる権利、オプトアウト、データ倫理：データのねつ造、改ざん、盗用、プライバシー保護、AI社会原則（公平性、説明責任、透明性、人間中心の判断）、データバイアス、アルゴリズムバイアス、AIサービスの責任論、データ・AI活用における負の事例について学ぶ 「ICT活用教育概論」（第１４回）  データやAIは，強⼒な道具であるだけに，使い⽅を誤ると⼈間や社会に⼤きなダメージを与えるおそれがある  データやAIを使うにあたり最低限気をつけるべきことについて学ぶ
C96: 3-2 | D96: 情報セキュリティ：機密性、完全性、可用性、匿名加工情報、暗号化、パスワード、悪意ある情報搾取、情報漏洩等によるセキュリティ事故の事例について学ぶ 「ICT活用教育概論」（第１５回）  3-1の具体例として、データやAIにまつわる基本的な倫理，合意事項について学ぶ  そして、 データを守ること，およびそれが破られて起こった事例について学ぶ
B97: （５）実データ・実課題（学術データ等を含む）を用いた演習など、社会での実例を題材として、「データを読む、説明する、扱う」といった数理・データサイエンス・ＡＩの基本的な活用法に関するもの | C97: 2-1 | D97: データの種類（量的変数、質的変数）、データの分布(ヒストグラム)と代表値（平均値、中央値、最頻値）、代表値の性質の違い（実社会では平均値＝最頻値でないことが多い）、データのばらつき（分散、標準偏差、偏差値）、母集団と標本抽出（国勢調査、アンケート調査、全数調査、単純無作為抽出、層別抽出、多段抽出）、統計情報の正しい理解（誇張表現に惑わされない）について学ぶ 「ICT活用教育概論」（第７回）  データを要約したり可視化したりする様々な手法について学ぶことで、事象の背景や意味合いを理解することを目標とする  これらの情報を読む上で注意すべきいくつかの点についても学ぶ  データを正しく読む上では、データがどのような背景から得られたものなのかを正しく理解することも重要であることを知る
...

Sheet 様式２ 履修者等数の実績
AQ1: 様式２
AL2: 大学等名 | AM2: ='様式１-３ プログラムを構成する授業科目'!C2 -> 金沢学院大学
A3: プログラムの履修者数等の実績について
A5: ①プログラム開設年度 | C5: 令和4 | E5: 年度
A7: ②履修者・修了者の実績
B9: 学部・学科名称 | C9: 学生数 | D9: 入学 定員 | E9: 収容 定員 | F9: 令和4年度 | L9: 令和3年度 | R9: 令和2年度 | X9: 令和元年度 | AD9: 平成30年度 | AJ9: 平成29年度 | AP9: 履修者数 合計 | AQ9: 履修率
F10: 履修者数 | I10: 修了者数 | L10: 履修者数 | O10: 修了者数 | R10: 履修者数 | U10: 修了者数 | X10: 履修者数 | AA10: 修了者数 | AD10: 履修者数 | AG10: 修了者数 | AJ10: 履修者数 | AM10: 修了者数
F11: 合計 | G11: 男性 | H11: 女性 | I11: 合計 | J11: 男性 | K11: 女性 | L11: 合計 | M11: 男性 | N11: 女性 | O11: 合計 | P11: 男性 | Q11: 女性 | R11: 合計 | S11: 男性 | T11: 女性 | U11: 合計 | V11: 男性 | W11: 女性 | X11: 合計 | Y11: 男性 | Z11: 女性 | AA11: 合計 | AB11: 男性 | AC11: 女性 | AD11: 合計 | AE11: 男性 | AF11: 女性 | AG11: 合計 | AH11: 男性 | AI11: 女性 | AJ11: 合計 | AK11: 男性 | AL11: 女性 | AM11: 合計 | AN11: 男性 | AO11: 女性
B12: 文学部 | C12: 1012 | D12: 180 | E12: 926 | F12: =SUM(G12:H12) -> 188 | G12: 95 | H12: 93 | I12: =J12+K12 -> 176 | J12: 88 | K12: 88 | L12: =M12+N12 -> 0 | O12: =P12+Q12 -> 0 | R12: =S12+T12 -> 0 | U12: =V12+W12 -> 0 | X12: =Y12+Z12 -> 0 | AA12: =AB12+AC12 -> 0 | AD12: =AE12+AF12 -> 0 | AG12: =AH12+AI12 -> 0 | AJ12: =AK12+AL12 -> 0 | AM12: =AN12+AO12 -> 0 | AP12: =F12+L12+R12+X12+AD12+AJ12 -> 188 | AQ12: =AP12/E12 -> 0.20302376
B13: 教育学部 | C13: 72 | D13: 70 | E13: 70 | F13: =SUM(G13:H13) -> 70 | G13: 30 | H13: 40 | I13: =J13+K13 -> 67 | J13: 29 | K13: 38 | L13: =M13+N13 -> 0 | O13: =P13+Q13 -> 0 | R13: =S13+T13 -> 0 | U13: =V13+W13 -> 0 | X13: =Y13+Z13 -> 0 | AA13: =AB13+AC13 -> 0 | AD13: =AE13+AF13 -> 0 | AG13: =AH13+AI13 -> 0 | AJ13: =AK13+AL13 -> 0 | AM13: =AN13+AO13 -> 0 | AP13: =F13+L13+R13+X13+AD13+AJ13 -> 70 | AQ13: =AP13/E13 -> 1
B14: 経済学部 | C14: 518 | D14: 180 | E14: 470 | F14: =SUM(G14:H14) -> 200 | G14: 171 | H14: 29 | I14: =J14+K14 -> 154 | J14: 128 | K14: 26 | L14: =M14+N14 -> 0 | O14: =P14+Q14 -> 0 | R14: =S14+T14 -> 0 | U14: =V14+W14 -> 0 | X14: =Y14+Z14 -> 0 | AA14: =AB14+AC14 -> 0 | AD14: =AE14+AF14 -> 0 | AG14: =AH14+AI14 -> 0 | AJ14: =AK14+AL14 -> 0 | AM14: =AN14+AO14 -> 0 | AP14: =F14+L14+R14+X14+AD14+AJ14 -> 200 | AQ14: =AP14/E14 -> 0.42553191
B15: 経済情報学部 | C15: 229 | D15: 70 | E15: 210 | F15: =SUM(G15:H15) -> 73 | G15: 70 | H15: 3 | I15: =J15+K15 -> 69 | J15: 66 | K15: 3 | L15: =M15+N15 -> 0 | O15: =P15+Q15 -> 0 | R15: =S15+T15 -> 0 | U15: =V15+W15 -> 0 | X15: =Y15+Z15 -> 0 | AA15: =AB15+AC15 -> 0 | AD15: =AE15+AF15 -> 0 | AG15: =AH15+AI15 -> 0 | AJ15: =AK15+AL15 -> 0 | AM15: =AN15+AO15 -> 0 | AP15: =F15+L15+R15+X15+AD15+AJ15 -> 73 | AQ15: =AP15/E15 -> 0.34761905
B16: 芸術学部 | C16: 322 | D16: 70 | E16: 284 | F16: =SUM(G16:H16) -> 72 | G16: 27 | H16: 45 | I16: =J16+K16 -> 68 | J16: 27 | K16: 41 | L16: =M16+N16 -> 0 | O16: =P16+Q16 -> 0 | R16: =S16+T16 -> 0 | U16: =V16+W16 -> 0 | X16: =Y16+Z16 -> 0 | AA16: =AB16+AC16 -> 0 | AD16: =AE16+AF16 -> 0 | AG16: =AH16+AI16 -> 0 | AJ16: =AK16+AL16 -> 0 | AM16: =AN16+AO16 -> 0 | AP16: =F15+L16+R16+X16+AD16+AJ16 -> 73 | AQ16: =AP16/E15 -> 0.34761905
B17: スポーツ科学部 | C17: 341 | D17: 150 | E17: 300 | F17: =SUM(G17:H17) -> 152 | G17: 118 | H17: 34 | I17: =J17+K17 -> 142 | J17: 109 | K17: 33 | L17: =M17+N17 -> 0 | O17: =P17+Q17 -> 0 | R17: =S17+T17 -> 0 | U17: =V17+W17 -> 0 | X17: =Y17+Z17 -> 0 | AA17: =AB17+AC17 -> 0 | AD17: =AE17+AF17 -> 0 | AG17: =AH17+AI17 -> 0 | AJ17: =AK17+AL17 -> 0 | AM17: =AN17+AO17 -> 0 | AP17: =F16+L17+R17+X17+AD17+AJ17 -> 72 | AQ17: =AP17/E16 -> 0.25352113
B18: 栄養学部 | C18: 167 | D18: 80 | E18: 160 | F18: =SUM(G18:H18) -> 10 | G18: 4 | H18: 6 | I18: =J18+K18 -> 10 | J18: 4 | K18: 6 | L18: =M18+N18 -> 0 | O18: =P18+Q18 -> 0 | R18: =S18+T18 -> 0 | U18: =V18+W18 -> 0 | X18: =Y18+Z18 -> 0 | AA18: =AB18+AC18 -> 0 | AD18: =AE18+AF18 -> 0 | AG18: =AH18+AI18 -> 0 | AJ18: =AK18+AL18 -> 0 | AM18: =AN18+AO18 -> 0 | AP18: =F17+L18+R18+X18+AD18+AJ18 -> 152 | AQ18: =AP18/E17 -> 0.50666667
F19: =G19+H19 -> 0 | I19: =J19+K19 -> 0 | L19: =M19+N19 -> 0 | O19: =P19+Q19 -> 0 | R19: =S19+T19 -> 0 | U19: =V19+W19 -> 0 | X19: =Y19+Z19 -> 0 | AA19: =AB19+AC19 -> 0 | AD19: =AE19+AF19 -> 0 | AG19: =AH19+AI19 -> 0 | AJ19: =AK19+AL19 -> 0 | AM19: =AN19+AO19 -> 0 | AP19: =F18+L19+R19+X19+AD19+AJ19 -> 10 | AQ19: =AP19/E18 -> 0.0625
F20: =G20+H20 -> 0 | I20: =J20+K20 -> 0 | L20: =M20+N20 -> 0 | O20: =P20+Q20 -> 0 | R20: =S20+T20 -> 0 | U20: =V20+W20 -> 0 | X20: =Y20+Z20 -> 0 | AA20: =AB20+AC20 -> 0 | AD20: =AE20+AF20 -> 0 | AG20: =AH20+AI20 -> 0 | AJ20: =AK20+AL20 -> 0 | AM20: =AN20+AO20 -> 0 | AP20: =F20+L20+R20+X20+AD20+AJ20 -> 0 | AQ20: =AP20/E20 -> #DIV/0!
F21: =G21+H21 -> 0 | I21: =J21+K21 -> 0 | L21: =M21+N21 -> 0 | O21: =P21+Q21 -> 0 | R21: =S21+T21 -> 0 | U21: =V21+W21 -> 0 | X21: =Y21+Z21 -> 0 | AA21: =AB21+AC21 -> 0 | AD21: =AE21+AF21 -> 0 | AG21: =AH21+AI21 -> 0 | AJ21: =AK21+AL21 -> 0 | AM21: =AN21+AO21 -> 0 | AP21: =F21+L21+R21+X21+AD21+AJ21 -> 0 | AQ21: =AP21/E21 -> #DIV/0!
F22: =G22+H22 -> 0 | I22: =J22+K22 -> 0 | L22: =M22+N22 -> 0 | O22: =P22+Q22 -> 0 | R22: =S22+T22 -> 0 | U22: =V22+W22 -> 0 | X22: =Y22+Z22 -> 0 | AA22: =AB22+AC22 -> 0 | AD22: =AE22+AF22 -> 0 | AG22: =AH22+AI22 -> 0 | AJ22: =AK22+AL22 -> 0 | AM22: =AN22+AO22 -> 0 | AP22: =F22+L22+R22+X22+AD22+AJ22 -> 0 | AQ22: =AP22/E22 -> #DIV/0!
F23: =G23+H23 -> 0 | I23: =J23+K23 -> 0 | L23: =M23+N23 -> 0 | O23: =P23+Q23 -> 0 | R23: =S23+T23 -> 0 | U23: =V23+W23 -> 0 | X23: =Y23+Z23 -> 0 | AA23: =AB23+AC23 -> 0 | AD23: =AE23+AF23 -> 0 | AG23: =AH23+AI23 -> 0 | AJ23: =AK23+AL23 -> 0 | AM23: =AN23+AO23 -> 0 | AP23: =F23+L23+R23+X23+AD23+AJ23 -> 0 | AQ23: =AP23/E23 -> #DIV/0!
F24: =G24+H24 -> 0 | I24: =J24+K24 -> 0 | L24: =M24+N24 -> 0 | O24: =P24+Q24 -> 0 | R24: =S24+T24 -> 0 | U24: =V24+W24 -> 0 | X24: =Y24+Z24 -> 0 | AA24: =AB24+AC24 -> 0 | AD24: =AE24+AF24 -> 0 | AG24: =AH24+AI24 -> 0 | AJ24: =AK24+AL24 -> 0 | AM24: =AN24+AO24 -> 0 | AP24: =F24+L24+R24+X24+AD24+AJ24 -> 0 | AQ24: =AP24/E24 -> #DIV/0!
F25: =G25+H25 -> 0 | I25: =J25+K25 -> 0 | L25: =M25+N25 -> 0 | O25: =P25+Q25 -> 0 | R25: =S25+T25 -> 0 | U25: =V25+W25 -> 0 | X25: =Y25+Z25 -> 0 | AA25: =AB25+AC25 -> 0 | AD25: =AE25+AF25 -> 0 | AG25: =AH25+AI25 -> 0 | AJ25: =AK25+AL25 -> 0 | AM25: =AN25+AO25 -> 0 | AP25: =F25+L25+R25+X25+AD25+AJ25 -> 0 | AQ25: =AP25/E25 -> #DIV/0!
F26: =G26+H26 -> 0 | I26: =J26+K26 -> 0 | L26: =M26+N26 -> 0 | O26: =P26+Q26 -> 0 | R26: =S26+T26 -> 0 | U26: =V26+W26 -> 0 | X26: =Y26+Z26 -> 0 | AA26: =AB26+AC26 -> 0 | AD26: =AE26+AF26 -> 0 | AG26: =AH26+AI26 -> 0 | AJ26: =AK26+AL26 -> 0 | AM26: =AN26+AO26 -> 0 | AP26: =F26+L26+R26+X26+AD26+AJ26 -> 0 | AQ26: =AP26/E26 -> #DIV/0!
F27: =G27+H27 -> 0 | I27: =J27+K27 -> 0 | L27: =M27+N27 -> 0 | O27: =P27+Q27 -> 0 | R27: =S27+T27 -> 0 | U27: =V27+W27 -> 0 | X27: =Y27+Z27 -> 0 | AA27: =AB27+AC27 -> 0 | AD27: =AE27+AF27 -> 0 | AG27: =AH27+AI27 -> 0 | AJ27: =AK27+AL27 -> 0 | AM27: =AN27+AO27 -> 0 | AP27: =F27+L27+R27+X27+AD27+AJ27 -> 0 | AQ27: =AP27/E27 -> #DIV/0!
F28: =G28+H28 -> 0 | I28: =J28+K28 -> 0 | L28: =M28+N28 -> 0 | O28: =P28+Q28 -> 0 | R28: =S28+T28 -> 0 | U28: =V28+W28 -> 0 | X28: =Y28+Z28 -> 0 | AA28: =AB28+AC28 -> 0 | AD28: =AE28+AF28 -> 0 | AG28: =AH28+AI28 -> 0 | AJ28: =AK28+AL28 -> 0 | AM28: =AN28+AO28 -> 0 | AP28: =F28+L28+R28+X28+AD28+AJ28 -> 0 | AQ28: =AP28/E28 -> #DIV/0!
F29: =G29+H29 -> 0 | I29: =J29+K29 -> 0 | L29: =M29+N29 -> 0 | O29: =P29+Q29 -> 0 | R29: =S29+T29 -> 0 | U29: =V29+W29 -> 0 | X29: =Y29+Z29 -> 0 | AA29: =AB29+AC29 -> 0 | AD29: =AE29+AF29 -> 0 | AG29: =AH29+AI29 -> 0 | AJ29: =AK29+AL29 -> 0 | AM29: =AN29+AO29 -> 0 | AP29: =F29+L29+R29+X29+AD29+AJ29 -> 0 | AQ29: =AP29/E29 -> #DIV/0!
F30: =G30+H30 -> 0 | I30: =J30+K30 -> 0 | L30: =M30+N30 -> 0 | O30: =P30+Q30 -> 0 | R30: =S30+T30 -> 0 | U30: =V30+W30 -> 0 | X30: =Y30+Z30 -> 0 | AA30: =AB30+AC30 -> 0 | AD30: =AE30+AF30 -> 0 | AG30: =AH30+AI30 -> 0 | AJ30: =AK30+AL30 -> 0 | AM30: =AN30+AO30 -> 0 | AP30: =F30+L30+R30+X30+AD30+AJ30 -> 0 | AQ30: =AP30/E30 -> #DIV/0!
F31: =G31+H31 -> 0 | I31: =J31+K31 -> 0 | L31: =M31+N31 -> 0 | O31: =P31+Q31 -> 0 | R31: =S31+T31 -> 0 | U31: =V31+W31 -> 0 | X31: =Y31+Z31 -> 0 | AA31: =AB31+AC31 -> 0 | AD31: =AE31+AF31 -> 0 | AG31: =AH31+AI31 -> 0 | AJ31: =AK31+AL31 -> 0 | AM31: =AN31+AO31 -> 0 | AP31: =F31+L31+R31+X31+AD31+AJ31 -> 0 | AQ31: =AP31/E31 -> #DIV/0!
B32: 合 計 | C32: =SUM(C12:C31) -> 2661 | D32: =SUM(D12:D31) -> 800 | E32: =SUM(E12:E31) -> 2420 | F32: =SUM(F12:F31) -> 765 | G32: =SUM(G12:G31) -> 515 | H32: =SUM(H12:H31) -> 250 | I32: =SUM(I12:I31) -> 686 | J32: =SUM(J12:J31) -> 451 | ... AP32: =SUM(AP12:AP31) -> 838 | AQ32: =AP32/E32 -> 0.34628099

Sheet 様式３ 教育の質・履修者数を向上させるための体制・計画
I1: 様式３
G2: 大学等名 | H2: ='様式１-３ プログラムを構成する授業科目'!C2 -> 金沢学院大学
A4: 教育の質・履修者数を向上させるための体制・計画について
A6: ① | B6: 全学の教員数 | C6: (常勤） | E6: 129 | F6: 人 | G6: （非常勤） | H6: 54 | I6: 人
A8: ② | B8: プログラムの授業を教えている教員数 | H8: 18 | I8: 人
A10: ③ | B10: プログラムの運営責任者
B11: （責任者名） | C11: 水洞 幸夫 | G11: （役職名） | H11: 副学長/全学教務委員長
A13: ④ | B13: プログラムを改善・進化させるための体制（委員会・組織等）
B14: 全学教務委員会
B16: （責任者名） | C16: 水洞 幸夫 | G16: （役職名） | H16: 副学長/全学教務委員長
A18: ⑤ | B18: プログラムを改善・進化させるための体制を定める規則名称
B19: 全学教務委員会規程
A21: ⑥ | B21: 体制の目的
B22: 本学学生が、数理・データサイエンス・AIに関するリテラシーを修得し、データの利活用により社会の課題の発見や解決する力を育成することを目的に、全学的な数理・データサイエンス・AI教育プログラムを実施する。本教育プログラムの実施にあたっては、学長・副学長の下、全学的な組織である全学教務委員会にて企画・運用および学修成果等を元に自己点検・評価を行うこととする。本プログラムの教育内容の改善や教育課程の編成について定期的に各学部から報告・提案を受け審議するとともに、その運用に関わる全学LMSの整備等に関しては本プログラムが円滑に実施されるよう全学情報システム運用委員会、総務部情報システム室、教務部と必要に応じて連携する体制を敷いている。
A34: ⑦ | B34: 具体的な構成員
B35: 学長： 秋山 稔 教授 副学長/全学教務委員長： 水洞 幸夫 教授 文学部長/文学部教務委員長： 蔀 際子 教授 教育学部教務委員長： 笠間 弘美 教授 経済学部長/経済学部教務委員長： 豊田 欣吾 教授 経済情報学部教務委員長： 藤本 祥二 教授 芸術学部長/芸術学部教務委員長： 飯田 栄治 教授 スポーツ科学部教務委員長： 外山 寛 教授 栄養学部教務委員長： 七尾 由美子 教授 短期大学教学部長： 河内 久美子 教授
A48: ⑧ | B48: 履修者数・履修率の向上に向けた計画 ※様式１の「履修必須の有無」で「計画がある」としている場合は詳細について記載すること
B49: 令和４年度実績 | C49: ='様式２ 履修者等数の実績'!AQ32 -> 0.34628099 | E49: 令和５年度予定 | F49: 0.6 | H49: 令和６年度予定 | I49: 0.8
B50: 令和７年度予定 | C50: 0.9 | E50: 令和８年度予定 | F50: 1 | H50: 収容定員（名） | I50: ='様式２ 履修者等数の実績'!E32 -> 2420
B51: 具体的な計画
B52: 本学の数理データサイエンスAI教育プログラムを構成する科目のうち、令和4年度以前までに必修科目とされていたのは文学部・芸術学部における「コンピュータ基礎演習Ⅱ」、教育学部における「ＩＣＴ活用教育概論」に限られていた。このことから収容定員に対する履修率が３５％となっている。これまで選択科目であったスポーツ科学部、栄養学部における「コンピュータ基礎演習Ⅱ」、経済学部、経済情報学部における「コンピュータ基礎演習Ⅱa」「コンピュータ基礎演習Ⅱｂ」を令和５年度から必修科目とすることとした。これを受け、本プログラムの対象科目全てが必修科目となり、原則として令和５年度以降の入学生数が履修者数となるため、収容定員に対する履修率の向上を見込んでいる。これに従い本プログラムを実施していくことで、年度を経る度に段階的に履修率は向上し、令和７年度には１～３年生において100％（全学年において90％）に達し、全科目が必修となった際の履修者が４年生となる令和８年度に履修率は100％となるよう計画している。
A65: ⑨ | B65: 学部・学科に関係なく希望する学生全員が受講可能となるような必要な体制・取組等
B66: ⑧に記載の通り、本学の数理データサイエンスAI教育プログラムを構成する科目の全てが必修科目として設定されたことから、今後は全学部・学科において卒業要件として全員履修することが前提となった。令和５年度以降の入学生については原則、１年次後期での履修率が１００％となる見込みである。現状においては、本学が実施しているBYODによる１人１端末で受講することを基本としているが、状況に応じてオンライン授業の併用も可能としている。また、学生端末が故障等の理由で使用できなくなった場合には、教室に備えられているコンピュータを使用するほか、貸し出し用のノートパソコンを活用し、履修者の学びを支援する体制となっている。
A79: ⑩ | B79: できる限り多くの学生が履修できるような具体的な周知方法・取組
B80: ⑧⑨に記載の通り、本学の数理データサイエンスAI教育プログラムを構成する科目の全てが必修科目として設定されたことから、今後は全学部・学科において卒業要件として全員履修することが前提となった。令和５年度以降の入学生については原則、１年次後期での履修率が１００％となる見込みである。入学直後に毎年度実施される入学生ガイダンスにおいて本プログラムの内容をアナウンスし、その意義と各学部の教育課程内での位置づけを確認している他、対象科目の開講時期に先立つ個別面談においても各学生のアドバイザーとなっている教員によって再度口頭で確認を行っている。また、全学生への情報提示・配信が可能な本学専用の修学支援・管理システムを利用し、各学部ごとに本プログラムについて発信することで情報提供を行っている。
A93: ⑪ | B93: できる限り多くの学生が履修・修得できるようなサポート体制
B94: ⑧⑨⑩に記載の通り、プログラム対象科目の全てが必修科目として設定されたことから、令和５年度以降の入学生については原則、１年次後期での履修率が１００％となる見込みである。入学直後に毎年度実施される入学生ガイダンスにおいて本プログラムの内容をアナウンスし、その意義と各学部の教育課程内での位置づけを確認している他、1年次の後期履修登録に向けての個別面談において、必修科目を登録するよう指導するとともに履修に際する質問等に対応している。また、学生の履修状況を各学部の教務委員、教務部職員とで随時チェックすることで履修漏れを防ぐ体制を敷いている。当該年次に何らかの理由により履修ができなかった学生および、履修取り消しをした学生等については、その翌年度以降に履修（及び再履修）することが可能となっており、各学部の教務委員をはじめクラスアドバイザー等教職員が学生の状況を鑑みながら適切に履修指導を行っている。
A107: ⑫ | B107: 授業時間内外で学習指導、質問を受け付ける具体的な仕組み
B108: 本学では各授業のシラバスに科目担当教員のオフィスアワー（研究室滞在時間帯）を記載しており、これについて各授業の第1回目にて履修者へ周知している。履修者はこの時間帯を利用し、直接教員の研究室を訪ね、学習指導を受けることができる。この他、メールや本学LMS等の遠隔支援システムを利用して担当教員に学習内容に関する質問をすることができる。担当教員は上記ルートによって寄せられた質問及び相談に対して返信または別途時間を設けての対面指導を行うなど、その解決にあたることとしている。また、本プログラムの対象科目ではデータ等を扱う際にMicrosoft Office365を使用する。本学では全学生にこのアカウントを付与しており、各自のBYOD端末へ当該ソフトウェアをインストールすることができる。授業開始までの期間中、もしくは授業期間中のコンピュータトラブル等については授業時間外に学部教員または総務部情報システム室職員等が支援を担当している。

Sheet 様式４　自己点検・評価
I1: 様式４
H2: 大学等名 | I2: ='様式１-３ プログラムを構成する授業科目'!C2 -> 金沢学院大学
A3: 自己点検・評価について
A5: ① | B5: プログラムの自己点検・評価を行う体制（委員会・組織等）
B6: 大学自己点検・評価委員会
D8: （責任者名） | E8: 秋山 稔 | G8: （役職名） | H8: 学長
A10: ② | B10: 自己点検・評価体制における意見等
B11: 自己点検・評価の視点 | E11: 自己点検・評価体制における意見・結果・改善に向けた取組等
B12: 学内からの視点
C13: プログラムの履修・修得状況 | E13: 本プログラムの履修者数、修了者数等は教務部において把握している。また、履修期間中にあっては対象科目の履修者出席状況を各学部教員が確認できる体制としている。数理・データサイエンス・ＡＩ教育強化拠点コンソーシアムが提示する「モデルカリキュラム（リテラシーレベル）」に準拠した授業を展開した科目において、履修者数・修了者数及び学修成績分布等により、授業実施状況、出席状況、成績評価及び基準等について分析を行い、全体の理解度を検証する。なお、本科目は必修科目であることから履修状況については問題ないが、修得状況（単位取得状況）については全学教務委員会が状況を報告し、学生の履修指導につなげることとする。
C14: 学修成果 | E14: 数理・データサイエンス・ＡＩリテラシー教育プログラム対象科目において、各科目の履修者の成績評価をもとに学修成果を把握する。これらのデータは教務部および各学部の教務委員会が収集し分析を行った上、全学教務委員会にてとりまとめる。この分析結果をもとに検証し、全学的に行われている授業改善アンケートにより寄せられた学生の意見・要望も参考とすることで教育プログラムの改善を図る。また、本教育プログラム対象科目ではそれぞれにLMS上に課題等を置いているが、これらコンテンツに対する回答内容・状況についても今後検証を実施し、学部を越えて横断的に担当教員が共有できる体制を整備し、授業改善に活かすこととする。
C15: 学生アンケート等を通じた学生の内容の理解度 | E15: 本プログラム対象科目である「コンピュータ基礎演習Ⅱ」、「コンピュータ基礎演習Ⅱａ」「コンピュータ基礎演習Ⅱｂ」および「ICT活用教育概論」における授業改善アンケートより次年度に向けた授業計画の見直し・改善を全学的に実施しており、これらのデータを基に大学自己点検・評価委員会にて検証を行い、理解度の向上を含めた本教育プログラムの改善に取り組む。
C16: 学生アンケート等を通じた後輩等他の学生への推奨度 | E16: 本プログラム対象科目である「コンピュータ基礎演習Ⅱ」、「コンピュータ基礎演習Ⅱａ」「コンピュータ基礎演習Ⅱｂ」及び「ICT活用教育概論」は、いずれも卒業要件の必修科目であることから後輩等他の学生への推奨を特に必要としないが、学生が回答した授業改善アンケートに対する「教員コメント（学生へのフィードバック）」を担当教員へ伝えることにより、授業改善の駆動力としている。
C17: 全学的な履修者数、履修率向上に向けた計画の達成・進捗状況 | E17: 本プログラム対象科目である「コンピュータ基礎演習Ⅱ」、「コンピュータ基礎演習Ⅱａ」「コンピュータ基礎演習Ⅱｂ」及び「ICT活用教育概論」は、令和5年度より全学必修科目として実施することとなり、１年生については実質１００％に近い履修率となる見込みである。全学としては年度を経る度に段階的に履修率は向上し、令和７年度には１～３年生において100％（全学年において90％）に達し、全科目が必修となった際の履修者が４年生となる令和８年度に履修率は100％となるよう計画している。今後も、全学必修科目として継続してプログラムを実施する予定としている。
B18: 学外からの視点
C19: 教育プログラム修了者の進路、活躍状況、企業等の評価 | E19: 当該プログラムにおける本授業科目は、令和４年度より内容を改訂し開講されているため、当該授業を修得し単位を修得して卒業した学生をまだ輩出していないが、卒業後、就職支援部と協力しながら、卒業後の追跡調査を実施する等、修了者のキャリアステップや活躍状況の把握に努めることとする。
C20: 産業界からの視点を含めた教育プログラム内容・手法等への意見 | E20: まず本学教育へ反映させることを目的とし、卒業生の就職先へのヒアリングにより、本学の教育に期待することや産業界で求められている資質・能力、本学卒業生に対する満足度等の情報収集を行う。そして、企業との教育コンテンツの共同開発等を通じて、産業界からのニーズの把握に取り組むこととし、卒業生の就職先に対するアンケート調査により、本教育プログラムの評価・改善サイクルを構築することとする。
B21: 数理・データサイエンス・ＡＩを「学ぶ楽しさ」「学ぶことの意義」を理解させること | E21: 各学部の専門分野におけるデータサイエンス・AIの事例を積極的に取り扱うことで、自身の専門分野とのつながりを認識させ、数理・データサイエンス・AIを学ぶ意義の理解を促すこととする。また、知識の共有・定着化を図るため、グループワーク・ディスカッションを取り入れ、学生の学び合いやコミュニケーションを促進し、学ぶ楽しさや学習意欲の向上の促進に努める。
B22: 内容・水準を維持・向上しつつ、より「分かりやすい」授業とすること | E22: 全学教務委員会において、授業振り返りアンケート等の学生の意見を参考に、学生の「分かりやすさ」の観点から講義の内容・実施方法の見直しを検討する。また、ファカルティ・ディベロップメント事業として、授業振り返りアンケートの結果を授業担当教員にフィードバックし、振り返りの内容を提出させることで、授業担当教員の授業改善を促進する取り組みを行う。
