Workbook

Sheet 【社福】様式１-1　プログラムを構成する授業科目
R1: 様式１－１ | T1: 「学部・学科によって、修了要件は相違する」場合は、本シートを複製の上＜様式１－〇＞と枝番号を付してください
B2: 大学等名 | C2: 関西福祉科学大学
B3: プログラム名 | C3: 関西福祉科学大学 ICT・データサイエンス教育プログラム
A5: プログラムを構成する授業科目について
A7: ① 対象となる学部・学科名称 | J7: ② 教育プログラムの修了要件 | K7: 学部・学科によって、修了要件は相違する
B9: 社会福祉学部（社会福祉学科）
A12: ③ 修了要件
B13: 5つの審査項目（①現在進行中の社会変化に深く寄与しているものであり、それが自らの生活と密接に結びついている、②「社会で活用されているデータ」や「データの活用領域」は非常に広範囲であって、日常生活や社会の課題を解決する有用なツールになり得るもの、③様々なデータ利活用の現場におけるデータ利活用事例が示され、様々な適用領域の知見と組み合わせることで価値を創出するもの、④活用に当たっての様々な留意事項を考慮し、情報セキュリティや情報漏洩等、データを守る上での留意事項への理解をする、⑤実データ・実課題を用いた演習など、社会での実例を題材として、「データを読む、説明する、扱う」といった数理・データサイエンス・ＡＩの基本的な活用法に関するもの）の全ての内容を含む全学共通の「データサイエンス入門」（2単位）を設置しており、当科目および「情報処理学Ⅱ」（1単位）を必修科目とし、計3単位以上を修得することを修了要件とする。なお、より発展的に学ぶために全学共通の科目や学部の専門に特化した科目を選択科目として設置している。 | V13: 【プルダウンリスト】
V14: 令和４年度以前より、履修することが必須のプログラムとして実施
V15: 令和７年度までに履修必須とする計画
V16: 令和８年度以降に履修必須とする計画、又は未定
B20: 必要最低単位数 | C20: 3 | E20: 単位 | J20: 履修必須の有無 | K20: 令和４年度以前より、履修することが必須のプログラムとして実施
A22: ④ 現在進行中の社会変化（第４次産業革命、Society 5.0、データ駆動型社会等）に深く寄与しているものであり、それが自らの生活と密接に結びついている」の内容を含む授業科目
B24: 授業科目 | F24: 単位数 | G24: 必須 | H24: 1-1 | I24: 1-6 | J24: 授業科目 | P24: 単位数 | Q24: 必須 | R24: 1-1 | S24: 1-6
B25: データサイエンス入門 | F25: 2 | G25: ○ | H25: ○ | I25: ○
A33: ⑤ 「社会で活用されているデータ」や「データの活用領域」は非常に広範囲であって、日常生活や社会の課題を解決する有用なツールになり得るもの」の内容を含む授業科目
B35: 授業科目 | F35: 単位数 | G35: 必須 | H35: 1-2 | I35: 1-3 | J35: 授業科目 | P35: 単位数 | Q35: 必須 | R35: 1-2 | S35: 1-3
B36: データサイエンス入門 | F36: 2 | G36: ○ | H36: ○ | I36: ○
B37: 社会福祉調査の基礎 | F37: 2 | H37: ○
A44: ⑥ 「様々なデータ利活用の現場におけるデータ利活用事例が示され、様々な適用領域（流通、製造、金融、サービス、インフラ、公共、ヘルスケア等）の知見と組み合わせることで価値を創出するもの」の内容を含む授業科目
B46: 授業科目 | F46: 単位数 | G46: 必須 | H46: 1-4 | I46: 1-5 | J46: 授業科目 | P46: 単位数 | Q46: 必須 | R46: 1-4 | S46: 1-5
B47: データサイエンス入門 | F47: 2 | G47: ○ | H47: ○ | I47: ○
A55: ⑦ 「活用に当たっての様々な留意事項（ELSI、個人情報、データ倫理、ＡＩ社会原則等）を考慮し、情報セキュリティや情報漏洩等、データを守る上での留意事項への理解をする」の内容を含む授業科目
B57: 授業科目 | F57: 単位数 | G57: 必須 | H57: 3-1 | I57: 3-2 | J57: 授業科目 | P57: 単位数 | Q57: 必須 | R57: 3-1 | S57: 3-2
B58: データサイエンス入門 | F58: 2 | G58: ○ | H58: ○ | I58: ○
A66: ⑧ 「実データ・実課題（学術データ等を含む）を用いた演習など、社会での実例を題材として、「データを読む、説明する、扱う」といった数理・データサイエンス・ＡＩの基本的な活用法に関するもの」の内容を含む授業科目
B68: 授業科目 | E68: 単位数 | F68: 必須 | G68: 2-1 | H68: 2-2 | I68: 2-3 | J68: 授業科目 | O68: 単位数 | P68: 必須 | Q68: 2-1 | R68: 2-2 | S68: 2-3
B69: データサイエンス入門 | E69: 2 | F69: ○ | G69: ○ | H69: ○ | I69: ○
B70: 情報処理学Ⅱ（福） | E70: 1 | F70: ○ | G70: ○ | H70: ○ | I70: ○
B71: 統計学 | E71: 1 | G71: ○ | H71: ○ | I71: ○
B72: 社会福祉調査の基礎 | E72: 2 | G72: ○
A77: ⑨ 選択「４．オプション」の内容を含む授業科目
B78: 授業科目 | F78: 選択項目 | J78: 授業科目 | P78: 選択項目
B79: 基礎数学 | F79: 4-1統計および数理基礎
B80: 統計学 | F80: 4-1統計および数理基礎
B81: 社会福祉調査の基礎 | F81: 4-1統計および数理基礎
A87: ⑩ プログラムを構成する授業の内容
B88: 授業に含まれている内容・要素 | D88: 講義内容
B89: （１）現在進行中の社会変化（第４次産業革命、Society 5.0、データ駆動型社会等）に深く寄与しているものであり、それが自らの生活と密接に結びついている | C89: 1-1 | D89: ・ビッグデータ、データ量の増加、第４次産業革命、データ駆動型社会、人間の知的活動とAIの関係性、データを起点としたものの見方、人口の知的活動を起点としたものの見方「データサイエンス入門」（1回目）
C90: 1-6 | D90: AIを活用したビジネスモデル（シェアリングエコノミー、商品のレコメンデーショなどン）、AI最新技術の活用例（敵対的生成ネットワーク、強化学習、転移学習など）「データサイエンス入門」（7回目）
...

Sheet 【心理】様式1-2
R1: 様式１－２ | T1: 「学部・学科によって、修了要件は相違する」場合は、本シートを複製の上＜様式１－〇＞と枝番号を付してください
B2: 大学等名 | C2: 関西福祉科学大学
B3: プログラム名 | C3: 関西福祉科学大学 ICT・データサイエンス教育プログラム
A5: プログラムを構成する授業科目について
A7: ① 対象となる学部・学科名称 | J7: ② 教育プログラムの修了要件 | K7: 学部・学科によって、修了要件は相違する
B9: 心理科学部（心理科学科）
A12: ③ 修了要件
B13: 5つの審査項目（①現在進行中の社会変化に深く寄与しているものであり、それが自らの生活と密接に結びついている、②「社会で活用されているデータ」や「データの活用領域」は非常に広範囲であって、日常生活や社会の課題を解決する有用なツールになり得るもの、③様々なデータ利活用の現場におけるデータ利活用事例が示され、様々な適用領域の知見と組み合わせることで価値を創出するもの、④活用に当たっての様々な留意事項を考慮し、情報セキュリティや情報漏洩等、データを守る上での留意事項への理解をする、⑤実データ・実課題を用いた演習など、社会での実例を題材として、「データを読む、説明する、扱う」といった数理・データサイエンス・ＡＩの基本的な活用法に関するもの）の全ての内容を含む全学共通の「データサイエンス入門」（2単位）を設置しており、当科目および「情報処理学Ⅱ」（1単位）を必修科目とし、計3単位以上を修得することを修了要件とする。なお、より発展的に学ぶために全学共通の科目や学部の専門に特化した科目を選択科目として設置している。 | V13: 【プルダウンリスト】
V14: 令和４年度以前より、履修することが必須のプログラムとして実施
V15: 令和７年度までに履修必須とする計画
V16: 令和８年度以降に履修必須とする計画、又は未定
B20: 必要最低単位数 | C20: 3 | E20: 単位 | J20: 履修必須の有無 | K20: 令和４年度以前より、履修することが必須のプログラムとして実施
A22: ④ 現在進行中の社会変化（第４次産業革命、Society 5.0、データ駆動型社会等）に深く寄与しているものであり、それが自らの生活と密接に結びついている」の内容を含む授業科目
B24: 授業科目 | F24: 単位数 | G24: 必須 | H24: 1-1 | I24: 1-6 | J24: 授業科目 | P24: 単位数 | Q24: 必須 | R24: 1-1 | S24: 1-6
B25: データサイエンス入門 | F25: 2 | G25: ○ | H25: ○ | I25: ○
A33: ⑤ 「社会で活用されているデータ」や「データの活用領域」は非常に広範囲であって、日常生活や社会の課題を解決する有用なツールになり得るもの」の内容を含む授業科目
B35: 授業科目 | F35: 単位数 | G35: 必須 | H35: 1-2 | I35: 1-3 | J35: 授業科目 | P35: 単位数 | Q35: 必須 | R35: 1-2 | S35: 1-3
B36: データサイエンス入門 | F36: 2 | G36: ○ | H36: ○ | I36: ○
B37: 心理学研究法Ⅱ（調査研究法） | F37: 2 | H37: ○
A44: ⑥ 「様々なデータ利活用の現場におけるデータ利活用事例が示され、様々な適用領域（流通、製造、金融、サービス、インフラ、公共、ヘルスケア等）の知見と組み合わせることで価値を創出するもの」の内容を含む授業科目
B46: 授業科目 | F46: 単位数 | G46: 必須 | H46: 1-4 | I46: 1-5 | J46: 授業科目 | P46: 単位数 | Q46: 必須 | R46: 1-4 | S46: 1-5
B47: データサイエンス入門 | F47: 2 | G47: ○ | H47: ○ | I47: ○
A55: ⑦ 「活用に当たっての様々な留意事項（ELSI、個人情報、データ倫理、ＡＩ社会原則等）を考慮し、情報セキュリティや情報漏洩等、データを守る上での留意事項への理解をする」の内容を含む授業科目
B57: 授業科目 | F57: 単位数 | G57: 必須 | H57: 3-1 | I57: 3-2 | J57: 授業科目 | P57: 単位数 | Q57: 必須 | R57: 3-1 | S57: 3-2
B58: データサイエンス入門 | F58: 2 | G58: ○ | H58: ○ | I58: ○
B59: 心理学研究法Ⅱ（調査研究法） | F59: 2 | H59: ○
A66: ⑧ 「実データ・実課題（学術データ等を含む）を用いた演習など、社会での実例を題材として、「データを読む、説明する、扱う」といった数理・データサイエンス・ＡＩの基本的な活用法に関するもの」の内容を含む授業科目
B68: 授業科目 | E68: 単位数 | F68: 必須 | G68: 2-1 | H68: 2-2 | I68: 2-3 | J68: 授業科目 | O68: 単位数 | P68: 必須 | Q68: 2-1 | R68: 2-2 | S68: 2-3
B69: データサイエンス入門 | E69: 2 | F69: ○ | G69: ○ | H69: ○ | I69: ○
B70: 情報処理学Ⅱ（心） | E70: 1 | F70: ○ | G70: ○ | H70: ○ | I70: ○
B71: 統計学 | E71: 1 | G71: ○ | H71: ○ | I71: ○
B72: 心理学統計法Ⅰ（心） | E72: 2 | G72: ○ | H72: ○ | I72: ○
B73: 心理学研究法Ⅱ（調査研究法） | E73: 2 | I73: ○
A77: ⑨ 選択「４．オプション」の内容を含む授業科目
B78: 授業科目 | F78: 選択項目 | J78: 授業科目 | P78: 選択項目
B79: 基礎数学 | F79: 4-1統計および数理基礎
B80: 統計学 | F80: 4-1統計および数理基礎
B81: 心理学統計法Ⅰ（心） | F81: 4-1統計および数理基礎
B82: 心理学研究法Ⅱ（調査研究法） | F82: 4‐7データハンドリング
A87: ⑩ プログラムを構成する授業の内容
...

Sheet 【健福】様式1-3
R1: 様式１－３ | T1: 「学部・学科によって、修了要件は相違する」場合は、本シートを複製の上＜様式１－〇＞と枝番号を付してください
B2: 大学等名 | C2: 関西福祉科学大学
B3: プログラム名 | C3: 関西福祉科学大学 ICT・データサイエンス教育プログラム
A5: プログラムを構成する授業科目について
A7: ① 対象となる学部・学科名称 | J7: ② 教育プログラムの修了要件 | K7: 学部・学科によって、修了要件は相違する
B9: 健康福祉学部（健康科学科・福祉栄養学科）
A12: ③ 修了要件
B13: 5つの審査項目（①現在進行中の社会変化に深く寄与しているものであり、それが自らの生活と密接に結びついている、②「社会で活用されているデータ」や「データの活用領域」は非常に広範囲であって、日常生活や社会の課題を解決する有用なツールになり得るもの、③様々なデータ利活用の現場におけるデータ利活用事例が示され、様々な適用領域の知見と組み合わせることで価値を創出するもの、④活用に当たっての様々な留意事項を考慮し、情報セキュリティや情報漏洩等、データを守る上での留意事項への理解をする、⑤実データ・実課題を用いた演習など、社会での実例を題材として、「データを読む、説明する、扱う」といった数理・データサイエンス・ＡＩの基本的な活用法に関するもの）の全ての内容を含む全学共通の「データサイエンス入門」（2単位）を設置しており、当科目および「情報処理学Ⅱ」（1単位）を必修科目とし、計3単位以上を修得することを修了要件とする。なお、より発展的に学ぶために全学共通の科目や学部の専門に特化した科目を選択科目として設置している。 | V13: 【プルダウンリスト】
V14: 令和４年度以前より、履修することが必須のプログラムとして実施
V15: 令和７年度までに履修必須とする計画
V16: 令和８年度以降に履修必須とする計画、又は未定
B20: 必要最低単位数 | C20: 3 | E20: 単位 | J20: 履修必須の有無 | K20: 令和４年度以前より、履修することが必須のプログラムとして実施
A22: ④ 現在進行中の社会変化（第４次産業革命、Society 5.0、データ駆動型社会等）に深く寄与しているものであり、それが自らの生活と密接に結びついている」の内容を含む授業科目
B24: 授業科目 | F24: 単位数 | G24: 必須 | H24: 1-1 | I24: 1-6 | J24: 授業科目 | P24: 単位数 | Q24: 必須 | R24: 1-1 | S24: 1-6
B25: データサイエンス入門 | F25: 2 | G25: ○ | H25: ○ | I25: ○
A33: ⑤ 「社会で活用されているデータ」や「データの活用領域」は非常に広範囲であって、日常生活や社会の課題を解決する有用なツールになり得るもの」の内容を含む授業科目
B35: 授業科目 | F35: 単位数 | G35: 必須 | H35: 1-2 | I35: 1-3 | J35: 授業科目 | P35: 単位数 | Q35: 必須 | R35: 1-2 | S35: 1-3
B36: データサイエンス入門 | F36: 2 | G36: ○ | H36: ○ | I36: ○
B37: 公衆衛生学（健） | F37: 2 | H37: ○
B38: 公衆衛生学（栄） | F38: 2 | H38: ○
B39: 栄養情報論実習（栄） | F39: 1 | H39: ○
A44: ⑥ 「様々なデータ利活用の現場におけるデータ利活用事例が示され、様々な適用領域（流通、製造、金融、サービス、インフラ、公共、ヘルスケア等）の知見と組み合わせることで価値を創出するもの」の内容を含む授業科目
B46: 授業科目 | F46: 単位数 | G46: 必須 | H46: 1-4 | I46: 1-5 | J46: 授業科目 | P46: 単位数 | Q46: 必須 | R46: 1-4 | S46: 1-5
B47: データサイエンス入門 | F47: 2 | G47: ○ | H47: ○ | I47: ○
A55: ⑦ 「活用に当たっての様々な留意事項（ELSI、個人情報、データ倫理、ＡＩ社会原則等）を考慮し、情報セキュリティや情報漏洩等、データを守る上での留意事項への理解をする」の内容を含む授業科目
B57: 授業科目 | F57: 単位数 | G57: 必須 | H57: 3-1 | I57: 3-2 | J57: 授業科目 | P57: 単位数 | Q57: 必須 | R57: 3-1 | S57: 3-2
B58: データサイエンス入門 | F58: 2 | G58: ○ | H58: ○ | I58: ○
B59: 公衆衛生学（健） | F59: 2 | H59: ○
A66: ⑧ 「実データ・実課題（学術データ等を含む）を用いた演習など、社会での実例を題材として、「データを読む、説明する、扱う」といった数理・データサイエンス・ＡＩの基本的な活用法に関するもの」の内容を含む授業科目
B68: 授業科目 | E68: 単位数 | F68: 必須 | G68: 2-1 | H68: 2-2 | I68: 2-3 | J68: 授業科目 | O68: 単位数 | P68: 必須 | Q68: 2-1 | R68: 2-2 | S68: 2-3
B69: データサイエンス入門 | E69: 2 | F69: ○ | G69: ○ | H69: ○ | I69: ○
B70: 情報処理学Ⅱ（健） | E70: 1 | F70: ○ | G70: ○ | H70: ○ | I70: ○
B71: 情報処理学Ⅱ（栄） | E71: 1 | F71: ○ | G71: ○ | H71: ○ | I71: ○
B72: 統計学 | E72: 1 | G72: ○ | H72: ○ | I72: ○
B73: 心理学統計法Ⅰ（健） | E73: 2 | G73: ○ | H73: ○ | I73: ○
B74: 栄養情報論実習（栄） | E74: 1 | G74: ○ | H74: ○ | I74: ○
B75: 公衆衛生学（栄） | E75: 2 | G75: ○
A77: ⑨ 選択「４．オプション」の内容を含む授業科目
B78: 授業科目 | F78: 選択項目 | J78: 授業科目 | P78: 選択項目
B79: 基礎数学 | F79: 4-1統計および数理基礎
...

Sheet 【教育】様式1-4
R1: 様式１－４ | T1: 「学部・学科によって、修了要件は相違する」場合は、本シートを複製の上＜様式１－〇＞と枝番号を付してください
B2: 大学等名 | C2: 関西福祉科学大学
B3: プログラム名 | C3: 関西福祉科学大学 ICT・データサイエンス教育プログラム
A5: プログラムを構成する授業科目について
A7: ① 対象となる学部・学科名称 | J7: ② 教育プログラムの修了要件 | K7: 学部・学科によって、修了要件は相違する
B9: 教育学部（教育学科 子ども発達教育専攻）
A12: ③ 修了要件
B13: 5つの審査項目（①現在進行中の社会変化に深く寄与しているものであり、それが自らの生活と密接に結びついている、②「社会で活用されているデータ」や「データの活用領域」は非常に広範囲であって、日常生活や社会の課題を解決する有用なツールになり得るもの、③様々なデータ利活用の現場におけるデータ利活用事例が示され、様々な適用領域の知見と組み合わせることで価値を創出するもの、④活用に当たっての様々な留意事項を考慮し、情報セキュリティや情報漏洩等、データを守る上での留意事項への理解をする、⑤実データ・実課題を用いた演習など、社会での実例を題材として、「データを読む、説明する、扱う」といった数理・データサイエンス・ＡＩの基本的な活用法に関するもの）の全ての内容を含む全学共通の「データサイエンス入門」（2単位）を設置しており、当科目および「情報処理学Ⅱ」（1単位）を必修科目とし、計3単位以上を修得することを修了要件とする。なお、より発展的に学ぶために全学共通の科目や学部の専門に特化した科目を選択科目として設置している。 | V13: 【プルダウンリスト】
V14: 令和４年度以前より、履修することが必須のプログラムとして実施
V15: 令和７年度までに履修必須とする計画
V16: 令和８年度以降に履修必須とする計画、又は未定
B20: 必要最低単位数 | C20: 3 | E20: 単位 | J20: 履修必須の有無 | K20: 令和４年度以前より、履修することが必須のプログラムとして実施
A22: ④ 現在進行中の社会変化（第４次産業革命、Society 5.0、データ駆動型社会等）に深く寄与しているものであり、それが自らの生活と密接に結びついている」の内容を含む授業科目
B24: 授業科目 | F24: 単位数 | G24: 必須 | H24: 1-1 | I24: 1-6 | J24: 授業科目 | P24: 単位数 | Q24: 必須 | R24: 1-1 | S24: 1-6
B25: データサイエンス入門 | F25: 2 | G25: ○ | H25: ○ | I25: ○
A33: ⑤ 「社会で活用されているデータ」や「データの活用領域」は非常に広範囲であって、日常生活や社会の課題を解決する有用なツールになり得るもの」の内容を含む授業科目
B35: 授業科目 | F35: 単位数 | G35: 必須 | H35: 1-2 | I35: 1-3 | J35: 授業科目 | P35: 単位数 | Q35: 必須 | R35: 1-2 | S35: 1-3
B36: データサイエンス入門 | F36: 2 | G36: ○ | H36: ○ | I36: ○
A44: ⑥ 「様々なデータ利活用の現場におけるデータ利活用事例が示され、様々な適用領域（流通、製造、金融、サービス、インフラ、公共、ヘルスケア等）の知見と組み合わせることで価値を創出するもの」の内容を含む授業科目
B46: 授業科目 | F46: 単位数 | G46: 必須 | H46: 1-4 | I46: 1-5 | J46: 授業科目 | P46: 単位数 | Q46: 必須 | R46: 1-4 | S46: 1-5
B47: データサイエンス入門 | F47: 2 | G47: ○ | H47: ○ | I47: ○
A55: ⑦ 「活用に当たっての様々な留意事項（ELSI、個人情報、データ倫理、ＡＩ社会原則等）を考慮し、情報セキュリティや情報漏洩等、データを守る上での留意事項への理解をする」の内容を含む授業科目
B57: 授業科目 | F57: 単位数 | G57: 必須 | H57: 3-1 | I57: 3-2 | J57: 授業科目 | P57: 単位数 | Q57: 必須 | R57: 3-1 | S57: 3-2
B58: データサイエンス入門 | F58: 2 | G58: ○ | H58: ○ | I58: ○
A66: ⑧ 「実データ・実課題（学術データ等を含む）を用いた演習など、社会での実例を題材として、「データを読む、説明する、扱う」といった数理・データサイエンス・ＡＩの基本的な活用法に関するもの」の内容を含む授業科目
B68: 授業科目 | E68: 単位数 | F68: 必須 | G68: 2-1 | H68: 2-2 | I68: 2-3 | J68: 授業科目 | O68: 単位数 | P68: 必須 | Q68: 2-1 | R68: 2-2 | S68: 2-3
B69: データサイエンス入門 | E69: 2 | F69: ○ | G69: ○ | H69: ○ | I69: ○
B70: 情報処理学Ⅱ（教） | E70: 1 | F70: ○ | G70: ○ | H70: ○ | I70: ○
B71: 統計学 | E71: 1 | G71: ○ | H71: ○ | I71: ○
B72: 算数（小） | E72: 2 | G72: ○ | H72: ○
A77: ⑨ 選択「４．オプション」の内容を含む授業科目
B78: 授業科目 | F78: 選択項目 | J78: 授業科目 | P78: 選択項目
B79: 基礎数学 | F79: 4-1統計および数理基礎
B80: 統計学 | F80: 4-1統計および数理基礎
A87: ⑩ プログラムを構成する授業の内容
B88: 授業に含まれている内容・要素 | D88: 講義内容
B89: （１）現在進行中の社会変化（第４次産業革命、Society 5.0、データ駆動型社会等）に深く寄与しているものであり、それが自らの生活と密接に結びついている | C89: 1-1 | D89: ・ビッグデータ、データ量の増加、第４次産業革命、データ駆動型社会、人間の知的活動とAIの関係性、データを起点としたものの見方、人口の知的活動を起点としたものの見方「データサイエンス入門」（1回目）
C90: 1-6 | D90: AIを活用したビジネスモデル（シェアリングエコノミー、商品のレコメンデーショなどン）、AI最新技術の活用例（敵対的生成ネットワーク、強化学習、転移学習など）「データサイエンス入門」（7回目）
B91: （２）「社会で活用されているデータ」や「データの活用領域」は非常に広範囲であって、日常生活や社会の課題を解決する有用なツールになり得るもの | C91: 1-2 | D91: ・調査データ、実験データ、人の行動ログデータ、1次データ、2次データ、データのメタ化、構造化データ、非構造化データ（文章、画像/動画、音声/音楽など）、データ作成（ビッグデータとアノテーション）、データのオープン化（オープンデータ）「データサイエンス入門」（2回目）
C92: 1-3 | D92: ・研究開発、購買物流・調達、製造、出荷物流、マーケティング、販売、サービス、仮説検証、知識発見、原因究明、計画策定、判断支援、活動代替、新規生成）「データサイエンス入門」（3回目）
...

Sheet 【保医】様式１-5
R1: 様式１－５ | T1: 「学部・学科によって、修了要件は相違する」場合は、本シートを複製の上＜様式１－〇＞と枝番号を付してください
B2: 大学等名 | C2: 関西福祉科学大学
B3: プログラム名 | C3: 関西福祉科学大学 ICT・データサイエンス教育プログラム
A5: プログラムを構成する授業科目について
A7: ① 対象となる学部・学科名称 | J7: ② 教育プログラムの修了要件 | K7: 学部・学科によって、修了要件は相違する
B9: 保健医療学部（リハビリテーション学科 理学療法学専攻（PT）・作業療法学専攻（OT）・言語聴覚学専攻（ST））
A12: ③ 修了要件
B13: 5つの審査項目（①現在進行中の社会変化に深く寄与しているものであり、それが自らの生活と密接に結びついている、②「社会で活用されているデータ」や「データの活用領域」は非常に広範囲であって、日常生活や社会の課題を解決する有用なツールになり得るもの、③様々なデータ利活用の現場におけるデータ利活用事例が示され、様々な適用領域の知見と組み合わせることで価値を創出するもの、④活用に当たっての様々な留意事項を考慮し、情報セキュリティや情報漏洩等、データを守る上での留意事項への理解をする、⑤実データ・実課題を用いた演習など、社会での実例を題材として、「データを読む、説明する、扱う」といった数理・データサイエンス・ＡＩの基本的な活用法に関するもの）の全ての内容を含む全学共通の「データサイエンス入門」（2単位）を設置しており、当科目および「情報処理学Ⅰ」（1単位）を必修科目とし、計3単位以上を修得することを修了要件とする。なお、より発展的に学ぶために全学共通の科目や学部の専門に特化した科目を選択科目として設置している。 | V13: 【プルダウンリスト】
V14: 令和４年度以前より、履修することが必須のプログラムとして実施
V15: 令和７年度までに履修必須とする計画
V16: 令和８年度以降に履修必須とする計画、又は未定
B20: 必要最低単位数 | C20: 3 | E20: 単位 | J20: 履修必須の有無 | K20: 令和４年度以前より、履修することが必須のプログラムとして実施
A22: ④ 現在進行中の社会変化（第４次産業革命、Society 5.0、データ駆動型社会等）に深く寄与しているものであり、それが自らの生活と密接に結びついている」の内容を含む授業科目
B24: 授業科目 | F24: 単位数 | G24: 必須 | H24: 1-1 | I24: 1-6 | J24: 授業科目 | P24: 単位数 | Q24: 必須 | R24: 1-1 | S24: 1-6
B25: データサイエンス入門 | F25: 2 | G25: ○ | H25: ○ | I25: ○
A33: ⑤ 「社会で活用されているデータ」や「データの活用領域」は非常に広範囲であって、日常生活や社会の課題を解決する有用なツールになり得るもの」の内容を含む授業科目
B35: 授業科目 | F35: 単位数 | G35: 必須 | H35: 1-2 | I35: 1-3 | J35: 授業科目 | P35: 単位数 | Q35: 必須 | R35: 1-2 | S35: 1-3
B36: データサイエンス入門 | F36: 2 | G36: ○ | H36: ○ | I36: ○
B37: 公衆衛生学（リ） | F37: 2 | H37: ○
A44: ⑥ 「様々なデータ利活用の現場におけるデータ利活用事例が示され、様々な適用領域（流通、製造、金融、サービス、インフラ、公共、ヘルスケア等）の知見と組み合わせることで価値を創出するもの」の内容を含む授業科目
B46: 授業科目 | F46: 単位数 | G46: 必須 | H46: 1-4 | I46: 1-5 | J46: 授業科目 | P46: 単位数 | Q46: 必須 | R46: 1-4 | S46: 1-5
B47: データサイエンス入門 | F47: 2 | G47: ○ | H47: ○ | I47: ○
A55: ⑦ 「活用に当たっての様々な留意事項（ELSI、個人情報、データ倫理、ＡＩ社会原則等）を考慮し、情報セキュリティや情報漏洩等、データを守る上での留意事項への理解をする」の内容を含む授業科目
B57: 授業科目 | F57: 単位数 | G57: 必須 | H57: 3-1 | I57: 3-2 | J57: 授業科目 | P57: 単位数 | Q57: 必須 | R57: 3-1 | S57: 3-2
B58: データサイエンス入門 | F58: 2 | G58: ○ | H58: ○ | I58: ○
A66: ⑧ 「実データ・実課題（学術データ等を含む）を用いた演習など、社会での実例を題材として、「データを読む、説明する、扱う」といった数理・データサイエンス・ＡＩの基本的な活用法に関するもの」の内容を含む授業科目
B68: 授業科目 | E68: 単位数 | F68: 必須 | G68: 2-1 | H68: 2-2 | I68: 2-3 | J68: 授業科目 | O68: 単位数 | P68: 必須 | Q68: 2-1 | R68: 2-2 | S68: 2-3
B69: データサイエンス入門 | E69: 2 | F69: ○ | G69: ○ | H69: ○ | I69: ○
B70: 情報処理学Ⅰ（リ） | E70: 1 | F70: ○ | G70: ○ | H70: ○ | I70: ○
B71: 統計学 | E71: 1 | G71: ○ | H71: ○ | I71: ○
B72: 情報処理学Ⅱ（リ） | E72: 1 | G72: ○ | H72: ○ | I72: ○
A77: ⑨ 選択「４．オプション」の内容を含む授業科目
B78: 授業科目 | F78: 選択項目 | J78: 授業科目 | P78: 選択項目
B79: 基礎数学 | F79: 4-1統計および数理基礎
B80: 統計学 | F80: 4-1統計および数理基礎
B81: 公衆衛生学（リ） | F81: 4-1統計および数理基礎
A87: ⑩ プログラムを構成する授業の内容
B88: 授業に含まれている内容・要素 | D88: 講義内容
B89: （１）現在進行中の社会変化（第４次産業革命、Society 5.0、データ駆動型社会等）に深く寄与しているものであり、それが自らの生活と密接に結びついている | C89: 1-1 | D89: ・ビッグデータ、データ量の増加、第４次産業革命、データ駆動型社会、人間の知的活動とAIの関係性、データを起点としたものの見方、人口の知的活動を起点としたものの見方「データサイエンス入門」（1回目）
C90: 1-6 | D90: AIを活用したビジネスモデル（シェアリングエコノミー、商品のレコメンデーショなどン）、AI最新技術の活用例（敵対的生成ネットワーク、強化学習、転移学習など）「データサイエンス入門」（7回目）
...

Sheet 様式２ 履修者等数の実績
AQ1: 様式２
AL2: 大学等名 | AM2: ='【保医】様式１-5'!C2 -> 関西福祉科学大学
A3: プログラムの履修者数等の実績について
A5: ①プログラム開設年度 | C5: 令和4 | E5: 年度
A7: ②履修者・修了者の実績
B9: 学部・学科名称 | C9: 学生数 | D9: 入学 定員 | E9: 収容 定員 | F9: 令和4年度 | L9: 令和3年度 | R9: 令和2年度 | X9: 令和元年度 | AD9: 平成30年度 | AJ9: 平成29年度 | AP9: 履修者数 合計 | AQ9: 履修率
F10: 履修者数 | I10: 修了者数 | L10: 履修者数 | O10: 修了者数 | R10: 履修者数 | U10: 修了者数 | X10: 履修者数 | AA10: 修了者数 | AD10: 履修者数 | AG10: 修了者数 | AJ10: 履修者数 | AM10: 修了者数
F11: 合計 | G11: 男性 | H11: 女性 | I11: 合計 | J11: 男性 | K11: 女性 | L11: 合計 | M11: 男性 | N11: 女性 | O11: 合計 | P11: 男性 | Q11: 女性 | R11: 合計 | S11: 男性 | T11: 女性 | U11: 合計 | V11: 男性 | W11: 女性 | X11: 合計 | Y11: 男性 | Z11: 女性 | AA11: 合計 | AB11: 男性 | AC11: 女性 | AD11: 合計 | AE11: 男性 | AF11: 女性 | AG11: 合計 | AH11: 男性 | AI11: 女性 | AJ11: 合計 | AK11: 男性 | AL11: 女性 | AM11: 合計 | AN11: 男性 | AO11: 女性
B12: 社会福祉学部 | C12: 543 | D12: 140 | E12: 600 | F12: 105 | I12: 83 | L12: =M12+N12 -> 0 | O12: =P12+Q12 -> 0 | R12: =S12+T12 -> 0 | U12: =V12+W12 -> 0 | X12: =Y12+Z12 -> 0 | AA12: =AB12+AC12 -> 0 | AD12: =AE12+AF12 -> 0 | AG12: =AH12+AI12 -> 0 | AJ12: =AK12+AL12 -> 0 | AM12: =AN12+AO12 -> 0 | AP12: =F12+L12+R12+X12+AD12+AJ12 -> 105 | AQ12: =AP12/E12 -> 0.175
B13: 心理科学部 | C13: 424 | D13: 110 | E13: 460 | F13: 85 | I13: 55 | L13: =M13+N13 -> 0 | O13: =P13+Q13 -> 0 | R13: =S13+T13 -> 0 | U13: =V13+W13 -> 0 | X13: =Y13+Z13 -> 0 | AA13: =AB13+AC13 -> 0 | AD13: =AE13+AF13 -> 0 | AG13: =AH13+AI13 -> 0 | AJ13: =AK13+AL13 -> 0 | AM13: =AN13+AO13 -> 0 | AP13: =F13+L13+R13+X13+AD13+AJ13 -> 85 | AQ13: =AP13/E13 -> 0.18478261
B14: 健康福祉学部 | C14: 532 | D14: 160 | E14: 670 | F14: 113 | I14: 108 | L14: =M14+N14 -> 0 | O14: =P14+Q14 -> 0 | R14: =S14+T14 -> 0 | U14: =V14+W14 -> 0 | X14: =Y14+Z14 -> 0 | AA14: =AB14+AC14 -> 0 | AD14: =AE14+AF14 -> 0 | AG14: =AH14+AI14 -> 0 | AJ14: =AK14+AL14 -> 0 | AM14: =AN14+AO14 -> 0 | AP14: =F14+L14+R14+X14+AD14+AJ14 -> 113 | AQ14: =AP14/E14 -> 0.16865672
B15: 保健医療学部 | C15: 630 | D15: 170 | E15: 680 | F15: 154 | I15: 149 | L15: =M15+N15 -> 0 | O15: =P15+Q15 -> 0 | R15: =S15+T15 -> 0 | U15: =V15+W15 -> 0 | X15: =Y15+Z15 -> 0 | AA15: =AB15+AC15 -> 0 | AD15: =AE15+AF15 -> 0 | AG15: =AH15+AI15 -> 0 | AJ15: =AK15+AL15 -> 0 | AM15: =AN15+AO15 -> 0 | AP15: =F15+L15+R15+X15+AD15+AJ15 -> 154 | AQ15: =AP15/E15 -> 0.22647059
B16: 教育学部 | C16: 295 | D16: 100 | E16: 400 | F16: 67 | I16: 58 | L16: =M16+N16 -> 0 | O16: =P16+Q16 -> 0 | R16: =S16+T16 -> 0 | U16: =V16+W16 -> 0 | X16: =Y16+Z16 -> 0 | AA16: =AB16+AC16 -> 0 | AD16: =AE16+AF16 -> 0 | AG16: =AH16+AI16 -> 0 | AJ16: =AK16+AL16 -> 0 | AM16: =AN16+AO16 -> 0 | AP16: =F16+L16+R16+X16+AD16+AJ16 -> 67 | AQ16: =AP16/E16 -> 0.1675
B32: 合 計 | C32: =SUM(C12:C31) -> 2424 | D32: =SUM(D12:D31) -> 680 | E32: =SUM(E12:E31) -> 2810 | F32: =SUM(F12:F31) -> 524 | G32: =SUM(G12:G31) -> 0 | H32: =SUM(H12:H31) -> 0 | I32: =SUM(I12:I31) -> 453 | J32: =SUM(J12:J31) -> 0 | ... AP32: =SUM(AP12:AP31) -> 524 | AQ32: =AP32/E32 -> 0.18647687

Sheet 様式３ 教育の質・履修者数を向上させるための体制・計画
I1: 様式３
G2: 大学等名 | H2: ='【保医】様式１-5'!C2 -> 関西福祉科学大学
A4: 教育の質・履修者数を向上させるための体制・計画について
A6: ① | B6: 全学の教員数 | C6: (常勤） | E6: 130 | F6: 人 | G6: （非常勤） | H6: 102 | I6: 人
A8: ② | B8: プログラムの授業を教えている教員数 | H8: 14 | I8: 人
A10: ③ | B10: プログラムの運営責任者
B11: （責任者名） | C11: 水鳥正二郎 | G11: （役職名） | H11: 共通教育センター会議 データサイエンス部門長
A13: ④ | B13: プログラムを改善・進化させるための体制（委員会・組織等）
B14: 共通教育センター会議 データサイエンス部門
B16: （責任者名） | C16: 水鳥正二郎 | G16: （役職名） | H16: 共通教育センター会議 データサイエンス部門長
A18: ⑤ | B18: プログラムを改善・進化させるための体制を定める規則名称
B19: 関西福祉科学大学共通教育センター規程
A21: ⑥ | B21: 体制の目的
B22: 共通教育センター（以下「センター」という。）は、本学の学部教育における基礎教育、教養教育並びに補習教育の全学的な充実を図るために設置しており、センター内にデータサイエンス部門を設けている。データサイエンス部門では、データサイエンスに関する科目のあり方及び運営に関する事項等を扱う業務を行っており、当該プログラムの改善・向上を図っている。
A34: ⑦ | B34: 具体的な構成員
B35: 共通教育センター会議のデータサイエンス部門の構成員は以下のとおりである。 ・部門長 水鳥正二郎（共通教育副センター長・健康福祉学部健康科学科 教授） ・副部門長 木村貴彦（共通教育センター長・健康福祉学部健康科学科 教授） ・部門員 尾崎拓（心理科学部 講師） ・部門員 家髙将明（社会福祉学部 准教授） ・部門員 治部哲也（健康福祉学部健康科学科 教授） ・部門員 山本訓子（健康福祉学部健康科学科 講師） ・部門員 竹田竜嗣（健康福祉学部福祉栄養学科 講師） ・部門員 森尚彫（保健医療学部 准教授） ・部門員 藤原靖浩（教育学部 講師） ・部門員 井上智（教務部 課長） ・部門員 田原里香子（教務部 課長） ・庶 務 後藤知寛（教務部 職員） ・庶務[補助] 岩田ふみ（総務部 担当課長）
A48: ⑧ | B48: 履修者数・履修率の向上に向けた計画 ※様式１の「履修必須の有無」で「計画がある」としている場合は詳細について記載すること
B49: 令和４年度実績 | C49: ='様式２ 履修者等数の実績'!AQ32 -> 0.18647687 | E49: 令和５年度予定 | F49: 0.4 | H49: 令和６年度予定 | I49: 0.6
B50: 令和７年度予定 | C50: 0.8 | E50: 令和８年度予定 | F50: 1 | H50: 収容定員（名） | I50: ='様式２ 履修者等数の実績'!E32 -> 2810
B51: 具体的な計画
B52: 本プログラムは令和4年度より導入しており、必修科目「データサイエンス入門」と「情報処理学Ⅰ」（保健医療学部）、「情報処理学Ⅱ」（保健医療学部以外）は、卒業必修であるため、令和4年度以降の入学生は全員が履修する予定である。また、より発展的に学ぶために全学共通の科目や学科の専門性に特化した科目を選択科目として設置している。なお、令和5年度以降は、新入生のオリエンテーションにて本プログラムの説明を行い、履修促進を図る予定である。
A65: ⑨ | B65: 学部・学科に関係なく希望する学生全員が受講可能となるような必要な体制・取組等
B66: 上記⑧のとおり、本プログラムの必修科目「データサイエンス入門」と「情報処理学Ⅰ」（保健医療学部）、「情報処理学Ⅱ」（保健医療学部以外）は、全学共通の基礎分野の卒業必修科目であるため、学部・学科横断的に希望する学生全員が受講可能である。また、共通教育センター会議のデータサイエンス部門には、各学部（学科）から部門員を配置しているため、適切な支援体制も整備できている。
A79: ⑩ | B79: できる限り多くの学生が履修できるような具体的な周知方法・取組
B80: 上記⑧のとおり、入学後の学科ごとのオリエンテーションにて説明を行い、履修促進を図っている。また、本学のWEBサイトのトップ画面にプログラム専用ページへのリンクを掲載して、学生が情報を受け取りやすい環境を整備している。
A93: ⑪ | B93: できる限り多くの学生が履修・修得できるようなサポート体制
B94: 上記⑧のとおり、本プログラムの必修科目「データサイエンス入門」と「情報処理学Ⅰ」（保健医療学部）、「情報処理学Ⅱ」（保健医療学部以外）は、卒業必修であるため、全学生が履修する。本プログラムの選択科目については、履修指導の一環としてアカデミック・アドバイザーよる指導・助言が行われている。データ操作の修得に困難を抱えている学生をフォローするために、令和5年度には授業時間外に学修サポーターによる相談会を開催する予定である。
A107: ⑫ | B107: 授業時間内外で学習指導、質問を受け付ける具体的な仕組み
B108: 本学では、授業中のリアルタイムコミュニケーションツールとして、responを導入している。本プログラムの中心的科目である「データサイエンス入門」では、授業中のワークの成果の共有やクイズへの回答の共有、質問の受付などに活用している。また、「情報処理学Ⅰ」「情報処理学Ⅱ」は演習科目であり、演習中には適宜学生の質問に答えている。 また、LMSとしてはmanabaを導入している。manabaの掲示板機能や個別指導機能を活用して、全体や個別に質問を受け付けたり学習指導をしたりしている。 さらに、上記⑪のとおり、令和5年度は授業時間外に学修サポーターによる相談会を開催する予定である。

Sheet 様式４　自己点検・評価
I1: 様式４
H2: 大学等名 | I2: ='【保医】様式１-5'!C2 -> 関西福祉科学大学
A3: 自己点検・評価について
A5: ① | B5: プログラムの自己点検・評価を行う体制（委員会・組織等）
B6: 共通教育センター会議
D8: （責任者名） | E8: 木村貴彦 | G8: （役職名） | H8: 共通教育センター長
A10: ② | B10: 自己点検・評価体制における意見等
B11: 自己点検・評価の視点 | E11: 自己点検・評価体制における意見・結果・改善に向けた取組等
B12: 学内からの視点
C13: プログラムの履修・修得状況 | E13: 本プログラムの必修科目「データサイエンス入門」と「情報処理学Ⅰ」（保健医療学部）、「情報処理学Ⅱ」（保健医療学部以外）は、全学共通の基礎分野の卒業必修科目であるため、全ての学生が履修している。 また、修得状況については共通教育センターが把握できる体制にある。
C14: 学修成果 | E14: 本プログラムの必修科目「データサイエンス入門」と「情報処理学Ⅰ」（保健医療学部）、「情報処理学Ⅱ」（保健医療学部以外）の成績は、共通教育センター会議で確認し、学修成果を判断する体制を取っている。 令和4年度は「データサイエンス入門」「情報処理学Ⅰ」には大きな問題がないが、「情報処理学Ⅱ」は秀と優の合計が約50％いる一方で、不合格者が約16％存在した。データの操作については十分に学修できたと考えられる層も多いが、不十分な学修状況にある学生も多いのが現状である。 データ操作の修得に困難を抱えている学生をフォローするために、令和5年度には授業時間外に学修サポーターによる相談会を開催する予定である。
C15: 学生アンケート等を通じた学生の内容の理解度 | E15: 「データサイエンス入門」の受講者にアンケートを実施し、当該授業やプログラム全体の理解度を確認した。「受講を通じてデータやAIの社会での役割について理解が深まったか」の質問に対し、「わかるようになった」と回答した学生が75.2％で、「どちらとも言えない」が16.1％、「わからなかった」が8.7％であった。また「この科目の受講を通じて、自分自身が将来データやAIを活用していけるようになったと思うか」の質問に対し、「そう思う」と回答した学生が57.1％で、「どちらとも言えない」が32.0％、「そう思わない」が10.9％であった。今後、内容の理解度の向上と利活用力を身に付けさせる工夫が必要である。
C16: 学生アンケート等を通じた後輩等他の学生への推奨度 | E16: 「データサイエンス入門」の受講生に対するアンケートにおいて、後輩学生等への推奨について確認している。「面白いし、ためになるから熱心に受講しよう」を10、「卒業必修だから受講しないといけない」を１として10段階で評定してもらった。その結果、平均は5.17であった。内訳をみると、1～3が23.3％、4～7が61.5％、8～10が15.2％であった。全体的に5点前後の範囲に集中しており、高評価よりも低評価がやや多い傾向にあった。こうしたアンケートの結果を基幹科目である「データサイエンス入門」の担当教員と共有し、学生から見た魅力の向上を図っていく。
C17: 全学的な履修者数、履修率向上に向けた計画の達成・進捗状況 | E17: 本プログラムの必修科目「データサイエンス入門」と「情報処理学Ⅰ」（保健医療学部）、「情報処理学Ⅱ」（保健医療学部以外）は、全学共通の基礎分野の卒業必修科目であるため、全ての学生が履修している。共通教育センター会議のデータサイエンス部門では、全学および各学部学科における数理・データサイエンス・AI教育の内容について各専門分野からの観点も取り入れ見直し等を行っている。 なお、令和5年度より新入生オリエンテーション時に本プログラムの目的と意義を説明する予定である。また、令和5年度のシラバスにデータサイエンス教育プログラムの対象科目であることを明記するなどして、学生の履修を推進する。
B18: 学外からの視点
C19: 教育プログラム修了者の進路、活躍状況、企業等の評価 | E19: 本プログラムは令和4年度に開始しているため、現時点で本プログラムを修了した卒業生はいないが、卒後1年半後を目途に、卒業生とその就職先を対象に毎年「卒業生・事業所アンケート」を実施しており、卒業生の進路先や活躍状況、企業等の評価を把握する仕組みを設けている。
C20: 産業界からの視点を含めた教育プログラム内容・手法等への意見 | E20: 就職先も対象にした「卒業生・事業所アンケート」にて、本プログラムの内容・手法等について意見を聴取した。それらの産業界の視点も踏まえて、共通教育センター会議データサイエンス部門にてカリキュラムの見直し・改善等行う。
B21: 数理・データサイエンス・ＡＩを「学ぶ楽しさ」「学ぶことの意義」を理解させること | E21: 「データサイエンス入門」の初回に、それぞれの学科で目指す資格を活かした職業に就いた際に、データサイエンスやAIがどのような役割を果たしているか、各学部（学科）の教員から紹介してもらい、「学ぶことの意義」について理解を深めている。また、授業中のワークや毎回の課題で、「自らの将来」との関連を考えさせるようにしている。
B22: 内容・水準を維持・向上しつつ、より「分かりやすい」授業とすること | E22: 授業で紹介するデータやAIの活用事例は、なるべく学生の身近な内容を取り上げ、また授業中のワークにも学生に身近なテーマを採用することで、学生がとらえやすい授業内容にしている。
