Workbook

Sheet 様式１-1　プログラムを構成する授業科目（経営・社会・薬）
R1: 様式１-1 | T1: 「学部・学科によって、修了要件は相違する」場合は、本シートを複製の上＜様式１－〇＞と枝番号を付してください
B2: 大学等名 | C2: 青森大学
B3: プログラム名 | C3: データサイエンス・AIリテラシープログラム
A5: プログラムを構成する授業科目について
A7: ① 対象となる学部・学科名称 | J7: ② 教育プログラムの修了要件 | K7: 学部・学科によって、修了要件は相違する
B9: 総合経営学部・経営学科、社会学部・社会学科、薬学部・薬学科
A12: ③ 修了要件
B13: 総合経営学部・経営学科、社会学部・社会学科、薬学部・薬学科の学生は、「情報社会と情報倫理」（２単位）および「情報の集計・分析」（１単位）を修得すること。 | V13: 【プルダウンリスト】
V14: 令和４年度以前より、履修することが必須のプログラムとして実施
V15: 令和７年度までに履修必須とする計画
V16: 令和８年度以降に履修必須とする計画、又は未定
B20: 必要最低単位数 | C20: 3 | E20: 単位 | J20: 履修必須の有無 | K20: 令和８年度以降に履修必須とする計画、又は未定
A22: ④ 現在進行中の社会変化（第４次産業革命、Society 5.0、データ駆動型社会等）に深く寄与しているものであり、それが自らの生活と密接に結びついている」の内容を含む授業科目
B24: 授業科目 | F24: 単位数 | G24: 必須 | H24: 1-1 | I24: 1-6 | J24: 授業科目 | P24: 単位数 | Q24: 必須 | R24: 1-1 | S24: 1-6
B25: 情報社会と情報倫理 | F25: 2 | G25: ○ | H25: ○ | I25: ○
A33: ⑤ 「社会で活用されているデータ」や「データの活用領域」は非常に広範囲であって、日常生活や社会の課題を解決する有用なツールになり得るもの」の内容を含む授業科目
B35: 授業科目 | F35: 単位数 | G35: 必須 | H35: 1-2 | I35: 1-3 | J35: 授業科目 | P35: 単位数 | Q35: 必須 | R35: 1-2 | S35: 1-3
B36: 情報の集計・分析 | F36: 1 | G36: ○ | H36: ○ | I36: ○
A44: ⑥ 「様々なデータ利活用の現場におけるデータ利活用事例が示され、様々な適用領域（流通、製造、金融、サービス、インフラ、公共、ヘルスケア等）の知見と組み合わせることで価値を創出するもの」の内容を含む授業科目
B46: 授業科目 | F46: 単位数 | G46: 必須 | H46: 1-4 | I46: 1-5 | J46: 授業科目 | P46: 単位数 | Q46: 必須 | R46: 1-4 | S46: 1-5
B47: 情報社会と情報倫理 | F47: 2 | G47: ○ | H47: ○ | I47: ○
A55: ⑦ 「活用に当たっての様々な留意事項（ELSI、個人情報、データ倫理、ＡＩ社会原則等）を考慮し、情報セキュリティや情報漏洩等、データを守る上での留意事項への理解をする」の内容を含む授業科目
B57: 授業科目 | F57: 単位数 | G57: 必須 | H57: 3-1 | I57: 3-2 | J57: 授業科目 | P57: 単位数 | Q57: 必須 | R57: 3-1 | S57: 3-2
B58: 情報社会と情報倫理 | F58: 2 | G58: ○ | H58: ○ | I58: ○
A66: ⑧ 「実データ・実課題（学術データ等を含む）を用いた演習など、社会での実例を題材として、「データを読む、説明する、扱う」といった数理・データサイエンス・ＡＩの基本的な活用法に関するもの」の内容を含む授業科目
B68: 授業科目 | E68: 単位数 | F68: 必須 | G68: 2-1 | H68: 2-2 | I68: 2-3 | J68: 授業科目 | O68: 単位数 | P68: 必須 | Q68: 2-1 | R68: 2-2 | S68: 2-3
B69: 情報の集計・分析 | E69: 1 | F69: ○ | G69: ○ | H69: ○ | I69: ○
A77: ⑨ 選択「４．オプション」の内容を含む授業科目
B78: 授業科目 | F78: 選択項目 | J78: 授業科目 | P78: 選択項目
A87: ⑩ プログラムを構成する授業の内容
B88: 授業に含まれている内容・要素 | D88: 講義内容
B89: （１）現在進行中の社会変化（第４次産業革命、Society 5.0、データ駆動型社会等）に深く寄与しているものであり、それが自らの生活と密接に結びついている | C89: 1-1 | D89: ・ビッグデータ、IoT、AI、ロボット：「情報社会と情報倫理」（2回目） ・データ量の増加、計算機の処理性能の向上、AIの非連続的進化：「情報社会と情報倫理」（3回目）（4回目） ・第4次産業革命、Society 5.0、データ駆動型社会：「情報社会と情報倫理」（2回目） ・複数技術を組み合わせたAIサービス：「情報社会と情報倫理」（3回目） ・人間の知的活動とAIの関係性：「情報社会と情報倫理」（2回目） ・データを起点としたものの見方、人間の知的活動を起点としたものの見方：「情報社会と情報倫理」（5回目）
C90: 1-6 | D90: ・AI等を活用した新しいビジネスモデル(シェアリングエコノミー、商品のレコメンデーションなど)：「情報社会と情報倫理」（10回目）（14回目） ・AI最新技術の活用例（深層生成モデル、敵対的生成ネットワーク、強化学習、転移学習など）：「情報社会と情報倫理」（10回目）（11回目）
B91: （２）「社会で活用されているデータ」や「データの活用領域」は非常に広範囲であって、日常生活や社会の課題を解決する有用なツールになり得るもの | C91: 1-2 | D91: ・調査データ、実験データ、人の行動ログデータ、機械の稼働ログデータなど：「情報の集計・分析」（5回目）（14回目） ・1次データ、2次データ、データのメタ化：「情報の集計・分析」（2回目）（3回目） ・構造化データ、非構造化データ（文章、画像/動画、音声/音楽など）：「情報の集計・分析」（4回目） ・データ作成（ビッグデータとアノテーション）：「情報の集計・分析」（8回目） ・データのオープン化（オープンデータ）：「情報の集計・分析」（11回目）
C92: 1-3 | D92: ・データ・AI活用領域の広がり(生産、消費、文化活動など)：「情報の集計・分析」（14回目） ・研究開発、調達、製造、物流、販売、マーケティング、サービスなど：「情報の集計・分析」（7回目）（9回目） ・仮説検証、知識発見、原因究明、計画策定、判断支援、活動代替、新規生成など：「情報の集計・分析」（12回目）
B93: （３）様々なデータ利活用の現場におけるデータ利活用事例が示され、様々な適用領域（流通、製造、金融、サービス、インフラ、公共、ヘルスケア等）の知見と組み合わせることで価値を創出するもの | C93: 1-4 | D93: ・データ解析：予測、グルーピング、パターン発見、最適化、シミュレーション・データ同化など：「情報社会と情報倫理」6回目） ・データ可視化：複合グラフ、2軸グラフ、多次元の可視化、関係性の可視化、地図上の可視化、 挙動・軌跡の可視化、リアルタイム可視化など：「情報社会と情報倫理」（6回目）（10回目）（11回目） ・非構造化データ処理：言語処理、画像/動画処理、音声/音楽処理など：「情報社会と情報倫理」（10回目）（11回目） ・特化型AIと汎用AI、今のAIで出来ることと出来ないこと、AIとビッグデータ：「情報社会と情報倫理」（13回目）（14回目） ・認識技術、ルールベース、自動化技術：「情報社会と情報倫理」(6回目）（13回目）
C94: 1-5 | D94: ・データサイエンスのサイクル（課題抽出と定式化、データの取得・管理・加工、探索的データ解析、データ解析と推論、結果の共有・伝達、課題解決に向けた提案）：「情報社会と情報倫理」（11回目）（14回目） ・流通、製造、金融、サービス、インフラ、公共、ヘルスケア等におけるデータ・AI利活用事例紹介：「情報社会と情報倫理」（10回目）（14回目）
B95: （４）活用に当たっての様々な留意事項（ELSI、個人情報、データ倫理、ＡＩ社会原則等）を考慮し、情報セキュリティや情報漏洩等、データを守る上での留意事項への理解をする | C95: 3-1 | D95: ・ELSI（Ethical, Legal and Social Issues）：「情報社会と情報倫理」（1回目）（8回目）（12回目） ・個人情報保護、EU一般データ保護規則(GDPR)、忘れられる権利、オプトアウト：「情報社会と情報倫理」（8回目） ・データ倫理：データのねつ造、改ざん、盗用、プライバシー保護：「情報社会と情報倫理」（7回目）（11回目） ・AI社会原則（公平性、説明責任、透明性、人間中心の判断）：「情報社会と情報倫理」（6回目）（8回目） ・データバイアス、アルゴリズムバイアス：「情報社会と情報倫理」（6回目）（11回目） ・AIサービスの責任論：「情報社会と情報倫理」（8回目）（9回目） ・データ・AI活用における負の事例紹介：「情報社会と情報倫理」（7回目）（14回目）
C96: 3-2 | D96: ・情報セキュリティ：機密性、完全性、可用性：「情報社会と情報倫理」（6回目） ・匿名加工情報、暗号化、パスワード、悪意ある情報搾取：「情報社会と情報倫理」（6回目）（8回目） ・情報漏洩等によるセキュリティ事故の事例紹介：「情報社会と情報倫理」（7回目）（11回目）
B97: （５）実データ・実課題（学術データ等を含む）を用いた演習など、社会での実例を題材として、「データを読む、説明する、扱う」といった数理・データサイエンス・ＡＩの基本的な活用法に関するもの | C97: 2-1 | D97: ・データの種類（量的変数、質的変数）：「情報の集計・分析」（1回目）（2回目） ・データの分布(ヒストグラム)と代表値（平均値、中央値、最頻値）：「情報の集計・分析」（9回目） ・代表値の性質の違い（実社会では平均値＝最頻値でないことが多い）：「情報の集計・分析」（4回目） ・データのばらつき（分散、標準偏差、偏差値）：「情報の集計・分析」（6回目） ・観測データに含まれる誤差の扱い：「情報の集計・分析」（12回目） ・打ち切りや脱落を含むデータ、層別の必要なデータ：「情報の集計・分析」（6回目）（8回目） ・相関と因果（相関係数、擬似相関、交絡）：「情報の集計・分析」（11回目） ・母集団と標本抽出（国勢調査、アンケート調査、全数調査、単純無作為抽出、層別抽出、多段抽出）：「情報の集計・分析」（5回目）（13回目） ・クロス集計表、分割表、相関係数行列、散布図行列：「情報の集計・分析」（7回目）（8回目） ・統計情報の正しい理解（誇張表現に惑わされない）：「情報の集計・分析」（10回目）（14回目）
...

Sheet 様式１-2　プログラムを構成する授業科目（ソフト）
R1: 様式１-2 | T1: 「学部・学科によって、修了要件は相違する」場合は、本シートを複製の上＜様式１－〇＞と枝番号を付してください
B2: 大学等名 | C2: 青森大学
B3: プログラム名 | C3: データサイエンス・AIリテラシープログラム
A5: プログラムを構成する授業科目について
A7: ① 対象となる学部・学科名称 | J7: ② 教育プログラムの修了要件 | K7: 学部・学科によって、修了要件は相違する
B9: ソフトウェア情報学部・ソフトウェア情報学科
A12: ③ 修了要件
B13: ソフトウェア情報学部・ソフトウェア情報学科の学生は、「情報社会と情報倫理」（２単位）および「情報リテラシー」（２単位）を修得すること。 | V13: 【プルダウンリスト】
V14: 令和４年度以前より、履修することが必須のプログラムとして実施
V15: 令和７年度までに履修必須とする計画
V16: 令和８年度以降に履修必須とする計画、又は未定
B20: 必要最低単位数 | C20: 4 | E20: 単位 | J20: 履修必須の有無 | K20: 令和８年度以降に履修必須とする計画、又は未定
A22: ④ 現在進行中の社会変化（第４次産業革命、Society 5.0、データ駆動型社会等）に深く寄与しているものであり、それが自らの生活と密接に結びついている」の内容を含む授業科目
B24: 授業科目 | F24: 単位数 | G24: 必須 | H24: 1-1 | I24: 1-6 | J24: 授業科目 | P24: 単位数 | Q24: 必須 | R24: 1-1 | S24: 1-6
B25: 情報社会と情報倫理 | F25: 2 | G25: ○ | H25: ○ | I25: ○
A33: ⑤ 「社会で活用されているデータ」や「データの活用領域」は非常に広範囲であって、日常生活や社会の課題を解決する有用なツールになり得るもの」の内容を含む授業科目
B35: 授業科目 | F35: 単位数 | G35: 必須 | H35: 1-2 | I35: 1-3 | J35: 授業科目 | P35: 単位数 | Q35: 必須 | R35: 1-2 | S35: 1-3
B36: 情報社会と情報倫理 | F36: 2 | G36: ○ | H36: ○ | I36: ○
A44: ⑥ 「様々なデータ利活用の現場におけるデータ利活用事例が示され、様々な適用領域（流通、製造、金融、サービス、インフラ、公共、ヘルスケア等）の知見と組み合わせることで価値を創出するもの」の内容を含む授業科目
B46: 授業科目 | F46: 単位数 | G46: 必須 | H46: 1-4 | I46: 1-5 | J46: 授業科目 | P46: 単位数 | Q46: 必須 | R46: 1-4 | S46: 1-5
B47: 情報社会と情報倫理 | F47: 2 | G47: ○ | H47: ○ | I47: ○
A55: ⑦ 「活用に当たっての様々な留意事項（ELSI、個人情報、データ倫理、ＡＩ社会原則等）を考慮し、情報セキュリティや情報漏洩等、データを守る上での留意事項への理解をする」の内容を含む授業科目
B57: 授業科目 | F57: 単位数 | G57: 必須 | H57: 3-1 | I57: 3-2 | J57: 授業科目 | P57: 単位数 | Q57: 必須 | R57: 3-1 | S57: 3-2
B58: 情報社会と情報倫理 | F58: 2 | G58: ○ | H58: ○ | I58: ○
A66: ⑧ 「実データ・実課題（学術データ等を含む）を用いた演習など、社会での実例を題材として、「データを読む、説明する、扱う」といった数理・データサイエンス・ＡＩの基本的な活用法に関するもの」の内容を含む授業科目
B68: 授業科目 | E68: 単位数 | F68: 必須 | G68: 2-1 | H68: 2-2 | I68: 2-3 | J68: 授業科目 | O68: 単位数 | P68: 必須 | Q68: 2-1 | R68: 2-2 | S68: 2-3
B69: 情報リテラシー | E69: 2 | F69: ○ | G69: ○ | H69: ○ | I69: ○
A77: ⑨ 選択「４．オプション」の内容を含む授業科目
B78: 授業科目 | F78: 選択項目 | J78: 授業科目 | P78: 選択項目
A87: ⑩ プログラムを構成する授業の内容
B88: 授業に含まれている内容・要素 | D88: 講義内容
B89: （１）現在進行中の社会変化（第４次産業革命、Society 5.0、データ駆動型社会等）に深く寄与しているものであり、それが自らの生活と密接に結びついている | C89: 1-1 | D89: ・ビッグデータ、IoT、AI、ロボット：「情報社会と情報倫理」（2回目） ・データ量の増加、計算機の処理性能の向上、AIの非連続的進化：「情報社会と情報倫理」（3回目）（4回目） ・第4次産業革命、Society 5.0、データ駆動型社会：「情報社会と情報倫理」（2回目） ・複数技術を組み合わせたAIサービス：「情報社会と情報倫理」（3回目） ・人間の知的活動とAIの関係性：「情報社会と情報倫理」（2回目） ・データを起点としたものの見方、人間の知的活動を起点としたものの見方：「情報社会と情報倫理」（5回目）
C90: 1-6 | D90: ・AI等を活用した新しいビジネスモデル(シェアリングエコノミー、商品のレコメンデーションなど)：「情報社会と情報倫理」（10回目）（14回目） ・AI最新技術の活用例（深層生成モデル、敵対的生成ネットワーク、強化学習、転移学習など）：「情報社会と情報倫理」（10回目）（11回目）
B91: （２）「社会で活用されているデータ」や「データの活用領域」は非常に広範囲であって、日常生活や社会の課題を解決する有用なツールになり得るもの | C91: 1-2 | D91: ・調査データ、実験データ、人の行動ログデータ、機械の稼働ログデータなど：「情報社会と情報倫理」（11回目） ・1次データ、2次データ、データのメタ化：「情報社会と情報倫理」（11回目） ・構造化データ、非構造化データ（文章、画像/動画、音声/音楽など）：「情報社会と情報倫理」（4回目）（6回目）（10回目） ・データ作成（ビッグデータとアノテーション）：「情報社会と情報倫理」（6回目） ・データのオープン化（オープンデータ）：「情報社会と情報倫理」（10回目）（11回目）（14回目）
C92: 1-3 | D92: ・データ・AI活用領域の広がり(生産、消費、文化活動など)：「情報社会と情報倫理」（10回目）（14回目） ・研究開発、調達、製造、物流、販売、マーケティング、サービスなど：「情報社会と情報倫理」（11回目） ・仮説検証、知識発見、原因究明、計画策定、判断支援、活動代替、新規生成など：「情報社会と情報倫理」（6回目）（10回目）（11回目）
B93: （３）様々なデータ利活用の現場におけるデータ利活用事例が示され、様々な適用領域（流通、製造、金融、サービス、インフラ、公共、ヘルスケア等）の知見と組み合わせることで価値を創出するもの | C93: 1-4 | D93: ・データ解析：予測、グルーピング、パターン発見、最適化、シミュレーション・データ同化など：「情報社会と情報倫理」6回目） ・データ可視化：複合グラフ、2軸グラフ、多次元の可視化、関係性の可視化、地図上の可視化、挙動・軌跡の可視化、リアルタイム可視化など：「情報社会と情報倫理」（6回目） ・非構造化データ処理：言語処理、画像/動画処理、音声/音楽処理など：「情報社会と情報倫理」（10回目） ・特化型AIと汎用AI、今のAIで出来ることと出来ないこと、AIとビッグデータ：「情報社会と情報倫理」（13回目） ・認識技術、ルールベース、自動化技術：「情報社会と情報倫理」（13回目）
C94: 1-5 | D94: ・データサイエンスのサイクル（課題抽出と定式化、データの取得・管理・加工、探索的データ解析、データ解析と推論、結果の共有・伝達、課題解決に向けた提案）：「情報社会と情報倫理」（11回目）（14回目） ・流通、製造、金融、サービス、インフラ、公共、ヘルスケア等におけるデータ・AI利活用事例紹介：「情報社会と情報倫理」（10回目）（14回目）
B95: （４）活用に当たっての様々な留意事項（ELSI、個人情報、データ倫理、ＡＩ社会原則等）を考慮し、情報セキュリティや情報漏洩等、データを守る上での留意事項への理解をする | C95: 3-1 | D95: ・ELSI（Ethical, Legal and Social Issues）：「情報社会と情報倫理」（1回目）（8回目）（12回目） ・個人情報保護、EU一般データ保護規則(GDPR)、忘れられる権利、オプトアウト：「情報社会と情報倫理」（8回目） ・データ倫理：データのねつ造、改ざん、盗用、プライバシー保護：「情報社会と情報倫理」（7回目）（11回目） ・AI社会原則（公平性、説明責任、透明性、人間中心の判断）：「情報社会と情報倫理」（6回目）（8回目） ・データバイアス、アルゴリズムバイアス：「情報社会と情報倫理」（6回目）（11回目） ・AIサービスの責任論：「情報社会と情報倫理」（8回目）（9回目） ・データ・AI活用における負の事例紹介：「情報社会と情報倫理」（7回目）（14回目）
C96: 3-2 | D96: ・情報セキュリティ：機密性、完全性、可用性：「情報社会と情報倫理」（6回目） ・匿名加工情報、暗号化、パスワード、悪意ある情報搾取：「情報社会と情報倫理」（6回目）（8回目） ・情報漏洩等によるセキュリティ事故の事例紹介：「情報社会と情報倫理」（7回目）（11回目）
B97: （５）実データ・実課題（学術データ等を含む）を用いた演習など、社会での実例を題材として、「データを読む、説明する、扱う」といった数理・データサイエンス・ＡＩの基本的な活用法に関するもの | C97: 2-1 | D97: ・データの種類（量的変数、質的変数）：「情報リテラシー（1回目）（3回目） ・データの分布(ヒストグラム)と代表値（平均値、中央値、最頻値）：「情報リテラシー（4回目） ・代表値の性質の違い（実社会では平均値＝最頻値でないことが多い）：「情報リテラシー（5回目） ・データのばらつき（分散、標準偏差、偏差値）：「情報リテラシー（6回目） ・観測データに含まれる誤差の扱い：「情報リテラシー（8回目） ・打ち切りや脱落を含むデータ、層別の必要なデータ：「情報リテラシー（9回目） ・相関と因果（相関係数、擬似相関、交絡）：「情報リテラシー（9回目） ・母集団と標本抽出（国勢調査、アンケート調査、全数調査、単純無作為抽出、層別抽出、多段抽出）：「情報リテラシー（8回目）（9回目） ・クロス集計表、分割表、相関係数行列、散布図行列：「情報リテラシー（8回目）（9回目） ・統計情報の正しい理解（誇張表現に惑わされない）：「情報リテラシー（7回目）
...

Sheet 様式２ 履修者等数の実績
AQ1: 様式２
AL2: 大学等名 | AM2: ='様式１-1 プログラムを構成する授業科目（経営・社会・薬）'!C2 -> 青森大学
A3: プログラムの履修者数等の実績について
A5: ①プログラム開設年度 | C5: 令和4 | E5: 年度
A7: ②履修者・修了者の実績
B9: 学部・学科名称 | C9: 学生数 | D9: 入学 定員 | E9: 収容 定員 | F9: 令和4年度 | L9: 令和3年度 | R9: 令和2年度 | X9: 令和元年度 | AD9: 平成30年度 | AJ9: 平成29年度 | AP9: 履修者数 合計 | AQ9: 履修率
F10: 履修者数 | I10: 修了者数 | L10: 履修者数 | O10: 修了者数 | R10: 履修者数 | U10: 修了者数 | X10: 履修者数 | AA10: 修了者数 | AD10: 履修者数 | AG10: 修了者数 | AJ10: 履修者数 | AM10: 修了者数
F11: 合計 | G11: 男性 | H11: 女性 | I11: 合計 | J11: 男性 | K11: 女性 | L11: 合計 | M11: 男性 | N11: 女性 | O11: 合計 | P11: 男性 | Q11: 女性 | R11: 合計 | S11: 男性 | T11: 女性 | U11: 合計 | V11: 男性 | W11: 女性 | X11: 合計 | Y11: 男性 | Z11: 女性 | AA11: 合計 | AB11: 男性 | AC11: 女性 | AD11: 合計 | AE11: 男性 | AF11: 女性 | AG11: 合計 | AH11: 男性 | AI11: 女性 | AJ11: 合計 | AK11: 男性 | AL11: 女性 | AM11: 合計 | AN11: 男性 | AO11: 女性
B12: 総合経営学部・経営学科 | C12: 461 | D12: 110 | E12: 440 | F12: =G12+H12 -> 285 | G12: 236 | H12: 49 | I12: =J12+K12 -> 250 | J12: 208 | K12: 42 | L12: =M12+N12 -> 0 | O12: =P12+Q12 -> 0 | R12: =S12+T12 -> 0 | U12: =V12+W12 -> 0 | X12: =Y12+Z12 -> 0 | AA12: =AB12+AC12 -> 0 | AD12: =AE12+AF12 -> 0 | AG12: =AH12+AI12 -> 0 | AJ12: =AK12+AL12 -> 0 | AM12: =AN12+AO12 -> 0 | AP12: =F12+L12+R12+X12+AD12+AJ12 -> 285 | AQ12: =AP12/E12 -> 0.64772727
B13: 社会学部・社会学科 | C13: 289 | D13: 70 | E13: 280 | F13: =G13+H13 -> 177 | G13: 108 | H13: 69 | I13: =J13+K13 -> 163 | J13: 97 | K13: 66 | L13: =M13+N13 -> 0 | O13: =P13+Q13 -> 0 | R13: =S13+T13 -> 0 | U13: =V13+W13 -> 0 | X13: =Y13+Z13 -> 0 | AA13: =AB13+AC13 -> 0 | AD13: =AE13+AF13 -> 0 | AG13: =AH13+AI13 -> 0 | AJ13: =AK13+AL13 -> 0 | AM13: =AN13+AO13 -> 0 | AP13: =F13+L13+R13+X13+AD13+AJ13 -> 177 | AQ13: =AP13/E13 -> 0.63214286
B14: ソフトウェア情報学部・ソフトウェア情報学科 | C14: 224 | D14: 50 | E14: 200 | F14: =G14+H14 -> 136 | G14: 122 | H14: 14 | I14: =J14+K14 -> 119 | J14: 105 | K14: 14 | L14: =M14+N14 -> 0 | O14: =P14+Q14 -> 0 | R14: =S14+T14 -> 0 | U14: =V14+W14 -> 0 | X14: =Y14+Z14 -> 0 | AA14: =AB14+AC14 -> 0 | AD14: =AE14+AF14 -> 0 | AG14: =AH14+AI14 -> 0 | AJ14: =AK14+AL14 -> 0 | AM14: =AN14+AO14 -> 0 | AP14: =F14+L14+R14+X14+AD14+AJ14 -> 136 | AQ14: =AP14/E14 -> 0.68
B15: 薬学部・薬学科 | C15: 234 | D15: 70 | E15: 420 | F15: =G15+H15 -> 60 | G15: 24 | H15: 36 | I15: =J15+K15 -> 59 | J15: 23 | K15: 36 | L15: =M15+N15 -> 0 | O15: =P15+Q15 -> 0 | R15: =S15+T15 -> 0 | U15: =V15+W15 -> 0 | X15: =Y15+Z15 -> 0 | AA15: =AB15+AC15 -> 0 | AD15: =AE15+AF15 -> 0 | AG15: =AH15+AI15 -> 0 | AJ15: =AK15+AL15 -> 0 | AM15: =AN15+AO15 -> 0 | AP15: =F15+L15+R15+X15+AD15+AJ15 -> 60 | AQ15: =AP15/E15 -> 0.14285714
F16: =G16+H16 -> 0 | I16: =J16+K16 -> 0 | L16: =M16+N16 -> 0 | O16: =P16+Q16 -> 0 | R16: =S16+T16 -> 0 | U16: =V16+W16 -> 0 | X16: =Y16+Z16 -> 0 | AA16: =AB16+AC16 -> 0 | AD16: =AE16+AF16 -> 0 | AG16: =AH16+AI16 -> 0 | AJ16: =AK16+AL16 -> 0 | AM16: =AN16+AO16 -> 0 | AP16: =F16+L16+R16+X16+AD16+AJ16 -> 0 | AQ16: =AP16/E16 -> #DIV/0!
F17: =G17+H17 -> 0 | I17: =J17+K17 -> 0 | L17: =M17+N17 -> 0 | O17: =P17+Q17 -> 0 | R17: =S17+T17 -> 0 | U17: =V17+W17 -> 0 | X17: =Y17+Z17 -> 0 | AA17: =AB17+AC17 -> 0 | AD17: =AE17+AF17 -> 0 | AG17: =AH17+AI17 -> 0 | AJ17: =AK17+AL17 -> 0 | AM17: =AN17+AO17 -> 0 | AP17: =F17+L17+R17+X17+AD17+AJ17 -> 0 | AQ17: =AP17/E17 -> #DIV/0!
F18: =G18+H18 -> 0 | I18: =J18+K18 -> 0 | L18: =M18+N18 -> 0 | O18: =P18+Q18 -> 0 | R18: =S18+T18 -> 0 | U18: =V18+W18 -> 0 | X18: =Y18+Z18 -> 0 | AA18: =AB18+AC18 -> 0 | AD18: =AE18+AF18 -> 0 | AG18: =AH18+AI18 -> 0 | AJ18: =AK18+AL18 -> 0 | AM18: =AN18+AO18 -> 0 | AP18: =F18+L18+R18+X18+AD18+AJ18 -> 0 | AQ18: =AP18/E18 -> #DIV/0!
F19: =G19+H19 -> 0 | I19: =J19+K19 -> 0 | L19: =M19+N19 -> 0 | O19: =P19+Q19 -> 0 | R19: =S19+T19 -> 0 | U19: =V19+W19 -> 0 | X19: =Y19+Z19 -> 0 | AA19: =AB19+AC19 -> 0 | AD19: =AE19+AF19 -> 0 | AG19: =AH19+AI19 -> 0 | AJ19: =AK19+AL19 -> 0 | AM19: =AN19+AO19 -> 0 | AP19: =F19+L19+R19+X19+AD19+AJ19 -> 0 | AQ19: =AP19/E19 -> #DIV/0!
F20: =G20+H20 -> 0 | I20: =J20+K20 -> 0 | L20: =M20+N20 -> 0 | O20: =P20+Q20 -> 0 | R20: =S20+T20 -> 0 | U20: =V20+W20 -> 0 | X20: =Y20+Z20 -> 0 | AA20: =AB20+AC20 -> 0 | AD20: =AE20+AF20 -> 0 | AG20: =AH20+AI20 -> 0 | AJ20: =AK20+AL20 -> 0 | AM20: =AN20+AO20 -> 0 | AP20: =F20+L20+R20+X20+AD20+AJ20 -> 0 | AQ20: =AP20/E20 -> #DIV/0!
F21: =G21+H21 -> 0 | I21: =J21+K21 -> 0 | L21: =M21+N21 -> 0 | O21: =P21+Q21 -> 0 | R21: =S21+T21 -> 0 | U21: =V21+W21 -> 0 | X21: =Y21+Z21 -> 0 | AA21: =AB21+AC21 -> 0 | AD21: =AE21+AF21 -> 0 | AG21: =AH21+AI21 -> 0 | AJ21: =AK21+AL21 -> 0 | AM21: =AN21+AO21 -> 0 | AP21: =F21+L21+R21+X21+AD21+AJ21 -> 0 | AQ21: =AP21/E21 -> #DIV/0!
F22: =G22+H22 -> 0 | I22: =J22+K22 -> 0 | L22: =M22+N22 -> 0 | O22: =P22+Q22 -> 0 | R22: =S22+T22 -> 0 | U22: =V22+W22 -> 0 | X22: =Y22+Z22 -> 0 | AA22: =AB22+AC22 -> 0 | AD22: =AE22+AF22 -> 0 | AG22: =AH22+AI22 -> 0 | AJ22: =AK22+AL22 -> 0 | AM22: =AN22+AO22 -> 0 | AP22: =F22+L22+R22+X22+AD22+AJ22 -> 0 | AQ22: =AP22/E22 -> #DIV/0!
F23: =G23+H23 -> 0 | I23: =J23+K23 -> 0 | L23: =M23+N23 -> 0 | O23: =P23+Q23 -> 0 | R23: =S23+T23 -> 0 | U23: =V23+W23 -> 0 | X23: =Y23+Z23 -> 0 | AA23: =AB23+AC23 -> 0 | AD23: =AE23+AF23 -> 0 | AG23: =AH23+AI23 -> 0 | AJ23: =AK23+AL23 -> 0 | AM23: =AN23+AO23 -> 0 | AP23: =F23+L23+R23+X23+AD23+AJ23 -> 0 | AQ23: =AP23/E23 -> #DIV/0!
F24: =G24+H24 -> 0 | I24: =J24+K24 -> 0 | L24: =M24+N24 -> 0 | O24: =P24+Q24 -> 0 | R24: =S24+T24 -> 0 | U24: =V24+W24 -> 0 | X24: =Y24+Z24 -> 0 | AA24: =AB24+AC24 -> 0 | AD24: =AE24+AF24 -> 0 | AG24: =AH24+AI24 -> 0 | AJ24: =AK24+AL24 -> 0 | AM24: =AN24+AO24 -> 0 | AP24: =F24+L24+R24+X24+AD24+AJ24 -> 0 | AQ24: =AP24/E24 -> #DIV/0!
F25: =G25+H25 -> 0 | I25: =J25+K25 -> 0 | L25: =M25+N25 -> 0 | O25: =P25+Q25 -> 0 | R25: =S25+T25 -> 0 | U25: =V25+W25 -> 0 | X25: =Y25+Z25 -> 0 | AA25: =AB25+AC25 -> 0 | AD25: =AE25+AF25 -> 0 | AG25: =AH25+AI25 -> 0 | AJ25: =AK25+AL25 -> 0 | AM25: =AN25+AO25 -> 0 | AP25: =F25+L25+R25+X25+AD25+AJ25 -> 0 | AQ25: =AP25/E25 -> #DIV/0!
F26: =G26+H26 -> 0 | I26: =J26+K26 -> 0 | L26: =M26+N26 -> 0 | O26: =P26+Q26 -> 0 | R26: =S26+T26 -> 0 | U26: =V26+W26 -> 0 | X26: =Y26+Z26 -> 0 | AA26: =AB26+AC26 -> 0 | AD26: =AE26+AF26 -> 0 | AG26: =AH26+AI26 -> 0 | AJ26: =AK26+AL26 -> 0 | AM26: =AN26+AO26 -> 0 | AP26: =F26+L26+R26+X26+AD26+AJ26 -> 0 | AQ26: =AP26/E26 -> #DIV/0!
F27: =G27+H27 -> 0 | I27: =J27+K27 -> 0 | L27: =M27+N27 -> 0 | O27: =P27+Q27 -> 0 | R27: =S27+T27 -> 0 | U27: =V27+W27 -> 0 | X27: =Y27+Z27 -> 0 | AA27: =AB27+AC27 -> 0 | AD27: =AE27+AF27 -> 0 | AG27: =AH27+AI27 -> 0 | AJ27: =AK27+AL27 -> 0 | AM27: =AN27+AO27 -> 0 | AP27: =F27+L27+R27+X27+AD27+AJ27 -> 0 | AQ27: =AP27/E27 -> #DIV/0!
... F31: =G31+H31 -> 0 | I31: =J31+K31 -> 0 | L31: =M31+N31 -> 0 | O31: =P31+Q31 -> 0 | R31: =S31+T31 -> 0 | U31: =V31+W31 -> 0 | X31: =Y31+Z31 -> 0 | AA31: =AB31+AC31 -> 0 | AD31: =AE31+AF31 -> 0 | AG31: =AH31+AI31 -> 0 | AJ31: =AK31+AL31 -> 0 | AM31: =AN31+AO31 -> 0 | AP31: =F31+L31+R31+X31+AD31+AJ31 -> 0 | AQ31: =AP31/E31 -> #DIV/0!
B32: 合 計 | C32: =SUM(C12:C31) -> 1208 | D32: =SUM(D12:D31) -> 300 | E32: =SUM(E12:E31) -> 1340 | F32: =SUM(F12:F31) -> 658 | G32: =SUM(G12:G31) -> 490 | H32: =SUM(H12:H31) -> 168 | I32: =SUM(I12:I31) -> 591 | J32: =SUM(J12:J31) -> 433 | ... AP32: =SUM(AP12:AP31) -> 658 | AQ32: =AP32/E32 -> 0.49104478

Sheet 様式３ 教育の質・履修者数を向上させるための体制・計画
I1: 様式３
G2: 大学等名 | H2: ='様式１-1 プログラムを構成する授業科目（経営・社会・薬）'!C2 -> 青森大学
A4: 教育の質・履修者数を向上させるための体制・計画について
A6: ① | B6: 全学の教員数 | C6: (常勤） | E6: 89 | F6: 人 | G6: （非常勤） | H6: 54 | I6: 人
A8: ② | B8: プログラムの授業を教えている教員数 | H8: 4 | I8: 人
A10: ③ | B10: プログラムの運営責任者
B11: （責任者名） | C11: 坂井 雄介 | G11: （役職名） | H11: 学監・教務委員長
A13: ④ | B13: プログラムを改善・進化させるための体制（委員会・組織等）
B14: 教務委員会
B16: （責任者名） | C16: 坂井 雄介 | G16: （役職名） | H16: 学監・教務委員長
A18: ⑤ | B18: プログラムを改善・進化させるための体制を定める規則名称
B19: 教務委員会規程
A21: ⑥ | B21: 体制の目的
B22: 青森大学のディプロマ・ポリシーにある「生涯をかけて学び続ける力」「人とつながる力」「自分自身を見据え、確かめる力」を醸成するために、文系理系を問わず、データ等を活用する学修活動をコンテンツとして、社会の課題を発見したり、解決できる人材を育成することを目的として、数理・データサイエンス・AI教育の全学的な普及、関連科目の整備を行い、学内共同委員会として教務委員会内で議論・調整を行うことを目的とする。
A28: ⑦ | B28: 具体的な構成員
B29: 教務委員長：坂井雄介 教務副委員長（教務課長）：赤石まなみ 教務委員（総合経営学部准教授）：石塚ゆかり 教務委員（総合経営学部准教授）：井岡佳代子 教務委員（社会学部教授）：佐藤淳 教務委員（社会学部教授）：田中志子 教務委員（社会学部講師）：木原博 教務委員（ソフトウェア情報学部教授）：穴田啓晃 教務委員（ソフトウェア情報学部准教授）：鹿内史 教務委員（ソフトウェア情報学部講師）：小野淳平 教務委員（薬学部教授）：植木章晴 教務委員（薬学部准教授）：上家勝芳 教務委員（東京キャンパス事務局次長）：小村剛史 教務委員（教務課課長補佐）：太田和也 教務委員（教務課主任）：工藤睦美 教務委員（むつキャンパス課員）：奈良雪月
A43: ⑧ | B43: 履修者数・履修率の向上に向けた計画 ※様式１の「履修必須の有無」で「計画がある」としている場合は詳細について記載すること
B44: 令和４年度実績 | C44: ='様式２ 履修者等数の実績'!AQ32 -> 0.49104478 | E44: 令和５年度予定 | F44: 0.55 | H44: 令和６年度予定 | I44: 0.6
B45: 令和７年度予定 | C45: 0.65 | E45: 令和８年度予定 | F45: 0.7 | H45: 収容定員（名） | I45: ='様式２ 履修者等数の実績'!E32 -> 1340
B46: 具体的な計画
B47: 目標を実現するために、令和３年度より教務委員会にて基礎スタンダード科目（全学における教養科目）内で本プログラムの対象となる科目の選定、授業内容の工夫等について議論を展開。令和４年度よりデータサイエンス・AIリテラシープログラムと位置づけした科目の運用を開始し、授業時間外での学修指導やその他学生指導や支援等の学修サポートなどについて、教務委員会にて議論し、関連する諸委員会などと連携し、学生のプログラム履修をサポートしている。毎年教務委員会にてこれらの内容等について確認・見直しを行い、学生に寄り添ったプログラムを展開していく計画である。
A55: ⑨ | B55: 学部・学科に関係なく希望する学生全員が受講可能となるような必要な体制・取組等
B56: 教務委員会での議論等により、現在ソフトウェア情報学部での対象科目となっている「情報リテラシー」については、対象学部以外の３学部（総合経営学部、社会学部、薬学部）についても他学部履修として選択できる制度を整備し、履修相談については、各学部の教務委員や教務課職員などを通じて、他学部の教職員へ相談状況等を共有し、履修の支援、相談体制の拡充を図り、全学的な履修を支援・促進している。
A63: ⑩ | B63: できる限り多くの学生が履修できるような具体的な周知方法・取組
B64: 入学後の各学部の教務ガイダンス、web学生掲示板での周知などを行うことで、学生が情報を即座に確認しやすい環境等を整備している。
A68: ⑪ | B68: できる限り多くの学生が履修・修得できるようなサポート体制
B69: 前期・後期の開始時に各学部の履修相談機関を設けたり、各学部のオフィスアワーについてメール案内やweb学生掲示板などで告知することにより、本教育プログラムの授業について、多くの学生がいつでも気軽に相談できるサポート体制を構築し支援している。
A74: ⑫ | B74: 授業時間内外で学習指導、質問を受け付ける具体的な仕組み
B75: 各学部のオフィスアワーの時間を活用し、学生は授業時間以外に不明点等を相談できる仕組みとなっている。また、教務課など事務局でも各種相談を対面およびオンライン等で随時受付しており、質問内容については担当教員へ連絡し、担当教職員を通じて返答する仕組み等を整備している。

Sheet 様式４　自己点検・評価
I1: 様式４
H2: 大学等名 | I2: ='様式１-1 プログラムを構成する授業科目（経営・社会・薬）'!C2 -> 青森大学
A3: 自己点検・評価について
A5: ① | B5: プログラムの自己点検・評価を行う体制（委員会・組織等）
B6: 自己点検評価・認証評価審査対策委員会
D8: （責任者名） | E8: 澁谷 泰秀 | G8: （役職名） | H8: 学長
A10: ② | B10: 自己点検・評価体制における意見等
B11: 自己点検・評価の視点 | E11: 自己点検・評価体制における意見・結果・改善に向けた取組等
B12: 学内からの視点
C13: プログラムの履修・修得状況 | E13: 自己点検評価・認証評価審査対策委員会のPDCA管理部会（ワーキンググループ）において、教務委員会など関連委員会よりプログラムの履修・取得状況データを吸い上げ、その内容等について確認や分析を行い、これらの内容等を活用しながら議論を行うことで、履修者の学修状況や修得状況などを把握し、関連委員会へ確認・分析内容をフィードバックし、関連プログラムの内容や支援体制について不断の見直しを行うような取組体制を取っている。
C14: 学修成果 | E14: 教務委員会の関連組織である学修支援センターを中心として実施している「学修状況・満足度調査」の「学修到達度調査」についての項目を分析することによって、授業内容の学生の理解度を把握することができ、その結果を教務委員会および自己点検評価・認証評価審査対策委員会などと連携し、本教育プログラムの評価・改善に活用している。
C15: 学生アンケート等を通じた学生の内容の理解度 | E15: 本教育プログラム受講者全員に対して授業アンケートを実施しており、教務委員会において学生の理解度について確認などを行っている。
C16: 学生アンケート等を通じた後輩等他の学生への推奨度 | E16: 履修者に対する授業アンケートにおいて、後輩学生や他の学生への推奨についての内容等について情報共有を行っている。また、履修者の授業アンケート内の自由意見など受講の感想等の意見について対象科目の教員が確認し、授業改善方策を策定し、全学部でフィードバックを行い、その内容などを図書館で学生が閲覧できる仕組みなども活用することで、後輩学生や他の学生への講義受講を推奨している。
C17: 全学的な履修者数、履修率向上に向けた計画の達成・進捗状況 | E17: 本教育プログラムを構成する科目「情報社会と情報倫理」については、選択科目となっているため、教務委員会にて履修の状況等について定期的に確認し、全学的な履修者数・履修率の向上に向け、各教職員の専門的な視点なども取り入れながら見直しなどを検討し、学生の履修を推進している。
B18: 学外からの視点
C19: 教育プログラム修了者の進路、活躍状況、企業等の評価 | E19: 卒業生アンケートを卒業時に実施し、本教育プログラムを修了した卒業生の進路先や活躍状況の把握が可能である。また学生の内定先企業や自治体等に対して企業調査を定期的に実施し、本プログラムを修了した卒業生における採用状況や企業評価を把握する仕組みなどを設けている。
C20: 産業界からの視点を含めた教育プログラム内容・手法等への意見 | E20: 本学での毎年の取り組み等についてまとめた冊子（青森大学の窓・青森大学ニュース）を外部の利害関係者へ配布や公表をする際に、アンケートを実施し、教育プログラムの講義内容等についても意見を収集するとともに、その内容について自己点検評価・認証評価審査対策委員会で確認し、教務委員会などへフィードバックを行いながらプログラムの改善に活用している。
B21: 数理・データサイエンス・ＡＩを「学ぶ楽しさ」「学ぶことの意義」を理解させること | E21: モデルカリキュラムリテラシーレベルに準じた内容を展開し、地域課題やトレンドなど地域社会での実例などを踏まえ、AIやデータ等がどのように活用をされているかを中心に、学生の興味・関心が沸く講義内容となるよう工夫している。取り上げる実例については、授業（学生）アンケートの内容等を活用しながら実施している。
B22: 内容・水準を維持・向上しつつ、より「分かりやすい」授業とすること | E22: 自己点検評価・認証評価審査対策委員会のPDCA管理部会（ワーキンググループ）において、教務委員会や関連委員会などから吸い上げた授業アンケートの内容や企業アンケートの内容、外部の利害関係者などからいただいたご意見などを参考に、学生目線に立った「分かりやすさ」の観点から、本学学生に寄り添った講義の内容・実施方法の見直しについて検討し、関連委員会にフィードバックしながらわかりやすい授業内容を構築している。
