Workbook

Sheet 様式１ー１　プログラムを構成する授業科目
R1: 様式１－１ | T1: 「学部・学科によって、修了要件は相違する」場合は、本シートを複製の上＜様式１－〇＞と枝番号を付してください
B2: 大学等名 | C2: 順天堂大学
B3: プログラム名 | C3: 数理・データサイエンス・AI教育プログラム
A5: プログラムを構成する授業科目について
A7: ① 対象となる学部・学科名称 | J7: ② 教育プログラムの修了要件 | K7: 学部・学科によって、修了要件は相違する
B9: 医学部
A12: ③ 修了要件
B13: 医学部においては、基本的には次の2つのコア科目を修了したことで、教育プログラムの修了要件としている。 また、項目2-1、2-2、2-3に関してはコア科目以外の必要な科目の組合せの修了でもプログラムの修了を認めることとする。 コア科目：データサイエンス基礎、情報処理Ⅰ | V13: 【プルダウンリスト】
V14: 令和４年度以前より、履修することが必須のプログラムとして実施
V15: 令和７年度までに履修必須とする計画
V16: 令和８年度以降に履修必須とする計画、又は未定
B20: 必要最低単位数 | C20: 2 | E20: 単位 | J20: 履修必須の有無 | K20: 令和４年度以前より、履修することが必須のプログラムとして実施
A22: ④ 現在進行中の社会変化（第４次産業革命、Society 5.0、データ駆動型社会等）に深く寄与しているものであり、それが自らの生活と密接に結びついている」の内容を含む授業科目
B24: 授業科目 | F24: 単位数 | G24: 必須 | H24: 1-1 | I24: 1-6 | J24: 授業科目 | P24: 単位数 | Q24: 必須 | R24: 1-1 | S24: 1-6
B25: データサイエンス基礎 | F25: 1 | G25: ○ | H25: ○ | I25: ○
B26: 医療の経営学 | F26: 1 | H26: ○
A33: ⑤ 「社会で活用されているデータ」や「データの活用領域」は非常に広範囲であって、日常生活や社会の課題を解決する有用なツールになり得るもの」の内容を含む授業科目
B35: 授業科目 | F35: 単位数 | G35: 必須 | H35: 1-2 | I35: 1-3 | J35: 授業科目 | P35: 単位数 | Q35: 必須 | R35: 1-2 | S35: 1-3
B36: データサイエンス基礎 | F36: 1 | G36: ○ | H36: ○ | I36: ○
A44: ⑥ 「様々なデータ利活用の現場におけるデータ利活用事例が示され、様々な適用領域（流通、製造、金融、サービス、インフラ、公共、ヘルスケア等）の知見と組み合わせることで価値を創出するもの」の内容を含む授業科目
B46: 授業科目 | F46: 単位数 | G46: 必須 | H46: 1-4 | I46: 1-5 | J46: 授業科目 | P46: 単位数 | Q46: 必須 | R46: 1-4 | S46: 1-5
B47: データサイエンス基礎 | F47: 1 | G47: ○ | H47: ○ | I47: ○
B48: 医療社会学 | F48: 1 | I48: ○
A55: ⑦ 「活用に当たっての様々な留意事項（ELSI、個人情報、データ倫理、ＡＩ社会原則等）を考慮し、情報セキュリティや情報漏洩等、データを守る上での留意事項への理解をする」の内容を含む授業科目
B57: 授業科目 | F57: 単位数 | G57: 必須 | H57: 3-1 | I57: 3-2 | J57: 授業科目 | P57: 単位数 | Q57: 必須 | R57: 3-1 | S57: 3-2
B58: データサイエンス基礎 | F58: 1 | G58: ○ | H58: ○ | I58: ○
A66: ⑧ 「実データ・実課題（学術データ等を含む）を用いた演習など、社会での実例を題材として、「データを読む、説明する、扱う」といった数理・データサイエンス・ＡＩの基本的な活用法に関するもの」の内容を含む授業科目
B68: 授業科目 | E68: 単位数 | F68: 必須 | G68: 2-1 | H68: 2-2 | I68: 2-3 | J68: 授業科目 | O68: 単位数 | P68: 必須 | Q68: 2-1 | R68: 2-2 | S68: 2-3
B69: 情報処理Ⅰ | E69: 1 | F69: ○ | G69: ○ | H69: ○ | I69: ○
B70: 情報処理Ⅱ | E70: 1 | G70: ○
B71: 統計解析への数学 | E71: 1 | G71: ○ | H71: ○
B72: 統計に基づいた科学的実証の実際 | E72: 1 | I72: ○
B73: 医事ニュースを読み解く統計学 | E73: 1 | G73: ○
B74: 科学研究のための基礎 | E74: 1 | G74: ○
B75: 疫学・統計学 | E75: 1 | G75: ○
A77: ⑨ 選択「４．オプション」の内容を含む授業科目
B78: 授業科目 | F78: 選択項目 | J78: 授業科目 | P78: 選択項目
B79: 情報処理Ⅱ | F79: 4‐3データ構造とプログラミング基礎
B80: 統計解析への数学 | F80: 4-1統計および数理基礎
A87: ⑩ プログラムを構成する授業の内容
...

Sheet 様式１ー２　プログラムを構成する授業科目
R1: 様式１－２ | T1: 「学部・学科によって、修了要件は相違する」場合は、本シートを複製の上＜様式１－〇＞と枝番号を付してください
B2: 大学等名 | C2: ='様式１ー１ プログラムを構成する授業科目'!C2 -> 順天堂大学
B3: プログラム名 | C3: ='様式１ー１ プログラムを構成する授業科目'!C3 -> 数理・データサイエンス・AI教育プログラム
A5: プログラムを構成する授業科目について
A7: ① 対象となる学部・学科名称 | J7: ② 教育プログラムの修了要件 | K7: 学部・学科によって、修了要件は相違する
B9: スポーツ健康科学部
A12: ③ 修了要件
B13: スポーツ健康科学部においては、次の2つのコア科目を修了したことで、教育プログラムの修了要件としている。 コア科目：情報処理演習【新カリ】、データサイエンスのための数学【新カリ】 | V13: 【プルダウンリスト】
V14: 令和４年度以前より、履修することが必須のプログラムとして実施
V15: 令和７年度までに履修必須とする計画
V16: 令和８年度以降に履修必須とする計画、又は未定
B20: 必要最低単位数 | C20: 4 | E20: 単位 | J20: 履修必須の有無 | K20: 令和８年度以降に履修必須とする計画、又は未定
A22: ④ 現在進行中の社会変化（第４次産業革命、Society 5.0、データ駆動型社会等）に深く寄与しているものであり、それが自らの生活と密接に結びついている」の内容を含む授業科目
B24: 授業科目 | F24: 単位数 | G24: 必須 | H24: 1-1 | I24: 1-6 | J24: 授業科目 | P24: 単位数 | Q24: 必須 | R24: 1-1 | S24: 1-6
B25: 情報処理演習【新カリ】 | F25: 2 | G25: ○ | H25: ○ | I25: ○
A33: ⑤ 「社会で活用されているデータ」や「データの活用領域」は非常に広範囲であって、日常生活や社会の課題を解決する有用なツールになり得るもの」の内容を含む授業科目
B35: 授業科目 | F35: 単位数 | G35: 必須 | H35: 1-2 | I35: 1-3 | J35: 授業科目 | P35: 単位数 | Q35: 必須 | R35: 1-2 | S35: 1-3
B36: 情報処理演習【新カリ】 | F36: 2 | G36: ○ | H36: ○
B37: データサイエンスのための数学【新カリ】 | F37: 2 | G37: ○ | I37: ○
A44: ⑥ 「様々なデータ利活用の現場におけるデータ利活用事例が示され、様々な適用領域（流通、製造、金融、サービス、インフラ、公共、ヘルスケア等）の知見と組み合わせることで価値を創出するもの」の内容を含む授業科目
B46: 授業科目 | F46: 単位数 | G46: 必須 | H46: 1-4 | I46: 1-5 | J46: 授業科目 | P46: 単位数 | Q46: 必須 | R46: 1-4 | S46: 1-5
B47: 情報処理演習【新カリ】 | F47: 2 | G47: ○ | I47: ○
B48: データサイエンスのための数学【新カリ】 | F48: 2 | G48: ○ | H48: ○
A55: ⑦ 「活用に当たっての様々な留意事項（ELSI、個人情報、データ倫理、ＡＩ社会原則等）を考慮し、情報セキュリティや情報漏洩等、データを守る上での留意事項への理解をする」の内容を含む授業科目
B57: 授業科目 | F57: 単位数 | G57: 必須 | H57: 3-1 | I57: 3-2 | J57: 授業科目 | P57: 単位数 | Q57: 必須 | R57: 3-1 | S57: 3-2
B58: 情報処理演習【新カリ】 | F58: 2 | G58: ○ | H58: ○ | I58: ○
A66: ⑧ 「実データ・実課題（学術データ等を含む）を用いた演習など、社会での実例を題材として、「データを読む、説明する、扱う」といった数理・データサイエンス・ＡＩの基本的な活用法に関するもの」の内容を含む授業科目
B68: 授業科目 | E68: 単位数 | F68: 必須 | G68: 2-1 | H68: 2-2 | I68: 2-3 | J68: 授業科目 | O68: 単位数 | P68: 必須 | Q68: 2-1 | R68: 2-2 | S68: 2-3
B69: 情報処理演習【新カリ】 | E69: 2 | F69: ○ | G69: ○ | H69: ○ | I69: ○
B70: 統計学【新カリ】 | E70: 2 | G70: ○
B71: スポーツ情報科学【新カリ】 | E71: 2 | I71: ○
A77: ⑨ 選択「４．オプション」の内容を含む授業科目
B78: 授業科目 | F78: 選択項目 | J78: 授業科目 | P78: 選択項目
B79: 情報処理演習【新カリ】 | F79: 4‐3データ構造とプログラミング基礎
B80: データサイエンスのための数学【新カリ】 | F80: 4-1統計および数理基礎
B81: 統計学【新カリ】 | F81: 4-1統計および数理基礎
B82: スポーツ情報科学【新カリ】 | F82: その他
A87: ⑩ プログラムを構成する授業の内容
B88: 授業に含まれている内容・要素 | D88: 講義内容
B89: （１）現在進行中の社会変化（第４次産業革命、Society 5.0、データ駆動型社会等）に深く寄与しているものであり、それが自らの生活と密接に結びついている | C89: 1-1 | D89: 社会の変化について、ビッグデータ、IoT、AI、ロボット、データの増加、コンピュータの進歩、Society5.0、データ駆動型社会、人間の知的活動とAI「情報処理演習【新カリ】」（2回目）
...

Sheet 様式１ー３　プログラムを構成する授業科目
R1: 様式１－３ | T1: 「学部・学科によって、修了要件は相違する」場合は、本シートを複製の上＜様式１－〇＞と枝番号を付してください
B2: 大学等名 | C2: ='様式１ー１ プログラムを構成する授業科目'!C2 -> 順天堂大学
B3: プログラム名 | C3: ='様式１ー１ プログラムを構成する授業科目'!C3 -> 数理・データサイエンス・AI教育プログラム
A5: プログラムを構成する授業科目について
A7: ① 対象となる学部・学科名称 | J7: ② 教育プログラムの修了要件 | K7: 学部・学科によって、修了要件は相違する
B9: 医療看護学部
A12: ③ 修了要件
B13: 医療看護学部においては、基本的には次の2つのコア科目を修了したことで、教育プログラムの修了要件としている。 また、項目2-1、2-2、2-3に関してはコア科目以外の必要な科目の組合せの修了でもプログラムの修了を認めることとする。 コア科目：情報科学、統計学 項目1-3、1-4に関しては、2022年度は「情報科学」においてオンデマンドビデオにより対応した。 | V13: 【プルダウンリスト】
V14: 令和４年度以前より、履修することが必須のプログラムとして実施
V15: 令和７年度までに履修必須とする計画
V16: 令和８年度以降に履修必須とする計画、又は未定
B20: 必要最低単位数 | C20: 2 | E20: 単位 | J20: 履修必須の有無 | K20: 令和７年度までに履修必須とする計画
A22: ④ 現在進行中の社会変化（第４次産業革命、Society 5.0、データ駆動型社会等）に深く寄与しているものであり、それが自らの生活と密接に結びついている」の内容を含む授業科目
B24: 授業科目 | F24: 単位数 | G24: 必須 | H24: 1-1 | I24: 1-6 | J24: 授業科目 | P24: 単位数 | Q24: 必須 | R24: 1-1 | S24: 1-6
B25: 情報科学 | F25: 1 | G25: ○ | H25: ○ | I25: ○
A33: ⑤ 「社会で活用されているデータ」や「データの活用領域」は非常に広範囲であって、日常生活や社会の課題を解決する有用なツールになり得るもの」の内容を含む授業科目
B35: 授業科目 | F35: 単位数 | G35: 必須 | H35: 1-2 | I35: 1-3 | J35: 授業科目 | P35: 単位数 | Q35: 必須 | R35: 1-2 | S35: 1-3
B36: 情報科学 | F36: 1 | G36: ○ | H36: ○ | I36: ○
A44: ⑥ 「様々なデータ利活用の現場におけるデータ利活用事例が示され、様々な適用領域（流通、製造、金融、サービス、インフラ、公共、ヘルスケア等）の知見と組み合わせることで価値を創出するもの」の内容を含む授業科目
B46: 授業科目 | F46: 単位数 | G46: 必須 | H46: 1-4 | I46: 1-5 | J46: 授業科目 | P46: 単位数 | Q46: 必須 | R46: 1-4 | S46: 1-5
B47: 情報科学 | F47: 1 | G47: ○ | H47: ○ | I47: ○
A55: ⑦ 「活用に当たっての様々な留意事項（ELSI、個人情報、データ倫理、ＡＩ社会原則等）を考慮し、情報セキュリティや情報漏洩等、データを守る上での留意事項への理解をする」の内容を含む授業科目
B57: 授業科目 | F57: 単位数 | G57: 必須 | H57: 3-1 | I57: 3-2 | J57: 授業科目 | P57: 単位数 | Q57: 必須 | R57: 3-1 | S57: 3-2
B58: 情報科学 | F58: 1 | G58: ○ | H58: ○ | I58: ○
A66: ⑧ 「実データ・実課題（学術データ等を含む）を用いた演習など、社会での実例を題材として、「データを読む、説明する、扱う」といった数理・データサイエンス・ＡＩの基本的な活用法に関するもの」の内容を含む授業科目
B68: 授業科目 | E68: 単位数 | F68: 必須 | G68: 2-1 | H68: 2-2 | I68: 2-3 | J68: 授業科目 | O68: 単位数 | P68: 必須 | Q68: 2-1 | R68: 2-2 | S68: 2-3
B69: 情報科学 | E69: 1 | F69: ○ | G69: ○ | H69: ○
B70: 統計学 | E70: 1 | F70: ○ | G70: ○ | H70: ○ | I70: ○
B71: 統計演習 | E71: 1 | H71: ○ | I71: ○
B72: 保健統計 | E72: 2 | G72: ○ | H72: ○
A77: ⑨ 選択「４．オプション」の内容を含む授業科目
B78: 授業科目 | F78: 選択項目 | J78: 授業科目 | P78: 選択項目
B79: 統計学 | F79: 4-1統計および数理基礎
B80: 統計演習 | F80: 4-1統計および数理基礎
A87: ⑩ プログラムを構成する授業の内容
B88: 授業に含まれている内容・要素 | D88: 講義内容
B89: （１）現在進行中の社会変化（第４次産業革命、Society 5.0、データ駆動型社会等）に深く寄与しているものであり、それが自らの生活と密接に結びついている | C89: 1-1 | D89: ビッグデータ、IoT、AI、ロボット、データの増加、コンピュータの進歩、Society5.0、データ駆動型社会、人間の知的活動とAI「情報科学」（2回目）
C90: 1-6 | D90: AIを活用した新たなビジネスモデル、AIの最新の活用例「情報科学」（4回目）
B91: （２）「社会で活用されているデータ」や「データの活用領域」は非常に広範囲であって、日常生活や社会の課題を解決する有用なツールになり得るもの | C91: 1-2 | D91: 調査データ、実験データ、人の行動ログデータ、機械の稼働ログデータなど、1次データ、2次データ、データのメタ化、構造化データ、非構造化データ（文章、画像/動画、音声/音楽など）、データ作成（ビッグデータとアノテーション）、データのオープン化（オープンデータ）「情報科学」（3回目）
C92: 1-3 | D92: データ・AIの活用領域の進展、製造、物流、販売、マーケティング、サービス等での活用、仮説検証、知識発見、原因究明、判断支援等「情報科学」(オンデマンドビデオ)
...

Sheet 様式１ー４　プログラムを構成する授業科目
R1: 様式１－４ | T1: 「学部・学科によって、修了要件は相違する」場合は、本シートを複製の上＜様式１－〇＞と枝番号を付してください
B2: 大学等名 | C2: ='様式１ー１ プログラムを構成する授業科目'!C2 -> 順天堂大学
B3: プログラム名 | C3: ='様式１ー１ プログラムを構成する授業科目'!C3 -> 数理・データサイエンス・AI教育プログラム
A5: プログラムを構成する授業科目について
A7: ① 対象となる学部・学科名称 | J7: ② 教育プログラムの修了要件 | K7: 学部・学科によって、修了要件は相違する
B9: 保健看護学部
A12: ③ 修了要件
B13: 保健看護学部においては、次の2つのコア科目を修了したことで、教育プログラムの修了要件としている。 コア科目：情報処理、統計学 | V13: 【プルダウンリスト】
V14: 令和４年度以前より、履修することが必須のプログラムとして実施
V15: 令和７年度までに履修必須とする計画
V16: 令和８年度以降に履修必須とする計画、又は未定
B20: 必要最低単位数 | C20: 1 | E20: 単位 | J20: 履修必須の有無 | K20: 令和８年度以降に履修必須とする計画、又は未定
A22: ④ 現在進行中の社会変化（第４次産業革命、Society 5.0、データ駆動型社会等）に深く寄与しているものであり、それが自らの生活と密接に結びついている」の内容を含む授業科目
B24: 授業科目 | F24: 単位数 | G24: 必須 | H24: 1-1 | I24: 1-6 | J24: 授業科目 | P24: 単位数 | Q24: 必須 | R24: 1-1 | S24: 1-6
B25: 情報処理 | F25: 1 | G25: ○ | H25: ○ | I25: ○
A33: ⑤ 「社会で活用されているデータ」や「データの活用領域」は非常に広範囲であって、日常生活や社会の課題を解決する有用なツールになり得るもの」の内容を含む授業科目
B35: 授業科目 | F35: 単位数 | G35: 必須 | H35: 1-2 | I35: 1-3 | J35: 授業科目 | P35: 単位数 | Q35: 必須 | R35: 1-2 | S35: 1-3
B36: 情報処理 | F36: 1 | G36: ○ | H36: ○ | I36: ○
A44: ⑥ 「様々なデータ利活用の現場におけるデータ利活用事例が示され、様々な適用領域（流通、製造、金融、サービス、インフラ、公共、ヘルスケア等）の知見と組み合わせることで価値を創出するもの」の内容を含む授業科目
B46: 授業科目 | F46: 単位数 | G46: 必須 | H46: 1-4 | I46: 1-5 | J46: 授業科目 | P46: 単位数 | Q46: 必須 | R46: 1-4 | S46: 1-5
B47: 情報処理 | F47: 1 | G47: ○ | H47: ○ | I47: ○
A55: ⑦ 「活用に当たっての様々な留意事項（ELSI、個人情報、データ倫理、ＡＩ社会原則等）を考慮し、情報セキュリティや情報漏洩等、データを守る上での留意事項への理解をする」の内容を含む授業科目
B57: 授業科目 | F57: 単位数 | G57: 必須 | H57: 3-1 | I57: 3-2 | J57: 授業科目 | P57: 単位数 | Q57: 必須 | R57: 3-1 | S57: 3-2
B58: 情報処理 | F58: 1 | G58: ○ | H58: ○ | I58: ○
A66: ⑧ 「実データ・実課題（学術データ等を含む）を用いた演習など、社会での実例を題材として、「データを読む、説明する、扱う」といった数理・データサイエンス・ＡＩの基本的な活用法に関するもの」の内容を含む授業科目
B68: 授業科目 | E68: 単位数 | F68: 必須 | G68: 2-1 | H68: 2-2 | I68: 2-3 | J68: 授業科目 | O68: 単位数 | P68: 必須 | Q68: 2-1 | R68: 2-2 | S68: 2-3
B69: 情報処理 | E69: 1 | F69: ○ | H69: ○
B70: 統計学 | E70: 1 | F70: ○ | G70: ○ | H70: ○ | I70: ○
B71: 疫学・保健統計Ⅰ | E71: 2 | G71: ○ | H71: ○
B72: 疫学・保健統計Ⅱ | E72: 2 | G72: ○ | H72: ○
A77: ⑨ 選択「４．オプション」の内容を含む授業科目
B78: 授業科目 | F78: 選択項目 | J78: 授業科目 | P78: 選択項目
B79: 情報処理 | F79: 4‐6画像解析
B80: 統計学 | F80: 4-1統計および数理基礎
A87: ⑩ プログラムを構成する授業の内容
B88: 授業に含まれている内容・要素 | D88: 講義内容
B89: （１）現在進行中の社会変化（第４次産業革命、Society 5.0、データ駆動型社会等）に深く寄与しているものであり、それが自らの生活と密接に結びついている | C89: 1-1 | D89: ビッグデータ、IoT、AI、ロボット、データの増加、コンピュータの進歩、Society5.0、データ駆動型社会、人間の知的活動とAI「情報処理」（1回目）
C90: 1-6 | D90: AIを活用した新たなビジネスモデル、AIの最新の活用例「情報処理」（6回目）
B91: （２）「社会で活用されているデータ」や「データの活用領域」は非常に広範囲であって、日常生活や社会の課題を解決する有用なツールになり得るもの | C91: 1-2 | D91: 1次データと2次データ、オープンデータ、構造化データと非構造化データ、データの作成と収集「情報処理」（2回目）
C92: 1-3 | D92: データ・AIの活用領域の進展、製造、物流、販売、マーケティング、サービス等での活用、仮説検証、知識発見、原因究明、判断支援等「情報処理」（3回目）
...

Sheet 様式１ー５　プログラムを構成する授業科目
R1: 様式１－５ | T1: 「学部・学科によって、修了要件は相違する」場合は、本シートを複製の上＜様式１－〇＞と枝番号を付してください
B2: 大学等名 | C2: ='様式１ー１ プログラムを構成する授業科目'!C2 -> 順天堂大学
B3: プログラム名 | C3: ='様式１ー１ プログラムを構成する授業科目'!C3 -> 数理・データサイエンス・AI教育プログラム
A5: プログラムを構成する授業科目について
A7: ① 対象となる学部・学科名称 | J7: ② 教育プログラムの修了要件 | K7: 学部・学科によって、修了要件は相違する
B9: 国際教養学部
A12: ③ 修了要件
B13: 国際教養学部においては、次の1つのコア科目を修了したことで、教育プログラムの修了要件としている。 コア科目：ICTリテラシー | V13: 【プルダウンリスト】
V14: 令和４年度以前より、履修することが必須のプログラムとして実施
V15: 令和７年度までに履修必須とする計画
V16: 令和８年度以降に履修必須とする計画、又は未定
B20: 必要最低単位数 | C20: 2 | E20: 単位 | J20: 履修必須の有無 | K20: 令和４年度以前より、履修することが必須のプログラムとして実施
A22: ④ 現在進行中の社会変化（第４次産業革命、Society 5.0、データ駆動型社会等）に深く寄与しているものであり、それが自らの生活と密接に結びついている」の内容を含む授業科目
B24: 授業科目 | F24: 単位数 | G24: 必須 | H24: 1-1 | I24: 1-6 | J24: 授業科目 | P24: 単位数 | Q24: 必須 | R24: 1-1 | S24: 1-6
B25: ICTリテラシー | F25: 2 | G25: ○ | H25: ○ | I25: ○
A33: ⑤ 「社会で活用されているデータ」や「データの活用領域」は非常に広範囲であって、日常生活や社会の課題を解決する有用なツールになり得るもの」の内容を含む授業科目
B35: 授業科目 | F35: 単位数 | G35: 必須 | H35: 1-2 | I35: 1-3 | J35: 授業科目 | P35: 単位数 | Q35: 必須 | R35: 1-2 | S35: 1-3
B36: ICTリテラシー | F36: 2 | G36: ○ | H36: ○ | I36: ○
A44: ⑥ 「様々なデータ利活用の現場におけるデータ利活用事例が示され、様々な適用領域（流通、製造、金融、サービス、インフラ、公共、ヘルスケア等）の知見と組み合わせることで価値を創出するもの」の内容を含む授業科目
B46: 授業科目 | F46: 単位数 | G46: 必須 | H46: 1-4 | I46: 1-5 | J46: 授業科目 | P46: 単位数 | Q46: 必須 | R46: 1-4 | S46: 1-5
B47: ICTリテラシー | F47: 2 | G47: ○ | H47: ○ | I47: ○
A55: ⑦ 「活用に当たっての様々な留意事項（ELSI、個人情報、データ倫理、ＡＩ社会原則等）を考慮し、情報セキュリティや情報漏洩等、データを守る上での留意事項への理解をする」の内容を含む授業科目
B57: 授業科目 | F57: 単位数 | G57: 必須 | H57: 3-1 | I57: 3-2 | J57: 授業科目 | P57: 単位数 | Q57: 必須 | R57: 3-1 | S57: 3-2
B58: ICTリテラシー | F58: 2 | G58: ○ | H58: ○ | I58: ○
A66: ⑧ 「実データ・実課題（学術データ等を含む）を用いた演習など、社会での実例を題材として、「データを読む、説明する、扱う」といった数理・データサイエンス・ＡＩの基本的な活用法に関するもの」の内容を含む授業科目
B68: 授業科目 | E68: 単位数 | F68: 必須 | G68: 2-1 | H68: 2-2 | I68: 2-3 | J68: 授業科目 | O68: 単位数 | P68: 必須 | Q68: 2-1 | R68: 2-2 | S68: 2-3
B69: ICTリテラシー | E69: 2 | F69: ○ | G69: ○ | H69: ○ | I69: ○
B70: わかりやすい統計 | E70: 2 | G70: ○ | H70: ○
B71: 疫学・統計 | E71: 2 | G71: ○ | H71: ○
B72: 社会調査法 | E72: 2 | G72: ○
B73: 量的調査演習 | E73: 2 | I73: ○
B74: 質的（フィールド）調査演習 | E74: 2 | G74: ○ | I74: ○
A77: ⑨ 選択「４．オプション」の内容を含む授業科目
B78: 授業科目 | F78: 選択項目 | J78: 授業科目 | P78: 選択項目
A87: ⑩ プログラムを構成する授業の内容
B88: 授業に含まれている内容・要素 | D88: 講義内容
B89: （１）現在進行中の社会変化（第４次産業革命、Society 5.0、データ駆動型社会等）に深く寄与しているものであり、それが自らの生活と密接に結びついている | C89: 1-1 | D89: ビッグデータ、IoT、AI、ロボット、データの増加、コンピュータの進歩、Society5.0、データ駆動型社会、人間の知的活動とAI「ICTリテラシー」（1回目）
C90: 1-6 | D90: AIを活用した新たなビジネスモデル、AIの最新の活用例「ICTリテラシー」（6回目）
B91: （２）「社会で活用されているデータ」や「データの活用領域」は非常に広範囲であって、日常生活や社会の課題を解決する有用なツールになり得るもの | C91: 1-2 | D91: 1次データと2次データ、オープンデータ、構造化データと非構造化データ、データの作成と収集「ICTリテラシー」（2回目）
C92: 1-3 | D92: データ・AIの活用領域の進展、製造、物流、販売、マーケティング、サービス等での活用、仮説検証、知識発見、原因究明、判断支援等「ICTリテラシー」（3回目）
...

Sheet 様式１ー6　プログラムを構成する授業科目
R1: 様式１－６ | T1: 「学部・学科によって、修了要件は相違する」場合は、本シートを複製の上＜様式１－〇＞と枝番号を付してください
B2: 大学等名 | C2: ='様式１ー１ プログラムを構成する授業科目'!C2 -> 順天堂大学
B3: プログラム名 | C3: ='様式１ー１ プログラムを構成する授業科目'!C3 -> 数理・データサイエンス・AI教育プログラム
A5: プログラムを構成する授業科目について
A7: ① 対象となる学部・学科名称 | J7: ② 教育プログラムの修了要件 | K7: 学部・学科によって、修了要件は相違する
B9: 保健医療学部
A12: ③ 修了要件
B13: 保健医療学部理学療法学科及び診療放射線学科においては、次の2つのコア科目を修了したことで、教育プログラムの修了要件としている。 コア科目：情報科学、統計学 項目1-1、1-6、1-3、1-4、3-1に関しては、2022年度は「情報科学」においてオンデマンドビデオにより対応した。 | V13: 【プルダウンリスト】
V14: 令和４年度以前より、履修することが必須のプログラムとして実施
V15: 令和７年度までに履修必須とする計画
V16: 令和８年度以降に履修必須とする計画、又は未定
B20: 必要最低単位数 | C20: 3 | E20: 単位 | J20: 履修必須の有無 | K20: 令和８年度以降に履修必須とする計画、又は未定
A22: ④ 現在進行中の社会変化（第４次産業革命、Society 5.0、データ駆動型社会等）に深く寄与しているものであり、それが自らの生活と密接に結びついている」の内容を含む授業科目
B24: 授業科目 | F24: 単位数 | G24: 必須 | H24: 1-1 | I24: 1-6 | J24: 授業科目 | P24: 単位数 | Q24: 必須 | R24: 1-1 | S24: 1-6
B25: 情報科学 | F25: 1 | G25: ○ | H25: ○ | I25: ○
A33: ⑤ 「社会で活用されているデータ」や「データの活用領域」は非常に広範囲であって、日常生活や社会の課題を解決する有用なツールになり得るもの」の内容を含む授業科目
B35: 授業科目 | F35: 単位数 | G35: 必須 | H35: 1-2 | I35: 1-3 | J35: 授業科目 | P35: 単位数 | Q35: 必須 | R35: 1-2 | S35: 1-3
B36: 情報科学 | F36: 1 | G36: ○ | H36: ○ | I36: ○
A44: ⑥ 「様々なデータ利活用の現場におけるデータ利活用事例が示され、様々な適用領域（流通、製造、金融、サービス、インフラ、公共、ヘルスケア等）の知見と組み合わせることで価値を創出するもの」の内容を含む授業科目
B46: 授業科目 | F46: 単位数 | G46: 必須 | H46: 1-4 | I46: 1-5 | J46: 授業科目 | P46: 単位数 | Q46: 必須 | R46: 1-4 | S46: 1-5
B47: 情報科学 | F47: 1 | G47: ○ | H47: ○ | I47: ○
A55: ⑦ 「活用に当たっての様々な留意事項（ELSI、個人情報、データ倫理、ＡＩ社会原則等）を考慮し、情報セキュリティや情報漏洩等、データを守る上での留意事項への理解をする」の内容を含む授業科目
B57: 授業科目 | F57: 単位数 | G57: 必須 | H57: 3-1 | I57: 3-2 | J57: 授業科目 | P57: 単位数 | Q57: 必須 | R57: 3-1 | S57: 3-2
B58: 情報科学 | F58: 1 | G58: ○ | H58: ○ | I58: ○
A66: ⑧ 「実データ・実課題（学術データ等を含む）を用いた演習など、社会での実例を題材として、「データを読む、説明する、扱う」といった数理・データサイエンス・ＡＩの基本的な活用法に関するもの」の内容を含む授業科目
B68: 授業科目 | E68: 単位数 | F68: 必須 | G68: 2-1 | H68: 2-2 | I68: 2-3 | J68: 授業科目 | O68: 単位数 | P68: 必須 | Q68: 2-1 | R68: 2-2 | S68: 2-3
B69: 統計学 | E69: 2 | F69: ○ | G69: ○ | H69: ○ | I69: ○
A77: ⑨ 選択「４．オプション」の内容を含む授業科目
B78: 授業科目 | F78: 選択項目 | J78: 授業科目 | P78: 選択項目
B79: 統計学 | F79: 4‐3データ構造とプログラミング基礎
B80: 統計学 | F80: 4‐8データ活用実践（教師あり学習）
B81: 統計学 | F81: 4‐9データ活用実践（教師なし学習）
B82: 情報科学 | F82: 4‐2アルゴリズム基礎
B83: 医用画像情報学 | F83: 4‐6画像解析
B84: 医用画像工学 | F84: 4‐6画像解析
A87: ⑩ プログラムを構成する授業の内容
B88: 授業に含まれている内容・要素 | D88: 講義内容
B89: （１）現在進行中の社会変化（第４次産業革命、Society 5.0、データ駆動型社会等）に深く寄与しているものであり、それが自らの生活と密接に結びついている | C89: 1-1 | D89: ビッグデータ、IoT、AI、ロボット、データの増加、コンピュータの進歩、Society5.0、データ駆動型社会、人間の知的活動とAI「情報科学」（オンデマンドビデオ）
C90: 1-6 | D90: AIを活用した新たなビジネスモデル、AIの最新の活用例「情報科学」（オンデマンドビデオ）
B91: （２）「社会で活用されているデータ」や「データの活用領域」は非常に広範囲であって、日常生活や社会の課題を解決する有用なツールになり得るもの | C91: 1-2 | D91: 一次データと二次データ、構造化データと非構造化データ等、データの後利用に必要な技術、現代社会のデータ活用事例「情報科学」（7回目）
...

Sheet 様式１ー7　プログラムを構成する授業科目
R1: 様式１－７ | T1: 「学部・学科によって、修了要件は相違する」場合は、本シートを複製の上＜様式１－〇＞と枝番号を付してください
B2: 大学等名 | C2: ='様式１ー１ プログラムを構成する授業科目'!C2 -> 順天堂大学
B3: プログラム名 | C3: ='様式１ー１ プログラムを構成する授業科目'!C3 -> 数理・データサイエンス・AI教育プログラム
A5: プログラムを構成する授業科目について
A7: ① 対象となる学部・学科名称 | J7: ② 教育プログラムの修了要件 | K7: 学部・学科によって、修了要件は相違する
B9: 医療科学部
A12: ③ 修了要件
B13: 医療科学部は2022年度より開設された学部であり、4年次までの科目でプログラムの内容を満たしていく予定である。 臨床検査学科では、情報科学基礎演習、情報科学概論、臨床統計学演習の3科目を修了したことで、教育プログラムの修了要件としている。2022年度は、項目1-1～1-6、2-2に関しては「情報科学基礎演習」、3-1に関しては「情報科学概論」、2-1に関しては「臨床統計学演習」において、オンデマンドビデオにより対応した。 臨床工学科では、情報科学基礎演習、医用情報処理工学、臨床統計学の3科目を修了したことで、教育プログラムの修了要件としている。2022年度は、項目1-1～1-6、2-2に関しては「情報科学基礎演習」において、オンデマンドビデオにより対応した。 | V13: 【プルダウンリスト】
V14: 令和４年度以前より、履修することが必須のプログラムとして実施
V15: 令和７年度までに履修必須とする計画
V16: 令和８年度以降に履修必須とする計画、又は未定
B20: 必要最低単位数 | C20: 臨床検査学科:3 臨床工学科:4 | E20: 単位 | J20: 履修必須の有無 | K20: 令和４年度以前より、履修することが必須のプログラムとして実施
A22: ④ 現在進行中の社会変化（第４次産業革命、Society 5.0、データ駆動型社会等）に深く寄与しているものであり、それが自らの生活と密接に結びついている」の内容を含む授業科目
B24: 授業科目 | F24: 単位数 | G24: 必須 | H24: 1-1 | I24: 1-6 | J24: 授業科目 | P24: 単位数 | Q24: 必須 | R24: 1-1 | S24: 1-6
B25: 情報科学基礎演習 | F25: 1 | G25: ○ | H25: ○ | I25: ○
A33: ⑤ 「社会で活用されているデータ」や「データの活用領域」は非常に広範囲であって、日常生活や社会の課題を解決する有用なツールになり得るもの」の内容を含む授業科目
B35: 授業科目 | F35: 単位数 | G35: 必須 | H35: 1-2 | I35: 1-3 | J35: 授業科目 | P35: 単位数 | Q35: 必須 | R35: 1-2 | S35: 1-3
B36: 情報科学基礎演習 | F36: 1 | G36: ○ | H36: ○ | I36: ○
A44: ⑥ 「様々なデータ利活用の現場におけるデータ利活用事例が示され、様々な適用領域（流通、製造、金融、サービス、インフラ、公共、ヘルスケア等）の知見と組み合わせることで価値を創出するもの」の内容を含む授業科目
B46: 授業科目 | F46: 単位数 | G46: 必須 | H46: 1-4 | I46: 1-5 | J46: 授業科目 | P46: 単位数 | Q46: 必須 | R46: 1-4 | S46: 1-5
B47: 情報科学基礎演習 | F47: 1 | G47: ○ | H47: ○ | I47: ○
A55: ⑦ 「活用に当たっての様々な留意事項（ELSI、個人情報、データ倫理、ＡＩ社会原則等）を考慮し、情報セキュリティや情報漏洩等、データを守る上での留意事項への理解をする」の内容を含む授業科目
B57: 授業科目 | F57: 単位数 | G57: 必須 | H57: 3-1 | I57: 3-2 | J57: 授業科目 | P57: 単位数 | Q57: 必須 | R57: 3-1 | S57: 3-2
B58: 情報科学概論 | F58: 1 | H58: ○ | I58: ○
B59: 医用情報処理工学 | F59: 2 | H59: ○ | I59: ○
A66: ⑧ 「実データ・実課題（学術データ等を含む）を用いた演習など、社会での実例を題材として、「データを読む、説明する、扱う」といった数理・データサイエンス・ＡＩの基本的な活用法に関するもの」の内容を含む授業科目
B68: 授業科目 | E68: 単位数 | F68: 必須 | G68: 2-1 | H68: 2-2 | I68: 2-3 | J68: 授業科目 | O68: 単位数 | P68: 必須 | Q68: 2-1 | R68: 2-2 | S68: 2-3
B69: 情報科学基礎演習 | E69: 1 | F69: ○ | H69: ○ | I69: ○
B70: 臨床統計学演習 | E70: 1 | G70: ○
B71: 医用情報処理工学演習 | E71: 1 | H71: ○
B72: 臨床統計学 | E72: 2 | G72: ○ | I72: ○
A77: ⑨ 選択「４．オプション」の内容を含む授業科目
B78: 授業科目 | F78: 選択項目 | J78: 授業科目 | P78: 選択項目
B79: 臨床統計学演習 | F79: 4-1統計および数理基礎
B80: 医用情報処理工学演習 | F80: 4‐3データ構造とプログラミング基礎
B81: 医用情報処理工学演習 | F81: 4‐4時系列データ解析
A87: ⑩ プログラムを構成する授業の内容
B88: 授業に含まれている内容・要素 | D88: 講義内容
B89: （１）現在進行中の社会変化（第４次産業革命、Society 5.0、データ駆動型社会等）に深く寄与しているものであり、それが自らの生活と密接に結びついている | C89: 1-1 | D89: ビッグデータ、IoT、AI、ロボット、データの増加、コンピュータの進歩、Society5.0、データ駆動型社会、人間の知的活動とAI「情報科学基礎演習」（オンデマンドビデオ）
C90: 1-6 | D90: AIを活用した新たなビジネスモデル、AIの最新の活用例「情報科学基礎演習」（オンデマンドビデオ）
...

Sheet 様式２ 履修者等数の実績
AQ1: 様式２
AL2: 大学等名 | AM2: ='様式１ー１ プログラムを構成する授業科目'!C2 -> 順天堂大学
A3: プログラムの履修者数等の実績について
A5: ①プログラム開設年度 | C5: 令和４ | E5: 年度
A7: ②履修者・修了者の実績
B9: 学部・学科名称 | C9: 学生数 | D9: 入学 定員 | E9: 収容 定員 | F9: 令和4年度 | L9: 令和3年度 | R9: 令和2年度 | X9: 令和元年度 | AD9: 平成30年度 | AJ9: 平成29年度 | AP9: 履修者数 合計 | AQ9: 履修率
F10: 履修者数 | I10: 修了者数 | L10: 履修者数 | O10: 修了者数 | R10: 履修者数 | U10: 修了者数 | X10: 履修者数 | AA10: 修了者数 | AD10: 履修者数 | AG10: 修了者数 | AJ10: 履修者数 | AM10: 修了者数
F11: 合計 | G11: 男性 | H11: 女性 | I11: 合計 | J11: 男性 | K11: 女性 | L11: 合計 | M11: 男性 | N11: 女性 | O11: 合計 | P11: 男性 | Q11: 女性 | R11: 合計 | S11: 男性 | T11: 女性 | U11: 合計 | V11: 男性 | W11: 女性 | X11: 合計 | Y11: 男性 | Z11: 女性 | AA11: 合計 | AB11: 男性 | AC11: 女性 | AD11: 合計 | AE11: 男性 | AF11: 女性 | AG11: 合計 | AH11: 男性 | AI11: 女性 | AJ11: 合計 | AK11: 男性 | AL11: 女性 | AM11: 合計 | AN11: 男性 | AO11: 女性
B12: 医学部 | C12: 828 | D12: 138 | E12: 826 | F12: =G12+H12 -> 138 | G12: 68 | H12: 70 | I12: =J12+K12 -> 138 | J12: 68 | K12: 70 | L12: =M12+N12 -> 0 | O12: =P12+Q12 -> 0 | R12: =S12+T12 -> 0 | U12: =V12+W12 -> 0 | X12: =Y12+Z12 -> 0 | AA12: =AB12+AC12 -> 0 | AD12: =AE12+AF12 -> 0 | AG12: =AH12+AI12 -> 0 | AJ12: =AK12+AL12 -> 0 | AM12: =AN12+AO12 -> 0 | AP12: =F12+L12+R12+X12+AD12+AJ12 -> 138 | AQ12: =AP12/E12 -> 0.16707022
B13: スポーツ健康科学部 | C13: 2045 | D13: 600 | E13: 2020 | F13: =G13+H13 -> 617 | G13: 394 | H13: 223 | I13: =J13+K13 -> 226 | J13: 122 | K13: 104 | L13: =M13+N13 -> 0 | O13: =P13+Q13 -> 0 | R13: =S13+T13 -> 0 | U13: =V13+W13 -> 0 | X13: =Y13+Z13 -> 0 | AA13: =AB13+AC13 -> 0 | AD13: =AE13+AF13 -> 0 | AG13: =AH13+AI13 -> 0 | AJ13: =AK13+AL13 -> 0 | AM13: =AN13+AO13 -> 0 | AP13: =F13+L13+R13+X13+AD13+AJ13 -> 617 | AQ13: =AP13/E13 -> 0.30544554
B14: 医療看護学部 | C14: 814 | D14: 220 | E14: 820 | F14: =G14+H14 -> 174 | G14: 11 | H14: 163 | I14: =J14+K14 -> 0 | J14: 0 | K14: 0 | L14: =M14+N14 -> 0 | O14: =P14+Q14 -> 0 | R14: =S14+T14 -> 0 | U14: =V14+W14 -> 0 | X14: =Y14+Z14 -> 0 | AA14: =AB14+AC14 -> 0 | AD14: =AE14+AF14 -> 0 | AG14: =AH14+AI14 -> 0 | AJ14: =AK14+AL14 -> 0 | AM14: =AN14+AO14 -> 0 | AP14: =F14+L14+R14+X14+AD14+AJ14 -> 174 | AQ14: =AP14/E14 -> 0.21219512
B15: 保健看護学部 | C15: 506 | D15: 130 | E15: 490 | F15: =G15+H15 -> 134 | G15: 13 | H15: 121 | I15: =J15+K15 -> 133 | J15: 13 | K15: 120 | L15: =M15+N15 -> 0 | O15: =P15+Q15 -> 0 | R15: =S15+T15 -> 0 | U15: =V15+W15 -> 0 | X15: =Y15+Z15 -> 0 | AA15: =AB15+AC15 -> 0 | AD15: =AE15+AF15 -> 0 | AG15: =AH15+AI15 -> 0 | AJ15: =AK15+AL15 -> 0 | AM15: =AN15+AO15 -> 0 | AP15: =F15+L15+R15+X15+AD15+AJ15 -> 134 | AQ15: =AP15/E15 -> 0.27346939
B16: 国際教養学部 | C16: 945 | D16: 240 | E16: 960 | F16: =G16+H16 -> 227 | G16: 104 | H16: 123 | I16: =J16+K16 -> 181 | J16: 81 | K16: 100 | L16: =M16+N16 -> 0 | O16: =P16+Q16 -> 0 | R16: =S16+T16 -> 0 | U16: =V16+W16 -> 0 | X16: =Y16+Z16 -> 0 | AA16: =AB16+AC16 -> 0 | AD16: =AE16+AF16 -> 0 | AG16: =AH16+AI16 -> 0 | AJ16: =AK16+AL16 -> 0 | AM16: =AN16+AO16 -> 0 | AP16: =F16+L16+R16+X16+AD16+AJ16 -> 227 | AQ16: =AP16/E16 -> 0.23645833
B17: 保健医療学部 | C17: 961 | D17: 240 | E17: 960 | F17: =G17+H17 -> 123 | G17: 54 | H17: 69 | I17: =J17+K17 -> 23 | J17: 11 | K17: 12 | L17: =M17+N17 -> 0 | O17: =P17+Q17 -> 0 | R17: =S17+T17 -> 0 | U17: =V17+W17 -> 0 | X17: =Y17+Z17 -> 0 | AA17: =AB17+AC17 -> 0 | AD17: =AE17+AF17 -> 0 | AG17: =AH17+AI17 -> 0 | AJ17: =AK17+AL17 -> 0 | AM17: =AN17+AO17 -> 0 | AP17: =F17+L17+R17+X17+AD17+AJ17 -> 123 | AQ17: =AP17/E17 -> 0.128125
B18: 医療科学部 | C18: 182 | D18: 180 | E18: 180 | F18: =G18+H18 -> 182 | G18: 47 | H18: 135 | I18: =J18+K18 -> 111 | J18: 19 | K18: 92 | L18: =M18+N18 -> 0 | O18: =P18+Q18 -> 0 | R18: =S18+T18 -> 0 | U18: =V18+W18 -> 0 | X18: =Y18+Z18 -> 0 | AA18: =AB18+AC18 -> 0 | AD18: =AE18+AF18 -> 0 | AG18: =AH18+AI18 -> 0 | AJ18: =AK18+AL18 -> 0 | AM18: =AN18+AO18 -> 0 | AP18: =F18+L18+R18+X18+AD18+AJ18 -> 182 | AQ18: =AP18/E18 -> 1.0111111
F19: =G19+H19 -> 0 | I19: =J19+K19 -> 0 | L19: =M19+N19 -> 0 | O19: =P19+Q19 -> 0 | R19: =S19+T19 -> 0 | U19: =V19+W19 -> 0 | X19: =Y19+Z19 -> 0 | AA19: =AB19+AC19 -> 0 | AD19: =AE19+AF19 -> 0 | AG19: =AH19+AI19 -> 0 | AJ19: =AK19+AL19 -> 0 | AM19: =AN19+AO19 -> 0 | AP19: =F19+L19+R19+X19+AD19+AJ19 -> 0 | AQ19: =AP19/E19 -> #DIV/0!
F20: =G20+H20 -> 0 | I20: =J20+K20 -> 0 | L20: =M20+N20 -> 0 | O20: =P20+Q20 -> 0 | R20: =S20+T20 -> 0 | U20: =V20+W20 -> 0 | X20: =Y20+Z20 -> 0 | AA20: =AB20+AC20 -> 0 | AD20: =AE20+AF20 -> 0 | AG20: =AH20+AI20 -> 0 | AJ20: =AK20+AL20 -> 0 | AM20: =AN20+AO20 -> 0 | AP20: =F20+L20+R20+X20+AD20+AJ20 -> 0 | AQ20: =AP20/E20 -> #DIV/0!
F21: =G21+H21 -> 0 | I21: =J21+K21 -> 0 | L21: =M21+N21 -> 0 | O21: =P21+Q21 -> 0 | R21: =S21+T21 -> 0 | U21: =V21+W21 -> 0 | X21: =Y21+Z21 -> 0 | AA21: =AB21+AC21 -> 0 | AD21: =AE21+AF21 -> 0 | AG21: =AH21+AI21 -> 0 | AJ21: =AK21+AL21 -> 0 | AM21: =AN21+AO21 -> 0 | AP21: =F21+L21+R21+X21+AD21+AJ21 -> 0 | AQ21: =AP21/E21 -> #DIV/0!
F22: =G22+H22 -> 0 | I22: =J22+K22 -> 0 | L22: =M22+N22 -> 0 | O22: =P22+Q22 -> 0 | R22: =S22+T22 -> 0 | U22: =V22+W22 -> 0 | X22: =Y22+Z22 -> 0 | AA22: =AB22+AC22 -> 0 | AD22: =AE22+AF22 -> 0 | AG22: =AH22+AI22 -> 0 | AJ22: =AK22+AL22 -> 0 | AM22: =AN22+AO22 -> 0 | AP22: =F22+L22+R22+X22+AD22+AJ22 -> 0 | AQ22: =AP22/E22 -> #DIV/0!
F23: =G23+H23 -> 0 | I23: =J23+K23 -> 0 | L23: =M23+N23 -> 0 | O23: =P23+Q23 -> 0 | R23: =S23+T23 -> 0 | U23: =V23+W23 -> 0 | X23: =Y23+Z23 -> 0 | AA23: =AB23+AC23 -> 0 | AD23: =AE23+AF23 -> 0 | AG23: =AH23+AI23 -> 0 | AJ23: =AK23+AL23 -> 0 | AM23: =AN23+AO23 -> 0 | AP23: =F23+L23+R23+X23+AD23+AJ23 -> 0 | AQ23: =AP23/E23 -> #DIV/0!
F24: =G24+H24 -> 0 | I24: =J24+K24 -> 0 | L24: =M24+N24 -> 0 | O24: =P24+Q24 -> 0 | R24: =S24+T24 -> 0 | U24: =V24+W24 -> 0 | X24: =Y24+Z24 -> 0 | AA24: =AB24+AC24 -> 0 | AD24: =AE24+AF24 -> 0 | AG24: =AH24+AI24 -> 0 | AJ24: =AK24+AL24 -> 0 | AM24: =AN24+AO24 -> 0 | AP24: =F24+L24+R24+X24+AD24+AJ24 -> 0 | AQ24: =AP24/E24 -> #DIV/0!
F25: =G25+H25 -> 0 | I25: =J25+K25 -> 0 | L25: =M25+N25 -> 0 | O25: =P25+Q25 -> 0 | R25: =S25+T25 -> 0 | U25: =V25+W25 -> 0 | X25: =Y25+Z25 -> 0 | AA25: =AB25+AC25 -> 0 | AD25: =AE25+AF25 -> 0 | AG25: =AH25+AI25 -> 0 | AJ25: =AK25+AL25 -> 0 | AM25: =AN25+AO25 -> 0 | AP25: =F25+L25+R25+X25+AD25+AJ25 -> 0 | AQ25: =AP25/E25 -> #DIV/0!
F26: =G26+H26 -> 0 | I26: =J26+K26 -> 0 | L26: =M26+N26 -> 0 | O26: =P26+Q26 -> 0 | R26: =S26+T26 -> 0 | U26: =V26+W26 -> 0 | X26: =Y26+Z26 -> 0 | AA26: =AB26+AC26 -> 0 | AD26: =AE26+AF26 -> 0 | AG26: =AH26+AI26 -> 0 | AJ26: =AK26+AL26 -> 0 | AM26: =AN26+AO26 -> 0 | AP26: =F26+L26+R26+X26+AD26+AJ26 -> 0 | AQ26: =AP26/E26 -> #DIV/0!
F27: =G27+H27 -> 0 | I27: =J27+K27 -> 0 | L27: =M27+N27 -> 0 | O27: =P27+Q27 -> 0 | R27: =S27+T27 -> 0 | U27: =V27+W27 -> 0 | X27: =Y27+Z27 -> 0 | AA27: =AB27+AC27 -> 0 | AD27: =AE27+AF27 -> 0 | AG27: =AH27+AI27 -> 0 | AJ27: =AK27+AL27 -> 0 | AM27: =AN27+AO27 -> 0 | AP27: =F27+L27+R27+X27+AD27+AJ27 -> 0 | AQ27: =AP27/E27 -> #DIV/0!
F28: =G28+H28 -> 0 | I28: =J28+K28 -> 0 | L28: =M28+N28 -> 0 | O28: =P28+Q28 -> 0 | R28: =S28+T28 -> 0 | U28: =V28+W28 -> 0 | X28: =Y28+Z28 -> 0 | AA28: =AB28+AC28 -> 0 | AD28: =AE28+AF28 -> 0 | AG28: =AH28+AI28 -> 0 | AJ28: =AK28+AL28 -> 0 | AM28: =AN28+AO28 -> 0 | AP28: =F28+L28+R28+X28+AD28+AJ28 -> 0 | AQ28: =AP28/E28 -> #DIV/0!
F29: =G29+H29 -> 0 | I29: =J29+K29 -> 0 | L29: =M29+N29 -> 0 | O29: =P29+Q29 -> 0 | R29: =S29+T29 -> 0 | U29: =V29+W29 -> 0 | X29: =Y29+Z29 -> 0 | AA29: =AB29+AC29 -> 0 | AD29: =AE29+AF29 -> 0 | AG29: =AH29+AI29 -> 0 | AJ29: =AK29+AL29 -> 0 | AM29: =AN29+AO29 -> 0 | AP29: =F29+L29+R29+X29+AD29+AJ29 -> 0 | AQ29: =AP29/E29 -> #DIV/0!
F30: =G30+H30 -> 0 | I30: =J30+K30 -> 0 | L30: =M30+N30 -> 0 | O30: =P30+Q30 -> 0 | R30: =S30+T30 -> 0 | U30: =V30+W30 -> 0 | X30: =Y30+Z30 -> 0 | AA30: =AB30+AC30 -> 0 | AD30: =AE30+AF30 -> 0 | AG30: =AH30+AI30 -> 0 | AJ30: =AK30+AL30 -> 0 | AM30: =AN30+AO30 -> 0 | AP30: =F30+L30+R30+X30+AD30+AJ30 -> 0 | AQ30: =AP30/E30 -> #DIV/0!
F31: =G31+H31 -> 0 | I31: =J31+K31 -> 0 | L31: =M31+N31 -> 0 | O31: =P31+Q31 -> 0 | R31: =S31+T31 -> 0 | U31: =V31+W31 -> 0 | X31: =Y31+Z31 -> 0 | AA31: =AB31+AC31 -> 0 | AD31: =AE31+AF31 -> 0 | AG31: =AH31+AI31 -> 0 | AJ31: =AK31+AL31 -> 0 | AM31: =AN31+AO31 -> 0 | AP31: =F31+L31+R31+X31+AD31+AJ31 -> 0 | AQ31: =AP31/E31 -> #DIV/0!
B32: 合 計 | C32: =SUM(C12:C31) -> 6281 | D32: =SUM(D12:D31) -> 1748 | E32: =SUM(E12:E31) -> 6256 | F32: =SUM(F12:F31) -> 1595 | G32: =SUM(G12:G31) -> 691 | H32: =SUM(H12:H31) -> 904 | I32: =SUM(I12:I31) -> 812 | J32: =SUM(J12:J31) -> 314 | ... AP32: =SUM(AP12:AP31) -> 1595 | AQ32: =AP32/E32 -> 0.25495524

Sheet 様式３ 教育の質・履修者数を向上させるための体制・計画
I1: 様式３
G2: 大学等名 | H2: ='様式１ー１ プログラムを構成する授業科目'!C2 -> 順天堂大学
A4: 教育の質・履修者数を向上させるための体制・計画について
A6: ① | B6: 全学の教員数 | C6: (常勤） | E6: 1871 | F6: 人 | G6: （非常勤） | H6: 3192 | I6: 人
A8: ② | B8: プログラムの授業を教えている教員数 | H8: 51 | I8: 人
A10: ③ | B10: プログラムの運営責任者
B11: （責任者名） | C11: 木南 英紀 | G11: （役職名） | H11: 数理・データ科学教育研究センター長
A13: ④ | B13: プログラムを改善・進化させるための体制（委員会・組織等）
B14: 順天堂大学数理・データ科学教育研究センター、数理科学教育管理委員会
B16: （責任者名） | C16: 木南 英紀 | G16: （役職名） | H16: 数理・データ科学教育研究センター長
A18: ⑤ | B18: プログラムを改善・進化させるための体制を定める規則名称
B19: 数理・データ科学教育研究センター管理運営規程、数理・データ科学教育研究センター数理科学教育管理委員会細則
A21: ⑥ | B21: 体制の目的
B22: 本学では、全学における数理科学教育（数学・統計学のほか、その応用として諸科学を数理的に研究する数理科学に関する教育をいう。）の充実や質の向上を図るとともに、数理科学に関連する教育・研究を推進するため、2022年4月に「順天堂大学数理・データ科学教育研究センター」（以下「センター」）を設置し、教育体制の整備を推進している。 さらに、本プログラムの実施に関する実務的事項を審議するため、センターの下に「数理科学教育管理委員会」を設置し、各学部で本プログラムの授業科目を担当する専任教員を構成員として、授業計画の策定や実施、履修指導、ファカルティ・ディベロップメントに関する事項等について検討を行っている。
A34: ⑦ | B34: 具体的な構成員
B35: １．数理・データ科学教育研究センター 木南 英紀 センター長（学長特別補佐） 大橋 真也 特任教授 ２．数理科学教育管理委員会 木南 英紀 管理委員長（数理・データ科学教育研究センター長） 川村 浩之 管理委員（医学部、准教授） 廣津 信義 管理委員（スポーツ健康科学部、教授） 長瀬 雅子 管理委員（医療看護学部、先任准教授） 石塚 淳子 管理委員（保健看護学部、教授） 白山 芳久 管理委員（国際教養学部、准教授） 野尻 宗子 管理委員（保健医療学部、准教授） 佐藤 正一 管理委員（医療科学部、教授） 大橋 真也 管理委員（数理・データ科学教育研究センター、特任教授）
A48: ⑧ | B48: 履修者数・履修率の向上に向けた計画 ※様式１の「履修必須の有無」で「計画がある」としている場合は詳細について記載すること
B49: 令和４年度実績 | C49: ='様式２ 履修者等数の実績'!AQ32 -> 0.25495524 | E49: 令和５年度予定 | F49: 0.5 | H49: 令和６年度予定 | I49: 0.7
B50: 令和７年度予定 | C50: 0.9 | E50: 令和８年度予定 | F50: 0.95 | H50: 収容定員（名） | I50: ='様式２ 履修者等数の実績'!E32 -> 6256
B51: 具体的な計画
B52: 本学では、医療系大学という特質上、各学部の特性や専門性に合わせた科目でプログラムを構成している。 (1)国際教養学部、医療科学部においては、リテラシープログラムの修得に必須となる科目（以下「コア科目」）を全て必修化しており、卒業までに全員がプログラム履修者・修了者となる予定である。 (2)医学部、スポーツ健康科学部、医療看護学部、保健看護学部、保健医療学部においては、コア科目で必修ではない科目があるが、学生に対する広報や履修指導により選択科目においても高い履修率を確保している。引き続きこうした取組を通じ、履修率を維持・向上させる計画である。 (3)なお、医療看護学部については、令和６年度よりコア科目を必修化する予定である。
A65: ⑨ | B65: 学部・学科に関係なく希望する学生全員が受講可能となるような必要な体制・取組等
B66: 本学では、上記の通り、学部毎にそれぞれの特性や専門性に応じた科目でプログラムを構成しているが、どの学部の学生でもリテラシーレベルの知識・スキルを必ず修得できるよう、センターで学内共通のオンデマンド教材を開発し、各学部のプログラム担当教員に講義での活用を推奨している。 令和４年度は、こうしたオンデマンド教材を、講義の中だけでなく学生の準備学習や反復学習に活用する取組も進んでおり、今後は希望する学生がオンデマンド教材を視聴して自主的に学習できる環境を整備する予定である。
A79: ⑩ | B79: できる限り多くの学生が履修できるような具体的な周知方法・取組
B80: 本学では、プログラムを周知する手段として、専用のWebサイトによる情報掲載のほか、授業支援システムを通じた情報提供を行い、全ての学生がプログラムについて情報を得ることができるようにしている。 新入生に対しては、センターでプログラムを紹介するリーフレットを作成し、各学部のオリエンテーションやガイダンスの機会に周知している。プログラム担当教員よりデータサイエンスを学ぶ意義や重要性、履修・修了要件等を説明し、学生の興味・関心が高まるよう取り組んでいる。 さらに、センターが中心となり、学部横断的なコンペティションやシンポジウム、各種セミナーやワークショップ等を定期的に開催していく計画である。イベントを通じて本プログラムの周知を図るとともに、データサイエンスに触れる機会を増やすことで学生の認知度を高めていく方針である。
A93: ⑪ | B93: できる限り多くの学生が履修・修得できるようなサポート体制
B94: 各学部の教務課に履修相談窓口を設け、学生に対する個別カウンセリングを実施している。また、演習科目では担当教員に加えてティーチング・アシスタント（TA）を配置しており、学生に対してきめ細かいサポート・指導を行っている。現状では学生の規模に対するTAの数が不足しており、更なるTAの拡充について引き続き検討していく。
A107: ⑫ | B107: 授業時間内外で学習指導、質問を受け付ける具体的な仕組み
B108: プログラムの各科目についてオフィスアワーを設置するとともに、メールや授業支援システムを通じて学生が教員にいつでも質問・相談できる体制を確保している。また、希望する学生、あるいは基礎学力が不足する学生などに対し、自主参加の勉強会を設けるなど、きめ細かく対応している。 さらに、学生は準備学習や復習の用途でオンデマンド教材を視聴することが可能であり、学生が自主的に学習できる体制を構築している。講義動画については、一部の科目でアーカイブ化を開始し学生にも提供しているが、今後は全てのプログラムでアーカイブ化を進め、学生のプログラムの修得に資するよう仕組みを整備していく方針である。

Sheet 様式４　自己点検・評価
I1: 様式４
H2: 大学等名 | I2: ='様式１ー１ プログラムを構成する授業科目'!C2 -> 順天堂大学
A3: 自己点検・評価について
A5: ① | B5: プログラムの自己点検・評価を行う体制（委員会・組織等）
B6: 数理科学教育点検・評価委員会
D8: （責任者名） | E8: 木南 英紀 | G8: （役職名） | H8: 数理科学教育点検・評価委員長
A10: ② | B10: 自己点検・評価体制における意見等
B11: 自己点検・評価の視点 | E11: 自己点検・評価体制における意見・結果・改善に向けた取組等
B12: 学内からの視点
C13: プログラムの履修・修得状況 | E13: 令和４年度プログラムの点検・評価では、以下の点が指摘されている。 ・令和４年度の履修者数は1,595名（全学生の25.4％）となったが、プログラム適用対象となった１年生の履修率は89.8％と、開講初年度としては概ね良い結果となった。 ・国際教養学部、医療科学部ではコア科目の必修化により全ての学生が修了することができるが、その他の学部では選択科目となっているため、引き続き履修率の向上に努める必要がある。 これを受けて、数理・データ科学教育研究センター（以下、センター）では、学生の関心を高めプログラムの履修を促すため新入生向けリーフレットを作成し、ガイダンスを通じた周知や履修指導を実施している。
C14: 学修成果 | E14: 令和４年度プログラムの点検・評価では、以下の点が指摘されている。 ・学生の履修意欲を高め学修成果を可視化するため、できるだけ早い時期に、プログラム修了生に対する修了証の整備が望まれる。 ・また、修了証の発行に合わせ、プログラム修了生に対するアンケートを行い、教育研究や臨床現場でのスキルの活用、資格試験合格等の成果などを追跡することを通じて、学修成果を測っていくことが望まれる。 これを受けて、センターでは、令和５年度中の修了証の発行に向けて準備を開始するほか、プログラム修了者に対するアンケートについても検討を進める。
C15: 学生アンケート等を通じた学生の内容の理解度 | E15: センターが中心となり、学生や担当教員に対する授業評価アンケートを実施し分析することにより、プログラムに対する学生の理解度・満足度を把握している。 令和４年度プログラムの点検・評価では、以下の点が指摘されている。 ・アンケートによれば、学部や科目毎にばらつきは見られるものの、理解度や満足度に関する設問において履修学生の7割以上から肯定的評価を得られた。 これを受けて、センターでは、引き続き高い理解度や満足度を得られるよう、各学部の取組を整理し、FDなどを通じて効果的な実践方法の共有を図っていく。また、オンデマンド教材についても、担当教員の意見を踏まえながら改善を図り、更なる活用を促していく。
C16: 学生アンケート等を通じた後輩等他の学生への推奨度 | E16: 後輩他への推奨度に関しては、現時点では把握できていない。今後、センターが中心となってプログラム修了生に対するアンケートを通じて他の学生への推奨度を把握し、専用ウェブサイトへの掲載などにより修了生の声を発信していくこととする。
C17: 全学的な履修者数、履修率向上に向けた計画の達成・進捗状況 | E17: 国際教養学部、医療科学部においては、リテラシープログラムの修得に必須となる科目（コア科目）を全て必修化しており、卒業までに全員がプログラム修了者となる予定である。 医学部、スポーツ健康科学部、医療看護学部、保健看護学部、保健医療学部においては、コア科目が必修でない科目があるが、令和４年度は選択科目で高い履修率（20～100％）を確保している。引き続き学生に対する広報や履修指導を行い、履修率の維持・向上を図る必要がある。 なお、医療看護学部については、令和６年度にコア科目を必修化する予定である。全てのコア科目の必修化に向けて引き続き検討することとする。
B18: 学外からの視点
C19: 教育プログラム修了者の進路、活躍状況、企業等の評価 | E19: 令和４年度にプログラムを開始したばかりであり、現時点では修了生が卒業していない。今後、センターが中心となり、各種アンケートを通じてプログラム修了生の進路、活躍状況等を把握し、評価することとする。
C20: 産業界からの視点を含めた教育プログラム内容・手法等への意見 | E20: 令和４年度にプログラムを開始したばかりであり、現時点では本プログラムに対する外部意見を得られていない。今後、大学全体の「外部評価プロセス」を活用しながら、本プログラムの妥当性・有効性に関する意見を収集する予定である。 また、センターでは、令和５年度以降、企業と連携したコンペティションやセミナー等を企画する予定であり、そうした機会を通じて企業から本プログラムの評価を得ることとする。
B21: 数理・データサイエンス・ＡＩを「学ぶ楽しさ」「学ぶことの意義」を理解させること | E21: 令和４年度プログラムの点検・評価では、以下の点が指摘されている。 ・アンケ―ト結果によれば、「授業から知的な刺激を受け、その分野や関連分野のことをもっと知りたいと思ったか」の質問で、７割以上の学生が肯定的に評価しており、概ね「学ぶ楽しさ」「学ぶ意義」を教える授業となっていると評価できる。 ・学生の興味・関心を更に引き出すため、より発展的なプログラムに導く必要がある。そのため、発展科目や応用プログラム（応用基礎レベル）の開発・展開が望まれる。 これを踏まえ、センター、数理科学教育管理委員会が中心となり、数理・データサイエンス・AIの発展科目の整備及び応用プログラムの開講に向けて検討する。
B22: 内容・水準を維持・向上しつつ、より「分かりやすい」授業とすること | E22: 令和４年度プログラムの点検・評価では、以下の点が指摘されている。 ・アンケート結果によれば、「授業の分かりやすさ」「理解や技能の獲得を助けるための工夫」に関する質問で、約８割の学生が肯定的に評価しており、「分かりやすい」授業となっていると評価できる。 これを受けて、センターでは各学部の取組を整理し、FDなどを通じて効果的な実践を促していく。また、センターが作成するオンデマンド教材についても、担当教員の意見を踏まえながら改善を図り、更なる活用を促していく。
