Workbook
Name URL: '様式５ 自己点検・評価'!$G$18

Sheet 様式１　大学等概要
M1: 様式１
A2: 数理・データサイエンス・AI教育プログラム認定制度（リテラシーレベル） 申請様式
A4: ① | B4: 学校名 | C4: 大和大学 | O4: =IF(C4="","入力してください","")
A6: ② | B6: 大学等の設置者 | D6: 学校法人西大和学園 | I6: ③ | J6: 設置形態 | K6: 私立大学 | O6: =IF(D6="","入力してください","")
A8: ④ | B8: 所在地 | C8: 大阪府吹田市片山町2丁目5-1 | O8: =IF(C8="","入力してください","")
A10: ⑤ | B10: 申請するプログラム名称 | E10: 数理・AI・データサイエンス教育プログラム | O10: =IF(E10="","入力してください","")
A12: ⑥ | B12: プログラムの開設年度 | E12: 令和3 | G12: 年度 | H12: ⑦応用基礎レベルの申請の有無 | N12: 無 | O12: =IF(E12="","入力してください","")
A14: ⑧ | B14: 教員数 | C14: （常勤） | E14: 148 | G14: 人 | I14: （非常勤） | K14: 8 | N14: 人 | O14: =IF(OR(E14="",K14=""),"入力してください","")
A16: ⑨ | B16: プログラムの授業を教えている教員数 | K16: 14 | N16: 人 | O16: =IF(K16="","入力してください","")
A18: ⑩ | B18: 全学部・学科の入学定員 | E18: 960 | G18: 人 | O18: =IF(E18="","入力してください","")
A20: ⑪ | B20: 全学部・学科の学生数（学年別） | H20: 総数 | J20: =C22+I22+I24+C24+C26+I26 -> 3051 | M20: 人 | O20: =IF(J20="","入力してください","")
B22: １年次 | C22: 1007 | E22: 人 | G22: ２年次 | I22: 863 | K22: 人
B24: ３年次 | C24: 600 | E24: 人 | G24: ４年次 | I24: 581 | K24: 人
B26: ５年次 | C26: 0 | E26: 人 | G26: ６年次 | I26: 0 | K26: 人
A28: ⑫ | B28: プログラムの運営責任者
B29: （責任者名） | D29: 今村 浩章 | G29: （役職名） | J29: 教育学部長 | O29: =IF(OR(D29="",J29=""),"入力してください","")
A31: ⑬ | B31: プログラムを改善・進化させるための体制（委員会・組織等）
B32: 大和大学情報教育委員会 | O32: =IF(B32="","入力してください","")
B34: （責任者名） | D34: 今村 浩章 | G34: （役職名） | J34: 教育学部長 | O34: =IF(OR(D34="",J34=""),"入力してください","")
A36: ⑭ | B36: プログラムの自己点検・評価を行う体制（委員会・組織等）
B37: 大和大学情報教育委員会 | O37: =IF(B37="","入力してください","")
B39: （責任者名） | D39: 今村 浩章 | G39: （役職名） | J39: 教育学部長 | O39: =IF(OR(D39="",J39=""),"入力してください","")
A41: ⑮ | B41: 申請する認定プログラム | F41: 認定教育プログラム | O41: =IF(F41="","入力してください","")
A43: 連絡先
B44: 所属部署名 | C44: 理工学部 | I44: 担当者名 | K44: 鴻上 啓次朗 | O44: =IF(OR(C44="",K44=""),"入力してください","")
B45: E-mail | C45: ai_ds@yamato-u.ac.jp | I45: 電話番号 | K45: 06-6155-8050 | O45: =IF(OR(C45="",K45=""),"入力してください","")

Sheet 様式２-1　プログラムを構成する授業科目
W1: ="様式２－"&AB1 -> 様式２－1 | AB1: 1
A2: プログラムを構成する授業科目について
A4: ①具体的な修了要件 | H4: ②教育プログラムの修了要件 | O4: 学部・学科によって、修了要件は相違する
B6: =VLOOKUP(AB1,'(作業用)'!B4:D7,2)&"では、「"&VLOOKUP(AB1,'(作業用)'!B4:D7,3)&"」2単位と「AIデータサイエンス入門」2単位を取得すること。" -> 教育学部・保健医療学部では、「情報処理」2単位と「AIデータサイエンス入門」2単位を取得すること。
A13: ③現在進行中の社会変化（第４次産業革命、Society 5.0、データ駆動型社会等）に深く寄与しているものであり、それが自らの生活と密接に結びついている」の内容を含む授業科目
B15: 授業科目 | G15: 単位数 | H15: 必修 | I15: 開講状況 | L15: 1-1 | M15: 1-6 | N15: 授業科目 | T15: 単位数 | U15: 必修 | V15: 開講状況 | Y15: 1-1 | Z15: 1-6
B16: AIデータサイエンス入門 | G16: 2 | H16: ○ | I16: 全学開講 | L16: ○ | M16: ○
A24: ④「社会で活用されているデータ」や「データの活用領域」は非常に広範囲であって、日常生活や社会の課題を解決する有用なツールになり得るもの」の内容を含む授業科目
B26: 授業科目 | G26: 単位数 | H26: 必修 | I26: 開講状況 | L26: 1-2 | M26: 1-3 | N26: 授業科目 | T26: 単位数 | U26: 必修 | V26: 開講状況 | Y26: 1-2 | Z26: 1-3
B27: AIデータサイエンス入門 | G27: 2 | H27: ○ | I27: 全学開講 | L27: ○ | M27: ○
A35: ⑤「様々なデータ利活用の現場におけるデータ利活用事例が示され、様々な適用領域（流通、製造、金融、サービス、インフラ、公共、ヘルスケア等）の知見と組み合わせることで価値を創出するもの」の内容を含む授業科目
B37: 授業科目 | G37: 単位数 | H37: 必修 | I37: 開講状況 | L37: 1-4 | M37: 1-5 | N37: 授業科目 | T37: 単位数 | U37: 必修 | V37: 開講状況 | Y37: 1-4 | Z37: 1-5
B38: AIデータサイエンス入門 | G38: 2 | H38: ○ | I38: 全学開講 | L38: ○ | M38: ○
B39: =VLOOKUP(AB1,'(作業用)'!B4:D7,3) -> 情報処理 | G39: 2 | H39: ○ | I39: 一部開講 | L39: ○
A46: ⑥「活用に当たっての様々な留意事項（ELSI、個人情報、データ倫理、ＡＩ社会原則等）を考慮し、情報セキュリティや情報漏洩等、データを守る上での留意事項への理解をする」の内容を含む授業科目
B48: 授業科目 | G48: 単位数 | H48: 必修 | I48: 開講状況 | L48: 3-1 | M48: 3-2 | N48: 授業科目 | T48: 単位数 | U48: 必修 | V48: 開講状況 | Y48: 3-1 | Z48: 3-2
B49: AIデータサイエンス入門 | G49: 2 | H49: ○ | I49: 全学開講 | L49: ○ | M49: ○
B50: =VLOOKUP(AB1,'(作業用)'!B4:D7,3) -> 情報処理 | G50: 2 | H50: ○ | I50: 一部開講 | L50: ○ | M50: ○
A57: ⑦「実データ・実課題（学術データ等を含む）を用いた演習など、社会での実例を題材として、「データを読む、説明する、扱う」といった数理・データサイエンス・ＡＩの基本的な活用法に関するもの」の内容を含む授業科目
B59: 授業科目 | F59: 単位数 | G59: 必修 | H59: 開講状況 | K59: 2-1 | L59: 2-2 | M59: 2-3 | N59: 授業科目 | S59: 単位数 | T59: 必修 | U59: 開講状況 | X59: 2-1 | Y59: 2-2 | Z59: 2-3
B60: AIデータサイエンス入門 | F60: 2 | G60: ○ | H60: 全学開講 | K60: ○ | L60: ○ | M60: ○
B61: =VLOOKUP(AB1,'(作業用)'!B4:D7,3) -> 情報処理 | F61: 2 | G61: ○ | H61: 一部開講 | K61: ○ | L61: ○ | M61: ○
A68: ⑧選択「４．オプション」の内容を含む授業科目
B69: 授業科目 | G69: 選択項目 | N69: 授業科目 | T69: 選択項目
B70: AIデータサイエンス入門 | G70: 4-1統計および数理基礎
A78: ⑨プログラムを構成する授業の内容
B79: 授業に含まれている内容・要素 | D79: 講義内容
B80: （１）現在進行中の社会変化（第４次産業革命、Society 5.0、データ駆動型社会等）に深く寄与しているものであり、それが自らの生活と密接に結びついている | C80: 1-1 | D80: オリエンテーション「AIデータサイエンス入門」(第1回)
C81: 1-6 | D81: 事例紹介 「AIデータサイエンス入門」 (第1回) ディープラーニングの事例1～3 「AIデータサイエンス入門」 (第12～14回)
B82: （２）「社会で活用されているデータ」や「データの活用領域」は非常に広範囲であって、日常生活や社会の課題を解決する有用なツールになり得るもの | C82: 1-2 | D82: テキストマイニングの体験「AIデータサイエンス入門」(第5・6回) アンケート結果の分析「AIデータサイエンス入門」(第7回) ビッグデータ収集のやり方「AIデータサイエンス入門」(第9回)
C83: 1-3 | D83: データマイニングとテキストマイニングの紹介「AIデータサイエンス入門」(第2回) ディープラーニングの紹介「AIデータサイエンス入門」(第11回)
B84: （３）様々なデータ利活用の現場におけるデータ利活用事例が示され、様々な適用領域（流通、製造、金融、サービス、インフラ、公共、ヘルスケア等）の知見と組み合わせることで価値を創出するもの | C84: 1-4 | D84: データマイニングとテキストマイニングの紹介「AIデータサイエンス入門」(第2回) ディープラーニングの紹介「AIデータサイエンス入門」(第11回) Excelによる統計分析「情報処理」(第10回) Excelによるモデル化とシミュレーション「情報処理」(第11回)
C85: 1-5 | D85: 実データの収集: アンケートの設計と実施「AIデータサイエンス入門」(第6回) アンケート結果の分析「AIデータサイエンス入門」(第7回)
B86: （４）活用に当たっての様々な留意事項（ELSI、個人情報、データ倫理、ＡＩ社会原則等）を考慮し、情報セキュリティや情報漏洩等、データを守る上での留意事項への理解をする | C86: 3-1 | D86: ビッグデータの活用方法とデータの取扱の留意事項「AIデータサイエンス入門」(第10回) まとめと総合演習「AIデータサイエンス入門」(第15回) 情報倫理「情報処理」(第1回)
C87: 3-2 | D87: ビッグデータの活用方法とデータの取扱の留意事項「AIデータサイエンス入門」(第10回) まとめと総合演習「AIデータサイエンス入門」(第15回) 情報倫理「情報処理」(第1回)
B88: （５）実データ・実課題（学術データ等を含む）を用いた演習など、社会での実例を題材として、「データを読む、説明する、扱う」といった数理・データサイエンス・ＡＩの基本的な活用法に関するもの | C88: 2-1 | D88: アンケート結果の分析「AIデータサイエンス入門」(第7回) Excelによるグラフの作成「情報処理」(第8回)
C89: 2-2 | D89: データを説明する: 相関と回帰「AIデータサイエンス入門」(第4回) Excelによるグラフの作成「情報処理」(第8回)
C90: 2-3 | D90: データを扱う: 基本統計量とは「AIデータサイエンス入門」(第3回) Excelによるグラフの作成「情報処理」(第8回)
A92: ⑩プログラムの学修成果（学生等が身に付けられる能力等）
B93: データを扱う基本統計量、データを説明する回帰や相関関係などの内容を通してデータリテラシーを修得する。 データの活用時に倫理・法律・社会的な留意事項や情報セキュリティ等を考慮する重要性を理解する。 様々な活用事例を用い、AIを利活用するための素養を身につける。
...

Sheet 様式２-2　プログラムを構成する授業科目
W1: ="様式２－"&AB1 -> 様式２－2 | AB1: 2
A2: プログラムを構成する授業科目について
A4: ①具体的な修了要件 | H4: ②教育プログラムの修了要件 | O4: 学部・学科によって、修了要件は相違する
B6: =VLOOKUP(AB1,'(作業用)'!B4:D7,2)&"では、「"&VLOOKUP(AB1,'(作業用)'!B4:D7,3)&"」1単位と「AIデータサイエンス入門」2単位を取得すること。" -> 政治経済学部では、「情報処理Ⅰ」1単位と「AIデータサイエンス入門」2単位を取得すること。
A13: ③現在進行中の社会変化（第４次産業革命、Society 5.0、データ駆動型社会等）に深く寄与しているものであり、それが自らの生活と密接に結びついている」の内容を含む授業科目
B15: 授業科目 | G15: 単位数 | H15: 必修 | I15: 開講状況 | L15: 1-1 | M15: 1-6 | N15: 授業科目 | T15: 単位数 | U15: 必修 | V15: 開講状況 | Y15: 1-1 | Z15: 1-6
B16: AIデータサイエンス入門 | G16: 2 | H16: ○ | I16: 全学開講 | L16: ○ | M16: ○
A24: ④「社会で活用されているデータ」や「データの活用領域」は非常に広範囲であって、日常生活や社会の課題を解決する有用なツールになり得るもの」の内容を含む授業科目
B26: 授業科目 | G26: 単位数 | H26: 必修 | I26: 開講状況 | L26: 1-2 | M26: 1-3 | N26: 授業科目 | T26: 単位数 | U26: 必修 | V26: 開講状況 | Y26: 1-2 | Z26: 1-3
B27: AIデータサイエンス入門 | G27: 2 | H27: ○ | I27: 全学開講 | L27: ○ | M27: ○
A35: ⑤「様々なデータ利活用の現場におけるデータ利活用事例が示され、様々な適用領域（流通、製造、金融、サービス、インフラ、公共、ヘルスケア等）の知見と組み合わせることで価値を創出するもの」の内容を含む授業科目
B37: 授業科目 | G37: 単位数 | H37: 必修 | I37: 開講状況 | L37: 1-4 | M37: 1-5 | N37: 授業科目 | T37: 単位数 | U37: 必修 | V37: 開講状況 | Y37: 1-4 | Z37: 1-5
B38: AIデータサイエンス入門 | G38: 2 | H38: ○ | I38: 全学開講 | L38: ○ | M38: ○
B39: =VLOOKUP(AB1,'(作業用)'!B4:D7,3) -> 情報処理Ⅰ | G39: 1 | H39: ○ | I39: 一部開講 | L39: ○
A46: ⑥「活用に当たっての様々な留意事項（ELSI、個人情報、データ倫理、ＡＩ社会原則等）を考慮し、情報セキュリティや情報漏洩等、データを守る上での留意事項への理解をする」の内容を含む授業科目
B48: 授業科目 | G48: 単位数 | H48: 必修 | I48: 開講状況 | L48: 3-1 | M48: 3-2 | N48: 授業科目 | T48: 単位数 | U48: 必修 | V48: 開講状況 | Y48: 3-1 | Z48: 3-2
B49: AIデータサイエンス入門 | G49: 2 | H49: ○ | I49: 全学開講 | L49: ○ | M49: ○
B50: =VLOOKUP(AB1,'(作業用)'!B4:D7,3) -> 情報処理Ⅰ | G50: 1 | H50: ○ | I50: 一部開講 | L50: ○ | M50: ○
A57: ⑦「実データ・実課題（学術データ等を含む）を用いた演習など、社会での実例を題材として、「データを読む、説明する、扱う」といった数理・データサイエンス・ＡＩの基本的な活用法に関するもの」の内容を含む授業科目
B59: 授業科目 | F59: 単位数 | G59: 必修 | H59: 開講状況 | K59: 2-1 | L59: 2-2 | M59: 2-3 | N59: 授業科目 | S59: 単位数 | T59: 必修 | U59: 開講状況 | X59: 2-1 | Y59: 2-2 | Z59: 2-3
B60: AIデータサイエンス入門 | F60: 2 | G60: ○ | H60: 全学開講 | K60: ○ | L60: ○ | M60: ○
B61: =VLOOKUP(AB1,'(作業用)'!B4:D7,3) -> 情報処理Ⅰ | F61: 1 | G61: ○ | H61: 一部開講 | K61: ○ | L61: ○ | M61: ○
A68: ⑧選択「４．オプション」の内容を含む授業科目
B69: 授業科目 | G69: 選択項目 | N69: 授業科目 | T69: 選択項目
B70: AIデータサイエンス入門 | G70: 4-1統計および数理基礎
A78: ⑨プログラムを構成する授業の内容
B79: 授業に含まれている内容・要素 | D79: 講義内容
B80: （１）現在進行中の社会変化（第４次産業革命、Society 5.0、データ駆動型社会等）に深く寄与しているものであり、それが自らの生活と密接に結びついている | C80: 1-1 | D80: オリエンテーション「AIデータサイエンス入門」(第1回)
C81: 1-6 | D81: 事例紹介 「AIデータサイエンス入門」 (第1回) ディープラーニングの事例1～3 「AIデータサイエンス入門」 (第12～14回)
B82: （２）「社会で活用されているデータ」や「データの活用領域」は非常に広範囲であって、日常生活や社会の課題を解決する有用なツールになり得るもの | C82: 1-2 | D82: テキストマイニングの体験「AIデータサイエンス入門」(第5・6回) アンケート結果の分析「AIデータサイエンス入門」(第7回) ビッグデータ収集のやり方「AIデータサイエンス入門」(第9回)
C83: 1-3 | D83: データマイニングとテキストマイニングの紹介「AIデータサイエンス入門」(第2回) ディープラーニングの紹介「AIデータサイエンス入門」(第11回)
B84: （３）様々なデータ利活用の現場におけるデータ利活用事例が示され、様々な適用領域（流通、製造、金融、サービス、インフラ、公共、ヘルスケア等）の知見と組み合わせることで価値を創出するもの | C84: 1-4 | D84: データマイニングとテキストマイニングの紹介「AIデータサイエンス入門」(第2回) ディープラーニングの紹介「AIデータサイエンス入門」(第11回) Excelによるデータ分析「情報処理Ⅰ」(第12回)
C85: 1-5 | D85: 実データの収集: アンケートの設計と実施「AIデータサイエンス入門」(第6回) アンケート結果の分析「AIデータサイエンス入門」(第7回)
B86: （４）活用に当たっての様々な留意事項（ELSI、個人情報、データ倫理、ＡＩ社会原則等）を考慮し、情報セキュリティや情報漏洩等、データを守る上での留意事項への理解をする | C86: 3-1 | D86: ビッグデータの活用方法とデータの取扱の留意事項「AIデータサイエンス入門」(第10回) まとめと総合演習「AIデータサイエンス入門」(第15回) ガイダンス「情報処理Ⅰ」(第1回)
C87: 3-2 | D87: ビッグデータの活用方法とデータの取扱の留意事項「AIデータサイエンス入門」(第10回) まとめと総合演習「AIデータサイエンス入門」(第15回) ガイダンス「情報処理Ⅰ」(第1回)
B88: （５）実データ・実課題（学術データ等を含む）を用いた演習など、社会での実例を題材として、「データを読む、説明する、扱う」といった数理・データサイエンス・ＡＩの基本的な活用法に関するもの | C88: 2-1 | D88: アンケート結果の分析「AIデータサイエンス入門」(第7回) Excelによるグラフの作成「情報処理Ⅰ」(第9回)
C89: 2-2 | D89: データを説明する: 相関と回帰「AIデータサイエンス入門」(第4回) Excelによるグラフの作成「情報処理Ⅰ」(第9回)
C90: 2-3 | D90: データを扱う: 基本統計量とは「AIデータサイエンス入門」(第3回) Excelによるデータのまとめ方「情報処理Ⅰ」(第7・8回)
A92: ⑩プログラムの学修成果（学生等が身に付けられる能力等）
B93: データを扱う基本統計量、データを説明する回帰や相関関係などの内容を通してデータリテラシーを修得する。 データの活用時に倫理・法律・社会的な留意事項や情報セキュリティ等を考慮する重要性を理解する。 様々な活用事例を用い、AIを利活用するための素養を身につける。
...

Sheet 様式２-3　プログラムを構成する授業科目
W1: ="様式２－"&AB1 -> 様式２－3 | AB1: 3
A2: プログラムを構成する授業科目について
A4: ①具体的な修了要件 | H4: ②教育プログラムの修了要件 | O4: 学部・学科によって、修了要件は相違する
B6: =VLOOKUP(AB1,'(作業用)'!B4:D7,2)&"では、「"&VLOOKUP(AB1,'(作業用)'!B4:D7,3)&"」2単位と「AIデータサイエンス入門」2単位を取得すること。" -> 理工学部では、「情報処理入門」2単位と「AIデータサイエンス入門」2単位を取得すること。
A13: ③現在進行中の社会変化（第４次産業革命、Society 5.0、データ駆動型社会等）に深く寄与しているものであり、それが自らの生活と密接に結びついている」の内容を含む授業科目
B15: 授業科目 | G15: 単位数 | H15: 必修 | I15: 開講状況 | L15: 1-1 | M15: 1-6 | N15: 授業科目 | T15: 単位数 | U15: 必修 | V15: 開講状況 | Y15: 1-1 | Z15: 1-6
B16: AIデータサイエンス入門 | G16: 2 | H16: ○ | I16: 全学開講 | L16: ○ | M16: ○
A24: ④「社会で活用されているデータ」や「データの活用領域」は非常に広範囲であって、日常生活や社会の課題を解決する有用なツールになり得るもの」の内容を含む授業科目
B26: 授業科目 | G26: 単位数 | H26: 必修 | I26: 開講状況 | L26: 1-2 | M26: 1-3 | N26: 授業科目 | T26: 単位数 | U26: 必修 | V26: 開講状況 | Y26: 1-2 | Z26: 1-3
B27: AIデータサイエンス入門 | G27: 2 | H27: ○ | I27: 全学開講 | L27: ○ | M27: ○
A35: ⑤「様々なデータ利活用の現場におけるデータ利活用事例が示され、様々な適用領域（流通、製造、金融、サービス、インフラ、公共、ヘルスケア等）の知見と組み合わせることで価値を創出するもの」の内容を含む授業科目
B37: 授業科目 | G37: 単位数 | H37: 必修 | I37: 開講状況 | L37: 1-4 | M37: 1-5 | N37: 授業科目 | T37: 単位数 | U37: 必修 | V37: 開講状況 | Y37: 1-4 | Z37: 1-5
B38: AIデータサイエンス入門 | G38: 2 | H38: ○ | I38: 全学開講 | L38: ○ | M38: ○
B39: =VLOOKUP(AB1,'(作業用)'!B4:D7,3) -> 情報処理入門 | G39: 2 | H39: ○ | I39: 一部開講 | L39: ○
A46: ⑥「活用に当たっての様々な留意事項（ELSI、個人情報、データ倫理、ＡＩ社会原則等）を考慮し、情報セキュリティや情報漏洩等、データを守る上での留意事項への理解をする」の内容を含む授業科目
B48: 授業科目 | G48: 単位数 | H48: 必修 | I48: 開講状況 | L48: 3-1 | M48: 3-2 | N48: 授業科目 | T48: 単位数 | U48: 必修 | V48: 開講状況 | Y48: 3-1 | Z48: 3-2
B49: AIデータサイエンス入門 | G49: 2 | H49: ○ | I49: 全学開講 | L49: ○ | M49: ○
B50: =VLOOKUP(AB1,'(作業用)'!B4:D7,3) -> 情報処理入門 | G50: 2 | H50: ○ | I50: 一部開講 | L50: ○ | M50: ○
A57: ⑦「実データ・実課題（学術データ等を含む）を用いた演習など、社会での実例を題材として、「データを読む、説明する、扱う」といった数理・データサイエンス・ＡＩの基本的な活用法に関するもの」の内容を含む授業科目
B59: 授業科目 | F59: 単位数 | G59: 必修 | H59: 開講状況 | K59: 2-1 | L59: 2-2 | M59: 2-3 | N59: 授業科目 | S59: 単位数 | T59: 必修 | U59: 開講状況 | X59: 2-1 | Y59: 2-2 | Z59: 2-3
B60: AIデータサイエンス入門 | F60: 2 | G60: ○ | H60: 全学開講 | K60: ○ | L60: ○ | M60: ○
B61: =VLOOKUP(AB1,'(作業用)'!B4:D7,3) -> 情報処理入門 | F61: 2 | G61: ○ | H61: 一部開講 | K61: ○ | L61: ○ | M61: ○
A68: ⑧選択「４．オプション」の内容を含む授業科目
B69: 授業科目 | G69: 選択項目 | N69: 授業科目 | T69: 選択項目
B70: AIデータサイエンス入門 | G70: 4-1統計および数理基礎
A78: ⑨プログラムを構成する授業の内容
B79: 授業に含まれている内容・要素 | D79: 講義内容
B80: （１）現在進行中の社会変化（第４次産業革命、Society 5.0、データ駆動型社会等）に深く寄与しているものであり、それが自らの生活と密接に結びついている | C80: 1-1 | D80: オリエンテーション「AIデータサイエンス入門」(第1回)
C81: 1-6 | D81: 事例紹介 「AIデータサイエンス入門」 (第1回) ディープラーニングの事例1～3 「AIデータサイエンス入門」 (第12～14回)
B82: （２）「社会で活用されているデータ」や「データの活用領域」は非常に広範囲であって、日常生活や社会の課題を解決する有用なツールになり得るもの | C82: 1-2 | D82: テキストマイニングの体験「AIデータサイエンス入門」(第5・6回) アンケート結果の分析「AIデータサイエンス入門」(第7回) ビッグデータ収集のやり方「AIデータサイエンス入門」(第9回)
C83: 1-3 | D83: データマイニングとテキストマイニングの紹介「AIデータサイエンス入門」(第2回) ディープラーニングの紹介「AIデータサイエンス入門」(第11回)
B84: （３）様々なデータ利活用の現場におけるデータ利活用事例が示され、様々な適用領域（流通、製造、金融、サービス、インフラ、公共、ヘルスケア等）の知見と組み合わせることで価値を創出するもの | C84: 1-4 | D84: データマイニングとテキストマイニングの紹介「AIデータサイエンス入門」(第2回) ディープラーニングの紹介「AIデータサイエンス入門」(第11回) Microsoft Excel利用方法・演習「情報処理入門」(第9～11回)
C85: 1-5 | D85: 実データの収集: アンケートの設計と実施「AIデータサイエンス入門」(第6回) アンケート結果の分析「AIデータサイエンス入門」(第7回)
B86: （４）活用に当たっての様々な留意事項（ELSI、個人情報、データ倫理、ＡＩ社会原則等）を考慮し、情報セキュリティや情報漏洩等、データを守る上での留意事項への理解をする | C86: 3-1 | D86: ビッグデータの活用方法とデータの取扱の留意事項「AIデータサイエンス入門」(第10回) まとめと総合演習「AIデータサイエンス入門」(第15回) 講義ガイダンス「情報処理入門」(第1回)
C87: 3-2 | D87: ビッグデータの活用方法とデータの取扱の留意事項「AIデータサイエンス入門」(第10回) まとめと総合演習「AIデータサイエンス入門」(第15回) 講義ガイダンス「情報処理入門」(第1回)
B88: （５）実データ・実課題（学術データ等を含む）を用いた演習など、社会での実例を題材として、「データを読む、説明する、扱う」といった数理・データサイエンス・ＡＩの基本的な活用法に関するもの | C88: 2-1 | D88: アンケート結果の分析「AIデータサイエンス入門」(第7回) Microsoft Excel利用方法・演習「情報処理入門」(第9～11回)
C89: 2-2 | D89: データを説明する: 相関と回帰「AIデータサイエンス入門」(第4回) Microsoft Excel利用方法・演習「情報処理入門」(第9～11回)
C90: 2-3 | D90: データを扱う: 基本統計量とは「AIデータサイエンス入門」(第3回) Microsoft Excel利用方法・演習「情報処理入門」(第9～11回)
A92: ⑩プログラムの学修成果（学生等が身に付けられる能力等）
B93: データを扱う基本統計量、データを説明する回帰や相関関係などの内容を通してデータリテラシーを修得する。 データの活用時に倫理・法律・社会的な留意事項や情報セキュリティ等を考慮する重要性を理解する。 様々な活用事例を用い、AIを利活用するための素養を身につける。
...

Sheet 様式２-4　プログラムを構成する授業科目
W1: ="様式２－"&AB1 -> 様式２－4 | AB1: 4
A2: プログラムを構成する授業科目について
A4: ①具体的な修了要件 | H4: ②教育プログラムの修了要件 | O4: 学部・学科によって、修了要件は相違する
B6: =VLOOKUP(AB1,'(作業用)'!B4:D7,2)&"では、「"&VLOOKUP(AB1,'(作業用)'!B4:D7,3)&"」2単位と「AIデータサイエンス入門」2単位を取得すること。" -> 社会学部では、「コンピュータ入門」2単位と「AIデータサイエンス入門」2単位を取得すること。
A13: ③現在進行中の社会変化（第４次産業革命、Society 5.0、データ駆動型社会等）に深く寄与しているものであり、それが自らの生活と密接に結びついている」の内容を含む授業科目
B15: 授業科目 | G15: 単位数 | H15: 必修 | I15: 開講状況 | L15: 1-1 | M15: 1-6 | N15: 授業科目 | T15: 単位数 | U15: 必修 | V15: 開講状況 | Y15: 1-1 | Z15: 1-6
B16: AIデータサイエンス入門 | G16: 2 | H16: ○ | I16: 全学開講 | L16: ○ | M16: ○
A24: ④「社会で活用されているデータ」や「データの活用領域」は非常に広範囲であって、日常生活や社会の課題を解決する有用なツールになり得るもの」の内容を含む授業科目
B26: 授業科目 | G26: 単位数 | H26: 必修 | I26: 開講状況 | L26: 1-2 | M26: 1-3 | N26: 授業科目 | T26: 単位数 | U26: 必修 | V26: 開講状況 | Y26: 1-2 | Z26: 1-3
B27: AIデータサイエンス入門 | G27: 2 | H27: ○ | I27: 全学開講 | L27: ○ | M27: ○
A35: ⑤「様々なデータ利活用の現場におけるデータ利活用事例が示され、様々な適用領域（流通、製造、金融、サービス、インフラ、公共、ヘルスケア等）の知見と組み合わせることで価値を創出するもの」の内容を含む授業科目
B37: 授業科目 | G37: 単位数 | H37: 必修 | I37: 開講状況 | L37: 1-4 | M37: 1-5 | N37: 授業科目 | T37: 単位数 | U37: 必修 | V37: 開講状況 | Y37: 1-4 | Z37: 1-5
B38: AIデータサイエンス入門 | G38: 2 | H38: ○ | I38: 全学開講 | L38: ○ | M38: ○
B39: =VLOOKUP(AB1,'(作業用)'!B4:D7,3) -> コンピュータ入門 | G39: 2 | H39: ○ | I39: 一部開講 | L39: ○
A46: ⑥「活用に当たっての様々な留意事項（ELSI、個人情報、データ倫理、ＡＩ社会原則等）を考慮し、情報セキュリティや情報漏洩等、データを守る上での留意事項への理解をする」の内容を含む授業科目
B48: 授業科目 | G48: 単位数 | H48: 必修 | I48: 開講状況 | L48: 3-1 | M48: 3-2 | N48: 授業科目 | T48: 単位数 | U48: 必修 | V48: 開講状況 | Y48: 3-1 | Z48: 3-2
B49: AIデータサイエンス入門 | G49: 2 | H49: ○ | I49: 全学開講 | L49: ○ | M49: ○
B50: =VLOOKUP(AB1,'(作業用)'!B4:D7,3) -> コンピュータ入門 | G50: 2 | H50: ○ | I50: 一部開講 | L50: ○ | M50: ○
A57: ⑦「実データ・実課題（学術データ等を含む）を用いた演習など、社会での実例を題材として、「データを読む、説明する、扱う」といった数理・データサイエンス・ＡＩの基本的な活用法に関するもの」の内容を含む授業科目
B59: 授業科目 | F59: 単位数 | G59: 必修 | H59: 開講状況 | K59: 2-1 | L59: 2-2 | M59: 2-3 | N59: 授業科目 | S59: 単位数 | T59: 必修 | U59: 開講状況 | X59: 2-1 | Y59: 2-2 | Z59: 2-3
B60: AIデータサイエンス入門 | F60: 2 | G60: ○ | H60: 全学開講 | K60: ○ | L60: ○ | M60: ○
B61: =VLOOKUP(AB1,'(作業用)'!B4:D7,3) -> コンピュータ入門 | F61: 2 | G61: ○ | H61: 一部開講 | K61: ○ | L61: ○ | M61: ○
A68: ⑧選択「４．オプション」の内容を含む授業科目
B69: 授業科目 | G69: 選択項目 | N69: 授業科目 | T69: 選択項目
B70: AIデータサイエンス入門 | G70: 4-1統計および数理基礎
A78: ⑨プログラムを構成する授業の内容
B79: 授業に含まれている内容・要素 | D79: 講義内容
B80: （１）現在進行中の社会変化（第４次産業革命、Society 5.0、データ駆動型社会等）に深く寄与しているものであり、それが自らの生活と密接に結びついている | C80: 1-1 | D80: オリエンテーション「AIデータサイエンス入門」(第1回)
C81: 1-6 | D81: 事例紹介 「AIデータサイエンス入門」 (第1回) ディープラーニングの事例1～3 「AIデータサイエンス入門」 (第12～14回)
B82: （２）「社会で活用されているデータ」や「データの活用領域」は非常に広範囲であって、日常生活や社会の課題を解決する有用なツールになり得るもの | C82: 1-2 | D82: テキストマイニングの体験「AIデータサイエンス入門」(第5・6回) アンケート結果の分析「AIデータサイエンス入門」(第7回) ビッグデータ収集のやり方「AIデータサイエンス入門」(第9回)
C83: 1-3 | D83: データマイニングとテキストマイニングの紹介「AIデータサイエンス入門」(第2回) ディープラーニングの紹介「AIデータサイエンス入門」(第11回)
B84: （３）様々なデータ利活用の現場におけるデータ利活用事例が示され、様々な適用領域（流通、製造、金融、サービス、インフラ、公共、ヘルスケア等）の知見と組み合わせることで価値を創出するもの | C84: 1-4 | D84: データマイニングとテキストマイニングの紹介「AIデータサイエンス入門」(第2回) ディープラーニングの紹介「AIデータサイエンス入門」(第11回) Excel活用・グラフ・データベース「コンピュータ入門」(第10・11回)
C85: 1-5 | D85: 実データの収集: アンケートの設計と実施「AIデータサイエンス入門」(第6回) アンケート結果の分析「AIデータサイエンス入門」(第7回)
B86: （４）活用に当たっての様々な留意事項（ELSI、個人情報、データ倫理、ＡＩ社会原則等）を考慮し、情報セキュリティや情報漏洩等、データを守る上での留意事項への理解をする | C86: 3-1 | D86: ビッグデータの活用方法とデータの取扱の留意事項「AIデータサイエンス入門」(第10回) まとめと総合演習「AIデータサイエンス入門」(第15回) 情報倫理「コンピュータ入門」(第1・2回)
C87: 3-2 | D87: ビッグデータの活用方法とデータの取扱の留意事項「AIデータサイエンス入門」(第10回) まとめと総合演習「AIデータサイエンス入門」(第15回) 情報倫理「コンピュータ入門」(第1・2回)
B88: （５）実データ・実課題（学術データ等を含む）を用いた演習など、社会での実例を題材として、「データを読む、説明する、扱う」といった数理・データサイエンス・ＡＩの基本的な活用法に関するもの | C88: 2-1 | D88: アンケート結果の分析「AIデータサイエンス入門」(第7回) Excel入門、実践、活用「コンピュータ入門」(第7～11回)
C89: 2-2 | D89: データを説明する: 相関と回帰「AIデータサイエンス入門」(第4回) Excel入門、実践、活用「コンピュータ入門」(第7～11回)
C90: 2-3 | D90: データを扱う: 基本統計量とは「AIデータサイエンス入門」(第3回) Excel入門、実践、活用「コンピュータ入門」(第7～11回)
A92: ⑩プログラムの学修成果（学生等が身に付けられる能力等）
B93: データを扱う基本統計量、データを説明する回帰や相関関係などの内容を通してデータリテラシーを修得する。 データの活用時に倫理・法律・社会的な留意事項や情報セキュリティ等を考慮する重要性を理解する。 様々な活用事例を用い、AIを利活用するための素養を身につける。
...

Sheet 様式３　履修者等数の実績
F1: 様式３
A2: プログラムの履修者数等の実績について
A4: ①プログラム開設年度 | C4: ='様式１ 大学等概要'!E12 -> 令和3 | E4: 年度
A6: ②履修者・修了者の実績
B8: 学部・学科名称 | C8: 入学 定員 | D8: 収容 定員 | E8: 令和3年度 | G8: 令和2年度 | I8: 令和元年度 | K8: 平成30年度 | M8: 平成29年度 | O8: 平成28年度 | Q8: 履修者数 合計 | R8: 履修率
E9: 履修者数 | F9: 修了者数 | G9: 履修者数 | H9: 修了者数 | I9: 履修者数 | J9: 修了者数 | K9: 履修者数 | L9: 修了者数 | M9: 履修者数 | N9: 修了者数 | O9: 履修者数 | P9: 修了者数
B10: 教育学部 | C10: 190 | D10: 770 | E10: 12 | F10: 8 | Q10: =E10+G10+I10+K10+M10+O10 -> 12 | R10: =Q10/D10 -> 0.015584416
B11: 保健医療学部 | C11: =D11/4 -> 220 | D11: =400+160*3 -> 880 | E11: 6 | F11: 6 | Q11: =E11+G11+I11+K11+M11+O11 -> 6 | R11: =Q11/D11 -> 0.0068181818
B12: 政治経済学部 | C12: =D12/4 -> 120 | D12: 480 | E12: 1 | F12: 1 | Q12: =E12+G12+I12+K12+M12+O12 -> 1 | R12: =Q12/D12 -> 0.0020833333
B13: 理工学部 | C13: =D13/4 -> 230 | D13: 920 | E13: 8 | F13: 5 | Q13: =E13+G13+I13+K13+M13+O13 -> 8 | R13: =Q13/D13 -> 0.0086956522
B14: 社会学部 | C14: =D14/4 -> 200 | D14: 800 | E14: 1 | F14: 1 | Q14: =E14+G14+I14+K14+M14+O14 -> 1 | R14: =Q14/D14 -> 0.00125
Q15: =E15+G15+I15+K15+M15+O15 -> 0 | R15: =Q15/D15 -> #DIV/0!
Q16: =E16+G16+I16+K16+M16+O16 -> 0 | R16: =Q16/D16 -> #DIV/0!
Q17: =E17+G17+I17+K17+M17+O17 -> 0 | R17: =Q17/D17 -> #DIV/0!
Q18: =E18+G18+I18+K18+M18+O18 -> 0 | R18: =Q18/D18 -> #DIV/0!
Q19: =E19+G19+I19+K19+M19+O19 -> 0 | R19: =Q19/D19 -> #DIV/0!
Q20: =E20+G20+I20+K20+M20+O20 -> 0 | R20: =Q20/D20 -> #DIV/0!
Q21: =E21+G21+I21+K21+M21+O21 -> 0 | R21: =Q21/D21 -> #DIV/0!
Q22: =E22+G22+I22+K22+M22+O22 -> 0 | R22: =Q22/D22 -> #DIV/0!
Q23: =E23+G23+I23+K23+M23+O23 -> 0 | R23: =Q23/D23 -> #DIV/0!
Q24: =E24+G24+I24+K24+M24+O24 -> 0 | R24: =Q24/D24 -> #DIV/0!
Q25: =E25+G25+I25+K25+M25+O25 -> 0 | R25: =Q25/D25 -> #DIV/0!
Q26: =E26+G26+I26+K26+M26+O26 -> 0 | R26: =Q26/D26 -> #DIV/0!
... Q29: =E29+G29+I29+K29+M29+O29 -> 0 | R29: =Q29/D29 -> #DIV/0!
B30: 合 計 | C30: =SUM(C10:C29) -> 960 | D30: =SUM(D10:D29) -> 3850 | E30: =SUM(E10:E29) -> 28 | F30: =SUM(F10:F29) -> 21 | G30: =SUM(G10:G29) -> 0 | H30: =SUM(H10:H29) -> 0 | I30: =SUM(I10:I29) -> 0 | J30: =SUM(J10:J29) -> 0 | ... Q30: =SUM(Q10:Q29) -> 28 | R30: =Q30/D30 -> 0.0072727273

Sheet 様式４　教育の質・履修者数を向上させるための体制・計画
J1: 様式４
A2: 教育の質・履修者数を向上させるための体制・計画について
A4: ① | B4: プログラムを改善・進化させるための体制を定める規則名称
B5: 大和大学情報教育委員会規程 | K5: =IF(B5="","入力してください","")
A7: ② | B7: 体制の目的
B8: 本委員会は、情報教育の今後の展開に向けて情報教育全般に関わる議論を行ってきた。数理・AI・データサイエンス教育プログラムの設置、普及、改善等についても、これまでの本学独自の情報教育内容からの円滑な移行、新展開を考え、本委員会において議論することが適切であると判断した。令和3年度は、数理・AI・データサイエンス教育プログラムの設置検討、関連科目の整備、全学的な普及を行うとともに、令和4年度以降に向けた改善等の議論も継続的に行っている。 | K8: =IF(B8="","入力してください","")
A14: ③ | B14: 具体的な構成員
B15: 委員長 今村 浩章（教育学部長） 副委員長 上村 佳永（理工学部長） 副委員長 鴻上 啓次朗（理工学部長補佐） 委 員 松本 啓之亮（理工学部情報科学専攻 教授） 委 員 北村 章（理工学部情報科学専攻 教授） 委 員 谷川 明夫（理工学部情報科学専攻 教授） 委 員 髙田 司郎（理工学部情報科学専攻 教授） 委 員 宮下 鋭也（理工学部数理科学専攻 准教授） 委 員 及川 久遠（教育学部 教授） 委 員 光永 文彦（教育学部 准教授） 委 員 立花 晃（社会学部 准教授） 委 員 阿部 哲也（理工学部 技術職員） | K15: =IF(B15="","入力してください","")
A27: ④ | B27: 履修者数・履修率の向上に向けた計画
B28: 令和３年度実績 | C28: ='様式３ 履修者等数の実績'!R30 -> 0.0072727273 | E28: 令和４年度予定 | F28: 0.04 | H28: 令和５年度予定 | I28: 0.29
B29: 令和６年度予定 | C29: 0.54 | E29: 令和７年度予定 | F29: 0.79 | H29: 収容定員（名） | I29: ='様式３ 履修者等数の実績'!D30 -> 3850
B30: 具体的な計画
B31: 各年度の履修者数の目標を以下のとおりとする。（（ ）内は履修率。） 令和４年度 168名 （4％） 令和５年度 1128名 （29％） 令和６年度 2088名 （54％） 令和７年度 3025名 （79％） 令和８年度 3850名 （100％） 令和5年度より、「AIデータサイエンス入門」を全学で必修化し、「情報処理」の関連科目と併せて数理・AI・データサイエンス教育に必要な内容を全て学べるようにする。また、授業時間内外での学習指導、質問を受け付ける仕組みや教育上の工夫、学生指導・支援等の学修サポート等について、情報教育委員会でより適切なものとなるよう、継続的に検討していく計画である。 | K31: =IF(B31="","入力してください","")
A45: ⑤ | B45: 学部・学科に関係なく希望する学生全員が受講可能となるような必要な体制・取組等
B46: 令和5年度より「AIデータサイエンス入門」を全学で必修化し、「情報処理」関連科目と併せて本教育プログラムを実施することにした。学部・学科に関係なく希望する学生全員が受講できる体制として、指導者の追加配置及びオンデマンド授業の実施などの指導体制を構築していく計画である。 | K46: =IF(B46="","入力してください","")
A68: ⑥ | B68: できる限り多くの学生が履修できるような具体的な周知方法・取組
B69: 既に必修である「情報処理」関連の科目と併せて、令和5年度より「AIデータサイエンス入門」を必修化する。また、全員に入学後のガイダンス等で本教育プログラムの意義・魅力を周知する。さらに、本学のWebサイト内に数理・AI・データサイエンス教育プログラムのページを設置して情報を掲載し、学生が情報を受け取りやすい環境を整備している。 | K69: =IF(B69="","入力してください","")
A88: ⑦ | B88: できる限り多くの学生が履修・修得できるようなサポート体制
B89: 多くの学生が本教育プログラムを円滑に修得できるよう、科目ごとのGoogle Classroomを作成し、随時担当教員に質問できる体制を構築するとともに、授業を録画したオンデマンド教材を提示するなど、学びを促すための取り組みを行う。
K91: =IF(B89="","入力してください","")
A110: ⑧ | B110: 授業時間内外で学習指導、質問を受け付ける具体的な仕組み
B111: 本教育プログラムの科目は、すべてGoogleClassroomに登録されており、そこの投稿やチャットなどの機能を用いて、授業時間内外で質問ができるようになっている。担当教員はそれに返信する形でいつでも学習指導をすることができる。また、担当教員が指導に困った際には、必要に応じて情報教育委員会の委員を経由して他の教員が返答する体制も整備している。
K113: =IF(B111="","入力してください","")

Sheet 様式５　自己点検・評価
J1: 様式５
A2: 自己点検・評価について
A4: ① | B4: 自己点検・評価体制における意見等
B5: 自己点検・評価の視点 | E5: 自己点検・評価体制における意見・結果・改善に向けた取組等
B6: 学内からの視点
C7: プログラムの履修・修得状況 | E7: 大和大学情報教育委員会にて、プログラムの履修・修得状況の報告を定期的に行い、委員会内で学生の出席状況や授業の進行状況を把握している。また、Google Classroomを活用し、受講者毎の課題の提出状況を把握することができる。これらの点検の結果を踏まえ、同委員会にて次期開講の授業実施形態などの改善に結びつけている。 「AIデータサイエンス入門」の講義は令和5年度より全学で必修化するため、授業実施形態を見直すとともに、指導者の追加配置、学習環境のオンデマンド化を推進していく。 | K7: =IF(E7="","入力してください","")
C8: 学修成果 | E8: 令和3年度に行った授業では、「AIデータサイエンス入門」の成績評価の平均は79点、「情報処理」関連科目の成績評価の平均は88点であり、当初想定していた点数よりも良い結果となった。また、学生による授業評価アンケートでは、「この授業はよく理解できましたか」という問いに対する点数は「AIデータサイエンス入門」で4点満点中2.88点、「情報処理」関連科目で4点満点中3.32点であり、学生は十分な学修成果を得られたものと考えている。 情報教育委員会で授業評価アンケートおよび講義の成績に基づいて、受講者の学修成果の状況を判断し、結果の分析を行っている。今後もこの活動を続け、プログラムの継続的改善につなげる方針である。 | K8: =IF(E8="","入力してください","")
C9: 学生アンケート等を通じた学生の内容の理解度 | E9: 学期末の授業評価アンケートのほか、適宜レポート課題または授業アンケートを実施し、受講者の理解度を確認している。また、この結果に応じて授業内容を随時見直している。LMS上でこれらの情報を管理するとともに、学生の理解度に応じた授業資料や補足資料の提供を行っている。 学期末の授業評価アンケートは、FD委員会で取りまとめ、その結果を各教員にフィードバックする。各教員はその結果をもとに授業改善計画を作成することにより、繰り返し授業の改善・向上に努めている。 | K9: =IF(E9="","入力してください","")
C10: 学生アンケート等を通じた後輩等他の学生への推奨度 | E10: 履修者に対して授業評価アンケートを実施しており、授業全体の満足度、説明のわかりやすさ、教材のわかりやすさ、授業が役に立ったかなどを調査し、その結果を公表することで、後輩等他の学生への推奨度が向上するように改善を行っている。分析結果については各教員にフィードバックを行い、次学期以降の授業に活用している。 | K10: =IF(E10="","入力してください","")
C11: 全学的な履修者数、履修率向上に向けた計画の達成・進捗状況 | E11: 既に必修である「情報処理」関連の科目に加えて、令和5年度に「AIデータサイエンス入門」を全学で必修化する計画である。これを達成するため、学修環境のオンデマンド化、BYOD演習環境等のインフラ整備や、新たな教員の配置等を実施中である。 学生の興味を引くように、学生が将来使用するような数理・AI・データサイエンスの利活用および学部に応じて各専門分野に関連した内容の授業を展開する予定である。 | K11: =IF(E11="","入力してください","")
B12: 学外からの視点
C13: 教育プログラム修了者の進路、活躍状況、企業等の評価 | E13: 同窓会を管轄する振興会という組織を通じて、学部あるいはキャリアセンターが本学の卒業生の進路状況を継続して把握している。本教育プログラムを修了した卒業生はまだいないが、本教育プログラムを修了した卒業生についても卒業後の状況調査や就職先企業・団体への調査を行い、活躍状況や企業評価を把握する計画である。 | K13: =IF(E13="","入力してください","")
C14: 産業界からの視点を含めた教育プログラム内容・手法等への意見 | E14: IT企業の現役の役員や研究員などを情報教育委員会に外部評価委員として年に2回招聘し本教育プログラムを評価して頂き、その内容をもとに授業内容の見直しを実施する計画である。 | K14: =IF(E14="","入力してください","")
B15: 数理・データサイエンス・ＡＩを「学ぶ楽しさ」「学ぶことの意義」を理解させること | E15: 社会の身近なサービスが数理・AI・データサイエンスによって実現されていることを学生に気づかせるとともに、学生の興味関心を引くような授業内容にする工夫をしている。また、授業において各学部の専門領域に関連するデータを題材にしてデータ分析を行うことにより、それぞれの領域にデータサイエンスが深く関わっていることや、卒業後の進路にも役立つものであることを理解させる。 | K15: =IF(E15="","入力してください","")
B16: 内容・水準を維持・向上しつつ、より「分かりやすい」授業とすること | E16: 授業評価アンケートおよび課題レポートの内容から受講者の理解度を確認し、FD委員会にて分析を行い、その結果を情報教育委員会にて報告している。更に、情報教育委員会では、報告内容をもとに授業内容の見直しおよび改善を行っている。 今後、学習環境のオンデマンド化を推進していく上で、対面での授業に比べて水準を落とすことのないように授業内容を十分検討するとともに、学生が繰り返し復習することができ、容易に教員に質問することができる環境を構築するべく検討している。 | K16: =IF(E16="","入力してください","")
A18: ②自己点検・評価体制における意見等を公表しているアドレス | G18: https://www.yamato-u.ac.jp/research/educational_features/mathematics_ai_data/ | K18: =IF(G18="","入力してください","")

Sheet (作業用)
B4: 1 | C4: 教育学部・保健医療学部 | D4: 情報処理
B5: 2 | C5: 政治経済学部 | D5: 情報処理Ⅰ
B6: 3 | C6: 理工学部 | D6: 情報処理入門
B7: 4 | C7: 社会学部 | D7: コンピュータ入門
