Workbook

Sheet 様式１　大学等概要
M1: 様式１
A2: 数理・データサイエンス・AI教育プログラム認定制度（リテラシーレベル） 申請様式
A4: ① | B4: 学校名 | C4: 福井工業高等専門学校 | O4: =IF(C4="","入力してください","")
A6: ② | B6: 大学等の設置者 | D6: 独立行政法人国立高等専門学校機構 | I6: ③ | J6: 設置形態 | K6: 高等専門学校 | O6: =IF(D6="","入力してください","")
A8: ④ | B8: 所在地 | C8: 福井県鯖江市下司町 | O8: =IF(C8="","入力してください","")
A10: ⑤ | B10: 申請するプログラム名称 | E10: 数理・データサイエンス・AI教育プログラム | O10: =IF(E10="","入力してください","")
A12: ⑥ | B12: プログラムの開設年度 | E12: 令和元 | G12: 年度 | H12: ⑦応用基礎レベルの申請の有無 | N12: 無 | O12: =IF(E12="","入力してください","")
A14: ⑧ | B14: 教員数 | C14: （常勤） | E14: 75 | G14: 人 | I14: （非常勤） | K14: 50 | N14: 人 | O14: =IF(OR(E14="",K14=""),"入力してください","")
A16: ⑨ | B16: プログラムの授業を教えている教員数 | K16: 43 | N16: 人 | O16: =IF(K16="","入力してください","")
A18: ⑩ | B18: 全学部・学科の入学定員 | E18: 200 | G18: 人 | O18: =IF(E18="","入力してください","")
A20: ⑪ | B20: 全学部・学科の学生数（学年別） | H20: 総数 | J20: 998 | M20: 人 | O20: =IF(J20="","入力してください","")
B22: １年次 | C22: 210 | E22: 人 | G22: ２年次 | I22: 204 | K22: 人
B24: ３年次 | C24: 201 | E24: 人 | G24: ４年次 | I24: 202 | K24: 人
B26: ５年次 | C26: 181 | E26: 人 | G26: ６年次 | K26: 人
A28: ⑫ | B28: プログラムの運営責任者
B29: （責任者名） | D29: 田村隆弘 | G29: （役職名） | J29: 校長 | O29: =IF(OR(D29="",J29=""),"入力してください","")
A31: ⑬ | B31: プログラムを改善・進化させるための体制（委員会・組織等）
B32: 教務委員会 | O32: =IF(B32="","入力してください","")
B34: （責任者名） | D34: 藤田克志 | G34: （役職名） | J34: 教務主事 | O34: =IF(OR(D34="",J34=""),"入力してください","")
A36: ⑭ | B36: プログラムの自己点検・評価を行う体制（委員会・組織等）
B37: 創造教育開発センター | O37: =IF(B37="","入力してください","")
B39: （責任者名） | D39: 長水壽寛 | G39: （役職名） | J39: 創造教育開発センター長 | O39: =IF(OR(D39="",J39=""),"入力してください","")
A41: ⑮ | B41: 申請する認定プログラム | F41: 認定教育プログラム | O41: =IF(F41="","入力してください","")
A43: 連絡先
B44: 所属部署名 | C44: 学生課教務係 | I44: 担当者名 | K44: 前川直紀 | O44: =IF(OR(C44="",K44=""),"入力してください","")
B45: E-mail | C45: kyomu@fukui-nct.ac.jp | I45: 電話番号 | K45: 0778-62-8209 | O45: =IF(OR(C45="",K45=""),"入力してください","")

Sheet 様式２-1　プログラムを構成する授業科目（M）
W1: 様式２－１
A2: プログラムを構成する授業科目について
A4: ①具体的な修了要件 | H4: ②教育プログラムの修了要件 | O4: 学部・学科によって、修了要件は相違する
B6: 機械工学科における本教育プログラムの修了要件は，専門基礎Ⅱ（1年前期），プロジェクト演習（4年前期），機械工学実験Ⅰ（4年後期），機械工学実験Ⅱ（5年前期）の単位を修得することである．また，数理統計学（3年），C言語基礎（2年後期）を受講し，単位を修得することで，数理・データサイエンス・AI（リテラシーレベル）モデルカリキュラムの「選択」に相当する内容を学修できる．
A13: ③現在進行中の社会変化（第４次産業革命、Society 5.0、データ駆動型社会等）に深く寄与しているものであり、それが自らの生活と密接に結びついている」の内容を含む授業科目
B15: 授業科目 | G15: 単位数 | H15: 必修 | I15: 開講状況 | L15: 1-1 | M15: 1-6 | N15: 授業科目 | T15: 単位数 | U15: 必修 | V15: 開講状況 | Y15: 1-1 | Z15: 1-6
B16: 専門基礎Ⅱ（機械工学科） | G16: 2 | H16: ○ | I16: 一部開講 | L16: ○ | M16: ○
B17: プロジェクト演習 | G17: 1 | H17: ○ | I17: 全学開講 | L17: ○ | M17: ○
A24: ④「社会で活用されているデータ」や「データの活用領域」は非常に広範囲であって、日常生活や社会の課題を解決する有用なツールになり得るもの」の内容を含む授業科目
B26: 授業科目 | G26: 単位数 | H26: 必修 | I26: 開講状況 | L26: 1-2 | M26: 1-3 | N26: 授業科目 | T26: 単位数 | U26: 必修 | V26: 開講状況 | Y26: 1-2 | Z26: 1-3
B27: 専門基礎Ⅱ（機械工学科） | G27: 2 | H27: ○ | I27: 一部開講 | L27: ○ | M27: ○
B28: プロジェクト演習 | G28: 1 | H28: ○ | I28: 全学開講 | L28: ○ | M28: ○
A35: ⑤「様々なデータ利活用の現場におけるデータ利活用事例が示され、様々な適用領域（流通、製造、金融、サービス、インフラ、公共、ヘルスケア等）の知見と組み合わせることで価値を創出するもの」の内容を含む授業科目
B37: 授業科目 | G37: 単位数 | H37: 必修 | I37: 開講状況 | L37: 1-4 | M37: 1-5 | N37: 授業科目 | T37: 単位数 | U37: 必修 | V37: 開講状況 | Y37: 1-4 | Z37: 1-5
B38: 専門基礎Ⅱ（機械工学科） | G38: 2 | H38: ○ | I38: 一部開講 | L38: ○ | M38: ○
B39: プロジェクト演習 | G39: 1 | H39: ○ | I39: 全学開講 | L39: ○ | M39: ○
A46: ⑥「活用に当たっての様々な留意事項（ELSI、個人情報、データ倫理、ＡＩ社会原則等）を考慮し、情報セキュリティや情報漏洩等、データを守る上での留意事項への理解をする」の内容を含む授業科目
B48: 授業科目 | G48: 単位数 | H48: 必修 | I48: 開講状況 | L48: 3-1 | M48: 3-2 | N48: 授業科目 | T48: 単位数 | U48: 必修 | V48: 開講状況 | Y48: 3-1 | Z48: 3-2
B49: 専門基礎Ⅱ（機械工学科） | G49: 2 | H49: ○ | I49: 一部開講 | L49: ○ | M49: ○
B50: プロジェクト演習 | G50: 1 | H50: ○ | I50: 全学開講 | L50: ○ | M50: ○
A57: ⑦「実データ・実課題（学術データ等を含む）を用いた演習など、社会での実例を題材として、「データを読む、説明する、扱う」といった数理・データサイエンス・ＡＩの基本的な活用法に関するもの」の内容を含む授業科目
B59: 授業科目 | F59: 単位数 | G59: 必修 | H59: 開講状況 | K59: 2-1 | L59: 2-2 | M59: 2-3 | N59: 授業科目 | S59: 単位数 | T59: 必修 | U59: 開講状況 | X59: 2-1 | Y59: 2-2 | Z59: 2-3
B60: 機械工学実験Ⅰ | F60: 2 | G60: ○ | H60: 一部開講 | K60: ○ | L60: ○ | M60: ○
B61: 機械工学実験Ⅱ | F61: 2 | G61: ○ | H61: 一部開講 | K61: ○ | L61: ○ | M61: ○
A68: ⑧選択「４．オプション」の内容を含む授業科目
B69: 授業科目 | G69: 選択項目 | N69: 授業科目 | T69: 選択項目
B70: 数理統計学（3年） | G70: 4-1統計および数理基礎
B71: C言語基礎（2年後期） | G71: 4‐2アルゴリズム基礎
B72: C言語基礎（2年後期） | G72: 4‐3データ構造とプログラミング基礎
A78: ⑨プログラムを構成する授業の内容
B79: 授業に含まれている内容・要素 | D79: 講義内容
B80: （１）現在進行中の社会変化（第４次産業革命、Society 5.0、データ駆動型社会等）に深く寄与しているものであり、それが自らの生活と密接に結びついている | C80: 1-1 | D80: ・ビッグデータ、IoT、AI、ロボット、第4次産業革命、Society 5.0、データ駆動型社会 ： 「専門基礎Ⅱ（1年）」（1, 3週） ・複数技術を組み合わせたAIサービス： 「プロジェクト演習」（1～15週）。
C81: 1-6 | D81: ・AI等を活用した新しいビジネスモデル、： 「専門基礎Ⅱ（1年）」（1, 3週） ・AI等を活用した新しいビジネスモデル： 「プロジェクト演習」(1～15週)
B82: （２）「社会で活用されているデータ」や「データの活用領域」は非常に広範囲であって、日常生活や社会の課題を解決する有用なツールになり得るもの | C82: 1-2 | D82: ・機械の稼働ログデータ、構造化データ： 「専門基礎Ⅱ（1年）」（3, 7, 9～15週） ・データのオープン化： 「プロジェクト演習」（1～15週）
C83: 1-3 | D83: ・データ・AI活用領域の広がり，研究開発： 「専門基礎Ⅱ（1年）」（6, 7週） ・研究開発、調達、製造、物流、販売、マーケティング、サービス： 「プロジェクト演習」(1～15週)
B84: （３）様々なデータ利活用の現場におけるデータ利活用事例が示され、様々な適用領域（流通、製造、金融、サービス、インフラ、公共、ヘルスケア等）の知見と組み合わせることで価値を創出するもの | C84: 1-4 | D84: ・シミュレーション，関係性の可視化、軌跡の可視化、自動化技術： 「専門基礎Ⅱ（1年）」（3, 7週） ・認識技術、ルールベース、自動化技術： 「プロジェクト演習」(1～15週)
C85: 1-5 | D85: ・製造におけるデータ、AI利用事例紹介： 「専門基礎Ⅱ（1年）」（3, 7週） ・流通、製造、金融、サービス、インフラ、公共、ヘルスケア等におけるデータ・AI利活用事例紹介： 「プロジェクト演習」(1週)
B86: （４）活用に当たっての様々な留意事項（ELSI、個人情報、データ倫理、ＡＩ社会原則等）を考慮し、情報セキュリティや情報漏洩等、データを守る上での留意事項への理解をする | C86: 3-1 | D86: ・個人情報保護、データのねつ造、改ざん、盗用、プライバシー保護 ： 「専門基礎Ⅱ（1年）」（4, 5週） ・データ・AIを利活用する上で知っておくべきこと： 「プロジェクト演習」(1～15週)
C87: 3-2 | D87: ・情報セキュリティ、暗号化、パスワード、情報漏洩等によるセキュリティ事故の事例紹介： 「専門基礎Ⅱ（1年）」（4, 5週） プロジェクト演習（4年前期）については、項目（１）と同様である。
B88: （５）実データ・実課題（学術データ等を含む）を用いた演習など、社会での実例を題材として、「データを読む、説明する、扱う」といった数理・データサイエンス・ＡＩの基本的な活用法に関するもの | C88: 2-1 | D88: ・データの種類、分布、ばらつき、誤差の扱い、統計情報の正しい理解： 「機械工学実験Ⅰ」（3, 6, 9, 12, 15週）、「機械工学実験Ⅱ」（3, 6, 9, 12, 15週）
...

Sheet 様式２-2　プログラムを構成する授業科目（E）
W1: 様式２－２
A2: プログラムを構成する授業科目について
A4: ①具体的な修了要件 | H4: ②教育プログラムの修了要件 | O4: 学部・学科によって、修了要件は相違する
B6: 電気電子工学科における本教育プログラムの修了要件は，専門基礎Ⅰ（1年），プロジェクト演習（4年前期），電気電子工学実験Ⅰ（2年後期），電気電子工学実験Ⅱ（3年前期）の単位を修得することである．また，数理統計学（3年），情報処理Ⅰ（2年前期），情報処理Ⅱ（3年前期）を受講し，単位を修得することで，数理・データサイエンス・AI（リテラシーレベル）モデルカリキュラムの「選択」に相当する内容を学修できる．
A13: ③現在進行中の社会変化（第４次産業革命、Society 5.0、データ駆動型社会等）に深く寄与しているものであり、それが自らの生活と密接に結びついている」の内容を含む授業科目
B15: 授業科目 | G15: 単位数 | H15: 必修 | I15: 開講状況 | L15: 1-1 | M15: 1-6 | N15: 授業科目 | T15: 単位数 | U15: 必修 | V15: 開講状況 | Y15: 1-1 | Z15: 1-6
B16: 専門基礎Ⅰ（電気電子工学科） | G16: 2 | H16: ○ | I16: 一部開講 | L16: ○ | M16: ○
B17: プロジェクト演習 | G17: 1 | H17: ○ | I17: 全学開講 | L17: ○ | M17: ○
A24: ④「社会で活用されているデータ」や「データの活用領域」は非常に広範囲であって、日常生活や社会の課題を解決する有用なツールになり得るもの」の内容を含む授業科目
B26: 授業科目 | G26: 単位数 | H26: 必修 | I26: 開講状況 | L26: 1-2 | M26: 1-3 | N26: 授業科目 | T26: 単位数 | U26: 必修 | V26: 開講状況 | Y26: 1-2 | Z26: 1-3
B27: 専門基礎Ⅰ（電気電子工学科） | G27: 2 | H27: ○ | I27: 一部開講 | L27: ○ | M27: ○
B28: プロジェクト演習 | G28: 1 | H28: ○ | I28: 全学開講 | L28: ○ | M28: ○
A35: ⑤「様々なデータ利活用の現場におけるデータ利活用事例が示され、様々な適用領域（流通、製造、金融、サービス、インフラ、公共、ヘルスケア等）の知見と組み合わせることで価値を創出するもの」の内容を含む授業科目
B37: 授業科目 | G37: 単位数 | H37: 必修 | I37: 開講状況 | L37: 1-4 | M37: 1-5 | N37: 授業科目 | T37: 単位数 | U37: 必修 | V37: 開講状況 | Y37: 1-4 | Z37: 1-5
B38: 専門基礎Ⅰ（電気電子工学科） | G38: 2 | H38: ○ | I38: 一部開講 | L38: ○ | M38: ○
B39: プロジェクト演習 | G39: 1 | H39: ○ | I39: 全学開講 | L39: ○ | M39: ○
A46: ⑥「活用に当たっての様々な留意事項（ELSI、個人情報、データ倫理、ＡＩ社会原則等）を考慮し、情報セキュリティや情報漏洩等、データを守る上での留意事項への理解をする」の内容を含む授業科目
B48: 授業科目 | G48: 単位数 | H48: 必修 | I48: 開講状況 | L48: 3-1 | M48: 3-2 | N48: 授業科目 | T48: 単位数 | U48: 必修 | V48: 開講状況 | Y48: 3-1 | Z48: 3-2
B49: 専門基礎Ⅰ（電気電子工学科） | G49: 2 | H49: ○ | I49: 一部開講 | L49: ○ | M49: ○
B50: プロジェクト演習 | G50: 1 | H50: ○ | I50: 全学開講 | L50: ○ | M50: ○
A57: ⑦「実データ・実課題（学術データ等を含む）を用いた演習など、社会での実例を題材として、「データを読む、説明する、扱う」といった数理・データサイエンス・ＡＩの基本的な活用法に関するもの」の内容を含む授業科目
B59: 授業科目 | F59: 単位数 | G59: 必修 | H59: 開講状況 | K59: 2-1 | L59: 2-2 | M59: 2-3 | N59: 授業科目 | S59: 単位数 | T59: 必修 | U59: 開講状況 | X59: 2-1 | Y59: 2-2 | Z59: 2-3
B60: 電気電子工学実験Ⅰ | F60: 2 | G60: ○ | H60: 一部開講 | K60: ○ | L60: ○ | M60: ○
B61: 電気電子工学実験Ⅱ | F61: 2 | G61: ○ | H61: 一部開講 | K61: ○ | L61: ○ | M61: ○
A68: ⑧選択「４．オプション」の内容を含む授業科目
B69: 授業科目 | G69: 選択項目 | N69: 授業科目 | T69: 選択項目
B70: 数理統計学（3年） | G70: 4-1統計および数理基礎
B71: 情報処理Ⅰ（2年前期） | G71: 4‐2アルゴリズム基礎
B72: 情報処理Ⅱ（3年前期） | G72: 4‐2アルゴリズム基礎
B73: 情報処理Ⅰ（2年前期） | G73: 4‐3データ構造とプログラミング基礎
B74: 情報処理Ⅱ（3年前期） | G74: 4‐3データ構造とプログラミング基礎
A78: ⑨プログラムを構成する授業の内容
B79: 授業に含まれている内容・要素 | D79: 講義内容
B80: （１）現在進行中の社会変化（第４次産業革命、Society 5.0、データ駆動型社会等）に深く寄与しているものであり、それが自らの生活と密接に結びついている | C80: 1-1 | D80: ・計算機の処理性能の向上、 Society 5.0、データ駆動型社会 ： 「専門基礎Ⅰ（1年）」（1～3, 7～9週） ・複数技術を組み合わせたAIサービス： 「プロジェクト演習」（1～15週）
C81: 1-6 | D81: ・AI等を活用した新しいビジネスモデル、： 「専門基礎Ⅰ（1年）」（7～12週） ・AI等を活用した新しいビジネスモデル： 「プロジェクト演習」(1～15週)
B82: （２）「社会で活用されているデータ」や「データの活用領域」は非常に広範囲であって、日常生活や社会の課題を解決する有用なツールになり得るもの | C82: 1-2 | D82: ・調査データ、実験データ、1次データ、2次データ： 「専門基礎Ⅰ（1年）」（7～12週） ・データのオープン化： 「プロジェクト演習」（1～15週）
C83: 1-3 | D83: ・データ・AI活用領域の広がり： 「専門基礎Ⅰ（1年）」（1～3, 7～9週） ・研究開発、調達、製造、物流、販売、マーケティング、サービス： 「プロジェクト演習」(1～15週)
B84: （３）様々なデータ利活用の現場におけるデータ利活用事例が示され、様々な適用領域（流通、製造、金融、サービス、インフラ、公共、ヘルスケア等）の知見と組み合わせることで価値を創出するもの | C84: 1-4 | D84: ・データ可視化：複合グラフ、2軸グラフ、多次元の可視化： 「専門基礎Ⅰ（1年）」（7～12週） ・認識技術、ルールベース、自動化技術： 「プロジェクト演習」(1～15週)
C85: 1-5 | D85: ・データサイエンスのサイクル： 「専門基礎Ⅰ（1年）」（7～9週） ・流通、製造、金融、サービス、インフラ、公共、ヘルスケア等におけるデータ・AI利活用事例紹介： 「プロジェクト演習」(1週)
B86: （４）活用に当たっての様々な留意事項（ELSI、個人情報、データ倫理、ＡＩ社会原則等）を考慮し、情報セキュリティや情報漏洩等、データを守る上での留意事項への理解をする | C86: 3-1 | D86: ・個人情報保護、データ倫理 ： 「専門基礎Ⅰ（1年）」（1～3週） ・データ・AIを利活用する上で知っておくべきこと： 「プロジェクト演習」(1～15週)
...

Sheet 様式２-3　プログラムを構成する授業科目（EI）
W1: 様式２－３
A2: プログラムを構成する授業科目について
A4: ①具体的な修了要件 | H4: ②教育プログラムの修了要件 | O4: 学部・学科によって、修了要件は相違する
B6: 電子情報工学科における本教育プログラムの修了要件は，専門基礎Ⅰ（1年），専門基礎Ⅱ（1年前期），プロジェクト演習（4年前期），電子情報工学実験Ⅰ（2年）を受講し，単位を修得することである。また，数理統計学（3年），プログラミング基礎(2年)を受講し，単位を修得することで，数理・データサイエンス・AI（リテラシーレベル）モデルカリキュラムの「選択」に相当する内容を学修できる．
A13: ③現在進行中の社会変化（第４次産業革命、Society 5.0、データ駆動型社会等）に深く寄与しているものであり、それが自らの生活と密接に結びついている」の内容を含む授業科目
B15: 授業科目 | G15: 単位数 | H15: 必修 | I15: 開講状況 | L15: 1-1 | M15: 1-6 | N15: 授業科目 | T15: 単位数 | U15: 必修 | V15: 開講状況 | Y15: 1-1 | Z15: 1-6
B16: 専門基礎Ⅰ（電子情報工学科） | G16: 2 | H16: ○ | I16: 一部開講 | L16: ○ | M16: ○
B17: プロジェクト演習 | G17: 1 | H17: ○ | I17: 全学開講 | L17: ○ | M17: ○
A24: ④「社会で活用されているデータ」や「データの活用領域」は非常に広範囲であって、日常生活や社会の課題を解決する有用なツールになり得るもの」の内容を含む授業科目
B26: 授業科目 | G26: 単位数 | H26: 必修 | I26: 開講状況 | L26: 1-2 | M26: 1-3 | N26: 授業科目 | T26: 単位数 | U26: 必修 | V26: 開講状況 | Y26: 1-2 | Z26: 1-3
B27: 専門基礎Ⅰ（電子情報工学科） | G27: 2 | H27: ○ | I27: 一部開講 | L27: ○ | M27: ○
B28: プロジェクト演習 | G28: 1 | H28: ○ | I28: 全学開講 | L28: ○ | M28: ○
A35: ⑤「様々なデータ利活用の現場におけるデータ利活用事例が示され、様々な適用領域（流通、製造、金融、サービス、インフラ、公共、ヘルスケア等）の知見と組み合わせることで価値を創出するもの」の内容を含む授業科目
B37: 授業科目 | G37: 単位数 | H37: 必修 | I37: 開講状況 | L37: 1-4 | M37: 1-5 | N37: 授業科目 | T37: 単位数 | U37: 必修 | V37: 開講状況 | Y37: 1-4 | Z37: 1-5
B38: 専門基礎Ⅱ（電子情報工学科） | G38: 2 | H38: ○ | I38: 一部開講 | L38: ○
B39: プロジェクト演習 | G39: 1 | H39: ○ | I39: 全学開講 | L39: ○ | M39: ○
A46: ⑥「活用に当たっての様々な留意事項（ELSI、個人情報、データ倫理、ＡＩ社会原則等）を考慮し、情報セキュリティや情報漏洩等、データを守る上での留意事項への理解をする」の内容を含む授業科目
B48: 授業科目 | G48: 単位数 | H48: 必修 | I48: 開講状況 | L48: 3-1 | M48: 3-2 | N48: 授業科目 | T48: 単位数 | U48: 必修 | V48: 開講状況 | Y48: 3-1 | Z48: 3-2
B49: 専門基礎Ⅰ（電子情報工学科） | G49: 2 | H49: ○ | I49: 一部開講 | M49: ○
B50: プロジェクト演習 | G50: 1 | H50: ○ | I50: 全学開講 | L50: ○
A57: ⑦「実データ・実課題（学術データ等を含む）を用いた演習など、社会での実例を題材として、「データを読む、説明する、扱う」といった数理・データサイエンス・ＡＩの基本的な活用法に関するもの」の内容を含む授業科目
B59: 授業科目 | F59: 単位数 | G59: 必修 | H59: 開講状況 | K59: 2-1 | L59: 2-2 | M59: 2-3 | N59: 授業科目 | S59: 単位数 | T59: 必修 | U59: 開講状況 | X59: 2-1 | Y59: 2-2 | Z59: 2-3
B60: 電子情報工学実験Ⅰ | F60: 2 | G60: ○ | H60: 一部開講 | K60: ○ | L60: ○ | M60: ○
A68: ⑧選択「４．オプション」の内容を含む授業科目
B69: 授業科目 | G69: 選択項目 | N69: 授業科目 | T69: 選択項目
B70: 数理統計学（3年） | G70: 4-1統計および数理基礎
B71: プログラミング基礎（2年） | G71: 4‐2アルゴリズム基礎
B72: プログラミング基礎（2年） | G72: 4‐3データ構造とプログラミング基礎
A78: ⑨プログラムを構成する授業の内容
B79: 授業に含まれている内容・要素 | D79: 講義内容
B80: （１）現在進行中の社会変化（第４次産業革命、Society 5.0、データ駆動型社会等）に深く寄与しているものであり、それが自らの生活と密接に結びついている | C80: 1-1 | D80: ・計算機の処理性能の向上「専門基礎Ⅰ」(前期2,3週) ・複数技術を組み合わせたAIサービス「プロジェクト演習」（1～15週）
C81: 1-6 | D81: ・AI等を活用した新しいビジネスモデル「プロジェクト演習」(1～15週) ・AI最新技術の活用例「専門基礎Ⅰ」(前期3週)
B82: （２）「社会で活用されているデータ」や「データの活用領域」は非常に広範囲であって、日常生活や社会の課題を解決する有用なツールになり得るもの | C82: 1-2 | D82: ・構造化データ、非構造化データ「専門基礎Ⅰ」(前期1週) ・データのオープン化「プロジェクト演習」（1～15週）
C83: 1-3 | D83: ・データ・AI活用領域の広がり「専門基礎Ⅰ」(前期2～3週) ・研究開発、調達、製造、物流、販売、マーケティング、サービス「プロジェクト演習」(1～15週)
B84: （３）様々なデータ利活用の現場におけるデータ利活用事例が示され、様々な適用領域（流通、製造、金融、サービス、インフラ、公共、ヘルスケア等）の知見と組み合わせることで価値を創出するもの | C84: 1-4 | D84: ・データ可視化：複合グラフ、２軸グラフ「専門基礎Ⅱ」(前期5～7週) ・認識技術、ルールベース、自動化技術「プロジェクト演習」(1～15週)
C85: 1-5 | D85: ・流通、製造、金融、サービス、インフラ、公共、ヘルスケア等におけるデータ・AI利活用事例紹介「プロジェクト演習」(1週)
B86: （４）活用に当たっての様々な留意事項（ELSI、個人情報、データ倫理、ＡＩ社会原則等）を考慮し、情報セキュリティや情報漏洩等、データを守る上での留意事項への理解をする | C86: 3-1 | D86: ・データ・AIを利活用する上で知っておくべきこと「プロジェクト演習」(1～15週)
C87: 3-2 | D87: ・データを守る上で知っておくべきこと「専門基礎Ⅰ」(1週)
B88: （５）実データ・実課題（学術データ等を含む）を用いた演習など、社会での実例を題材として、「データを読む、説明する、扱う」といった数理・データサイエンス・ＡＩの基本的な活用法に関するもの | C88: 2-1 | D88: ・データのばらつき、観測データに含まれる誤差の扱い「電子情報工学実験Ⅰ」（2～4週）
C89: 2-2 | D89: ・データ表現、不適切なグラフ表現、優れた可視化事例の紹介「電子情報工学実験Ⅰ」（2～4週）
...

Sheet 様式２-4　プログラムを構成する授業科目（C）
W1: 様式２－４
A2: プログラムを構成する授業科目について
A4: ①具体的な修了要件 | H4: ②教育プログラムの修了要件 | O4: 学部・学科によって、修了要件は相違する
B6: 物質工学科における本教育プログラムの修了要件は，専門基礎Ⅲ（1年前期），プロジェクト演習（4年前期），物質工学実験Ⅰ（2年），物質工学実験Ⅱ（3年前期）の単位を修得することである．加えて，4年生における実験については，生物工学コースの学生は生物工学実験Ⅰ（4年）を，材料工学コースの学生は材料工学実験Ⅰ（4年）を受講し，単位を修得する必要がある．また，数理統計学（3年），情報化学Ⅱ（4年）を受講し，単位を修得することで，数理・データサイエンス・AI（リテラシーレベル）モデルカリキュラムの「選択」に相当する内容を学修できる．
A13: ③現在進行中の社会変化（第４次産業革命、Society 5.0、データ駆動型社会等）に深く寄与しているものであり、それが自らの生活と密接に結びついている」の内容を含む授業科目
B15: 授業科目 | G15: 単位数 | H15: 必修 | I15: 開講状況 | L15: 1-1 | M15: 1-6 | N15: 授業科目 | T15: 単位数 | U15: 必修 | V15: 開講状況 | Y15: 1-1 | Z15: 1-6
B16: 専門基礎Ⅲ（物質工学科） | G16: 2 | H16: ○ | I16: 一部開講 | L16: ○ | M16: ○
B17: プロジェクト演習 | G17: 1 | H17: ○ | I17: 全学開講 | L17: ○ | M17: ○
A24: ④「社会で活用されているデータ」や「データの活用領域」は非常に広範囲であって、日常生活や社会の課題を解決する有用なツールになり得るもの」の内容を含む授業科目
B26: 授業科目 | G26: 単位数 | H26: 必修 | I26: 開講状況 | L26: 1-2 | M26: 1-3 | N26: 授業科目 | T26: 単位数 | U26: 必修 | V26: 開講状況 | Y26: 1-2 | Z26: 1-3
B27: 専門基礎Ⅲ（物質工学科） | G27: 2 | H27: ○ | I27: 一部開講 | L27: ○ | M27: ○
B28: プロジェクト演習 | G28: 1 | H28: ○ | I28: 全学開講 | L28: ○ | M28: ○
A35: ⑤「様々なデータ利活用の現場におけるデータ利活用事例が示され、様々な適用領域（流通、製造、金融、サービス、インフラ、公共、ヘルスケア等）の知見と組み合わせることで価値を創出するもの」の内容を含む授業科目
B37: 授業科目 | G37: 単位数 | H37: 必修 | I37: 開講状況 | L37: 1-4 | M37: 1-5 | N37: 授業科目 | T37: 単位数 | U37: 必修 | V37: 開講状況 | Y37: 1-4 | Z37: 1-5
B38: 専門基礎Ⅲ（物質工学科） | G38: 2 | H38: ○ | I38: 一部開講 | L38: ○ | M38: ○
B39: プロジェクト演習 | G39: 1 | H39: ○ | I39: 全学開講 | L39: ○ | M39: ○
A46: ⑥「活用に当たっての様々な留意事項（ELSI、個人情報、データ倫理、ＡＩ社会原則等）を考慮し、情報セキュリティや情報漏洩等、データを守る上での留意事項への理解をする」の内容を含む授業科目
B48: 授業科目 | G48: 単位数 | H48: 必修 | I48: 開講状況 | L48: 3-1 | M48: 3-2 | N48: 授業科目 | T48: 単位数 | U48: 必修 | V48: 開講状況 | Y48: 3-1 | Z48: 3-2
B49: 専門基礎Ⅲ（物質工学科） | G49: 2 | H49: ○ | I49: 一部開講 | L49: ○ | M49: ○
B50: プロジェクト演習 | G50: 1 | H50: ○ | I50: 全学開講 | L50: ○ | M50: ○
A57: ⑦「実データ・実課題（学術データ等を含む）を用いた演習など、社会での実例を題材として、「データを読む、説明する、扱う」といった数理・データサイエンス・ＡＩの基本的な活用法に関するもの」の内容を含む授業科目
B59: 授業科目 | F59: 単位数 | G59: 必修 | H59: 開講状況 | K59: 2-1 | L59: 2-2 | M59: 2-3 | N59: 授業科目 | S59: 単位数 | T59: 必修 | U59: 開講状況 | X59: 2-1 | Y59: 2-2 | Z59: 2-3
B60: 物質工学実験Ⅰ | F60: 5 | G60: ○ | H60: 一部開講 | K60: ○ | L60: ○ | M60: ○
B61: 物質工学実験Ⅱ | F61: 4 | G61: ○ | H61: 一部開講 | K61: ○ | L61: ○ | M61: ○
B62: 生物工学実験Ⅰ | F62: 4 | G62: ○ | H62: 一部開講 | K62: ○ | L62: ○ | M62: ○
B63: 材料工学実験Ⅰ | F63: 4 | G63: ○ | H63: 一部開講 | K63: ○ | L63: ○ | M63: ○
A68: ⑧選択「４．オプション」の内容を含む授業科目
B69: 授業科目 | G69: 選択項目 | N69: 授業科目 | T69: 選択項目
B70: 数理統計学（3年） | G70: 4-1統計および数理基礎
B71: 情報化学Ⅱ（4年通年） | G71: 4‐2アルゴリズム基礎
B72: 情報化学Ⅱ（4年通年） | G72: 4‐3データ構造とプログラミング基礎
A78: ⑨プログラムを構成する授業の内容
B79: 授業に含まれている内容・要素 | D79: 講義内容
B80: （１）現在進行中の社会変化（第４次産業革命、Society 5.0、データ駆動型社会等）に深く寄与しているものであり、それが自らの生活と密接に結びついている | C80: 1-1 | D80: ・計算機の処理性能の向上、 Society 5.0、データ駆動型社会 ： 「専門基礎Ⅲ（1年）」（1～3, 5, 7～10週） ・複数技術を組み合わせたAIサービス： 「プロジェクト演習」（1～15週）
C81: 1-6 | D81: ・AI等を活用した新しいビジネスモデル、： 「専門基礎Ⅲ（1年）」（9～11, 14週） ・AI等を活用した新しいビジネスモデル： 「プロジェクト演習」(1～15週)
B82: （２）「社会で活用されているデータ」や「データの活用領域」は非常に広範囲であって、日常生活や社会の課題を解決する有用なツールになり得るもの | C82: 1-2 | D82: ・調査データ、実験データ、1次データ、2次データ、構造化データ、非構造化データ、データのオープン化： 「専門基礎Ⅲ（1年）」（前期4～11週） ・データのオープン化： 「プロジェクト演習」（1～15週）
C83: 1-3 | D83: ・データ・AI活用領域の広がり： 「専門基礎Ⅲ（1年）」（前期1～3, 7～11, 14週） ・研究開発、調達、製造、物流、販売、マーケティング、サービス： 「プロジェクト演習」(1～15週)
B84: （３）様々なデータ利活用の現場におけるデータ利活用事例が示され、様々な適用領域（流通、製造、金融、サービス、インフラ、公共、ヘルスケア等）の知見と組み合わせることで価値を創出するもの | C84: 1-4 | D84: ・データ可視化：複合グラフ、2軸グラフ、多次元の可視化： 「専門基礎Ⅲ（1年）」（後期4～7週） ・認識技術、ルールベース、自動化技術： 「プロジェクト演習」(1～15週)
C85: 1-5 | D85: ・データサイエンスのサイクル： 「専門基礎Ⅲ（1年）」（前期8～9週, 後期4～7週） ・流通、製造、金融、サービス、インフラ、公共、ヘルスケア等におけるデータ・AI利活用事例紹介： 「プロジェクト演習」(1週)
B86: （４）活用に当たっての様々な留意事項（ELSI、個人情報、データ倫理、ＡＩ社会原則等）を考慮し、情報セキュリティや情報漏洩等、データを守る上での留意事項への理解をする | C86: 3-1 | D86: ・個人情報保護、データ倫理 ： 「専門基礎Ⅲ（1年）」（前期1～3, 10～14週） ・データ・AIを利活用する上で知っておくべきこと： 「プロジェクト演習」(1～15週)
...

Sheet 様式２-5　プログラムを構成する授業科目（B）
W1: 様式２－５
A2: プログラムを構成する授業科目について
A4: ①具体的な修了要件 | H4: ②教育プログラムの修了要件 | O4: 学部・学科によって、修了要件は相違する
B6: 環境都市工学科における本教育プログラムの修了要件は，専門基礎Ⅲ（1年前期），プロジェクト演習（4年前期），環境都市工学実験実習Ⅰ（2年），環境都市工学実験実習Ⅱ（3年）の単位を修得することである．また，数理統計学（3年），プログラミング（2年後期）を受講し，単位を修得することで，数理・データサイエンス・AI（リテラシーレベル）モデルカリキュラムの「選択」に相当する内容を学修できる．
A13: ③現在進行中の社会変化（第４次産業革命、Society 5.0、データ駆動型社会等）に深く寄与しているものであり、それが自らの生活と密接に結びついている」の内容を含む授業科目
B15: 授業科目 | G15: 単位数 | H15: 必修 | I15: 開講状況 | L15: 1-1 | M15: 1-6 | N15: 授業科目 | T15: 単位数 | U15: 必修 | V15: 開講状況 | Y15: 1-1 | Z15: 1-6
B16: 専門基礎Ⅲ（環境都市工学科） | G16: 2 | H16: ○ | I16: 一部開講 | L16: ○ | M16: ○
B17: プロジェクト演習 | G17: 1 | H17: ○ | I17: 全学開講 | L17: ○ | M17: ○
A24: ④「社会で活用されているデータ」や「データの活用領域」は非常に広範囲であって、日常生活や社会の課題を解決する有用なツールになり得るもの」の内容を含む授業科目
B26: 授業科目 | G26: 単位数 | H26: 必修 | I26: 開講状況 | L26: 1-2 | M26: 1-3 | N26: 授業科目 | T26: 単位数 | U26: 必修 | V26: 開講状況 | Y26: 1-2 | Z26: 1-3
B27: 専門基礎Ⅲ（環境都市工学科） | G27: 2 | H27: ○ | I27: 一部開講 | L27: ○ | M27: ○
B28: プロジェクト演習 | G28: 1 | H28: ○ | I28: 全学開講 | L28: ○ | M28: ○
A35: ⑤「様々なデータ利活用の現場におけるデータ利活用事例が示され、様々な適用領域（流通、製造、金融、サービス、インフラ、公共、ヘルスケア等）の知見と組み合わせることで価値を創出するもの」の内容を含む授業科目
B37: 授業科目 | G37: 単位数 | H37: 必修 | I37: 開講状況 | L37: 1-4 | M37: 1-5 | N37: 授業科目 | T37: 単位数 | U37: 必修 | V37: 開講状況 | Y37: 1-4 | Z37: 1-5
B38: 専門基礎Ⅲ（環境都市工学科） | G38: 2 | H38: ○ | I38: 一部開講 | L38: ○
B39: プロジェクト演習 | G39: 1 | H39: ○ | I39: 全学開講 | L39: ○ | M39: ○
A46: ⑥「活用に当たっての様々な留意事項（ELSI、個人情報、データ倫理、ＡＩ社会原則等）を考慮し、情報セキュリティや情報漏洩等、データを守る上での留意事項への理解をする」の内容を含む授業科目
B48: 授業科目 | G48: 単位数 | H48: 必修 | I48: 開講状況 | L48: 3-1 | M48: 3-2 | N48: 授業科目 | T48: 単位数 | U48: 必修 | V48: 開講状況 | Y48: 3-1 | Z48: 3-2
B49: 専門基礎Ⅲ（環境都市工学科） | G49: 2 | H49: ○ | I49: 一部開講 | M49: ○
B50: プロジェクト演習 | G50: 1 | H50: ○ | I50: 全学開講 | L50: ○
A57: ⑦「実データ・実課題（学術データ等を含む）を用いた演習など、社会での実例を題材として、「データを読む、説明する、扱う」といった数理・データサイエンス・ＡＩの基本的な活用法に関するもの」の内容を含む授業科目
B59: 授業科目 | F59: 単位数 | G59: 必修 | H59: 開講状況 | K59: 2-1 | L59: 2-2 | M59: 2-3 | N59: 授業科目 | S59: 単位数 | T59: 必修 | U59: 開講状況 | X59: 2-1 | Y59: 2-2 | Z59: 2-3
B60: 環境都市工学実験実習Ⅰ | F60: 2 | G60: ○ | H60: 一部開講 | K60: ○ | L60: ○ | M60: ○
B61: 環境都市工学実験実習Ⅱ | F61: 2 | G61: ○ | H61: 一部開講 | M61: ○
A68: ⑧選択「４．オプション」の内容を含む授業科目
B69: 授業科目 | G69: 選択項目 | N69: 授業科目 | T69: 選択項目
B70: 数理統計学（3年） | G70: 4-1統計および数理基礎
B71: プログラミング（2年後期） | G71: 4‐2アルゴリズム基礎
B72: プログラミング（2年後期） | G72: 4‐3データ構造とプログラミング基礎
A78: ⑨プログラムを構成する授業の内容
B79: 授業に含まれている内容・要素 | D79: 講義内容
B80: （１）現在進行中の社会変化（第４次産業革命、Society 5.0、データ駆動型社会等）に深く寄与しているものであり、それが自らの生活と密接に結びついている | C80: 1-1 | D80: ・第4次産業革命、Society 5.0、データ駆動型社会 「専門基礎Ⅲ」(前期1～2週) ・複数技術を組み合わせたAIサービス「プロジェクト演習」（1～15週）
C81: 1-6 | D81: ・AI等を活用した新しいビジネスモデル「プロジェクト演習」(1～15週) ・AI最新技術の活用例「専門基礎Ⅲ」(前期3～4週)
B82: （２）「社会で活用されているデータ」や「データの活用領域」は非常に広範囲であって、日常生活や社会の課題を解決する有用なツールになり得るもの | C82: 1-2 | D82: ・データ作成（ビッグデータとアノテーション）「専門基礎Ⅲ」(前期5～6週) ・データのオープン化「プロジェクト演習」（1～15週）
C83: 1-3 | D83: ・データ・AI活用領域の広がり「専門基礎Ⅲ」(前期5～6週) ・研究開発、調達、製造、物流、販売、マーケティング、サービス「プロジェクト演習」(1～15週)
B84: （３）様々なデータ利活用の現場におけるデータ利活用事例が示され、様々な適用領域（流通、製造、金融、サービス、インフラ、公共、ヘルスケア等）の知見と組み合わせることで価値を創出するもの | C84: 1-4 | D84: ・データ可視化：複合グラフ、２軸グラフ「専門基礎Ⅲ」(前期10～12週) ・認識技術、ルールベース、自動化技術「プロジェクト演習」(1～15週)
C85: 1-5 | D85: ・流通、製造、金融、サービス、インフラ、公共、ヘルスケア等におけるデータ・AI利活用事例紹介「プロジェクト演習」(1週)
B86: （４）活用に当たっての様々な留意事項（ELSI、個人情報、データ倫理、ＡＩ社会原則等）を考慮し、情報セキュリティや情報漏洩等、データを守る上での留意事項への理解をする | C86: 3-1 | D86: ・データ・AIを利活用する上で知っておくべきこと「プロジェクト演習」(1～15週)
C87: 3-2 | D87: ・データを守る上で知っておくべきこと「専門基礎Ⅲ」(前期3～4週)
B88: （５）実データ・実課題（学術データ等を含む）を用いた演習など、社会での実例を題材として、「データを読む、説明する、扱う」といった数理・データサイエンス・ＡＩの基本的な活用法に関するもの | C88: 2-1 | D88: ・データの分布(ヒストグラム)と代表値（平均値、中央値、最頻値） 「環境都市工学実験実習Ⅰ」（後期5～8週）
...

Sheet 様式３　履修者等数の実績
F1: 様式３
A2: プログラムの履修者数等の実績について
A4: ①プログラム開設年度 | C4: ='様式１ 大学等概要'!E12 -> 令和元 | E4: 年度
A6: ②履修者・修了者の実績
B8: 学部・学科名称 | C8: 入学 定員 | D8: 収容 定員 | E8: 令和3年度 | G8: 令和2年度 | I8: 令和元年度 | K8: 平成30年度 | M8: 平成29年度 | O8: 平成28年度 | Q8: 履修者数 合計 | R8: 履修率
E9: 履修者数 | F9: 修了者数 | G9: 履修者数 | H9: 修了者数 | I9: 履修者数 | J9: 修了者数 | K9: 履修者数 | L9: 修了者数 | M9: 履修者数 | N9: 修了者数 | O9: 履修者数 | P9: 修了者数
B10: 機械工学科 | C10: 40 | D10: 200 | E10: 44 | F10: 41 | G10: 35 | H10: 33 | I10: 44 | J10: 37 | K10: 0 | L10: 0 | M10: 0 | N10: 0 | O10: 0 | P10: 0 | Q10: =E10+G10+I10+K10+M10+O10 -> 123 | R10: =Q10/D10 -> 0.615
B11: 電気電子工学科 | C11: 40 | D11: 200 | E11: 38 | F11: 35 | G11: 38 | H11: 36 | I11: 38 | J11: 36 | K11: 0 | L11: 0 | M11: 0 | N11: 0 | O11: 0 | P11: 0 | Q11: =E11+G11+I11+K11+M11+O11 -> 114 | R11: =Q11/D11 -> 0.57
B12: 電子情報工学科 | C12: 40 | D12: 200 | E12: 38 | F12: 34 | G12: 37 | H12: 35 | I12: 38 | J12: 33 | K12: 0 | L12: 0 | M12: 0 | N12: 0 | O12: 0 | P12: 0 | Q12: =E12+G12+I12+K12+M12+O12 -> 113 | R12: =Q12/D12 -> 0.565
B13: 物質工学科 | C13: 40 | D13: 200 | E13: 39 | F13: 38 | G13: 36 | H13: 36 | I13: 40 | J13: 36 | K13: 0 | L13: 0 | M13: 0 | N13: 0 | O13: 0 | P13: 0 | Q13: =E13+G13+I13+K13+M13+O13 -> 115 | R13: =Q13/D13 -> 0.575
B14: 環境都市工学科 | C14: 40 | D14: 200 | E14: 43 | F14: 39 | G14: 42 | H14: 40 | I14: 44 | J14: 44 | K14: 0 | L14: 0 | M14: 0 | N14: 0 | O14: 0 | P14: 0 | Q14: =E14+G14+I14+K14+M14+O14 -> 129 | R14: =Q14/D14 -> 0.645
Q15: =E15+G15+I15+K15+M15+O15 -> 0 | R15: =Q15/D15 -> #DIV/0!
Q16: =E16+G16+I16+K16+M16+O16 -> 0 | R16: =Q16/D16 -> #DIV/0!
Q17: =E17+G17+I17+K17+M17+O17 -> 0 | R17: =Q17/D17 -> #DIV/0!
Q18: =E18+G18+I18+K18+M18+O18 -> 0 | R18: =Q18/D18 -> #DIV/0!
Q19: =E19+G19+I19+K19+M19+O19 -> 0 | R19: =Q19/D19 -> #DIV/0!
Q20: =E20+G20+I20+K20+M20+O20 -> 0 | R20: =Q20/D20 -> #DIV/0!
Q21: =E21+G21+I21+K21+M21+O21 -> 0 | R21: =Q21/D21 -> #DIV/0!
Q22: =E22+G22+I22+K22+M22+O22 -> 0 | R22: =Q22/D22 -> #DIV/0!
Q23: =E23+G23+I23+K23+M23+O23 -> 0 | R23: =Q23/D23 -> #DIV/0!
Q24: =E24+G24+I24+K24+M24+O24 -> 0 | R24: =Q24/D24 -> #DIV/0!
Q25: =E25+G25+I25+K25+M25+O25 -> 0 | R25: =Q25/D25 -> #DIV/0!
Q26: =E26+G26+I26+K26+M26+O26 -> 0 | R26: =Q26/D26 -> #DIV/0!
... Q29: =E29+G29+I29+K29+M29+O29 -> 0 | R29: =Q29/D29 -> #DIV/0!
B30: 合 計 | C30: =SUM(C10:C29) -> 200 | D30: =SUM(D10:D29) -> 1000 | E30: =SUM(E10:E29) -> 202 | F30: =SUM(F10:F29) -> 187 | G30: =SUM(G10:G29) -> 188 | H30: =SUM(H10:H29) -> 180 | I30: =SUM(I10:I29) -> 204 | J30: =SUM(J10:J29) -> 186 | ... Q30: =SUM(Q10:Q29) -> 594 | R30: =Q30/D30 -> 0.594

Sheet 様式４　教育の質・履修者数を向上させるための体制・計画
J1: 様式４
A2: 教育の質・履修者数を向上させるための体制・計画について
A4: ① | B4: プログラムを改善・進化させるための体制を定める規則名称
B5: 福井工業高等専門学校教務委員会規則 | K5: =IF(B5="","入力してください","")
A7: ② | B7: 体制の目的
B8: 福井工業高等専門学校内部組織規則（昭和54年規則第2号）第4条の規定に基づき、教務委員会を設置している。本委員会は、校長の命を受けて次の事項を審議する組織であり、その中に、授業改善も含まれる。 （1） 教育課程及び授業時間割の編成等授業実施に関する事項、（2） 特別活動、学校行事等に関する事項、（3） 退学、休学、進級及び卒業の認定等に関する事項、（4） その他教務に関する重要な事項 | K8: =IF(B8="","入力してください","")
A14: ③ | B14: 具体的な構成員
B15: 第３条 委員会は、次の各号に掲げる委員をもって組織する。 （1） 教務主事：藤田克志 （2） 教務副主事及び教務主事補：芳賀正和、川上由紀、佐々和洋、藤田卓郎 （3） 学科長及び教室主任：村中貴幸、米田知晃、斉藤徹、髙山勝己、吉田雅穂、長水壽寛 （4） 学生課長：出口雅弘 | K15: =IF(B15="","入力してください","")
A27: ④ | B27: 履修者数・履修率の向上に向けた計画
B28: 令和３年度実績 | C28: ='様式３ 履修者等数の実績'!R30 -> 0.594 | E28: 令和４年度予定 | F28: 0.8 | H28: 令和５年度予定 | I28: 1
B29: 令和６年度予定 | C29: 1 | E29: 令和７年度予定 | F29: 1 | H29: 収容定員（名） | I29: ='様式３ 履修者等数の実績'!D30 -> 1000
B30: 具体的な計画
B31: 全ての教育プログラム構成科目は必修科目で構成されており、全科目を在学生が履修済み、あるいは履修予定であることから、在学生の教育プログラム履修率は100%である。 具体的には、教育プログラム構成科目の一部（プロジェクト演習：４年前期）が令和元年度からの開講となっているおり、その他の科目は、従来より実施されていたので、現５年生から令和2年度卒業生についても本教育プログラムを履修済みである。 一年生においても、一年時に設定された科目（専門基礎）を受講済みであり、学年が進むにつれて、すべての教育プログラム構成科目を受講予定である。 以上の体制をとっていることから、履修者数・履修率の向上に向けた計画については、問題はない。 | K31: =IF(B31="","入力してください","")
A45: ⑤ | B45: 学部・学科に関係なく希望する学生全員が受講可能となるような必要な体制・取組等
B46: ④で述べたように、すべての教育プログラム構成科目は必修科目で構成されており、全学生が受講可能な時間割で提供されている。 | K46: =IF(B46="","入力してください","")
A68: ⑥ | B68: できる限り多くの学生が履修できるような具体的な周知方法・取組
B69: ④で述べたように、すべての教育プログラム構成科目は必修科目で構成されており、全学生が受講可能な時間割で提供されている。 また、各科目が教育プログラムの構成要素であることをシラバスに記載し、さらに、教育プログラムの概要をHPやガイダンスで説明することにより、教育プログラムを履修していることについて意識づけを行う。 | K69: =IF(B69="","入力してください","")
A88: ⑦ | B88: できる限り多くの学生が履修・修得できるようなサポート体制
B89: 履修については、④で述べたように、すべての教育プログラム構成科目は必修科目で構成されており、全学生が受講可能な時間割で提供されているため、何ら問題はない。
K91: =IF(B89="","入力してください","")
A110: ⑧ | B110: 授業時間内外で学習指導、質問を受け付ける具体的な仕組み
B111: サポート体制については、各教員が直接学生の質問を受け付ける時間帯（オフィスアワー）を設けて公開している。また、Microsoft Teams のチーム機能とチャットによる質問も受け付けるなど、複数の方法で担当教員に質問ができる体制を構築している。
K113: =IF(B111="","入力してください","")

Sheet 様式５　自己点検・評価
J1: 様式５
A2: 自己点検・評価について
A4: ① | B4: 自己点検・評価体制における意見等
B5: 自己点検・評価の視点 | E5: 自己点検・評価体制における意見・結果・改善に向けた取組等
B6: 学内からの視点
C7: プログラムの履修・修得状況 | E7: 教育プログラムを構成する科目は全て必修科目であり，入学するすべての学生が教育プログラムを修了できる体制となっている。履修状況／成績状況については、出席簿やteamsを通じた担当教員のやり取りにより把握されており、問題のある学生については、自主的な質問についてはオフィスアワーやteamsによる対応を、申し出が無い場合についても、成績表をチェックし、補習などのフォローを行っている。 履修・修得の実績としては、教育プログラム開始年が令和元年度であり、教育プログラムを構成科目の最高学年が4年次であることから、令和元年度の4年生からが教育プログラム受講対象者であり、卒業生の修了率は100％と、履修状況は良好である。 | K7: =IF(E7="","入力してください","")
C8: 学修成果 | E8: 本校では、従来より、全学科において、ソフトウェア開発、データ処理など情報教育に力を入れてきたが、社会の動向を鑑み、数理・データサイエンス・AI分野について既存科目を整理・体系化したことにより、データの活用ができる素養を備えたエンジニアを育成する明示的なカリキュラムとなっている。 学生が習得すべき内容については、WEBシラバスのルーブリックに記載されており、学生自身がいつでも確認可能であり、授業ガイダンスにおいても説明している。 学修成果については、教育プログラムを構成する科目の成績や創造教育開発センターで実施している授業アンケートの分析により把握し、学生のフォローや、次年度に対する授業改善に活用している。 | K8: =IF(E8="","入力してください","")
C9: 学生アンケート等を通じた学生の内容の理解度 | E9: 学修成果にも挙げたように、本教育プログラム受講者に対しては毎年全員に授業アンケートを実施している。 また、アンケート結果については集計し、統計的な傾向を見るだけでなく、科目担当教員にフィードバックし、授業改善に役立てている。 | K9: =IF(E9="","入力してください","")
C10: 学生アンケート等を通じた後輩等他の学生への推奨度 | E10: 教育プログラムを構成する科目は全て必修科目なので、特に推奨などは行っていない。令和二年度卒業生における教育プログラム履修修了者率は100%である。 | K10: =IF(E10="","入力してください","")
C11: 全学的な履修者数、履修率向上に向けた計画の達成・進捗状況 | E11: 教育プログラムを構成する科目は全て必修科目なので、特に推奨などは行っていない。 ただし、教育プログラムの質の向上については、授業アンケートなどを通じて随時行っている。 | K11: =IF(E11="","入力してください","")
B12: 学外からの視点
C13: 教育プログラム修了者の進路、活躍状況、企業等の評価 | E13: 隔年で外部有識者会議を実施し、本校の長中期計画、教育状況、入試状況などについて評価を受けている。外部有識者会議の委員は、高等教育機関の教員および経験者／地域の教育関係者／地方自治体等研究機関の研究者／産業界の有識者／報道機関の有識者／本校関係者からなっており、平成二年度に開催された有識者会議委員は、長岡技術科学大学学長、福井大学副学長、福井県中学校長会会長、福井県工業技術センター所長、鯖江商工会議所会頭、信越化学工業（株）武生工場長、（株）福井新聞社編集局長、福井高専同窓会会長に評価していただき、ご意見をいただいている。 また、３年毎に卒業生の就職先に対して企業アンケートを実施しており、卒業生の能力・技能に対する評価をいただき、こちらについても教員にフィードバックを行い授業改善に役立てるとともに、教務全体の改善に役立てている。 | K13: =IF(E13="","入力してください","")
C14: 産業界からの視点を含めた教育プログラム内容・手法等への意見 | E14: 「教育プログラム修了者の進路、活躍状況、企業等の評価」に記した内容に加え，本教育プログラムを構成する科目のひとつであるプロジェクト演習（4年前期）では、発表会に企業エンジニアを招き、学生に対して直接評価をしていただいている。これにより、学生は、自身が行った「問題発見～調査検討～問題解決」というプロセスについて、外部からの評価を得ることができ、自身の学修内容を評価することができる。 | K14: =IF(E14="","入力してください","")
B15: 数理・データサイエンス・ＡＩを「学ぶ楽しさ」「学ぶことの意義」を理解させること | E15: 専門基礎は、学科ごとの開講とすることにより、同じ学習目標に対しても、各学科の専門内容に合った実例で授業を実施するなど、学生の学ぶ意識を高める工夫をしている。 また、学習を座学だけで終わらせることなく、社会連携PBL授業であるプロジェクト演習では、実問題の抽出から解決策の提案までをグループワークで行うこと、その際、座学で得た知識を活用できるように教員がメンターに付くなど、学生のモチベーションを高め、学びに対して積極的になれるようなサポートを行っている。 | K15: =IF(E15="","入力してください","")
B16: 内容・水準を維持・向上しつつ、より「分かりやすい」授業とすること | E16: 情報を専門としない学科においても，学生に学習の意義が伝わるように、専門基礎は、学科ごとの開講とし、同じ学習目標に対しても専門内容に合った内容で授業を実施することにより、内容のレベルを下げることなく、学ぶ意識を高めることができる工夫をしている。 社会連携PBL授業（プロジェクト演習）では、馴染みのある課題を提示すること、知識の活用ができるように基礎講座を実施し、教員がメンターに付くなど、学生の学びをサポートするための工夫を随所で行っている。 | K16: =IF(E16="","入力してください","")
A18: ②自己点検・評価体制における意見等を公表しているアドレス | G18: https://www.fukui-nct.ac.jp/wp/wp-content/uploads/2022/07/5584712ec86c69d2db1870fa6194ea51.pdf | K18: =IF(G18="","入力してください","")

Sheet 様式６　特色ある取組
E1: 様式６
A2: 数理・データサイエンス・AI教育プログラム認定制度（リテラシーレベル）プラス 申請書
A4: ① | B4: 授業内容
A43: ② | B43: 学生への学習支援
A84: ③ | B84: その他の取組（地域連携、産業界との連携、海外の大学等との連携等）
