Workbook

Sheet 様式１　大学等概要
M1: 様式１
A2: 数理・データサイエンス・AI教育プログラム認定制度（リテラシーレベル） 申請様式
A4: ① | B4: 学校名 | C4: 長岡工業高等専門学校
A6: ② | B6: 大学等の設置者 | D6: 独立行政法人 国立高等専門学校機構 理事長 谷口 功
A8: ③ | B8: 設置形態 | C8: 高等専門学校
A10: ④ | B10: 所在地 | C10: 新潟県長岡市西片貝町888
A12: ⑤ | B12: 申請するプログラム又は授業科目名称 | G12: AIR Techエンジニア育成プログラム
A14: ⑥ | B14: プログラムの開設年度 | F14: 令和元年度
A16: ⑦ | B16: 教員数 | C16: （常勤） | E16: 77 | G16: 人 | I16: （非常勤） | K16: 51 | N16: 人
A18: ⑧ | B18: プログラムの授業を教えている教員数 | K18: 19 | N18: 人
A20: ⑨ | B20: 全学部・学科の入学定員 | E20: 200 | G20: 人
A22: ⑩ | B22: 全学部・学科の学生数（学年別） | H22: 総数 | J22: 1038 | M22: 人
B24: １年次 | C24: 211 | E24: 人 | G24: ２年次 | I24: 212 | K24: 人
B26: ３年次 | C26: 218 | E26: 人 | G26: ４年次 | I26: 209 | K26: 人
B28: ５年次 | C28: 188 | E28: 人 | G28: ６年次 | K28: 人
A30: ⑪ | B30: プログラムの運営責任者
B31: （責任者名） | D31: 原田信弘 | G31: （役職名） | J31: 校長
A33: ⑫ | B33: プログラムを改善・進化させるための体制（委員会・組織等）
B34: AIR Tech ワーキンググループ
B36: （責任者名） | D36: 工藤慈 | G36: （役職名） | J36: AIRTechワーキンググループ長
A38: ⑬ | B38: プログラムの自己点検・評価を行う体制（委員会・組織等）
B39: 教務委員会
B41: （責任者名） | D41: 田中聡 | G41: （役職名） | J41: 教務主事
A43: ⑭ | B43: 申請する認定プログラム | F43: 認定教育プログラムと認定教育プログラム+（プラス）
A45: 連絡先
B46: 所属部署名 | C46: 学生課教務入試係 | I46: 担当者名 | K46: 小林 仁
B47: E-mail | C47: kyoumu@nagaoka-ct.ac.jp | I47: 電話番号 | K47: 0258-34-9331

Sheet 様式２　プログラムを構成する授業科目
I1: 様式２
G2: 学校名： | H2: ='様式１ 大学等概要'!C4 -> 長岡工業高等専門学校
A4: プログラムを構成する授業科目について
A6: ① | B6: 教育プログラムの修了要件 | E6: 学部・学科によって、修了要件は相違しない
A8: ② | B8: 具体的な修了要件
B9: 以下の授業科目をすべて修得すること ・基礎情報処理（１年次，全学科必修） ・確率（３年次，全学科必修） ・統計学（４年次，全学科必修）
A18: ③ | B18: 授業科目名称
A19: 授業科目名称 | F19: 授業科目名称
A20: 1 | B20: 基礎情報処理 | F20: 26
A21: 2 | B21: 確率 | F21: 27
A22: 3 | B22: 統計学 | F22: 28
A23: 4 | F23: 29
A24: 5 | F24: 30
A25: 6 | F25: 31
A26: 7 | F26: 32
A27: 8 | F27: 33
A28: 9 | F28: 34
A29: 10 | F29: 35
A30: 11 | F30: 36
A31: 12 | F31: 37
A32: 13 | F32: 38
A33: 14 | F33: 39
A34: 15 | F34: 40
... A44: 25 | F44: 50

Sheet 様式３　履修者等数の実績
F1: 様式３
K2: 学校名： | M2: ='様式１ 大学等概要'!C4 -> 長岡工業高等専門学校
A4: プログラムの履修者数等の実績について
B6: 学部・学科名称 | D6: 収容 定員 | E6: 令和2年度 | G6: 令和元年度 | I6: 平成30年度 | K6: 平成29年度 | M6: 平成28年度 | O6: 平成27年度 | Q6: 履修者数 合計 | R6: 履修率
E7: 履修者数 | F7: 修了者数 | G7: 履修者数 | H7: 修了者数 | I7: 履修者数 | J7: 修了者数 | K7: 履修者数 | L7: 修了者数 | M7: 履修者数 | N7: 修了者数 | O7: 履修者数 | P7: 修了者数
B8: 機械工学科（工業） | D8: 200 | E8: 44 | F8: 0 | G8: 41 | H8: 0 | I8: 0 | J8: 0 | K8: 0 | L8: 0 | M8: 0 | N8: 0 | O8: 0 | P8: 0 | Q8: =E8+G8+I8+K8+M8+O8 -> 85 | R8: =Q8/D8 -> 0.425
B9: 電気電子システム工学科（工業） | D9: 200 | E9: 43 | F9: 0 | G9: 44 | H9: 0 | I9: 0 | J9: 0 | K9: 0 | L9: 0 | M9: 0 | N9: 0 | O9: 0 | P9: 0 | Q9: =E9+G9+I9+K9+M9+O9 -> 87 | R9: =Q9/D9 -> 0.435
B10: 電子制御工学科（工業） | D10: 200 | E10: 41 | F10: 0 | G10: 40 | H10: 0 | I10: 0 | J10: 0 | K10: 0 | L10: 0 | M10: 0 | N10: 0 | O10: 0 | P10: 0 | Q10: =E10+G10+I10+K10+M10+O10 -> 81 | R10: =Q10/D10 -> 0.405
B11: 物質工学科（工業） | D11: 200 | E11: 41 | F11: 0 | G11: 42 | H11: 0 | I11: 0 | J11: 0 | K11: 0 | L11: 0 | M11: 0 | N11: 0 | O11: 0 | P11: 0 | Q11: =E11+G11+I11+K11+M11+O11 -> 83 | R11: =Q11/D11 -> 0.415
B12: 環境都市工学科（工業） | D12: 200 | E12: 42 | F12: 0 | G12: 42 | H12: 0 | I12: 0 | J12: 0 | K12: 0 | L12: 0 | M12: 0 | N12: 0 | O12: 0 | P12: 0 | Q12: =E12+G12+I12+K12+M12+O12 -> 84 | R12: =Q12/D12 -> 0.42
Q13: =E13+G13+I13+K13+M13+O13 -> 0 | R13: =Q13/D13 -> #DIV/0!
Q14: =E14+G14+I14+K14+M14+O14 -> 0 | R14: =Q14/D14 -> #DIV/0!
Q15: =E15+G15+I15+K15+M15+O15 -> 0 | R15: =Q15/D15 -> #DIV/0!
Q16: =E16+G16+I16+K16+M16+O16 -> 0 | R16: =Q16/D16 -> #DIV/0!
Q17: =E17+G17+I17+K17+M17+O17 -> 0 | R17: =Q17/D17 -> #DIV/0!
Q18: =E18+G18+I18+K18+M18+O18 -> 0 | R18: =Q18/D18 -> #DIV/0!
Q19: =E19+G19+I19+K19+M19+O19 -> 0 | R19: =Q19/D19 -> #DIV/0!
Q20: =E20+G20+I20+K20+M20+O20 -> 0 | R20: =Q20/D20 -> #DIV/0!
Q21: =E21+G21+I21+K21+M21+O21 -> 0 | R21: =Q21/D21 -> #DIV/0!
Q22: =E22+G22+I22+K22+M22+O22 -> 0 | R22: =Q22/D22 -> #DIV/0!
Q23: =E23+G23+I23+K23+M23+O23 -> 0 | R23: =Q23/D23 -> #DIV/0!
Q24: =E24+G24+I24+K24+M24+O24 -> 0 | R24: =Q24/D24 -> #DIV/0!
... Q27: =E27+G27+I27+K27+M27+O27 -> 0 | R27: =Q27/D27 -> #DIV/0!
B28: 合 計 | D28: =SUM(D8:D27) -> 1000 | E28: =SUM(E8:E27) -> 211 | F28: =SUM(F8:F27) -> 0 | G28: =SUM(G8:G27) -> 209 | H28: =SUM(H8:H27) -> 0 | I28: =SUM(I8:I27) -> 0 | J28: =SUM(J8:J27) -> 0 | K28: =SUM(K8:K27) -> 0 | ... Q28: =SUM(Q8:Q27) -> 420 | R28: =Q28/D28 -> 0.42

Sheet 様式4　プログラムの授業内容・概要
G1: 様式４－○
F2: 学校名： | G2: ='様式１ 大学等概要'!C4 -> 長岡工業高等専門学校
A3: プログラムの授業内容・概要
A4: ① | B4: プログラムを構成する授業の内容・概要（数理・データサイエンス・AI（リテラシーレベル）モデルカリキュラムの「導入」、「基礎」、「心得」に相当）
B5: 授業に含まれている内容・要素 | C5: 授業概要
B6: （１）現在進行中の社会変化（第４次産業革命、Society 5.0、データ駆動型社会等）に深く寄与しているものであり、それが自らの生活と密接に結びついている ※モデルカリキュラム導入１－１、導入１－６が該当 | C6: 第４次産業革命、Society 5.0に代表される近年の急速な産業構造の変化を支えるAIに関する基礎事項を学ぶ。 まずAIの概念そのものを解説した後に，AIと機械学習とディープラーニングの関係性や，機械学習の3つのトピック「教師あり学習」「教師なし学習」「強化学習」の違いとそれぞれの活用例を学ぶ。 その後に，実際に企業でAIが活用されている例として ・トレイ上のパンの種類・値段をカメラで一括識別するシステム ・カメラによる画像認識や超音波センサやレーダーなどのセンサを活用した自動運転車 ・画像認識によって撮影した服と似た服をショッピングサイトから探すアプリ ・飲食店の売上を予測し，広告プランの自動最適化を行うシステム を動画やWebサイトを示しながら紹介し，AIが自らの生活と密接に結びついていることを理解させる。
C10: 授業科目名称 | D10: 講義テーマ
C11: 基礎情報処理（機械工学科） | D11: AI技術の基礎１（２８）
C12: 基礎情報処理（電気電子システム工学科） | D12: AI技術の基礎１（２８）
C13: 基礎情報処理（電子制御工学科） | D13: AI技術の基礎１（１８）
C14: 基礎情報処理（物質工学科） | D14: AI技術の基礎１（２８）
C15: 基礎情報処理（環境都市工学科） | D15: AI技術の基礎１（２８）
B26: （２）「社会で活用されているデータ」や「データの活用領域」は非常に広範囲であって、日常生活や社会の課題を解決する有用なツールになり得るもの ※モデルカリキュラム導入１－２、導入１－３が該当 | C26: 授業概要
C27: AIの概念の解説にて，「データ駆動型のAIでは，集めたデータに基づいてコンピュータ自身が学習を行って，その結果に基づいて推論を行うものである」という解説を行い，特定のデータに限った技術ではないということを理解させる。 また，実際に企業でAIが活用されている例を示す際にも，AIというのは画像認識だけで用いられる技術ではなく，センサデータや売上などのデータも活用できるということを示す。 さらに，実際にAIによる処理を体験してもらうために，Pepperの「年齢当て」アプリによる学生たちの年齢推定を体験させたり，Google社が提供している「Quick, Draw!」というWebアプリによって手書き画像の認識を体験させるワークを実施する。この経験を通して，AIというのは入力と意味のある出力との変換を行う枠組みであるという理解を深める。その理解をもとに，発想次第でAIの活用場面は広がっていくという実感をもたせる。
C32: 授業科目名称 | D32: 講義テーマ
C33: 基礎情報処理（機械工学科） | D33: AI技術の基礎１（２８）
C34: 基礎情報処理（電気電子システム工学科） | D34: AI技術の基礎１（２８）
C35: 基礎情報処理（電子制御工学科） | D35: AI技術の基礎１（１８）
C36: 基礎情報処理（物質工学科） | D36: AI技術の基礎１（２８）
C37: 基礎情報処理（環境都市工学科） | D37: AI技術の基礎１（２８）
B51: （３）様々なデータ利活用の現場におけるデータ利活用事例が示され、様々な適用領域（流通、製造、金融、サービス、インフラ、公共、ヘルスケア等）の知見と組み合わせることで価値を創出するもの ※モデルカリキュラム導入１－４、導入１－５が該当 | C51: 授業概要
C52: 実際に企業でAIが活用されている例として ・トレイ上のパンの種類・値段をカメラで一括識別するシステム ・カメラによる画像認識や超音波センサやレーダーなどのセンサを活用した自動運転車 ・画像認識によって撮影した服と似た服をショッピングサイトから探すアプリ ・飲食店の売上を予測し，広告プランの自動最適化を行うシステム を動画やWebサイトを示しながら紹介し，AIは様々な適用領域で活用されていることを理解させる。また，AIを体験するために， ・Pepperによる年齢当てアプリ ・「Quick, Draw!」による手書き画像認識 を実施し，より一層適用範囲の広さを認識させる。 また，AIの仕組みを解説する際に，AIというのは「入力」を「意味のある出力」に変換させる枠組みで，その変換の仕方を学習しているという解説を行い，入力と正解のペアを与えられれば様々な分野で適用できるという原理を説明する。
C57: 授業科目名称 | D57: 講義テーマ
C58: 基礎情報処理（機械工学科） | D58: AI技術の基礎１（２８）
C59: 基礎情報処理（電気電子システム工学科） | D59: AI技術の基礎１（２８）
C60: 基礎情報処理（電子制御工学科） | D60: AI技術の基礎１（１８）
C61: 基礎情報処理（物質工学科） | D61: AI技術の基礎１（２８）
C62: 基礎情報処理（環境都市工学科） | D62: AI技術の基礎１（２８）
B76: （４）活用に当たっての様々な留意事項（ELSI、個人情報、データ倫理、ＡＩ社会原則等）を考慮し、情報セキュリティや情報漏洩等、データを守る上での留意事項への理解をする ※モデルカリキュラム心得３－１、心得３－２が該当 | C76: 授業概要
C77: AIの実践として，ディープラーニング用PCを用いて授業担当教員の開発した画像認識AIのプログラムを動かし，画像認識の学習と推論を体験させる。まず第1段階として用意した犬と猫の画像を用いて，犬と猫を識別するAIの学習を行う。学習後，インターネット上の画像を用いて推論を行わせ，犬や猫以外の動物を入力しても犬か猫のどちらかだと判断する様子を示しながら，「AIは学習した範囲でしか有効ではない」ということを理解させる。 その後，学生たち同士で顔写真を撮影させ，同じプログラムで顔認識AIの作成を行う。最初は10枚程度の学習データで学習を行うため，精度が低い場合が出てくる。そのことを踏まえて，「実用的な高精度のAIを作るためには大量の学習データが必要である」ということを理解させる。 また，電子メールやインターネット利活用時のルール・マナーについても事前に学習しており，その知識と合わせながらAI利活用時の注意点などの解説を行う。具体的には，採用試験等にAIを用いた場合に，AIの学習が不十分だと人種や性別によってバイアスがかかって差別を増強してしまう恐れがあることや，会話を学習するAIが誹謗中傷の発言をしてしまうような学習をしかねない，といったことを説明する。
C82: 授業科目名称 | D82: 講義テーマ
C83: 基礎情報処理（機械工学科） | D83: 電子メール（２～４）、情報検索（６～９）、AI技術の基礎（２８〜３０）
C84: 基礎情報処理（電気電子システム工学科） | D84: インターネット・電子メールのしくみ、ルール、マナー（３～４）、AI技術の基礎（２８〜３０）
C85: 基礎情報処理（電子制御工学科） | D85: 電子メール使用法、情報の収集・整理（３～４）、AI技術の基礎（１７〜１９）
C86: 基礎情報処理（物質工学科） | D86: 電子メール、情報検索、ネットワーク利用の注意（４～８）、AI技術の基礎（２８〜３０）
C87: 基礎情報処理（環境都市工学科） | D87: ネットワークの利用とモラル（２２～２３）、AI技術の基礎（２８〜３０）
B101: （５）実データ・実課題（学術データ等を含む）を用いた演習など、社会での実例を題材として、「データを読む、説明する、扱う」といった数理・データサイエンス・ＡＩの基本的な活用法に関するもの ※モデルカリキュラム基礎２－１、基礎２－２、基礎２－３が該当 | C101: 授業概要
C102: AIの実践として，ディープラーニング用PCを用いて授業担当教員の開発した画像認識AIのプログラムを動かし，画像認識の学習と推論を体験させる。まず第1段階として用意した犬と猫の画像を用いて，犬と猫を識別するAIの学習を行い，学習後にインターネット上の画像を用いて推論を行わせる。 その後，学生たち同士で顔写真を撮影させ，同じプログラムで顔認識AIの作成を行うことで，学習データの作成，ラベル付け，前処理，学習，効果検証，といったAIのシステム構築に関する一連の流れを体験させる。 また，プログラムの実行を通して，「正解率」「再現率」「適合率」の違いを説明し，不適切な指標を使わないように，推論の精度の尺度についての正しい知識を得てもらう。 そして，AIを学習させるためには，ただデータがあればいいというだけでなく， ・精度を上げるには大量の学習データが必要である。 ・実運用の場面を想定した学習データを用意する必要がある。 といった理解を深めてもらう。
C107: 授業科目名称 | D107: 講義テーマ
C108: 基礎情報処理（機械工学科） | D108: AI技術の基礎（２８〜３０）
...

Sheet 様式５　教育の質・履修者数を向上させるための体制・計画
E1: 様式５
B2: 学校名 | C2: ： | D2: ='様式１ 大学等概要'!C4 -> 長岡工業高等専門学校
B4: 教育の質・履修者数を向上させるための体制・計画について
A6: ① | B6: プログラムを改善・進化させるための体制を定める規則名称
B7: AIR Tech ワーキンググループ
A9: ② | B9: 体制の目的
B10: 次世代技術者にとって空気のごとく必須となるAI・IoT・RT（ロボット技術）のそれぞれの頭文字を取りAIR Tech（エアーテック）と命名し、低学年のリテラシー教育から高学年の社会実装プロジェクトまで、段階的にステップアップしながらAIR Tech技術を学び続ける人材の育成を目的に、本ワーキンググループを構築した。特に高専入学後の早期教育として、1・2年生に共通のAI・IoTのリテラシー教育を実施することにより、AIR Tech技術が身近で必須の技術であることを学科を問わず、全学生に理解させる。
A16: ③ | B16: 具体的な構成員
B17: 全学科から１名以上の教員ならびに技術系・事務系職員が集まって組織される AIR Tech ワーキンググループを立ち上げ、多様な視点からの教材検討やスムーズな学科内調整を可能にした。 機械工学科 教授 池田 富士雄 機械工学科 助教 工藤 慈 電気電子システム工学科 准教授 島宗 洋介 電気電子システム工学科 助教 和久井 直樹 電子制御工学科 教授・校長補佐 外山 茂浩 電子制御工学科 准教授 上村 健二 電子制御工学科 助教 酒井 一樹 物質工学科 准教授 宮田 真理 環境都市工学科 准教授 衞藤 俊彦 教育研究技術支援センター 技術職員 和田 政輝 学生課 桑原 透
A30: ④ | B30: 履修者数・履修率の向上に向けた計画
B31: 各年度の履修者数の目標を以下のとおりとする。（（ ）内は履修率。） 令和3年度 600名 （60%） 令和4年度 800名 （80%） 令和5年度 1000名 （100%） 令和6年度 1000名 （100%） 令和7年度 1000名 （100%） 本教育プログラムは既に令和元年度より実施しており、全学科の第1学年から必修科目として履修している。今後、学年進行によって履修者が増加し、令和5年度以降は全学生が履修済みとなる計画である。また、第4学年での開講科目の単位を取得した段階で本プログラムの修了となるため、令和4年度に約200名がプログラム修了となり、その後は年度ごとに約200名ずつ修了者が増加していく。
A47: ⑤ | B47: 学部・学科に関係なく希望する学生全員が受講可能となるような必要な体制・取組等
B48: １、３、４学年の学生全員が、全学科共通の必修科目「基礎情報処理」「確率」「統計学」を履修していくため、学科に関係なく学生全員が受講可能な体制を構築している。
A70: ⑥ | B70: できる限り多くの学生が履修できるような具体的な周知方法・取組
B71: プログラム認定に必要な科目をすべて必修科目とすることで履修申請漏れを防ぎ、全学生が履修するように構築した。また、本プログラムについて入学後のガイダンスにて周知するとともに、本校WEBサイトホームページトップ画面に専用ページへのリンクを掲載し、学生が情報を受け取りやすい環境を整備している。
A91: ⑦ | B91: できる限り多くの学生が履修・修得できるようなサポート体制
B92: 令和元年度より本校の学生向けホームページ上に、AIリテラシー授業で必要となる講義資料のWEBサイトを掲載しており、学習内容はWEBサイトにていつでも閲覧できる環境を構築している。専用のワークステーションを整備した教室での講義は複数名の教員を配置し、グループワークにより学生同士が教え合うことで、全学生がPCを操作してAIの構築から検証までを理解できるように設計している。
A113: ⑧ | B113: 授業時間内外で学習指導、質問を受け付ける具体的な仕組み
B114: 本教育プログラムについての履修を学内の出席管理システムにて管理している。学生は授業時間以外に不明点等を専用WEBサイトにて確認することができ、令和2年度より全学生にMicrosoft Teamsをインストールさせ、オンラインでの質問が可能な体制を構築した。

Sheet 様式６　自己点検・評価
J1: 様式６
H2: 学校名： | I2: ='様式１ 大学等概要'!C4 -> 長岡工業高等専門学校
A3: 自己点検・評価について
A5: ① | B5: 自己点検・評価体制における意見等
B6: 自己点検・評価の視点 | E6: 自己点検・評価体制における意見・結果・改善に向けた取組等
B7: 学内からの視点
C8: プログラムの履修・修得状況 | E8: プログラム認定に必要な科目をすべて必修科目とすることで履修申請漏れを防ぎ、全学生が履修するように構築した。本校教務委員会において、プログラムの履修・取得状況の分析を実施している。学内の出席管理システムの活用により、受講者毎の講義演習進捗状況を把握することができる。
C9: 学修成果 | E9: 各授業科目の最終回にて理解度テストを実施しており、授業内容の学生の理解度を把握することができる。テストの結果をもとに、理解が十分ではない授業内容を洗い出すとともに、学科ごとの傾向を比較することにより、各専門分野において理解が定着しやすい教授方法を再検討し、本教育プログラムの評価・改善に活用している。
C10: 学生アンケート等を通じた学生の内容の理解度 | E10: Microsoft Formsを用いた受講生に対する授業評価アンケートにおいて、授業内容の理解度に関する質問項目（教員の熱意、授業内容の工夫、学生の反応を理解しながら授業を進めているか、質問への対応の度合い）を設け、確認している。また同アンケートにおいて学生自身の授業への姿勢を問うことにより、自己の成長を促している。
C11: 学生アンケート等を通じた後輩等他の学生への推奨度 | E11: 受講生に対する授業評価アンケートにおいて、授業への満足度や受講の感想等の意見を掲示することにより、後輩等他の学生への推奨について確認し、次年度以降の授業改善に活用している。
C12: 全学的な履修者数、履修率向上に向けた計画の達成・進捗状況 | E12: 本教育プログラムを構成する全ての科目は既に令和元年度より実施しており、全学科の第1、２学年の学生が必修科目として履修している。今後、学年進行によって履修者が増加し、令和5年度以降は履修率が１００％となる計画である。
B13: 学外からの視点
C14: 教育プログラム修了者の進路、活躍状況、企業等の評価 | E14: 令和5年度に卒業する学生が本プログラムを修了した最初の卒業生となる。それ以降の評価として、本校卒業生により組織される同窓会「高志会」にて卒後５年から10年の卒業生に対しアンケート調査を実施し、本教育プログラムを修了した卒業生の進路先や活躍状況を把握することが可能である。また本校との連携交流等を目的とする企業約200社からなる「技術協力会」を通じて企業調査を実施し、本教育プログラムを修了した卒業生における採用状況や企業評価を把握する仕組みを設けている。
C15: 産業界からの視点を含めた教育プログラム内容・手法等への意見 | E15: 本教育プログラムの立ち上げ初年度末（平成30年度、2019年3月）において、外部有識者会議（委員11名）を開催し、事業計画及び内容に関して高い評価4.5（5点満点）を受けた。具体的には以下のような意見（抜粋）を頂いた。 ・長岡でのイノベーションを推進していく上では、核となる事業、組織が必要。長岡高専が提唱した、AIRテクノロジーという発想は、素晴らしいものであり、もっとこの取組みを地域に広げ、関係機関を巻き込み、ダイナミックに展開していってほしい。 ・地域における中小企業にとっては、AI、IoTはまだまだ身近な存在にはなっていない現状にあるなか、高専が先導的役割を果たし、長岡市IoT推進ラボとの連携のもと、本事業の成果を地域産業界に還元されることを大いに期待している。 ・低学年からリテラシー教育としてAIR Techを実施していることは、学生のAIRへの興味を増進させることから、大いに評価する。
B16: 数理・データサイエンス・ＡＩを「学ぶ楽しさ」「学ぶことの意義」を理解させること | E16: ・AI用のGPU搭載ワークステーションを44台設置したAIリテラシー教育専用の部屋（AIルーム）を用意し、座学だけに留まらず実際にAIを構築する体験を提供できる環境を用意した。このAIルームでは地域の中学生、小学生向けの体験授業でも高い満足度を得ており、「数理・データサイエンス・AI」を学ぶ楽しさを初等教育の段階から教える上で重要な役割を持つ。
B17: 内容・水準を維持・向上しつつ、より「分かりやすい」授業とすること | E17: ・講義資料は、Web上からアクセスできるものを充実させ、授業をスムーズに実施でき、かつ学生が授業外での自主学習を手軽に行えるようにしている。 ・AIの入門セミナーに多くの実績を持つ株式会社キカガクより講師を招へいし、教職員を対象としたAIに関する研修を毎年実施している。これによりAIのリテラシー教育を行える教職員の裾野を広げるとともに、各教員の教授力向上および維持に繋げている。 ・リテラシー授業の導入においては、世間でも話題に上がっている身近で先端的な活用事例を紹介することにより、次世代技術者にとって身近で必須の技術であることの理解を促している。
H19: ※公表している場合のアドレス
A20: ② | B20: 自己点検・評価体制における意見等の公表の有無 | F20: 有 | H20: http://www.nagaoka-ct.ac.jp/jisedai/it/air/

Sheet 様式７　特色ある取組
E1: 様式７
C2: 学校名 | D2: ： | E2: ='様式１ 大学等概要'!C4 -> 長岡工業高等専門学校
A4: 数理・データサイエンス・AI教育プログラム認定制度（リテラシーレベル）プラス 申請書
A6: ① | B6: 授業内容
B7: 令和元年度より全学科での低学年向けのAI・IoTリテラシー教育を実施するため、6号館1階にAI開発用ワークステーション44台（＋教員用1台）を導入したAIルームを整備した。リアルタイム画像処理用の演算装置GPU（グラフィックボード）を画像処理以外の汎用計算に応用する技術GPGPUに対応したワークステーションであり、大規模な行列演算処理が高速に実行可能である。この技術は、画像認識・物体検出をはじめとした多くの最先端のAIに用いられているディープラーニングという手法の根幹を成す技術であり、学習を必要とする実課題を短時間で解決するために必要不可欠な要素である。AIルームを整備し、最先端の技術・手法に触れられるようにすることで、極めて効率的な教育環境が整っている。以上の先進的な教育体制のもと、本科第1学年の基礎情報処理30時間中、90分×3回分のAIリテラシー教育を行う。ここでは、AI技術を構築・運用するために必要なスキルと開発の流れについて説明できることを到達目標とする。 授業計画（3回分） 1回目：AI技術の基礎1：AIの概要と活用例、Pythonによる犬・猫判別AIの構築 （到達目標）AI技術の概要、活用例、使われている技術を説明できる 2回目：AI技術の基礎2：機械学習による顔認証① （到達目標）教師データの作成と機械学習による顔認証を体験し、一連の開発を実行できる 3回目：AI技術の基礎3：機械学習による顔認証②、まとめ （到達目標）モデルの修正を行い、AI技術の開発に必要なスキルと運用方法を説明できる 90分講義×3回分のＷｅｂ上で閲覧可能な教材 ・講義テキスト×3回分 教材内容 機械学習に関する基礎を簡単な画像認識を通して学習する。 第一回目: Python（Jupyter notebook）を使用し、犬および猫の写真200～300枚について、それぞれ共通項を抽出する学習を行い、モデルを構築する。そのモデルを使用して、犬および猫の写真を判定させる。学生は簡単な機械学習の一連の流れを習得できる。 第二回目: 4～6名ごとに学生をグループに分け、学生自身の顔写真を撮影し、グループ内のメンバーの写真を共有し、学習させる。新たな写真を用いて顔認証を行う。認識の際の”精度”について人間の顔という多様性の高いデータを通して学習する。 第三回目: 顔認証精度が低い場合と高い場合について特徴を洗い出し、精度を上げるためにはどうすべきかを検討する。その一つの施策として学習データの量と質に多様性を持たせることが重要であると認識させる。実際に学習データを増加させた場合の認証精度について実行、考察する。 以上の一連の講義の中でモデルカリキュラムに含まれる導入1-1～1-6・基礎2-1～2-3・心得3-1、3-2についての教育を行っている。また、必要に応じて基礎情報処理の講義内で適宜補足説明を入れている。 これらの講義は複数名の教員を配置し、グループワークにより学生同士が教え合うことで、PCの操作が不慣れな学生に対してもフォローを入れながら全学生がPCを操作してAIの構築から検証までを理解できるように設計している。学生からの評価は令和２年度に行った学生アンケートの結果から非常に好意的な回答を得られている。
A45: ② | B45: 学生への学習支援
B46: １．対面・オンラインでの学習支援体制 本プログラムに限らず、本校の各教員は毎週１時間以上のオフィスアワーを設けており、学生は対面で教員への質問がしやすい体制をとっている。また、令和2年度より全学生にMicrosoft Teamsをインストールさせ、オンラインでの質問が可能な体制を構築した。本プログラムについては、令和元年度より本校の学生向けホームページ上に、AIリテラシー授業で必要となる講義資料のWEBサイトを掲載しており、学習内容はオンラインでいつでも閲覧できる環境となっている。そのため、学生は授業時間以外に不明点等を専用WEBサイトにて確認することができる。さらにAIに関する自主学習用のWEBサイトへのリンクも掲載しており、発展的な学びを希望する学生に向けた支援も行っている。 ２．海外留学生への対応 本プログラムの根幹となっている基礎情報処理のAIリテラシー講義に使用する教材のうち、実際に学生がAI構築の操作を行うJupyter notebookに記載しているテキストには、１年次から入学してくる留学生用に英語による説明が併記されている。これは本校のタイ・チュラポーン王女サイエンスハイスクールからの留学生への対応のため作成されたものであるが、３年次以降に編入学してくる正規留学生や短期留学生も使用できるようになっている。また、必要に応じて専攻科生によるTA制度も実施しており、学習内容の説明やPC操作の補助も行っている。 ３．プレラボ制度 プレラボ（Pre-laboratory）制度は、教員の萌芽的研究への支援と低学年からの研究活動を活発化させる事を目的として運用されている。本制度は、「萌芽的研究・アイデアの具現化（学生教育）」、「各種セミナーの開催」、「新しい教育の模索」の三つを柱としており、誰もが萌芽的テーマやセミナー等を全学生（学年横断・学科横断）・全教職員に提案できることに大きな特徴がある。高専には、ものづくりや実験が好きな学生が比較的多く入学するが、一般的に低学年では研究活動の基礎となる学力を修得するための授業が中心であり、2年生頃に数学・物理等の成績不振で悩み学習意欲を失ってくるという事例が報告されている。そこで本制度の活用により、ものづくりへの興味を再確認させると同時に、学習意欲を持ち直させる事を大きな目的の一つとしている。本制度を利用して全国高専ディープラーニングコンテストに参加した学生たちは、大会内で極めて優秀な成績を収めており、学内のアクティビティを高めている。さらに、本校を卒業したOBが起業した「フラー株式会社」と包括的連携協定を結び、プログラミングやアプリ開発を行うプレラボで講師として参加いただいている。この活動も毎年多くの学生が参加してくれており、学科学年を横断して学生の自主的な創造力を支援する取り組みとなっている。
A88: ③ | B88: その他の取組（地域連携、産業界との連携、海外の大学等との連携等）
B89: 本教育プログラムは、様々な外部機関との連携により実施されている。 以下に取り組み状況を示す。 １．地域連携 本教育プログラムの元となっている「長岡版イノベーションの源泉となるAIR Techエンジニアの育成」では外部有識者から高い評価を得ている。本事業は、長岡市が進める「長岡版イノベーション」を支えるAI・IoT・RT技術を自然に使いこなすエンジニアの育成に関するものである。次世代技術者にとって必須のAI・IoT・RT技術をAIRテクノロジーと命名し、リテラシー教育、自主的実践活動、社会実装プロジェクトを通じて、学科や専門によらず当たり前の知識・技術として定着させ、地元地域の産業、経済活性化の源泉となる次世代エンジニアを育成することを事業目的としている。長岡市にある３大学（長岡技術科学大学、長岡造形大学、長岡大学）と長岡市役所、長岡商工会議所との協働構想であるNaDeC（Nagaoka Delta Cone）構想推進コンソーシアムをベースに、産学官連携体制を編成している。３大学の強みは、国際交流、先端技術、デザイン、ビジネスといった多様な教育リソースを有することであり、協働により多様な教育機会を学生に提供できる。また、長岡市商工会議所の強みは地元企業との連携であり、企業が抱える課題をPBLとして解決するような教育機会を学生に提供できる。長岡市は、そのような協働教育の実践スペースとして、コワーキングスペースNaDeC BASEを整備するなど、行政側から強力に支援している。 ２．産業界との連携 最先端ＩＴ分野およびアントレプレナーシップ教育の実現に向けてフラー株式会社との包括的連携協定を締結した。この協定は、本校が文部科学省より採択された平成２９年度「 ”ＫＯＳＥＮ（高専）4.0”イニシアティブ」支援対象事業である「長岡リジュベネーションに立脚したNaDeCアントレプレナーの育成」の一環として、最先端ＩＴ分野および未来の起業家を輩出するアントレプレナーシップ教育の実現に向けた連携を目指したものである。フラー株式会社は、本校を卒業した渋谷修太代表取締役ＣＥＯらが設立したスマートフォンアプリ開発などのソフトウエア開発のＩＴベンチャー企業である。本協定では、本校の学生を対象として起業家マインドなどアントレプレナーシップについての実践キャリア教育のための講演会、基礎セミナー、実践セミナーなどを開催し、起業家精神の育成やＩＴ技術の向上に取り組むとともに実践力のある創造的技術者の人材育成を図っている。 ３．海外の大学等との連携 本校は、毎年多くの留学生が編入学すると共に、フィンランドのトゥルク応用科学大学やロシアのハバロフスク地域専門職上級資格・再教育研究所、コムソモリスクオンアムール州立技術大学、メキシコのグアナファト大学といったマレーシア・タイ・モンゴル・ベトナム・メキシコ・シンガポールなどの11の大学・教育機関と学術交流協定を結び、海外派遣・受入事業を定期的に行っており、全国51高専の中でも国際交流が大変盛んな高専の1つである。その中でもタイ国立中高一貫校であるチュラポーン王女サイエンスハイスクール（PCSHS）からの１年次からの留学生受け入れでは学内の国際活動の活性化に大きく貢献している。その一例として、令和２年度に内閣府地方創生推進室主催、経済産業省共催で開催された「地方創生☆政策アイデアコンテスト」の全国大会で、本校の日本人学生と留学生の混成チームによるアイデア「未利用魚の利活用」が優秀賞を受賞した。
